Workbook
Name Annual_Data: '$template-default'!$A$1:$A$2

Sheet $template-default

Sheet >> CHARTS

Sheet >> DATA

Sheet Chart Data
B1: GDP levels | I1: Public sector net debt (ex BoE) | L1: Change year-to-year | V1: Real government spending across fiscal events | CM1: Public sector net investment | CR1: Public sector current budget | CW1: Cyclically-adjusted current budget | DD1: Higher growth scenario | DQ1: >> NOT USED | DT1: Real government spending per head across fiscal events | EU1: Cyclically-adjusted current budget
V2: Real PSCE in RDEL per head (2023-2024=100) | AC2: Real PSGI in RDEL per head (2023-2024=100) | AJ2: Real PSCE in RDEL per head (2023-2024 prices) | AP2: Real PSGI in RDEL per head (2023-2024 prices) | AV2: PSCE in RDEL per head | BB2: PSGI in RDEL per head | BH2: PSCE in RDEL | BN2: PSGI in RDEL | BT2: GDP deflator (2023-2024 = 100) | BZ2: GDP deflator (raw) | CF2: Population | DA2: Output gap | DE2: GDP | DI2: PSNDX | DM2: CACB | DT2: Real PSCE in RDEL per head (2023-2024=100) | EA2: Real PSGI in RDEL per head (2023-2024=100) | EI2: Real PSCE in RDEL per capita | EO2: Real PSGI in CDEL per capita | EZ2: CACB - baseline | FC2: CACB - scenario
B3: Current baseline | C3: New fiscal rules scenario | D3: 100 LINE | F3: Diff | I3: Current baseline | J3: New fiscal rules scenario | L3: Current baseline | M3: New fiscal rules scenario | O3: Current baseline | P3: New fiscal rules scenario | R3: BoE | S3: APF valuation losses | V3: 44621 | W3: 44866 | X3: 44986 | Y3: 45231 | Z3: 45352 | AA3: 100 LINE | AC3: 44621 | AD3: 44866 | AE3: 44986 | AF3: 45231 | AG3: 45352 | AH3: 100 LINE | AJ3: 44621 | AK3: 44866 | AL3: 44986 | AM3: 45231 | AN3: 45352 | AP3: 44621 | AQ3: 44866 | AR3: 44986 | AS3: 45231 | AT3: 45352 | AV3: SS22 | AW3: AS22 | AX3: Budget23 | AY3: AS23 | AZ3: Budget24 | BB3: SS22 | BC3: AS22 | BD3: Budget23 | BE3: AS23 | BF3: Budget24 | BH3: SS22 | BI3: AS22 | BJ3: Budget23 | BK3: AS23 | BL3: Budget24 | BN3: SS22 | BO3: AS22 | BP3: Budget23 | BQ3: AS23 | BR3: Budget24 | BT3: SS22 | BU3: AS22 | BV3: Budget23 | BW3: AS23 | BX3: Budget24 | BZ3: SS22 | CA3: AS22 | CB3: Budget23 | CC3: AS23 | CD3: Budget24 | CF3: SS22 | CG3: AS22 | CH3: Budget23 | CI3: AS23 | CJ3: Budget24 | CM3: Current baseline | CN3: New fiscal rules scenario | CO3: 3% LINE | CR3: Current baseline | CS3: New fiscal rules scenario | CT3: ZERO LINE | CW3: Current baseline | CX3: New fiscal rules scenario | CY3: ZERO LINE | DA3: Current baseline | DB3: New fiscal rules scenario | DE3: Current baseline | DF3: New fiscal rules | DG3: New fiscal rules & higher growth | DI3: Current baseline | DJ3: New fiscal rules | DK3: New fiscal rules & higher growth | DM3: Current baseline | DN3: New fiscal rules | DO3: New fiscal rules & higher growth | DT3: 44621 | DU3: 44866 | DV3: 44986 | DW3: 45231 | DX3: 45352 | DY3: 100 LINE | EA3: 44621 | EB3: 44866 | EC3: 44986 | ED3: 45231 | EE3: 45352 | EF3: 100 LINE | EI3: 44621 | EJ3: 44866 | EK3: 44986 | EL3: 45231 | EM3: 45352 | EO3: 44621 | EP3: 44866 | EQ3: 44986 | ER3: 45231 | ES3: 45352 | EV3: Current baseline | EW3: New fiscal rules scenario | EX3: ZERO LINE | EZ3: Structural revenue | FA3: Structural expenditure | FC3: Structural revenue | FD3: Structural expenditure
A4: 2000 | B4: =100*(Data!BO27/Data!BO$46) -> 73.434314 | C4: =100*(Data!CH27/Data!CH$46) -> 73.434314 | D4: 100 | F4: =100*((C4/B4)-1) -> 0 | H4: 2000 | I4: =100*(O4/Data!$BW27) -> 30.093194 | J4: =100*(P4/Data!$CP27) -> 30.093194 | O4: =Data!BV27-$R4 -> 334500 | P4: =Data!CO27-$R4 -> 334500 | R4: ='GNDBTX ex BoE'!D120 -> -12500 | U4: 2019-20 | V4: =100*(AJ4/AJ$9) -> 88.103473 | AA4: 100 | AC4: =100*(AP4/AP$9) -> 70.104704 | AH4: 100 | AJ4: =100*(AV4/BT4) -> 5.3631027 | AP4: =100*(BB4/BT4) -> 0.96593107 | AV4: =BH4/(CF4/1000) -> 4.8043274 | BB4: =BN4/(CF4/1000) -> 0.86529185 | BH4: {=TRANSPOSE(OBR_MAR22_T3.16!C8:J8)} -> 321.42632 | BN4: {=TRANSPOSE(OBR_MAR22_T3.16!C31:J31)} -> 57.891053 | BT4: =100*(BZ4/BZ$8) -> 89.581117 | BU4: =100*(CA4/CA$8) -> 87.221869 | BV4: =100*(CB4/CB$8) -> 87.485684 | BW4: =100*(CC4/CC$8) -> 84.464903 | BX4: =100*(CD4/CD$8) -> 84.011728 | BZ4: =OBR_MAR22_1.2!X112 -> 100.74871 | CA4: =OBR_NOV22_1.2!X117 -> 100.88484 | CB4: =OBR_MAR23_1.2!X117 -> 100.88484 | CC4: =OBR_NOV23_1.2!X122 -> 100.73409 | CD4: =OBR_MAR24_1.2!X122 -> 100.73409 | CF4: {=TRANSPOSE(OBR_MAR22_ST3.3!Q34:X34)} -> 66903.5 | CG4: {=TRANSPOSE(OBR_NOV22_ST3.3!Q34:Y34)} -> 66903.5 | CH4: {=TRANSPOSE(OBR_MAR23_ST3.3!Q34:Y34)} -> 66903.5 | CI4: {=TRANSPOSE(OBR_NOV23_ST3.3!Q34:Z34)} -> 66903.5 | CJ4: {=TRANSPOSE(OBR_MAR24_ST4.3!Q34:Z34)} -> 66903.5 | CL4: 2000 | CM4: =100*(Data!BS27/Data!$BW27) -> 0.40583079 | CN4: =100*(Data!CL27/Data!$CP27) -> 0.40583079 | CO4: 3 | CQ4: 2000 | CR4: =100*(Data!BQ27/Data!$BW27) -> 1.8496744 | CS4: =100*(Data!CJ27/Data!$CP27) -> 1.8496744 | CT4: 0 | CV4: 2000 | CW4: =CR4-DA4 -> -1.7681846 | CX4: =CS4-DB4 -> -1.7681846 | CY4: 0 | DA4: =Data!CF27 -> 3.617859 | DB4: =Data!CY27 -> 3.617859 | DD4: 2000 | DE4: =100*(Data!BO27/Data!BO$46) -> 73.434314 | DF4: =100*(Data!CH27/Data!CH$46) -> 73.434314 | DG4: =100*(Data!DA27/Data!DA$46) -> 73.434314 | DI4: =I4 -> 30.093194 | DJ4: =J4 -> 30.093194 | DK4: =100*(Data!DH27-$R4)/Data!DI27 -> 30.093194 | DM4: =CW4 -> -1.7681846 | DN4: =CX4 -> -1.7681846 | DO4: =(100*(Data!DC27/Data!$DI27))-Data!$DR27 -> -1.7681846 | DS4: 2007-08 | DT4: =100*(EI4/EI$20) -> 95.558492 | DU4: =100*(EJ4/EJ$20) -> 96.229945 | DV4: =100*(EK4/EK$20) -> 95.912198 | DW4: =100*(EL4/EL$20) -> 99.049288 | DX4: =100*(EM4/EM$20) -> 100.43541 | DY4: 100 | EA4: =100*(EO4/EO$20) -> 77.851095 | EB4: =100*(EP4/EP$20) -> 80.810199 | EC4: =100*(EQ4/EQ$20) -> 98.927543 | ED4: =100*(ER4/ER$20) -> 83.163642 | EE4: =100*(ES4/ES$20) -> 83.985641 | EF4: 100 | EH4: 2007-08 | EI4: {=TRANSPOSE(OBR_MAR22_ST3.3!E11:X11)} -> 5424.4566 | EJ4: {=TRANSPOSE(OBR_NOV22_ST3.3!E11:Y11)} -> 5758.8387 | EK4: {=TRANSPOSE(OBR_MAR23_ST3.3!E11:Y11)} -> 5781.014 | EL4: {=TRANSPOSE(OBR_NOV23_ST3.3!E11:Z11)} -> 5806.2508 | EM4: {=TRANSPOSE(OBR_MAR24_ST4.3!E11:Z11)} -> 6193.1143 | EO4: {=TRANSPOSE(OBR_MAR22_ST3.3!E17:X17)} -> 1025.1214 | EP4: {=TRANSPOSE(OBR_NOV22_ST3.3!E17:Y17)} -> 1088.3134 | EQ4: {=TRANSPOSE(OBR_MAR23_ST3.3!E17:Y17)} -> 1092.5041 | ER4: {=TRANSPOSE(OBR_NOV23_ST3.3!E17:Z17)} -> 1097.2734 | ES4: {=TRANSPOSE(OBR_MAR24_ST4.3!E17:Z17)} -> 1170.3834 | EU4: 2000 | EV4: =100*((EZ4-FA4)/Data!BX27*Data!BY27*0.01) -> 0.85646479 | EW4: =100*((FC4-FD4)/Data!CQ27*Data!CR27*0.01) -> 0.85646479 | EX4: 0 | EZ4: =Data!BU27*(Data!BX27*Data!BY27*0.01/Data!BW27)^1 -> 392499.41 | FA4: =(Data!BR27+Data!BT27)*(Data!BX27*Data!BY27*0.01/Data!BW27)^1 -> 372671.58 | FC4: =Data!CN27*(Data!CQ27*Data!CR27*0.01/Data!CP27)^1 -> 392499.41 | FD4: =(Data!CK27+Data!CM27)*(Data!CQ27*Data!CR27*0.01/Data!CP27)^1 -> 372671.58
A5: 2001 | B5: =100*(Data!BO28/Data!BO$46) -> 75.074594 | C5: =100*(Data!CH28/Data!CH$46) -> 75.074594 | D5: 100 | F5: =100*((C5/B5)-1) -> 0 | H5: 2001 | I5: =100*(O5/Data!$BW28) -> 29.144049 | J5: =100*(P5/Data!$CP28) -> 29.144049 | O5: =Data!BV28-$R5 -> 336800 | P5: =Data!CO28-$R5 -> 336800 | R5: ='GNDBTX ex BoE'!D121 -> -6200 | U5: 2020-21 | V5: =100*(AJ5/AJ$9) -> 112.38525 | AA5: 100 | AC5: =100*(AP5/AP$9) -> 82.988486 | AH5: 100 | AJ5: =100*(AV5/BT5) -> 6.8412017 | AP5: =100*(BB5/BT5) -> 1.1434491 | AV5: =BH5/(CF5/1000) -> 6.4777615 | BB5: =BN5/(CF5/1000) -> 1.0827031 | BH5: 434.5177 | BN5: 72.625962 | BT5: =100*(BZ5/BZ$8) -> 94.68748 | BU5: =100*(CA5/CA$8) -> 92.72465 | BV5: =100*(CB5/CB$8) -> 92.876405 | BW5: =100*(CC5/CC$8) -> 88.965576 | BX5: =100*(CD5/CD$8) -> 88.488253 | BZ5: =OBR_MAR22_1.2!X113 -> 106.49166 | CA5: =OBR_NOV22_1.2!X118 -> 107.24961 | CB5: =OBR_MAR23_1.2!X118 -> 107.10119 | CC5: =OBR_NOV23_1.2!X123 -> 106.10166 | CD5: =OBR_MAR24_1.2!X123 -> 106.10166 | CF5: 67078.373 | CG5: 67249.5 | CH5: 67182 | CI5: 67060.5 | CJ5: 67060.5 | CL5: 2001 | CM5: =100*(Data!BS28/Data!$BW28) -> 1.0938537 | CN5: =100*(Data!CL28/Data!$CP28) -> 1.0938537 | CO5: 3 | CQ5: 2001 | CR5: =100*(Data!BQ28/Data!$BW28) -> 0.57820825 | CS5: =100*(Data!CJ28/Data!$CP28) -> 0.57820825 | CT5: 0 | CV5: 2001 | CW5: =CR5-DA5 -> -1.9299548 | CX5: =CS5-DB5 -> -1.9299548 | CY5: 0 | DA5: =Data!CF28 -> 2.508163 | DB5: =Data!CY28 -> 2.508163 | DD5: 2001 | DE5: =100*(Data!BO28/Data!BO$46) -> 75.074594 | DF5: =100*(Data!CH28/Data!CH$46) -> 75.074594 | DG5: =100*(Data!DA28/Data!DA$46) -> 75.074594 | DI5: =I5 -> 29.144049 | DJ5: =J5 -> 29.144049 | DK5: =100*(Data!DH28-$R5)/Data!DI28 -> 29.144049 | DM5: =CW5 -> -1.9299548 | DN5: =CX5 -> -1.9299548 | DO5: =(100*(Data!DC28/Data!$DI28))-Data!$DR28 -> -1.9299548 | DS5: 2008-09 | DT5: =100*(EI5/EI$20) -> 96.378326 | DU5: =100*(EJ5/EJ$20) -> 96.4484 | DV5: =100*(EK5/EK$20) -> 96.129932 | DW5: =100*(EL5/EL$20) -> 99.274143 | DX5: =100*(EM5/EM$20) -> 100.66341 | DY5: 100 | EA5: =100*(EO5/EO$20) -> 80.930504 | EB5: =100*(EP5/EP$20) -> 83.481145 | EC5: =100*(EQ5/EQ$20) -> 102.19731 | ED5: =100*(ER5/ER$20) -> 85.912375 | EE5: =100*(ES5/ES$20) -> 86.761543 | EF5: 100 | EH5: 2008-09 | EI5: 5470.9951 | EJ5: 5771.9121 | EK5: 5794.1376 | EL5: 5819.4318 | EM5: 6207.1735 | EO5: 1065.6702 | EP5: 1124.2844 | EQ5: 1128.6136 | ER5: 1133.5406 | ES5: 1209.067 | EU5: 2001 | EV5: =100*((EZ5-FA5)/Data!BX28*Data!BY28*0.01) -> 0.2768968 | EW5: =100*((FC5-FD5)/Data!CQ28*Data!CR28*0.01) -> 0.2768968 | EX5: 0 | EZ5: =Data!BU28*(Data!BX28*Data!BY28*0.01/Data!BW28)^1 -> 401136.14 | FA5: =(Data!BR28+Data!BT28)*(Data!BX28*Data!BY28*0.01/Data!BW28)^1 -> 394644.22 | FC5: =Data!CN28*(Data!CQ28*Data!CR28*0.01/Data!CP28)^1 -> 401136.14 | FD5: =(Data!CK28+Data!CM28)*(Data!CQ28*Data!CR28*0.01/Data!CP28)^1 -> 394644.22
A6: 2002 | B6: =100*(Data!BO29/Data!BO$46) -> 76.631299 | C6: =100*(Data!CH29/Data!CH$46) -> 76.631299 | D6: 100 | F6: =100*((C6/B6)-1) -> 0 | H6: 2002 | I6: =100*(O6/Data!$BW29) -> 30.651608 | J6: =100*(P6/Data!$CP29) -> 30.651608 | O6: =Data!BV29-$R6 -> 369800 | P6: =Data!CO29-$R6 -> 369800 | R6: ='GNDBTX ex BoE'!D122 -> -600 | U6: 2021-22 | V6: =100*(AJ6/AJ$9) -> 105.64515 | W6: =100*(AK6/AK$9) -> 108.48135 | X6: =100*(AL6/AL$9) -> 108.36459 | AA6: 100 | AC6: =100*(AP6/AP$9) -> 79.750604 | AD6: =100*(AQ6/AQ$9) -> 89.928544 | AE6: =100*(AR6/AR$9) -> 88.791675 | AH6: 100 | AJ6: =100*(AV6/BT6) -> 6.4309131 | AK6: =100*(AW6/BU6) -> 6.6285693 | AL6: =100*(AX6/BV6) -> 6.6412055 | AP6: =100*(BB6/BT6) -> 1.0988362 | AQ6: =100*(BC6/BU6) -> 1.2333911 | AR6: =100*(BD6/BV6) -> 1.2357423 | AV6: =BH6/(CF6/1000) -> 6.0354237 | AW6: =BI6/(CG6/1000) -> 6.1247712 | AX6: =BJ6/(CH6/1000) -> 6.1316693 | BB6: =BN6/(CF6/1000) -> 1.0312598 | BC6: =BO6/(CG6/1000) -> 1.1396483 | BD6: =BP6/(CH6/1000) -> 1.1409319 | BH6: 405.02778 | BI6: {=TRANSPOSE(OBR_NOV22_TA.8!C8:I8)} -> 413.76045 | BJ6: {=TRANSPOSE(OBR_MAR23_TA.7!D8:J8)} -> 413.76045 | BN6: 69.20622 | BO6: {=TRANSPOSE(OBR_NOV22_TA.8!C30:I30)} -> 76.989229 | BP6: {=TRANSPOSE(OBR_MAR23_TA.7!D32:J32)} -> 76.989229 | BT6: =100*(BZ6/BZ$8) -> 93.850184 | BU6: =100*(CA6/CA$8) -> 92.399594 | BV6: =100*(CB6/CB$8) -> 92.327656 | BW6: =100*(CC6/CC$8) -> 88.374124 | BX6: =100*(CD6/CD$8) -> 87.880815 | BZ6: =OBR_MAR22_1.2!X114 -> 105.54998 | CA6: =OBR_NOV22_1.2!X119 -> 106.87364 | CB6: =OBR_MAR23_1.2!X119 -> 106.4684 | CC6: =OBR_NOV23_1.2!X124 -> 105.39629 | CD6: =OBR_MAR24_1.2!X124 -> 105.37331 | CF6: 67108.425 | CG6: 67555.25 | CH6: 67479.25 | CI6: 67313.25 | CJ6: 67313.25 | CL6: 2002 | CM6: =100*(Data!BS29/Data!$BW29) -> 1.4477041 | CN6: =100*(Data!CL29/Data!$CP29) -> 1.4477041 | CO6: 3 | CQ6: 2002 | CR6: =100*(Data!BQ29/Data!$BW29) -> -1.5019122 | CS6: =100*(Data!CJ29/Data!$CP29) -> -1.5019122 | CT6: 0 | CV6: 2002 | CW6: =CR6-DA6 -> -4.1614242 | CX6: =CS6-DB6 -> -4.1614242 | CY6: 0 | DA6: =Data!CF29 -> 2.659512 | DB6: =Data!CY29 -> 2.659512 | DD6: 2002 | DE6: =100*(Data!BO29/Data!BO$46) -> 76.631299 | DF6: =100*(Data!CH29/Data!CH$46) -> 76.631299 | DG6: =100*(Data!DA29/Data!DA$46) -> 76.631299 | DI6: =I6 -> 30.651608 | DJ6: =J6 -> 30.651608 | DK6: =100*(Data!DH29-$R6)/Data!DI29 -> 30.651608 | DM6: =CW6 -> -4.1614242 | DN6: =CX6 -> -4.1614242 | DO6: =(100*(Data!DC29/Data!$DI29))-Data!$DR29 -> -4.1614242 | DS6: 2009-10 | DT6: =100*(EI6/EI$20) -> 100.24105 | DU6: =100*(EJ6/EJ$20) -> 100.55955 | DV6: =100*(EK6/EK$20) -> 100.22751 | DW6: =100*(EL6/EL$20) -> 103.50574 | DX6: =100*(EM6/EM$20) -> 104.95422 | DY6: 100 | EA6: =100*(EO6/EO$20) -> 90.013179 | EB6: =100*(EP6/EP$20) -> 93.077417 | EC6: =100*(EQ6/EQ$20) -> 113.94503 | ED6: =100*(ER6/ER$20) -> 95.78812 | EE6: =100*(ES6/ES$20) -> 96.7349 | EF6: 100 | EH6: 2009-10 | EI6: 5690.2657 | EJ6: 6017.9419 | EK6: 6041.1149 | EL6: 6067.4872 | EM6: 6471.7565 | EO6: 1185.2683 | EP6: 1253.5225 | EQ6: 1258.3493 | ER6: 1263.8426 | ES6: 1348.0509 | EU6: 2002 | EV6: =100*((EZ6-FA6)/Data!BX29*Data!BY29*0.01) -> -0.7523072 | EW6: =100*((FC6-FD6)/Data!CQ29*Data!CR29*0.01) -> -0.7523072 | EX6: 0 | EZ6: =Data!BU29*(Data!BX29*Data!BY29*0.01/Data!BW29)^1 -> 407851.25 | FA6: =(Data!BR29+Data!BT29)*(Data!BX29*Data!BY29*0.01/Data!BW29)^1 -> 425514.24 | FC6: =Data!CN29*(Data!CQ29*Data!CR29*0.01/Data!CP29)^1 -> 407851.25 | FD6: =(Data!CK29+Data!CM29)*(Data!CQ29*Data!CR29*0.01/Data!CP29)^1 -> 425514.24
A7: 2003 | B7: =100*(Data!BO30/Data!BO$46) -> 79.104037 | C7: =100*(Data!CH30/Data!CH$46) -> 79.104037 | D7: 100 | F7: =100*((C7/B7)-1) -> 0 | H7: 2003 | I7: =100*(O7/Data!$BW30) -> 31.868562 | J7: =100*(P7/Data!$CP30) -> 31.868562 | O7: =Data!BV30-$R7 -> 405900 | P7: =Data!CO30-$R7 -> 405900 | R7: ='GNDBTX ex BoE'!D123 -> -1400 | U7: 2022-23 | V7: =100*(AJ7/AJ$9) -> 101.74477 | W7: =100*(AK7/AK$9) -> 103.7007 | X7: =100*(AL7/AL$9) -> 102.44555 | Y7: =100*(AM7/AM$9) -> 103.34926 | Z7: =100*(AN7/AN$9) -> 103.4887 | AA7: 100 | AC7: =100*(AP7/AP$9) -> 94.978351 | AD7: =100*(AQ7/AQ$9) -> 98.759829 | AE7: =100*(AR7/AR$9) -> 93.720941 | AF7: =100*(AS7/AS$9) -> 98.987577 | AG7: =100*(AT7/AT$9) -> 98.901005 | AH7: 100 | AJ7: =100*(AV7/BT7) -> 6.1934863 | AK7: =100*(AW7/BU7) -> 6.3364562 | AL7: =100*(AX7/BV7) -> 6.2784528 | AM7: =100*(AY7/BW7) -> 6.4180282 | AN7: =100*(AZ7/BX7) -> 6.3887696 | AP7: =100*(BB7/BT7) -> 1.3086503 | AQ7: =100*(BC7/BU7) -> 1.3545142 | AR7: =100*(BD7/BV7) -> 1.3043445 | AS7: =100*(BE7/BW7) -> 1.4003288 | AT7: =100*(BF7/BX7) -> 1.4078975 | AV7: =BH7/(CF7/1000) -> 6.0477297 | AW7: =BI7/(CG7/1000) -> 6.1379817 | AX7: =BJ7/(CH7/1000) -> 6.1222512 | AY7: =BK7/(CI7/1000) -> 6.0496958 | AZ7: =BL7/(CJ7/1000) -> 5.9957062 | BB7: =BN7/(CF7/1000) -> 1.2778527 | BC7: =BO7/(CG7/1000) -> 1.3120873 | BD7: =BP7/(CH7/1000) -> 1.2718937 | BE7: =BQ7/(CI7/1000) -> 1.3199636 | BF7: =BR7/(CJ7/1000) -> 1.3212779 | BH7: 406.97511 | BI7: 415.47497 | BJ7: 415.47476 | BK7: {=TRANSPOSE(OBR_NOV23_TA.7!C8:I8)} -> 411.5361 | BL7: {=TRANSPOSE(OBR_MAR24_TA.7!C8:I8)} -> 407.4577 | BN7: 85.991647 | BO7: 88.814116 | BP7: 86.31461 | BQ7: {=TRANSPOSE(OBR_NOV23_TA.7!C32:I32)} -> 89.791733 | BR7: {=TRANSPOSE(OBR_MAR24_TA.7!C32:I32)} -> 89.791733 | BT7: =100*(BZ7/BZ$8) -> 97.646614 | BU7: =100*(CA7/CA$8) -> 96.867736 | BV7: =100*(CB7/CB$8) -> 97.5121 | BW7: =100*(CC7/CC$8) -> 94.260972 | BX7: =100*(CD7/CD$8) -> 93.847589 | BZ7: =OBR_MAR22_1.2!X115 -> 109.81969 | CA7: =OBR_NOV22_1.2!X120 -> 112.0417 | CB7: =OBR_MAR23_1.2!X120 -> 112.44689 | CC7: =OBR_NOV23_1.2!X125 -> 112.41703 | CD7: =OBR_MAR24_1.2!X125 -> 112.52776 | CF7: 67293.866 | CG7: 67689.184 | CH7: 67863.07 | CI7: 68025.917 | CJ7: 67958.25 | CL7: 2003 | CM7: =100*(Data!BS30/Data!$BW30) -> 1.6907847 | CN7: =100*(Data!CL30/Data!$CP30) -> 1.6907847 | CO7: 3 | CQ7: 2003 | CR7: =100*(Data!BQ30/Data!$BW30) -> -1.7829593 | CS7: =100*(Data!CJ30/Data!$CP30) -> -1.7829593 | CT7: 0 | CV7: 2003 | CW7: =CR7-DA7 -> -4.8384363 | CX7: =CS7-DB7 -> -4.8384363 | CY7: 0 | DA7: =Data!CF30 -> 3.055477 | DB7: =Data!CY30 -> 3.055477 | DD7: 2003 | DE7: =100*(Data!BO30/Data!BO$46) -> 79.104037 | DF7: =100*(Data!CH30/Data!CH$46) -> 79.104037 | DG7: =100*(Data!DA30/Data!DA$46) -> 79.104037 | DI7: =I7 -> 31.868562 | DJ7: =J7 -> 31.868562 | DK7: =100*(Data!DH30-$R7)/Data!DI30 -> 31.868562 | DM7: =CW7 -> -4.8384363 | DN7: =CX7 -> -4.8384363 | DO7: =(100*(Data!DC30/Data!$DI30))-Data!$DR30 -> -4.8384363 | DS7: 2010-11 | DT7: =100*(EI7/EI$20) -> 99.949353 | DU7: =100*(EJ7/EJ$20) -> 100.27327 | DV7: =100*(EK7/EK$20) -> 229.83438 | DW7: =100*(EL7/EL$20) -> 102.88886 | DX7: =100*(EM7/EM$20) -> 104.32871 | DY7: 100 | EA7: =100*(EO7/EO$20) -> 75.30368 | EB7: =100*(EP7/EP$20) -> 77.8721 | EC7: =100*(EQ7/EQ$20) -> 95.330733 | ED7: =100*(ER7/ER$20) -> 79.993858 | EE7: =100*(ES7/ES$20) -> 80.784526 | EF7: 100 | EH7: 2010-11 | EI7: 5673.7075 | EJ7: 6000.8097 | EK7: 13853.042 | EL7: 6031.3257 | EM7: 6433.1857 | EO7: 991.57774 | EP7: 1048.7445 | EQ7: 1052.7828 | ER7: 1055.4508 | ES7: 1125.7742 | EU7: 2003 | EV7: =100*((EZ7-FA7)/Data!BX30*Data!BY30*0.01) -> -0.93415157 | EW7: =100*((FC7-FD7)/Data!CQ30*Data!CR30*0.01) -> -0.93415157 | EX7: 0 | EZ7: =Data!BU30*(Data!BX30*Data!BY30*0.01/Data!BW30)^1 -> 437050.61 | FA7: =(Data!BR30+Data!BT30)*(Data!BX30*Data!BY30*0.01/Data!BW30)^1 -> 459047.22 | FC7: =Data!CN30*(Data!CQ30*Data!CR30*0.01/Data!CP30)^1 -> 437050.61 | FD7: =(Data!CK30+Data!CM30)*(Data!CQ30*Data!CR30*0.01/Data!CP30)^1 -> 459047.22
A8: 2004 | B8: =100*(Data!BO31/Data!BO$46) -> 80.870374 | C8: =100*(Data!CH31/Data!CH$46) -> 80.870374 | D8: 100 | F8: =100*((C8/B8)-1) -> 0 | H8: 2004 | I8: =100*(O8/Data!$BW31) -> 34.684374 | J8: =100*(P8/Data!$CP31) -> 34.684374 | O8: =Data!BV31-$R8 -> 465200 | P8: =Data!CO31-$R8 -> 465200 | R8: ='GNDBTX ex BoE'!D124 -> -4300 | U8: 2023-24 | V8: =100*(AJ8/AJ$9) -> 99.372895 | W8: =100*(AK8/AK$9) -> 101.1059 | X8: =100*(AL8/AL$9) -> 100.83213 | Y8: =100*(AM8/AM$9) -> 100.15211 | Z8: =100*(AN8/AN$9) -> 99.88447 | AA8: 100 | AC8: =100*(AP8/AP$9) -> 101.83936 | AD8: =100*(AQ8/AQ$9) -> 101.36806 | AE8: =100*(AR8/AR$9) -> 101.20179 | AF8: =100*(AS8/AS$9) -> 98.955955 | AG8: =100*(AT8/AT$9) -> 97.893255 | AH8: 100 | AJ8: =100*(AV8/BT8) -> 6.0491038 | AK8: =100*(AW8/BU8) -> 6.1779053 | AL8: =100*(AX8/BV8) -> 6.1795727 | AM8: =100*(AY8/BW8) -> 6.2194842 | AN8: =100*(AZ8/BX8) -> 6.1662659 | AP8: =100*(BB8/BT8) -> 1.4031841 | AQ8: =100*(BC8/BU8) -> 1.3902867 | AR8: =100*(BD8/BV8) -> 1.4084579 | AS8: =100*(BE8/BW8) -> 1.3998815 | AT8: =100*(BF8/BX8) -> 1.3935518 | AV8: =BH8/(CF8/1000) -> 6.0491038 | AW8: =BI8/(CG8/1000) -> 6.1779053 | AX8: =BJ8/(CH8/1000) -> 6.1795727 | AY8: =BK8/(CI8/1000) -> 6.2194842 | AZ8: =BL8/(CJ8/1000) -> 6.1662659 | BB8: =BN8/(CF8/1000) -> 1.4031841 | BC8: =BO8/(CG8/1000) -> 1.3902867 | BD8: =BP8/(CH8/1000) -> 1.4084579 | BE8: =BQ8/(CI8/1000) -> 1.3998815 | BF8: =BR8/(CJ8/1000) -> 1.3935518 | BH8: 408.019 | BI8: 419.68701 | BJ8: 421.6874 | BK8: 426.51629 | BL8: 422.94449 | BN8: 94.646379 | BO8: 94.447103 | BP8: 96.111651 | BQ8: 96.000288 | BR8: 95.583786 | BT8: =100*(BZ8/BZ$8) -> 100 | BU8: =100*(CA8/CA$8) -> 100 | BV8: =100*(CB8/CB$8) -> 100 | BW8: =100*(CC8/CC$8) -> 100 | BX8: =100*(CD8/CD$8) -> 100 | BZ8: =OBR_MAR22_1.2!X116 -> 112.46646 | CA8: =OBR_NOV22_1.2!X121 -> 115.66462 | CB8: =OBR_MAR23_1.2!X121 -> 115.31583 | CC8: =OBR_NOV23_1.2!X126 -> 119.26148 | CD8: =OBR_MAR24_1.2!X126 -> 119.9048 | CF8: 67451.149 | CG8: 67933.545 | CH8: 68238.924 | CI8: 68577.439 | CJ8: 68590.05 | CL8: 2004 | CM8: =100*(Data!BS31/Data!$BW31) -> 2.0473622 | CN8: =100*(Data!CL31/Data!$CP31) -> 2.0473622 | CO8: 3 | CQ8: 2004 | CR8: =100*(Data!BQ31/Data!$BW31) -> -1.8647697 | CS8: =100*(Data!CJ31/Data!$CP31) -> -1.8647697 | CT8: 0 | CV8: 2004 | CW8: =CR8-DA8 -> -4.1531117 | CX8: =CS8-DB8 -> -4.1531117 | CY8: 0 | DA8: =Data!CF31 -> 2.288342 | DB8: =Data!CY31 -> 2.288342 | DD8: 2004 | DE8: =100*(Data!BO31/Data!BO$46) -> 80.870374 | DF8: =100*(Data!CH31/Data!CH$46) -> 80.870374 | DG8: =100*(Data!DA31/Data!DA$46) -> 80.870374 | DI8: =I8 -> 34.684374 | DJ8: =J8 -> 34.684374 | DK8: =100*(Data!DH31-$R8)/Data!DI31 -> 34.684374 | DM8: =CW8 -> -4.1531117 | DN8: =CX8 -> -4.1531117 | DO8: =(100*(Data!DC31/Data!$DI31))-Data!$DR31 -> -4.1531117 | DS8: 2011-12 | DT8: =100*(EI8/EI$20) -> 96.213761 | DU8: =100*(EJ8/EJ$20) -> 96.256732 | DV8: =100*(EK8/EK$20) -> 95.938897 | DW8: =100*(EL8/EL$20) -> 98.94705 | DX8: =100*(EM8/EM$20) -> 100.33174 | DY8: 100 | EA8: =100*(EO8/EO$20) -> 63.587319 | EB8: =100*(EP8/EP$20) -> 65.572983 | EC8: =100*(EQ8/EQ$20) -> 80.2742 | ED8: =100*(ER8/ER$20) -> 67.394256 | EE8: =100*(ES8/ES$20) -> 68.060388 | EF8: 100 | EH8: 2011-12 | EI8: 5461.6535 | EJ8: 5760.4418 | EK8: 5782.6232 | EL8: 5800.2577 | EM8: 6186.7218 | EO8: 837.29999 | EP8: 883.10579 | EQ8: 886.50632 | ER8: 889.20978 | ES8: 948.45675 | EU8: 2004 | EV8: =100*((EZ8-FA8)/Data!BX31*Data!BY31*0.01) -> -1.0365719 | EW8: =100*((FC8-FD8)/Data!CQ31*Data!CR31*0.01) -> -1.0365719 | EX8: 0 | EZ8: =Data!BU31*(Data!BX31*Data!BY31*0.01/Data!BW31)^1 -> 470566.16 | FA8: =(Data!BR31+Data!BT31)*(Data!BX31*Data!BY31*0.01/Data!BW31)^1 -> 494904.83 | FC8: =Data!CN31*(Data!CQ31*Data!CR31*0.01/Data!CP31)^1 -> 470566.16 | FD8: =(Data!CK31+Data!CM31)*(Data!CQ31*Data!CR31*0.01/Data!CP31)^1 -> 494904.83
A9: 2005 | B9: =100*(Data!BO32/Data!BO$46) -> 83.258503 | C9: =100*(Data!CH32/Data!CH$46) -> 83.258503 | D9: 100 | F9: =100*((C9/B9)-1) -> 0 | H9: 2005 | I9: =100*(O9/Data!$BW32) -> 35.640119 | J9: =100*(P9/Data!$CP32) -> 35.640119 | O9: =Data!BV32-$R9 -> 505600 | P9: =Data!CO32-$R9 -> 505600 | R9: ='GNDBTX ex BoE'!D125 -> -6200 | U9: 2024-25 | V9: =100*(AJ9/AJ$9) -> 100 | W9: =100*(AK9/AK$9) -> 100 | X9: =100*(AL9/AL$9) -> 100 | Y9: =100*(AM9/AM$9) -> 100 | Z9: =100*(AN9/AN$9) -> 100 | AA9: 100 | AC9: =100*(AP9/AP$9) -> 100 | AD9: =100*(AQ9/AQ$9) -> 100 | AE9: =100*(AR9/AR$9) -> 100 | AF9: =100*(AS9/AS$9) -> 100 | AG9: =100*(AT9/AT$9) -> 100 | AH9: 100 | AJ9: =100*(AV9/BT9) -> 6.0872774 | AK9: =100*(AW9/BU9) -> 6.110331 | AL9: =100*(AX9/BV9) -> 6.1285753 | AM9: =100*(AY9/BW9) -> 6.210038 | AN9: =100*(AZ9/BX9) -> 6.173398 | AP9: =100*(BB9/BT9) -> 1.3778406 | AQ9: =100*(BC9/BU9) -> 1.3715235 | AR9: =100*(BD9/BV9) -> 1.3917322 | AS9: =100*(BE9/BW9) -> 1.4146511 | AT9: =100*(BF9/BX9) -> 1.4235422 | AV9: =BH9/(CF9/1000) -> 6.2000928 | AW9: =BI9/(CG9/1000) -> 6.1908219 | AX9: =BJ9/(CH9/1000) -> 6.2247511 | AY9: =BK9/(CI9/1000) -> 6.3139475 | AZ9: =BL9/(CJ9/1000) -> 6.2223006 | BB9: =BN9/(CF9/1000) -> 1.4033761 | BC9: =BO9/(CG9/1000) -> 1.3895904 | BD9: =BP9/(CH9/1000) -> 1.4135726 | BE9: =BQ9/(CI9/1000) -> 1.4383218 | BF9: =BR9/(CJ9/1000) -> 1.4348188 | BH9: 419.09821 | BI9: 422.00137 | BJ9: 426.65635 | BK9: 435.45198 | BL9: 430.19538 | BN9: 94.861872 | BO9: 94.722329 | BP9: 96.888973 | BQ9: 99.196273 | BR9: 99.20003 | BT9: =100*(BZ9/BZ$8) -> 101.8533 | BU9: =100*(CA9/CA$8) -> 101.31729 | BV9: =100*(CB9/CB$8) -> 101.5693 | BW9: =100*(CC9/CC$8) -> 101.67325 | BX9: =100*(CD9/CD$8) -> 100.79215 | BZ9: =OBR_MAR22_1.2!X117 -> 114.5508 | CA9: =OBR_NOV22_1.2!X122 -> 117.18826 | CB9: =OBR_MAR23_1.2!X122 -> 117.12548 | CC9: =OBR_NOV23_1.2!X127 -> 121.25702 | CD9: =OBR_MAR24_1.2!X127 -> 120.85462 | CF9: 67595.474 | CG9: 68165.646 | CH9: 68541.913 | CI9: 68966.677 | CJ9: 69137.672 | CL9: 2005 | CM9: =100*(Data!BS32/Data!$BW32) -> 1.8518623 | CN9: =100*(Data!CL32/Data!$CP32) -> 1.8518623 | CO9: 3 | CQ9: 2005 | CR9: =100*(Data!BQ32/Data!$BW32) -> -1.4213753 | CS9: =100*(Data!CJ32/Data!$CP32) -> -1.4213753 | CT9: 0 | CV9: 2005 | CW9: =CR9-DA9 -> -4.0404513 | CX9: =CS9-DB9 -> -4.0404513 | CY9: 0 | DA9: =Data!CF32 -> 2.619076 | DB9: =Data!CY32 -> 2.619076 | DD9: 2005 | DE9: =100*(Data!BO32/Data!BO$46) -> 83.258503 | DF9: =100*(Data!CH32/Data!CH$46) -> 83.258503 | DG9: =100*(Data!DA32/Data!DA$46) -> 83.258503 | DI9: =I9 -> 35.640119 | DJ9: =J9 -> 35.640119 | DK9: =100*(Data!DH32-$R9)/Data!DI32 -> 35.640119 | DM9: =CW9 -> -4.0404513 | DN9: =CX9 -> -4.0404513 | DO9: =(100*(Data!DC32/Data!$DI32))-Data!$DR32 -> -4.0404513 | DS9: 2012-13 | DT9: =100*(EI9/EI$20) -> 92.421101 | DU9: =100*(EJ9/EJ$20) -> 92.75854 | DV9: =100*(EK9/EK$20) -> 92.452256 | DW9: =100*(EL9/EL$20) -> 95.211701 | DX9: =100*(EM9/EM$20) -> 96.544117 | DY9: 100 | EA9: =100*(EO9/EO$20) -> 59.985971 | EB9: =100*(EP9/EP$20) -> 62.057312 | EC9: =100*(EQ9/EQ$20) -> 75.970329 | ED9: =100*(ER9/ER$20) -> 63.687703 | EE9: =100*(ES9/ES$20) -> 64.3172 | EF9: 100 | EH9: 2012-13 | EI9: 5246.36 | EJ9: 5551.094 | EK9: 5572.4693 | EL9: 5581.2922 | EM9: 5953.1669 | EO9: 789.87844 | EP9: 835.75841 | EQ9: 838.97662 | ER9: 840.30497 | ES9: 896.29347 | EU9: 2005 | EV9: =100*((EZ9-FA9)/Data!BX32*Data!BY32*0.01) -> -0.83393975 | EW9: =100*((FC9-FD9)/Data!CQ32*Data!CR32*0.01) -> -0.83393975 | EX9: 0 | EZ9: =Data!BU32*(Data!BX32*Data!BY32*0.01/Data!BW32)^1 -> 506398.14 | FA9: =(Data!BR32+Data!BT32)*(Data!BX32*Data!BY32*0.01/Data!BW32)^1 -> 526030.96 | FC9: =Data!CN32*(Data!CQ32*Data!CR32*0.01/Data!CP32)^1 -> 506398.14 | FD9: =(Data!CK32+Data!CM32)*(Data!CQ32*Data!CR32*0.01/Data!CP32)^1 -> 526030.96
A10: 2006 | B10: =100*(Data!BO33/Data!BO$46) -> 85.047094 | C10: =100*(Data!CH33/Data!CH$46) -> 85.047094 | D10: 100 | F10: =100*((C10/B10)-1) -> 0 | H10: 2006 | I10: =100*(O10/Data!$BW33) -> 36.36195 | J10: =100*(P10/Data!$CP33) -> 36.36195 | O10: =Data!BV33-$R10 -> 541000 | P10: =Data!CO33-$R10 -> 541000 | R10: ='GNDBTX ex BoE'!D126 -> -5800 | U10: 2025-26 | V10: =100*(AJ10/AJ$9) -> 101.70071 | W10: =100*(AK10/AK$9) -> 101.11258 | X10: =100*(AL10/AL$9) -> 100.76934 | Y10: =100*(AM10/AM$9) -> 100.0921 | Z10: =100*(AN10/AN$9) -> 100.36343 | AA10: 100 | AC10: =100*(AP10/AP$9) -> 102.43388 | AD10: =100*(AQ10/AQ$9) -> 100.08052 | AE10: =100*(AR10/AR$9) -> 98.837947 | AF10: =100*(AS10/AS$9) -> 95.93841 | AG10: =100*(AT10/AT$9) -> 96.994319 | AH10: 100 | AJ10: =100*(AV10/BT10) -> 6.1908042 | AK10: =100*(AW10/BU10) -> 6.1783131 | AL10: =100*(AX10/BV10) -> 6.1757246 | AM10: =100*(AY10/BW10) -> 6.2157576 | AN10: =100*(AZ10/BX10) -> 6.1958343 | AP10: =100*(BB10/BT10) -> 1.4113756 | AQ10: =100*(BC10/BU10) -> 1.3726278 | AR10: =100*(BD10/BV10) -> 1.3755595 | AS10: =100*(BE10/BW10) -> 1.3571938 | AT10: =100*(BF10/BX10) -> 1.380755 | AV10: =BH10/(CF10/1000) -> 6.4286771 | AW10: =BI10/(CG10/1000) -> 6.2928926 | AX10: =BJ10/(CH10/1000) -> 6.3330478 | AY10: =BK10/(CI10/1000) -> 6.4280068 | AZ10: =BL10/(CJ10/1000) -> 6.3291723 | BB10: =BN10/(CF10/1000) -> 1.4656057 | BC10: =BO10/(CG10/1000) -> 1.3980838 | BD10: =BP10/(CH10/1000) -> 1.4106011 | BE10: =BQ10/(CI10/1000) -> 1.4035378 | BF10: =BR10/(CJ10/1000) -> 1.4104697 | BH10: 435.39391 | BI10: 430.32556 | BJ10: 435.84566 | BK10: 445.2619 | BL10: 440.03535 | BN10: 99.260827 | BO10: 95.604873 | BP10: 97.078752 | BQ10: 97.221725 | BR10: 98.062828 | BT10: =100*(BZ10/BZ$8) -> 103.84236 | BU10: =100*(CA10/CA$8) -> 101.85454 | BV10: =100*(CB10/CB$8) -> 102.54745 | BW10: =100*(CC10/CC$8) -> 103.4147 | BX10: =100*(CD10/CD$8) -> 102.15206 | BZ10: =OBR_MAR22_1.2!X118 -> 116.78782 | CA10: =OBR_NOV22_1.2!X123 -> 117.80967 | CB10: =OBR_MAR23_1.2!X123 -> 118.25344 | CC10: =OBR_NOV23_1.2!X128 -> 123.33389 | CD10: =OBR_MAR24_1.2!X128 -> 122.48522 | CF10: 67726.828 | CG10: 68382.791 | CH10: 68820.839 | CI10: 69269.047 | CJ10: 69524.944 | CL10: 2006 | CM10: =100*(Data!BS33/Data!$BW33) -> 1.814468 | CN10: =100*(Data!CL33/Data!$CP33) -> 1.814468 | CO10: 3 | CQ10: 2006 | CR10: =100*(Data!BQ33/Data!$BW33) -> -1.0067085 | CS10: =100*(Data!CJ33/Data!$CP33) -> -1.0067085 | CT10: 0 | CV10: 2006 | CW10: =CR10-DA10 -> -3.3480745 | CX10: =CS10-DB10 -> -3.3480745 | CY10: 0 | DA10: =Data!CF33 -> 2.341366 | DB10: =Data!CY33 -> 2.341366 | DD10: 2006 | DE10: =100*(Data!BO33/Data!BO$46) -> 85.047094 | DF10: =100*(Data!CH33/Data!CH$46) -> 85.047094 | DG10: =100*(Data!DA33/Data!DA$46) -> 85.047094 | DI10: =I10 -> 36.36195 | DJ10: =J10 -> 36.36195 | DK10: =100*(Data!DH33-$R10)/Data!DI33 -> 36.36195 | DM10: =CW10 -> -3.3480745 | DN10: =CX10 -> -3.3480745 | DO10: =(100*(Data!DC33/Data!$DI33))-Data!$DR33 -> -3.3480745 | DS10: 2013-14 | DT10: =100*(EI10/EI$20) -> 91.214232 | DU10: =100*(EJ10/EJ$20) -> 91.729503 | DV10: =100*(EK10/EK$20) -> 91.426616 | DW10: =100*(EL10/EL$20) -> 94.306273 | DX10: =100*(EM10/EM$20) -> 95.557909 | DY10: 100 | EA10: =100*(EO10/EO$20) -> 62.953306 | EB10: =100*(EP10/EP$20) -> 65.256755 | EC10: =100*(EQ10/EQ$20) -> 79.887075 | ED10: =100*(ER10/ER$20) -> 67.078482 | EE10: =100*(ES10/ES$20) -> 67.741493 | EF10: 100 | EH10: 2013-14 | EI10: 5177.8511 | EJ10: 5489.5117 | EK10: 5510.6499 | EL10: 5528.2162 | EM10: 5892.3547 | EO10: 828.95148 | EP10: 878.84699 | EQ10: 882.23112 | ER10: 885.04341 | ES10: 944.01278 | EU10: 2006 | EV10: =100*((EZ10-FA10)/Data!BX33*Data!BY33*0.01) -> -0.62266181 | EW10: =100*((FC10-FD10)/Data!CQ33*Data!CR33*0.01) -> -0.62266181 | EX10: 0 | EZ10: =Data!BU33*(Data!BX33*Data!BY33*0.01/Data!BW33)^1 -> 539810.92 | FA10: =(Data!BR33+Data!BT33)*(Data!BX33*Data!BY33*0.01/Data!BW33)^1 -> 554473 | FC10: =Data!CN33*(Data!CQ33*Data!CR33*0.01/Data!CP33)^1 -> 539810.92 | FD10: =(Data!CK33+Data!CM33)*(Data!CQ33*Data!CR33*0.01/Data!CP33)^1 -> 554473
A11: 2007 | B11: =100*(Data!BO34/Data!BO$46) -> 87.352728 | C11: =100*(Data!CH34/Data!CH$46) -> 87.352728 | D11: 100 | F11: =100*((C11/B11)-1) -> 0 | H11: 2007 | I11: =100*(O11/Data!$BW34) -> 36.846638 | J11: =100*(P11/Data!$CP34) -> 36.846638 | O11: =Data!BV34-$R11 -> 576700 | P11: =Data!CO34-$R11 -> 576700 | R11: ='GNDBTX ex BoE'!D127 -> -9500 | U11: 2026-27 | V11: =100*(AJ11/AJ$9) -> 103.22797 | W11: =100*(AK11/AK$9) -> 101.83027 | X11: =100*(AL11/AL$9) -> 101.55697 | Y11: =100*(AM11/AM$9) -> 100.70195 | Z11: =100*(AN11/AN$9) -> 100.87705 | AA11: 100 | AC11: =100*(AP11/AP$9) -> 103.96473 | AD11: =100*(AQ11/AQ$9) -> 99.012347 | AE11: =100*(AR11/AR$9) -> 97.711402 | AF11: =100*(AS11/AS$9) -> 94.338659 | AG11: =100*(AT11/AT$9) -> 95.127077 | AH11: 100 | AJ11: =100*(AV11/BT11) -> 6.2837726 | AK11: =100*(AW11/BU11) -> 6.2221663 | AL11: =100*(AX11/BV11) -> 6.2239951 | AM11: =100*(AY11/BW11) -> 6.2536295 | AN11: =100*(AZ11/BX11) -> 6.2275418 | AP11: =100*(BB11/BT11) -> 1.4324682 | AQ11: =100*(BC11/BU11) -> 1.3579776 | AR11: =100*(BD11/BV11) -> 1.359881 | AS11: =100*(BE11/BW11) -> 1.3345629 | AT11: =100*(BF11/BX11) -> 1.3541741 | AV11: =BH11/(CF11/1000) -> 6.6557745 | AW11: =BI11/(CG11/1000) -> 6.4147626 | AX11: =BJ11/(CH11/1000) -> 6.4590222 | AY11: =BK11/(CI11/1000) -> 6.5722539 | AZ11: =BL11/(CJ11/1000) -> 6.472483 | BB11: =BN11/(CF11/1000) -> 1.5172709 | BC11: =BO11/(CG11/1000) -> 1.4000114 | BD11: =BP11/(CH11/1000) -> 1.4112321 | BE11: =BQ11/(CI11/1000) -> 1.4025593 | BF11: =BR11/(CJ11/1000) -> 1.4074363 | BH11: 451.57825 | BI11: 439.94671 | BJ11: 446.15051 | BK11: 456.91761 | BL11: 452.28089 | BN11: 102.94317 | BO11: 96.017646 | BP11: 97.479447 | BQ11: 97.50902 | BR11: 98.348124 | BT11: =100*(BZ11/BZ$8) -> 105.92004 | BU11: =100*(CA11/CA$8) -> 103.09533 | BV11: =100*(CB11/CB$8) -> 103.77614 | BW11: =100*(CC11/CC$8) -> 105.09503 | BX11: =100*(CD11/CD$8) -> 103.93319 | BZ11: =OBR_MAR22_1.2!X119 -> 119.12452 | CA11: =OBR_NOV22_1.2!X124 -> 119.24482 | CB11: =OBR_MAR23_1.2!X124 -> 119.67032 | CC11: =OBR_NOV23_1.2!X129 -> 125.33789 | CD11: =OBR_MAR24_1.2!X129 -> 124.62088 | CF11: 67847.589 | CG11: 68583.475 | CH11: 69074.002 | CI11: 69522.21 | CJ11: 69877.494 | CL11: 2007 | CM11: =100*(Data!BS34/Data!$BW34) -> 1.7932627 | CN11: =100*(Data!CL34/Data!$CP34) -> 1.7932627 | CO11: 3 | CQ11: 2007 | CR11: =100*(Data!BQ34/Data!$BW34) -> -1.1465457 | CS11: =100*(Data!CJ34/Data!$CP34) -> -1.1465457 | CT11: 0 | CV11: 2007 | CW11: =CR11-DA11 -> -3.2130627 | CX11: =CS11-DB11 -> -3.2130627 | CY11: 0 | DA11: =Data!CF34 -> 2.066517 | DB11: =Data!CY34 -> 2.066517 | DD11: 2007 | DE11: =100*(Data!BO34/Data!BO$46) -> 87.352728 | DF11: =100*(Data!CH34/Data!CH$46) -> 87.352728 | DG11: =100*(Data!DA34/Data!DA$46) -> 87.352728 | DI11: =I11 -> 36.846638 | DJ11: =J11 -> 36.846638 | DK11: =100*(Data!DH34-$R11)/Data!DI34 -> 36.846638 | DM11: =CW11 -> -3.2130627 | DN11: =CX11 -> -3.2130627 | DO11: =(100*(Data!DC34/Data!$DI34))-Data!$DR34 -> -3.2130627 | DS11: 2014-15 | DT11: =100*(EI11/EI$20) -> 90.185995 | DU11: =100*(EJ11/EJ$20) -> 90.696836 | DV11: =100*(EK11/EK$20) -> 90.397359 | DW11: =100*(EL11/EL$20) -> 93.164712 | DX11: =100*(EM11/EM$20) -> 94.289963 | DY11: 100 | EA11: =100*(EO11/EO$20) -> 66.999319 | EB11: =100*(EP11/EP$20) -> 69.451866 | EC11: =100*(EQ11/EQ$20) -> 85.022714 | ED11: =100*(ER11/ER$20) -> 71.329543 | EE11: =100*(ES11/ES$20) -> 72.034572 | EF11: 100 | EH11: 2014-15 | EI11: 5119.4824 | EJ11: 5427.7122 | EK11: 5448.6124 | EL11: 5461.2981 | EM11: 5814.1698 | EO11: 882.22824 | EP11: 935.34475 | EQ11: 938.94643 | ER11: 941.13253 | ES11: 1003.839 | EU11: 2007 | EV11: =100*((EZ11-FA11)/Data!BX34*Data!BY34*0.01) -> -0.74388266 | EW11: =100*((FC11-FD11)/Data!CQ34*Data!CR34*0.01) -> -0.74388266 | EX11: 0 | EZ11: =Data!BU34*(Data!BX34*Data!BY34*0.01/Data!BW34)^1 -> 570389.09 | FA11: =(Data!BR34+Data!BT34)*(Data!BX34*Data!BY34*0.01/Data!BW34)^1 -> 587905.9 | FC11: =Data!CN34*(Data!CQ34*Data!CR34*0.01/Data!CP34)^1 -> 570389.09 | FD11: =(Data!CK34+Data!CM34)*(Data!CQ34*Data!CR34*0.01/Data!CP34)^1 -> 587905.9
A12: 2008 | B12: =100*(Data!BO35/Data!BO$46) -> 85.284869 | C12: =100*(Data!CH35/Data!CH$46) -> 85.284869 | D12: 100 | F12: =100*((C12/B12)-1) -> 0 | H12: 2008 | I12: =100*(O12/Data!$BW35) -> 47.561554 | J12: =100*(P12/Data!$CP35) -> 47.561554 | O12: =Data!BV35-$R12 -> 752800 | P12: =Data!CO35-$R12 -> 752800 | R12: ='GNDBTX ex BoE'!D128 -> 34400 | U12: 2027-28 | W12: =100*(AK12/AK$9) -> 102.64759 | X12: =100*(AL12/AL$9) -> 102.41965 | Y12: =100*(AM12/AM$9) -> 101.42685 | Z12: =100*(AN12/AN$9) -> 101.39982 | AA12: 100 | AD12: =100*(AQ12/AQ$9) -> 97.184404 | AE12: =100*(AR12/AR$9) -> 95.945409 | AF12: =100*(AS12/AS$9) -> 92.467929 | AG12: =100*(AT12/AT$9) -> 92.88519 | AH12: 100 | AK12: =100*(AW12/BU12) -> 6.2721077 | AL12: =100*(AX12/BV12) -> 6.2768653 | AM12: =100*(AY12/BW12) -> 6.2986462 | AN12: =100*(AZ12/BX12) -> 6.2598142 | AQ12: =100*(BC12/BU12) -> 1.3329069 | AR12: =100*(BD12/BV12) -> 1.3353031 | AS12: =100*(BE12/BW12) -> 1.3080986 | AT12: =100*(BF12/BX12) -> 1.3222599 | AW12: =BI12/(CG12/1000) -> 6.5824047 | AX12: =BJ12/(CH12/1000) -> 6.6215131 | AY12: =BK12/(CI12/1000) -> 6.7370087 | AZ12: =BL12/(CJ12/1000) -> 6.6278684 | BC12: =BO12/(CG12/1000) -> 1.3988492 | BD12: =BP12/(CH12/1000) -> 1.4086214 | BE12: =BQ12/(CI12/1000) -> 1.3991374 | BF12: =BR12/(CJ12/1000) -> 1.4000039 | BI12: 452.66747 | BJ12: 458.91766 | BK12: 469.9419 | BL12: 465.55777 | BO12: 96.197899 | BP12: 97.627423 | BQ12: 97.597216 | BR12: 98.339717 | BU12: =100*(CA12/CA$8) -> 104.94725 | BV12: =100*(CB12/CB$8) -> 105.49076 | BW12: =100*(CC12/CC$8) -> 106.95963 | BX12: =100*(CD12/CD$8) -> 105.87963 | CA12: =OBR_NOV22_1.2!X125 -> 121.38684 | CB12: =OBR_MAR23_1.2!X125 -> 121.64755 | CC12: =OBR_NOV23_1.2!X130 -> 127.56164 | CD12: =OBR_MAR24_1.2!X130 -> 126.95476 | CG12: 68769.315 | CH12: 69307.068 | CI12: 69755.276 | CJ12: 70242.459 | CL12: 2008 | CM12: =100*(Data!BS35/Data!$BW35) -> 3.0057032 | CN12: =100*(Data!CL35/Data!$CP35) -> 3.0057032 | CO12: 3 | CQ12: 2008 | CR12: =100*(Data!BQ35/Data!$BW35) -> -4.4357088 | CS12: =100*(Data!CJ35/Data!$CP35) -> -4.4357088 | CT12: 0 | CV12: 2008 | CW12: =CR12-DA12 -> 0.11064718 | CX12: =CS12-DB12 -> 0.11064718 | CY12: 0 | DA12: =Data!CF35 -> -4.546356 | DB12: =Data!CY35 -> -4.546356 | DD12: 2008 | DE12: =100*(Data!BO35/Data!BO$46) -> 85.284869 | DF12: =100*(Data!CH35/Data!CH$46) -> 85.284869 | DG12: =100*(Data!DA35/Data!DA$46) -> 85.284869 | DI12: =I12 -> 47.561554 | DJ12: =J12 -> 47.561554 | DK12: =100*(Data!DH35-$R12)/Data!DI35 -> 47.561554 | DM12: =CW12 -> 0.11064718 | DN12: =CX12 -> 0.11064718 | DO12: =(100*(Data!DC35/Data!$DI35))-Data!$DR35 -> 0.11064718 | DS12: 2015-16 | DT12: =100*(EI12/EI$20) -> 88.493824 | DU12: =100*(EJ12/EJ$20) -> 88.876336 | DV12: =100*(EK12/EK$20) -> 88.58287 | DW12: =100*(EL12/EL$20) -> 91.317221 | DX12: =100*(EM12/EM$20) -> 92.40396 | DY12: 100 | EA12: =100*(EO12/EO$20) -> 63.589313 | EB12: =100*(EP12/EP$20) -> 65.829084 | EC12: =100*(EQ12/EQ$20) -> 80.587718 | ED12: =100*(ER12/ER$20) -> 67.625512 | EE12: =100*(ES12/ES$20) -> 68.29393 | EF12: 100 | EH12: 2015-16 | EI12: 5023.4249 | EJ12: 5318.7652 | EK12: 5339.2459 | EL12: 5352.9985 | EM12: 5697.8739 | EO12: 837.32625 | EP12: 886.55485 | EQ12: 889.96866 | ER12: 892.261 | ES12: 951.71127 | EU12: 2008 | EV12: =100*((EZ12-FA12)/Data!BX35*Data!BY35*0.01) -> -3.0888948 | EW12: =100*((FC12-FD12)/Data!CQ35*Data!CR35*0.01) -> -3.0888948 | EX12: 0 | EZ12: =Data!BU35*(Data!BX35*Data!BY35*0.01/Data!BW35)^1 -> 578702.88 | FA12: =(Data!BR35+Data!BT35)*(Data!BX35*Data!BY35*0.01/Data!BW35)^1 -> 649965.95 | FC12: =Data!CN35*(Data!CQ35*Data!CR35*0.01/Data!CP35)^1 -> 578702.88 | FD12: =(Data!CK35+Data!CM35)*(Data!CQ35*Data!CR35*0.01/Data!CP35)^1 -> 649965.95
A13: 2009 | B13: =100*(Data!BO36/Data!BO$46) -> 82.821167 | C13: =100*(Data!CH36/Data!CH$46) -> 82.821167 | D13: 100 | F13: =100*((C13/B13)-1) -> 0 | H13: 2009 | I13: =100*(O13/Data!$BW36) -> 60.590075 | J13: =100*(P13/Data!$CP36) -> 60.590075 | O13: =Data!BV36-$R13 -> 944100 | P13: =Data!CO36-$R13 -> 944100 | R13: ='GNDBTX ex BoE'!D129 -> 83800 | U13: 2028-29 | Y13: =100*(AM13/AM$9) -> 102.13089 | Z13: =100*(AN13/AN$9) -> 101.85455 | AA13: 100 | AF13: =100*(AS13/AS$9) -> 90.249216 | AG13: =100*(AT13/AT$9) -> 89.74839 | AH13: 100 | AM13: =100*(AY13/BW13) -> 6.3423672 | AN13: =100*(AZ13/BX13) -> 6.2878867 | AS13: =100*(BE13/BW13) -> 1.2767115 | AT13: =100*(BF13/BX13) -> 1.2776062 | AY13: =BK13/(CI13/1000) -> 6.9113577 | AZ13: =BL13/(CJ13/1000) -> 6.7862634 | BE13: =BQ13/(CI13/1000) -> 1.3912487 | BF13: =BR13/(CJ13/1000) -> 1.378869 | BK13: 483.64675 | BL13: 479.15889 | BQ13: 97.357557 | BR13: 97.358047 | BW13: =100*(CC13/CC$8) -> 108.97126 | BX13: =100*(CD13/CD$8) -> 107.92598 | CC13: =OBR_NOV23_1.2!X131 -> 129.96074 | CD13: =OBR_MAR24_1.2!X131 -> 129.40843 | CI13: 69978.545 | CJ13: 70607.176 | CL13: 2009 | CM13: =100*(Data!BS36/Data!$BW36) -> 3.000688 | CN13: =100*(Data!CL36/Data!$CP36) -> 3.000688 | CO13: 3 | CQ13: 2009 | CR13: =100*(Data!BQ36/Data!$BW36) -> -7.3260017 | CS13: =100*(Data!CJ36/Data!$CP36) -> -7.3260017 | CT13: 0 | CV13: 2009 | CW13: =CR13-DA13 -> -3.1070417 | CX13: =CS13-DB13 -> -3.1070417 | CY13: 0 | DA13: =Data!CF36 -> -4.21896 | DB13: =Data!CY36 -> -4.21896 | DD13: 2009 | DE13: =100*(Data!BO36/Data!BO$46) -> 82.821167 | DF13: =100*(Data!CH36/Data!CH$46) -> 82.821167 | DG13: =100*(Data!DA36/Data!DA$46) -> 82.821167 | DI13: =I13 -> 60.590075 | DJ13: =J13 -> 60.590075 | DK13: =100*(Data!DH36-$R13)/Data!DI36 -> 60.590075 | DM13: =CW13 -> -3.1070417 | DN13: =CX13 -> -3.1070417 | DO13: =(100*(Data!DC36/Data!$DI36))-Data!$DR36 -> -3.1070417 | DS13: 2016-17 | DT13: =100*(EI13/EI$20) -> 86.896166 | DU13: =100*(EJ13/EJ$20) -> 87.437668 | DV13: =100*(EK13/EK$20) -> 87.148953 | DW13: =100*(EL13/EL$20) -> 89.643912 | DX13: =100*(EM13/EM$20) -> 90.751464 | DY13: 100 | EA13: =100*(EO13/EO$20) -> 63.052092 | EB13: =100*(EP13/EP$20) -> 65.397019 | EC13: =100*(EQ13/EQ$20) -> 80.058785 | ED13: =100*(ER13/ER$20) -> 67.035737 | EE13: =100*(ES13/ES$20) -> 67.698326 | EF13: 100 | EH13: 2016-17 | EI13: 4932.7325 | EJ13: 5232.6688 | EK13: 5252.8179 | EL13: 5254.9094 | EM13: 5595.9765 | EO13: 830.25226 | EP13: 880.73599 | EQ13: 884.12739 | ER13: 884.47943 | ES13: 943.41122 | EU13: 2009 | EV13: =100*((EZ13-FA13)/Data!BX36*Data!BY36*0.01) -> -5.2406143 | EW13: =100*((FC13-FD13)/Data!CQ36*Data!CR36*0.01) -> -5.2406143 | EX13: 0 | EZ13: =Data!BU36*(Data!BX36*Data!BY36*0.01/Data!BW36)^1 -> 590368.18 | FA13: =(Data!BR36+Data!BT36)*(Data!BX36*Data!BY36*0.01/Data!BW36)^1 -> 710195.9 | FC13: =Data!CN36*(Data!CQ36*Data!CR36*0.01/Data!CP36)^1 -> 590368.18 | FD13: =(Data!CK36+Data!CM36)*(Data!CQ36*Data!CR36*0.01/Data!CP36)^1 -> 710195.9
A14: 2010 | B14: =100*(Data!BO37/Data!BO$46) -> 84.888308 | C14: =100*(Data!CH37/Data!CH$46) -> 84.888308 | D14: 100 | F14: =100*((C14/B14)-1) -> 0 | H14: 2010 | I14: =100*(O14/Data!$BW37) -> 70.398212 | J14: =100*(P14/Data!$CP37) -> 70.398212 | O14: =Data!BV37-$R14 -> 1145500 | P14: =Data!CO37-$R14 -> 1145500 | R14: ='GNDBTX ex BoE'!D130 -> 23200 | CL14: 2010 | CM14: =100*(Data!BS37/Data!$BW37) -> 2.4455927 | CN14: =100*(Data!CL37/Data!$CP37) -> 2.4455927 | CO14: 3 | CQ14: 2010 | CR14: =100*(Data!BQ37/Data!$BW37) -> -6.2858137 | CS14: =100*(Data!CJ37/Data!$CP37) -> -6.2858137 | CT14: 0 | CV14: 2010 | CW14: =CR14-DA14 -> -2.5273837 | CX14: =CS14-DB14 -> -2.5273837 | CY14: 0 | DA14: =Data!CF37 -> -3.75843 | DB14: =Data!CY37 -> -3.75843 | DD14: 2010 | DE14: =100*(Data!BO37/Data!BO$46) -> 84.888308 | DF14: =100*(Data!CH37/Data!CH$46) -> 84.888308 | DG14: =100*(Data!DA37/Data!DA$46) -> 84.888308 | DI14: =I14 -> 70.398212 | DJ14: =J14 -> 70.398212 | DK14: =100*(Data!DH37-$R14)/Data!DI37 -> 70.398212 | DM14: =CW14 -> -2.5273837 | DN14: =CX14 -> -2.5273837 | DO14: =(100*(Data!DC37/Data!$DI37))-Data!$DR37 -> -2.5273837 | DS14: 2017-18 | DT14: =100*(EI14/EI$20) -> 86.306349 | DU14: =100*(EJ14/EJ$20) -> 86.890298 | DV14: =100*(EK14/EK$20) -> 86.60339 | DW14: =100*(EL14/EL$20) -> 88.89911 | DX14: =100*(EM14/EM$20) -> 89.829709 | DY14: 100 | EA14: =100*(EO14/EO$20) -> 65.948945 | EB14: =100*(EP14/EP$20) -> 68.437934 | EC14: =100*(EQ14/EQ$20) -> 83.781463 | ED14: =100*(ER14/ER$20) -> 70.232475 | EE14: =100*(ES14/ES$20) -> 70.926661 | EF14: 100 | EH14: 2017-18 | EI14: 4899.2511 | EJ14: 5199.9116 | EK14: 5219.9347 | EL14: 5211.2493 | EM14: 5539.1387 | EO14: 868.39721 | EP14: 921.6896 | EQ14: 925.2387 | ER14: 926.65766 | ES14: 988.39974 | EU14: 2010 | EV14: =100*((EZ14-FA14)/Data!BX37*Data!BY37*0.01) -> -4.6676078 | EW14: =100*((FC14-FD14)/Data!CQ37*Data!CR37*0.01) -> -4.6676078 | EX14: 0 | EZ14: =Data!BU37*(Data!BX37*Data!BY37*0.01/Data!BW37)^1 -> 625002.14 | FA14: =(Data!BR37+Data!BT37)*(Data!BX37*Data!BY37*0.01/Data!BW37)^1 -> 731109.29 | FC14: =Data!CN37*(Data!CQ37*Data!CR37*0.01/Data!CP37)^1 -> 625002.14 | FD14: =(Data!CK37+Data!CM37)*(Data!CQ37*Data!CR37*0.01/Data!CP37)^1 -> 731109.29
A15: 2011 | B15: =100*(Data!BO38/Data!BO$46) -> 85.744862 | C15: =100*(Data!CH38/Data!CH$46) -> 85.744862 | D15: 100 | F15: =100*((C15/B15)-1) -> 0 | H15: 2011 | I15: =100*(O15/Data!$BW38) -> 74.897074 | J15: =100*(P15/Data!$CP38) -> 74.897074 | O15: =Data!BV38-$R15 -> 1252700 | P15: =Data!CO38-$R15 -> 1252700 | R15: ='GNDBTX ex BoE'!D131 -> 8500 | CL15: 2011 | CM15: =100*(Data!BS38/Data!$BW38) -> 1.8428614 | CN15: =100*(Data!CL38/Data!$CP38) -> 1.8428614 | CO15: 3 | CQ15: 2011 | CR15: =100*(Data!BQ38/Data!$BW38) -> -5.4081104 | CS15: =100*(Data!CJ38/Data!$CP38) -> -5.4081104 | CT15: 0 | CV15: 2011 | CW15: =CR15-DA15 -> -2.1343374 | CX15: =CS15-DB15 -> -2.1343374 | CY15: 0 | DA15: =Data!CF38 -> -3.273773 | DB15: =Data!CY38 -> -3.273773 | DD15: 2011 | DE15: =100*(Data!BO38/Data!BO$46) -> 85.744862 | DF15: =100*(Data!CH38/Data!CH$46) -> 85.744862 | DG15: =100*(Data!DA38/Data!DA$46) -> 85.744862 | DI15: =I15 -> 74.897074 | DJ15: =J15 -> 74.897074 | DK15: =100*(Data!DH38-$R15)/Data!DI38 -> 74.897074 | DM15: =CW15 -> -2.1343374 | DN15: =CX15 -> -2.1343374 | DO15: =(100*(Data!DC38/Data!$DI38))-Data!$DR38 -> -2.1343374 | DS15: 2018-19 | DT15: =100*(EI15/EI$20) -> 86.315066 | DU15: =100*(EJ15/EJ$20) -> 86.987854 | DV15: =100*(EK15/EK$20) -> 86.700624 | DW15: =100*(EL15/EL$20) -> 88.679068 | DX15: =100*(EM15/EM$20) -> 89.519645 | DY15: 100 | EA15: =100*(EO15/EO$20) -> 68.732334 | EB15: =100*(EP15/EP$20) -> 71.399242 | EC15: =100*(EQ15/EQ$20) -> 87.406685 | ED15: =100*(ER15/ER$20) -> 73.081639 | EE15: =100*(ES15/ES$20) -> 73.803986 | EF15: 100 | EH15: 2018-19 | EI15: 4899.7459 | EJ15: 5205.7498 | EK15: 5225.7953 | EL15: 5198.3505 | EM15: 5520.0193 | EO15: 905.0481 | EP15: 961.57109 | EQ15: 965.27376 | ER15: 964.24995 | ES15: 1028.4968 | EU15: 2011 | EV15: =100*((EZ15-FA15)/Data!BX38*Data!BY38*0.01) -> -4.1586588 | EW15: =100*((FC15-FD15)/Data!CQ38*Data!CR38*0.01) -> -4.1586588 | EX15: 0 | EZ15: =Data!BU38*(Data!BX38*Data!BY38*0.01/Data!BW38)^1 -> 645977.61 | FA15: =(Data!BR38+Data!BT38)*(Data!BX38*Data!BY38*0.01/Data!BW38)^1 -> 739571.55 | FC15: =Data!CN38*(Data!CQ38*Data!CR38*0.01/Data!CP38)^1 -> 645977.61 | FD15: =(Data!CK38+Data!CM38)*(Data!CQ38*Data!CR38*0.01/Data!CP38)^1 -> 739571.55
A16: 2012 | B16: =100*(Data!BO39/Data!BO$46) -> 86.945963 | C16: =100*(Data!CH39/Data!CH$46) -> 86.945963 | D16: 100 | F16: =100*((C16/B16)-1) -> 0 | H16: 2012 | I16: =100*(O16/Data!$BW39) -> 77.586077 | J16: =100*(P16/Data!$CP39) -> 77.586077 | O16: =Data!BV39-$R16 -> 1340000 | P16: =Data!CO39-$R16 -> 1340000 | R16: ='GNDBTX ex BoE'!D132 -> 26200 | V16: =V5-DT17 -> -1.1894328 | CL16: 2012 | CM16: =100*(Data!BS39/Data!$BW39) -> 1.8779305 | CN16: =100*(Data!CL39/Data!$CP39) -> 1.8779305 | CO16: 3 | CQ16: 2012 | CR16: =100*(Data!BQ39/Data!$BW39) -> -5.3302214 | CS16: =100*(Data!CJ39/Data!$CP39) -> -5.3302214 | CT16: 0 | CV16: 2012 | CW16: =CR16-DA16 -> -1.2041494 | CX16: =CS16-DB16 -> -1.2041494 | CY16: 0 | DA16: =Data!CF39 -> -4.126072 | DB16: =Data!CY39 -> -4.126072 | DD16: 2012 | DE16: =100*(Data!BO39/Data!BO$46) -> 86.945963 | DF16: =100*(Data!CH39/Data!CH$46) -> 86.945963 | DG16: =100*(Data!DA39/Data!DA$46) -> 86.945963 | DI16: =I16 -> 77.586077 | DJ16: =J16 -> 77.586077 | DK16: =100*(Data!DH39-$R16)/Data!DI39 -> 77.586077 | DM16: =CW16 -> -1.2041494 | DN16: =CX16 -> -1.2041494 | DO16: =(100*(Data!DC39/Data!$DI39))-Data!$DR39 -> -1.2041494 | DS16: 2019-20 | DT16: =100*(EI16/EI$20) -> 90.213486 | DU16: =100*(EJ16/EJ$20) -> 90.712326 | DV16: =100*(EK16/EK$20) -> 90.412798 | DW16: =100*(EL16/EL$20) -> 92.725512 | DX16: =100*(EM16/EM$20) -> 93.503228 | DY16: 100 | EA16: =100*(EO16/EO$20) -> 70.119281 | EB16: =100*(EP16/EP$20) -> 72.676298 | EC16: =100*(EQ16/EQ$20) -> 88.970051 | ED16: =100*(ER16/ER$20) -> 74.548298 | EE16: =100*(ES16/ES$20) -> 75.285142 | EF16: 100 | EH16: 2019-20 | EI16: 5121.0429 | EJ16: 5428.6392 | EK16: 5449.543 | EL16: 5435.5523 | EM16: 5765.6577 | EO16: 923.31103 | EP16: 978.76987 | EQ16: 982.53876 | ER16: 983.60127 | ES16: 1049.1374 | EU16: 2012 | EV16: =100*((EZ16-FA16)/Data!BX39*Data!BY39*0.01) -> -4.250604 | EW16: =100*((FC16-FD16)/Data!CQ39*Data!CR39*0.01) -> -4.250604 | EX16: 0 | EZ16: =Data!BU39*(Data!BX39*Data!BY39*0.01/Data!BW39)^1 -> 661512.16 | FA16: =(Data!BR39+Data!BT39)*(Data!BX39*Data!BY39*0.01/Data!BW39)^1 -> 757323.47 | FC16: =Data!CN39*(Data!CQ39*Data!CR39*0.01/Data!CP39)^1 -> 661512.16 | FD16: =(Data!CK39+Data!CM39)*(Data!CQ39*Data!CR39*0.01/Data!CP39)^1 -> 757323.47
A17: 2013 | B17: =100*(Data!BO40/Data!BO$46) -> 88.966484 | C17: =100*(Data!CH40/Data!CH$46) -> 88.966484 | D17: 100 | F17: =100*((C17/B17)-1) -> 0 | H17: 2013 | I17: =100*(O17/Data!$BW40) -> 78.251214 | J17: =100*(P17/Data!$CP40) -> 78.251214 | O17: =Data!BV40-$R17 -> 1409500 | P17: =Data!CO40-$R17 -> 1409500 | R17: ='GNDBTX ex BoE'!D133 -> 51600 | V17: =V6-DT18 -> -0.6762853 | W17: =W6-DU18 -> 1.1633951 | X17: =X6-DV18 -> 0.85289492 | CL17: 2013 | CM17: =100*(Data!BS40/Data!$BW40) -> 1.4547675 | CN17: =100*(Data!CL40/Data!$CP40) -> 1.4547675 | CO17: 3 | CQ17: 2013 | CR17: =100*(Data!BQ40/Data!$BW40) -> -4.3294934 | CS17: =100*(Data!CJ40/Data!$CP40) -> -4.3294934 | CT17: 0 | CV17: 2013 | CW17: =CR17-DA17 -> -1.5670804 | CX17: =CS17-DB17 -> -1.5670804 | CY17: 0 | DA17: =Data!CF40 -> -2.762413 | DB17: =Data!CY40 -> -2.762413 | DD17: 2013 | DE17: =100*(Data!BO40/Data!BO$46) -> 88.966484 | DF17: =100*(Data!CH40/Data!CH$46) -> 88.966484 | DG17: =100*(Data!DA40/Data!DA$46) -> 88.966484 | DI17: =I17 -> 78.251214 | DJ17: =J17 -> 78.251214 | DK17: =100*(Data!DH40-$R17)/Data!DI40 -> 78.251214 | DM17: =CW17 -> -1.5670804 | DN17: =CX17 -> -1.5670804 | DO17: =(100*(Data!DC40/Data!$DI40))-Data!$DR40 -> -1.5670804 | DS17: 2020-21 | DT17: =100*(EI17/EI$20) -> 113.57468 | DU17: =100*(EJ17/EJ$20) -> 111.97582 | DV17: =100*(EK17/EK$20) -> 111.84845 | DW17: =100*(EL17/EL$20) -> 113.97779 | DX17: =100*(EM17/EM$20) -> 112.15508 | DY17: 100 | EA17: =100*(EO17/EO$20) -> 81.384706 | EB17: =100*(EP17/EP$20) -> 87.029466 | EC17: =100*(EQ17/EQ$20) -> 106.77252 | ED17: =100*(ER17/ER$20) -> 90.335461 | EE17: =100*(ES17/ES$20) -> 91.228347 | EF17: 100 | EH17: 2020-21 | EI17: 6447.1604 | EJ17: 6701.1436 | EK17: 6741.556 | EL17: 6681.3569 | EM17: 6915.7804 | EO17: 1071.651 | EP17: 1172.0715 | EQ17: 1179.1399 | ER17: 1191.8994 | ES17: 1271.3142 | EU17: 2013 | EV17: =100*((EZ17-FA17)/Data!BX40*Data!BY40*0.01) -> -3.5866227 | EW17: =100*((FC17-FD17)/Data!CQ40*Data!CR40*0.01) -> -3.5866227 | EX17: 0 | EZ17: =Data!BU40*(Data!BX40*Data!BY40*0.01/Data!BW40)^1 -> 684946.87 | FA17: =(Data!BR40+Data!BT40)*(Data!BX40*Data!BY40*0.01/Data!BW40)^1 -> 765565.65 | FC17: =Data!CN40*(Data!CQ40*Data!CR40*0.01/Data!CP40)^1 -> 684946.87 | FD17: =(Data!CK40+Data!CM40)*(Data!CQ40*Data!CR40*0.01/Data!CP40)^1 -> 765565.65
A18: 2014 | B18: =100*(Data!BO41/Data!BO$46) -> 91.704958 | C18: =100*(Data!CH41/Data!CH$46) -> 91.704958 | D18: 100 | F18: =100*((C18/B18)-1) -> 0 | H18: 2014 | I18: =100*(O18/Data!$BW41) -> 80.228388 | J18: =100*(P18/Data!$CP41) -> 80.228388 | O18: =Data!BV41-$R18 -> 1507700 | P18: =Data!CO41-$R18 -> 1507700 | R18: ='GNDBTX ex BoE'!D134 -> 45200 | V18: =V7-DT19 -> -0.64218983 | W18: =W7-DU19 -> 1.1352963 | X18: =X7-DV19 -> 0.87192324 | Y18: =Y7-DW19 -> 0.14702494 | Z18: =Z7-DX19 -> -0.10865682 | CL18: 2014 | CM18: =100*(Data!BS41/Data!$BW41) -> 1.9251727 | CN18: =100*(Data!CL41/Data!$CP41) -> 1.9251727 | CO18: 3 | CQ18: 2014 | CR18: =100*(Data!BQ41/Data!$BW41) -> -3.3486053 | CS18: =100*(Data!CJ41/Data!$CP41) -> -3.3486053 | CT18: 0 | CV18: 2014 | CW18: =CR18-DA18 -> -1.7708463 | CX18: =CS18-DB18 -> -1.7708463 | CY18: 0 | DA18: =Data!CF41 -> -1.577759 | DB18: =Data!CY41 -> -1.577759 | DD18: 2014 | DE18: =100*(Data!BO41/Data!BO$46) -> 91.704958 | DF18: =100*(Data!CH41/Data!CH$46) -> 91.704958 | DG18: =100*(Data!DA41/Data!DA$46) -> 91.704958 | DI18: =I18 -> 80.228388 | DJ18: =J18 -> 80.228388 | DK18: =100*(Data!DH41-$R18)/Data!DI41 -> 80.228388 | DM18: =CW18 -> -1.7708463 | DN18: =CX18 -> -1.7708463 | DO18: =(100*(Data!DC41/Data!$DI41))-Data!$DR41 -> -1.7708463 | DS18: 2021-22 | DT18: =100*(EI18/EI$20) -> 106.32143 | DU18: =100*(EJ18/EJ$20) -> 107.31795 | DV18: =100*(EK18/EK$20) -> 107.51169 | DW18: =100*(EL18/EL$20) -> 110.49503 | DX18: =100*(EM18/EM$20) -> 110.01328 | DY18: 100 | EA18: =100*(EO18/EO$20) -> 78.317265 | EB18: =100*(EP18/EP$20) -> 88.73404 | EC18: =100*(EQ18/EQ$20) -> 109.18451 | ED18: =100*(ER18/ER$20) -> 92.667949 | EE18: =100*(ES18/ES$20) -> 93.606097 | EF18: 100 | EH18: 2021-22 | EI18: 6035.4237 | EJ18: 6422.3956 | EK18: 6480.1623 | EL18: 6477.1981 | EM18: 6783.7111 | EO18: 1031.2598 | EP18: 1195.0279 | EQ18: 1205.7767 | ER18: 1222.6746 | ES18: 1304.4494 | EU18: 2014 | EV18: =100*((EZ18-FA18)/Data!BX41*Data!BY41*0.01) -> -2.8419416 | EW18: =100*((FC18-FD18)/Data!CQ41*Data!CR41*0.01) -> -2.8419416 | EX18: 0 | EZ18: =Data!BU41*(Data!BX41*Data!BY41*0.01/Data!BW41)^1 -> 701959.34 | FA18: =(Data!BR41+Data!BT41)*(Data!BX41*Data!BY41*0.01/Data!BW41)^1 -> 766045.55 | FC18: =Data!CN41*(Data!CQ41*Data!CR41*0.01/Data!CP41)^1 -> 701959.34 | FD18: =(Data!CK41+Data!CM41)*(Data!CQ41*Data!CR41*0.01/Data!CP41)^1 -> 766045.55
A19: 2015 | B19: =100*(Data!BO42/Data!BO$46) -> 93.577842 | C19: =100*(Data!CH42/Data!CH$46) -> 93.577842 | D19: 100 | F19: =100*((C19/B19)-1) -> 0 | H19: 2015 | I19: =100*(O19/Data!$BW42) -> 80.613303 | J19: =100*(P19/Data!$CP42) -> 80.613303 | O19: =Data!BV42-$R19 -> 1557000 | P19: =Data!CO42-$R19 -> 1557000 | R19: ='GNDBTX ex BoE'!D135 -> 42700 | V19: =V8-DT20 -> -0.62710491 | W19: =W8-DU20 -> 1.1059032 | X19: =X8-DV20 -> 0.83212605 | Y19: =Y8-DW20 -> 0.15211225 | Z19: =Z8-DX20 -> -0.11553016 | CL19: 2015 | CM19: =100*(Data!BS42/Data!$BW42) -> 1.669736 | CN19: =100*(Data!CL42/Data!$CP42) -> 1.669736 | CO19: 3 | CQ19: 2015 | CR19: =100*(Data!BQ42/Data!$BW42) -> -2.5887381 | CS19: =100*(Data!CJ42/Data!$CP42) -> -2.5887381 | CT19: 0 | CV19: 2015 | CW19: =CR19-DA19 -> -1.2133491 | CX19: =CS19-DB19 -> -1.2133491 | CY19: 0 | DA19: =Data!CF42 -> -1.375389 | DB19: =Data!CY42 -> -1.375389 | DD19: 2015 | DE19: =100*(Data!BO42/Data!BO$46) -> 93.577842 | DF19: =100*(Data!CH42/Data!CH$46) -> 93.577842 | DG19: =100*(Data!DA42/Data!DA$46) -> 93.577842 | DI19: =I19 -> 80.613303 | DJ19: =J19 -> 80.613303 | DK19: =100*(Data!DH42-$R19)/Data!DI42 -> 80.613303 | DM19: =CW19 -> -1.2133491 | DN19: =CX19 -> -1.2133491 | DO19: =(100*(Data!DC42/Data!$DI42))-Data!$DR42 -> -1.2133491 | DS19: 2022-23 | DT19: =100*(EI19/EI$20) -> 102.38696 | DU19: =100*(EJ19/EJ$20) -> 102.56541 | DV19: =100*(EK19/EK$20) -> 101.57363 | DW19: =100*(EL19/EL$20) -> 103.20223 | DX19: =100*(EM19/EM$20) -> 103.59736 | DY19: 100 | EA19: =100*(EO19/EO$20) -> 93.263013 | EB19: =100*(EP19/EP$20) -> 97.426011 | EC19: =100*(EQ19/EQ$20) -> 115.17148 | ED19: =100*(ER19/ER$20) -> 100.04159 | EE19: =100*(ES19/ES$20) -> 101.01867 | EF19: 100 | EH19: 2022-23 | EI19: 5812.0802 | EJ19: 6137.9817 | EK19: 6122.2512 | EL19: 6049.6958 | EM19: 6388.0887 | EO19: 1228.0612 | EP19: 1312.0873 | EQ19: 1271.8937 | ER19: 1319.9636 | ES19: 1407.7475 | EU19: 2015 | EV19: =100*((EZ19-FA19)/Data!BX42*Data!BY42*0.01) -> -2.228772 | EW19: =100*((FC19-FD19)/Data!CQ42*Data!CR42*0.01) -> -2.228772 | EX19: 0 | EZ19: =Data!BU42*(Data!BX42*Data!BY42*0.01/Data!BW42)^1 -> 723785 | FA19: =(Data!BR42+Data!BT42)*(Data!BX42*Data!BY42*0.01/Data!BW42)^1 -> 774468.87 | FC19: =Data!CN42*(Data!CQ42*Data!CR42*0.01/Data!CP42)^1 -> 723785 | FD19: =(Data!CK42+Data!CM42)*(Data!CQ42*Data!CR42*0.01/Data!CP42)^1 -> 774468.87
A20: 2016 | B20: =100*(Data!BO43/Data!BO$46) -> 95.492356 | C20: =100*(Data!CH43/Data!CH$46) -> 95.492356 | D20: 100 | F20: =100*((C20/B20)-1) -> 0 | H20: 2016 | I20: =100*(O20/Data!$BW43) -> 79.619375 | J20: =100*(P20/Data!$CP43) -> 79.619375 | O20: =Data!BV43-$R20 -> 1605000 | P20: =Data!CO43-$R20 -> 1605000 | R20: ='GNDBTX ex BoE'!D136 -> 113000 | V20: =V9-DT21 -> -0.63004636 | W20: =W9-DU21 -> 1.0919213 | X20: =X9-DV21 -> 0.82546009 | Y20: =Y9-DW21 -> 0.15577301 | Z20: =Z9-DX21 -> -0.10404915 | CL20: 2016 | CM20: =100*(Data!BS43/Data!$BW43) -> 1.8081783 | CN20: =100*(Data!CL43/Data!$CP43) -> 1.8081783 | CO20: 3 | CQ20: 2016 | CR20: =100*(Data!BQ43/Data!$BW43) -> -1.0794502 | CS20: =100*(Data!CJ43/Data!$CP43) -> -1.0794502 | CT20: 0 | CV20: 2016 | CW20: =CR20-DA20 -> -0.26176981 | CX20: =CS20-DB20 -> -0.26176981 | CY20: 0 | DA20: =Data!CF43 -> -0.8176804 | DB20: =Data!CY43 -> -0.8176804 | DD20: 2016 | DE20: =100*(Data!BO43/Data!BO$46) -> 95.492356 | DF20: =100*(Data!CH43/Data!CH$46) -> 95.492356 | DG20: =100*(Data!DA43/Data!DA$46) -> 95.492356 | DI20: =I20 -> 79.619375 | DJ20: =J20 -> 79.619375 | DK20: =100*(Data!DH43-$R20)/Data!DI43 -> 79.619375 | DM20: =CW20 -> -0.26176981 | DN20: =CX20 -> -0.26176981 | DO20: =(100*(Data!DC43/Data!$DI43))-Data!$DR43 -> -0.26176981 | DS20: 2023-24 | DT20: =100*(EI20/EI$20) -> 100 | DU20: =100*(EJ20/EJ$20) -> 100 | DV20: =100*(EK20/EK$20) -> 100 | DW20: =100*(EL20/EL$20) -> 100 | DX20: =100*(EM20/EM$20) -> 100 | DY20: 100 | EA20: =100*(EO20/EO$20) -> 100 | EB20: =100*(EP20/EP$20) -> 100 | EC20: =100*(EQ20/EQ$20) -> 100 | ED20: =100*(ER20/ER$20) -> 100 | EE20: =100*(ES20/ES$20) -> 100 | EF20: 100 | EH20: 2023-24 | EI20: 5676.5825 | EJ20: 5984.456 | EK20: 6027.4022 | EL20: 5861.9814 | EM20: 6166.2659 | EO20: 1316.772 | EP20: 1346.7525 | EQ20: 1104.3477 | ER20: 1319.4148 | ES20: 1393.5518 | EU20: 2016 | EV20: =100*((EZ20-FA20)/Data!BX43*Data!BY43*0.01) -> -0.97210959 | EW20: =100*((FC20-FD20)/Data!CQ43*Data!CR43*0.01) -> -0.97210959 | EX20: 0 | EZ20: =Data!BU43*(Data!BX43*Data!BY43*0.01/Data!BW43)^1 -> 763326.22 | FA20: =(Data!BR43+Data!BT43)*(Data!BX43*Data!BY43*0.01/Data!BW43)^1 -> 785317.42 | FC20: =Data!CN43*(Data!CQ43*Data!CR43*0.01/Data!CP43)^1 -> 763326.22 | FD20: =(Data!CK43+Data!CM43)*(Data!CQ43*Data!CR43*0.01/Data!CP43)^1 -> 785317.42
A21: 2017 | B21: =100*(Data!BO44/Data!BO$46) -> 97.939198 | C21: =100*(Data!CH44/Data!CH$46) -> 97.939198 | D21: 100 | F21: =100*((C21/B21)-1) -> 0 | H21: 2017 | I21: =100*(O21/Data!$BW44) -> 75.096842 | J21: =100*(P21/Data!$CP44) -> 75.096842 | O21: =Data!BV44-$R21 -> 1576900 | P21: =Data!CO44-$R21 -> 1576900 | R21: ='GNDBTX ex BoE'!D137 -> 180400 | V21: =V10-DT22 -> -0.64054795 | W21: =W10-DU22 -> 1.1057325 | X21: =X10-DV22 -> 0.83243957 | Y21: =Y10-DW22 -> 0.15521239 | Z21: =Z10-DX22 -> -0.1054679 | CL21: 2017 | CM21: =100*(Data!BS44/Data!$BW44) -> 2.2078538 | CN21: =100*(Data!CL44/Data!$CP44) -> 2.2078538 | CO21: 3 | CQ21: 2017 | CR21: =100*(Data!BQ44/Data!$BW44) -> -0.66162746 | CS21: =100*(Data!CJ44/Data!$CP44) -> -0.66162746 | CT21: 0 | CV21: 2017 | CW21: =CR21-DA21 -> -0.80048246 | CX21: =CS21-DB21 -> -0.80048246 | CY21: 0 | DA21: =Data!CF44 -> 0.138855 | DB21: =Data!CY44 -> 0.138855 | DD21: 2017 | DE21: =100*(Data!BO44/Data!BO$46) -> 97.939198 | DF21: =100*(Data!CH44/Data!CH$46) -> 97.939198 | DG21: =100*(Data!DA44/Data!DA$46) -> 97.939198 | DI21: =I21 -> 75.096842 | DJ21: =J21 -> 75.096842 | DK21: =100*(Data!DH44-$R21)/Data!DI44 -> 75.096842 | DM21: =CW21 -> -0.80048246 | DN21: =CX21 -> -0.80048246 | DO21: =(100*(Data!DC44/Data!$DI44))-Data!$DR44 -> -0.80048246 | DS21: 2024-25 | DT21: =100*(EI21/EI$20) -> 100.63005 | DU21: =100*(EJ21/EJ$20) -> 98.908079 | DV21: =100*(EK21/EK$20) -> 99.17454 | DW21: =100*(EL21/EL$20) -> 99.844227 | DX21: =100*(EM21/EM$20) -> 100.10405 | DY21: 100 | EA21: =100*(EO21/EO$20) -> 98.192867 | EB21: =100*(EP21/EP$20) -> 98.652286 | EC21: =100*(EQ21/EQ$20) -> 122.91946 | ED21: =100*(ER21/ER$20) -> 101.05112 | EE21: =100*(ES21/ES$20) -> 102.14023 | EF21: 100 | EH21: 2024-25 | EI21: 5712.3476 | EJ21: 5919.1104 | EK21: 5977.6484 | EL21: 5852.85 | EM21: 6172.6818 | EO21: 1292.9761 | EP21: 1328.6021 | EQ21: 1357.4583 | ER21: 1333.2834 | ES21: 1423.377 | EU21: 2017 | EV21: =100*((EZ21-FA21)/Data!BX44*Data!BY44*0.01) -> -0.61464397 | EW21: =100*((FC21-FD21)/Data!CQ44*Data!CR44*0.01) -> -0.61464397 | EX21: 0 | EZ21: =Data!BU44*(Data!BX44*Data!BY44*0.01/Data!BW44)^1 -> 779852.73 | FA21: =(Data!BR44+Data!BT44)*(Data!BX44*Data!BY44*0.01/Data!BW44)^1 -> 793738.21 | FC21: =Data!CN44*(Data!CQ44*Data!CR44*0.01/Data!CP44)^1 -> 779852.73 | FD21: =(Data!CK44+Data!CM44)*(Data!CQ44*Data!CR44*0.01/Data!CP44)^1 -> 793738.21
