Workbook
Name Annual_Data: '$template-default'!$A$1:$A$2

Sheet Chart Data
A1: Changes to PSNBX forecast | I1: Impact on tax revenues of income tax & NICs decisions | S1: Real government spending across fiscal events | BI1: Real government spending across fiscal events | DG1: Interest rates - gilts | DL1: Interest rates - market expectations | DR1: Interest rates - gilts | DV1: Interest rates - short rates
S2: Real PSCE in RDEL per head (2024-2025=100) | Z2: Real PSGI in RDEL per head (2024-2025=100) | AG2: Real PSCE in RDEL per head (2023-2024 prices) | AM2: Real PSGI in RDEL per head (2023-2024 prices) | AS2: PSCE in RDEL per head | AY2: PSGI in RDEL per head | BI2: Real PSCE in RDEL (2024-2025=100) | BP2: Real PSGI in RDEL (2024-2025=100) | BW2: Real PSCE in RDEL (2023-2024 prices) | CC2: Real PSGI in RDEL (2023-2024 prices) | CI2: PSCE in RDEL | CO2: PSGI in RDEL | CU2: GDP deflator (2023-2024 = 100) | DA2: GDP deflator (raw)
B3: 2023- 2024 | C3: 2024- 2025 | D3: 2025- 2026 | E3: 2026- 2027 | F3: 2027- 2028 | G3: 2028- 2029 | J3: =OBR_NOV23_T3.A!D6 -> 2022-23 | K3: =OBR_NOV23_T3.A!E6 -> 2023-24 | L3: =OBR_NOV23_T3.A!F6 -> 2024-25 | M3: =OBR_NOV23_T3.A!G6 -> 2025-26 | N3: =OBR_NOV23_T3.A!H6 -> 2026-27 | O3: =OBR_NOV23_T3.A!I6 -> 2027-28 | P3: =OBR_NOV23_T3.A!J6 -> 2028-29 | S3: 44621 | T3: 44866 | U3: 44986 | V3: 45231 | W3: 45352 | X3: 100 LINE | Z3: 44621 | AA3: 44866 | AB3: 44986 | AC3: 45231 | AD3: 45352 | AE3: 100 LINE | AG3: 44621 | AH3: 44866 | AI3: 44986 | AJ3: 45231 | AK3: 45352 | AM3: 44621 | AN3: 44866 | AO3: 44986 | AP3: 45231 | AQ3: 45352 | AS3: SS22 | AT3: AS22 | AU3: Budget23 | AV3: AS23 | AW3: Budget24 | AY3: SS22 | AZ3: AS22 | BA3: Budget23 | BB3: AS23 | BC3: Budget24 | BF3: Population | BI3: 44621 | BJ3: 44866 | BK3: 44986 | BL3: 45231 | BM3: 45352 | BN3: 100 LINE | BP3: 44621 | BQ3: 44866 | BR3: 44986 | BS3: 45231 | BT3: 45352 | BU3: 100 LINE | BW3: 44621 | BX3: 44866 | BY3: 44986 | BZ3: 45231 | CA3: 45352 | CC3: 44621 | CD3: 44866 | CE3: 44986 | CF3: 45231 | CG3: 45352 | CI3: SS22 | CJ3: AS22 | CK3: Budget23 | CL3: AS23 | CM3: Budget24 | CO3: SS22 | CP3: AS22 | CQ3: Budget23 | CR3: AS23 | CS3: Budget24 | CU3: SS22 | CV3: AS22 | CW3: Budget23 | CX3: AS23 | CY3: Budget24 | DA3: SS22 | DB3: AS22 | DC3: Budget23 | DD3: AS23 | DE3: Budget24 | DH3: Autumn Statement 2023 | DI3: Budget 24 | DJ3: 10 days to 5th March | DM3: AS 2023 | DN3: Budget 24 | DO3: 10 days to 5th March | DR3: OBR gilt | DS3: OE gilt | DT3: Impact | DV3: OBR RCB | DW3: OE RCB | DX3: Impact
A4: Underlying forecast changes | B4: =OBR_MAR24_T4.12!D11 -> -10.148123 | C4: =OBR_MAR24_T4.12!E11 -> -10.012101 | D4: =OBR_MAR24_T4.12!F11 -> -9.721845 | E4: =OBR_MAR24_T4.12!G11 -> -6.171292 | F4: =OBR_MAR24_T4.12!H11 -> -3.6160179 | G4: =OBR_MAR24_T4.12!I11 -> -0.77357379 | I4: Income tax threshold freezes | J4: =-SUM(OBR_MAR24_T3.8!C8:C9) -> 2.99 | K4: =-SUM(OBR_MAR24_T3.8!D8:D9) -> 13.99 | L4: =-SUM(OBR_MAR24_T3.8!E8:E9) -> 24.045 | M4: =-SUM(OBR_MAR24_T3.8!F8:F9) -> 27.86 | N4: =-SUM(OBR_MAR24_T3.8!G8:G9) -> 30.205 | O4: =-SUM(OBR_MAR24_T3.8!H8:H9) -> 33.16 | P4: =-SUM(OBR_MAR24_T3.8!I8:I9) -> 34.555 | R4: 2019-20 | S4: =100*(AG4/AG$9) -> 90.373881 | X4: 100 | Z4: =100*(AM4/AM$9) -> 71.911288 | AE4: 100 | AG4: =100*(AS4/CU4) -> 5.3545791 | AM4: =100*(AY4/CU4) -> 0.9643959 | AS4: =CI4/($BF4/1000) -> 4.7966918 | AY4: =CO4/($BF4/1000) -> 0.86391662 | BE4: 202001 | BF4: =VLOOKUP(BE4,Data!$A$7:$C$318,3,FALSE) -> 67010 | BH4: 2019-20 | BI4: =100*(BW4/BW$9) -> 87.201559 | BN4: 100 | BP4: =100*(CC4/CC$9) -> 69.387043 | BU4: 100 | BW4: =100*(CI4/CU4) -> 358.81034 | CC4: =100*(CO4/CU4) -> 64.624169 | CI4: {=TRANSPOSE(OBR_MAR22_T3.16!C8:J8)} -> 321.42632 | CO4: {=TRANSPOSE(OBR_MAR22_T3.16!C31:J31)} -> 57.891053 | CU4: =100*(DA4/DA$8) -> 89.581117 | CV4: =100*(DB4/DB$8) -> 87.221869 | CW4: =100*(DC4/DC$8) -> 87.485684 | CX4: =100*(DD4/DD$8) -> 84.464903 | CY4: =100*(DE4/DE$8) -> 84.011728 | DA4: =OBR_MAR22_1.2!X112 -> 100.74871 | DB4: =OBR_NOV22_1.2!X117 -> 100.88484 | DC4: =OBR_MAR23_1.2!X117 -> 100.88484 | DD4: =OBR_NOV23_1.2!X122 -> 100.73409 | DE4: =OBR_MAR24_1.2!X122 -> 100.73409 | DG4: 2 | DH4: {=TRANSPOSE(HAVERD!B318:G318)} -> 4.8863636 | DI4: {=TRANSPOSE(HAVERD!B319:G319)} -> 4.2618182 | DJ4: {=TRANSPOSE(HAVERD!B321:G321)} -> 4.358 | DL4: 2024 | DM4: {=TRANSPOSE(HAVERD!H318:L318)} -> 5.1774546 | DN4: {=TRANSPOSE(HAVERD!H319:L319)} -> 4.0490152 | DO4: {=TRANSPOSE(HAVERD!H321:L321)} -> 4.4681172 | DQ4: FY2022/23 | DR4: 3.1333693 | DS4: =DR4 -> 3.1333693 | DV4: 2.30915 | DW4: =AVERAGE([2]CSV!AG207:AG210) -> 2.3120337
A5: Policy decisions - NICs cut | B5: =OBR_MAR24_T4.12!D21 -> 0 | C5: =OBR_MAR24_T4.12!E21 -> 10.196025 | D5: =OBR_MAR24_T4.12!F21 -> 10.329817 | E5: =OBR_MAR24_T4.12!G21 -> 10.465234 | F5: =OBR_MAR24_T4.12!H21 -> 10.705217 | G5: =OBR_MAR24_T4.12!I21 -> 11.037294 | I5: NICs threshold freezes | J5: =-SUM(OBR_MAR24_T3.8!C10:C12) -> -6.72 | K5: =-SUM(OBR_MAR24_T3.8!D10:D12) -> -2.12 | L5: =-SUM(OBR_MAR24_T3.8!E10:E12) -> 2.66 | M5: =-SUM(OBR_MAR24_T3.8!F10:F12) -> 4.105 | N5: =-SUM(OBR_MAR24_T3.8!G10:G12) -> 5.145 | O5: =-SUM(OBR_MAR24_T3.8!H10:H12) -> 6.34 | P5: =-SUM(OBR_MAR24_T3.8!I10:I12) -> 6.57 | R5: 2020-21 | S5: =100*(AG5/AG$9) -> 115.53143 | X5: 100 | Z5: =100*(AM5/AM$9) -> 85.311714 | AE5: 100 | AG5: =100*(AS5/CU5) -> 6.8451431 | AM5: =100*(AY5/CU5) -> 1.1441078 | AS5: =CI5/($BF5/1000) -> 6.4814935 | AY5: =CO5/($BF5/1000) -> 1.0833269 | BE5: =+BE4+100 -> 202101 | BF5: =VLOOKUP(BE5,Data!$A$7:$C$318,3,FALSE) -> 67039.75 | BH5: 2020-21 | BI5: =100*(BW5/BW$9) -> 111.52551 | BN5: 100 | BP5: =100*(CC5/CC$9) -> 82.353631 | BU5: 100 | BW5: =100*(CI5/CU5) -> 458.89668 | CC5: =100*(CO5/CU5) -> 76.700702 | CI5: 434.5177 | CO5: 72.625962 | CU5: =100*(DA5/DA$8) -> 94.68748 | CV5: =100*(DB5/DB$8) -> 92.72465 | CW5: =100*(DC5/DC$8) -> 92.876405 | CX5: =100*(DD5/DD$8) -> 88.965576 | CY5: =100*(DE5/DE$8) -> 88.488253 | DA5: =OBR_MAR22_1.2!X113 -> 106.49166 | DB5: =OBR_NOV22_1.2!X118 -> 107.24961 | DC5: =OBR_MAR23_1.2!X118 -> 107.10119 | DD5: =OBR_NOV23_1.2!X123 -> 106.10166 | DE5: =OBR_MAR24_1.2!X123 -> 106.10166 | DG5: 5 | DH5: 4.5309091 | DI5: 3.7881818 | DJ5: 4.065 | DL5: 2025 | DM5: 4.5591652 | DN5: 3.3800845 | DO5: 3.8999436 | DQ5: FY2023/24 | DR5: 4.2044264 | DS5: =DR5+0.05 -> 4.2544264 | DT5: ='OBR RR Oct23 - Debt interest'!C8*(DS5-DR5) -> 55.397924 | DV5: 5.0075041 | DW5: =DV5 -> 5.0075041 | DX5: ='OBR RR Oct23 - Debt interest'!C13*(DW5-DV5) -> 0
A6: Policy decisions - other tax | B6: =OBR_MAR24_T4.12!D22+OBR_MAR24_T4.12!D23 -> 0.18808678 | C6: =OBR_MAR24_T4.12!E22+OBR_MAR24_T4.12!E23 -> 3.3254114 | D6: =OBR_MAR24_T4.12!F22+OBR_MAR24_T4.12!F23 -> -0.084666271 | E6: =OBR_MAR24_T4.12!G22+OBR_MAR24_T4.12!G23 -> -3.2535558 | F6: =OBR_MAR24_T4.12!H22+OBR_MAR24_T4.12!H23 -> -5.1248695 | G6: =OBR_MAR24_T4.12!I22+OBR_MAR24_T4.12!I23 -> -5.1179031 | I6: NICs rate cut (AS 23) | J6: =-OBR_MAR24_T3.8!C15 -> 0 | K6: =-OBR_MAR24_T3.8!D15 -> -2.3828955 | L6: =-OBR_MAR24_T3.8!E15 -> -9.9944842 | M6: =-OBR_MAR24_T3.8!F15 -> -10.141012 | N6: =-OBR_MAR24_T3.8!G15 -> -10.17163 | O6: =-OBR_MAR24_T3.8!H15 -> -10.385803 | P6: =-OBR_MAR24_T3.8!I15 -> -10.66816 | R6: 2021-22 | S6: =100*(AG6/AG$9) -> 107.90585 | T6: =100*(AH6/AH$9) -> 110.60751 | U6: =100*(AI6/AI$9) -> 109.75831 | X6: 100 | Z6: =100*(AM6/AM$9) -> 81.457188 | AA6: =100*(AN6/AN$9) -> 91.691086 | AB6: =100*(AO6/AO$9) -> 89.933662 | AE6: 100 | AG6: =100*(AS6/CU6) -> 6.3933339 | AH6: =100*(AT6/CV6) -> 6.6337119 | AI6: =100*(AU6/CW6) -> 6.6388806 | AM6: =100*(AY6/CU6) -> 1.0924151 | AN6: =100*(AZ6/CV6) -> 1.234348 | AO6: =100*(BA6/CW6) -> 1.2353097 | AS6: =CI6/($BF6/1000) -> 6.0001556 | AT6: =CJ6/($BF6/1000) -> 6.1295229 | AU6: =CK6/($BF6/1000) -> 6.1295229 | AY6: =CO6/($BF6/1000) -> 1.0252336 | AZ6: =CP6/($BF6/1000) -> 1.1405325 | BA6: =CQ6/($BF6/1000) -> 1.1405325 | BE6: =+BE5+100 -> 202201 | BF6: =VLOOKUP(BE6,Data!$A$7:$C$318,3,FALSE) -> 67502.88 | BH6: 2021-22 | BI6: =100*(BW6/BW$9) -> 104.88394 | BJ6: =100*(BX6/BX$9) -> 107.50994 | BK6: =100*(BY6/BY$9) -> 106.68452 | BN6: 100 | BP6: =100*(CC6/CC$9) -> 79.175973 | BQ6: =100*(CD6/CD$9) -> 89.123271 | BR6: =100*(CE6/CE$9) -> 87.415063 | BU6: 100 | BW6: =100*(CI6/CU6) -> 431.56845 | BX6: =100*(CJ6/CV6) -> 447.79466 | BY6: =100*(CK6/CW6) -> 448.14356 | CC6: =100*(CO6/CU6) -> 73.741166 | CD6: =100*(CP6/CV6) -> 83.322042 | CE6: =100*(CQ6/CW6) -> 83.386964 | CI6: 405.02778 | CJ6: {=TRANSPOSE(OBR_NOV22_TA.8!C8:I8)} -> 413.76045 | CK6: {=TRANSPOSE(OBR_MAR23_TA.7!D8:J8)} -> 413.76045 | CO6: 69.20622 | CP6: {=TRANSPOSE(OBR_NOV22_TA.8!C30:I30)} -> 76.989229 | CQ6: {=TRANSPOSE(OBR_MAR23_TA.7!D32:J32)} -> 76.989229 | CU6: =100*(DA6/DA$8) -> 93.850184 | CV6: =100*(DB6/DB$8) -> 92.399594 | CW6: =100*(DC6/DC$8) -> 92.327656 | CX6: =100*(DD6/DD$8) -> 88.374124 | CY6: =100*(DE6/DE$8) -> 87.880815 | DA6: =OBR_MAR22_1.2!X114 -> 105.54998 | DB6: =OBR_NOV22_1.2!X119 -> 106.87364 | DC6: =OBR_MAR23_1.2!X119 -> 106.4684 | DD6: =OBR_NOV23_1.2!X124 -> 105.39629 | DE6: =OBR_MAR24_1.2!X124 -> 105.37331 | DG6: 10 | DH6: 4.4927273 | DI6: 3.8763636 | DJ6: 4.12 | DL6: 2026 | DM6: 4.2005259 | DN6: 3.2100345 | DO6: 3.6148366 | DQ6: FY2024/25 | DR6: 3.8713343 | DS6: =DR6+0.05 -> 3.9213343 | DT6: ='OBR RR Oct23 - Debt interest'!D9*(DS6-DR6)+'OBR RR Oct23 - Debt interest'!D8*(DS5-DR5) -> 167.11496 | DV6: 4.3665594 | DW6: =DV6+(DO4-DN4) -> 4.7856613 | DX6: ='OBR RR Oct23 - Debt interest'!D14*(DW6-DV6)+'OBR RR Oct23 - Debt interest'!D13*(DW5-DV5) -> 4172.2539 | DZ6: =DX6+DT6 -> 4339.3688
A7: Policy decisions - spending | B7: =OBR_MAR24_T4.12!D24 -> -0.13021465 | C7: =OBR_MAR24_T4.12!E24 -> 0.3781002 | D7: =OBR_MAR24_T4.12!F24 -> -0.1288523 | E7: =OBR_MAR24_T4.12!G24 -> 0.47131558 | F7: =OBR_MAR24_T4.12!H24 -> 0.7581139 | G7: =OBR_MAR24_T4.12!I24 -> 0.017641508 | I7: NICs rate cut (Budget 24) | J7: =-OBR_MAR24_T3.8!C16 -> 0 | K7: =-OBR_MAR24_T3.8!D16 -> 0 | L7: =-OBR_MAR24_T3.8!E16 -> -10.070957 | M7: =-OBR_MAR24_T3.8!F16 -> -10.145467 | N7: =-OBR_MAR24_T3.8!G16 -> -10.226379 | O7: =-OBR_MAR24_T3.8!H16 -> -10.44633 | P7: =-OBR_MAR24_T3.8!I16 -> -10.749149 | R7: 2022-23 | S7: =100*(AG7/AG$9) -> 103.17708 | T7: =100*(AH7/AH$9) -> 104.89353 | U7: =100*(AI7/AI$9) -> 103.31983 | V7: =100*(AJ7/AJ$9) -> 103.83787 | W7: =100*(AK7/AK$9) -> 103.61763 | X7: 100 | Z7: =100*(AM7/AM$9) -> 96.315408 | AA7: =100*(AN7/AN$9) -> 99.895826 | AB7: =100*(AO7/AO$9) -> 94.520759 | AC7: =100*(AP7/AP$9) -> 99.455563 | AD7: =100*(AQ7/AQ$9) -> 99.024219 | AE7: 100 | AG7: =100*(AS7/CU7) -> 6.1131583 | AH7: =100*(AT7/CV7) -> 6.2910147 | AI7: =100*(AU7/CW7) -> 6.2494401 | AJ7: =100*(AV7/CX7) -> 6.4037004 | AK7: =100*(AW7/CY7) -> 6.3681662 | AM7: =100*(AY7/CU7) -> 1.2916774 | AN7: =100*(AZ7/CV7) -> 1.3448004 | AO7: =100*(BA7/CW7) -> 1.2983171 | AP7: =100*(BB7/CX7) -> 1.3972027 | AQ7: =100*(BC7/CY7) -> 1.4033571 | AS7: =CI7/($BF7/1000) -> 5.9692921 | AT7: =CJ7/($BF7/1000) -> 6.0939635 | AU7: =CK7/($BF7/1000) -> 6.0939603 | AV7: =CL7/($BF7/1000) -> 6.0361903 | AW7: =CM7/($BF7/1000) -> 5.9763705 | AY7: =CO7/($BF7/1000) -> 1.2612792 | AZ7: =CP7/($BF7/1000) -> 1.3026777 | BA7: =CQ7/($BF7/1000) -> 1.2660163 | BB7: =CR7/($BF7/1000) -> 1.3170169 | BC7: =CS7/($BF7/1000) -> 1.3170169 | BE7: =+BE6+100 -> 202301 | BF7: =VLOOKUP(BE7,Data!$A$7:$C$318,3,FALSE) -> 68178.12 | BH7: 2022-23 | BI7: =100*(BW7/BW$9) -> 101.29079 | BJ7: =100*(BX7/BX$9) -> 102.97586 | BK7: =100*(BY7/BY$9) -> 101.43092 | BL7: =100*(BZ7/BZ$9) -> 101.93949 | BM7: =100*(CA7/CA$9) -> 101.72329 | BN7: 100 | BP7: =100*(CC7/CC$9) -> 94.554562 | BQ7: =100*(CD7/CD$9) -> 98.069522 | BR7: =100*(CE7/CE$9) -> 92.792723 | BS7: =100*(CF7/CF$9) -> 97.637308 | BT7: =100*(CG7/CG$9) -> 97.21385 | BU7: 100 | BW7: =100*(CI7/CU7) -> 416.78364 | BX7: =100*(CJ7/CV7) -> 428.90955 | BY7: =100*(CK7/CW7) -> 426.07508 | BZ7: =100*(CL7/CX7) -> 436.59226 | CA7: =100*(CM7/CY7) -> 434.1696 | CC7: =100*(CO7/CU7) -> 88.064136 | CD7: =100*(CP7/CV7) -> 91.685962 | CE7: =100*(CQ7/CW7) -> 88.51682 | CF7: =100*(CR7/CX7) -> 95.258654 | CG7: =100*(CS7/CY7) -> 95.678252 | CI7: 406.97511 | CJ7: 415.47497 | CK7: 415.47476 | CL7: {=TRANSPOSE(OBR_NOV23_TA.7!C8:I8)} -> 411.5361 | CM7: {=TRANSPOSE(OBR_MAR24_TA.7!C8:I8)} -> 407.4577 | CO7: 85.991647 | CP7: 88.814116 | CQ7: 86.31461 | CR7: {=TRANSPOSE(OBR_NOV23_TA.7!C32:I32)} -> 89.791733 | CS7: {=TRANSPOSE(OBR_MAR24_TA.7!C32:I32)} -> 89.791733 | CU7: =100*(DA7/DA$8) -> 97.646614 | CV7: =100*(DB7/DB$8) -> 96.867736 | CW7: =100*(DC7/DC$8) -> 97.5121 | CX7: =100*(DD7/DD$8) -> 94.260972 | CY7: =100*(DE7/DE$8) -> 93.847589 | DA7: =OBR_MAR22_1.2!X115 -> 109.81969 | DB7: =OBR_NOV22_1.2!X120 -> 112.0417 | DC7: =OBR_MAR23_1.2!X120 -> 112.44689 | DD7: =OBR_NOV23_1.2!X125 -> 112.41703 | DE7: =OBR_MAR24_1.2!X125 -> 112.52776 | DG7: 15 | DH7: 4.8027273 | DI7: 4.2445455 | DJ7: 4.415 | DL7: 2027 | DM7: 4.0434114 | DN7: 3.1959024 | DO7: 3.4910066 | DQ7: FY2025/26 | DR7: 3.9037698 | DS7: =DR7+0.05 -> 3.9537698 | DT7: ='OBR RR Oct23 - Debt interest'!E10*(DS7-DR7)+'OBR RR Oct23 - Debt interest'!E9*(DS6-DR6)+'OBR RR Oct23 - Debt interest'!E8*(DS5-DR5) -> 275.76327 | DV7: 3.4904092 | DW7: =DV7+(DO5-DN5) -> 4.0102683 | DX7: ='OBR RR Oct23 - Debt interest'!E15*(DW7-DV7)+'OBR RR Oct23 - Debt interest'!E14*(DW6-DV6) -> 4843.9166 | DZ7: =DX7+DT7 -> 5119.6799
A8: Other | B8: =OBR_MAR24_T4.12!D25 -> 0.26529421 | C8: =OBR_MAR24_T4.12!E25 -> -1.2311794 | D8: =OBR_MAR24_T4.12!F25 -> 0.25222169 | E8: =OBR_MAR24_T4.12!G25 -> -1.2566479 | F8: =OBR_MAR24_T4.12!H25 -> -1.2189023 | G8: =OBR_MAR24_T4.12!I25 -> -0.73269675 | I8: Total impact | J8: =SUM(J4:J7) -> -3.73 | K8: =SUM(K4:K7) -> 9.4871045 | L8: =SUM(L4:L7) -> 6.639559 | M8: =SUM(M4:M7) -> 11.678521 | N8: =SUM(N4:N7) -> 14.951991 | O8: =SUM(O4:O7) -> 18.667867 | P8: =SUM(P4:P7) -> 19.707692 | R8: 2023-24 | S8: =100*(AG8/AG$9) -> 100.02575 | T8: =100*(AH8/AH$9) -> 101.64064 | U8: =100*(AI8/AI$9) -> 101.26212 | V8: =100*(AJ8/AJ$9) -> 100.45562 | W8: =100*(AK8/AK$9) -> 99.957754 | X8: 100 | Z8: =100*(AM8/AM$9) -> 102.50842 | AA8: =100*(AN8/AN$9) -> 101.90418 | AB8: =100*(AO8/AO$9) -> 101.63336 | AC8: =100*(AP8/AP$9) -> 99.255834 | AD8: =100*(AQ8/AQ$9) -> 97.965078 | AE8: 100 | AG8: =100*(AS8/CU8) -> 5.9264446 | AH8: =100*(AT8/CV8) -> 6.0959215 | AI8: =100*(AU8/CW8) -> 6.124977 | AJ8: =100*(AV8/CX8) -> 6.1951164 | AK8: =100*(AW8/CY8) -> 6.1432362 | AM8: =100*(AY8/CU8) -> 1.3747314 | AN8: =100*(AZ8/CV8) -> 1.3718369 | AO8: =100*(BA8/CW8) -> 1.3960143 | AP8: =100*(BB8/CX8) -> 1.3943968 | AQ8: =100*(BC8/CY8) -> 1.3883471 | AS8: =CI8/($BF8/1000) -> 5.9264446 | AT8: =CJ8/($BF8/1000) -> 6.0959215 | AU8: =CK8/($BF8/1000) -> 6.124977 | AV8: =CL8/($BF8/1000) -> 6.1951164 | AW8: =CM8/($BF8/1000) -> 6.1432362 | AY8: =CO8/($BF8/1000) -> 1.3747314 | AZ8: =CP8/($BF8/1000) -> 1.3718369 | BA8: =CQ8/($BF8/1000) -> 1.3960143 | BB8: =CR8/($BF8/1000) -> 1.3943968 | BC8: =CS8/($BF8/1000) -> 1.3883471 | BE8: =+BE7+100 -> 202401 | BF8: =VLOOKUP(BE8,Data!$A$7:$C$318,3,FALSE) -> 68847.18 | BH8: 2023-24 | BI8: =100*(BW8/BW$9) -> 99.160721 | BJ8: =100*(BX8/BX$9) -> 100.76164 | BK8: =100*(BY8/BY$9) -> 100.3864 | BL8: =100*(BZ8/BZ$9) -> 99.586867 | BM8: =100*(CA8/CA$9) -> 99.093311 | BN8: 100 | BP8: =100*(CC8/CC$9) -> 101.62192 | BQ8: =100*(CD8/CD$9) -> 101.0229 | BR8: =100*(CE8/CE$9) -> 100.75443 | BS8: =100*(CF8/CF$9) -> 98.397461 | BT8: =100*(CG8/CG$9) -> 97.117868 | BU8: 100 | BW8: =100*(CI8/CU8) -> 408.019 | BX8: =100*(CJ8/CV8) -> 419.68701 | BY8: =100*(CK8/CW8) -> 421.6874 | BZ8: =100*(CL8/CX8) -> 426.51629 | CA8: =100*(CM8/CY8) -> 422.94449 | CC8: =100*(CO8/CU8) -> 94.646379 | CD8: =100*(CP8/CV8) -> 94.447103 | CE8: =100*(CQ8/CW8) -> 96.111651 | CF8: =100*(CR8/CX8) -> 96.000288 | CG8: =100*(CS8/CY8) -> 95.583786 | CI8: 408.019 | CJ8: 419.68701 | CK8: 421.6874 | CL8: 426.51629 | CM8: 422.94449 | CO8: 94.646379 | CP8: 94.447103 | CQ8: 96.111651 | CR8: 96.000288 | CS8: 95.583786 | CU8: =100*(DA8/DA$8) -> 100 | CV8: =100*(DB8/DB$8) -> 100 | CW8: =100*(DC8/DC$8) -> 100 | CX8: =100*(DD8/DD$8) -> 100 | CY8: =100*(DE8/DE$8) -> 100 | DA8: =OBR_MAR22_1.2!X116 -> 112.46646 | DB8: =OBR_NOV22_1.2!X121 -> 115.66462 | DC8: =OBR_MAR23_1.2!X121 -> 115.31583 | DD8: =OBR_NOV23_1.2!X126 -> 119.26148 | DE8: =OBR_MAR24_1.2!X126 -> 119.9048 | DG8: 20 | DH8: 4.8945455 | DI8: 4.4172727 | DJ8: 4.561 | DL8: 2028 | DM8: 3.9784684 | DN8: 3.2529278 | DO8: 3.4607663 | DQ8: FY2026/27 | DR8: 4.028261 | DS8: =DR8+0.05 -> 4.078261 | DT8: ='OBR RR Oct23 - Debt interest'!F11*(DS8-DR8)+'OBR RR Oct23 - Debt interest'!F10*(DS7-DR7)+'OBR RR Oct23 - Debt interest'!F9*(DS6-DR6)+'OBR RR Oct23 - Debt interest'!F8*(DS5-DR5) -> 361.99077 | DV8: 3.2404348 | DW8: =DV8+(DO6-DN6) -> 3.6452369 | DX8: ='OBR RR Oct23 - Debt interest'!F16*(DW8-DV8)+'OBR RR Oct23 - Debt interest'!F15*(DW7-DV7) -> 3548.3844 | DZ8: =DX8+DT8 -> 3910.3752
A9: Change to PSNB forecast | B9: =SUM(B4:B8) -> -9.8249571 | C9: =SUM(C4:C8) -> 2.6562558 | D9: =SUM(D4:D8) -> 0.64667534 | E9: =SUM(E4:E8) -> 0.2550542 | F9: =SUM(F4:F8) -> 1.5035416 | G9: =SUM(G4:G8) -> 4.4307623 | R9: 2024-25 | S9: =100*(AG9/AG$9) -> 100 | T9: =100*(AH9/AH$9) -> 100 | U9: =100*(AI9/AI$9) -> 100 | V9: =100*(AJ9/AJ$9) -> 100 | W9: =100*(AK9/AK$9) -> 100 | X9: 100 | Z9: =100*(AM9/AM$9) -> 100 | AA9: =100*(AN9/AN$9) -> 100 | AB9: =100*(AO9/AO$9) -> 100 | AC9: =100*(AP9/AP$9) -> 100 | AD9: =100*(AQ9/AQ$9) -> 100 | AE9: 100 | AG9: =100*(AS9/CU9) -> 5.9249188 | AH9: =100*(AT9/CV9) -> 5.9975238 | AI9: =100*(AU9/CW9) -> 6.0486359 | AJ9: =100*(AV9/CX9) -> 6.1670185 | AK9: =100*(AW9/CY9) -> 6.1458326 | AM9: =100*(AY9/CU9) -> 1.3410911 | AN9: =100*(AZ9/CV9) -> 1.3462028 | AO9: =100*(BA9/CW9) -> 1.3735788 | AP9: =100*(BB9/CX9) -> 1.4048512 | AQ9: =100*(BC9/CY9) -> 1.4171858 | AS9: =CI9/($BF9/1000) -> 6.0347252 | AT9: =CJ9/($BF9/1000) -> 6.0765288 | AU9: =CK9/($BF9/1000) -> 6.1435572 | AV9: =CL9/($BF9/1000) -> 6.2702082 | AW9: =CM9/($BF9/1000) -> 6.1945168 | AY9: =CO9/($BF9/1000) -> 1.3659455 | AZ9: =CP9/($BF9/1000) -> 1.3639362 | BA9: =CQ9/($BF9/1000) -> 1.3951344 | BB9: =CR9/($BF9/1000) -> 1.4283579 | BC9: =CS9/($BF9/1000) -> 1.428412 | BE9: =+BE8+100 -> 202501 | BF9: =VLOOKUP(BE9,Data!$A$7:$C$318,3,FALSE) -> 69447.77 | BH9: 2024-25 | BI9: =100*(BW9/BW$9) -> 100 | BJ9: =100*(BX9/BX$9) -> 100 | BK9: =100*(BY9/BY$9) -> 100 | BL9: =100*(BZ9/BZ$9) -> 100 | BM9: =100*(CA9/CA$9) -> 100 | BN9: 100 | BP9: =100*(CC9/CC$9) -> 100 | BQ9: =100*(CD9/CD$9) -> 100 | BR9: =100*(CE9/CE$9) -> 100 | BS9: =100*(CF9/CF$9) -> 100 | BT9: =100*(CG9/CG$9) -> 100 | BU9: 100 | BW9: =100*(CI9/CU9) -> 411.4724 | BX9: =100*(CJ9/CV9) -> 416.51465 | BY9: =100*(CK9/CW9) -> 420.06427 | BZ9: =100*(CL9/CX9) -> 428.28568 | CA9: =100*(CM9/CY9) -> 426.81437 | CC9: =100*(CO9/CU9) -> 93.135788 | CD9: =100*(CP9/CV9) -> 93.490781 | CE9: =100*(CQ9/CW9) -> 95.391985 | CF9: =100*(CR9/CX9) -> 97.563786 | CG9: =100*(CS9/CY9) -> 98.420392 | CI9: 419.09821 | CJ9: 422.00137 | CK9: 426.65635 | CL9: 435.45198 | CM9: 430.19538 | CO9: 94.861872 | CP9: 94.722329 | CQ9: 96.888973 | CR9: 99.196273 | CS9: 99.20003 | CU9: =100*(DA9/DA$8) -> 101.8533 | CV9: =100*(DB9/DB$8) -> 101.31729 | CW9: =100*(DC9/DC$8) -> 101.5693 | CX9: =100*(DD9/DD$8) -> 101.67325 | CY9: =100*(DE9/DE$8) -> 100.79215 | DA9: =OBR_MAR22_1.2!X117 -> 114.5508 | DB9: =OBR_NOV22_1.2!X122 -> 117.18826 | DC9: =OBR_MAR23_1.2!X122 -> 117.12548 | DD9: =OBR_NOV23_1.2!X127 -> 121.25702 | DE9: =OBR_MAR24_1.2!X127 -> 120.85462 | DG9: 30 | DH9: 4.9418182 | DI9: 4.5090909 | DJ9: 4.596 | DQ9: FY2027/28 | DR9: 4.2057432 | DS9: =DR9+0.05 -> 4.2557432 | DT9: ='OBR RR Oct23 - Debt interest'!G12*(DS9-DR9)+'OBR RR Oct23 - Debt interest'!G11*(DS8-DR8)+'OBR RR Oct23 - Debt interest'!G10*(DS7-DR7)+'OBR RR Oct23 - Debt interest'!G9*(DS6-DR6)+'OBR RR Oct23 - Debt interest'!G8*(DS5-DR5) -> 443.03413 | DV9: 3.2030148 | DW9: =DV9+(DO7-DN7) -> 3.498119 | DX9: ='OBR RR Oct23 - Debt interest'!G17*(DW9-DV9)+'OBR RR Oct23 - Debt interest'!G16*(DW8-DV8) -> 2351.8635 | DZ9: =DX9+DT9 -> 2794.8976
R10: 2025-26 | S10: =100*(AG10/AG$9) -> 101.14957 | T10: =100*(AH10/AH$9) -> 100.68932 | U10: =100*(AI10/AI$9) -> 100.43593 | V10: =100*(AJ10/AJ$9) -> 99.792219 | W10: =100*(AK10/AK$9) -> 100.184 | X10: 100 | Z10: =100*(AM10/AM$9) -> 101.87877 | AA10: =100*(AN10/AN$9) -> 99.661585 | AB10: =100*(AO10/AO$9) -> 98.510929 | AC10: =100*(AP10/AP$9) -> 95.650971 | AD10: =100*(AQ10/AQ$9) -> 96.820909 | AE10: 100 | AG10: =100*(AS10/CU10) -> 5.9930301 | AH10: =100*(AT10/CV10) -> 6.0388659 | AI10: =100*(AU10/CW10) -> 6.0750035 | AJ10: =100*(AV10/CX10) -> 6.1542047 | AK10: =100*(AW10/CY10) -> 6.157141 | AM10: =100*(AY10/CU10) -> 1.3662872 | AN10: =100*(AZ10/CV10) -> 1.341647 | AO10: =100*(BA10/CW10) -> 1.3531252 | AP10: =100*(BB10/CX10) -> 1.3437538 | AQ10: =100*(BC10/CY10) -> 1.3721322 | AS10: =CI10/($BF10/1000) -> 6.2233038 | AT10: =CJ10/($BF10/1000) -> 6.1508593 | AU10: =CK10/($BF10/1000) -> 6.2297609 | AV10: =CL10/($BF10/1000) -> 6.364352 | AW10: =CM10/($BF10/1000) -> 6.2896463 | AY10: =CO10/($BF10/1000) -> 1.4187848 | AZ10: =CP10/($BF10/1000) -> 1.3665285 | BA10: =CQ10/($BF10/1000) -> 1.3875954 | BB10: =CR10/($BF10/1000) -> 1.3896389 | BC10: =CS10/($BF10/1000) -> 1.4016612 | BE10: =+BE9+100 -> 202601 | BF10: =VLOOKUP(BE10,Data!$A$7:$C$318,3,FALSE) -> 69961.86 | BH10: 2025-26 | BI10: =100*(BW10/BW$9) -> 101.89834 | BJ10: =100*(BX10/BX$9) -> 101.43468 | BK10: =100*(BY10/BY$9) -> 101.17941 | BL10: =100*(BZ10/BZ$9) -> 100.53094 | BM10: =100*(CA10/CA$9) -> 100.92562 | BN10: 100 | BP10: =100*(CC10/CC$9) -> 102.63294 | BQ10: =100*(CD10/CD$9) -> 100.39933 | BR10: =100*(CE10/CE$9) -> 99.24016 | BS10: =100*(CF10/CF$9) -> 96.359031 | BT10: =100*(CG10/CG$9) -> 97.53763 | BU10: 100 | BW10: =100*(CI10/CU10) -> 419.28353 | BX10: =100*(CJ10/CV10) -> 422.49029 | BY10: =100*(CK10/CW10) -> 425.01855 | BZ10: =100*(CL10/CX10) -> 430.5596 | CA10: =100*(CM10/CY10) -> 430.76503 | CC10: =100*(CO10/CU10) -> 95.587994 | CD10: =100*(CP10/CV10) -> 93.864122 | CE10: =100*(CQ10/CW10) -> 94.667158 | CF10: =100*(CR10/CX10) -> 94.011519 | CG10: =100*(CS10/CY10) -> 95.996918 | CI10: 435.39391 | CJ10: 430.32556 | CK10: 435.84566 | CL10: 445.2619 | CM10: 440.03535 | CO10: 99.260827 | CP10: 95.604873 | CQ10: 97.078752 | CR10: 97.221725 | CS10: 98.062828 | CU10: =100*(DA10/DA$8) -> 103.84236 | CV10: =100*(DB10/DB$8) -> 101.85454 | CW10: =100*(DC10/DC$8) -> 102.54745 | CX10: =100*(DD10/DD$8) -> 103.4147 | CY10: =100*(DE10/DE$8) -> 102.15206 | DA10: =OBR_MAR22_1.2!X118 -> 116.78782 | DB10: =OBR_NOV22_1.2!X123 -> 117.80967 | DC10: =OBR_MAR23_1.2!X123 -> 118.25344 | DD10: =OBR_NOV23_1.2!X128 -> 123.33389 | DE10: =OBR_MAR24_1.2!X128 -> 122.48522 | DQ10: FY2028/29 | DR10: 4.4042974 | DS10: =DR10+0.05 -> 4.4542974 | DT10: ='OBR RR Oct23 - Debt interest'!J12*(DS10-DR10)+'OBR RR Oct23 - Debt interest'!H12*(DS9-DR9)+'OBR RR Oct23 - Debt interest'!H11*(DS8-DR8)+'OBR RR Oct23 - Debt interest'!H10*(DS7-DR7)+'OBR RR Oct23 - Debt interest'!H9*(DS6-DR6)+'OBR RR Oct23 - Debt interest'!H8*(DS5-DR5) -> 534.18895 | DV10: 3.2471111 | DW10: =DV10+(DO8-DN8) -> 3.4549496 | DX10: ='OBR RR Oct23 - Debt interest'!J17*(DW10-DV10)+'OBR RR Oct23 - Debt interest'!H17*(DW9-DV9) -> 1496.5704 | DZ10: =DX10+DT10 -> 2030.7594
A11: Check | B11: =OBR_MAR24_T4.12!D9 -> -9.8249571 | C11: =OBR_MAR24_T4.12!E9 -> 2.6562558 | D11: =OBR_MAR24_T4.12!F9 -> 0.64667534 | E11: =OBR_MAR24_T4.12!G9 -> 0.2550542 | F11: =OBR_MAR24_T4.12!H9 -> 1.5035416 | G11: =OBR_MAR24_T4.12!I9 -> 4.4307623 | R11: 2026-27 | S11: =100*(AG11/AG$9) -> 102.23065 | T11: =100*(AH11/AH$9) -> 101.08757 | U11: =100*(AI11/AI$9) -> 100.97993 | V11: =100*(AJ11/AJ$9) -> 100.1588 | W11: =100*(AK11/AK$9) -> 100.59628 | X11: 100 | Z11: =100*(AM11/AM$9) -> 102.96029 | AA11: =100*(AN11/AN$9) -> 98.290207 | AB11: =100*(AO11/AO$9) -> 97.156218 | AC11: =100*(AP11/AP$9) -> 93.829829 | AD11: =100*(AQ11/AQ$9) -> 94.862307 | AE11: 100 | AG11: =100*(AS11/CU11) -> 6.0570831 | AH11: =100*(AT11/CV11) -> 6.0627513 | AI11: =100*(AU11/CW11) -> 6.1079084 | AJ11: =100*(AV11/CX11) -> 6.1768118 | AK11: =100*(AW11/CY11) -> 6.1824787 | AM11: =100*(AY11/CU11) -> 1.3807914 | AN11: =100*(AZ11/CV11) -> 1.3231855 | AO11: =100*(BA11/CW11) -> 1.3345172 | AP11: =100*(BB11/CX11) -> 1.3181695 | AQ11: =100*(BC11/CY11) -> 1.3443751 | AS11: =CI11/($BF11/1000) -> 6.4156649 | AT11: =CJ11/($BF11/1000) -> 6.2504132 | AU11: =CK11/($BF11/1000) -> 6.3385519 | AV11: =CL11/($BF11/1000) -> 6.4915223 | AW11: =CM11/($BF11/1000) -> 6.4256475 | AY11: =CO11/($BF11/1000) -> 1.4625348 | AZ11: =CP11/($BF11/1000) -> 1.3641424 | BA11: =CQ11/($BF11/1000) -> 1.3849105 | BB11: =CR11/($BF11/1000) -> 1.3853307 | BC11: =CS11/($BF11/1000) -> 1.397252 | BE11: =+BE10+100 -> 202701 | BF11: =VLOOKUP(BE11,Data!$A$7:$C$318,3,FALSE) -> 70386.82 | BH11: 2026-27 | BI11: =100*(BW11/BW$9) -> 103.61298 | BJ11: =100*(BX11/BX$9) -> 102.45445 | BK11: =100*(BY11/BY$9) -> 102.34535 | BL11: =100*(BZ11/BZ$9) -> 101.51312 | BM11: =100*(CA11/CA$9) -> 101.95651 | BN11: 100 | BP11: =100*(CC11/CC$9) -> 104.35249 | BQ11: =100*(CD11/CD$9) -> 99.619255 | BR11: =100*(CE11/CE$9) -> 98.469932 | BS11: =100*(CF11/CF$9) -> 95.098565 | BT11: =100*(CG11/CG$9) -> 96.145004 | BU11: 100 | BW11: =100*(CI11/CU11) -> 426.33882 | BX11: =100*(CJ11/CV11) -> 426.73778 | BY11: =100*(CK11/CW11) -> 429.91625 | BZ11: =100*(CL11/CX11) -> 434.76614 | CA11: =100*(CM11/CY11) -> 435.16502 | CC11: =100*(CO11/CU11) -> 97.189513 | CD11: =100*(CP11/CV11) -> 93.13482 | CE11: =100*(CQ11/CW11) -> 93.932423 | CF11: =100*(CR11/CX11) -> 92.78176 | CG11: =100*(CS11/CY11) -> 94.62629 | CI11: 451.57825 | CJ11: 439.94671 | CK11: 446.15051 | CL11: 456.91761 | CM11: 452.28089 | CO11: 102.94317 | CP11: 96.017646 | CQ11: 97.479447 | CR11: 97.50902 | CS11: 98.348124 | CU11: =100*(DA11/DA$8) -> 105.92004 | CV11: =100*(DB11/DB$8) -> 103.09533 | CW11: =100*(DC11/DC$8) -> 103.77614 | CX11: =100*(DD11/DD$8) -> 105.09503 | CY11: =100*(DE11/DE$8) -> 103.93319 | DA11: =OBR_MAR22_1.2!X119 -> 119.12452 | DB11: =OBR_NOV22_1.2!X124 -> 119.24482 | DC11: =OBR_MAR23_1.2!X124 -> 119.67032 | DD11: =OBR_NOV23_1.2!X129 -> 125.33789 | DE11: =OBR_MAR24_1.2!X129 -> 124.62088 | DG11: Av | DH11: =AVERAGE(DH4:DH9) -> 4.7581818 | DI11: =AVERAGE(DI4:DI9) -> 4.1828788 | DJ11: =AVERAGE(DJ4:DJ9) -> 4.3525 | DM11: =AVERAGE(DM4:DM9) -> 4.3918051 | DN11: =AVERAGE(DN4:DN9) -> 3.4175929 | DO11: =AVERAGE(DO4:DO9) -> 3.7869341
R12: 2027-28 | T12: =100*(AH12/AH$9) -> 101.69253 | U12: =100*(AI12/AI$9) -> 101.69878 | V12: =100*(AJ12/AJ$9) -> 100.73998 | W12: =100*(AK12/AK$9) -> 101.16569 | X12: 100 | AA12: =100*(AN12/AN$9) -> 96.280174 | AB12: =100*(AO12/AO$9) -> 95.270105 | AC12: =100*(AP12/AP$9) -> 91.841724 | AD12: =100*(AQ12/AQ$9) -> 92.670727 | AE12: 100 | AH12: =100*(AT12/CV12) -> 6.0990339 | AI12: =100*(AU12/CW12) -> 6.1513887 | AJ12: =100*(AV12/CX12) -> 6.2126532 | AK12: =100*(AW12/CY12) -> 6.2174741 | AN12: =100*(AZ12/CV12) -> 1.2961264 | AO12: =100*(BA12/CW12) -> 1.30861 | AP12: =100*(BB12/CX12) -> 1.2902396 | AQ12: =100*(BC12/CY12) -> 1.3133164 | AT12: =CJ12/($BF12/1000) -> 6.4007685 | AU12: =CK12/($BF12/1000) -> 6.4891469 | AV12: =CL12/($BF12/1000) -> 6.6450309 | AW12: =CM12/($BF12/1000) -> 6.5830388 | AZ12: =CP12/($BF12/1000) -> 1.360249 | BA12: =CQ12/($BF12/1000) -> 1.3804626 | BB12: =CR12/($BF12/1000) -> 1.3800355 | BC12: =CS12/($BF12/1000) -> 1.3905346 | BE12: =+BE11+100 -> 202801 | BF12: =VLOOKUP(BE12,Data!$A$7:$C$318,3,FALSE) -> 70720.8 | BH12: 2027-28 | BJ12: =100*(BX12/BX$9) -> 103.55663 | BK12: =100*(BY12/BY$9) -> 103.56299 | BL12: =100*(BZ12/BZ$9) -> 102.58662 | BM12: =100*(CA12/CA$9) -> 103.02014 | BN12: 100 | BQ12: =100*(CD12/CD$9) -> 98.045062 | BR12: =100*(CE12/CE$9) -> 97.016478 | BS12: =100*(CF12/CF$9) -> 93.525252 | BT12: =100*(CG12/CG$9) -> 94.369451 | BU12: 100 | BX12: =100*(CJ12/CV12) -> 431.32856 | BY12: =100*(CK12/CW12) -> 435.03113 | BZ12: =100*(CL12/CX12) -> 439.3638 | CA12: =100*(CM12/CY12) -> 439.70474 | CD12: =100*(CP12/CV12) -> 91.663094 | CE12: =100*(CQ12/CW12) -> 92.545944 | CF12: =100*(CR12/CX12) -> 91.246777 | CG12: =100*(CS12/CY12) -> 92.878783 | CJ12: 452.66747 | CK12: 458.91766 | CL12: 469.9419 | CM12: 465.55777 | CP12: 96.197899 | CQ12: 97.627423 | CR12: 97.597216 | CS12: 98.339717 | CV12: =100*(DB12/DB$8) -> 104.94725 | CW12: =100*(DC12/DC$8) -> 105.49076 | CX12: =100*(DD12/DD$8) -> 106.95963 | CY12: =100*(DE12/DE$8) -> 105.87963 | DB12: =OBR_NOV22_1.2!X125 -> 121.38684 | DC12: =OBR_MAR23_1.2!X125 -> 121.64755 | DD12: =OBR_NOV23_1.2!X130 -> 127.56164 | DE12: =OBR_MAR24_1.2!X130 -> 126.95476 | DG12: Diff | DI12: =DI11-$DH$11 -> -0.57530303 | DJ12: =DJ11-$DH$11 -> -0.40568182 | DN12: =DN11-$DM$11 -> -0.97421222 | DO12: =DO11-$DM$11 -> -0.60487104
R13: 2028-29 | V13: =100*(AJ13/AJ$9) -> 101.32775 | W13: =100*(AK13/AK$9) -> 101.70919 | X13: 100 | AC13: =100*(AP13/AP$9) -> 89.539507 | AD13: =100*(AQ13/AQ$9) -> 89.620305 | AE13: 100 | AJ13: =100*(AV13/CX13) -> 6.248901 | AK13: =100*(AW13/CY13) -> 6.2508762 | AP13: =100*(BB13/CX13) -> 1.2578969 | AQ13: =100*(BC13/CY13) -> 1.2700862 | AV13: =CL13/($BF13/1000) -> 6.8095063 | AW13: =CM13/($BF13/1000) -> 6.7463195 | BB13: =CR13/($BF13/1000) -> 1.3707461 | BC13: =CS13/($BF13/1000) -> 1.370753 | BE13: =+BE12+100 -> 202901 | BF13: =VLOOKUP(BE13,Data!$A$7:$C$318,3,FALSE) -> 71025.23 | BH13: 2028-29 | BL13: =100*(BZ13/BZ$9) -> 103.62934 | BM13: =100*(CA13/CA$9) -> 104.01944 | BN13: 100 | BS13: =100*(CF13/CF$9) -> 91.573337 | BT13: =100*(CG13/CG$9) -> 91.65597 | BU13: 100 | BZ13: =100*(CL13/CX13) -> 443.82963 | CA13: =100*(CM13/CY13) -> 443.96992 | CF13: =100*(CR13/CX13) -> 89.342414 | CG13: =100*(CS13/CY13) -> 90.208165 | CL13: 483.64675 | CM13: 479.15889 | CR13: 97.357557 | CS13: 97.358047 | CX13: =100*(DD13/DD$8) -> 108.97126 | CY13: =100*(DE13/DE$8) -> 107.92598 | DD13: =OBR_NOV23_1.2!X131 -> 129.96074 | DE13: =OBR_MAR24_1.2!X131 -> 129.40843 | DJ13: =-DI12+DJ12 -> 0.16962121 | DO13: =-DN12+DO12 -> 0.36934118

Sheet OBR_MAR24_C1.5
A1: Back to contents
B2: Chart 1.5: Public sector net borrowing: change since November
C25: 2023-24 | D25: 2024-25 | E25: 2025-26 | F25: 2026-27 | G25: 2027-28 | H25: 2028-29
B26: Effects of policy | C26: 0.32316634 | D26: 12.668357 | E26: 10.36852 | F26: 6.4263462 | G26: 5.1195595 | H26: 5.2043361
B27: Receipts | C27: 0.78696365 | D27: 5.2325724 | E27: 8.7181301 | F27: 10.354385 | G27: 12.288382 | H27: 14.770554
B28: Other spending | C28: 0.060529746 | D28: 2.2845351 | E28: 0.80306501 | F28: 0.63733687 | G28: -0.020847638 | H28: 0.19608465
B29: Debt interest spending | C29: -11.477824 | D29: -16.173451 | E29: -14.680019 | F29: -13.834613 | G29: -13.306391 | H29: -14.193449
B30: Welfare spending | C30: 0.48220721 | D30: -1.3557579 | E30: -4.5630214 | F30: -3.3284018 | G30: -2.5771608 | H30: -1.5467628
B31: Change in post-measures borrowing | C31: -9.8249571 | D31: 2.6562558 | E31: 0.64667534 | F31: 0.2550542 | G31: 1.5035416 | H31: 4.4307623
B32: Change in pre-measures borrowing | C32: -10.148123 | D32: -10.012101 | E32: -9.721845 | F32: -6.171292 | G32: -3.6160179 | H32: -0.77357379

Sheet OBR_MAR24_T3.8
A1: Back to contents
B2: Table 3.8: Latest costings of personal tax measures
C4: £ billion
C5: Forecast
C6: 2022-23 | D6: 2023-24 | E6: 2024-25 | F6: 2025-26 | G6: 2026-27 | H6: 2027-28 | I6: 2028-29
B7: Changes to thresholds
B8: PA and HRT freezes | C8: -2.91 | D8: -13.545 | E8: -23.23 | F8: -27.045 | G8: -29.36 | H8: -32.265 | I8: -33.61
B9: Additional rate threshold: reduction | C9: -0.08 | D9: -0.445 | E9: -0.815 | F9: -0.815 | G9: -0.845 | H9: -0.895 | I9: -0.945
B10: NICs: rise in primary threshold | C10: 6.645 | D10: 5.365 | E10: 2.98 | F10: 2.31 | G10: 2.42 | H10: 2.47 | I10: 2.49
B11: Class 2 NICs: threshold rise | C11: 0.075 | D11: 0.085 | E11: 0.075 | F11: 0.07 | G11: 0.075 | H11: 0.085 | I11: 0.085
B12: Class 1 NICs: threshold freezes | C12: 0 | D12: -3.33 | E12: -5.715 | F12: -6.485 | G12: -7.64 | H12: -8.895 | I12: -9.145
B13: Total | C13: 3.73 | D13: -11.87 | E13: -26.705 | F13: -31.965 | G13: -35.35 | H13: -39.5 | I13: -41.125
B14: Rate cuts
B15: Autumn Statement 2023 NICs | C15: 0 | D15: 2.3828955 | E15: 9.9944842 | F15: 10.141012 | G15: 10.17163 | H15: 10.385803 | I15: 10.66816
B16: Budget 2024 measures | C16: 0 | D16: 0 | E16: 10.070957 | F16: 10.145467 | G16: 10.226379 | H16: 10.44633 | I16: 10.749149
B17: Total | C17: 0 | D17: 2.3828955 | E17: 20.065441 | F17: 20.286479 | G17: 20.398009 | H17: 20.832133 | I17: 21.417308

Sheet OBR_MAR24_T4.12
A1: Back to contents
B2: Table 4.12: Public sector net borrowing: changes since November 2023
C4: £ billion
C5: Outturn | D5: Forecast | E5: 0 | F5: 0 | G5: 0 | H5: 0 | I5: 0
C6: 2022-23 | D6: 2023-24 | E6: 2024-25 | F6: 2025-26 | G6: 2026-27 | H6: 2027-28 | I6: 2028-29
B7: November 2023 forecast | C7: 128.266 | D7: 123.90988 | E7: 84.570326 | F7: 76.83564 | G7: 68.405587 | H7: 49.05861 | I7: 35.003998
B8: March 2024 forecast | C8: 128.682 | D8: 114.08493 | E8: 87.226582 | F8: 77.482315 | G8: 68.660641 | H8: 50.562152 | I8: 39.43476
B9: Difference | C9: 0.416 | D9: -9.8249571 | E9: 2.6562558 | F9: 0.64667534 | G9: 0.2550542 | H9: 1.5035416 | I9: 4.4307623
B10: of which:
B11: Underlying differences | D11: -10.148123 | E11: -10.012101 | F11: -9.721845 | G11: -6.171292 | H11: -3.6160179 | I11: -0.77357379
B12: of which:
B13: Receipts | D13: 0.78696365 | E13: 5.2325724 | F13: 8.7181301 | G13: 10.354385 | H13: 12.288382 | I13: 14.770554
B14: Spending | D14: -10.935087 | E14: -15.244674 | F14: -18.439975 | G14: -16.525677 | H14: -15.9044 | I14: -15.544128
B15: of which:
B16: Debt interest spending | D16: -11.477824 | E16: -16.173451 | F16: -14.680019 | G16: -13.834613 | H16: -13.306391 | I16: -14.193449
B17: Welfare spending | D17: 0.48220721 | E17: -1.3557579 | F17: -4.5630214 | G17: -3.3284018 | H17: -2.5771608 | I17: -1.5467628
B18: Other spending | D18: 0.060529746 | E18: 2.2845351 | F18: 0.80306501 | G18: 0.63733687 | H18: -0.020847638 | I18: 0.19608465
B19: Direct effect of policy decisions | D19: 0.057872132 | E19: 13.899537 | F19: 10.116299 | G19: 7.6829941 | H19: 6.3384618 | I19: 5.9370328
B20: of which:
B21: National insurance contributions cut | D21: 0 | E21: 10.196025 | F21: 10.329817 | G21: 10.465234 | H21: 10.705217 | I21: 11.037294
B22: Reform of non-domicile regime | D22: 0 | E22: 0 | F22: -0.186 | G22: -2.733 | H22: -3.557 | I22: -2.643
B23: Other receipts decisions | D23: 0.18808678 | E23: 3.3254114 | F23: 0.10133373 | G23: -0.52055575 | H23: -1.5678695 | I23: -2.4749031
B24: Spending decisions | D24: -0.13021465 | E24: 0.3781002 | F24: -0.1288523 | G24: 0.47131558 | H24: 0.7581139 | I24: 0.017641508
B25: Indirect effect of decisions | D25: 0.26529421 | E25: -1.2311794 | F25: 0.25222169 | G25: -1.2566479 | H25: -1.2189023 | I25: -0.73269675
B26: of which:
B27: Debt interest spending | D27: 0.0038115824 | E27: -1.0457675 | F27: 1.6753159 | G27: 1.1899314 | H27: 1.1847893 | I27: 1.3482743
B28: Other economic effects | D28: 0.26148263 | E28: -0.1854119 | F28: -1.4230943 | G28: -2.4465793 | H28: -2.4036915 | I28: -2.0809711
B29: Note: This table uses the convention that a negative figure means a reduction in PSNB i.e. an increase in receipts or a reduction in spending will have a negative effect on PSNB. It does not include the effects of changes in our underlying forecasts for most environmental levies, VAT refunds or depreciation, as each change both receipts and spending by equal amounts and therefore do not change borrowing.

Sheet OBR_MAR24_TA.7
A1: Back to contents
B2: Table A.7: Total managed expenditure
C4: £ billion
C5: Outturn | D5: Forecast
C6: 2022-23 | D6: 2023-24 | E6: 2024-25 | F6: 2025-26 | G6: 2026-27 | H6: 2027-28 | I6: 2028-29
B7: Public sector current expenditure (PSCE)
B8: PSCE in RDEL | C8: 407.4577 | D8: 422.94449 | E8: 430.19538 | F8: 440.03535 | G8: 452.28089 | H8: 465.55777 | I8: 479.15889
B9: PSCE in AME | C9: 643.6143 | D9: 659.96315 | E9: 660.1941 | F9: 679.56195 | G9: 705.7294 | H9: 725.75804 | I9: 751.95568
B10: of which:
B11: Welfare spending | C11: 261.4874 | D11: 295.84845 | E11: 315.14089 | F11: 329.00886 | G11: 339.72754 | H11: 348.2333 | I11: 360.06887
B12: Locally financed current expenditure | C12: 60.137438 | D12: 62.063371 | E12: 64.070522 | F12: 66.14117 | G12: 69.311315 | H12: 72.175566 | I12: 75.387203
B13: Central government debt interest, net of APF1 | C13: 111.481 | D13: 104.74828 | E13: 88.955775 | F13: 88.888563 | G13: 96.20421 | H13: 103.044 | I13: 109.63575
B14: Scottish Government's current spending | C14: 39.586038 | D14: 42.618447 | E14: 44.427363 | F14: 45.138799 | G14: 46.302917 | H14: 47.157818 | I14: 49.134058
B15: EU financial settlement | C15: 8.8096667 | D15: 7.7514634 | E15: 1.135536 | F15: 1.0637573 | G15: 0.5381457 | H15: 0.18596545 | I15: 0.52161233
B16: Unfunded public service pensions | C16: 3.5806935 | D16: 4.5721668 | E16: 3.4392333 | F16: 4.1530844 | G16: 3.100412 | H16: 2.231031 | I16: 0.64376789
B17: Company and other tax credits | C17: 9.2172361 | D17: 9.3808388 | E17: 9.6580323 | F17: 10.166965 | G17: 10.582 | H17: 10.989011 | I17: 11.355334
B18: BBC current expenditure | C18: 4.2246768 | D18: 4.1788233 | E18: 4.3327533 | F18: 4.1190666 | G18: 4.270332 | H18: 4.355332 | I18: 4.4052235
B19: National Lottery current grants | C19: 1.28536 | D19: 1.2437495 | E19: 1.414753 | F19: 1.4105405 | G19: 1.318127 | H19: 1.2435335 | I19: 1.2428825
B20: General government imputed pensions | C20: 3.3853899 | D20: 1.6987073 | E20: 1.7594719 | F20: 1.8057996 | G20: 1.85605 | H20: 1.9100249 | I20: 1.9688475
B21: Public corporations' debt interest | C21: 0.544 | D21: 0.54 | E21: 0.54 | F21: 0.54 | G21: 0.54 | H21: 0.54 | I21: 0.54
B22: Non-domestic energy support | C22: 7.48 | D22: 0.621 | E22: 0 | F22: 0 | G22: 0 | H22: 0 | I22: 0
... B30: Total public sector current expenditure | C30: 1051.072 | D30: 1082.9076 | E30: 1090.3895 | F30: 1119.5973 | G30: 1158.0103 | H30: 1191.3158 | I30: 1231.1146
B31: Public sector gross investment (PSGI)
B32: PSGI in CDEL | C32: 89.791733 | D32: 95.583786 | E32: 99.20003 | F32: 98.062828 | G32: 98.348124 | H32: 98.339717 | I32: 97.358047
B33: PSGI in AME | C33: 16.548267 | D33: 37.78248 | E33: 36.758702 | F33: 33.997042 | G33: 33.894631 | H33: 33.406167 | I33: 33.203153
B34: of which:
B35: Locally financed capital expenditure | C35: 10.835605 | D35: 8.8351359 | E35: 8.2751924 | F35: 7.5499586 | G35: 8.1494607 | H35: 8.1407231 | I35: 8.2007894
B36: Public corporations' capital expenditure | C36: 11.556757 | D36: 11.199767 | E36: 11.740905 | F36: 11.617591 | G36: 11.610803 | H36: 11.667161 | I36: 11.740328
B37: Student loans | C37: 0.488 | D37: 9.8426785 | E37: 8.9549482 | F37: 8.1280841 | G37: 7.5164923 | H37: 7.2257973 | I37: 7.0930287
B38: Funded public sector pension schemes | C38: -4.854 | D38: 0.71152891 | E38: 0.71152891 | F38: 0.71152891 | G38: 0.71152891 | H38: 0.71152891 | I38: 0.71152891
B39: Scottish Government's capital spending | C39: 4.569481 | D39: 5.6714916 | E39: 5.4709199 | F39: 5.2342224 | G39: 5.2275066 | H39: 5.2113555 | I39: 5.1460268
B40: Tax litigation | C40: 0 | D40: 0.8235 | E40: 1.203396 | F40: 0.63406325 | G40: 0.63406325 | H40: 0.63406325 | I40: 0.63406325
B41: Other PSGI items in AME | C41: 0.38561146 | D41: 1.2091956 | E41: 0.89061083 | F41: 0.81662252 | G41: 0.72455505 | H41: 0.56602273 | I41: 0.52125924
B42: Other National Accounts adjustments | C42: -6.4331875 | D42: -0.5108177 | E42: -0.48879946 | F42: -0.69502831 | G42: -0.6797789 | H42: -0.75048428 | I42: -0.84387143
B43: Total public sector gross investment | C43: 106.34 | D43: 133.36627 | E43: 135.95873 | F43: 132.05987 | G43: 132.24276 | H43: 131.74588 | I43: 130.5612
B44: Less public sector depreciation | C44: -60.341 | D44: -66.227455 | E44: -69.392239 | F44: -71.109614 | G44: -73.128371 | H44: -75.412565 | I44: -77.50292
B45: Public sector net investment | C45: 45.999 | D45: 67.138811 | E45: 66.566493 | F45: 60.950257 | G45: 59.114384 | H45: 56.333319 | I45: 53.05828
B46: Total managed expenditure | C46: 1157.412 | D46: 1216.2739 | E46: 1226.3482 | F46: 1251.6572 | G46: 1290.253 | H46: 1323.0617 | I46: 1361.6758
B47: 1 Includes increases in debt interest payments due to the APF.

Sheet OBR_MAR24_C4.10
A1: Back to contents
B2: Chart 4.10: Real departmental spending per person (2023-24 prices)
C25: 2021-22 | D25: 2022-23 | E25: 2023-24 | F25: 2024-25 | G25: 2025-26 | H25: 2026-27 | I25: 2027-28 | J25: 2028-29
B26: Initial October 2021 SR plans | C26: 8058.0943 | D26: 7886.165 | E26: 7924.843 | F26: 7936.6873 | G26: 8093.8952 | H26: 8213.0077
B27: Effect of policy since October 2021 | C27: 8096.5237 | D27: 8161.9941 | E27: 8294.4252 | F27: 8283.4996 | G27: 8231.465 | H27: 8230.5647
B28: Effect of policy and higher inflation since October 2021 | C28: 8096.5237 | D28: 7848.2929 | E28: 7650.2726 | F28: 7722.1683 | G28: 7722.1878 | H28: 7745.8693
B29: Effect of policy, hihger inflation and population since October 2021 (March 2024 forecast) | C29: 8088.1605 | D29: 7786.1672 | E29: 7547.7841 | F29: 7583.7687 | G29: 7563.5996 | H29: 7568.7853 | I29: 7569.1965 | J29: 7552.703

Sheet OBR_MAR24_1.1
A1: Back to contents
B2: 1.1 GDP expenditure components (£ billion chain-linked volumes, seasonally adjusted)
C3: Private consumption | D3: Government consumption | E3: Fixed investment | J3: Net acquisition of valuables | K3: Final domestic demand | L3: Change in inventories | M3: Total domestic demand | N3: Exports | O3: Total final expenditure | P3: Imports | Q3: Statistical discrepancy | R3: Real GDP | S3: Non-oil GVA
E4: of which: | F4: Business investment | G4: Private dwellings | H4: General government | I4: Public corps dwellings
B5: 2008Q1 | C5: 308.104 | D5: 93.323 | E5: 84.847 | F5: 45.209 | G5: 24.954 | H5: 13.732 | I5: 1.494 | J5: 0.253 | K5: 486.527 | L5: -2.688 | M5: 483.839 | N5: 140.286 | O5: 626.489 | P5: 137.103 | Q5: 0 | R5: 489.783 | S5: 426.405
B6: 2008Q2 | C6: 304.494 | D6: 92.738 | E6: 85.799 | F6: 46.925 | G6: 23.782 | H6: 14.129 | I6: 1.45 | J6: -0.422 | K6: 482.609 | L6: -1.231 | M6: 481.378 | N6: 140.305 | O6: 623.241 | P6: 136.253 | Q6: 0 | R6: 487.386 | S6: 424.841
B7: 2008Q3 | C7: 299.633 | D7: 94.397 | E7: 81.323 | F7: 45.148 | G7: 19.58 | H7: 14.145 | I7: 2.775 | J7: -0.984 | K7: 474.369 | L7: -3.213 | M7: 471.156 | N7: 140.846 | O7: 613.272 | P7: 133.811 | Q7: 0 | R7: 479.872 | S7: 418.251
B8: 2008Q4 | C8: 292.373 | D8: 95.402 | E8: 79.978 | F8: 43.617 | G8: 18.727 | H8: 15.192 | I8: 2.722 | J8: 0.11 | K8: 467.863 | L8: -5.656 | M8: 462.207 | N8: 135.424 | O8: 596.031 | P8: 126.724 | Q8: 0 | R8: 469.694 | S8: 409.321
B9: 2009Q1 | C9: 291.284 | D9: 94.802 | E9: 75.261 | F9: 39.697 | G9: 17.619 | H9: 15.489 | I9: 2.681 | J9: 1.308 | K9: 462.655 | L9: -9.394 | M9: 453.261 | N9: 126.723 | O9: 581.258 | P9: 121.718 | Q9: 0 | R9: 460.105 | S9: 401.251
B10: 2009Q2 | C10: 291.11 | D10: 94.564 | E10: 72.063 | F10: 37.614 | G10: 17.124 | H10: 14.824 | I10: 2.644 | J10: 0.617 | K10: 458.354 | L10: -8.962 | M10: 449.392 | N10: 125.42 | O10: 580.028 | P10: 122.009 | Q10: 0 | R10: 458.599 | S10: 399.499
B11: 2009Q3 | C11: 292.732 | D11: 95.362 | E11: 72.551 | F11: 36.801 | G11: 17.177 | H11: 16.069 | I11: 2.675 | J11: 1.036 | K11: 461.681 | L11: -9.269 | M11: 452.412 | N11: 124.828 | O11: 583.709 | P11: 125.311 | Q11: 0 | R11: 458.875 | S11: 400.202
B12: 2009Q4 | C12: 294.909 | D12: 96.11 | E12: 71.335 | F12: 36.482 | G12: 16.394 | H12: 15.851 | I12: 2.728 | J12: -0.228 | K12: 462.126 | L12: -7.406 | M12: 454.72 | N12: 130.663 | O12: 587.166 | P12: 127.35 | Q12: 0 | R12: 460.238 | S12: 401.681
B13: 2010Q1 | C13: 293.465 | D13: 94.805 | E13: 75.138 | F13: 38.204 | G13: 17.617 | H13: 16.792 | I13: 2.709 | J13: -0.366 | K13: 463.042 | L13: -2.196 | M13: 460.846 | N13: 130.582 | O13: 593.834 | P13: 129.677 | Q13: 0 | R13: 464.543 | S13: 405.884
B14: 2010Q2 | C14: 300.592 | D14: 95.123 | E14: 74.022 | F14: 37.63 | G14: 18.596 | H14: 15.355 | I14: 2.698 | J14: -0.577 | K14: 469.16 | L14: -1.663 | M14: 467.497 | N14: 134.894 | O14: 603.085 | P14: 133.785 | Q14: 0 | R14: 469.606 | S14: 410.793
B15: 2010Q3 | C15: 300.841 | D15: 95.137 | E15: 76.899 | F15: 39.313 | G15: 19.56 | H15: 15.628 | I15: 2.678 | J15: 0.524 | K15: 473.401 | L15: -0.658 | M15: 472.743 | N15: 136.309 | O15: 610.106 | P15: 138.104 | Q15: 0 | R15: 472.199 | S15: 413.478
B16: 2010Q4 | C16: 300.342 | D16: 95.696 | E16: 78.973 | F16: 41.914 | G16: 19.064 | H16: 15.547 | I16: 2.618 | J16: 0.418 | K16: 475.429 | L16: -4.046 | M16: 471.383 | N16: 139.076 | O16: 611.773 | P16: 139.318 | Q16: 0 | R16: 472.612 | S16: 414.371
... B89: 2029Q1 | C89: 386.99075 | D89: 130.50646 | E89: 108.5662 | F89: 61.292345 | G89: 28.99537 | H89: 16.60913 | I89: 1.6693576 | J89: -1.2825 | K89: 624.78092 | L89: 0.76566173 | M89: 625.54658 | N89: 181.1219 | O89: 806.66848 | P89: 187.91993 | Q89: 4.757 | R89: 623.50554 | S89: 554.78657
B90: 2008 | C90: 1204.604 | D90: 375.86 | E90: 331.947 | F90: 180.899 | G90: 87.043 | H90: 57.198 | I90: 8.441 | J90: -1.043 | K90: 1911.368 | L90: -12.788 | M90: 1898.58 | N90: 556.861 | O90: 2459.033 | P90: 533.891 | Q90: 0 | R90: 1926.735 | S90: 1678.818
B91: 2009 | C91: 1170.035 | D91: 380.838 | E91: 291.21 | F91: 150.594 | G91: 68.314 | H91: 62.233 | I91: 10.728 | J91: 2.733 | K91: 1844.816 | L91: -35.031 | M91: 1809.785 | N91: 507.634 | O91: 2332.161 | P91: 496.388 | Q91: 0 | R91: 1837.817 | S91: 1602.633
B92: 2010 | C92: 1195.24 | D92: 380.761 | E92: 305.032 | F92: 157.061 | G92: 74.837 | H92: 63.322 | I92: 10.703 | J92: -0.001 | K92: 1881.032 | L92: -8.563 | M92: 1872.469 | N92: 540.861 | O92: 2418.798 | P92: 540.884 | Q92: 0 | R92: 1878.96 | S92: 1644.526
B93: 2011 | C93: 1191.27 | D93: 380.515 | E93: 305.354 | F93: 166.465 | G93: 71.386 | H93: 57.955 | I93: 9.969 | J93: -0.705 | K93: 1876.434 | L93: -3.784 | M93: 1872.65 | N93: 578.333 | O93: 2456.555 | P93: 556.723 | Q93: 0 | R93: 1900.476 | S93: 1672.213
B94: 2012 | C94: 1211.807 | D94: 386.188 | E94: 310.222 | F94: 178.179 | G94: 69.926 | H94: 53.007 | I94: 9.042 | J94: -1.036 | K94: 1907.181 | L94: 6.378 | M94: 1913.559 | N94: 582.729 | O94: 2499.35 | P94: 570.385 | Q94: 0 | R94: 1929.229 | S94: 1706.911
B95: 2013 | C95: 1242.448 | D95: 387.05 | E95: 320.303 | F95: 184.651 | G95: 77.388 | H95: 49.603 | I95: 8.512 | J95: 7.022 | K95: 1956.823 | L95: 6.784 | M95: 1963.607 | N95: 584.387 | O95: 2552.855 | P95: 588.884 | Q95: 0 | R95: 1963.807 | S95: 1740.343
B96: 2014 | C96: 1276.097 | D96: 397.069 | E96: 342.84 | F96: 194.883 | G96: 82.424 | H96: 55.58 | I96: 9.862 | J96: 6.071 | K96: 2022.077 | L96: 15.349 | M96: 2037.426 | N96: 590.26 | O96: 2646.112 | P96: 618.888 | Q96: 0 | R96: 2026.566 | S96: 1797.211
B97: 2015 | C97: 1312.213 | D97: 402.148 | E97: 367.34 | F97: 213.281 | G97: 87.743 | H97: 56.548 | I97: 9.646 | J97: 0.393 | K97: 2082.094 | L97: 12.105 | M97: 2094.199 | N97: 612.533 | O97: 2721.787 | P97: 649.558 | Q97: 0 | R97: 2071.561 | S97: 1831.364
B98: 2016 | C98: 1360.504 | D98: 404.984 | E98: 386.225 | F98: 227.965 | G98: 93.928 | H98: 54.579 | I98: 9.742 | J98: 1.599 | K98: 2153.312 | L98: 5.036 | M98: 2158.348 | N98: 629.527 | O98: 2786.771 | P98: 675.388 | Q98: 0 | R98: 2111.357 | S98: 1867.008
B99: 2017 | C99: 1385.378 | D99: 407.632 | E99: 399.752 | F99: 227.445 | G99: 102.153 | H99: 60.512 | I99: 9.612 | J99: 0.606 | K99: 2193.368 | L99: 13.307 | M99: 2206.675 | N99: 672.118 | O99: 2864.105 | P99: 696.761 | Q99: 0 | R99: 2167.415 | S99: 1919.054
B100: 2018 | C100: 1412.6 | D100: 410.171 | E100: 397.838 | F100: 223.77 | G100: 108.26 | H100: 60.511 | I100: 5.347 | J100: 3.137 | K100: 2223.746 | L100: 0.941 | M100: 2224.687 | N100: 692.86 | O100: 2916.14 | P100: 718.347 | Q100: 0 | R100: 2197.841 | S100: 1943.493
B101: 2019 | C101: 1427.94 | D101: 426.592 | E101: 406.423 | F101: 228.581 | G101: 109.909 | H101: 62.14 | I101: 5.7435985 | J101: 2.88 | K101: 2263.835 | L101: 1.262 | M101: 2265.097 | N101: 706.696 | O101: 2971.793 | P101: 737.872 | Q101: 0 | R101: 2233.921 | S101: 1978.192
... B110: 2028 | C110: 1529.7754 | D110: 516.75272 | E110: 431.27728 | F110: 243.67744 | G110: 113.25735 | H110: 67.827732 | I110: 6.5147616 | J110: -5.13 | K110: 2472.6754 | L110: 2.5476196 | M110: 2475.223 | N110: 721.5985 | O110: 3196.8215 | P110: 747.55672 | Q110: 19.028 | R110: 2468.2928 | S110: 2195.7429
B111: 2008-09 | C111: 1187.784 | D111: 377.339 | E111: 322.361 | F111: 175.387 | G111: 79.708 | H111: 58.955 | I111: 9.628 | J111: 0.012 | K111: 1887.496 | L111: -19.494 | M111: 1868.002 | N111: 543.298 | O111: 2413.802 | P111: 518.506 | Q111: 0 | R111: 1897.057 | S111: 1653.664
B112: 2009-10 | C112: 1172.216 | D112: 380.841 | E112: 291.087 | F112: 149.101 | G112: 68.312 | H112: 63.536 | I112: 10.756 | J112: 1.059 | K112: 1845.203 | L112: -27.833 | M112: 1817.37 | N112: 511.493 | O112: 2344.737 | P112: 504.347 | Q112: 0 | R112: 1842.255 | S112: 1607.266
B113: 2010-11 | C113: 1199.499 | D113: 382.218 | E113: 305.816 | F113: 157.857 | G113: 75.328 | H113: 62.987 | I113: 10.618 | J113: -1.944 | K113: 1885.589 | L113: -8.626 | M113: 1876.963 | N113: 555.074 | O113: 2434.524 | P113: 547.238 | Q113: 0 | R113: 1888.236 | S113: 1654.774
B114: 2011-12 | C114: 1192.115 | D114: 382.481 | E114: 308.087 | F114: 172.739 | G114: 70.143 | H114: 55.594 | I114: 9.64 | J114: -0.36 | K114: 1882.323 | L114: -6.242 | M114: 1876.081 | N114: 583.603 | O114: 2469.395 | P114: 562.558 | Q114: 0 | R114: 1907.289 | S114: 1680.39
B115: 2012-13 | C115: 1219.509 | D115: 383.864 | E115: 308.262 | F115: 177.636 | G115: 71.051 | H115: 50.724 | I115: 8.845 | J115: 1.689 | K115: 1913.324 | L115: 12.249 | M115: 1925.573 | N115: 578.781 | O115: 2503.373 | P115: 569.73 | Q115: 0 | R115: 1934.006 | S115: 1713.037
B116: 2013-14 | C116: 1251.056 | D116: 389.959 | E116: 328.218 | F116: 187.917 | G116: 79.759 | H116: 51.897 | I116: 8.542 | J116: 7.843 | K116: 1977.076 | L116: 4.264 | M116: 1981.34 | N116: 582.917 | O116: 2576.023 | P116: 596.666 | Q116: 0 | R116: 1978.95 | S116: 1753.086
B117: 2014-15 | C117: 1286.09 | D117: 397.794 | E117: 349.357 | F117: 200.346 | G117: 82.466 | H117: 56.077 | I117: 10.342 | J117: 7.428 | K117: 2040.669 | L117: 21.859 | M117: 2062.528 | N117: 596.564 | O117: 2674.223 | P117: 633.483 | Q117: 0 | R117: 2039.864 | S117: 1809.444
B118: 2015-16 | C118: 1323.968 | D118: 403.76 | E118: 371.051 | F118: 216.768 | G118: 89.667 | H118: 55.113 | I118: 9.42 | J118: -1.311 | K118: 2097.468 | L118: 7.486 | M118: 2104.954 | N118: 616.107 | O118: 2733.568 | P118: 651.515 | Q118: 0 | R118: 2081.524 | S118: 1838.471
B119: 2016-17 | C119: 1368.575 | D119: 405.169 | E119: 390.464 | F119: 228.363 | G119: 96.898 | H119: 55.373 | I119: 9.834 | J119: -0.129 | K119: 2164.079 | L119: 9.618 | M119: 2173.697 | N119: 638.633 | O119: 2805.016 | P119: 680.972 | Q119: 0 | R119: 2124.11 | S119: 1879.97
B120: 2017-18 | C120: 1391.8 | D120: 408.182 | E120: 401.053 | F120: 226.789 | G120: 103.486 | H120: 62.242 | I120: 8.527 | J120: 1.596 | K120: 2202.631 | L120: 7.439 | M120: 2210.07 | N120: 680.185 | O120: 2880.648 | P120: 702.211 | Q120: 0 | R120: 2178.537 | S120: 1927.785
...

Sheet OBR_MAR24_1.2
A1: Back to contents
B2: 1.2 GDP expenditure components (£ billion current prices, seasonally adjusted) | S2: Deflators
C3: Private consumption | D3: Government consumption | E3: Fixed investment | G3: Net acquisition of valuables | H3: Final domestic demand | I3: Change in inventories | J3: Total domestic demand | K3: Exports | L3: Total final expenditure | M3: Imports | N3: Statistical discrepancy | O3: GDP at market prices | P3: Gross national income | S3: C | T3: GC | U3: IF | V3: X | W3: M | X3: GDP | Z3: C | AA3: GC | AB3: IF | AC3: X | AD3: M | AE3: GDP
E4: of which: | F4: General government
B5: 2008Q1 | C5: 255.438 | D5: 80.007 | E5: 71.229 | F5: 12.058 | G5: 0.277 | H5: 406.951 | I5: -0.163 | J5: 406.788 | K5: 104.955 | L5: 511.743 | M5: 114.195 | N5: 0 | O5: 397.548 | P5: 396.936 | S5: =100*(C5/OBR_MAR24_1.1!C5) -> 82.906421 | T5: =100*(D5/OBR_MAR24_1.1!D5) -> 85.731277 | U5: =100*(E5/OBR_MAR24_1.1!E5) -> 83.949933 | V5: =100*(K5/OBR_MAR24_1.1!N5) -> 74.815021 | W5: =100*(M5/OBR_MAR24_1.1!P5) -> 83.291394 | X5: =100*(O5/OBR_MAR24_1.1!R5) -> 81.168191
B6: 2008Q2 | C6: 256.141 | D6: 80.199 | E6: 72.373 | F6: 11.633 | G6: -0.087 | H6: 408.626 | I6: 0.83 | J6: 409.456 | K6: 110.409 | L6: 519.865 | M6: 118.984 | N6: 0 | O6: 400.881 | P6: 396.091 | S6: =100*(C6/OBR_MAR24_1.1!C6) -> 84.120213 | T6: =100*(D6/OBR_MAR24_1.1!D6) -> 86.479113 | U6: =100*(E6/OBR_MAR24_1.1!E6) -> 84.351799 | V6: =100*(K6/OBR_MAR24_1.1!N6) -> 78.692135 | W6: =100*(M6/OBR_MAR24_1.1!P6) -> 87.325784 | X6: =100*(O6/OBR_MAR24_1.1!R6) -> 82.251234 | AA6: =100*((T6/T5)-1) -> 0.87230219
B7: 2008Q3 | C7: 255.819 | D7: 81.155 | E7: 69.19 | F7: 11.875 | G7: -0.658 | H7: 405.506 | I7: 0.855 | J7: 406.361 | K7: 113.34 | L7: 519.701 | M7: 119.731 | N7: 0 | O7: 399.97 | P7: 395.566 | S7: =100*(C7/OBR_MAR24_1.1!C7) -> 85.377445 | T7: =100*(D7/OBR_MAR24_1.1!D7) -> 85.972012 | U7: =100*(E7/OBR_MAR24_1.1!E7) -> 85.080482 | V7: =100*(K7/OBR_MAR24_1.1!N7) -> 80.470869 | W7: =100*(M7/OBR_MAR24_1.1!P7) -> 89.477696 | X7: =100*(O7/OBR_MAR24_1.1!R7) -> 83.34931 | AA7: =100*((T7/T6)-1) -> -0.58638596
B8: 2008Q4 | C8: 247.924 | D8: 83.414 | E8: 68.46 | F8: 12.733 | G8: 0.279 | H8: 400.077 | I8: -2.203 | J8: 397.874 | K8: 109.631 | L8: 507.505 | M8: 112.304 | N8: 0 | O8: 395.201 | P8: 383.976 | S8: =100*(C8/OBR_MAR24_1.1!C8) -> 84.79716 | T8: =100*(D8/OBR_MAR24_1.1!D8) -> 87.434226 | U8: =100*(E8/OBR_MAR24_1.1!E8) -> 85.59854 | V8: =100*(K8/OBR_MAR24_1.1!N8) -> 80.953893 | W8: =100*(M8/OBR_MAR24_1.1!P8) -> 88.62094 | X8: =100*(O8/OBR_MAR24_1.1!R8) -> 84.1401 | AA8: =100*((T8/T7)-1) -> 1.7008022
B9: 2009Q1 | C9: 247.707 | D9: 84.238 | E9: 65.081 | F9: 13.271 | G9: 1.281 | H9: 398.307 | I9: -6.857 | J9: 391.45 | K9: 103.636 | L9: 495.086 | M9: 108.347 | N9: 0 | O9: 386.739 | P9: 379.763 | S9: =100*(C9/OBR_MAR24_1.1!C9) -> 85.039686 | T9: =100*(D9/OBR_MAR24_1.1!D9) -> 88.856775 | U9: =100*(E9/OBR_MAR24_1.1!E9) -> 86.473738 | V9: =100*(K9/OBR_MAR24_1.1!N9) -> 81.781523 | W9: =100*(M9/OBR_MAR24_1.1!P9) -> 89.014772 | X9: =100*(O9/OBR_MAR24_1.1!R9) -> 84.054509 | AA9: =100*((T9/T8)-1) -> 1.6269939
B10: 2009Q2 | C10: 248.136 | D10: 84.184 | E10: 62.025 | F10: 12.265 | G10: 0.516 | H10: 394.861 | I10: -3.785 | J10: 391.076 | K10: 101.716 | L10: 492.792 | M10: 106.228 | N10: 0 | O10: 386.564 | P10: 380.724 | S10: =100*(C10/OBR_MAR24_1.1!C10) -> 85.237883 | T10: =100*(D10/OBR_MAR24_1.1!D10) -> 89.023307 | U10: =100*(E10/OBR_MAR24_1.1!E10) -> 86.070522 | V10: =100*(K10/OBR_MAR24_1.1!N10) -> 81.100303 | W10: =100*(M10/OBR_MAR24_1.1!P10) -> 87.065708 | X10: =100*(O10/OBR_MAR24_1.1!R10) -> 84.292377 | AA10: =100*((T10/T9)-1) -> 0.18741598
B11: 2009Q3 | C11: 249.481 | D11: 86.207 | E11: 62.265 | F11: 13.498 | G11: 0.57 | H11: 398.523 | I11: -3.917 | J11: 394.606 | K11: 102.632 | L11: 497.238 | M11: 108.614 | N11: 0 | O11: 388.624 | P11: 389.479 | S11: =100*(C11/OBR_MAR24_1.1!C11) -> 85.225052 | T11: =100*(D11/OBR_MAR24_1.1!D11) -> 90.39974 | U11: =100*(E11/OBR_MAR24_1.1!E11) -> 85.822387 | V11: =100*(K11/OBR_MAR24_1.1!N11) -> 82.218733 | W11: =100*(M11/OBR_MAR24_1.1!P11) -> 86.675551 | X11: =100*(O11/OBR_MAR24_1.1!R11) -> 84.690602 | AA11: =100*((T11/T10)-1) -> 1.546149
B12: 2009Q4 | C12: 250.34 | D12: 85.942 | E12: 60.697 | F12: 13.189 | G12: -0.013 | H12: 396.966 | I12: -6.071 | J12: 390.895 | K12: 108.358 | L12: 499.253 | M12: 112.378 | N12: 0 | O12: 386.875 | P12: 385.824 | S12: =100*(C12/OBR_MAR24_1.1!C12) -> 84.887202 | T12: =100*(D12/OBR_MAR24_1.1!D12) -> 89.420456 | U12: =100*(E12/OBR_MAR24_1.1!E12) -> 85.087264 | V12: =100*(K12/OBR_MAR24_1.1!N12) -> 82.929368 | W12: =100*(M12/OBR_MAR24_1.1!P12) -> 88.243424 | X12: =100*(O12/OBR_MAR24_1.1!R12) -> 84.059769 | AA12: =100*((T12/T11)-1) -> -1.0832821
B13: 2010Q1 | C13: 249.159 | D13: 86.856 | E13: 63.512 | F13: 13.272 | G13: -0.221 | H13: 399.306 | I13: 1.601 | J13: 400.907 | K13: 110.685 | L13: 511.592 | M13: 115.479 | N13: 0 | O13: 396.113 | P13: 396.248 | S13: =100*(C13/OBR_MAR24_1.1!C13) -> 84.902459 | T13: =100*(D13/OBR_MAR24_1.1!D13) -> 91.615421 | U13: =100*(E13/OBR_MAR24_1.1!E13) -> 84.527137 | V13: =100*(K13/OBR_MAR24_1.1!N13) -> 84.762831 | W13: =100*(M13/OBR_MAR24_1.1!P13) -> 89.051258 | X13: =100*(O13/OBR_MAR24_1.1!R13) -> 85.269394 | AA13: =100*((T13/T12)-1) -> 2.4546569
B14: 2010Q2 | C14: 257.449 | D14: 86.19 | E14: 62.846 | F14: 12.714 | G14: -0.362 | H14: 406.123 | I14: 0.261 | J14: 406.384 | K14: 115.919 | L14: 522.303 | M14: 120.992 | N14: 0 | O14: 401.311 | P14: 401.775 | S14: =100*(C14/OBR_MAR24_1.1!C14) -> 85.647323 | T14: =100*(D14/OBR_MAR24_1.1!D14) -> 90.609001 | U14: =100*(E14/OBR_MAR24_1.1!E14) -> 84.901786 | V14: =100*(K14/OBR_MAR24_1.1!N14) -> 85.9334 | W14: =100*(M14/OBR_MAR24_1.1!P14) -> 90.437642 | X14: =100*(O14/OBR_MAR24_1.1!R14) -> 85.456958 | AA14: =100*((T14/T13)-1) -> -1.098527
B15: 2010Q3 | C15: 259.351 | D15: 85.911 | E15: 65.226 | F15: 13.003 | G15: 0.447 | H15: 410.935 | I15: 1.096 | J15: 412.031 | K15: 116.698 | L15: 528.729 | M15: 124.53 | N15: 0 | O15: 404.199 | P15: 403.675 | S15: =100*(C15/OBR_MAR24_1.1!C15) -> 86.208662 | T15: =100*(D15/OBR_MAR24_1.1!D15) -> 90.302406 | U15: =100*(E15/OBR_MAR24_1.1!E15) -> 84.820349 | V15: =100*(K15/OBR_MAR24_1.1!N15) -> 85.612836 | W15: =100*(M15/OBR_MAR24_1.1!P15) -> 90.171175 | X15: =100*(O15/OBR_MAR24_1.1!R15) -> 85.599292 | AA15: =100*((T15/T14)-1) -> -0.33837143
B16: 2010Q4 | C16: 261.157 | D16: 87.359 | E16: 66.706 | F16: 12.588 | G16: 0.574 | H16: 415.796 | I16: -1.483 | J16: 414.313 | K16: 120.874 | L16: 535.187 | M16: 128.257 | N16: 0 | O16: 406.93 | P16: 407.562 | S16: =100*(C16/OBR_MAR24_1.1!C16) -> 86.953207 | T16: =100*(D16/OBR_MAR24_1.1!D16) -> 91.288037 | U16: =100*(E16/OBR_MAR24_1.1!E16) -> 84.466843 | V16: =100*(K16/OBR_MAR24_1.1!N16) -> 86.912192 | W16: =100*(M16/OBR_MAR24_1.1!P16) -> 92.06061 | X16: =100*(O16/OBR_MAR24_1.1!R16) -> 86.102342 | AA16: =100*((T16/T15)-1) -> 1.0914782
B17: 2011Q1 | C17: 263.602 | D17: 89.47 | E17: 64.274 | F17: 13.122 | G17: -1.752 | H17: 415.594 | I17: -1.655 | J17: 413.939 | K17: 128.717 | L17: 542.656 | M17: 127.924 | N17: 0 | O17: 414.732 | P17: 416.433 | S17: =100*(C17/OBR_MAR24_1.1!C17) -> 88.53905 | T17: =100*(D17/OBR_MAR24_1.1!D17) -> 92.944256 | U17: =100*(E17/OBR_MAR24_1.1!E17) -> 84.657938 | V17: =100*(K17/OBR_MAR24_1.1!N17) -> 88.896025 | W17: =100*(M17/OBR_MAR24_1.1!P17) -> 94.040329 | X17: =100*(O17/OBR_MAR24_1.1!R17) -> 87.529626 | AA17: =100*((T17/T16)-1) -> 1.8142784
... B55: 2020Q3 | C55: 319.136 | D55: 121.322 | E55: 92.349 | F55: 16.901 | G55: 1.172 | H55: 533.979 | I55: -0.951 | J55: 533.028 | K55: 147.825 | L55: 680.853 | M55: 147.185 | N55: 0 | O55: 533.668 | P55: 527.792 | S55: =100*(C55/OBR_MAR24_1.1!C55) -> 100.72307 | T55: =100*(D55/OBR_MAR24_1.1!D55) -> 121.40213 | U55: =100*(E55/OBR_MAR24_1.1!E55) -> 101.75526 | V55: =100*(K55/OBR_MAR24_1.1!N55) -> 99.277372 | W55: =100*(M55/OBR_MAR24_1.1!P55) -> 97.882542 | X55: =100*(O55/OBR_MAR24_1.1!R55) -> 105.12663 | AA55: =100*((T55/T54)-1) -> -15.407269
B56: 2020Q4 | C56: 314.018 | D56: 123.948 | E56: 96.772 | F56: 17.161 | G56: 7.662 | H56: 542.4 | I56: 10.552 | J56: 552.952 | K56: 158.181 | L56: 711.133 | M56: 172.439 | N56: 0 | O56: 538.694 | P56: 530.241 | S56: =100*(C56/OBR_MAR24_1.1!C56) -> 100.71814 | T56: =100*(D56/OBR_MAR24_1.1!D56) -> 118.23151 | U56: =100*(E56/OBR_MAR24_1.1!E56) -> 100.65005 | V56: =100*(K56/OBR_MAR24_1.1!N56) -> 100.37439 | W56: =100*(M56/OBR_MAR24_1.1!P56) -> 100.12774 | X56: =100*(O56/OBR_MAR24_1.1!R56) -> 104.69612 | Z56: =100*((S56/S55)-1) -> -0.0048942098 | AA56: =100*((T56/T55)-1) -> -2.6116666
