Workbook
Name _DLX1.INC: HAVERM!$I$1:$BB$6
Name _DLX2.INC: 'HAVER - UK Electricity'!$B$2:$DB$7
Name _DLX3.INC: 'HAVER - UK Gas'!$B$2:$DB$7
Name _DLX4.INC: HAVERM!$A$1:$F$6
Name _DLX5.INC: 'BoE feb MPR'!$O$1:$U$6
Name Annual_Data: '$template-default'!$A$1:$A$2
Name Annual_Data: GMW!$A$1:$A$2

Sheet Chart data
A1: Food price chart >>> | G1: m/m food seasonality chart >>> | S1: Gas futures prices chart >>> | Y1: =(Z299/Y298)-1 -> -0.16051506 | AE1: OE vs BoE inflation forecast chart >>>
A3: Date | B3: UK food price inflation (LHS) | C3: UK food producer input prices (adv 6 months, LHS) | D3: Global UN food price inflation (adv 6 months, RHS) | E3: Zero line | G3: Date | H3: 2024 | I3: 2023 | J3: 2022 | K3: 2010-2019 average | L3: 2010-2019 min | M3: 2010-2019 max | N3: 2010-2019 range | S3: Date | T3: Month | U3: Pence per therm | V3: Jul-2023 price cap | W3: Oct-2023 price cap | X3: Jan-2024 price cap | Y3: Apr-2024 price cap | Z3: Jul-2024 price cap | AB3: Average of observation window | AC3: Price cap period | AE3: Date | AF3: Oxford Economics - latest | AG3: Bank of England - February projections | AH3: modal fcast | AI3: 2% line | AK3: Date | AL3: Food | AM3: Petrol | AN3: Energy | AO3: Other goods | AP3: Services | AQ3: CPI | AR3: 2% line
A4: 40909 | B4: =HAVERM!K151 -> 3.4920635 | C4: =((HAVERM!M145/HAVERM!M133)-1)*100 -> 11.567568 | D4: =((HAVERM!R144/HAVERM!R132)-1)*100 -> 28.292691 | E4: 0 | G4: Jan | H4: =HAVERM!L295 -> -0.37009623 | I4: =HAVERM!L283 -> 0.55955236 | J4: =HAVERM!L271 -> 0.65359477 | K4: =AVERAGE(H20:Q20) -> -0.13281103 | L4: =MIN(H20:Q20) -> -0.68627451 | M4: =MAX(H20:Q20) -> 0.20429009 | N4: =M4-L4 -> 0.8905646 | S4: 44928 | T4: Jan | U4: =IF('HAVER - UK Gas'!H1574="",C1286,AVERAGE('HAVER - UK Gas'!H1574:Q1574)) -> 204.88 | AE4: 43831 | AF4: ='[1]CPI Forecast'!D294 -> 1.7692706 | AG4: =NA() -> #N/A | AH4: =NA() -> #N/A | AI4: 2 | AK4: 43466 | AL4: =[1]Contributions!C255 -> 0.25967276 | AM4: =[1]Contributions!D255 -> 0.022038567 | AN4: =[1]Contributions!E255 -> 0.049180328 | AO4: =[1]Contributions!H255 -> 0.3144532 | AP4: =[1]Contributions!I255 -> 1.2240339 | AQ4: =[1]Contributions!G255 -> 1.847949 | AR4: 2
A5: 40940 | B5: =HAVERM!K152 -> 3.6649215 | C5: =((HAVERM!M146/HAVERM!M134)-1)*100 -> 9.9465241 | D5: =((HAVERM!R145/HAVERM!R133)-1)*100 -> 26.222165 | E5: 0 | G5: Feb | H5: =HAVERM!L296 -> 0.22288262 | I5: =HAVERM!L284 -> 2.1462639 | J5: =HAVERM!L272 -> 1.0204082 | K5: =AVERAGE(H21:Q21) -> 0.59831851 | L5: =MIN(H21:Q21) -> -0.29615005 | M5: =MAX(H21:Q21) -> 1.2269939 | N5: =M5-L5 -> 1.5231439 | S5: 44929 | T5: Jan | U5: =IF('HAVER - UK Gas'!H1575="",C1287,AVERAGE('HAVER - UK Gas'!H1575:Q1575)) -> 183.035 | AE5: 43862 | AF5: ='[1]CPI Forecast'!D295 -> 1.7095297 | AG5: =NA() -> #N/A | AH5: =NA() -> #N/A | AI5: 2 | AK5: 43497 | AL5: =[1]Contributions!C256 -> 0.32713694 | AM5: =[1]Contributions!D256 -> 0.017187141 | AN5: =[1]Contributions!E256 -> 0.054936997 | AO5: =[1]Contributions!H256 -> 0.35977537 | AP5: =[1]Contributions!I256 -> 1.1728362 | AQ5: =[1]Contributions!G256 -> 1.8692837 | AR5: 2
A6: 40969 | B6: =HAVERM!K153 -> 4.5647558 | C6: =((HAVERM!M147/HAVERM!M135)-1)*100 -> 10.127932 | D6: =((HAVERM!R146/HAVERM!R134)-1)*100 -> 19.42735 | E6: 0 | G6: Mar | H6: =NA() -> #N/A | I6: =HAVERM!L285 -> 1.0894942 | J6: =HAVERM!L273 -> 0.091827365 | K6: =AVERAGE(H22:Q22) -> -0.25212978 | L6: =MIN(H22:Q22) -> -1.3612565 | M6: =MAX(H22:Q22) -> 0.40444894 | N6: =M6-L6 -> 1.7657055 | S6: 44930 | T6: Jan | U6: =IF('HAVER - UK Gas'!H1576="",C1288,AVERAGE('HAVER - UK Gas'!H1576:Q1576)) -> 202.814 | AE6: 43891 | AF6: ='[1]CPI Forecast'!D296 -> 1.5233075 | AG6: =NA() -> #N/A | AH6: =NA() -> #N/A | AI6: 2 | AK6: 43525 | AL6: =[1]Contributions!C257 -> 0.28591248 | AM6: =[1]Contributions!D257 -> 0.087241062 | AN6: =[1]Contributions!E257 -> 0.051600078 | AO6: =[1]Contributions!H257 -> 0.36155217 | AP6: =[1]Contributions!I257 -> 1.1708768 | AQ6: =[1]Contributions!G257 -> 1.9076009 | AR6: 2
A7: 41000 | B7: =HAVERM!K154 -> 4.3478261 | C7: =((HAVERM!M148/HAVERM!M136)-1)*100 -> 8.2809224 | D7: =((HAVERM!R147/HAVERM!R135)-1)*100 -> 12.801946 | E7: 0 | G7: Apr | H7: =NA() -> #N/A | I7: =HAVERM!L286 -> 1.3856813 | J7: =HAVERM!L274 -> 1.559633 | K7: =AVERAGE(H23:Q23) -> -0.02421449 | L7: =MIN(H23:Q23) -> -0.48123195 | M7: =MAX(H23:Q23) -> 0.68493151 | N7: =M7-L7 -> 1.1661635 | S7: 44931 | T7: Jan | U7: =IF('HAVER - UK Gas'!H1577="",C1289,AVERAGE('HAVER - UK Gas'!H1577:Q1577)) -> 197.436 | AE7: 43922 | AF7: ='[1]CPI Forecast'!D297 -> 0.76742263 | AG7: =NA() -> #N/A | AH7: =NA() -> #N/A | AI7: 2 | AK7: 43556 | AL7: =[1]Contributions!C258 -> 0.23115496 | AM7: =[1]Contributions!D258 -> 0.13025484 | AN7: =[1]Contributions!E258 -> 0.32590659 | AO7: =[1]Contributions!H258 -> 0.047641725 | AP7: =[1]Contributions!I258 -> 1.3872623 | AQ7: =[1]Contributions!G258 -> 2.117627 | AR7: 2
A8: 41030 | B8: =HAVERM!K155 -> 3.3507853 | C8: =((HAVERM!M149/HAVERM!M137)-1)*100 -> 8.125 | D8: =((HAVERM!R148/HAVERM!R136)-1)*100 -> 5.3369843 | E8: 0 | G8: May | H8: =NA() -> #N/A | I8: =HAVERM!L287 -> 0.91116173 | J8: =HAVERM!L275 -> 1.535682 | K8: =AVERAGE(H24:Q24) -> -0.01028101 | L8: =MIN(H24:Q24) -> -1.0638298 | M8: =MAX(H24:Q24) -> 1.2725345 | N8: =M8-L8 -> 2.3363643 | S8: 44932 | T8: Jan | U8: =IF('HAVER - UK Gas'!H1578="",C1290,AVERAGE('HAVER - UK Gas'!H1578:Q1578)) -> 205.748 | AE8: 43952 | AF8: ='[1]CPI Forecast'!D298 -> 0.47986067 | AG8: =NA() -> #N/A | AH8: =NA() -> #N/A | AI8: 2 | AK8: 43586 | AL8: =[1]Contributions!C259 -> 0.22997911 | AM8: =[1]Contributions!D259 -> 0.10253856 | AN8: =[1]Contributions!E259 -> 0.32437309 | AO8: =[1]Contributions!H259 -> 0.161432 | AP8: =[1]Contributions!I259 -> 1.203002 | AQ8: =[1]Contributions!G259 -> 2.020603 | AR8: 2
A9: 41061 | B9: =HAVERM!K156 -> 2.1761658 | C9: =((HAVERM!M150/HAVERM!M138)-1)*100 -> 6.4351379 | D9: =((HAVERM!R149/HAVERM!R137)-1)*100 -> 2.6213397 | E9: 0 | G9: Jun | H9: =NA() -> #N/A | I9: =HAVERM!L288 -> 0.37622272 | J9: =HAVERM!L276 -> 1.1565836 | K9: =AVERAGE(H25:Q25) -> -0.065925175 | L9: =MIN(H25:Q25) -> -0.49067713 | M9: =MAX(H25:Q25) -> 1.0471204 | N9: =M9-L9 -> 1.5377976 | S9: =+S4+7 -> 44935 | T9: Jan | U9: =IF('HAVER - UK Gas'!H1579="",C1291,AVERAGE('HAVER - UK Gas'!H1579:Q1579)) -> 196.433 | AE9: 43983 | AF9: ='[1]CPI Forecast'!D299 -> 0.60315196 | AG9: =NA() -> #N/A | AH9: =NA() -> #N/A | AI9: 2 | AK9: 43617 | AL9: =[1]Contributions!C260 -> 0.31087954 | AM9: =[1]Contributions!D260 -> 0.018591026 | AN9: =[1]Contributions!E260 -> 0.24701496 | AO9: =[1]Contributions!H260 -> 0.23588458 | AP9: =[1]Contributions!I260 -> 1.2020789 | AQ9: =[1]Contributions!G260 -> 2.0054626 | AR9: 2
A10: 41091 | B10: =HAVERM!K157 -> 2.1716649 | C10: =((HAVERM!M151/HAVERM!M139)-1)*100 -> 4.7331319 | D10: =((HAVERM!R150/HAVERM!R138)-1)*100 -> -4.2907793 | E10: 0 | G10: Jul | H10: =NA() -> #N/A | I10: =HAVERM!L289 -> 0.074962519 | J10: =HAVERM!L277 -> 2.2867194 | K10: =AVERAGE(H26:Q26) -> 0.069648957 | L10: =MIN(H26:Q26) -> -0.69860279 | M10: =MAX(H26:Q26) -> 0.99778271 | N10: =M10-L10 -> 1.6963855 | S10: =+S5+7 -> 44936 | T10: Jan | U10: =IF('HAVER - UK Gas'!H1580="",C1292,AVERAGE('HAVER - UK Gas'!H1580:Q1580)) -> 187.879 | AE10: 44013 | AF10: ='[1]CPI Forecast'!D300 -> 1.0403061 | AG10: =NA() -> #N/A | AH10: =NA() -> #N/A | AI10: 2 | AK10: 43647 | AL10: =[1]Contributions!C261 -> 0.29741971 | AM10: =[1]Contributions!D261 -> 0.0024687872 | AN10: =[1]Contributions!E261 -> 0.19884962 | AO10: =[1]Contributions!H261 -> 0.38893211 | AP10: =[1]Contributions!I261 -> 1.2007321 | AQ10: =[1]Contributions!G261 -> 2.0610954 | AR10: 2
A11: 41122 | B11: =HAVERM!K158 -> 2.1671827 | C11: =((HAVERM!M152/HAVERM!M140)-1)*100 -> 4.1874377 | D11: =((HAVERM!R151/HAVERM!R139)-1)*100 -> -6.8841632 | E11: 0 | G11: Aug | H11: =NA() -> #N/A | I11: =HAVERM!L290 -> 0.37453184 | J11: =HAVERM!L278 -> 1.4617369 | K11: =AVERAGE(H27:Q27) -> 0.20020714 | L11: =MIN(H27:Q27) -> -0.19569472 | M11: =MAX(H27:Q27) -> 0.58195926 | N11: =M11-L11 -> 0.77765398 | S11: =+S6+7 -> 44937 | T11: Jan | U11: =IF('HAVER - UK Gas'!H1581="",C1293,AVERAGE('HAVER - UK Gas'!H1581:Q1581)) -> 189.916 | AE11: 44044 | AF11: ='[1]CPI Forecast'!D301 -> 0.21960784 | AG11: =NA() -> #N/A | AH11: =NA() -> #N/A | AI11: 2 | AK11: 43678 | AL11: =[1]Contributions!C262 -> 0.30735609 | AM11: =[1]Contributions!D262 -> -0.0091266104 | AN11: =[1]Contributions!E262 -> 0.20035491 | AO11: =[1]Contributions!H262 -> 0.10015742 | AP11: =[1]Contributions!I262 -> 1.1017182 | AQ11: =[1]Contributions!G262 -> 1.7242674 | AR11: 2
A12: 41153 | B12: =HAVERM!K159 -> 1.9567456 | C12: =((HAVERM!M153/HAVERM!M141)-1)*100 -> 2.9498525 | D12: =((HAVERM!R152/HAVERM!R140)-1)*100 -> -6.978313 | E12: 0 | G12: Sep | H12: =NA() -> #N/A | I12: =HAVERM!L291 -> -0.14925373 | J12: =HAVERM!L279 -> 1.1016949 | K12: =AVERAGE(H28:Q28) -> 0.063265634 | L12: =MIN(H28:Q28) -> -0.19627085 | M12: =MAX(H28:Q28) -> 0.80482897 | N12: =M12-L12 -> 1.0010998 | S12: =+S7+7 -> 44938 | T12: Jan | U12: =IF('HAVER - UK Gas'!H1582="",C1294,AVERAGE('HAVER - UK Gas'!H1582:Q1582)) -> 183.519 | AE12: 44075 | AF12: ='[1]CPI Forecast'!D302 -> 0.53190018 | AG12: =NA() -> #N/A | AH12: =NA() -> #N/A | AI12: 2 | AK12: 43709 | AL12: =[1]Contributions!C263 -> 0.29412248 | AM12: =[1]Contributions!D263 -> -0.072719435 | AN12: =[1]Contributions!E263 -> 0.14559002 | AO12: =[1]Contributions!H263 -> 0.16419639 | AP12: =[1]Contributions!I263 -> 1.1905117 | AQ12: =[1]Contributions!G263 -> 1.7149555 | AR12: 2
A13: 41183 | B13: =HAVERM!K160 -> 3.4303534 | C13: =((HAVERM!M154/HAVERM!M142)-1)*100 -> 2.0368574 | D13: =((HAVERM!R153/HAVERM!R141)-1)*100 -> -4.3355408 | E13: 0 | G13: Oct | H13: =NA() -> #N/A | I13: =HAVERM!L292 -> 0.14947683 | J13: =HAVERM!L280 -> 2.0117351 | K13: =AVERAGE(H29:Q29) -> -0.1081351 | L13: =MIN(H29:Q29) -> -0.92687951 | M13: =MAX(H29:Q29) -> 0.50505051 | N13: =M13-L13 -> 1.43193 | S13: =+S8+7 -> 44939 | T13: Jan | U13: =IF('HAVER - UK Gas'!H1583="",C1295,AVERAGE('HAVER - UK Gas'!H1583:Q1583)) -> 160.836 | AE13: 44105 | AF13: ='[1]CPI Forecast'!D303 -> 0.69715046 | AG13: =NA() -> #N/A | AH13: =NA() -> #N/A | AI13: 2 | AK13: 43739 | AL13: =[1]Contributions!C264 -> 0.26808715 | AM13: =[1]Contributions!D264 -> -0.11127734 | AN13: =[1]Contributions!E264 -> -0.081176493 | AO13: =[1]Contributions!H264 -> 0.19533852 | AP13: =[1]Contributions!I264 -> 1.2339005 | AQ13: =[1]Contributions!G264 -> 1.4643744 | AR13: 2
A14: 41214 | B14: =HAVERM!K161 -> 3.9256198 | C14: =((HAVERM!M155/HAVERM!M143)-1)*100 -> 1.3500482 | D14: =((HAVERM!R154/HAVERM!R142)-1)*100 -> -6.4065877 | E14: 0 | G14: Nov | H14: =NA() -> #N/A | I14: =HAVERM!L293 -> 0.29850746 | J14: =HAVERM!L281 -> 1.1503698 | K14: =AVERAGE(H30:Q30) -> 0.50448327 | L14: =MIN(H30:Q30) -> -0.19627085 | M14: =MAX(H30:Q30) -> 1.5267176 | N14: =M14-L14 -> 1.7229884 | S14: =+S9+7 -> 44942 | T14: Jan | U14: =IF('HAVER - UK Gas'!H1584="",C1296,AVERAGE('HAVER - UK Gas'!H1584:Q1584)) -> 170.941 | AE14: 44136 | AF14: ='[1]CPI Forecast'!D304 -> 0.31506509 | AG14: =NA() -> #N/A | AH14: =NA() -> #N/A | AI14: 2 | AK14: 43770 | AL14: =[1]Contributions!C265 -> 0.27924808 | AM14: =[1]Contributions!D265 -> -0.096602573 | AN14: =[1]Contributions!E265 -> -0.074597789 | AO14: =[1]Contributions!H265 -> 0.16802979 | AP14: =[1]Contributions!I265 -> 1.1872287 | AQ14: =[1]Contributions!G265 -> 1.4742176 | AR14: 2
A15: 41244 | B15: =HAVERM!K162 -> 3.7716616 | C15: =((HAVERM!M156/HAVERM!M144)-1)*100 -> 2.3121387 | D15: =((HAVERM!R155/HAVERM!R143)-1)*100 -> -9.2371197 | E15: 0 | G15: Dec | H15: =NA() -> #N/A | I15: =HAVERM!L294 -> 0.52083333 | J15: =HAVERM!L282 -> 1.6246954 | K15: =AVERAGE(H31:Q31) -> 0.75041757 | L15: =MIN(H31:Q31) -> -0.2016129 | M15: =MAX(H31:Q31) -> 1.6111708 | N15: =M15-L15 -> 1.8127837 | S15: =+S10+7 -> 44943 | T15: Jan | U15: =IF('HAVER - UK Gas'!H1585="",C1297,AVERAGE('HAVER - UK Gas'!H1585:Q1585)) -> 173.819 | AE15: 44166 | AF15: ='[1]CPI Forecast'!D305 -> 0.58876645 | AG15: =NA() -> #N/A | AH15: =NA() -> #N/A | AI15: 2 | AK15: 43800 | AL15: =[1]Contributions!C266 -> 0.23858853 | AM15: =[1]Contributions!D266 -> 0.028714951 | AN15: =[1]Contributions!E266 -> -0.068093901 | AO15: =[1]Contributions!H266 -> 0.047240213 | AP15: =[1]Contributions!I266 -> 1.0078178 | AQ15: =[1]Contributions!G266 -> 1.3020712 | AR15: 2
A16: 41275 | B16: =HAVERM!K163 -> 4.192229 | C16: =((HAVERM!M157/HAVERM!M145)-1)*100 -> 2.3255814 | D16: =((HAVERM!R156/HAVERM!R144)-1)*100 -> -11.040591 | E16: 0 | S16: =+S11+7 -> 44944 | T16: Jan | U16: =IF('HAVER - UK Gas'!H1586="",C1298,AVERAGE('HAVER - UK Gas'!H1586:Q1586)) -> 172.696 | AE16: 44197 | AF16: ='[1]CPI Forecast'!D306 -> 0.70058043 | AG16: =NA() -> #N/A | AH16: =NA() -> #N/A | AI16: 2 | AK16: 43831 | AL16: =[1]Contributions!C267 -> 0.21172023 | AM16: =[1]Contributions!D267 -> 0.14220602 | AN16: =[1]Contributions!E267 -> 0.16311787 | AO16: =[1]Contributions!H267 -> 0.083346322 | AP16: =[1]Contributions!I267 -> 1.0983456 | AQ16: =[1]Contributions!G267 -> 1.7692706 | AR16: 2
A17: 41306 | B17: =HAVERM!K164 -> 3.6363636 | C17: =((HAVERM!M158/HAVERM!M146)-1)*100 -> 3.0155642 | D17: =((HAVERM!R157/HAVERM!R145)-1)*100 -> -5.0628427 | E17: 0 | S17: =+S12+7 -> 44945 | T17: Jan | U17: =IF('HAVER - UK Gas'!H1587="",C1299,AVERAGE('HAVER - UK Gas'!H1587:Q1587)) -> 187.973 | AE17: 44228 | AF17: ='[1]CPI Forecast'!D307 -> 0.41421589 | AG17: =NA() -> #N/A | AH17: =NA() -> #N/A | AI17: 2 | AK17: 43862 | AL17: =[1]Contributions!C268 -> 0.14481804 | AM17: =[1]Contributions!D268 -> 0.081385655 | AN17: =[1]Contributions!E268 -> 0.13454013 | AO17: =[1]Contributions!H268 -> -0.027200463 | AP17: =[1]Contributions!I268 -> 1.1904598 | AQ17: =[1]Contributions!G268 -> 1.7095297 | AR17: 2
A18: 41334 | B18: =HAVERM!K165 -> 3.7563452 | C18: =((HAVERM!M159/HAVERM!M147)-1)*100 -> 2.7105518 | D18: =((HAVERM!R158/HAVERM!R146)-1)*100 -> -6.5663908 | E18: 0 | S18: =+S13+7 -> 44946 | T18: Jan | U18: =IF('HAVER - UK Gas'!H1588="",C1300,AVERAGE('HAVER - UK Gas'!H1588:Q1588)) -> 186.824 | AE18: 44256 | AF18: ='[1]CPI Forecast'!D308 -> 0.71432517 | AG18: =NA() -> #N/A | AH18: =NA() -> #N/A | AI18: 2 | AK18: 43891 | AL18: =[1]Contributions!C269 -> 0.19696619 | AM18: =[1]Contributions!D269 -> -0.071410361 | AN18: =[1]Contributions!E269 -> 0.11918783 | AO18: =[1]Contributions!H269 -> -0.074988764 | AP18: =[1]Contributions!I269 -> 1.2334412 | AQ18: =[1]Contributions!G269 -> 1.5233075 | AR18: 2
A19: 41365 | B19: =HAVERM!K166 -> 4.5731707 | C19: =((HAVERM!M160/HAVERM!M148)-1)*100 -> 3.1945789 | D19: =((HAVERM!R159/HAVERM!R147)-1)*100 -> -5.9744777 | E19: 0 | H19: 2010 | I19: 2011 | J19: 2012 | K19: 2013 | L19: 2014 | M19: 2015 | N19: 2016 | O19: 2017 | P19: 2018 | Q19: 2019 | S19: =+S14+7 -> 44949 | T19: Jan | U19: =IF('HAVER - UK Gas'!H1589="",C1301,AVERAGE('HAVER - UK Gas'!H1589:Q1589)) -> 168.307 | AE19: 44287 | AF19: ='[1]CPI Forecast'!D309 -> 1.5259222 | AG19: =NA() -> #N/A | AH19: =NA() -> #N/A | AI19: 2 | AK19: 43922 | AL19: =[1]Contributions!C270 -> 0.23502657 | AM19: =[1]Contributions!D270 -> -0.37714641 | AN19: =[1]Contributions!E270 -> -0.23267241 | AO19: =[1]Contributions!H270 -> 0.04100588 | AP19: =[1]Contributions!I270 -> 0.96774728 | AQ19: =[1]Contributions!G270 -> 0.76742263 | AR19: 2
A20: 41395 | B20: =HAVERM!K167 -> 4.2553191 | C20: =((HAVERM!M161/HAVERM!M149)-1)*100 -> 3.7572254 | D20: =((HAVERM!R160/HAVERM!R148)-1)*100 -> -3.3087193 | E20: 0 | G20: January | H20: =HAVERM!L127 -> -0.22446689 | I20: =HAVERM!L139 -> -0.10570825 | J20: =HAVERM!L151 -> -0.3058104 | K20: =HAVERM!L163 -> 0.098231827 | L20: =HAVERM!L175 -> 0.096339114 | M20: =HAVERM!L187 -> -0.68627451 | N20: =HAVERM!L199 -> -0.4040404 | O20: =HAVERM!L211 -> 0.20429009 | P20: =HAVERM!L223 -> -0.098231827 | Q20: =HAVERM!L235 -> 0.097560976 | S20: =+S15+7 -> 44950 | T20: Jan | U20: =IF('HAVER - UK Gas'!H1590="",C1302,AVERAGE('HAVER - UK Gas'!H1590:Q1590)) -> 163.369 | AE20: 44317 | AF20: ='[1]CPI Forecast'!D310 -> 2.1149485 | AG20: =NA() -> #N/A | AH20: =NA() -> #N/A | AI20: 2 | AK20: 43952 | AL20: =[1]Contributions!C271 -> 0.28616843 | AM20: =[1]Contributions!D271 -> -0.52713414 | AN20: =[1]Contributions!E271 -> -0.23789164 | AO20: =[1]Contributions!H271 -> -0.11161792 | AP20: =[1]Contributions!I271 -> 0.96492333 | AQ20: =[1]Contributions!G271 -> 0.47986067 | AR20: 2
A21: 41426 | B21: =HAVERM!K168 -> 3.8539554 | C21: =((HAVERM!M162/HAVERM!M150)-1)*100 -> 4.2226488 | D21: =((HAVERM!R161/HAVERM!R149)-1)*100 -> -2.9503066 | E21: 0 | G21: February | H21: =HAVERM!L128 -> 1.1248594 | I21: =HAVERM!L140 -> 1.0582011 | J21: =HAVERM!L152 -> 1.2269939 | K21: =HAVERM!L164 -> 0.68694799 | L21: =HAVERM!L176 -> 0.57747834 | M21: =HAVERM!L188 -> -0.29615005 | N21: =HAVERM!L200 -> 0.20283976 | O21: =HAVERM!L212 -> 0.81549439 | P21: =HAVERM!L224 -> 0.19665683 | Q21: =HAVERM!L236 -> 0.38986355 | S21: =+S16+7 -> 44951 | T21: Jan | U21: =IF('HAVER - UK Gas'!H1591="",C1303,AVERAGE('HAVER - UK Gas'!H1591:Q1591)) -> 159.381 | AE21: 44348 | AF21: ='[1]CPI Forecast'!D311 -> 2.5141826 | AG21: =NA() -> #N/A | AH21: =NA() -> #N/A | AI21: 2 | AK21: 43983 | AL21: =[1]Contributions!C272 -> 0.19527087 | AM21: =[1]Contributions!D272 -> -0.51373872 | AN21: =[1]Contributions!E272 -> -0.22603286 | AO21: =[1]Contributions!H272 -> 0.21133783 | AP21: =[1]Contributions!I272 -> 0.87854939 | AQ21: =[1]Contributions!G272 -> 0.60315196 | AR21: 2
A22: 41456 | B22: =HAVERM!K169 -> 3.8461538 | C22: =((HAVERM!M163/HAVERM!M151)-1)*100 -> 4.6153846 | D22: =((HAVERM!R162/HAVERM!R150)-1)*100 -> 0.67431019 | E22: 0 | G22: March | H22: =HAVERM!L129 -> 0.22246941 | I22: =HAVERM!L141 -> -1.3612565 | J22: =HAVERM!L153 -> -0.50505051 | K22: =HAVERM!L165 -> -0.38986355 | L22: =HAVERM!L177 -> -0.57416268 | M22: =HAVERM!L189 -> -0.099009901 | N22: =HAVERM!L201 -> -0.70850202 | O22: =HAVERM!L213 -> 0.40444894 | P22: =HAVERM!L225 -> 0.39254171 | Q22: =HAVERM!L237 -> 0.097087379 | S22: =+S17+7 -> 44952 | T22: Jan | U22: =IF('HAVER - UK Gas'!H1592="",C1304,AVERAGE('HAVER - UK Gas'!H1592:Q1592)) -> 159.47 | AE22: 44378 | AF22: ='[1]CPI Forecast'!D312 -> 2.0399369 | AG22: =NA() -> #N/A | AH22: =NA() -> #N/A | AI22: 2 | AK22: 44013 | AL22: =[1]Contributions!C273 -> 0.18227004 | AM22: =[1]Contributions!D273 -> -0.37317568 | AN22: =[1]Contributions!E273 -> -0.2230972 | AO22: =[1]Contributions!H273 -> 0.37030064 | AP22: =[1]Contributions!I273 -> 1.01431 | AQ22: =[1]Contributions!G273 -> 1.0403061 | AR22: 2
A23: 41487 | B23: =HAVERM!K170 -> 4.1414141 | C23: =((HAVERM!M164/HAVERM!M152)-1)*100 -> 4.6889952 | D23: =((HAVERM!R163/HAVERM!R151)-1)*100 -> 1.8715633 | E23: 0 | G23: April | H23: =HAVERM!L130 -> 0.33296337 | I23: =HAVERM!L142 -> 0.10615711 | J23: =HAVERM!L154 -> -0.10152284 | K23: =HAVERM!L166 -> 0.68493151 | L23: =HAVERM!L178 -> -0.48123195 | M23: =HAVERM!L190 -> -0.39643211 | N23: =HAVERM!L202 -> -0.1019368 | O23: =HAVERM!L214 -> 0.20140987 | P23: =HAVERM!L226 -> -0.19550342 | Q23: =HAVERM!L238 -> -0.29097963 | S23: =+S18+7 -> 44953 | T23: Jan | U23: =IF('HAVER - UK Gas'!H1593="",C1305,AVERAGE('HAVER - UK Gas'!H1593:Q1593)) -> 160.034 | AE23: 44409 | AF23: ='[1]CPI Forecast'!D313 -> 3.1966707 | AG23: =NA() -> #N/A | AH23: =NA() -> #N/A | AI23: 2 | AK23: 44044 | AL23: =[1]Contributions!C274 -> 0.10372773 | AM23: =[1]Contributions!D274 -> -0.35277846 | AN23: =[1]Contributions!E274 -> -0.2280952 | AO23: =[1]Contributions!H274 -> 0.27483006 | AP23: =[1]Contributions!I274 -> 0.30999998 | AQ23: =[1]Contributions!G274 -> 0.21960784 | AR23: 2
A24: 41518 | B24: =HAVERM!K171 -> 4.2424242 | C24: =((HAVERM!M165/HAVERM!M153)-1)*100 -> 5.5396371 | D24: =((HAVERM!R164/HAVERM!R152)-1)*100 -> 0.38472031 | E24: 0 | G24: May | H24: =HAVERM!L131 -> -0.11061947 | I24: =HAVERM!L143 -> 1.2725345 | J24: =HAVERM!L155 -> 0.30487805 | K24: =HAVERM!L167 -> 0 | L24: =HAVERM!L179 -> -1.0638298 | M24: =HAVERM!L191 -> -0.099502488 | N24: =HAVERM!L203 -> -0.40816327 | O24: =HAVERM!L215 -> 0.10050251 | P24: =HAVERM!L227 -> -0.19588639 | Q24: =HAVERM!L239 -> 0.097276265 | S24: =+S19+7 -> 44956 | T24: Jan | U24: =IF('HAVER - UK Gas'!H1594="",C1306,AVERAGE('HAVER - UK Gas'!H1594:Q1594)) -> 167.975 | AE24: 44440 | AF24: ='[1]CPI Forecast'!D314 -> 3.080069 | AG24: =NA() -> #N/A | AH24: =NA() -> #N/A | AI24: 2 | AK24: 44075 | AL24: =[1]Contributions!C275 -> 0.065022832 | AM24: =[1]Contributions!D275 -> -0.32830787 | AN24: =[1]Contributions!E275 -> -0.22787652 | AO24: =[1]Contributions!H275 -> 0.24150721 | AP24: =[1]Contributions!I275 -> 0.70256487 | AQ24: =[1]Contributions!G275 -> 0.53190018 | AR24: 2
A25: 41548 | B25: =HAVERM!K172 -> 3.919598 | C25: =((HAVERM!M166/HAVERM!M154)-1)*100 -> 5.7034221 | D25: =((HAVERM!R165/HAVERM!R153)-1)*100 -> -0.13010683 | E25: 0 | G25: June | H25: =HAVERM!L132 -> -0.11074197 | I25: =HAVERM!L144 -> 1.0471204 | J25: =HAVERM!L156 -> -0.10131712 | K25: =HAVERM!L168 -> -0.48590865 | L25: =HAVERM!L180 -> 0.097751711 | M25: =HAVERM!L192 -> -0.19920319 | N25: =HAVERM!L204 -> -0.40983607 | O25: =HAVERM!L216 -> -0.20080321 | P25: =HAVERM!L228 -> -0.49067713 | Q25: =HAVERM!L240 -> 0.19436346 | S25: =+S20+7 -> 44957 | T25: Jan | U25: =IF('HAVER - UK Gas'!H1595="",C1307,AVERAGE('HAVER - UK Gas'!H1595:Q1595)) -> 173.496 | AE25: 44470 | AF25: ='[1]CPI Forecast'!D315 -> 4.2062117 | AG25: =NA() -> #N/A | AH25: =NA() -> #N/A | AI25: 2 | AK25: 44105 | AL25: =[1]Contributions!C276 -> 0.14295255 | AM25: =[1]Contributions!D276 -> -0.31544409 | AN25: =[1]Contributions!E276 -> -0.28976607 | AO25: =[1]Contributions!H276 -> 0.36791692 | AP25: =[1]Contributions!I276 -> 0.65975538 | AQ25: =[1]Contributions!G276 -> 0.69715046 | AR25: 2
A26: 41579 | B26: =HAVERM!K173 -> 2.7833002 | C26: =((HAVERM!M167/HAVERM!M155)-1)*100 -> 5.4234063 | D26: =((HAVERM!R166/HAVERM!R154)-1)*100 -> 0.62078635 | E26: 0 | G26: July | H26: =HAVERM!L133 -> 0.99778271 | I26: =HAVERM!L145 -> 0.20725389 | J26: =HAVERM!L157 -> 0.20283976 | K26: =HAVERM!L169 -> 0.1953125 | L26: =HAVERM!L181 -> -0.1953125 | M26: =HAVERM!L193 -> -0.69860279 | N26: =HAVERM!L205 -> -0.30864198 | O26: =HAVERM!L217 -> 0 | P26: =HAVERM!L229 -> 0.29585799 | Q26: =HAVERM!L241 -> 0 | S26: =+S21+7 -> 44958 | T26: Feb | U26: =IF('HAVER - UK Gas'!H1596="",C1308,AVERAGE('HAVER - UK Gas'!H1596:Q1596)) -> 169.514 | AE26: 44501 | AF26: ='[1]CPI Forecast'!D316 -> 5.1299005 | AG26: =NA() -> #N/A | AH26: =NA() -> #N/A | AI26: 2 | AK26: 44136 | AL26: =[1]Contributions!C277 -> 0.026160354 | AM26: =[1]Contributions!D277 -> -0.30405477 | AN26: =[1]Contributions!E277 -> -0.29207545 | AO26: =[1]Contributions!H277 -> 0.091255071 | AP26: =[1]Contributions!I277 -> 0.70152952 | AQ26: =[1]Contributions!G277 -> 0.31506509 | AR26: 2
A27: 41609 | B27: =HAVERM!K174 -> 1.9646365 | C27: =((HAVERM!M168/HAVERM!M156)-1)*100 -> 5.5555556 | D27: =((HAVERM!R167/HAVERM!R155)-1)*100 -> 4.1146348 | E27: 0 | G27: August | H27: =HAVERM!L134 -> 0.10976948 | I27: =HAVERM!L146 -> 0.20682523 | J27: =HAVERM!L158 -> 0.20242915 | K27: =HAVERM!L170 -> 0.48732943 | L27: =HAVERM!L182 -> -0.19569472 | M27: =HAVERM!L194 -> 0 | N27: =HAVERM!L206 -> 0.4127967 | O27: =HAVERM!L218 -> 0 | P27: =HAVERM!L230 -> 0.19665683 | Q27: =HAVERM!L242 -> 0.58195926 | S27: =+S22+7 -> 44959 | T27: Feb | U27: =IF('HAVER - UK Gas'!H1597="",C1309,AVERAGE('HAVER - UK Gas'!H1597:Q1597)) -> 172.12 | AE27: 44531 | AF27: ='[1]CPI Forecast'!D317 -> 5.3860457 | AG27: =NA() -> #N/A | AH27: =NA() -> #N/A | AI27: 2 | AK27: 44166 | AL27: =[1]Contributions!C278 -> 0.00036004292 | AM27: =[1]Contributions!D278 -> -0.25306379 | AN27: =[1]Contributions!E278 -> -0.28020169 | AO27: =[1]Contributions!H278 -> 0.31839669 | AP27: =[1]Contributions!I278 -> 0.70338654 | AQ27: =[1]Contributions!G278 -> 0.58876645 | AR27: 2
A28: 41640 | B28: =HAVERM!K175 -> 1.9627085 | C28: =((HAVERM!M169/HAVERM!M157)-1)*100 -> 4.9242424 | D28: =((HAVERM!R168/HAVERM!R156)-1)*100 -> 5.4549047 | E28: 0 | G28: September | H28: =HAVERM!L135 -> 0.10964912 | I28: =HAVERM!L147 -> 0.20639835 | J28: =HAVERM!L159 -> 0 | K28: =HAVERM!L171 -> 0.09699321 | L28: =HAVERM!L183 -> -0.19607843 | M28: =HAVERM!L195 -> 0 | N28: =HAVERM!L207 -> 0 | O28: =HAVERM!L219 -> 0.80482897 | P28: =HAVERM!L231 -> -0.19627085 | Q28: =HAVERM!L243 -> -0.19286403 | S28: =+S23+7 -> 44960 | T28: Feb | U28: =IF('HAVER - UK Gas'!H1598="",C1310,AVERAGE('HAVER - UK Gas'!H1598:Q1598)) -> 168.629 | AE28: 44562 | AF28: ='[1]CPI Forecast'!D318 -> 5.4555133 | AG28: =NA() -> #N/A | AH28: =NA() -> #N/A | AI28: 2 | AK28: 44197 | AL28: =[1]Contributions!C279 -> 0.051396648 | AM28: =[1]Contributions!D279 -> -0.25361184 | AN28: =[1]Contributions!E279 -> -0.26956522 | AO28: =[1]Contributions!H279 -> 0.70999565 | AP28: =[1]Contributions!I279 -> 0.83306379 | AQ28: =[1]Contributions!G279 -> 0.70058043 | AR28: 2
A29: 41671 | B29: =HAVERM!K176 -> 1.8518519 | C29: =((HAVERM!M170/HAVERM!M158)-1)*100 -> 2.9272899 | D29: =((HAVERM!R169/HAVERM!R157)-1)*100 -> -0.78903406 | E29: 0 | G29: October | H29: =HAVERM!L136 -> 0.4381161 | I29: =HAVERM!L148 -> -0.92687951 | J29: =HAVERM!L160 -> 0.50505051 | K29: =HAVERM!L172 -> 0.19379845 | L29: =HAVERM!L184 -> 0.098231827 | M29: =HAVERM!L196 -> -0.40201005 | N29: =HAVERM!L208 -> -0.51387461 | O29: =HAVERM!L220 -> 0.3992016 | P29: =HAVERM!L232 -> -0.19665683 | Q29: =HAVERM!L244 -> -0.6763285 | S29: =+S24+7 -> 44963 | T29: Feb | U29: =IF('HAVER - UK Gas'!H1599="",C1311,AVERAGE('HAVER - UK Gas'!H1599:Q1599)) -> 163.256 | AE29: 44593 | AF29: ='[1]CPI Forecast'!D319 -> 6.1766081 | AG29: =NA() -> #N/A | AH29: =NA() -> #N/A | AI29: 2 | AK29: 44228 | AL29: =[1]Contributions!C280 -> 0.053460793 | AM29: =[1]Contributions!D280 -> -0.1084029 | AN29: =[1]Contributions!E280 -> -0.25512712 | AO29: =[1]Contributions!H280 -> 0.34458477 | AP29: =[1]Contributions!I280 -> 0.7345853 | AQ29: =[1]Contributions!G280 -> 0.41421589 | AR29: 2
A30: 41699 | B30: =HAVERM!K177 -> 1.6634051 | C30: =((HAVERM!M171/HAVERM!M159)-1)*100 -> 2.3562677 | D30: =((HAVERM!R170/HAVERM!R158)-1)*100 -> -3.8084369 | E30: 0 | G30: November | H30: =HAVERM!L137 -> 1.5267176 | I30: =HAVERM!L149 -> 0.62370062 | J30: =HAVERM!L161 -> 1.1055276 | K30: =HAVERM!L173 -> 0 | L30: =HAVERM!L185 -> -0.19627085 | M30: =HAVERM!L197 -> 0.10090817 | N30: =HAVERM!L209 -> 0.41322314 | O30: =HAVERM!L221 -> 0.49701789 | P30: =HAVERM!L233 -> 0.098522167 | Q30: =HAVERM!L245 -> 0.87548638 | S30: =+S25+7 -> 44964 | T30: Feb | U30: =IF('HAVER - UK Gas'!H1600="",C1312,AVERAGE('HAVER - UK Gas'!H1600:Q1600)) -> 157.95 | AE30: 44621 | AF30: ='[1]CPI Forecast'!D320 -> 7.023124 | AG30: =NA() -> #N/A | AH30: =NA() -> #N/A | AI30: 2 | AK30: 44256 | AL30: =[1]Contributions!C281 -> -0.059171934 | AM30: =[1]Contributions!D281 -> 0.092082718 | AN30: =[1]Contributions!E281 -> -0.23697976 | AO30: =[1]Contributions!H281 -> 0.50026976 | AP30: =[1]Contributions!I281 -> 0.72382812 | AQ30: =[1]Contributions!G281 -> 0.71432517 | AR30: 2
A31: 41730 | B31: =HAVERM!K178 -> 0.48590865 | C31: =((HAVERM!M172/HAVERM!M160)-1)*100 -> 2.0637899 | D31: =((HAVERM!R171/HAVERM!R159)-1)*100 -> -5.5557963 | E31: 0 | G31: December | H31: =HAVERM!L138 -> 1.6111708 | I31: =HAVERM!L150 -> 1.3429752 | J31: =HAVERM!L162 -> 1.1928429 | K31: =HAVERM!L174 -> 0.3868472 | L31: =HAVERM!L186 -> 0.29498525 | M31: =HAVERM!L198 -> -0.2016129 | N31: =HAVERM!L210 -> 0.72016461 | O31: =HAVERM!L222 -> 0.69238378 | P31: =HAVERM!L234 -> 0.88582677 | Q31: =HAVERM!L246 -> 0.57859209 | S31: =+S26+7 -> 44965 | T31: Feb | U31: =IF('HAVER - UK Gas'!H1601="",C1313,AVERAGE('HAVER - UK Gas'!H1601:Q1601)) -> 154.895 | AE31: 44652 | AF31: ='[1]CPI Forecast'!D321 -> 9.0106617 | AG31: =NA() -> #N/A | AH31: =NA() -> #N/A | AI31: 2 | AK31: 44287 | AL31: =[1]Contributions!C282 -> 0.044450556 | AM31: =[1]Contributions!D282 -> 0.3543065 | AN31: =[1]Contributions!E282 -> 0.10426883 | AO31: =[1]Contributions!H282 -> 0.6426047 | AP31: =[1]Contributions!I282 -> 0.73108502 | AQ31: =[1]Contributions!G282 -> 1.5259222 | AR31: 2
A32: 41760 | B32: =HAVERM!K179 -> -0.58309038 | C32: =((HAVERM!M173/HAVERM!M161)-1)*100 -> 1.2070566 | D32: =((HAVERM!R172/HAVERM!R160)-1)*100 -> -4.2779272 | E32: 0 | S32: =+S27+7 -> 44966 | T32: Feb | U32: =IF('HAVER - UK Gas'!H1602="",C1314,AVERAGE('HAVER - UK Gas'!H1602:Q1602)) -> 155.348 | AE32: 44682 | AF32: ='[1]CPI Forecast'!D322 -> 9.0827013 | AG32: =NA() -> #N/A | AH32: =NA() -> #N/A | AI32: 2 | AK32: 44317 | AL32: =[1]Contributions!C283 -> -0.064550276 | AM32: =[1]Contributions!D283 -> 0.45743575 | AN32: =[1]Contributions!E283 -> 0.11052257 | AO32: =[1]Contributions!H283 -> 1.037649 | AP32: =[1]Contributions!I283 -> 0.84657298 | AQ32: =[1]Contributions!G283 -> 2.1149485 | AR32: 2
A33: 41791 | B33: =HAVERM!K180 -> 0 | C33: =((HAVERM!M174/HAVERM!M162)-1)*100 -> 0.18416206 | D33: =((HAVERM!R173/HAVERM!R161)-1)*100 -> -4.8133191 | E33: 0 | S33: =+S28+7 -> 44967 | T33: Feb | U33: =IF('HAVER - UK Gas'!H1603="",C1315,AVERAGE('HAVER - UK Gas'!H1603:Q1603)) -> 150.51 | AE33: 44713 | AF33: ='[1]CPI Forecast'!D323 -> 9.4121135 | AG33: =NA() -> #N/A | AH33: =NA() -> #N/A | AI33: 2 | AK33: 44348 | AL33: =[1]Contributions!C284 -> 0.044399386 | AM33: =[1]Contributions!D284 -> 0.51600178 | AN33: =[1]Contributions!E284 -> 0.10474233 | AO33: =[1]Contributions!H284 -> 1.210991 | AP33: =[1]Contributions!I284 -> 0.9556646 | AQ33: =[1]Contributions!G284 -> 2.5141826 | AR33: 2
A34: 41821 | B34: =HAVERM!K181 -> -0.38986355 | C34: =((HAVERM!M175/HAVERM!M163)-1)*100 -> -0.36764706 | D34: =((HAVERM!R174/HAVERM!R162)-1)*100 -> -6.5324871 | E34: 0 | S34: =+S29+7 -> 44970 | T34: Feb | U34: =IF('HAVER - UK Gas'!H1604="",C1316,AVERAGE('HAVER - UK Gas'!H1604:Q1604)) -> 150 | AE34: 44743 | AF34: ='[1]CPI Forecast'!D324 -> 10.100901 | AG34: =NA() -> #N/A | AH34: =NA() -> #N/A | AI34: 2 | AK34: 44378 | AL34: =[1]Contributions!C285 -> -0.0018952519 | AM34: =[1]Contributions!D285 -> 0.46543883 | AN34: =[1]Contributions!E285 -> 0.11079483 | AO34: =[1]Contributions!H285 -> 1.122908 | AP34: =[1]Contributions!I285 -> 0.67323793 | AQ34: =[1]Contributions!G285 -> 2.0399369 | AR34: 2
A35: 41852 | B35: =HAVERM!K182 -> -1.0669253 | C35: =((HAVERM!M176/HAVERM!M164)-1)*100 -> -1.3711152 | D35: =((HAVERM!R175/HAVERM!R163)-1)*100 -> -10.271322 | E35: 0 | S35: =+S30+7 -> 44971 | T35: Feb | U35: =IF('HAVER - UK Gas'!H1605="",C1317,AVERAGE('HAVER - UK Gas'!H1605:Q1605)) -> 153.979 | AE35: 44774 | AF35: ='[1]CPI Forecast'!D325 -> 9.8701878 | AG35: =NA() -> #N/A | AH35: =NA() -> #N/A | AI35: 2 | AK35: 44409 | AL35: =[1]Contributions!C286 -> 0.14415191 | AM35: =[1]Contributions!D286 -> 0.47085525 | AN35: =[1]Contributions!E286 -> 0.11096636 | AO35: =[1]Contributions!H286 -> 1.5349375 | AP35: =[1]Contributions!I286 -> 1.3507984 | AQ35: =[1]Contributions!G286 -> 3.1966707 | AR35: 2
A36: 41883 | B36: =HAVERM!K183 -> -1.3565891 | C36: =((HAVERM!M177/HAVERM!M165)-1)*100 -> -2.6244344 | D36: =((HAVERM!R176/HAVERM!R164)-1)*100 -> -10.208926 | E36: 0 | S36: =+S31+7 -> 44972 | T36: Feb | U36: =IF('HAVER - UK Gas'!H1606="",C1318,AVERAGE('HAVER - UK Gas'!H1606:Q1606)) -> 149.83 | AE36: 44805 | AF36: ='[1]CPI Forecast'!D326 -> 10.095628 | AG36: =NA() -> #N/A | AH36: =NA() -> #N/A | AI36: 2 | AK36: 44440 | AL36: =[1]Contributions!C287 -> 0.2077674 | AM36: =[1]Contributions!D287 -> 0.47137954 | AN36: =[1]Contributions!E287 -> 0.11703769 | AO36: =[1]Contributions!H287 -> 1.5235567 | AP36: =[1]Contributions!I287 -> 1.1269214 | AQ36: =[1]Contributions!G287 -> 3.080069 | AR36: 2
A37: 41913 | B37: =HAVERM!K184 -> -1.450677 | C37: =((HAVERM!M178/HAVERM!M166)-1)*100 -> -3.4172662 | D37: =((HAVERM!R177/HAVERM!R165)-1)*100 -> -7.488173 | E37: 0 | S37: =+S32+7 -> 44973 | T37: Feb | U37: =IF('HAVER - UK Gas'!H1607="",C1319,AVERAGE('HAVER - UK Gas'!H1607:Q1607)) -> 144.123 | AE37: 44835 | AF37: ='[1]CPI Forecast'!D327 -> 11.051566 | AG37: =NA() -> #N/A | AH37: =NA() -> #N/A | AI37: 2 | AK37: 44470 | AL37: =[1]Contributions!C288 -> 0.21156428 | AM37: =[1]Contributions!D288 -> 0.56867529 | AN37: =[1]Contributions!E288 -> 0.75184398 | AO37: =[1]Contributions!H288 -> 1.627456 | AP37: =[1]Contributions!I288 -> 1.4387625 | AQ37: =[1]Contributions!G288 -> 4.2062117 | AR37: 2
A38: 41944 | B38: =HAVERM!K185 -> -1.6441006 | C38: =((HAVERM!M179/HAVERM!M167)-1)*100 -> -2.7075812 | D38: =((HAVERM!R178/HAVERM!R166)-1)*100 -> -8.4643529 | E38: 0 | S38: =+S33+7 -> 44974 | T38: Feb | U38: =IF('HAVER - UK Gas'!H1608="",C1320,AVERAGE('HAVER - UK Gas'!H1608:Q1608)) -> 143.293 | AE38: 44866 | AF38: ='[1]CPI Forecast'!D328 -> 10.672013 | AG38: =NA() -> #N/A | AH38: =NA() -> #N/A | AI38: 2 | AK38: 44501 | AL38: =[1]Contributions!C289 -> 0.48658715 | AM38: =[1]Contributions!D289 -> 0.74681144 | AN38: =[1]Contributions!E289 -> 0.76246454 | AO38: =[1]Contributions!H289 -> 2.0371257 | AP38: =[1]Contributions!I289 -> 1.4792644 | AQ38: =[1]Contributions!G289 -> 5.1299005 | AR38: 2
A39: 41974 | B39: =HAVERM!K186 -> -1.734104 | C39: =((HAVERM!M180/HAVERM!M168)-1)*100 -> -5.6199822 | D39: =((HAVERM!R179/HAVERM!R167)-1)*100 -> -8.5345035 | E39: 0 | S39: =+S34+7 -> 44977 | T39: Feb | U39: =IF('HAVER - UK Gas'!H1609="",C1321,AVERAGE('HAVER - UK Gas'!H1609:Q1609)) -> 139.197 | V39: =AVERAGE($U$39:$U$71,$U$73:$U$102) -> 136.05151 | AB39: =AVERAGE($U$39:$U$71,$U$73:$U$102) -> 136.05151 | AC39: Q3 2023 | AE39: 44896 | AF39: ='[1]CPI Forecast'!D329 -> 10.528374 | AG39: =NA() -> #N/A | AH39: =NA() -> #N/A | AI39: 2 | AK39: 44531 | AL39: =[1]Contributions!C290 -> 0.61403406 | AM39: =[1]Contributions!D290 -> 0.7101353 | AN39: =[1]Contributions!E290 -> 0.74540163 | AO39: =[1]Contributions!H290 -> 2.2230712 | AP39: =[1]Contributions!I290 -> 1.4976266 | AQ39: =[1]Contributions!G290 -> 5.3860457 | AR39: 2
A40: 42005 | B40: =HAVERM!K187 -> -2.5024062 | C40: =((HAVERM!M181/HAVERM!M169)-1)*100 -> -5.7761733 | D40: =((HAVERM!R180/HAVERM!R168)-1)*100 -> -9.6586953 | E40: 0 | S40: =+S35+7 -> 44978 | T40: Feb | U40: =IF('HAVER - UK Gas'!H1610="",C1322,AVERAGE('HAVER - UK Gas'!H1610:Q1610)) -> 142.254 | V40: =AVERAGE($U$39:$U$71,$U$73:$U$102) -> 136.05151 | AB40: =AVERAGE($U$39:$U$71,$U$73:$U$102) -> 136.05151 | AE40: 44927 | AF40: ='[1]CPI Forecast'!D330 -> 10.051524 | AG40: =NA() -> #N/A | AH40: =NA() -> #N/A | AI40: 2 | AK40: 44562 | AL40: =[1]Contributions!C291 -> 0.63024119 | AM40: =[1]Contributions!D291 -> 0.61364929 | AN40: =[1]Contributions!E291 -> 0.75727003 | AO40: =[1]Contributions!H291 -> 1.991572 | AP40: =[1]Contributions!I291 -> 1.4120141 | AQ40: =[1]Contributions!G291 -> 5.4555133 | AR40: 2
A41: 42036 | B41: =HAVERM!K188 -> -3.3492823 | C41: =((HAVERM!M182/HAVERM!M170)-1)*100 -> -5.5963303 | D41: =((HAVERM!R181/HAVERM!R169)-1)*100 -> -12.242069 | E41: 0 | S41: =+S36+7 -> 44979 | T41: Feb | U41: =IF('HAVER - UK Gas'!H1611="",C1323,AVERAGE('HAVER - UK Gas'!H1611:Q1611)) -> 142.471 | V41: =AVERAGE($U$39:$U$71,$U$73:$U$102) -> 136.05151 | AB41: =AVERAGE($U$39:$U$71,$U$73:$U$102) -> 136.05151 | AE41: 44958 | AF41: ='[1]CPI Forecast'!D331 -> 10.416397 | AG41: =NA() -> #N/A | AH41: =NA() -> #N/A | AI41: 2 | AK41: 44593 | AL41: =[1]Contributions!C292 -> 0.74348786 | AM41: =[1]Contributions!D292 -> 0.61736985 | AN41: =[1]Contributions!E292 -> 0.76180494 | AO41: =[1]Contributions!H292 -> 2.5463428 | AP41: =[1]Contributions!I292 -> 1.4977042 | AQ41: =[1]Contributions!G292 -> 6.1766081 | AR41: 2
...

Sheet HAVERM
A1: 201801 !M | B1: DOBY@UK | C1: DOBX@UK | D1: PEGDX@WBPRICES | E1: PEGEU@WBPRICES | F1: INTERP(X112USB@INTDAILY) | I1: 200001 !M | J1: D7BU@UK | M1: GHHV@UK | N1: GBA7@UK | O1: PUNFPI@CMDTY | P1: INTERP(X112USB@INTDAILY)
A2: .DESC | B2: UK: RPI: Fuel & Light: Gas (NSA, Jan-87=100) | C2: UK: RPI: Fuel & Light: Electricity (NSA, Jan-87=100) | D2: Natural Gas Index (NSA, 2010=100) | E2: Average Price: Natural Gas: Europe (US$/Mil.BTU) | F2: UK: Spot Exchange Rate: US Dollar (US$/GBP) | I2: .DESC | J2: UK: Consumer Price Index: Food & Non-Alcoholic Beverages (NSA, 2015=100) | K2: y/y calc | L2: m/m calc | M2: UK: PPI: Gross Sector Input: Food, Beverages & Tobacco (NSA, 2015=100) | N2: UK: PPI: Gross Sector Output: Food Products, Beverages & Tobacco (NSA, 2015=100) | O2: Food and Agriculture Organization of the UN: Food Price Index (2014-16=100) | P2: UK: Spot Exchange Rate: US Dollar (US$/GBP) | Q2: UN fx adjustment | R2: UN re-basing to 2015=100 | S2: BRC shop price inflation y/y
A3: .T1 | B3: Jan-1987 | C3: Jan-1987 | D3: Jan-1960 | E3: Jan-1960 | F3: Jan-1975 <- 02-Jan-1975 | I3: .T1 | J3: Jan-1988 | M3: Jan-1996 | N3: Jan-1996 | O3: Jan-1990 | P3: Jan-1975 <- 02-Jan-1975 | R3: =AVERAGE(Q187:Q198) -> 60.809735
A4: .TN | B4: Feb-2024 | C4: Feb-2024 | D4: Mar-2024 | E4: Mar-2024 | F4: Mar-2024 <- 05-Apr-2024 | I4: .TN | J4: Feb-2024 | M4: Feb-2024 | N4: Feb-2024 | O4: Mar-2024 | P4: Mar-2024 <- 05-Apr-2024
A5: .SOURCE | B5: ONS | C5: ONS | D5: WB | E5: WB | F5: BoE | I5: .LSOURCE | J5: Office for National Statistics | M5: Office for National Statistics | N5: Office for National Statistics | O5: Food and Agriculture Organization of the UN | P5: Bank of England
A6: .DTLM | B6: Mar-20-2024 07:15 | C6: Mar-20-2024 07:15 | D6: Apr-02-2024 21:20 | E6: Apr-02-2024 21:20 | F6: Apr-08-2024 09:31 | I6: .DTLM | J6: Mar-20-2024 07:15 | M6: Mar-20-2024 07:17 | N6: Mar-20-2024 07:17 | O6: Apr-05-2024 09:09 | P6: Apr-08-2024 09:31
A7: 201801 | B7: 353.2 | C7: 335.7 | D7: 84.82 | E7: 6.66 | F7: 1.3713621 | I7: 200001 | J7: 66 | M7: 64.8 | N7: 68.2 | O7: 52.6 | P7: 1.6069929 | Q7: =O7/P7 -> 32.731944 | R7: =(Q7/$R$3)*100 -> 53.826815
A8: 201802 | B8: 353.2 | C8: 335.7 | D8: 71.03 | E8: 6.72 | F8: 1.396075 | I8: 200002 | J8: 65.9 | L8: =((J8/J7)-1)*100 -> -0.15151515 | M8: 64.7 | N8: 68.2 | O8: 52.3 | P8: 1.5998143 | Q8: =O8/P8 -> 32.691295 | R8: =(Q8/$R$3)*100 -> 53.759969
A9: 201803 | B9: 353.2 | C9: 335.7 | D9: 71.46 | E9: 6.7 | F9: 1.3792563 | I9: 200003 | J9: 65.4 | L9: =((J9/J8)-1)*100 -> -0.75872534 | M9: 64.9 | N9: 68.5 | O9: 52.8 | P9: 1.5802217 | Q9: =O9/P9 -> 33.413032 | R9: =(Q9/$R$3)*100 -> 54.946847
A10: 201804 | B10: 354.5 | C10: 338.6 | D10: 73.52 | E10: 6.93 | F10: 1.3624375 | I10: 200004 | J10: 65.2 | L10: =((J10/J9)-1)*100 -> -0.3058104 | M10: 64.4 | N10: 69.1 | O10: 53.4 | P10: 1.5564403 | Q10: =O10/P10 -> 34.309059 | R10: =(Q10/$R$3)*100 -> 56.420339
A11: 201805 | B11: 354.7 | C11: 338.9 | D11: 76.51 | E11: 7.49 | F11: 1.3456187 | I11: 200005 | J11: 65.9 | L11: =((J11/J10)-1)*100 -> 1.0736196 | M11: 64.8 | N11: 69.4 | O11: 53.6 | P11: 1.5326588 | Q11: =O11/P11 -> 34.971907 | R11: =(Q11/$R$3)*100 -> 57.510376
A12: 201806 | B12: 363.9 | C12: 346.5 | D12: 78.34 | E12: 7.45 | F12: 1.3288 | I12: 200006 | J12: 66.1 | L12: =((J12/J11)-1)*100 -> 0.30349014 | M12: 66.3 | N12: 69.4 | O12: 53.8 | P12: 1.5088773 | Q12: =O12/P12 -> 35.65565 | R12: =(Q12/$R$3)*100 -> 58.634773
A13: 201807 | B13: 367.8 | C13: 352.7 | D13: 77.5 | E13: 7.6 | F13: 1.3168682 | I13: 200007 | J13: 66.6 | L13: =((J13/J12)-1)*100 -> 0.75642965 | M13: 66.6 | N13: 69.4 | O13: 54 | P13: 1.5087857 | Q13: =O13/P13 -> 35.790371 | R13: =(Q13/$R$3)*100 -> 58.856317
A14: 201808 | B14: 367.8 | C14: 352.7 | D14: 81.71 | E14: 8.08 | F14: 1.3115241 | I14: 200008 | J14: 66.1 | L14: =((J14/J13)-1)*100 -> -0.75075075 | M14: 66.7 | N14: 69.3 | O14: 53.2 | P14: 1.4721429 | Q14: =O14/P14 -> 36.137797 | R14: =(Q14/$R$3)*100 -> 59.427651
A15: 201809 | B15: 372.2 | C15: 359 | D15: 89.17 | E15: 9.52 | F15: 1.30618 | I15: 200009 | J15: 66.3 | L15: =((J15/J14)-1)*100 -> 0.30257186 | M15: 66.3 | N15: 69.3 | O15: 52.6 | P15: 1.4355 | Q15: =O15/P15 -> 36.642285 | R15: =(Q15/$R$3)*100 -> 60.257268
A16: 201810 | B16: 379.7 | C16: 366 | D16: 89.57 | E16: 8.79 | F16: 1.3011696 | I16: 200010 | J16: 66.3 | L16: =((J16/J15)-1)*100 -> 0 | M16: 66.2 | N16: 69.4 | O16: 53.4 | P16: 1.4511045 | Q16: =O16/P16 -> 36.799554 | R16: =(Q16/$R$3)*100 -> 60.515893
A17: 201811 | B17: 379.7 | C17: 366 | D17: 97.36 | E17: 8.27 | F17: 1.2900727 | I17: 200011 | J17: 66.7 | L17: =((J17/J16)-1)*100 -> 0.60331825 | M17: 66.5 | N17: 69.4 | O17: 53.8 | P17: 1.4255773 | Q17: =O17/P17 -> 37.739098 | R17: =(Q17/$R$3)*100 -> 62.060947
A18: 201812 | B18: 379.7 | C18: 366 | D18: 94.41 | E18: 7.98 | F18: 1.2939552 | I18: 200012 | J18: 66.8 | L18: =((J18/J17)-1)*100 -> 0.14992504 | M18: 66.7 | N18: 69.6 | O18: 54.4 | P18: 1.4346815 | Q18: =O18/P18 -> 37.917823 | R18: =(Q18/$R$3)*100 -> 62.354857
A19: 201901 | B19: 346.7 | C19: 348.2 | D19: 80.06 | E19: 7.26 | F19: 1.2978376 | I19: 200101 | J19: 67 | K19: =((J19/J7)-1)*100 -> 1.5151515 | L19: =((J19/J18)-1)*100 -> 0.2994012 | M19: 67 | N19: 69.7 | O19: 53.8 | P19: 1.4437858 | Q19: =O19/P19 -> 37.263146 | R19: =(Q19/$R$3)*100 -> 61.278258
A20: 201902 | B20: 347 | C20: 348.6 | D20: 69.55 | E20: 6.01 | F20: 1.30172 | I20: 200102 | J20: 67.1 | K20: =((J20/J8)-1)*100 -> 1.8209408 | L20: =((J20/J19)-1)*100 -> 0.14925373 | M20: 66.9 | N20: 69.8 | O20: 54.2 | P20: 1.45289 | Q20: =O20/P20 -> 37.304958 | R20: =(Q20/$R$3)*100 -> 61.347016
A21: 201903 | B21: 347 | C21: 348.6 | D21: 67.91 | E21: 5.18 | F21: 1.3165333 | I21: 200103 | J21: 67.9 | K21: =((J21/J9)-1)*100 -> 3.82263 | L21: =((J21/J20)-1)*100 -> 1.1922504 | M21: 67.4 | N21: 70.4 | O21: 55.1 | P21: 1.4453864 | Q21: =O21/P21 -> 38.121295 | R21: =(Q21/$R$3)*100 -> 62.689461
A22: 201904 | B22: 379.5 | C22: 386.4 | D22: 62.49 | E22: 4.92 | F22: 1.3003172 | I22: 200104 | J22: 68.1 | K22: =((J22/J10)-1)*100 -> 4.4478528 | L22: =((J22/J21)-1)*100 -> 0.29455081 | M22: 67.9 | N22: 70.5 | O22: 54.6 | P22: 1.4307211 | Q22: =O22/P22 -> 38.162575 | R22: =(Q22/$R$3)*100 -> 62.757345
A23: 201905 | B23: 379.5 | C23: 386.4 | D23: 59.42 | E23: 4.34 | F23: 1.2841011 | I23: 200105 | J23: 70 | K23: =((J23/J11)-1)*100 -> 6.2215478 | L23: =((J23/J22)-1)*100 -> 2.7900147 | M23: 68.7 | N23: 70.8 | O23: 55.4 | P23: 1.4160558 | Q23: =O23/P23 -> 39.122753 | R23: =(Q23/$R$3)*100 -> 64.336332
A24: 201906 | B24: 379.5 | C24: 386.4 | D24: 52.96 | E24: 3.59 | F24: 1.267885 | I24: 200106 | J24: 70.4 | K24: =((J24/J12)-1)*100 -> 6.505295 | L24: =((J24/J23)-1)*100 -> 0.57142857 | M24: 68.5 | N24: 70.6 | O24: 54.8 | P24: 1.4013905 | Q24: =O24/P24 -> 39.104019 | R24: =(Q24/$R$3)*100 -> 64.305525
A25: 201907 | B25: 379.5 | C25: 386.4 | D25: 52.73 | E25: 3.62 | F25: 1.2468913 | I25: 200107 | J25: 69 | K25: =((J25/J13)-1)*100 -> 3.6036036 | L25: =((J25/J24)-1)*100 -> -1.9886364 | M25: 68.8 | N25: 70.5 | O25: 56.5 | P25: 1.4138727 | Q25: =O25/P25 -> 39.961164 | R25: =(Q25/$R$3)*100 -> 65.715077
A26: 201908 | B26: 379.5 | C26: 386.4 | D26: 51.85 | E26: 3.68 | F26: 1.2411671 | I26: 200108 | J26: 68.8 | K26: =((J26/J14)-1)*100 -> 4.0847201 | L26: =((J26/J25)-1)*100 -> -0.28985507 | M26: 68.2 | N26: 70.5 | O26: 56.6 | P26: 1.4386614 | Q26: =O26/P26 -> 39.342128 | R26: =(Q26/$R$3)*100 -> 64.697089
A27: 201909 | B27: 379.5 | C27: 386.4 | D27: 58.19 | E27: 4.21 | F27: 1.2354429 | I27: 200109 | J27: 68.7 | K27: =((J27/J15)-1)*100 -> 3.6199095 | L27: =((J27/J26)-1)*100 -> -0.14534884 | M27: 67.7 | N27: 70.6 | O27: 55.4 | P27: 1.46345 | Q27: =O27/P27 -> 37.855752 | R27: =(Q27/$R$3)*100 -> 62.252782
A28: 201910 | B28: 345.7 | C28: 378.1 | D28: 59.12 | E28: 5.06 | F28: 1.2646913 | I28: 200110 | J28: 68.8 | K28: =((J28/J16)-1)*100 -> 3.7707391 | L28: =((J28/J27)-1)*100 -> 0.14556041 | M28: 67.4 | N28: 70.7 | O28: 54.2 | P28: 1.4517522 | Q28: =O28/P28 -> 37.334196 | R28: =(Q28/$R$3)*100 -> 61.395097
A29: 201911 | B29: 345.7 | C29: 378.1 | D29: 63.47 | E29: 5.15 | F29: 1.2882714 | I29: 200111 | J29: 68.7 | K29: =((J29/J17)-1)*100 -> 2.9985007 | L29: =((J29/J28)-1)*100 -> -0.14534884 | M29: 67.7 | N29: 70.7 | O29: 54.7 | P29: 1.4357818 | Q29: =O29/P29 -> 38.09771 | R29: =(Q29/$R$3)*100 -> 62.650677
A30: 201912 | B30: 345.7 | C30: 378.1 | D30: 56.01 | E30: 4.62 | F30: 1.2907593 | I30: 200112 | J30: 69.1 | K30: =((J30/J18)-1)*100 -> 3.4431138 | L30: =((J30/J29)-1)*100 -> 0.58224163 | M30: 68 | N30: 71.1 | O30: 54.3 | P30: 1.4315479 | Q30: =O30/P30 -> 37.93097 | R30: =(Q30/$R$3)*100 -> 62.376477
... A80: 202402 | B80: 636.6 | C80: 633.1 | D80: 68.88 | E80: 8.15 | F80: 1.2622333 | I80: 200602 | J80: 72.2 | K80: =((J80/J68)-1)*100 -> 0.97902098 | L80: =((J80/J79)-1)*100 -> 0.55710306 | M80: 72.6 | N80: 74.7 | O80: 70.4 | P80: 1.74703 | Q80: =O80/P80 -> 40.296961 | R80: =(Q80/$R$3)*100 -> 66.267286
A81: 202403 | D81: 68.05 | E81: 8.55 | F81: #N/A | I81: 200603 | J81: 71.8 | K81: =((J81/J69)-1)*100 -> -0.41608877 | L81: =((J81/J80)-1)*100 -> -0.55401662 | M81: 73.3 | N81: 74.9 | O81: 69.4 | P81: 1.7435261 | Q81: =O81/P81 -> 39.804394 | R81: =(Q81/$R$3)*100 -> 65.457273
I82: 200604 | J82: 71.7 | K82: =((J82/J70)-1)*100 -> 0.42016807 | L82: =((J82/J81)-1)*100 -> -0.13927577 | M82: 73 | N82: 75.3 | O82: 69.7 | P82: 1.776631 | Q82: =O82/P82 -> 39.231556 | R82: =(Q82/$R$3)*100 -> 64.515256
I83: 200605 | J83: 72.7 | K83: =((J83/J71)-1)*100 -> 1.1126565 | L83: =((J83/J82)-1)*100 -> 1.3947001 | M83: 73.4 | N83: 75.8 | O83: 71 | P83: 1.809736 | Q83: =O83/P83 -> 39.232242 | R83: =(Q83/$R$3)*100 -> 64.516384
I84: 200606 | J84: 73.2 | K84: =((J84/J72)-1)*100 -> 1.8080668 | L84: =((J84/J83)-1)*100 -> 0.68775791 | M84: 74.1 | N84: 76 | O84: 71.1 | P84: 1.8428409 | Q84: =O84/P84 -> 38.581735 | R84: =(Q84/$R$3)*100 -> 63.446643
I85: 200607 | J85: 73.3 | K85: =((J85/J73)-1)*100 -> 3.0942335 | L85: =((J85/J84)-1)*100 -> 0.13661202 | M85: 74.3 | N85: 76.1 | O85: 72.9 | P85: 1.8447429 | Q85: =O85/P85 -> 39.517703 | R85: =(Q85/$R$3)*100 -> 64.985816
I86: 200608 | J86: 73.7 | K86: =((J86/J74)-1)*100 -> 3.511236 | L86: =((J86/J85)-1)*100 -> 0.54570259 | M86: 74.8 | N86: 76.3 | O86: 72.9 | P86: 1.8647214 | Q86: =O86/P86 -> 39.094311 | R86: =(Q86/$R$3)*100 -> 64.28956
I87: 200609 | J87: 74.1 | K87: =((J87/J75)-1)*100 -> 3.9270687 | L87: =((J87/J86)-1)*100 -> 0.54274084 | M87: 74.8 | N87: 76.4 | O87: 73 | P87: 1.8847 | Q87: =O87/P87 -> 38.732955 | R87: =(Q87/$R$3)*100 -> 63.695319
I88: 200610 | J88: 74.5 | K88: =((J88/J76)-1)*100 -> 4.7819972 | L88: =((J88/J87)-1)*100 -> 0.53981107 | M88: 73.9 | N88: 76.4 | O88: 74.9 | P88: 1.8755227 | Q88: =O88/P88 -> 39.935533 | R88: =(Q88/$R$3)*100 -> 65.672927
I89: 200611 | J89: 75.2 | K89: =((J89/J77)-1)*100 -> 5.027933 | L89: =((J89/J88)-1)*100 -> 0.93959732 | M89: 74.9 | N89: 76.7 | O89: 77.5 | P89: 1.9118545 | Q89: =O89/P89 -> 40.536557 | R89: =(Q89/$R$3)*100 -> 66.661295
...

Sheet HAVER - UK Gas
D1: 1 | E1: 2 | F1: 3 | G1: 4 | H1: 5 | I1: 6 | J1: 7 | K1: 8 | L1: 9 | M1: 10 | N1: 11 | O1: 12 | P1: 13 | Q1: 14 | R1: 15 | S1: 16 | T1: 17 | U1: 18 | V1: 19 | W1: 20 | X1: 21 | Y1: 22 | Z1: 23 | AA1: 24 | AB1: 25 | AC1: 26 | AD1: 27 | AE1: 28 | AF1: 29 | AG1: 30 | AH1: 31 | AI1: 32 | AJ1: 33 | AK1: 34 | AL1: 35 | AM1: 36 | AN1: 37 | AO1: 38 | AP1: 39 | AQ1: 40 | AR1: 41 | AS1: 42 | AT1: 43 | AU1: 44 | AV1: 45 | AW1: 46 | AX1: 47 | AY1: 48
B2: 20170101 !D | C2: .excel_last | D2: IFNG01C@CMDTY | E2: IFNG02C@CMDTY | F2: IFNG03C@CMDTY | G2: IFNG04C@CMDTY | H2: IFNG05C@CMDTY | I2: IFNG06C@CMDTY | J2: IFNG07C@CMDTY | K2: IFNG08C@CMDTY | L2: IFNG09C@CMDTY | M2: IFNG10C@CMDTY | N2: IFNG11C@CMDTY | O2: IFNG12C@CMDTY | P2: IFNG13C@CMDTY | Q2: IFNG14C@CMDTY | R2: IFNG15C@CMDTY | S2: IFNG16C@CMDTY | T2: IFNG17C@CMDTY | U2: IFNG18C@CMDTY | V2: IFNG19C@CMDTY | W2: IFNG20C@CMDTY | X2: IFNG21C@CMDTY | Y2: IFNG22C@CMDTY | Z2: IFNG23C@CMDTY | AA2: IFNG24C@CMDTY | AB2: IFNG25C@CMDTY | AC2: IFNG26C@CMDTY | AD2: IFNG27C@CMDTY | AE2: IFNG28C@CMDTY | AF2: IFNG29C@CMDTY | AG2: IFNG30C@CMDTY | AH2: IFNG31C@CMDTY | AI2: IFNG32C@CMDTY | AJ2: IFNG33C@CMDTY | AK2: IFNG34C@CMDTY | AL2: IFNG35C@CMDTY | AM2: IFNG36C@CMDTY | AN2: IFNG37C@CMDTY | AO2: IFNG38C@CMDTY | AP2: IFNG39C@CMDTY | AQ2: IFNG40C@CMDTY | AR2: IFNG41C@CMDTY | AS2: IFNG42C@CMDTY | AT2: IFNG43C@CMDTY | AU2: IFNG44C@CMDTY | AV2: IFNG45C@CMDTY | AW2: IFNG46C@CMDTY | AX2: IFNG47C@CMDTY | AY2: IFNG48C@CMDTY
B3: .DESC | D3: ICE UK Natural Gas Futures: 1st Position: Settlement Price (Sterling/Therm) | E3: ICE UK Natural Gas Futures: 2nd Position: Settlement Price (Sterling/Therm) | F3: ICE UK Natural Gas Futures: 3rd Position: Settlement Price (Sterling/Therm) | G3: ICE UK Natural Gas Futures: 4th Position: Settlement Price (Sterling/Therm) | H3: ICE UK Natural Gas Futures: 5th Position: Settlement Price (Sterling/Therm) | I3: ICE UK Natural Gas Futures: 6th Position: Settlement Price (Sterling/Therm) | J3: ICE UK Natural Gas Futures: 7th Position: Settlement Price (Sterling/Therm) | K3: ICE UK Natural Gas Futures: 8th Position: Settlement Price (Sterling/Therm) | L3: ICE UK Natural Gas Futures: 9th Position: Settlement Price (Sterling/Therm) | M3: ICE UK Natural Gas Futures: 10th Position: Settlement Price (Sterling/Therm) | N3: ICE UK Natural Gas Futures: 11th Position: Settlement Price (Sterling/Therm) | O3: ICE UK Natural Gas Futures: 12th Position: Settlement Price (Sterling/Therm) | P3: ICE UK Natural Gas Futures: 13th Position: Settlement Price (Sterling/Therm) | Q3: ICE UK Natural Gas Futures: 14th Position: Settlement Price (Sterling/Therm) | R3: ICE UK Natural Gas Futures: 15th Position: Settlement Price (Sterling/Therm) | S3: ICE UK Natural Gas Futures: 16th Position: Settlement Price (Sterling/Therm) | T3: ICE UK Natural Gas Futures: 17th Position: Settlement Price (Sterling/Therm) | U3: ICE UK Natural Gas Futures: 18th Position: Settlement Price (Sterling/Therm) | V3: ICE UK Natural Gas Future: 19th Position: Settlement Price (Sterling/Therm) | W3: ICE UK Natural Gas Future: 20th Position: Settlement Price (Sterling/Therm) | X3: ICE UK Natural Gas Future: 21st Position: Settlement Price (Sterling/Therm) | Y3: ICE UK Natural Gas Future: 22nd Position: Settlement Price (Sterling/Therm) | Z3: ICE UK Natural Gas Future: 23rd Position: Settlement Price (Sterling/Therm) | AA3: ICE UK Natural Gas Future: 24th Position: Settlement Price (Sterling/Therm) | AB3: ICE UK Natural Gas Future: 25th Position: Settlement Price (Sterling/Therm) | AC3: ICE UK Natural Gas Future: 26th Position: Settlement Price (Sterling/Therm) | AD3: ICE UK Natural Gas Future: 27th Position: Settlement Price (Sterling/Therm) | AE3: ICE UK Natural Gas Future: 28th Position: Settlement Price (Sterling/Therm) | AF3: ICE UK Natural Gas Future: 29th Position: Settlement Price (Sterling/Therm) | AG3: ICE UK Natural Gas Future: 30th Position: Settlement Price (Sterling/Therm) | AH3: ICE UK Natural Gas Future: 31st Position: Settlement Price (Sterling/Therm) | AI3: ICE UK Natural Gas Future: 32nd Position: Settlement Price (Sterling/Therm) | AJ3: ICE UK Natural Gas Future: 33rd Position: Settlement Price (Sterling/Therm) | AK3: ICE UK Natural Gas Future: 34th Position: Settlement Price (Sterling/Therm) | AL3: ICE UK Natural Gas Future: 35th Position: Settlement Price (Sterling/Therm) | AM3: ICE UK Natural Gas Future: 36th Position: Settlement Price (Sterling/Therm) | AN3: ICE UK Natural Gas Future: 37th Position: Settlement Price (Sterling/Therm) | AO3: ICE UK Natural Gas Future: 38th Position: Settlement Price (Sterling/Therm) | AP3: ICE UK Natural Gas Future: 39th Position: Settlement Price (Sterling/Therm) | AQ3: ICE UK Natural Gas Future: 40th Position: Settlement Price (Sterling/Therm) | AR3: ICE UK Natural Gas Future: 41st Position: Settlement Price (Sterling/Therm) | AS3: ICE UK Natural Gas Future: 42nd Position: Settlement Price (Sterling/Therm) | AT3: ICE UK Natural Gas Future: 43rd Position: Settlement Price (Sterling/Therm) | AU3: ICE UK Natural Gas Future: 44th Position: Settlement Price (Sterling/Therm) | AV3: ICE UK Natural Gas Future: 45th Position: Settlement Price (Sterling/Therm) | AW3: ICE UK Natural Gas Future: 46th Position: Settlement Price (Sterling/Therm) | AX3: ICE UK Natural Gas Future: 47th Position: Settlement Price (Sterling/Therm) | AY3: ICE UK Natural Gas Future: 48th Position: Settlement Price (Sterling/Therm)
B4: .T1 | D4: 31-Jan-1997 | E4: 31-Jan-1997 | F4: 31-Jan-1997 | G4: 31-Jan-1997 | H4: 31-Jan-1997 | I4: 31-Jan-1997 | J4: 31-Jan-1997 | K4: 31-Jan-1997 | L4: 31-Jan-1997 | M4: 31-Jan-1997 | N4: 31-Jan-1997 | O4: 29-Jun-2004 | P4: 28-Feb-2007 | Q4: 11-Apr-2008 | R4: 11-Apr-2008 | S4: 11-Apr-2008 | T4: 11-Apr-2008 | U4: 30-May-2008 | V4: 16-Aug-2010 | W4: 16-Aug-2010 | X4: 16-Aug-2010 | Y4: 16-Aug-2010 | Z4: 16-Aug-2010 | AA4: 16-Aug-2010 | AB4: 16-Aug-2010 | AC4: 16-Aug-2010 | AD4: 16-Aug-2010 | AE4: 16-Aug-2010 | AF4: 16-Aug-2010 | AG4: 16-Aug-2010 | AH4: 16-Aug-2010 | AI4: 16-Aug-2010 | AJ4: 16-Aug-2010 | AK4: 16-Aug-2010 | AL4: 16-Aug-2010 | AM4: 16-Aug-2010 | AN4: 16-Aug-2010 | AO4: 16-Aug-2010 | AP4: 16-Aug-2010 | AQ4: 16-Aug-2010 | AR4: 16-Aug-2010 | AS4: 16-Aug-2010 | AT4: 16-Aug-2010 | AU4: 16-Aug-2010 | AV4: 16-Aug-2010 | AW4: 16-Aug-2010 | AX4: 16-Aug-2010 | AY4: 16-Aug-2010
B5: .TN | D5: 09-Apr-2024 | E5: 09-Apr-2024 | F5: 09-Apr-2024 | G5: 09-Apr-2024 | H5: 09-Apr-2024 | I5: 09-Apr-2024 | J5: 09-Apr-2024 | K5: 09-Apr-2024 | L5: 09-Apr-2024 | M5: 09-Apr-2024 | N5: 09-Apr-2024 | O5: 09-Apr-2024 | P5: 09-Apr-2024 | Q5: 09-Apr-2024 | R5: 09-Apr-2024 | S5: 09-Apr-2024 | T5: 09-Apr-2024 | U5: 09-Apr-2024 | V5: 09-Apr-2024 | W5: 09-Apr-2024 | X5: 09-Apr-2024 | Y5: 09-Apr-2024 | Z5: 09-Apr-2024 | AA5: 09-Apr-2024 | AB5: 09-Apr-2024 | AC5: 09-Apr-2024 | AD5: 09-Apr-2024 | AE5: 09-Apr-2024 | AF5: 09-Apr-2024 | AG5: 09-Apr-2024 | AH5: 09-Apr-2024 | AI5: 09-Apr-2024 | AJ5: 09-Apr-2024 | AK5: 09-Apr-2024 | AL5: 09-Apr-2024 | AM5: 09-Apr-2024 | AN5: 09-Apr-2024 | AO5: 09-Apr-2024 | AP5: 09-Apr-2024 | AQ5: 09-Apr-2024 | AR5: 09-Apr-2024 | AS5: 09-Apr-2024 | AT5: 09-Apr-2024 | AU5: 09-Apr-2024 | AV5: 09-Apr-2024 | AW5: 09-Apr-2024 | AX5: 09-Apr-2024 | AY5: 09-Apr-2024
B6: .LSOURCE | D6: IntercontinentalExchange | E6: IntercontinentalExchange | F6: IntercontinentalExchange | G6: IntercontinentalExchange | H6: IntercontinentalExchange | I6: IntercontinentalExchange | J6: IntercontinentalExchange | K6: IntercontinentalExchange | L6: IntercontinentalExchange | M6: IntercontinentalExchange | N6: IntercontinentalExchange | O6: IntercontinentalExchange | P6: IntercontinentalExchange | Q6: IntercontinentalExchange | R6: IntercontinentalExchange | S6: IntercontinentalExchange | T6: IntercontinentalExchange | U6: IntercontinentalExchange | V6: IntercontinentalExchange | W6: IntercontinentalExchange | X6: IntercontinentalExchange | Y6: IntercontinentalExchange | Z6: IntercontinentalExchange | AA6: IntercontinentalExchange | AB6: IntercontinentalExchange | AC6: IntercontinentalExchange | AD6: IntercontinentalExchange | AE6: IntercontinentalExchange | AF6: IntercontinentalExchange | AG6: IntercontinentalExchange | AH6: IntercontinentalExchange | AI6: IntercontinentalExchange | AJ6: IntercontinentalExchange | AK6: IntercontinentalExchange | AL6: IntercontinentalExchange | AM6: IntercontinentalExchange | AN6: IntercontinentalExchange | AO6: IntercontinentalExchange | AP6: IntercontinentalExchange | AQ6: IntercontinentalExchange | AR6: IntercontinentalExchange | AS6: IntercontinentalExchange | AT6: IntercontinentalExchange | AU6: IntercontinentalExchange | AV6: IntercontinentalExchange | AW6: IntercontinentalExchange | AX6: IntercontinentalExchange | AY6: IntercontinentalExchange
B7: .DTLM | D7: Apr-10-2024 03:12 | E7: Apr-10-2024 03:12 | F7: Apr-10-2024 03:12 | G7: Apr-10-2024 03:12 | H7: Apr-10-2024 03:12 | I7: Apr-10-2024 03:12 | J7: Apr-10-2024 03:12 | K7: Apr-10-2024 03:12 | L7: Apr-10-2024 03:12 | M7: Apr-10-2024 03:12 | N7: Apr-10-2024 03:12 | O7: Apr-10-2024 03:12 | P7: Apr-10-2024 03:12 | Q7: Apr-10-2024 03:12 | R7: Apr-10-2024 03:12 | S7: Apr-10-2024 03:12 | T7: Apr-10-2024 03:12 | U7: Apr-10-2024 03:12 | V7: Apr-10-2024 03:12 | W7: Apr-10-2024 03:12 | X7: Apr-10-2024 03:12 | Y7: Apr-10-2024 03:12 | Z7: Apr-10-2024 03:12 | AA7: Apr-10-2024 03:12 | AB7: Apr-10-2024 03:12 | AC7: Apr-10-2024 03:12 | AD7: Apr-10-2024 03:12 | AE7: Apr-10-2024 03:12 | AF7: Apr-10-2024 03:12 | AG7: Apr-10-2024 03:12 | AH7: Apr-10-2024 03:12 | AI7: Apr-10-2024 03:12 | AJ7: Apr-10-2024 03:12 | AK7: Apr-10-2024 03:12 | AL7: Apr-10-2024 03:12 | AM7: Apr-10-2024 03:12 | AN7: Apr-10-2024 03:12 | AO7: Apr-10-2024 03:12 | AP7: Apr-10-2024 03:12 | AQ7: Apr-10-2024 03:12 | AR7: Apr-10-2024 03:12 | AS7: Apr-10-2024 03:12 | AT7: Apr-10-2024 03:12 | AU7: Apr-10-2024 03:12 | AV7: Apr-10-2024 03:12 | AW7: Apr-10-2024 03:12 | AX7: Apr-10-2024 03:12 | AY7: Apr-10-2024 03:12
A8: 42737 | B8: 20170102 | C8: 42737 | D8: 53.63 | E8: 52.47 | F8: 50.06 | G8: 47.79 | H8: 45.84 | I8: 45.85 | J8: 45.98 | K8: 46.29 | L8: 48.14 | M8: 51.71 | N8: 53.29 | O8: 53.87 | P8: 54.08 | Q8: 52.93 | R8: 49.32 | S8: 45.74 | T8: 44.74 | U8: 45.08 | V8: 45.24 | W8: 45.07 | X8: 48.13 | Y8: 50.28 | Z8: 50.87 | AA8: 52.84 | AB8: 52.5 | AC8: 51.06 | AD8: 46.22 | AE8: 44.8 | AF8: 44.12 | AG8: 44.36 | AH8: 44.67 | AI8: 44.99 | AJ8: 48.74 | AK8: 49.4 | AL8: 50.74 | AM8: 51.88 | AN8: 49.84 | AO8: 48.9 | AP8: 45.61 | AQ8: 44.45 | AR8: 44.25 | AS8: 44.32 | AT8: 44.69 | AU8: 45.62 | AV8: 49.02 | AW8: 50.23 | AX8: 50.66 | AY8: 51.23
A9: =+A8+1 -> 42738 | B9: 20170103 | C9: 42738 | D9: 49.45 | E9: 48.66 | F9: 46.82 | G9: 44.95 | H9: 43.2 | I9: 43.27 | J9: 43.4 | K9: 43.59 | L9: 45.19 | M9: 48.69 | N9: 50.4 | O9: 51.11 | P9: 51.29 | Q9: 49.89 | R9: 46.11 | S9: 43.32 | T9: 42.07 | U9: 42.34 | V9: 42.5 | W9: 42.32 | X9: 45.43 | Y9: 47.58 | Z9: 48.13 | AA9: 50.1 | AB9: 49.76 | AC9: 48.6 | AD9: 43.99 | AE9: 42.57 | AF9: 41.89 | AG9: 42.13 | AH9: 42.44 | AI9: 42.76 | AJ9: 46.51 | AK9: 47.17 | AL9: 48.51 | AM9: 49.65 | AN9: 47.61 | AO9: 46.67 | AP9: 43.38 | AQ9: 42.22 | AR9: 42.02 | AS9: 42.09 | AT9: 42.46 | AU9: 43.39 | AV9: 46.79 | AW9: 48 | AX9: 48.43 | AY9: 49
A10: =+A9+1 -> 42739 | B10: 20170104 | C10: 42739 | D10: 50.68 | E10: 49.81 | F10: 47.81 | G10: 45.74 | H10: 43.97 | I10: 44.04 | J10: 44.17 | K10: 44.33 | L10: 45.93 | M10: 49.43 | N10: 51.14 | O10: 51.85 | P10: 52 | Q10: 50.6 | R10: 46.84 | S10: 44.05 | T10: 42.8 | U10: 43.1 | V10: 43.27 | W10: 43.1 | X10: 46.19 | Y10: 48.32 | Z10: 48.87 | AA10: 50.84 | AB10: 50.5 | AC10: 49.34 | AD10: 44.66 | AE10: 43.24 | AF10: 42.56 | AG10: 42.8 | AH10: 43.11 | AI10: 43.43 | AJ10: 47.18 | AK10: 47.84 | AL10: 49.18 | AM10: 50.32 | AN10: 48.28 | AO10: 47.34 | AP10: 44.05 | AQ10: 42.89 | AR10: 42.69 | AS10: 42.76 | AT10: 43.13 | AU10: 44.06 | AV10: 47.46 | AW10: 48.67 | AX10: 49.1 | AY10: 49.67
A11: =+A10+1 -> 42740 | B11: 20170105 | C11: 42740 | D11: 50.69 | E11: 49.81 | F11: 47.97 | G11: 45.77 | H11: 43.87 | I11: 43.88 | J11: 44.11 | K11: 44.38 | L11: 45.9 | M11: 49.3 | N11: 50.92 | O11: 51.63 | P11: 51.78 | Q11: 50.38 | R11: 46.66 | S11: 43.87 | T11: 42.61 | U11: 42.89 | V11: 43.05 | W11: 42.78 | X11: 45.77 | Y11: 47.87 | Z11: 48.48 | AA11: 50.52 | AB11: 50.22 | AC11: 49.06 | AD11: 44.36 | AE11: 42.94 | AF11: 42.26 | AG11: 42.5 | AH11: 42.81 | AI11: 43.13 | AJ11: 46.88 | AK11: 47.54 | AL11: 48.88 | AM11: 50.02 | AN11: 47.98 | AO11: 47.04 | AP11: 43.75 | AQ11: 42.59 | AR11: 42.39 | AS11: 42.46 | AT11: 42.83 | AU11: 43.76 | AV11: 47.16 | AW11: 48.37 | AX11: 48.8 | AY11: 49.37
A12: =+A11+1 -> 42741 | B12: 20170106 | C12: 42741 | D12: 49.77 | E12: 48.99 | F12: 47.1 | G12: 44.99 | H12: 43.06 | I12: 43.06 | J12: 43.27 | K12: 43.56 | L12: 45.08 | M12: 48.48 | N12: 50.12 | O12: 50.86 | P12: 51.01 | Q12: 49.61 | R12: 45.95 | S12: 43.15 | T12: 41.88 | U12: 42.17 | V12: 42.34 | W12: 42.08 | X12: 45.05 | Y12: 47.16 | Z12: 47.77 | AA12: 49.81 | AB12: 49.51 | AC12: 48.35 | AD12: 43.65 | AE12: 42.23 | AF12: 41.55 | AG12: 41.79 | AH12: 42.1 | AI12: 42.42 | AJ12: 46.17 | AK12: 46.83 | AL12: 48.17 | AM12: 49.31 | AN12: 47.27 | AO12: 46.33 | AP12: 43.04 | AQ12: 41.88 | AR12: 41.68 | AS12: 41.75 | AT12: 42.12 | AU12: 43.05 | AV12: 46.45 | AW12: 47.66 | AX12: 48.09 | AY12: 48.66
