Workbook
Name _DLX1.INC: HAVERQ!$A$3:$BJ$8
Name _DLX2.INC: HAVERM!$A$2:$BL$7
Name Annual_Data: GMWA!$A$1:$A$2
Name Annual_Data: GMWQ!$A$1:$A$2
Name Data: [1]sheet0!$C$2

Sheet >> CHARTS

Sheet >> DATA

Sheet Chart Data
A1: Business investment & corporate gearing rate | F1: Business investment & corporate gearing rate (4qma) | N1: Business investment & ICT (Q1 2021=100) | T1: Business investment by industry (Diff vs Q1 2021, £bn) | AA1: Business investment by industry (cont to rise since Q1 2021) | AH1: Business investment by industry (cont to change since Q4 2019) | AO1: Business investment by industry (cont to change since 2016) | AV1: Interest rates | BA1: Interest rates - change since Bank Rate started to rise | BI1: Business investment by industry (Q4 2019=100) | BQ1: Business investment by industry (Diff vs Q4 2019, £bn) | BY1: Business investment by industry (cont to change since Q4 2019) | CG1: Business investment by industry (£bn) | CN1: Business investment by sector - services (Diff vs Q4 2019, £bn) | CW1: Business investment by sector - services (Diff vs Q4 2019, £bn) | DI1: Investment by asset (Q4 2019=100) | DR1: Business investment by asset (Diff vs Q4 2019, £bn) | DZ1: Surveys vs business investment | EL1: Standard deviations | EQ1: Whole economy weighted averages | EV1: Weights | EW1: Manufacturing | EX1: Services | EY1: Retail | EZ1: B&P | FA1: Consumer | FC1: Corporate debt - SMEs vs large (Feb20=100) | FI1: Services - business investment shortfall vs change in debt | FV1: Corporate deposits vs pre-pandemic trend | GC1: Business investment forecasts | GJ1: Business investment historical revisions | GO1: Business investment historical revisions | GT1: IPNR - UK vs G7 | HA1: Business investment history | HJ1: IPNR - UK vs G7 | HQ1: Business investment forecast | HZ1: Capital stock per hour worked | IH1: CBI surveys - constraints on investment | IQ1: Business investment & expected loan growth | IW1: Financing: | IX1: https://twitter.com/Gilesyb/status/1519332233206714375?s=20&t=cwRE5RP0CO_DabR5P63a5w
N2: https://www.gov.uk/guidance/super-deduction | EQ2: LT av | ER2: =AVERAGE(ER7:ER102) -> 8.20371 | ES2: =AVERAGE(ES7:ES102) -> -6.2358118 | ET2: =AVERAGE(ET7:ET102) -> 0.82260665 | EW2: =SUM(HAVERQ!I125:I128)/SUM(HAVERQ!B125:B128) -> 0.15573293 | EX2: =1-EW2 -> 0.84426707 | EY2: =SUM(HAVERQ!L125:L128)/SUM(HAVERQ!B125:B128) -> 0.089018552 | EZ2: =1-EW2-EY2-FA2 -> 0.73088214 | FA2: =SUM(HAVERQ!O125:O128)/SUM(HAVERQ!B125:B128) -> 0.024366377 | FI2: Q2 2024 vs Q4 2019 | GC2: Q4 2019 = 100 | GJ2: 2022 = 100 | GO2: Q4 2019= 100 | IH2: Z scores | IW2: Debt and investmet: | IX2: https://bankunderground.co.uk/2022/05/25/debt-and-investment-what-can-we-learn-from-smes-investment-behaviour-during-and-after-the-global-financial-crisis/
EQ3: STDEV | ER3: =STDEV(ER7:ER102) -> 11.720889 | ES3: =STDEV(ES7:ES102) -> 14.071805 | ET3: =STDEV(ET7:ET102) -> 1.570543 | IX3: https://bankunderground.co.uk/2021/09/28/weighed-down-by-debt-revisiting-the-link-between-corporate-debt-overhang-and-investment/
B4: Business investment (LHS) | C4: Corporate debt servicing costs (RHS) | D4: ZERO LINE | G4: Business investment (LHS) | H4: Corporate debt servicing costs (RHS) | I4: ZERO LINE | K4: CGEAR forecast | L4: Actual CGEAR | O4: Total business investment | P4: ICT equipment and other machinery | Q4: Super deduction | R4: 100 LINE | U4: Transport equipment | V4: ICT equipment and other machinery | W4: Other buildings & structures | X4: Intellectual property products | Y4: Total | AB4: Transport equipment | AC4: ICT equipment and other machinery | AD4: Other buildings & structures | AE4: Intellectual property products | AF4: Total | AI4: Transport equipment | AJ4: ICT equipment and other machinery | AK4: Other buildings & structures | AL4: Intellectual property products | AM4: Total | AP4: Transport equipment | AQ4: ICT equipment & oth. machinery | AR4: Other buildings & structures | AS4: Intellectual property products | AT4: Total | AW4: Bank Rate | AX4: Non-financial corporations | AY4: Secured household | BB4: Non-financial corporations | BC4: Secured household | BD4: Hiking cycle | BE4: Cutting cycle | BF4: ZERO LINE | BJ4: Total | BK4: Manufacturing | BL4: Other production | BM4: Construction | BN4: Services | BO4: 100 LINE | BR4: Manufacturing | BS4: Other production | BT4: Construction | BU4: Services | BV4: Other | BW4: Total | BZ4: Manufacturing | CA4: Other production | CB4: Construction | CC4: Services | CD4: Other | CE4: Total | CH4: Manufacturing | CI4: Other production | CJ4: Construction | CK4: Services | CL4: Other | CO4: Distribution | CP4: Hotels & restaurants | CQ4: Financial interm. | CR4: Transport | CS4: Real estate | CT4: Other | CU4: Total services | CX4: Distribution | CY4: Hotels & restaurants | CZ4: Financial interm. | DA4: Transport | DB4: Information & comms | DC4: Real estate | DD4: Education | DE4: Health | DF4: Other services | DG4: Total services | DJ4: Total | DK4: Transport equipment | DL4: ICT and other machinery | DM4: Dwellings | DN4: Other buildings | DO4: Intellectual property | DP4: 100 LINE | DS4: Transport equipment | DT4: ICT and other machinery | DU4: Dwellings | DV4: Other buildings | DW4: Intellectual property | DX4: Total | EA4: Min | EB4: Range of surveys* (LHS) | EC4: Business investment (RHS) | ED4: ZERO LINE | EF4: Max | EG4: Average | EJ4: Business investment exc nuclear fuels | EM4: BCC | EN4: CBI | EO4: BoE agents | ER4: BCC | ES4: CBI | ET4: BoE agents | FD4: All firms | FE4: SMEs | FF4: Large | FG4: 100 LINE | FJ4: Manufacturing | FK4: Utilities | FL4: Construction | FM4: Distribution | FN4: Hotels & restaurants | FO4: Transport & comms | FP4: Real estate | FQ4: Education | FR4: Health | FS4: Other services | FT4: Total services | FW4: Actual | FX4: Assuming 2016-2019 trend had continued | FY4: Monthly change | FZ4: Av monthly change | GA4: Difference | GD4: January 2020 | GE4: June 2021 | GF4: September 2024 | GG4: Super deduction | GH4: 100 LINE | GK4: September 2024 | GL4: October 2024 | GM4: 100 LINE | GP4: September 2024 | GQ4: October 2024 | GR4: 100 LINE | GU4: UK | GV4: G7 bottom | GW4: Range of G7 exc. UK | GX4: 100 LINE | GY4: G7 top | HB4: UK | HC4: US | HD4: Japan | HE4: Germany | HF4: France | HG4: Italy | HH4: Canada | HK4: UK | HL4: G7 bottom | HM4: Range of G7 exc. UK | HN4: 100 LINE | HO4: G7 top | HR4: UK | HS4: US | HT4: Japan | HU4: Germany | HV4: France | HW4: Italy | HX4: Canada | IA4: Actual | IB4: Pre-2008 trend | IC4: Difference | IF4: Hours worked | II4: Inadequate net return | IJ4: Internal finance shortage | IK4: Unable to raise finance | IL4: Cost of finance | IM4: Demand uncertainty | IN4: Labour Shortage | IO4: Other | IR4: Expected change in loan demand due to investment (LHS) | IS4: Business investment (RHS) | IT4: ZERO LINE
A5: 1990 | B5: =100*((DataQ!C75/DataQ!C71)-1) -> 1.672029 | C5: =K5 -> 18.593076 | D5: 0 | F5: 1990 | I5: 0 | K5: =L5 -> 18.593076 | L5: =100*(HAVERQ!AF9/HAVERQ!AI9) -> 18.593076 | N5: 2018 | O5: =100*('ONS CVM_SA_(Quarterly)'!B89/'ONS CVM_SA_(Quarterly)'!B$101) -> 113.95928 | P5: =100*('ONS CVM_SA_(Quarterly)'!D89/'ONS CVM_SA_(Quarterly)'!D$101) -> 115.73484 | R5: 100 | T5: 2021 | U5: ='ONS CVM_SA_(Quarterly)'!C101-'ONS CVM_SA_(Quarterly)'!C$101 -> 0 | V5: ='ONS CVM_SA_(Quarterly)'!D101-'ONS CVM_SA_(Quarterly)'!D$101 -> 0 | W5: ='ONS CVM_SA_(Quarterly)'!E101-'ONS CVM_SA_(Quarterly)'!E$101 -> 0 | X5: ='ONS CVM_SA_(Quarterly)'!F101-'ONS CVM_SA_(Quarterly)'!F$101 -> 0 | Y5: ='ONS CVM_SA_(Quarterly)'!B101-'ONS CVM_SA_(Quarterly)'!B$101 -> 0 | AA5: 2021 | AB5: =100*(U5/'ONS CVM_SA_(Quarterly)'!$B$101) -> 0 | AC5: =100*(V5/'ONS CVM_SA_(Quarterly)'!$B$101) -> 0 | AD5: =100*(W5/'ONS CVM_SA_(Quarterly)'!$B$101) -> 0 | AE5: =100*(X5/'ONS CVM_SA_(Quarterly)'!$B$101) -> 0 | AF5: =100*(('ONS CVM_SA_(Quarterly)'!B101/'ONS CVM_SA_(Quarterly)'!B$101)-1) -> 0 | AH5: 2019 | AI5: =100*(('ONS CVM_SA_(Quarterly)'!C93-'ONS CVM_SA_(Quarterly)'!C$96)/'ONS CVM_SA_(Quarterly)'!$B$96) -> 1.3469045 | AJ5: =100*(('ONS CVM_SA_(Quarterly)'!D93-'ONS CVM_SA_(Quarterly)'!D$96)/'ONS CVM_SA_(Quarterly)'!$B$96) -> 0.58231442 | AK5: =100*(('ONS CVM_SA_(Quarterly)'!E93-'ONS CVM_SA_(Quarterly)'!E$96)/'ONS CVM_SA_(Quarterly)'!$B$96) -> 0.41778237 | AL5: =100*(('ONS CVM_SA_(Quarterly)'!F93-'ONS CVM_SA_(Quarterly)'!F$96)/'ONS CVM_SA_(Quarterly)'!$B$96) -> -1.3194825 | AM5: =100*(('ONS CVM_SA_(Quarterly)'!B93-'ONS CVM_SA_(Quarterly)'!B$96)/'ONS CVM_SA_(Quarterly)'!$B$96) -> -1.279156 | AO5: 2016 | AP5: =100*(('ONS CVM_SA_(Quarterly)'!C81-AVERAGE('ONS CVM_SA_(Quarterly)'!C$81:C$84))/AVERAGE('ONS CVM_SA_(Quarterly)'!$B$81:$B$84)) -> 1.2876667 | AQ5: =100*(('ONS CVM_SA_(Quarterly)'!D81-AVERAGE('ONS CVM_SA_(Quarterly)'!D$81:D$84))/AVERAGE('ONS CVM_SA_(Quarterly)'!$B$81:$B$84)) -> 0.1616674 | AR5: =100*(('ONS CVM_SA_(Quarterly)'!E81-AVERAGE('ONS CVM_SA_(Quarterly)'!E$81:E$84))/AVERAGE('ONS CVM_SA_(Quarterly)'!$B$81:$B$84)) -> -0.32455035 | AS5: =100*(('ONS CVM_SA_(Quarterly)'!F81-AVERAGE('ONS CVM_SA_(Quarterly)'!F$81:F$84))/AVERAGE('ONS CVM_SA_(Quarterly)'!$B$81:$B$84)) -> -0.33143843 | AT5: =100*(('ONS CVM_SA_(Quarterly)'!B81-AVERAGE('ONS CVM_SA_(Quarterly)'!B$81:B$84))/AVERAGE('ONS CVM_SA_(Quarterly)'!$B$81:$B$84)) -> -0.027147158 | AV5: 43466 | AW5: =HAVERM!D236 -> 0.75 | AX5: =HAVERM!B236 -> 3.35 | AY5: =HAVERM!C236 -> 2.48 | BA5: 44531 | BB5: =AX40-AX$39 -> 0.05 | BC5: =AY40-AY$39 -> -0.01 | BD5: 1000 | BF5: 0 | BI5: 2018 | BJ5: =100*(HAVERQ!B121/HAVERQ!B$128) -> 98.948285 | BK5: =100*(HAVERQ!I121/HAVERQ!I$128) -> 104.1024 | BL5: =100*(HAVERQ!J121/HAVERQ!J$128) -> 87.403786 | BM5: =100*(HAVERQ!K121/HAVERQ!K$128) -> 59.678417 | BN5: =100*((HAVERQ!L121+HAVERQ!M121)/(HAVERQ!L$128+HAVERQ!M$128)) -> 95.582593 | BO5: 100 | BQ5: 2018 | BR5: =HAVERQ!I121-HAVERQ!I$128 -> 383 | BS5: =HAVERQ!J121-HAVERQ!J$128 -> -1211 | BT5: =HAVERQ!K121-HAVERQ!K$128 -> -1304 | BU5: =(HAVERQ!L121+HAVERQ!M121)-(HAVERQ!L$128+HAVERQ!M$128) -> -1750 | BV5: =HAVERQ!N121-HAVERQ!N$128 -> 45 | BW5: =HAVERQ!B121-HAVERQ!B$128 -> -652 | BY5: 2019 | BZ5: =100*((HAVERQ!I125-HAVERQ!I$128)/HAVERQ!$B$128) -> 1.0549408 | CA5: =100*((HAVERQ!J125-HAVERQ!J$128)/HAVERQ!$B$128) -> -2.0469723 | CB5: =100*((HAVERQ!K125-HAVERQ!K$128)/HAVERQ!$B$128) -> -0.44520437 | CC5: =100*(((HAVERQ!L125+HAVERQ!M125)-(HAVERQ!L$128+HAVERQ!M$128))/HAVERQ!$B$128) -> -0.20969771 | CD5: =CE5-BZ5-CA5-CB5-CC5 -> 0.36777753 | CE5: =100*((HAVERQ!B125-HAVERQ!B$128)/HAVERQ!B$128) -> -1.279156 | CG5: 2018 | CH5: =HAVERQ!I121 -> 9719 | CI5: =HAVERQ!J121 -> 8403 | CJ5: =HAVERQ!K121 -> 1930 | CK5: =HAVERQ!L121+HAVERQ!M121 -> 37866 | CL5: =HAVERQ!N121 -> 1403 | CN5: 2018 | CO5: =CX5 -> -251 | CP5: =CY5 -> 94 | CQ5: =CZ5 -> 80 | CR5: =DA5 -> -442 | CS5: =DC5 -> 1041 | CT5: =+DB5+DD5+DE5+DF5 -> -437 | CU5: =DG5 -> -1750 | CW5: 2018 | CX5: =HAVERQ!L121-HAVERQ!L$128 -> -251 | CY5: =HAVERQ!O121-HAVERQ!O$128 -> 94 | CZ5: =HAVERQ!P121-HAVERQ!P$128 -> 80 | DA5: =HAVERQ!Q121-HAVERQ!Q$128 -> -442 | DB5: =HAVERQ!R121-HAVERQ!R$128 -> -155 | DC5: =HAVERQ!S121-HAVERQ!S$128 -> 1041 | DD5: =HAVERQ!T121-HAVERQ!T$128 -> 127 | DE5: =HAVERQ!U121-HAVERQ!U$128 -> 147 | DF5: =HAVERQ!V121-HAVERQ!V$128 -> -556 | DG5: =(HAVERQ!L121+HAVERQ!M121)-(HAVERQ!L$128+HAVERQ!M$128) -> -1750 | DI5: 2018 | DJ5: =100*(HAVERQ!C121/HAVERQ!C$128) -> 99.463919 | DK5: =100*(HAVERQ!D121/HAVERQ!D$128) -> 120.35968 | DL5: =100*(HAVERQ!E121/HAVERQ!E$128) -> 103.4275 | DM5: =100*(HAVERQ!F121/HAVERQ!F$128) -> 97.293779 | DN5: =100*(HAVERQ!G121/HAVERQ!G$128) -> 99.390359 | DO5: =100*(HAVERQ!H121/HAVERQ!H$128) -> 94.274795 | DP5: 100 | DR5: 2018 | DS5: =HAVERQ!D121-HAVERQ!D$128 -> 917 | DT5: =HAVERQ!E121-HAVERQ!E$128 -> 569 | DU5: =HAVERQ!F121-HAVERQ!F$128 -> -686 | DV5: =HAVERQ!G121-HAVERQ!G$128 -> -226 | DW5: =HAVERQ!H121-HAVERQ!H$128 -> -1513 | DX5: =HAVERQ!C121-HAVERQ!C$128 -> -588 | DZ5: 2000 | EA5: =MIN(EM5:EO5) -> 0.51551789 | EB5: =+EF5-EA5 -> 0.44336509 | EC5: =100*((EJ9/EJ5)-1) -> 6.0508083 | ED5: 0 | EF5: =MAX(EM5:EO5) -> 0.95888298 | EG5: =AVERAGE(EM5:EO5) -> 0.80805841 | EI5: 1999 | EJ5: ='IPNR ex BNFL'!I13 -> 41135 | EM5: =(ER5-ER$2)/ER$3 -> 0.95888298 | EN5: =(ES5-ES$2)/ES$3 -> 0.94977435 | EO5: =(ET5-ET$2)/ET$3 -> 0.51551789 | ER5: =(HAVERQ!W47*$EW$2)+(HAVERQ!X47*$EX$2)/($EW$2+$EX$2) -> 19.442671 | ES5: =(HAVERQ!AB47*$EW$2)+(HAVERQ!AC47*$EY$2)+(HAVERQ!AD47*$EZ$2)+(HAVERQ!AE47*$FA$2)/($EW$2+$EY$2+$EZ$2+$FA$2) -> 7.1292275 | ET5: =(HAVERQ!Y47*$EW$2)+(HAVERQ!Z47*$EX$2)/($EW$2+$EX$2) -> 1.6322497 | FC5: 43466 | FD5: =100*((HAVERM!E236+HAVERM!F236)/(HAVERM!E$249+HAVERM!F$249)) -> 98.455793 | FE5: =100*(HAVERM!E236/HAVERM!E$249) -> 98.994791 | FF5: =100*(HAVERM!F236/HAVERM!F$249) -> 98.160042 | FG5: 100 | FI5: Investment | FJ5: =100*((HAVERQ!I146/HAVERQ!I$128)-1) -> 12.992716 | FK5: =100*((HAVERQ!J146/HAVERQ!J$128)-1) -> 8.0403578 | FL5: =100*((HAVERQ!K146/HAVERQ!K$128)-1) -> -28.911565 | FM5: =100*((HAVERQ!L146/HAVERQ!L$128)-1) -> -44.648919 | FN5: =100*((HAVERQ!O146/HAVERQ!O$128)-1) -> 9.3023256 | FO5: =100*(((HAVERQ!Q146+HAVERQ!R146)/(HAVERQ!Q$128+HAVERQ!R$128))-1) -> 24.249763 | FP5: =100*((HAVERQ!S146/HAVERQ!S$128)-1) -> 14.619818 | FQ5: =100*((HAVERQ!T146/HAVERQ!T$128)-1) -> -6.302202 | FR5: =100*((HAVERQ!U146/HAVERQ!U$128)-1) -> -47.300564 | FS5: =100*((HAVERQ!V146/HAVERQ!V$128)-1) -> -6.9942452 | FT5: =100*(((HAVERQ!L146+HAVERQ!M146)/(HAVERQ!L$128+HAVERQ!M$128))-1) -> -4.8010905 | FV5: 42339 | FW5: =HAVERM!G199 -> 343353 | GC5: 2010 | GD5: =100*(DataQ!W155/DataQ!W$194) -> 73.538662 | GE5: =100*(DataQ!X155/DataQ!X$194) -> 70.761518 | GF5: =100*(DataQ!C155/DataQ!C$194) -> 66.908088 | GH5: 100 | GJ5: 2005 | GK5: =100*(DataQ!Z135/AVERAGE(DataQ!$Z$203:$Z$206)) -> 67.924859 | GL5: =100*(DataQ!C135/AVERAGE(DataQ!$C$203:$C$206)) -> 70.279484 | GM5: 100 | GO5: 2005 | GP5: =100*(DataQ!Z135/DataQ!$Z$194) -> 67.671443 | GQ5: =100*(DataQ!C135/DataQ!$C$194) -> 67.840436 | GR5: 100 | GT5: 2018 | GU5: =HB5 -> 98.948285 | GV5: =MIN(HC5:HH5) -> 93.70119 | GW5: =+GY5-GV5 -> 11.699942 | GX5: 100 | GY5: =MAX(HC5:HH5) -> 105.40113 | HA5: 2018 | HB5: =100*(DataQ!C187/DataQ!C$194) -> 98.948285 | HC5: =100*(DataQ!Q187/DataQ!Q$194) -> 94.445006 | HD5: =100*(DataQ!R187/DataQ!R$194) -> 105.40113 | HE5: =100*(DataQ!S187/DataQ!S$194) -> 96.262109 | HF5: =100*(DataQ!T187/DataQ!T$194) -> 93.70119 | HG5: =100*(DataQ!U187/DataQ!U$194) -> 98.836204 | HH5: =100*(DataQ!V187/DataQ!V$194) -> 97.446653 | HJ5: 2018 | HK5: =HR5 -> 98.948285 | HL5: =MIN(HS5:HX5) -> 93.70119 | HM5: =+HO5-HL5 -> 11.699942 | HN5: 100 | HO5: =MAX(HS5:HX5) -> 105.40113 | HQ5: 2018 | HR5: =100*(DataQ!C187/DataQ!C$194) -> 98.948285 | HS5: =100*(DataQ!Q187/DataQ!Q$194) -> 94.445006 | HT5: =100*(DataQ!R187/DataQ!R$194) -> 105.40113 | HU5: =100*(DataQ!S187/DataQ!S$194) -> 96.262109 | HV5: =100*(DataQ!T187/DataQ!T$194) -> 93.70119 | HW5: =100*(DataQ!U187/DataQ!U$194) -> 98.836204 | HX5: =100*(DataQ!V187/DataQ!V$194) -> 97.446653 | HZ5: 1990 | IA5: =DataA!J24/'Chart Data'!IF5 -> 1.7494582 | IB5: =IA5 -> 1.7494582 | IC5: =100*((IA5/IB5)-1) -> 0 | ID5: =100*((IA22/IA5)^(1/17)-1) -> 2.6565709 | IF5: =DataA!K24*DataA!L24 -> 903065.32 | IH5: Manufacturing | II5: =(HAVERQ!AJ147-HAVERQ!AJ1)/HAVERQ!AJ2 -> -0.64986461 | IJ5: =(HAVERQ!AK147-HAVERQ!AK1)/HAVERQ!AK2 -> -0.15549091 | IK5: =(HAVERQ!AL147-HAVERQ!AL1)/HAVERQ!AL2 -> -0.1555263 | IL5: =(HAVERQ!AM147-HAVERQ!AM1)/HAVERQ!AM2 -> 0.98209825 | IM5: =(HAVERQ!AN147-HAVERQ!AN1)/HAVERQ!AN2 -> -0.97139905 | IN5: =(HAVERQ!AO147-HAVERQ!AO1)/HAVERQ!AO2 -> 0.91449689 | IO5: =(HAVERQ!AP147-HAVERQ!AP1)/HAVERQ!AP2 -> 1.8777181 | IQ5: 2007 | IR5: =HAVERQ!AH76 -> #N/A | IS5: =100*(('IPNR ex BNFL'!I45/'IPNR ex BNFL'!I41)-1) -> 8.6831897 | IT5: 0
B6: =100*((DataQ!C76/DataQ!C72)-1) -> 1.9545723 | C6: =K6 -> 20.025766 | D6: 0 | I6: 0 | K6: =L6 -> 20.025766 | L6: =100*(HAVERQ!AF10/HAVERQ!AI10) -> 20.025766 | O6: =100*('ONS CVM_SA_(Quarterly)'!B90/'ONS CVM_SA_(Quarterly)'!B$101) -> 111.56833 | P6: =100*('ONS CVM_SA_(Quarterly)'!D90/'ONS CVM_SA_(Quarterly)'!D$101) -> 113.69953 | R6: 100 | U6: ='ONS CVM_SA_(Quarterly)'!C102-'ONS CVM_SA_(Quarterly)'!C$101 -> -52 | V6: ='ONS CVM_SA_(Quarterly)'!D102-'ONS CVM_SA_(Quarterly)'!D$101 -> 101 | W6: ='ONS CVM_SA_(Quarterly)'!E102-'ONS CVM_SA_(Quarterly)'!E$101 -> 1967 | X6: ='ONS CVM_SA_(Quarterly)'!F102-'ONS CVM_SA_(Quarterly)'!F$101 -> 2097 | Y6: ='ONS CVM_SA_(Quarterly)'!B102-'ONS CVM_SA_(Quarterly)'!B$101 -> 4159 | AB6: =100*(U6/'ONS CVM_SA_(Quarterly)'!$B$101) -> -0.096603998 | AC6: =100*(V6/'ONS CVM_SA_(Quarterly)'!$B$101) -> 0.18763469 | AD6: =100*(W6/'ONS CVM_SA_(Quarterly)'!$B$101) -> 3.654232 | AE6: =100*(X6/'ONS CVM_SA_(Quarterly)'!$B$101) -> 3.895742 | AF6: =100*(('ONS CVM_SA_(Quarterly)'!B102/'ONS CVM_SA_(Quarterly)'!B$101)-1) -> 7.7264621 | AI6: =100*(('ONS CVM_SA_(Quarterly)'!C94-'ONS CVM_SA_(Quarterly)'!C$96)/'ONS CVM_SA_(Quarterly)'!$B$96) -> 2.1598864 | AJ6: =100*(('ONS CVM_SA_(Quarterly)'!D94-'ONS CVM_SA_(Quarterly)'!D$96)/'ONS CVM_SA_(Quarterly)'!$B$96) -> 0.91460464 | AK6: =100*(('ONS CVM_SA_(Quarterly)'!E94-'ONS CVM_SA_(Quarterly)'!E$96)/'ONS CVM_SA_(Quarterly)'!$B$96) -> 0.18872794 | AL6: =100*(('ONS CVM_SA_(Quarterly)'!F94-'ONS CVM_SA_(Quarterly)'!F$96)/'ONS CVM_SA_(Quarterly)'!$B$96) -> -1.0839759 | AM6: =100*(('ONS CVM_SA_(Quarterly)'!B94-'ONS CVM_SA_(Quarterly)'!B$96)/'ONS CVM_SA_(Quarterly)'!$B$96) -> 0.30164209 | AP6: =100*(('ONS CVM_SA_(Quarterly)'!C82-AVERAGE('ONS CVM_SA_(Quarterly)'!C$81:C$84))/AVERAGE('ONS CVM_SA_(Quarterly)'!$B$81:$B$84)) -> 0.34278352 | AQ6: =100*(('ONS CVM_SA_(Quarterly)'!D82-AVERAGE('ONS CVM_SA_(Quarterly)'!D$81:D$84))/AVERAGE('ONS CVM_SA_(Quarterly)'!$B$81:$B$84)) -> 0.1487016 | AR6: =100*(('ONS CVM_SA_(Quarterly)'!E82-AVERAGE('ONS CVM_SA_(Quarterly)'!E$81:E$84))/AVERAGE('ONS CVM_SA_(Quarterly)'!$B$81:$B$84)) -> 0.44205297 | AS6: =100*(('ONS CVM_SA_(Quarterly)'!F82-AVERAGE('ONS CVM_SA_(Quarterly)'!F$81:F$84))/AVERAGE('ONS CVM_SA_(Quarterly)'!$B$81:$B$84)) -> -0.062397945 | AT6: =100*(('ONS CVM_SA_(Quarterly)'!B82-AVERAGE('ONS CVM_SA_(Quarterly)'!B$81:B$84))/AVERAGE('ONS CVM_SA_(Quarterly)'!$B$81:$B$84)) -> -0.32698144 | AV6: 43497 | AW6: =HAVERM!D237 -> 0.75 | AX6: =HAVERM!B237 -> 3.34 | AY6: =HAVERM!C237 -> 2.46 | BA6: 44562 | BB6: =AX41-AX$39 -> 0.11 | BC6: =AY41-AY$39 -> -0.01 | BD6: 1000 | BF6: 0 | BJ6: =100*(HAVERQ!B122/HAVERQ!B$128) -> 96.872278 | BK6: =100*(HAVERQ!I122/HAVERQ!I$128) -> 102.28149 | BL6: =100*(HAVERQ!J122/HAVERQ!J$128) -> 91.231537 | BM6: =100*(HAVERQ!K122/HAVERQ!K$128) -> 63.234385 | BN6: =100*((HAVERQ!L122+HAVERQ!M122)/(HAVERQ!L$128+HAVERQ!M$128)) -> 94.908623 | BO6: 100 | BR6: =HAVERQ!I122-HAVERQ!I$128 -> 213 | BS6: =HAVERQ!J122-HAVERQ!J$128 -> -843 | BT6: =HAVERQ!K122-HAVERQ!K$128 -> -1189 | BU6: =(HAVERQ!L122+HAVERQ!M122)-(HAVERQ!L$128+HAVERQ!M$128) -> -2017 | BV6: =HAVERQ!N122-HAVERQ!N$128 -> -100 | BW6: =HAVERQ!B122-HAVERQ!B$128 -> -1939 | BZ6: =100*((HAVERQ!I126-HAVERQ!I$128)/HAVERQ!$B$128) -> 0.59683195 | CA6: =100*((HAVERQ!J126-HAVERQ!J$128)/HAVERQ!$B$128) -> -2.6196083 | CB6: =100*((HAVERQ!K126-HAVERQ!K$128)/HAVERQ!$B$128) -> -0.10484886 | CC6: =100*(((HAVERQ!L126+HAVERQ!M126)-(HAVERQ!L$128+HAVERQ!M$128))/HAVERQ!$B$128) -> -0.2855115 | CD6: =CE6-BZ6-CA6-CB6-CC6 -> 2.7147788 | CE6: =100*((HAVERQ!B126-HAVERQ!B$128)/HAVERQ!B$128) -> 0.30164209 | CH6: =HAVERQ!I122 -> 9549 | CI6: =HAVERQ!J122 -> 8771 | CJ6: =HAVERQ!K122 -> 2045 | CK6: =HAVERQ!L122+HAVERQ!M122 -> 37599 | CL6: =HAVERQ!N122 -> 1258 | CO6: =CX6 -> -89 | CP6: =CY6 -> 45 | CQ6: =CZ6 -> 75 | CR6: =DA6 -> -1635 | CS6: =DC6 -> 1220 | CT6: =+DB6+DD6+DE6+DF6 -> -558 | CU6: =DG6 -> -2017 | CX6: =HAVERQ!L122-HAVERQ!L$128 -> -89 | CY6: =HAVERQ!O122-HAVERQ!O$128 -> 45 | CZ6: =HAVERQ!P122-HAVERQ!P$128 -> 75 | DA6: =HAVERQ!Q122-HAVERQ!Q$128 -> -1635 | DB6: =HAVERQ!R122-HAVERQ!R$128 -> -202 | DC6: =HAVERQ!S122-HAVERQ!S$128 -> 1220 | DD6: =HAVERQ!T122-HAVERQ!T$128 -> 95 | DE6: =HAVERQ!U122-HAVERQ!U$128 -> -110 | DF6: =HAVERQ!V122-HAVERQ!V$128 -> -341 | DG6: =(HAVERQ!L122+HAVERQ!M122)-(HAVERQ!L$128+HAVERQ!M$128) -> -2017 | DJ6: =100*(HAVERQ!C122/HAVERQ!C$128) -> 98.307882 | DK6: =100*(HAVERQ!D122/HAVERQ!D$128) -> 72.868561 | DL6: =100*(HAVERQ!E122/HAVERQ!E$128) -> 104.36118 | DM6: =100*(HAVERQ!F122/HAVERQ!F$128) -> 100.79688 | DN6: =100*(HAVERQ!G122/HAVERQ!G$128) -> 98.594589 | DO6: =100*(HAVERQ!H122/HAVERQ!H$128) -> 97.010633 | DP6: 100 | DS6: =HAVERQ!D122-HAVERQ!D$128 -> -1222 | DT6: =HAVERQ!E122-HAVERQ!E$128 -> 724 | DU6: =HAVERQ!F122-HAVERQ!F$128 -> 202 | DV6: =HAVERQ!G122-HAVERQ!G$128 -> -521 | DW6: =HAVERQ!H122-HAVERQ!H$128 -> -790 | DX6: =HAVERQ!C122-HAVERQ!C$128 -> -1856 | EA6: =MIN(EM6:EO6) -> 0.67591527 | EB6: =+EF6-EA6 -> 0.61095198 | EC6: =100*((EJ10/EJ6)-1) -> 12.08986 | ED6: 0 | EF6: =MAX(EM6:EO6) -> 1.2868673 | EG6: =AVERAGE(EM6:EO6) -> 0.98404781 | EJ6: ='IPNR ex BNFL'!I14 -> 41175 | EM6: =(ER6-ER$2)/ER$3 -> 1.2868673 | EN6: =(ES6-ES$2)/ES$3 -> 0.98936091 | EO6: =(ET6-ET$2)/ET$3 -> 0.67591527 | ER6: =(HAVERQ!W48*$EW$2)+(HAVERQ!X48*$EX$2)/($EW$2+$EX$2) -> 23.286938 | ES6: =(HAVERQ!AB48*$EW$2)+(HAVERQ!AC48*$EY$2)+(HAVERQ!AD48*$EZ$2)+(HAVERQ!AE48*$FA$2)/($EW$2+$EY$2+$EZ$2+$FA$2) -> 7.6862819 | ET6: =(HAVERQ!Y48*$EW$2)+(HAVERQ!Z48*$EX$2)/($EW$2+$EX$2) -> 1.8841606 | FC6: 43497 | FD6: =100*((HAVERM!E237+HAVERM!F237)/(HAVERM!E$249+HAVERM!F$249)) -> 99.010632 | FE6: =100*(HAVERM!E237/HAVERM!E$249) -> 98.8816 | FF6: =100*(HAVERM!F237/HAVERM!F$249) -> 99.081432 | FG6: 100 | FI6: Loans (exc overdrafts) | FJ6: =100*((HAVERM!AR301/HAVERM!AR$247)-1) -> -10.687935 | FK6: =100*((HAVERM!AS301/HAVERM!AS$247)-1) -> 74.410266 | FL6: =100*((HAVERM!AT301/HAVERM!AT$247)-1) -> 5.3551277 | FM6: =100*((HAVERM!AU301/HAVERM!AU$247)-1) -> -1.0601875 | FN6: =100*((HAVERM!AV301/HAVERM!AV$247)-1) -> 0.13226484 | FO6: =100*((HAVERM!AW301/HAVERM!AW$247)-1) -> 32.185076 | FP6: =100*((HAVERM!AX301/HAVERM!AX$247)-1) -> 17.050048 | FQ6: =100*((HAVERM!AY301/HAVERM!AY$247)-1) -> -22.896942 | ... FT6: =100*((HAVERM!BB301/HAVERM!BB$247)-1) -> 9.889607 | FV6: 42370 | FW6: =HAVERM!G200 -> 347433 | FY6: =FW6-FW5 -> 4080 | GD6: =100*(DataQ!W156/DataQ!W$194) -> 72.325013 | GE6: =100*(DataQ!X156/DataQ!X$194) -> 69.9162 | GF6: =100*(DataQ!C156/DataQ!C$194) -> 65.906378 | GH6: 100 | GK6: =100*(DataQ!Z136/AVERAGE(DataQ!$Z$203:$Z$206)) -> 69.771414 | GL6: =100*(DataQ!C136/AVERAGE(DataQ!$C$203:$C$206)) -> 72.212057 | GM6: 100 | GP6: =100*(DataQ!Z136/DataQ!$Z$194) -> 69.51111 | GQ6: =100*(DataQ!C136/DataQ!$C$194) -> 69.705939 | GR6: 100 | GU6: =HB6 -> 96.872278 | GV6: =MIN(HC6:HH6) -> 94.856789 | GW6: =+GY6-GV6 -> 12.0845 | GX6: 100 | GY6: =MAX(HC6:HH6) -> 106.94129 | HB6: =100*(DataQ!C188/DataQ!C$194) -> 96.872278 | HC6: =100*(DataQ!Q188/DataQ!Q$194) -> 95.515604 | HD6: =100*(DataQ!R188/DataQ!R$194) -> 106.94129 | HE6: =100*(DataQ!S188/DataQ!S$194) -> 97.989399 | HF6: =100*(DataQ!T188/DataQ!T$194) -> 94.856789 | HG6: =100*(DataQ!U188/DataQ!U$194) -> 100.81953 | HH6: =100*(DataQ!V188/DataQ!V$194) -> 98.996503 | HK6: =HR6 -> 96.872278 | HL6: =MIN(HS6:HX6) -> 94.856789 | HM6: =+HO6-HL6 -> 12.0845 | HN6: 100 | HO6: =MAX(HS6:HX6) -> 106.94129 | HR6: =100*(DataQ!C188/DataQ!C$194) -> 96.872278 | HS6: =100*(DataQ!Q188/DataQ!Q$194) -> 95.515604 | HT6: =100*(DataQ!R188/DataQ!R$194) -> 106.94129 | HU6: =100*(DataQ!S188/DataQ!S$194) -> 97.989399 | HV6: =100*(DataQ!T188/DataQ!T$194) -> 94.856789 | HW6: =100*(DataQ!U188/DataQ!U$194) -> 100.81953 | HX6: =100*(DataQ!V188/DataQ!V$194) -> 98.996503 | HZ6: 1991 | IA6: =DataA!J25/'Chart Data'!IF6 -> 1.8782797 | IB6: =IB5*(1+$ID$5/100) -> 1.7959338 | IC6: =100*((IA6/IB6)-1) -> 4.5851298 | IF6: =DataA!K25*DataA!L25 -> 868391.46 | IH6: Business & professional services | II6: =(HAVERQ!AQ147-HAVERQ!AQ1)/HAVERQ!AQ2 -> 0.4099103 | IJ6: =(HAVERQ!AR147-HAVERQ!AR1)/HAVERQ!AR2 -> 0.74386752 | IK6: =(HAVERQ!AS147-HAVERQ!AS1)/HAVERQ!AS2 -> -0.048963609 | IL6: =(HAVERQ!AT147-HAVERQ!AT1)/HAVERQ!AT2 -> 2.0208248 | IM6: =(HAVERQ!AU147-HAVERQ!AU1)/HAVERQ!AU2 -> -1.5628406 | IN6: =(HAVERQ!AV147-HAVERQ!AV1)/HAVERQ!AV2 -> 0.48966085 | IO6: =(HAVERQ!AW147-HAVERQ!AW1)/HAVERQ!AW2 -> 2.6192848 | IR6: =HAVERQ!AH77 -> #N/A | IS6: =100*(('IPNR ex BNFL'!I46/'IPNR ex BNFL'!I42)-1) -> 14.678179 | IT6: 0
B7: =100*((DataQ!C77/DataQ!C73)-1) -> -2.5390103 | C7: =K7 -> 20.106924 | D7: 0 | I7: 0 | K7: =L7 -> 20.106924 | L7: =100*(HAVERQ!AF11/HAVERQ!AI11) -> 20.106924 | O7: =100*('ONS CVM_SA_(Quarterly)'!B91/'ONS CVM_SA_(Quarterly)'!B$101) -> 111.67979 | P7: =100*('ONS CVM_SA_(Quarterly)'!D91/'ONS CVM_SA_(Quarterly)'!D$101) -> 112.56335 | R7: 100 | U7: ='ONS CVM_SA_(Quarterly)'!C103-'ONS CVM_SA_(Quarterly)'!C$101 -> 762 | V7: ='ONS CVM_SA_(Quarterly)'!D103-'ONS CVM_SA_(Quarterly)'!D$101 -> 640 | W7: ='ONS CVM_SA_(Quarterly)'!E103-'ONS CVM_SA_(Quarterly)'!E$101 -> 1149 | X7: ='ONS CVM_SA_(Quarterly)'!F103-'ONS CVM_SA_(Quarterly)'!F$101 -> 553 | Y7: ='ONS CVM_SA_(Quarterly)'!B103-'ONS CVM_SA_(Quarterly)'!B$101 -> 3170 | AB7: =100*(U7/'ONS CVM_SA_(Quarterly)'!$B$101) -> 1.4156201 | AC7: =100*(V7/'ONS CVM_SA_(Quarterly)'!$B$101) -> 1.1889723 | AD7: =100*(W7/'ONS CVM_SA_(Quarterly)'!$B$101) -> 2.1345768 | AE7: =100*(X7/'ONS CVM_SA_(Quarterly)'!$B$101) -> 1.0273464 | AF7: =100*(('ONS CVM_SA_(Quarterly)'!B103/'ONS CVM_SA_(Quarterly)'!B$101)-1) -> 5.8891283 | AI7: =100*(('ONS CVM_SA_(Quarterly)'!C95-'ONS CVM_SA_(Quarterly)'!C$96)/'ONS CVM_SA_(Quarterly)'!$B$96) -> 1.2049553 | AJ7: =100*(('ONS CVM_SA_(Quarterly)'!D95-'ONS CVM_SA_(Quarterly)'!D$96)/'ONS CVM_SA_(Quarterly)'!$B$96) -> 0.037100365 | AK7: =100*(('ONS CVM_SA_(Quarterly)'!E95-'ONS CVM_SA_(Quarterly)'!E$96)/'ONS CVM_SA_(Quarterly)'!$B$96) -> -0.81782108 | AL7: =100*(('ONS CVM_SA_(Quarterly)'!F95-'ONS CVM_SA_(Quarterly)'!F$96)/'ONS CVM_SA_(Quarterly)'!$B$96) -> -0.36132529 | AM7: =100*(('ONS CVM_SA_(Quarterly)'!B95-'ONS CVM_SA_(Quarterly)'!B$96)/'ONS CVM_SA_(Quarterly)'!$B$96) -> -0.10000968 | AP7: =100*(('ONS CVM_SA_(Quarterly)'!C83-AVERAGE('ONS CVM_SA_(Quarterly)'!C$81:C$84))/AVERAGE('ONS CVM_SA_(Quarterly)'!$B$81:$B$84)) -> 1.3249434 | AQ7: =100*(('ONS CVM_SA_(Quarterly)'!D83-AVERAGE('ONS CVM_SA_(Quarterly)'!D$81:D$84))/AVERAGE('ONS CVM_SA_(Quarterly)'!$B$81:$B$84)) -> 0.28646329 | AR7: =100*(('ONS CVM_SA_(Quarterly)'!E83-AVERAGE('ONS CVM_SA_(Quarterly)'!E$81:E$84))/AVERAGE('ONS CVM_SA_(Quarterly)'!$B$81:$B$84)) -> 0.25404878 | AS7: =100*(('ONS CVM_SA_(Quarterly)'!F83-AVERAGE('ONS CVM_SA_(Quarterly)'!F$81:F$84))/AVERAGE('ONS CVM_SA_(Quarterly)'!$B$81:$B$84)) -> 0.1726073 | AT7: =100*(('ONS CVM_SA_(Quarterly)'!B83-AVERAGE('ONS CVM_SA_(Quarterly)'!B$81:B$84))/AVERAGE('ONS CVM_SA_(Quarterly)'!$B$81:$B$84)) -> 2.0652099 | AV7: 43525 | AW7: =HAVERM!D238 -> 0.75 | AX7: =HAVERM!B238 -> 3.34 | AY7: =HAVERM!C238 -> 2.45 | BA7: 44593 | BB7: =AX42-AX$39 -> 0.25 | BC7: =AY42-AY$39 -> 0 | BD7: 1000 | BF7: 0 | BJ7: =100*(HAVERQ!B123/HAVERQ!B$128) -> 96.969062 | BK7: =100*(HAVERQ!I123/HAVERQ!I$128) -> 105.40917 | BL7: =100*(HAVERQ!J123/HAVERQ!J$128) -> 85.105055 | BM7: =100*(HAVERQ!K123/HAVERQ!K$128) -> 70.34632 | BN7: =100*((HAVERQ!L123+HAVERQ!M123)/(HAVERQ!L$128+HAVERQ!M$128)) -> 104.3644 | BO7: 100 | BR7: =HAVERQ!I123-HAVERQ!I$128 -> 505 | BS7: =HAVERQ!J123-HAVERQ!J$128 -> -1432 | BT7: =HAVERQ!K123-HAVERQ!K$128 -> -959 | BU7: =(HAVERQ!L123+HAVERQ!M123)-(HAVERQ!L$128+HAVERQ!M$128) -> 1729 | BV7: =HAVERQ!N123-HAVERQ!N$128 -> -111 | BW7: =HAVERQ!B123-HAVERQ!B$128 -> -1879 | BZ7: =100*((HAVERQ!I127-HAVERQ!I$128)/HAVERQ!$B$128) -> 0.23550666 | CA7: =100*((HAVERQ!J127-HAVERQ!J$128)/HAVERQ!$B$128) -> -2.7373617 | CB7: =100*((HAVERQ!K127-HAVERQ!K$128)/HAVERQ!$B$128) -> -0.31615963 | CC7: =100*(((HAVERQ!L127+HAVERQ!M127)-(HAVERQ!L$128+HAVERQ!M$128))/HAVERQ!$B$128) -> 0.67587186 | CD7: =CE7-BZ7-CA7-CB7-CC7 -> 2.0421331 | CE7: =100*((HAVERQ!B127-HAVERQ!B$128)/HAVERQ!B$128) -> -0.10000968 | CH7: =HAVERQ!I123 -> 9841 | CI7: =HAVERQ!J123 -> 8182 | CJ7: =HAVERQ!K123 -> 2275 | CK7: =HAVERQ!L123+HAVERQ!M123 -> 41345 | CL7: =HAVERQ!N123 -> 1247 | CO7: =CX7 -> -139 | CP7: =CY7 -> 73 | CQ7: =CZ7 -> -309 | CR7: =DA7 -> 800 | CS7: =DC7 -> 519 | CT7: =+DB7+DD7+DE7+DF7 -> 9 | CU7: =DG7 -> 1729 | CX7: =HAVERQ!L123-HAVERQ!L$128 -> -139 | CY7: =HAVERQ!O123-HAVERQ!O$128 -> 73 | CZ7: =HAVERQ!P123-HAVERQ!P$128 -> -309 | DA7: =HAVERQ!Q123-HAVERQ!Q$128 -> 800 | DB7: =HAVERQ!R123-HAVERQ!R$128 -> 122 | DC7: =HAVERQ!S123-HAVERQ!S$128 -> 519 | DD7: =HAVERQ!T123-HAVERQ!T$128 -> 26 | DE7: =HAVERQ!U123-HAVERQ!U$128 -> -40 | DF7: =HAVERQ!V123-HAVERQ!V$128 -> -99 | DG7: =(HAVERQ!L123+HAVERQ!M123)-(HAVERQ!L$128+HAVERQ!M$128) -> 1729 | DJ7: =100*(HAVERQ!C123/HAVERQ!C$128) -> 98.287824 | DK7: =100*(HAVERQ!D123/HAVERQ!D$128) -> 125.97691 | DL7: =100*(HAVERQ!E123/HAVERQ!E$128) -> 99.873502 | DM7: =100*(HAVERQ!F123/HAVERQ!F$128) -> 98.982208 | DN7: =100*(HAVERQ!G123/HAVERQ!G$128) -> 98.397669 | DO7: =100*(HAVERQ!H123/HAVERQ!H$128) -> 90.509706 | DP7: 100 | DS7: =HAVERQ!D123-HAVERQ!D$128 -> 1170 | DT7: =HAVERQ!E123-HAVERQ!E$128 -> -21 | DU7: =HAVERQ!F123-HAVERQ!F$128 -> -258 | DV7: =HAVERQ!G123-HAVERQ!G$128 -> -594 | DW7: =HAVERQ!H123-HAVERQ!H$128 -> -2508 | DX7: =HAVERQ!C123-HAVERQ!C$128 -> -1878 | EA7: =MIN(EM7:EO7) -> -0.1043378 | EB7: =+EF7-EA7 -> 0.94152221 | EC7: =100*((EJ11/EJ7)-1) -> 1.6332696 | ED7: 0 | EF7: =MAX(EM7:EO7) -> 0.83718441 | EG7: =AVERAGE(EM7:EO7) -> 0.48302103 | EJ7: ='IPNR ex BNFL'!I15 -> 42369 | EL7: 2000 | EM7: =(ER7-ER$2)/ER$3 -> 0.71621648 | EN7: =(ES7-ES$2)/ES$3 -> -0.1043378 | EO7: =(ET7-ET$2)/ET$3 -> 0.83718441 | EQ7: 2000 | ER7: =(HAVERQ!W49*$EW$2)+(HAVERQ!X49*$EX$2)/($EW$2+$EX$2) -> 16.598404 | ES7: =(HAVERQ!AB49*$EW$2)+(HAVERQ!AC49*$EY$2)+(HAVERQ!AD49*$EZ$2)+(HAVERQ!AE49*$FA$2)/($EW$2+$EY$2+$EZ$2+$FA$2) -> -7.704033 | ET7: =(HAVERQ!Y49*$EW$2)+(HAVERQ!Z49*$EX$2)/($EW$2+$EX$2) -> 2.1374408 | FC7: 43525 | FD7: =100*((HAVERM!E238+HAVERM!F238)/(HAVERM!E$249+HAVERM!F$249)) -> 98.884853 | FE7: =100*(HAVERM!E238/HAVERM!E$249) -> 99.062319 | FF7: =100*(HAVERM!F238/HAVERM!F$249) -> 98.787477 | FG7: 100 | FV7: 42401 | FW7: =HAVERM!G201 -> 347792 | FY7: =FW7-FW6 -> 359 | GD7: =100*(DataQ!W157/DataQ!W$194) -> 74.929721 | GE7: =100*(DataQ!X157/DataQ!X$194) -> 72.560105 | GF7: =100*(DataQ!C157/DataQ!C$194) -> 68.872794 | GH7: 100 | GK7: =100*(DataQ!Z137/AVERAGE(DataQ!$Z$203:$Z$206)) -> 71.61797 | GL7: =100*(DataQ!C137/AVERAGE(DataQ!$C$203:$C$206)) -> 74.14463 | GM7: 100 | GP7: =100*(DataQ!Z137/DataQ!$Z$194) -> 71.350776 | GQ7: =100*(DataQ!C137/DataQ!$C$194) -> 71.571442 | GR7: 100 | GU7: =HB7 -> 96.969062 | GV7: =MIN(HC7:HH7) -> 95.909498 | GW7: =+GY7-GV7 -> 7.9581683 | GX7: 100 | GY7: =MAX(HC7:HH7) -> 103.86767 | HB7: =100*(DataQ!C189/DataQ!C$194) -> 96.969062 | HC7: =100*(DataQ!Q189/DataQ!Q$194) -> 96.104771 | HD7: =100*(DataQ!R189/DataQ!R$194) -> 103.86767 | HE7: =100*(DataQ!S189/DataQ!S$194) -> 98.711387 | HF7: =100*(DataQ!T189/DataQ!T$194) -> 95.909498 | HG7: =100*(DataQ!U189/DataQ!U$194) -> 99.390287 | HH7: =100*(DataQ!V189/DataQ!V$194) -> 96.997835 | HK7: =HR7 -> 96.969062 | HL7: =MIN(HS7:HX7) -> 95.909498 | HM7: =+HO7-HL7 -> 7.9581683 | HN7: 100 | HO7: =MAX(HS7:HX7) -> 103.86767 | HR7: =100*(DataQ!C189/DataQ!C$194) -> 96.969062 | HS7: =100*(DataQ!Q189/DataQ!Q$194) -> 96.104771 | HT7: =100*(DataQ!R189/DataQ!R$194) -> 103.86767 | HU7: =100*(DataQ!S189/DataQ!S$194) -> 98.711387 | HV7: =100*(DataQ!T189/DataQ!T$194) -> 95.909498 | HW7: =100*(DataQ!U189/DataQ!U$194) -> 99.390287 | HX7: =100*(DataQ!V189/DataQ!V$194) -> 96.997835 | HZ7: 1992 | IA7: =DataA!J26/'Chart Data'!IF7 -> 1.967248 | IB7: =IB6*(1+$ID$5/100) -> 1.843644 | IC7: =100*((IA7/IB7)-1) -> 6.7043282 | IF7: =DataA!K26*DataA!L26 -> 844768.45 | IH7: Consumer services | II7: =(HAVERQ!AX147-HAVERQ!AX1)/HAVERQ!AX2 -> 0.27759281 | IJ7: =(HAVERQ!AY147-HAVERQ!AY1)/HAVERQ!AY2 -> 1.8605197 | IK7: =(HAVERQ!AZ147-HAVERQ!AZ1)/HAVERQ!AZ2 -> 0.81079388 | IL7: =(HAVERQ!BA147-HAVERQ!BA1)/HAVERQ!BA2 -> 2.5848416 | IM7: =(HAVERQ!BB147-HAVERQ!BB1)/HAVERQ!BB2 -> -0.15880748 | IN7: =(HAVERQ!BC147-HAVERQ!BC1)/HAVERQ!BC2 -> 0.98110399 | IO7: =(HAVERQ!BD147-HAVERQ!BD1)/HAVERQ!BD2 -> 0.16358536 | IR7: =HAVERQ!AH78 -> -4.2 | IS7: =100*(('IPNR ex BNFL'!I47/'IPNR ex BNFL'!I43)-1) -> 1.7949732 | IT7: 0
B8: =100*((DataQ!C78/DataQ!C74)-1) -> -1.2784077 | C8: =K8 -> 18.468171 | D8: 0 | I8: 0 | K8: =L8 -> 18.468171 | L8: =100*(HAVERQ!AF12/HAVERQ!AI12) -> 18.468171 | O8: =100*('ONS CVM_SA_(Quarterly)'!B92/'ONS CVM_SA_(Quarterly)'!B$101) -> 112.46192 | P8: =100*('ONS CVM_SA_(Quarterly)'!D92/'ONS CVM_SA_(Quarterly)'!D$101) -> 107.88785 | R8: 100 | U8: ='ONS CVM_SA_(Quarterly)'!C104-'ONS CVM_SA_(Quarterly)'!C$101 -> 1538 | V8: ='ONS CVM_SA_(Quarterly)'!D104-'ONS CVM_SA_(Quarterly)'!D$101 -> 93 | W8: ='ONS CVM_SA_(Quarterly)'!E104-'ONS CVM_SA_(Quarterly)'!E$101 -> 927 | X8: ='ONS CVM_SA_(Quarterly)'!F104-'ONS CVM_SA_(Quarterly)'!F$101 -> 630 | Y8: ='ONS CVM_SA_(Quarterly)'!B104-'ONS CVM_SA_(Quarterly)'!B$101 -> 3350 | AB8: =100*(U8/'ONS CVM_SA_(Quarterly)'!$B$101) -> 2.857249 | AC8: =100*(V8/'ONS CVM_SA_(Quarterly)'!$B$101) -> 0.17277253 | AD8: =100*(W8/'ONS CVM_SA_(Quarterly)'!$B$101) -> 1.722152 | AE8: =100*(X8/'ONS CVM_SA_(Quarterly)'!$B$101) -> 1.1703946 | AF8: =100*(('ONS CVM_SA_(Quarterly)'!B104/'ONS CVM_SA_(Quarterly)'!B$101)-1) -> 6.2235268 | AI8: =100*(('ONS CVM_SA_(Quarterly)'!C96-'ONS CVM_SA_(Quarterly)'!C$96)/'ONS CVM_SA_(Quarterly)'!$B$96) -> 0 | AJ8: =100*(('ONS CVM_SA_(Quarterly)'!D96-'ONS CVM_SA_(Quarterly)'!D$96)/'ONS CVM_SA_(Quarterly)'!$B$96) -> 0 | AK8: =100*(('ONS CVM_SA_(Quarterly)'!E96-'ONS CVM_SA_(Quarterly)'!E$96)/'ONS CVM_SA_(Quarterly)'!$B$96) -> 0 | AL8: =100*(('ONS CVM_SA_(Quarterly)'!F96-'ONS CVM_SA_(Quarterly)'!F$96)/'ONS CVM_SA_(Quarterly)'!$B$96) -> 0 | AM8: =100*(('ONS CVM_SA_(Quarterly)'!B96-'ONS CVM_SA_(Quarterly)'!B$96)/'ONS CVM_SA_(Quarterly)'!$B$96) -> 0 | AP8: =100*(('ONS CVM_SA_(Quarterly)'!C84-AVERAGE('ONS CVM_SA_(Quarterly)'!C$81:C$84))/AVERAGE('ONS CVM_SA_(Quarterly)'!$B$81:$B$84)) -> -2.9553936 | AQ8: =100*(('ONS CVM_SA_(Quarterly)'!D84-AVERAGE('ONS CVM_SA_(Quarterly)'!D$81:D$84))/AVERAGE('ONS CVM_SA_(Quarterly)'!$B$81:$B$84)) -> -0.59683229 | AR8: =100*(('ONS CVM_SA_(Quarterly)'!E84-AVERAGE('ONS CVM_SA_(Quarterly)'!E$81:E$84))/AVERAGE('ONS CVM_SA_(Quarterly)'!$B$81:$B$84)) -> -0.3715514 | AS8: =100*(('ONS CVM_SA_(Quarterly)'!F84-AVERAGE('ONS CVM_SA_(Quarterly)'!F$81:F$84))/AVERAGE('ONS CVM_SA_(Quarterly)'!$B$81:$B$84)) -> 0.22122908 | AT8: =100*(('ONS CVM_SA_(Quarterly)'!B84-AVERAGE('ONS CVM_SA_(Quarterly)'!B$81:B$84))/AVERAGE('ONS CVM_SA_(Quarterly)'!$B$81:$B$84)) -> -1.7110813 | AV8: 43556 | AW8: =HAVERM!D239 -> 0.75 | AX8: =HAVERM!B239 -> 3.34 | AY8: =HAVERM!C239 -> 2.45 | BA8: 44621 | BB8: =AX43-AX$39 -> 0.35 | BC8: =AY43-AY$39 -> 0.03 | BD8: 1000 | BF8: 0 | BJ8: =100*(HAVERQ!B124/HAVERQ!B$128) -> 97.648159 | BK8: =100*(HAVERQ!I124/HAVERQ!I$128) -> 105.09854 | BL8: =100*(HAVERQ!J124/HAVERQ!J$128) -> 90.815477 | BM8: =100*(HAVERQ!K124/HAVERQ!K$128) -> 75.819419 | BN8: =100*((HAVERQ!L124+HAVERQ!M124)/(HAVERQ!L$128+HAVERQ!M$128)) -> 102.98364 | BO8: 100 | BR8: =HAVERQ!I124-HAVERQ!I$128 -> 476 | BS8: =HAVERQ!J124-HAVERQ!J$128 -> -883 | BT8: =HAVERQ!K124-HAVERQ!K$128 -> -782 | BU8: =(HAVERQ!L124+HAVERQ!M124)-(HAVERQ!L$128+HAVERQ!M$128) -> 1182 | BV8: =HAVERQ!N124-HAVERQ!N$128 -> -123 | BW8: =HAVERQ!B124-HAVERQ!B$128 -> -1458 | BZ8: =100*((HAVERQ!I128-HAVERQ!I$128)/HAVERQ!$B$128) -> 0 | CA8: =100*((HAVERQ!J128-HAVERQ!J$128)/HAVERQ!$B$128) -> 0 | CB8: =100*((HAVERQ!K128-HAVERQ!K$128)/HAVERQ!$B$128) -> 0 | CC8: =100*(((HAVERQ!L128+HAVERQ!M128)-(HAVERQ!L$128+HAVERQ!M$128))/HAVERQ!$B$128) -> 0 | CD8: =CE8-BZ8-CA8-CB8-CC8 -> 0 | CE8: =100*((HAVERQ!B128-HAVERQ!B$128)/HAVERQ!B$128) -> 0 | CH8: =HAVERQ!I124 -> 9812 | CI8: =HAVERQ!J124 -> 8731 | CJ8: =HAVERQ!K124 -> 2452 | CK8: =HAVERQ!L124+HAVERQ!M124 -> 40798 | CL8: =HAVERQ!N124 -> 1235 | CO8: =CX8 -> -626 | CP8: =CY8 -> 265 | CQ8: =CZ8 -> 67 | CR8: =DA8 -> 2021 | CS8: =DC8 -> 311 | CT8: =+DB8+DD8+DE8+DF8 -> -43 | CU8: =DG8 -> 1182 | CX8: =HAVERQ!L124-HAVERQ!L$128 -> -626 | CY8: =HAVERQ!O124-HAVERQ!O$128 -> 265 | CZ8: =HAVERQ!P124-HAVERQ!P$128 -> 67 | DA8: =HAVERQ!Q124-HAVERQ!Q$128 -> 2021 | DB8: =HAVERQ!R124-HAVERQ!R$128 -> 178 | DC8: =HAVERQ!S124-HAVERQ!S$128 -> 311 | DD8: =HAVERQ!T124-HAVERQ!T$128 -> 112 | DE8: =HAVERQ!U124-HAVERQ!U$128 -> 27 | DF8: =HAVERQ!V124-HAVERQ!V$128 -> -360 | DG8: =(HAVERQ!L124+HAVERQ!M124)-(HAVERQ!L$128+HAVERQ!M$128) -> 1182 | DJ8: =100*(HAVERQ!C124/HAVERQ!C$128) -> 98.155627 | DK8: =100*(HAVERQ!D124/HAVERQ!D$128) -> 130.17318 | DL8: =100*(HAVERQ!E124/HAVERQ!E$128) -> 97.078489 | DM8: =100*(HAVERQ!F124/HAVERQ!F$128) -> 98.982208 | DN8: =100*(HAVERQ!G124/HAVERQ!G$128) -> 98.888619 | DO8: =100*(HAVERQ!H124/HAVERQ!H$128) -> 90.237257 | DP8: 100 | DS8: =HAVERQ!D124-HAVERQ!D$128 -> 1359 | DT8: =HAVERQ!E124-HAVERQ!E$128 -> -485 | DU8: =HAVERQ!F124-HAVERQ!F$128 -> -258 | DV8: =HAVERQ!G124-HAVERQ!G$128 -> -412 | DW8: =HAVERQ!H124-HAVERQ!H$128 -> -2580 | DX8: =HAVERQ!C124-HAVERQ!C$128 -> -2023 | EA8: =MIN(EM8:EO8) -> 0.11963873 | EB8: =+EF8-EA8 -> 0.86228838 | EC8: =100*((EJ12/EJ8)-1) -> 6.3559423 | ED8: 0 | EF8: =MAX(EM8:EO8) -> 0.98192711 | EG8: =AVERAGE(EM8:EO8) -> 0.6912452 | EJ8: ='IPNR ex BNFL'!I16 -> 41945 | EM8: =(ER8-ER$2)/ER$3 -> 0.97216977 | EN8: =(ES8-ES$2)/ES$3 -> 0.11963873 | EO8: =(ET8-ET$2)/ET$3 -> 0.98192711 | ER8: =(HAVERQ!W50*$EW$2)+(HAVERQ!X50*$EX$2)/($EW$2+$EX$2) -> 19.598404 | ES8: =(HAVERQ!AB50*$EW$2)+(HAVERQ!AC50*$EY$2)+(HAVERQ!AD50*$EZ$2)+(HAVERQ!AE50*$FA$2)/($EW$2+$EY$2+$EZ$2+$FA$2) -> -4.5522789 | ET8: =(HAVERQ!Y50*$EW$2)+(HAVERQ!Z50*$EX$2)/($EW$2+$EX$2) -> 2.3647654 | FC8: 43556 | FD8: =100*((HAVERM!E239+HAVERM!F239)/(HAVERM!E$249+HAVERM!F$249)) -> 98.09304 | FE8: =100*(HAVERM!E239/HAVERM!E$249) -> 98.668082 | FF8: =100*(HAVERM!F239/HAVERM!F$249) -> 97.777511 | FG8: 100 | FV8: 42430 | FW8: =HAVERM!G202 -> 349767 | FY8: =FW8-FW7 -> 1975 | GD8: =100*(DataQ!W158/DataQ!W$194) -> 79.266198 | GE8: =100*(DataQ!X158/DataQ!X$194) -> 77.549676 | GF8: =100*(DataQ!C158/DataQ!C$194) -> 73.418395 | GH8: 100 | GK8: =100*(DataQ!Z138/AVERAGE(DataQ!$Z$203:$Z$206)) -> 71.236045 | GL8: =100*(DataQ!C138/AVERAGE(DataQ!$C$203:$C$206)) -> 73.773656 | GM8: 100 | GP8: =100*(DataQ!Z138/DataQ!$Z$194) -> 70.970276 | GQ8: =100*(DataQ!C138/DataQ!$C$194) -> 71.213343 | GR8: 100 | GU8: =HB8 -> 97.648159 | GV8: =MIN(HC8:HH8) -> 96.743943 | GW8: =+GY8-GV8 -> 9.3122804 | GX8: 100 | GY8: =MAX(HC8:HH8) -> 106.05622 | HB8: =100*(DataQ!C190/DataQ!C$194) -> 97.648159 | HC8: =100*(DataQ!Q190/DataQ!Q$194) -> 96.97337 | HD8: =100*(DataQ!R190/DataQ!R$194) -> 106.05622 | HE8: =100*(DataQ!S190/DataQ!S$194) -> 99.826357 | HF8: =100*(DataQ!T190/DataQ!T$194) -> 96.743943 | HG8: =100*(DataQ!U190/DataQ!U$194) -> 98.91243 | HH8: =100*(DataQ!V190/DataQ!V$194) -> 97.285285 | HK8: =HR8 -> 97.648159 | HL8: =MIN(HS8:HX8) -> 96.743943 | HM8: =+HO8-HL8 -> 9.3122804 | HN8: 100 | HO8: =MAX(HS8:HX8) -> 106.05622 | HR8: =100*(DataQ!C190/DataQ!C$194) -> 97.648159 | HS8: =100*(DataQ!Q190/DataQ!Q$194) -> 96.97337 | HT8: =100*(DataQ!R190/DataQ!R$194) -> 106.05622 | HU8: =100*(DataQ!S190/DataQ!S$194) -> 99.826357 | HV8: =100*(DataQ!T190/DataQ!T$194) -> 96.743943 | HW8: =100*(DataQ!U190/DataQ!U$194) -> 98.91243 | HX8: =100*(DataQ!V190/DataQ!V$194) -> 97.285285 | HZ8: 1993 | IA8: =DataA!J27/'Chart Data'!IF8 -> 2.0277195 | IB8: =IB7*(1+$ID$5/100) -> 1.8926217 | IC8: =100*((IA8/IB8)-1) -> 7.1381273 | IF8: =DataA!K27*DataA!L27 -> 834990.75 | IR8: =HAVERQ!AH79 -> -27.5 | IS8: =100*(('IPNR ex BNFL'!I48/'IPNR ex BNFL'!I44)-1) -> 10.124899 | IT8: 0
A9: 1991 | B9: =100*((DataQ!C79/DataQ!C75)-1) -> -3.4497683 | C9: =K9 -> 21.139532 | D9: 0 | F9: 1991 | G9: =100*((AVERAGE(DataQ!C76:C79)/AVERAGE(DataQ!C72:C75))-1) -> -1.3371628 | H9: =AVERAGE(K6:K9) -> 19.935098 | I9: 0 | K9: =L9 -> 21.139532 | L9: =100*(HAVERQ!AF13/HAVERQ!AI13) -> 21.139532 | N9: 2019 | O9: =100*('ONS CVM_SA_(Quarterly)'!B93/'ONS CVM_SA_(Quarterly)'!B$101) -> 113.69733 | P9: =100*('ONS CVM_SA_(Quarterly)'!D93/'ONS CVM_SA_(Quarterly)'!D$101) -> 107.45463 | R9: 100 | T9: 2022 | U9: ='ONS CVM_SA_(Quarterly)'!C105-'ONS CVM_SA_(Quarterly)'!C$101 -> 916 | V9: ='ONS CVM_SA_(Quarterly)'!D105-'ONS CVM_SA_(Quarterly)'!D$101 -> 1387 | W9: ='ONS CVM_SA_(Quarterly)'!E105-'ONS CVM_SA_(Quarterly)'!E$101 -> 2002 | X9: ='ONS CVM_SA_(Quarterly)'!F105-'ONS CVM_SA_(Quarterly)'!F$101 -> 524 | Y9: ='ONS CVM_SA_(Quarterly)'!B105-'ONS CVM_SA_(Quarterly)'!B$101 -> 5074 | AA9: 2022 | AB9: =100*(U9/'ONS CVM_SA_(Quarterly)'!$B$101) -> 1.7017166 | AC9: =100*(V9/'ONS CVM_SA_(Quarterly)'!$B$101) -> 2.5767259 | AD9: =100*(W9/'ONS CVM_SA_(Quarterly)'!$B$101) -> 3.7192539 | AE9: =100*(X9/'ONS CVM_SA_(Quarterly)'!$B$101) -> 0.97347106 | AF9: =100*(('ONS CVM_SA_(Quarterly)'!B105/'ONS CVM_SA_(Quarterly)'!B$101)-1) -> 9.4263209 | AH9: 2020 | AI9: =100*(('ONS CVM_SA_(Quarterly)'!C97-'ONS CVM_SA_(Quarterly)'!C$96)/'ONS CVM_SA_(Quarterly)'!$B$96) -> 0.67587186 | AJ9: =100*(('ONS CVM_SA_(Quarterly)'!D97-'ONS CVM_SA_(Quarterly)'!D$96)/'ONS CVM_SA_(Quarterly)'!$B$96) -> -0.014517534 | AK9: =100*(('ONS CVM_SA_(Quarterly)'!E97-'ONS CVM_SA_(Quarterly)'!E$96)/'ONS CVM_SA_(Quarterly)'!$B$96) -> -2.2679614 | AL9: =100*(('ONS CVM_SA_(Quarterly)'!F97-'ONS CVM_SA_(Quarterly)'!F$96)/'ONS CVM_SA_(Quarterly)'!$B$96) -> 0.35648611 | AM9: =100*(('ONS CVM_SA_(Quarterly)'!B97-'ONS CVM_SA_(Quarterly)'!B$96)/'ONS CVM_SA_(Quarterly)'!$B$96) -> -2.2502178 | AO9: 2017 | AP9: =100*(('ONS CVM_SA_(Quarterly)'!C85-AVERAGE('ONS CVM_SA_(Quarterly)'!C$81:C$84))/AVERAGE('ONS CVM_SA_(Quarterly)'!$B$81:$B$84)) -> -1.1790781 | AQ9: =100*(('ONS CVM_SA_(Quarterly)'!D85-AVERAGE('ONS CVM_SA_(Quarterly)'!D$81:D$84))/AVERAGE('ONS CVM_SA_(Quarterly)'!$B$81:$B$84)) -> 0.27187676 | AR9: =100*(('ONS CVM_SA_(Quarterly)'!E85-AVERAGE('ONS CVM_SA_(Quarterly)'!E$81:E$84))/AVERAGE('ONS CVM_SA_(Quarterly)'!$B$81:$B$84)) -> -0.21758244 | AS9: =100*(('ONS CVM_SA_(Quarterly)'!F85-AVERAGE('ONS CVM_SA_(Quarterly)'!F$81:F$84))/AVERAGE('ONS CVM_SA_(Quarterly)'!$B$81:$B$84)) -> 0.209884 | AT9: =100*(('ONS CVM_SA_(Quarterly)'!B85-AVERAGE('ONS CVM_SA_(Quarterly)'!B$81:B$84))/AVERAGE('ONS CVM_SA_(Quarterly)'!$B$81:$B$84)) -> 0.54983124 | AV9: 43586 | AW9: =HAVERM!D240 -> 0.75 | AX9: =HAVERM!B240 -> 3.32 | AY9: =HAVERM!C240 -> 2.43 | BA9: 44652 | BB9: =AX44-AX$39 -> 0.45 | BC9: =AY44-AY$39 -> 0.03 | BD9: 1000 | BF9: 0 | BI9: 2019 | BJ9: =100*(HAVERQ!B125/HAVERQ!B$128) -> 98.720844 | BK9: =100*(HAVERQ!I125/HAVERQ!I$128) -> 107.00514 | BL9: =100*(HAVERQ!J125/HAVERQ!J$128) -> 86.800499 | BM9: =100*(HAVERQ!K125/HAVERQ!K$128) -> 91.465677 | BN9: =100*((HAVERQ!L125+HAVERQ!M125)/(HAVERQ!L$128+HAVERQ!M$128)) -> 99.67185 | BO9: 100 | BQ9: 2019 | BR9: =HAVERQ!I125-HAVERQ!I$128 -> 654 | BS9: =HAVERQ!J125-HAVERQ!J$128 -> -1269 | BT9: =HAVERQ!K125-HAVERQ!K$128 -> -276 | BU9: =(HAVERQ!L125+HAVERQ!M125)-(HAVERQ!L$128+HAVERQ!M$128) -> -130 | BV9: =HAVERQ!N125-HAVERQ!N$128 -> -104 | BW9: =HAVERQ!B125-HAVERQ!B$128 -> -793 | BY9: 2020 | BZ9: =100*((HAVERQ!I129-HAVERQ!I$128)/HAVERQ!$B$128) -> -0.040326483 | CA9: =100*((HAVERQ!J129-HAVERQ!J$128)/HAVERQ!$B$128) -> -2.8228538 | CB9: =100*((HAVERQ!K129-HAVERQ!K$128)/HAVERQ!$B$128) -> -0.34035552 | CC9: =100*(((HAVERQ!L129+HAVERQ!M129)-(HAVERQ!L$128+HAVERQ!M$128))/HAVERQ!$B$128) -> -4.9101526 | CD9: =CE9-BZ9-CA9-CB9-CC9 -> 5.8634707 | CE9: =100*((HAVERQ!B129-HAVERQ!B$128)/HAVERQ!B$128) -> -2.2502178 | CG9: 2019 | CH9: =HAVERQ!I125 -> 9990 | CI9: =HAVERQ!J125 -> 8345 | CJ9: =HAVERQ!K125 -> 2958 | CK9: =HAVERQ!L125+HAVERQ!M125 -> 39486 | CL9: =HAVERQ!N125 -> 1254 | CN9: 2019 | CO9: =CX9 -> -297 | CP9: =CY9 -> 65 | CQ9: =CZ9 -> 138 | CR9: =DA9 -> 867 | CS9: =DC9 -> 100 | CT9: =+DB9+DD9+DE9+DF9 -> -403 | CU9: =DG9 -> -130 | CW9: 2019 | CX9: =HAVERQ!L125-HAVERQ!L$128 -> -297 | CY9: =HAVERQ!O125-HAVERQ!O$128 -> 65 | CZ9: =HAVERQ!P125-HAVERQ!P$128 -> 138 | DA9: =HAVERQ!Q125-HAVERQ!Q$128 -> 867 | DB9: =HAVERQ!R125-HAVERQ!R$128 -> -23 | DC9: =HAVERQ!S125-HAVERQ!S$128 -> 100 | DD9: =HAVERQ!T125-HAVERQ!T$128 -> 167 | DE9: =HAVERQ!U125-HAVERQ!U$128 -> -107 | DF9: =HAVERQ!V125-HAVERQ!V$128 -> -440 | DG9: =(HAVERQ!L125+HAVERQ!M125)-(HAVERQ!L$128+HAVERQ!M$128) -> -130 | DI9: 2019 | DJ9: =100*(HAVERQ!C125/HAVERQ!C$128) -> 101.15148 | DK9: =100*(HAVERQ!D125/HAVERQ!D$128) -> 118.51687 | DL9: =100*(HAVERQ!E125/HAVERQ!E$128) -> 99.506054 | DM9: =100*(HAVERQ!F125/HAVERQ!F$128) -> 101.5543 | DN9: =100*(HAVERQ!G125/HAVERQ!G$128) -> 103.73338 | DO9: =100*(HAVERQ!H125/HAVERQ!H$128) -> 94.569947 | DP9: 100 | DR9: 2019 | DS9: =HAVERQ!D125-HAVERQ!D$128 -> 834 | DT9: =HAVERQ!E125-HAVERQ!E$128 -> -82 | DU9: =HAVERQ!F125-HAVERQ!F$128 -> 394 | DV9: =HAVERQ!G125-HAVERQ!G$128 -> 1384 | DW9: =HAVERQ!H125-HAVERQ!H$128 -> -1435 | DX9: =HAVERQ!C125-HAVERQ!C$128 -> 1263 | DZ9: 2001 | EA9: =MIN(EM9:EO9) -> 0.55360156 | EB9: =+EF9-EA9 -> 0.47171535 | EC9: =100*((EJ13/EJ9)-1) -> 1.6481753 | ED9: 0 | EF9: =MAX(EM9:EO9) -> 1.0253169 | EG9: =AVERAGE(EM9:EO9) -> 0.79922117 | EI9: 2000 | EJ9: ='IPNR ex BNFL'!I17 -> 43624 | EM9: =(ER9-ER$2)/ER$3 -> 1.0253169 | EN9: =(ES9-ES$2)/ES$3 -> 0.55360156 | EO9: =(ET9-ET$2)/ET$3 -> 0.81874503 | ER9: =(HAVERQ!W51*$EW$2)+(HAVERQ!X51*$EX$2)/($EW$2+$EX$2) -> 20.221335 | ES9: =(HAVERQ!AB51*$EW$2)+(HAVERQ!AC51*$EY$2)+(HAVERQ!AD51*$EZ$2)+(HAVERQ!AE51*$FA$2)/($EW$2+$EY$2+$EZ$2+$FA$2) -> 1.5543614 | ET9: =(HAVERQ!Y51*$EW$2)+(HAVERQ!Z51*$EX$2)/($EW$2+$EX$2) -> 2.1084809 | FC9: 43586 | FD9: =100*((HAVERM!E240+HAVERM!F240)/(HAVERM!E$249+HAVERM!F$249)) -> 99.160108 | FE9: =100*(HAVERM!E240/HAVERM!E$249) -> 99.295132 | FF9: =100*(HAVERM!F240/HAVERM!F$249) -> 99.08602 | FG9: 100 | FV9: 42461 | FW9: =HAVERM!G203 -> 345227 | FY9: =FW9-FW8 -> -4540 | GC9: 2011 | GD9: =100*(DataQ!W159/DataQ!W$194) -> 72.139538 | GE9: =100*(DataQ!X159/DataQ!X$194) -> 70.642588 | GF9: =100*(DataQ!C159/DataQ!C$194) -> 68.280801 | GH9: 100 | GJ9: 2006 | GK9: =100*(DataQ!Z139/AVERAGE(DataQ!$Z$203:$Z$206)) -> 74.848566 | GL9: =100*(DataQ!C139/AVERAGE(DataQ!$C$203:$C$206)) -> 77.536868 | GM9: 100 | GO9: 2006 | GP9: =100*(DataQ!Z139/DataQ!$Z$194) -> 74.569319 | GQ9: =100*(DataQ!C139/DataQ!$C$194) -> 74.845953 | GR9: 100 | GT9: 2019 | GU9: =HB9 -> 98.720844 | GV9: =MIN(HC9:HH9) -> 97.150651 | GW9: =+GY9-GV9 -> 8.9744031 | GX9: 100 | GY9: =MAX(HC9:HH9) -> 106.12505 | HA9: 2019 | HB9: =100*(DataQ!C191/DataQ!C$194) -> 98.720844 | HC9: =100*(DataQ!Q191/DataQ!Q$194) -> 97.626502 | HD9: =100*(DataQ!R191/DataQ!R$194) -> 106.12505 | HE9: =100*(DataQ!S191/DataQ!S$194) -> 101.27947 | HF9: =100*(DataQ!T191/DataQ!T$194) -> 97.150651 | HG9: =100*(DataQ!U191/DataQ!U$194) -> 99.355527 | HH9: =100*(DataQ!V191/DataQ!V$194) -> 101.984 | HJ9: 2019 | HK9: =HR9 -> 98.720844 | HL9: =MIN(HS9:HX9) -> 97.150651 | HM9: =+HO9-HL9 -> 8.9744031 | HN9: 100 | HO9: =MAX(HS9:HX9) -> 106.12505 | HQ9: 2019 | HR9: =100*(DataQ!C191/DataQ!C$194) -> 98.720844 | HS9: =100*(DataQ!Q191/DataQ!Q$194) -> 97.626502 | HT9: =100*(DataQ!R191/DataQ!R$194) -> 106.12505 | HU9: =100*(DataQ!S191/DataQ!S$194) -> 101.27947 | HV9: =100*(DataQ!T191/DataQ!T$194) -> 97.150651 | HW9: =100*(DataQ!U191/DataQ!U$194) -> 99.355527 | HX9: =100*(DataQ!V191/DataQ!V$194) -> 101.984 | HZ9: 1994 | IA9: =DataA!J28/'Chart Data'!IF9 -> 2.0419879 | IB9: =IB8*(1+$ID$5/100) -> 1.9429006 | IC9: =100*((IA9/IB9)-1) -> 5.0999682 | IF9: =DataA!K28*DataA!L28 -> 847387.01 | IQ9: 2008 | IR9: =HAVERQ!AH80 -> -8.3 | IS9: =100*(('IPNR ex BNFL'!I49/'IPNR ex BNFL'!I45)-1) -> -2.5877967 | IT9: 0
B10: =100*((DataQ!C80/DataQ!C76)-1) -> -9.0430141 | C10: =K10 -> 21.655655 | D10: 0 | G10: =100*((AVERAGE(DataQ!C77:C80)/AVERAGE(DataQ!C73:C76))-1) -> -4.0916 | H10: =AVERAGE(K7:K10) -> 20.34257 | I10: 0 | K10: =L10 -> 21.655655 | L10: =100*(HAVERQ!AF14/HAVERQ!AI14) -> 21.655655 | O10: =100*('ONS CVM_SA_(Quarterly)'!B94/'ONS CVM_SA_(Quarterly)'!B$101) -> 115.51795 | P10: =100*('ONS CVM_SA_(Quarterly)'!D94/'ONS CVM_SA_(Quarterly)'!D$101) -> 109.13847 | R10: 100 | U10: ='ONS CVM_SA_(Quarterly)'!C106-'ONS CVM_SA_(Quarterly)'!C$101 -> 3063 | V10: ='ONS CVM_SA_(Quarterly)'!D106-'ONS CVM_SA_(Quarterly)'!D$101 -> 1819 | W10: ='ONS CVM_SA_(Quarterly)'!E106-'ONS CVM_SA_(Quarterly)'!E$101 -> 1388 | X10: ='ONS CVM_SA_(Quarterly)'!F106-'ONS CVM_SA_(Quarterly)'!F$101 -> -8 | Y10: ='ONS CVM_SA_(Quarterly)'!B106-'ONS CVM_SA_(Quarterly)'!B$101 -> 6504 | AB10: =100*(U10/'ONS CVM_SA_(Quarterly)'!$B$101) -> 5.690347 | AC10: =100*(V10/'ONS CVM_SA_(Quarterly)'!$B$101) -> 3.3792822 | AD10: =100*(W10/'ONS CVM_SA_(Quarterly)'!$B$101) -> 2.5785836 | AE10: =100*(X10/'ONS CVM_SA_(Quarterly)'!$B$101) -> -0.014862154 | AF10: =100*(('ONS CVM_SA_(Quarterly)'!B106/'ONS CVM_SA_(Quarterly)'!B$101)-1) -> 12.082931 | AI10: =100*(('ONS CVM_SA_(Quarterly)'!C98-'ONS CVM_SA_(Quarterly)'!C$96)/'ONS CVM_SA_(Quarterly)'!$B$96) -> -3.9342517 | AJ10: =100*(('ONS CVM_SA_(Quarterly)'!D98-'ONS CVM_SA_(Quarterly)'!D$96)/'ONS CVM_SA_(Quarterly)'!$B$96) -> -5.5763461 | AK10: =100*(('ONS CVM_SA_(Quarterly)'!E98-'ONS CVM_SA_(Quarterly)'!E$96)/'ONS CVM_SA_(Quarterly)'!$B$96) -> -7.1571442 | AL10: =100*(('ONS CVM_SA_(Quarterly)'!F98-'ONS CVM_SA_(Quarterly)'!F$96)/'ONS CVM_SA_(Quarterly)'!$B$96) -> -2.9051199 | AM10: =100*(('ONS CVM_SA_(Quarterly)'!B98-'ONS CVM_SA_(Quarterly)'!B$96)/'ONS CVM_SA_(Quarterly)'!$B$96) -> -21.039133 | AP10: =100*(('ONS CVM_SA_(Quarterly)'!C86-AVERAGE('ONS CVM_SA_(Quarterly)'!C$81:C$84))/AVERAGE('ONS CVM_SA_(Quarterly)'!$B$81:$B$84)) -> 0.46433795 | AQ10: =100*(('ONS CVM_SA_(Quarterly)'!D86-AVERAGE('ONS CVM_SA_(Quarterly)'!D$81:D$84))/AVERAGE('ONS CVM_SA_(Quarterly)'!$B$81:$B$84)) -> 0.31563636 | AR10: =100*(('ONS CVM_SA_(Quarterly)'!E86-AVERAGE('ONS CVM_SA_(Quarterly)'!E$81:E$84))/AVERAGE('ONS CVM_SA_(Quarterly)'!$B$81:$B$84)) -> -1.7264782 | AS10: =100*(('ONS CVM_SA_(Quarterly)'!F86-AVERAGE('ONS CVM_SA_(Quarterly)'!F$81:F$84))/AVERAGE('ONS CVM_SA_(Quarterly)'!$B$81:$B$84)) -> 0.7495857 | AT10: =100*(('ONS CVM_SA_(Quarterly)'!B86-AVERAGE('ONS CVM_SA_(Quarterly)'!B$81:B$84))/AVERAGE('ONS CVM_SA_(Quarterly)'!$B$81:$B$84)) -> 0.047406231 | AV10: 43617 | AW10: =HAVERM!D241 -> 0.75 | AX10: =HAVERM!B241 -> 3.31 | AY10: =HAVERM!C241 -> 2.43 | BA10: 44682 | BB10: =AX45-AX$39 -> 0.65 | BC10: =AY45-AY$39 -> 0.06 | BD10: 1000 | BF10: 0 | BJ10: =100*(HAVERQ!B126/HAVERQ!B$128) -> 100.30164 | BK10: =100*(HAVERQ!I126/HAVERQ!I$128) -> 103.96315 | BL10: =100*(HAVERQ!J126/HAVERQ!J$128) -> 83.107968 | BM10: =100*(HAVERQ!K126/HAVERQ!K$128) -> 97.990105 | BN10: =100*((HAVERQ!L126+HAVERQ!M126)/(HAVERQ!L$128+HAVERQ!M$128)) -> 99.553211 | BO10: 100 | BR10: =HAVERQ!I126-HAVERQ!I$128 -> 370 | BS10: =HAVERQ!J126-HAVERQ!J$128 -> -1624 | BT10: =HAVERQ!K126-HAVERQ!K$128 -> -65 | BU10: =(HAVERQ!L126+HAVERQ!M126)-(HAVERQ!L$128+HAVERQ!M$128) -> -177 | BV10: =HAVERQ!N126-HAVERQ!N$128 -> -6 | BW10: =HAVERQ!B126-HAVERQ!B$128 -> 187 | BZ10: =100*((HAVERQ!I130-HAVERQ!I$128)/HAVERQ!$B$128) -> -1.7066168 | CA10: =100*((HAVERQ!J130-HAVERQ!J$128)/HAVERQ!$B$128) -> -4.6165758 | CB10: =100*((HAVERQ!K130-HAVERQ!K$128)/HAVERQ!$B$128) -> -1.8405007 | CC10: =100*(((HAVERQ!L130+HAVERQ!M130)-(HAVERQ!L$128+HAVERQ!M$128))/HAVERQ!$B$128) -> -5.3521309 | CD10: =CE10-BZ10-CA10-CB10-CC10 -> -7.5233087 | CE10: =100*((HAVERQ!B130-HAVERQ!B$128)/HAVERQ!B$128) -> -21.039133 | CH10: =HAVERQ!I126 -> 9706 | CI10: =HAVERQ!J126 -> 7990 | CJ10: =HAVERQ!K126 -> 3169 | CK10: =HAVERQ!L126+HAVERQ!M126 -> 39439 | CL10: =HAVERQ!N126 -> 1352 | CO10: =CX10 -> -258 | CP10: =CY10 -> -104 | CQ10: =CZ10 -> 52 | CR10: =DA10 -> 2139 | CS10: =DC10 -> 95 | CT10: =+DB10+DD10+DE10+DF10 -> -31 | CU10: =DG10 -> -177 | CX10: =HAVERQ!L126-HAVERQ!L$128 -> -258 | CY10: =HAVERQ!O126-HAVERQ!O$128 -> -104 | CZ10: =HAVERQ!P126-HAVERQ!P$128 -> 52 | DA10: =HAVERQ!Q126-HAVERQ!Q$128 -> 2139 | DB10: =HAVERQ!R126-HAVERQ!R$128 -> 246 | DC10: =HAVERQ!S126-HAVERQ!S$128 -> 95 | DD10: =HAVERQ!T126-HAVERQ!T$128 -> 127 | DE10: =HAVERQ!U126-HAVERQ!U$128 -> 14 | DF10: =HAVERQ!V126-HAVERQ!V$128 -> -418 | DG10: =(HAVERQ!L126+HAVERQ!M126)-(HAVERQ!L$128+HAVERQ!M$128) -> -177 | DJ10: =100*(HAVERQ!C126/HAVERQ!C$128) -> 100.32912 | DK10: =100*(HAVERQ!D126/HAVERQ!D$128) -> 129.66252 | DL10: =100*(HAVERQ!E126/HAVERQ!E$128) -> 99.108487 | DM10: =100*(HAVERQ!F126/HAVERQ!F$128) -> 102.0632 | DN10: =100*(HAVERQ!G126/HAVERQ!G$128) -> 100.31022 | DO10: =100*(HAVERQ!H126/HAVERQ!H$128) -> 94.191547 | DP10: 100 | DS10: =HAVERQ!D126-HAVERQ!D$128 -> 1336 | DT10: =HAVERQ!E126-HAVERQ!E$128 -> -148 | DU10: =HAVERQ!F126-HAVERQ!F$128 -> 523 | DV10: =HAVERQ!G126-HAVERQ!G$128 -> 115 | DW10: =HAVERQ!H126-HAVERQ!H$128 -> -1535 | DX10: =HAVERQ!C126-HAVERQ!C$128 -> 361 | EA10: =MIN(EM10:EO10) -> 0.52228064 | EB10: =+EF10-EA10 -> 0.65269528 | EC10: =100*((EJ14/EJ10)-1) -> -3.0572227 | ED10: 0 | EF10: =MAX(EM10:EO10) -> 1.1749759 | EG10: =AVERAGE(EM10:EO10) -> 0.82625722 | EJ10: ='IPNR ex BNFL'!I18 -> 46153 | EM10: =(ER10-ER$2)/ER$3 -> 1.1749759 | EN10: =(ES10-ES$2)/ES$3 -> 0.52228064 | EO10: =(ET10-ET$2)/ET$3 -> 0.78151509 | ER10: =(HAVERQ!W52*$EW$2)+(HAVERQ!X52*$EX$2)/($EW$2+$EX$2) -> 21.975472 | ES10: =(HAVERQ!AB52*$EW$2)+(HAVERQ!AC52*$EY$2)+(HAVERQ!AD52*$EZ$2)+(HAVERQ!AE52*$FA$2)/($EW$2+$EY$2+$EZ$2+$FA$2) -> 1.1136195 | ET10: =(HAVERQ!Y52*$EW$2)+(HAVERQ!Z52*$EX$2)/($EW$2+$EX$2) -> 2.0500097 | FC10: 43617 | FD10: =100*((HAVERM!E241+HAVERM!F241)/(HAVERM!E$249+HAVERM!F$249)) -> 99.441515 | FE10: =100*(HAVERM!E241/HAVERM!E$249) -> 100.05531 | FF10: =100*(HAVERM!F241/HAVERM!F$249) -> 99.104723 | FG10: 100 | FV10: 42491 | FW10: =HAVERM!G204 -> 346739 | FY10: =FW10-FW9 -> 1512 | GD10: =100*(DataQ!W160/DataQ!W$194) -> 73.802761 | GE10: =100*(DataQ!X160/DataQ!X$194) -> 72.464961 | GF10: =100*(DataQ!C160/DataQ!C$194) -> 72.1715 | GH10: 100 | GK10: =100*(DataQ!Z140/AVERAGE(DataQ!$Z$203:$Z$206)) -> 71.957848 | GL10: =100*(DataQ!C140/AVERAGE(DataQ!$C$203:$C$206)) -> 74.512261 | GM10: 100 | GP10: =100*(DataQ!Z140/DataQ!$Z$194) -> 71.689386 | GQ10: =100*(DataQ!C140/DataQ!$C$194) -> 71.926315 | GR10: 100 | GU10: =HB10 -> 100.30164 | GV10: =MIN(HC10:HH10) -> 98.655933 | GW10: =+GY10-GV10 -> 6.8336367 | GX10: 100 | GY10: =MAX(HC10:HH10) -> 105.48957 | HB10: =100*(DataQ!C192/DataQ!C$194) -> 100.30164 | HC10: =100*(DataQ!Q192/DataQ!Q$194) -> 99.484901 | HD10: =100*(DataQ!R192/DataQ!R$194) -> 105.48957 | HE10: =100*(DataQ!S192/DataQ!S$194) -> 100.7951 | HF10: =100*(DataQ!T192/DataQ!T$194) -> 98.655933 | HG10: =100*(DataQ!U192/DataQ!U$194) -> 101.05983 | HH10: =100*(DataQ!V192/DataQ!V$194) -> 99.711361 | HK10: =HR10 -> 100.30164 | HL10: =MIN(HS10:HX10) -> 98.655933 | HM10: =+HO10-HL10 -> 6.8336367 | HN10: 100 | HO10: =MAX(HS10:HX10) -> 105.48957 | HR10: =100*(DataQ!C192/DataQ!C$194) -> 100.30164 | HS10: =100*(DataQ!Q192/DataQ!Q$194) -> 99.484901 | HT10: =100*(DataQ!R192/DataQ!R$194) -> 105.48957 | HU10: =100*(DataQ!S192/DataQ!S$194) -> 100.7951 | HV10: =100*(DataQ!T192/DataQ!T$194) -> 98.655933 | HW10: =100*(DataQ!U192/DataQ!U$194) -> 101.05983 | HX10: =100*(DataQ!V192/DataQ!V$194) -> 99.711361 | HZ10: 1995 | IA10: =DataA!J29/'Chart Data'!IF10 -> 2.0650402 | IB10: =IB9*(1+$ID$5/100) -> 1.9945151 | IC10: =100*((IA10/IB10)-1) -> 3.5359532 | IF10: =DataA!K29*DataA!L29 -> 858465.12 | IR10: =HAVERQ!AH81 -> -10.6 | IS10: =100*(('IPNR ex BNFL'!I50/'IPNR ex BNFL'!I46)-1) -> -0.28356312 | IT10: 0
