Workbook
Name _DLX1.INC: HAVERA!$A$2:$BN$7

Sheet Chart Data
A1: Budget policy decisions | I1: Fiscal rules | U1: Fiscal rules | AA1: Public sector net investment | AH1: OBR estimates of fiscal tightening | AM1: NICs impact
K2: Levels | P2: Diff | V2: Public sector net debt | W2: Public sector net debt (ex BoE) | X2: Public sector net financial liabilities | Y2: Public sector net worth | AN2: GDP | AR2: ER | AV2: ETILO | AZ2: UPILO | BD2: TP
B3: 2024-2025 | C3: 2025-2026 | D3: 2026-2027 | E3: 2027-2028 | F3: 2028-2029 | G3: 2029-2030 | K3: Public sector net debt | L3: Public sector net debt (ex BoE) | M3: Public sector net financial liabilities | N3: Public sector net worth (inverted) | P3: Public sector net debt | Q3: Public sector net debt (ex BoE) | R3: Public sector net financial liabilities | S3: Public sector net worth (inverted) | V3: Public sector net debt | W3: Public sector net debt (ex BoE) | X3: Public sector net financial liabilities | Y3: Public sector net worth (inverted) | AC3: Budget (Oct24) | AD3: Budget (Mar24) | AE3: UK average (2004-2023) | AF3: OECD average | AJ3: Budget (Oct24) | AK3: Budget (Mar24) | AN3: Baseline | AO3: Scenario | AP3: Diff | AR3: Baseline | AS3: Scenario | AT3: Diff | AV3: Baseline | AW3: Scenario | AX3: Diff | AZ3: Baseline | BA3: Scenario | BB3: Diff | BD3: Baseline | BE3: Scenario | BF3: Diff
A4: Tax | B4: ='HMT - Table 5.1'!F88 -> 1160 | C4: ='HMT - Table 5.1'!G88 -> 24005 | D4: ='HMT - Table 5.1'!H88 -> 34785 | E4: ='HMT - Table 5.1'!I88 -> 39065 | F4: ='HMT - Table 5.1'!J88 -> 39725 | G4: ='HMT - Table 5.1'!K88 -> 41170 | I4: 2000-01 | J4: =LEFT(I4,4) -> 2000 | K4: {=TRANSPOSE('C6.11'!D26:AG29)} -> 28.3 | L4: 28.4 | M4: 26.955398 | N4: 32.43637 | U4: 2029-2030 | V4: =-(P33/100)*$V$7 -> 6.6405827 | W4: =-(Q33/100)*$V$7 -> -5.7796597 | X4: =-(R33/100)*$V$7 -> 15.747235 | Y4: =-(S33/100)*$V$7 -> 16.945561 | AA4: ='Aggregates (% GDP) Oct24'!B57 -> 2000-01 | AB4: =LEFT(AA4,4) -> 2000 | AC4: ='Aggregates (% GDP) Oct24'!F57 -> 0.40470502 | AD4: ='Aggregates (% GDP) Mar24'!F57 -> 0.40470502 | AE4: =AVERAGE($AD$8:$AD$27) -> 2.145275 | AH4: ='Aggregates (% GDP) Oct24'!B57 -> 2000-01 | AI4: =LEFT(AH4,4) -> 2000 | AJ4: =-('Aggregates (% GDP) Oct24'!M57-'Aggregates (% GDP) Oct24'!M56) -> -0.014492648 | AM4: 2024 | AN4: =100*((DataCY!B51/DataCY!B50)-1) -> 0.98266797 | AO4: =100*((DataCY!H51/DataCY!H50)-1) -> 0.98266797 | AP4: =AO4-AN4 -> 0 | AR4: =100*((DataCY!D51/DataCY!D50)-1) -> 4.2451725 | AS4: =100*((DataCY!J51/DataCY!J50)-1) -> 4.2451725 | AT4: =AS4-AR4 -> 0 | AV4: =DataCY!C51 -> 33138.705 | AW4: =DataCY!I51 -> 33138.705 | AX4: =AW4-AV4 -> 0 | AZ4: =DataCY!E51 -> 4.2879467 | BA4: =DataCY!K51 -> 4.2879467 | BB4: =BA4-AZ4 -> 0 | BD4: =DataFY!G51 -> 152663.25 | BE4: =DataFY!M51 -> 152663.25 | BF4: =BE4-BD4 -> 0
A5: Current spending | B5: ='HMT - Table 5.1'!F87-'Chart Data'!B6 -> -27630 | C5: ='HMT - Table 5.1'!G87-'Chart Data'!C6 -> -48190 | D5: ='HMT - Table 5.1'!H87-'Chart Data'!D6 -> -50675 | E5: ='HMT - Table 5.1'!I87-'Chart Data'!E6 -> -51825 | F5: ='HMT - Table 5.1'!J87-'Chart Data'!F6 -> -52805 | G5: ='HMT - Table 5.1'!K87-'Chart Data'!G6 -> -51035 | I5: 2001-02 | J5: =LEFT(I5,4) -> 2001 | K5: 28.1 | L5: 28.2 | M5: 28.366806 | N5: 34.14847 | P5: =K5-K4 -> -0.2 | Q5: =L5-L4 -> -0.2 | R5: =M5-M4 -> 1.4114071 | S5: =N5-N4 -> 1.7120996 | AA5: ='Aggregates (% GDP) Oct24'!B58 -> 2001-02 | AB5: =LEFT(AA5,4) -> 2001 | AC5: ='Aggregates (% GDP) Oct24'!F58 -> 1.0969634 | AD5: ='Aggregates (% GDP) Mar24'!F58 -> 1.0969634 | AE5: =AVERAGE($AD$8:$AD$27) -> 2.145275 | AH5: ='Aggregates (% GDP) Oct24'!B58 -> 2001-02 | AI5: =LEFT(AH5,4) -> 2001 | AJ5: =-('Aggregates (% GDP) Oct24'!M58-'Aggregates (% GDP) Oct24'!M57) -> 1.9591308 | AM5: 2025 | AN5: =100*((DataCY!B52/DataCY!B51)-1) -> 1.5341097 | AO5: =100*((DataCY!H52/DataCY!H51)-1) -> 1.39618 | AP5: =AO5-AN5 -> -0.13792967 | AR5: =100*((DataCY!D52/DataCY!D51)-1) -> 3.5514545 | AS5: =100*((DataCY!J52/DataCY!J51)-1) -> 3.478492 | AT5: =AS5-AR5 -> -0.072962485 | AV5: =DataCY!C52 -> 33430.338 | AW5: =DataCY!I52 -> 33403.51 | AX5: =AW5-AV5 -> -26.8275 | AZ5: =DataCY!E52 -> 4.3347963 | BA5: =DataCY!K52 -> 4.4113922 | BB5: =BA5-AZ5 -> 0.076596 | BD5: =DataFY!G52 -> 159368.98 | BE5: =DataFY!M52 -> 182720.43 | BF5: =BE5-BD5 -> 23351.45
A6: Capital spending | B6: ='HMT - Table 5.1'!F5 -> 1765 | C6: ='HMT - Table 5.1'!G5 -> -15360 | D6: ='HMT - Table 5.1'!H5 -> -19440 | E6: ='HMT - Table 5.1'!I5 -> -23820 | F6: ='HMT - Table 5.1'!J5 -> -25695 | G6: ='HMT - Table 5.1'!K5 -> -23125 | I6: 2002-03 | J6: =LEFT(I6,4) -> 2002 | K6: 29.8 | L6: 29.9 | M6: 31.350052 | N6: 36.652789 | P6: =K6-K5 -> 1.7 | Q6: =L6-L5 -> 1.7 | R6: =M6-M5 -> 2.9832465 | S6: =N6-N5 -> 2.5043195 | U6: Change % of GDP | AA6: ='Aggregates (% GDP) Oct24'!B59 -> 2002-03 | AB6: =LEFT(AA6,4) -> 2002 | AC6: ='Aggregates (% GDP) Oct24'!F59 -> 1.4448275 | AD6: ='Aggregates (% GDP) Mar24'!F59 -> 1.4448275 | AE6: =AVERAGE($AD$8:$AD$27) -> 2.145275 | AH6: ='Aggregates (% GDP) Oct24'!B59 -> 2002-03 | AI6: =LEFT(AH6,4) -> 2002 | AJ6: =-('Aggregates (% GDP) Oct24'!M59-'Aggregates (% GDP) Oct24'!M58) -> 2.0383229 | AM6: 2026 | AN6: =100*((DataCY!B53/DataCY!B52)-1) -> 1.631252 | AO6: =100*((DataCY!H53/DataCY!H52)-1) -> 1.5073108 | AP6: =AO6-AN6 -> -0.12394115 | AR6: =100*((DataCY!D53/DataCY!D52)-1) -> 2.6851513 | AS6: =100*((DataCY!J53/DataCY!J52)-1) -> 2.5624237 | AT6: =AS6-AR6 -> -0.12272757 | AV6: =DataCY!C53 -> 33874.042 | AW6: =DataCY!I53 -> 33820.61 | AX6: =AW6-AV6 -> -53.4325 | AZ6: =DataCY!E53 -> 4.127162 | BA6: =DataCY!K53 -> 4.2783833 | BB6: =BA6-AZ6 -> 0.15122125 | BD6: =DataFY!G53 -> 166351.45 | BE6: =DataFY!M53 -> 189385.05 | BF6: =BE6-BD6 -> 23033.6
A7: Total | B7: =SUM(B4:B6) -> -24705 | C7: =SUM(C4:C6) -> -39545 | D7: =SUM(D4:D6) -> -35330 | E7: =SUM(E4:E6) -> -36580 | F7: =SUM(F4:F6) -> -38775 | G7: =SUM(G4:G6) -> -32990 | I7: 2003-04 | J7: =LEFT(I7,4) -> 2003 | K7: 30.9 | L7: 31 | M7: 31.244827 | N7: 37.45462 | P7: =K7-K6 -> 1.1 | Q7: =L7-L6 -> 1.1 | R7: =M7-M6 -> -0.10522481 | S7: =N7-N6 -> 0.80183026 | U7: GDP! | V7: 3459.596 | AA7: ='Aggregates (% GDP) Oct24'!B60 -> 2003-04 | AB7: =LEFT(AA7,4) -> 2003 | AC7: ='Aggregates (% GDP) Oct24'!F60 -> 1.6922036 | AD7: ='Aggregates (% GDP) Mar24'!F60 -> 1.6922036 | AE7: =AVERAGE($AD$8:$AD$27) -> 2.145275 | AH7: ='Aggregates (% GDP) Oct24'!B60 -> 2003-04 | AI7: =LEFT(AH7,4) -> 2003 | AJ7: =-('Aggregates (% GDP) Oct24'!M60-'Aggregates (% GDP) Oct24'!M59) -> 0.4553037 | AM7: 2027 | AN7: =100*((DataCY!B54/DataCY!B53)-1) -> 1.6566706 | AO7: =100*((DataCY!H54/DataCY!H53)-1) -> 1.6837409 | AP7: =AO7-AN7 -> 0.027070292 | AR7: =100*((DataCY!D54/DataCY!D53)-1) -> 2.5895984 | AS7: =100*((DataCY!J54/DataCY!J53)-1) -> 2.6013744 | AT7: =AS7-AR7 -> 0.011775959 | AV7: =DataCY!C54 -> 34275.132 | AW7: =DataCY!I54 -> 34229.768 | AX7: =AW7-AV7 -> -45.365 | AZ7: =DataCY!E54 -> 3.940423 | BA7: =DataCY!K54 -> 4.0675903 | BB7: =BA7-AZ7 -> 0.12716725 | BD7: =DataFY!G54 -> 173561.32 | BE7: =DataFY!M54 -> 197158.96 | BF7: =BE7-BD7 -> 23597.64
I8: 2004-05 | J8: =LEFT(I8,4) -> 2004 | K8: 33.5 | L8: 33.6 | M8: 33.412416 | N8: 37.390259 | P8: =K8-K7 -> 2.6 | Q8: =L8-L7 -> 2.6 | R8: =M8-M7 -> 2.1675887 | S8: =N8-N7 -> -0.064360255 | AA8: ='Aggregates (% GDP) Oct24'!B61 -> 2004-05 | AB8: =LEFT(AA8,4) -> 2004 | AC8: ='Aggregates (% GDP) Oct24'!F61 -> 2.0459664 | AD8: ='Aggregates (% GDP) Mar24'!F61 -> 2.0459664 | AE8: =AVERAGE($AD$8:$AD$27) -> 2.145275 | AH8: ='Aggregates (% GDP) Oct24'!B61 -> 2004-05 | AI8: =LEFT(AH8,4) -> 2004 | AJ8: =-('Aggregates (% GDP) Oct24'!M61-'Aggregates (% GDP) Oct24'!M60) -> 0.50237965 | AM8: 2028 | AN8: =100*((DataCY!B55/DataCY!B54)-1) -> 1.6473682 | AO8: =100*((DataCY!H55/DataCY!H54)-1) -> 1.6778525 | AP8: =AO8-AN8 -> 0.030484248 | AR8: =100*((DataCY!D55/DataCY!D54)-1) -> 2.591253 | AS8: =100*((DataCY!J55/DataCY!J54)-1) -> 2.6296951 | AT8: =AS8-AR8 -> 0.038442166 | AV8: =DataCY!C55 -> 34669.898 | AW8: =DataCY!I55 -> 34633.96 | AX8: =AW8-AV8 -> -35.9375 | AZ8: =DataCY!E55 -> 3.7972135 | BA8: =DataCY!K55 -> 3.8969493 | BB8: =BA8-AZ8 -> 0.09973575 | BD8: =DataFY!G55 -> 180390.25 | BE8: =DataFY!M55 -> 204855.91 | BF8: =BE8-BD8 -> 24465.66
A9: check | B9: ='HMT - Table 5.1'!F86 -> -24705 | C9: ='HMT - Table 5.1'!G86 -> -39550 | D9: ='HMT - Table 5.1'!H86 -> -35330 | E9: ='HMT - Table 5.1'!I86 -> -36585 | F9: ='HMT - Table 5.1'!J86 -> -38775 | G9: ='HMT - Table 5.1'!K86 -> -32990 | I9: 2005-06 | J9: =LEFT(I9,4) -> 2005 | K9: 34.3 | L9: 34.5 | M9: 32.378335 | N9: 34.942387 | P9: =K9-K8 -> 0.8 | Q9: =L9-L8 -> 0.9 | R9: =M9-M8 -> -1.0340813 | S9: =N9-N8 -> -2.4478726 | W9: Diff | X9: £bn | Y9: =X4-W4 -> 21.526895 | AA9: ='Aggregates (% GDP) Oct24'!B62 -> 2005-06 | AB9: =LEFT(AA9,4) -> 2005 | AC9: ='Aggregates (% GDP) Oct24'!F62 -> 1.8521352 | AD9: ='Aggregates (% GDP) Mar24'!F62 -> 1.8521352 | AE9: =AVERAGE($AD$8:$AD$27) -> 2.145275 | AH9: ='Aggregates (% GDP) Oct24'!B62 -> 2005-06 | AI9: =LEFT(AH9,4) -> 2005 | AJ9: =-('Aggregates (% GDP) Oct24'!M62-'Aggregates (% GDP) Oct24'!M61) -> -0.69717717 | AM9: 2029 | AN9: =100*((DataCY!B56/DataCY!B55)-1) -> 1.6121887 | AO9: =100*((DataCY!H56/DataCY!H55)-1) -> 1.6514389 | AP9: =AO9-AN9 -> 0.039250219 | AR9: =100*((DataCY!D56/DataCY!D55)-1) -> 2.649545 | AS9: =100*((DataCY!J56/DataCY!J55)-1) -> 2.6857202 | AT9: =AS9-AR9 -> 0.036175242 | AV9: =DataCY!C56 -> 35019.358 | AW9: =DataCY!I56 -> 34992.588 | AX9: =AW9-AV9 -> -26.77 | AZ9: =DataCY!E56 -> 3.749889 | BA9: =DataCY!K56 -> 3.8234867 | BB9: =BA9-AZ9 -> 0.07359775 | BD9: =DataFY!G56 -> 187169.91 | BE9: =DataFY!M56 -> 212530.68 | BF9: =BE9-BD9 -> 25360.77
I10: 2006-07 | J10: =LEFT(I10,4) -> 2006 | K10: 35.1 | L10: 35.3 | M10: 32.440742 | N10: 35.127873 | P10: =K10-K9 -> 0.8 | Q10: =L10-L9 -> 0.8 | R10: =M10-M9 -> 0.062407551 | S10: =N10-N9 -> 0.18548609 | X10: % of GDP | Y10: =R33-Q33 -> -0.62223726 | AA10: ='Aggregates (% GDP) Oct24'!B63 -> 2006-07 | AB10: =LEFT(AA10,4) -> 2006 | AC10: ='Aggregates (% GDP) Oct24'!F63 -> 1.8163774 | AD10: ='Aggregates (% GDP) Mar24'!F63 -> 1.8163774 | AE10: =AVERAGE($AD$8:$AD$27) -> 2.145275 | AH10: ='Aggregates (% GDP) Oct24'!B63 -> 2006-07 | AI10: =LEFT(AH10,4) -> 2006 | AJ10: =-('Aggregates (% GDP) Oct24'!M63-'Aggregates (% GDP) Oct24'!M62) -> -0.71890443 | AM10: 2030 | AN10: =100*((DataCY!B57/DataCY!B56)-1) -> 1.6097059 | AO10: =100*((DataCY!H57/DataCY!H56)-1) -> 1.6548179 | AP10: =AO10-AN10 -> 0.045112052 | AR10: =100*((DataCY!D57/DataCY!D56)-1) -> 2.7035181 | AS10: =100*((DataCY!J57/DataCY!J56)-1) -> 2.7420534 | AT10: =AS10-AR10 -> 0.038535354 | AV10: =DataCY!C57 -> 35334.71 | AW10: =DataCY!I57 -> 35317.572 | AX10: =AW10-AV10 -> -17.1375 | AZ10: =DataCY!E57 -> 3.7498765 | BA10: =DataCY!K57 -> 3.7965653 | BB10: =BA10-AZ10 -> 0.04668875
A11: GDP! | B11: 2814.6771 | C11: 2950.0172 | D11: 3059.3962 | E11: 3167.3346 | F11: 3279.0494 | G11: 3397.2814 | I11: 2007-08 | J11: =LEFT(I11,4) -> 2007 | K11: 35.6 | L11: 35.8 | M11: 34.196775 | N11: 37.427136 | P11: =K11-K10 -> 0.5 | Q11: =L11-L10 -> 0.5 | R11: =M11-M10 -> 1.7560329 | S11: =N11-N10 -> 2.2992633 | AA11: ='Aggregates (% GDP) Oct24'!B64 -> 2007-08 | AB11: =LEFT(AA11,4) -> 2007 | AC11: ='Aggregates (% GDP) Oct24'!F64 -> 1.7924771 | AD11: ='Aggregates (% GDP) Mar24'!F64 -> 1.7924771 | AE11: =AVERAGE($AD$8:$AD$27) -> 2.145275 | AH11: ='Aggregates (% GDP) Oct24'!B64 -> 2007-08 | AI11: =LEFT(AH11,4) -> 2007 | AJ11: =-('Aggregates (% GDP) Oct24'!M64-'Aggregates (% GDP) Oct24'!M63) -> 0.49578275
I12: 2008-09 | J12: =LEFT(I12,4) -> 2008 | K12: 50.6 | L12: 50.6 | M12: 47.544202 | N12: 46.938699 | P12: =K12-K11 -> 15 | Q12: =L12-L11 -> 14.8 | R12: =M12-M11 -> 13.347427 | S12: =N12-N11 -> 9.5115631 | AA12: ='Aggregates (% GDP) Oct24'!B65 -> 2008-09 | AB12: =LEFT(AA12,4) -> 2008 | AC12: ='Aggregates (% GDP) Oct24'!F65 -> 3.0053462 | AD12: ='Aggregates (% GDP) Mar24'!F65 -> 3.0053462 | AE12: =AVERAGE($AD$8:$AD$27) -> 2.145275 | AH12: ='Aggregates (% GDP) Oct24'!B65 -> 2008-09 | AI12: =LEFT(AH12,4) -> 2008 | AJ12: =-('Aggregates (% GDP) Oct24'!M65-'Aggregates (% GDP) Oct24'!M64) -> 3.6279951
A13: % of GDP | I13: 2009-10 | J13: =LEFT(I13,4) -> 2009 | K13: 64.7 | L13: 63.9 | M13: 54.597887 | N13: 54.07218 | P13: =K13-K12 -> 14.1 | Q13: =L13-L12 -> 13.3 | R13: =M13-M12 -> 7.0536849 | S13: =N13-N12 -> 7.1334808 | AA13: ='Aggregates (% GDP) Oct24'!B66 -> 2009-10 | AB13: =LEFT(AA13,4) -> 2009 | AC13: ='Aggregates (% GDP) Oct24'!F66 -> 3.0029004 | AD13: ='Aggregates (% GDP) Mar24'!F66 -> 3.0029004 | AE13: =AVERAGE($AD$8:$AD$27) -> 2.145275 | AH13: ='Aggregates (% GDP) Oct24'!B66 -> 2009-10 | AI13: =LEFT(AH13,4) -> 2009 | AJ13: =-('Aggregates (% GDP) Oct24'!M66-'Aggregates (% GDP) Oct24'!M65) -> 1.4319908
A14: Tax | B14: =100*((B4/1000)/B$11) -> 0.041212542 | C14: =100*((C4/1000)/C$11) -> 0.81372406 | D14: =100*((D4/1000)/D$11) -> 1.1369891 | E14: =100*((E4/1000)/E$11) -> 1.2333714 | F14: =100*((F4/1000)/F$11) -> 1.2114791 | G14: =100*((G4/1000)/G$11) -> 1.2118513 | I14: 2010-11 | J14: =LEFT(I14,4) -> 2010 | K14: 70.9 | L14: 70.6 | M14: 58.946492 | N14: 49.558414 | P14: =K14-K13 -> 6.2 | Q14: =L14-L13 -> 6.7 | R14: =M14-M13 -> 4.3486046 | S14: =N14-N13 -> -4.5137655 | AA14: ='Aggregates (% GDP) Oct24'!B67 -> 2010-11 | AB14: =LEFT(AA14,4) -> 2010 | AC14: ='Aggregates (% GDP) Oct24'!F67 -> 2.4446147 | AD14: ='Aggregates (% GDP) Mar24'!F67 -> 2.4446147 | AE14: =AVERAGE($AD$8:$AD$27) -> 2.145275 | AH14: ='Aggregates (% GDP) Oct24'!B67 -> 2010-11 | AI14: =LEFT(AH14,4) -> 2010 | AJ14: =-('Aggregates (% GDP) Oct24'!M67-'Aggregates (% GDP) Oct24'!M66) -> -2.2415985
A15: Current spending | B15: =100*((B5/1000)/B$11) -> -0.98164012 | C15: =100*((C5/1000)/C$11) -> -1.6335498 | D15: =100*((D5/1000)/D$11) -> -1.6563726 | E15: =100*((E5/1000)/E$11) -> -1.6362338 | F15: =100*((F5/1000)/F$11) -> -1.6103752 | G15: =100*((G5/1000)/G$11) -> -1.5022306 | I15: 2011-12 | J15: =LEFT(I15,4) -> 2011 | K15: 74.3 | L15: 74.6 | M15: 65.016918 | N15: 54.680429 | P15: =K15-K14 -> 3.4 | Q15: =L15-L14 -> 4 | R15: =M15-M14 -> 6.0704267 | S15: =N15-N14 -> 5.1220142 | AA15: ='Aggregates (% GDP) Oct24'!B68 -> 2011-12 | AB15: =LEFT(AA15,4) -> 2011 | AC15: ='Aggregates (% GDP) Oct24'!F68 -> 1.8421103 | AD15: ='Aggregates (% GDP) Mar24'!F68 -> 1.8421103 | AE15: =AVERAGE($AD$8:$AD$27) -> 2.145275 | AH15: ='Aggregates (% GDP) Oct24'!B68 -> 2011-12 | AI15: =LEFT(AH15,4) -> 2011 | AJ15: =-('Aggregates (% GDP) Oct24'!M68-'Aggregates (% GDP) Oct24'!M67) -> -1.4113887
A16: Capital spending | B16: =100*((B6/1000)/B$11) -> 0.062707015 | C16: =100*((C6/1000)/C$11) -> -0.52067492 | D16: =100*((D6/1000)/D$11) -> -0.6354195 | E16: =100*((E6/1000)/E$11) -> -0.7520519 | F16: =100*((F6/1000)/F$11) -> -0.78361125 | G16: =100*((G6/1000)/G$11) -> -0.68069133 | I16: 2012-13 | J16: =LEFT(I16,4) -> 2012 | K16: 77.5 | L16: 76.2 | M16: 69.72436 | N16: 58.751603 | P16: =K16-K15 -> 3.2 | Q16: =L16-L15 -> 1.6 | R16: =M16-M15 -> 4.7074411 | S16: =N16-N15 -> 4.0711743 | AA16: ='Aggregates (% GDP) Oct24'!B69 -> 2012-13 | AB16: =LEFT(AA16,4) -> 2012 | AC16: ='Aggregates (% GDP) Oct24'!F69 -> 1.8798625 | AD16: ='Aggregates (% GDP) Mar24'!F69 -> 1.8798625 | AE16: =AVERAGE($AD$8:$AD$27) -> 2.145275 | AH16: ='Aggregates (% GDP) Oct24'!B69 -> 2012-13 | AI16: =LEFT(AH16,4) -> 2012 | AJ16: =-('Aggregates (% GDP) Oct24'!M69-'Aggregates (% GDP) Oct24'!M68) -> 0.44780765
A17: Total | B17: =100*((B7/1000)/B$11) -> -0.87772057 | C17: =100*((C7/1000)/C$11) -> -1.3405006 | D17: =100*((D7/1000)/D$11) -> -1.154803 | E17: =100*((E7/1000)/E$11) -> -1.1549143 | F17: =100*((F7/1000)/F$11) -> -1.1825073 | G17: =100*((G7/1000)/G$11) -> -0.97107057 | I17: 2013-14 | J17: =LEFT(I17,4) -> 2013 | K17: 79.2 | L17: 77 | M17: 70.718374 | N17: 56.326968 | P17: =K17-K16 -> 1.7 | Q17: =L17-L16 -> 0.8 | R17: =M17-M16 -> 0.99401484 | S17: =N17-N16 -> -2.4246345 | AA17: ='Aggregates (% GDP) Oct24'!B70 -> 2013-14 | AB17: =LEFT(AA17,4) -> 2013 | AC17: ='Aggregates (% GDP) Oct24'!F70 -> 1.4526683 | AD17: ='Aggregates (% GDP) Mar24'!F70 -> 1.4526683 | AE17: =AVERAGE($AD$8:$AD$27) -> 2.145275 | AH17: ='Aggregates (% GDP) Oct24'!B70 -> 2013-14 | AI17: =LEFT(AH17,4) -> 2013 | AJ17: =-('Aggregates (% GDP) Oct24'!M70-'Aggregates (% GDP) Oct24'!M69) -> -0.91274837
I18: 2014-15 | J18: =LEFT(I18,4) -> 2014 | K18: 81.6 | L18: 79.2 | M18: 72.913428 | N18: 53.4578 | P18: =K18-K17 -> 2.4 | Q18: =L18-L17 -> 2.2 | R18: =M18-M17 -> 2.1950537 | S18: =N18-N17 -> -2.8691685 | AA18: ='Aggregates (% GDP) Oct24'!B71 -> 2014-15 | AB18: =LEFT(AA18,4) -> 2014 | AC18: ='Aggregates (% GDP) Oct24'!F71 -> 1.929131 | AD18: ='Aggregates (% GDP) Mar24'!F71 -> 1.929131 | AE18: =AVERAGE($AD$8:$AD$27) -> 2.145275 | AH18: ='Aggregates (% GDP) Oct24'!B71 -> 2014-15 | AI18: =LEFT(AH18,4) -> 2014 | AJ18: =-('Aggregates (% GDP) Oct24'!M71-'Aggregates (% GDP) Oct24'!M70) -> 0.36659488
I19: 2015-16 | J19: =LEFT(I19,4) -> 2015 | K19: 81.3 | L19: 78.9 | M19: 73.981933 | N19: 51.950634 | P19: =K19-K18 -> -0.3 | Q19: =L19-L18 -> -0.3 | R19: =M19-M18 -> 1.0685047 | S19: =N19-N18 -> -1.5071661 | AA19: ='Aggregates (% GDP) Oct24'!B72 -> 2015-16 | AB19: =LEFT(AA19,4) -> 2015 | AC19: ='Aggregates (% GDP) Oct24'!F72 -> 1.6691683 | AD19: ='Aggregates (% GDP) Mar24'!F72 -> 1.6691683 | AE19: =AVERAGE($AD$8:$AD$27) -> 2.145275 | AH19: ='Aggregates (% GDP) Oct24'!B72 -> 2015-16 | AI19: =LEFT(AH19,4) -> 2015 | AJ19: =-('Aggregates (% GDP) Oct24'!M72-'Aggregates (% GDP) Oct24'!M71) -> -0.50198668
I20: 2016-17 | J20: =LEFT(I20,4) -> 2016 | K20: 83.5 | L20: 77.4 | M20: 74.221682 | N20: 61.429268 | P20: =K20-K19 -> 2.2 | Q20: =L20-L19 -> -1.5 | R20: =M20-M19 -> 0.23974945 | S20: =N20-N19 -> 9.4786344 | AA20: ='Aggregates (% GDP) Oct24'!B73 -> 2016-17 | AB20: =LEFT(AA20,4) -> 2016 | AC20: ='Aggregates (% GDP) Oct24'!F73 -> 1.8101862 | AD20: ='Aggregates (% GDP) Mar24'!F73 -> 1.8101862 | AE20: =AVERAGE($AD$8:$AD$27) -> 2.145275 | AH20: ='Aggregates (% GDP) Oct24'!B73 -> 2016-17 | AI20: =LEFT(AH20,4) -> 2016 | AJ20: =-('Aggregates (% GDP) Oct24'!M73-'Aggregates (% GDP) Oct24'!M72) -> -1.4760005
I21: 2017-18 | J21: =LEFT(I21,4) -> 2017 | K21: 82.3 | L21: 73.7 | M21: 70.188464 | N21: 63.049303 | P21: =K21-K20 -> -1.2 | Q21: =L21-L20 -> -3.7 | R21: =M21-M20 -> -4.0332186 | S21: =N21-N20 -> 1.6200343 | AA21: ='Aggregates (% GDP) Oct24'!B74 -> 2017-18 | AB21: =LEFT(AA21,4) -> 2017 | AC21: ='Aggregates (% GDP) Oct24'!F74 -> 2.2089205 | AD21: ='Aggregates (% GDP) Mar24'!F74 -> 2.2089205 | AE21: =AVERAGE($AD$8:$AD$27) -> 2.145275 | AH21: ='Aggregates (% GDP) Oct24'!B74 -> 2017-18 | AI21: =LEFT(AH21,4) -> 2017 | AJ21: =-('Aggregates (% GDP) Oct24'!M74-'Aggregates (% GDP) Oct24'!M73) -> 0.080590287
I22: 2018-19 | J22: =LEFT(I22,4) -> 2018 | K22: 80.3 | L22: 72.3 | M22: 66.982374 | N22: 58.905421 | P22: =K22-K21 -> -2 | Q22: =L22-L21 -> -1.4 | R22: =M22-M21 -> -3.2060891 | S22: =N22-N21 -> -4.1438817 | AA22: ='Aggregates (% GDP) Oct24'!B75 -> 2018-19 | AB22: =LEFT(AA22,4) -> 2018 | AC22: ='Aggregates (% GDP) Oct24'!F75 -> 2.100128 | AD22: ='Aggregates (% GDP) Mar24'!F75 -> 2.100128 | AE22: =AVERAGE($AD$8:$AD$27) -> 2.145275 | AH22: ='Aggregates (% GDP) Oct24'!B75 -> 2018-19 | AI22: =LEFT(AH22,4) -> 2018 | AJ22: =-('Aggregates (% GDP) Oct24'!M75-'Aggregates (% GDP) Oct24'!M74) -> -0.22729184
I23: 2019-20 | J23: =LEFT(I23,4) -> 2019 | K23: 85.2 | L23: 77.1 | M23: 74.576335 | N23: 67.191349 | P23: =K23-K22 -> 4.9 | Q23: =L23-L22 -> 4.8 | R23: =M23-M22 -> 7.5939601 | S23: =N23-N22 -> 8.2859278 | AA23: ='Aggregates (% GDP) Oct24'!B76 -> 2019-20 | AB23: =LEFT(AA23,4) -> 2019 | AC23: ='Aggregates (% GDP) Oct24'!F76 -> 1.8937327 | AD23: ='Aggregates (% GDP) Mar24'!F76 -> 1.8960049 | AE23: =AVERAGE($AD$8:$AD$27) -> 2.145275 | AH23: ='Aggregates (% GDP) Oct24'!B76 -> 2019-20 | AI23: =LEFT(AH23,4) -> 2019 | AJ23: =-('Aggregates (% GDP) Oct24'!M76-'Aggregates (% GDP) Oct24'!M75) -> 1.0124527
I24: 2020-21 | J24: =LEFT(I24,4) -> 2020 | K24: 96.5 | L24: 86.5 | M24: 83.079863 | N24: 73.560623 | P24: =K24-K23 -> 11.3 | Q24: =L24-L23 -> 9.4 | R24: =M24-M23 -> 8.5035288 | S24: =N24-N23 -> 6.3692739 | AA24: ='Aggregates (% GDP) Oct24'!B77 -> 2020-21 | AB24: =LEFT(AA24,4) -> 2020 | AC24: ='Aggregates (% GDP) Oct24'!F77 -> 3.4413002 | AD24: ='Aggregates (% GDP) Mar24'!F77 -> 3.4519952 | AE24: =AVERAGE($AD$8:$AD$27) -> 2.145275 | AH24: ='Aggregates (% GDP) Oct24'!B77 -> 2020-21 | AI24: =LEFT(AH24,4) -> 2020 | AJ24: =-('Aggregates (% GDP) Oct24'!M77-'Aggregates (% GDP) Oct24'!M76) -> 12.342741
I25: 2021-22 | J25: =LEFT(I25,4) -> 2021 | K25: 96.6 | L25: 83.2 | M25: 80.629863 | N25: 67.135032 | P25: =K25-K24 -> 0.1 | Q25: =L25-L24 -> -3.3 | R25: =M25-M24 -> -2.4500005 | S25: =N25-N24 -> -6.4255903 | AA25: ='Aggregates (% GDP) Oct24'!B78 -> 2021-22 | AB25: =LEFT(AA25,4) -> 2021 | AC25: ='Aggregates (% GDP) Oct24'!F78 -> 2.2556225 | AD25: ='Aggregates (% GDP) Mar24'!F78 -> 2.3021101 | AE25: =AVERAGE($AD$8:$AD$27) -> 2.145275 | AH25: ='Aggregates (% GDP) Oct24'!B78 -> 2021-22 | AI25: =LEFT(AH25,4) -> 2021 | AJ25: =-('Aggregates (% GDP) Oct24'!M78-'Aggregates (% GDP) Oct24'!M77) -> -10.050778
I26: 2022-23 | J26: =LEFT(I26,4) -> 2022 | K26: 95.7 | L26: 84.8 | M26: 81.31136 | N26: 69.332774 | P26: =K26-K25 -> -0.9 | Q26: =L26-L25 -> 1.6 | R26: =M26-M25 -> 0.68149667 | S26: =N26-N25 -> 2.1977416 | AA26: ='Aggregates (% GDP) Oct24'!B79 -> 2022-23 | AB26: =LEFT(AA26,4) -> 2022 | AC26: ='Aggregates (% GDP) Oct24'!F79 -> 1.79943 | AD26: ='Aggregates (% GDP) Mar24'!F79 -> 1.7982158 | AE26: =AVERAGE($AD$8:$AD$27) -> 2.145275 | AH26: ='Aggregates (% GDP) Oct24'!B79 -> 2022-23 | AI26: =LEFT(AH26,4) -> 2022 | AJ26: =-('Aggregates (% GDP) Oct24'!M79-'Aggregates (% GDP) Oct24'!M78) -> -2.0594822
I27: 2023-24 | J27: =LEFT(I27,4) -> 2023 | K27: 97.810368 | L27: 88.853958 | M27: 82.794795 | N27: 69.878037 | P27: =K27-K26 -> 2.1103679 | Q27: =L27-L26 -> 4.0539585 | R27: =M27-M26 -> 1.4834357 | S27: =N27-N26 -> 0.54526299 | AA27: ='Aggregates (% GDP) Oct24'!B80 -> 2023-24 | AB27: =LEFT(AA27,4) -> 2023 | AC27: ='Aggregates (% GDP) Oct24'!F80 -> 2.5565458 | AD27: ='Aggregates (% GDP) Mar24'!F80 -> 2.6051807 | AE27: =AVERAGE($AD$8:$AD$27) -> 2.145275 | AH27: ='Aggregates (% GDP) Oct24'!B80 -> 2023-24 | AI27: =LEFT(AH27,4) -> 2023 | AJ27: =-('Aggregates (% GDP) Oct24'!M80-'Aggregates (% GDP) Oct24'!M79) -> -0.20463319
I28: 2024-25 | J28: =LEFT(I28,4) -> 2024 | K28: 98.395587 | L28: 91.752913 | M28: 83.54479 | N28: 69.572316 | P28: =K28-K27 -> 0.58521875 | Q28: =L28-L27 -> 2.8989543 | R28: =M28-M27 -> 0.74999443 | S28: =N28-N27 -> -0.30572066 | AA28: ='Aggregates (% GDP) Oct24'!B81 -> 2024-25 | AB28: =LEFT(AA28,4) -> 2024 | AC28: ='Aggregates (% GDP) Oct24'!F81 -> 2.5585174 | AD28: ='Aggregates (% GDP) Mar24'!F81 -> 2.3896524 | AE28: =AVERAGE($AD$8:$AD$27) -> 2.145275 | AH28: ='Aggregates (% GDP) Oct24'!B81 -> 2024-25 | AI28: =LEFT(AH28,4) -> 2024 | AJ28: =-('Aggregates (% GDP) Oct24'!M81-'Aggregates (% GDP) Oct24'!M80) -> -0.18733025 | AK28: =-('Aggregates (% GDP) Mar24'!N81-'Aggregates (% GDP) Mar24'!N80) -> -1.1415503
I29: 2025-26 | J29: =LEFT(I29,4) -> 2025 | K29: 96.921744 | L29: 93.140493 | M29: 83.791436 | N29: 69.261948 | P29: =K29-K28 -> -1.4738427 | Q29: =L29-L28 -> 1.3875805 | R29: =M29-M28 -> 0.24664648 | S29: =N29-N28 -> -0.31036835 | AA29: ='Aggregates (% GDP) Oct24'!B82 -> 2025-26 | AB29: =LEFT(AA29,4) -> 2025 | AC29: ='Aggregates (% GDP) Oct24'!F82 -> 2.6919811 | AD29: ='Aggregates (% GDP) Mar24'!F82 -> 2.1199635 | AE29: =AVERAGE($AD$8:$AD$27) -> 2.145275 | AH29: ='Aggregates (% GDP) Oct24'!B82 -> 2025-26 | AI29: =LEFT(AH29,4) -> 2025 | AJ29: =-('Aggregates (% GDP) Oct24'!M82-'Aggregates (% GDP) Oct24'!M81) -> -0.76306604 | AK29: =-('Aggregates (% GDP) Mar24'!N82-'Aggregates (% GDP) Mar24'!N81) -> -0.57313333
I30: 2026-27 | J30: =LEFT(I30,4) -> 2026 | K30: 96.966301 | L30: 94.384386 | M30: 84.227751 | N30: 69.189137 | P30: =K30-K29 -> 0.044556571 | Q30: =L30-L29 -> 1.2438926 | R30: =M30-M29 -> 0.43631488 | S30: =N30-N29 -> -0.072811329 | AA30: ='Aggregates (% GDP) Oct24'!B83 -> 2026-27 | AB30: =LEFT(AA30,4) -> 2026 | AC30: ='Aggregates (% GDP) Oct24'!F83 -> 2.7207402 | AD30: ='Aggregates (% GDP) Mar24'!F83 -> 1.9804928 | AE30: =AVERAGE($AD$8:$AD$27) -> 2.145275 | AH30: ='Aggregates (% GDP) Oct24'!B83 -> 2026-27 | AI30: =LEFT(AH30,4) -> 2026 | AJ30: =-('Aggregates (% GDP) Oct24'!M83-'Aggregates (% GDP) Oct24'!M82) -> -0.52998375 | AK30: =-('Aggregates (% GDP) Mar24'!N83-'Aggregates (% GDP) Mar24'!N82) -> -0.3785978
I31: 2027-28 | J31: =LEFT(I31,4) -> 2027 | K31: 97.245969 | L31: 95.054134 | M31: 84.100989 | N31: 68.709184 | P31: =K31-K30 -> 0.27966853 | Q31: =L31-L30 -> 0.66974783 | R31: =M31-M30 -> -0.12676194 | S31: =N31-N30 -> -0.47995311 | AA31: ='Aggregates (% GDP) Oct24'!B84 -> 2027-28 | AB31: =LEFT(AA31,4) -> 2027 | AC31: ='Aggregates (% GDP) Oct24'!F84 -> 2.6234059 | AD31: ='Aggregates (% GDP) Mar24'!F84 -> 1.8204393 | AE31: =AVERAGE($AD$8:$AD$27) -> 2.145275 | AH31: ='Aggregates (% GDP) Oct24'!B84 -> 2027-28 | AI31: =LEFT(AH31,4) -> 2027 | AJ31: =-('Aggregates (% GDP) Oct24'!M84-'Aggregates (% GDP) Oct24'!M83) -> -0.69853767 | AK31: =-('Aggregates (% GDP) Mar24'!N84-'Aggregates (% GDP) Mar24'!N83) -> -0.60360284
I32: 2028-29 | J32: =LEFT(I32,4) -> 2028 | K32: 97.339932 | L32: 95.607594 | M32: 83.872927 | N32: 68.377937 | P32: =K32-K31 -> 0.093962633 | Q32: =L32-L31 -> 0.55346059 | R32: =M32-M31 -> -0.22806211 | S32: =N32-N31 -> -0.33124701 | AA32: ='Aggregates (% GDP) Oct24'!B85 -> 2028-29 | AB32: =LEFT(AA32,4) -> 2028 | AC32: ='Aggregates (% GDP) Oct24'!F85 -> 2.4777518 | AD32: ='Aggregates (% GDP) Mar24'!F85 -> 1.6542068 | AE32: =AVERAGE($AD$8:$AD$27) -> 2.145275 | AH32: ='Aggregates (% GDP) Oct24'!B85 -> 2028-29 | AI32: =LEFT(AH32,4) -> 2028 | AJ32: =-('Aggregates (% GDP) Oct24'!M85-'Aggregates (% GDP) Oct24'!M84) -> -0.21076074 | AK32: =-('Aggregates (% GDP) Mar24'!N85-'Aggregates (% GDP) Mar24'!N84) -> -0.43227169
I33: 2029-30 | J33: =LEFT(I33,4) -> 2029 | K33: 97.147985 | L33: 95.774656 | M33: 83.417751 | N33: 67.888123 | P33: =K33-K32 -> -0.19194677 | Q33: =L33-L32 -> 0.1670617 | R33: =M33-M32 -> -0.45517556 | S33: =N33-N32 -> -0.48981329 | AA33: ='Aggregates (% GDP) Oct24'!B86 -> 2029-30 | AB33: =LEFT(AA33,4) -> 2029 | AC33: ='Aggregates (% GDP) Oct24'!F86 -> 2.3699287 | AE33: =AVERAGE($AD$8:$AD$27) -> 2.145275 | AH33: ='Aggregates (% GDP) Oct24'!B86 -> 2029-30 | AI33: =LEFT(AH33,4) -> 2029 | AJ33: =-('Aggregates (% GDP) Oct24'!M86-'Aggregates (% GDP) Oct24'!M85) -> -0.18679438
I36: 23-24 | K36: 97.6 | L36: 88.8 | M36: 82.9 | N36: 69.5
I37: 24-25 | K37: 98.8 | L37: 91.7 | M37: 83.6 | N37: 70.2
I38: 25-26 | K38: 96.4 | L38: 92.8 | M38: 83.2 | N38: 69.5
I39: 26-27 | K39: 95.5 | L39: 93.2 | M39: 82.1 | N39: 67.9
I40: 27-28 | K40: 95.1 | L40: 93.2 | M40: 80.6 | N40: 66
I41: 28-29 | K41: 94.3 | L41: 92.9 | M41: 78.7 | N41: 63.9

Sheet GMW
A1: Location | B1: Indicator | C1: Scenario | D1: Units | E1: Scale | F1: Measurement | G1: 1980 Q1 | H1: 1980 Q2 | I1: 1980 Q3 | J1: 1980 Q4 | K1: 1981 Q1 | L1: 1981 Q2 | M1: 1981 Q3 | N1: 1981 Q4 | O1: 1982 Q1 | P1: 1982 Q2 | Q1: 1982 Q3 | R1: 1982 Q4 | S1: 1983 Q1 | T1: 1983 Q2 | U1: 1983 Q3 | V1: 1983 Q4 | W1: 1984 Q1 | X1: 1984 Q2 | Y1: 1984 Q3 | Z1: 1984 Q4 | AA1: 1985 Q1 | AB1: 1985 Q2 | AC1: 1985 Q3 | AD1: 1985 Q4 | AE1: 1986 Q1 | AF1: 1986 Q2 | AG1: 1986 Q3 | AH1: 1986 Q4 | AI1: 1987 Q1 | AJ1: 1987 Q2 | AK1: 1987 Q3 | AL1: 1987 Q4 | AM1: 1988 Q1 | AN1: 1988 Q2 | AO1: 1988 Q3 | AP1: 1988 Q4 | AQ1: 1989 Q1 | AR1: 1989 Q2 | AS1: 1989 Q3 | AT1: 1989 Q4 | AU1: 1990 Q1 | AV1: 1990 Q2 | AW1: 1990 Q3 | AX1: 1990 Q4 | AY1: 1991 Q1 | AZ1: 1991 Q2 | BA1: 1991 Q3 | BB1: 1991 Q4 | BC1: 1992 Q1 | BD1: 1992 Q2 | BE1: 1992 Q3 | BF1: 1992 Q4 | BG1: 1993 Q1 | BH1: 1993 Q2 | BI1: 1993 Q3 | BJ1: 1993 Q4 | BK1: 1994 Q1 | BL1: 1994 Q2 | BM1: 1994 Q3 | BN1: 1994 Q4 | BO1: 1995 Q1 | BP1: 1995 Q2 | BQ1: 1995 Q3 | BR1: 1995 Q4 | BS1: 1996 Q1 | BT1: 1996 Q2 | BU1: 1996 Q3 | BV1: 1996 Q4 | BW1: 1997 Q1 | BX1: 1997 Q2 | BY1: 1997 Q3 | BZ1: 1997 Q4 | CA1: 1998 Q1 | CB1: 1998 Q2 | CC1: 1998 Q3 | CD1: 1998 Q4 | CE1: 1999 Q1 | CF1: 1999 Q2 | CG1: 1999 Q3 | CH1: 1999 Q4 | CI1: 2000 Q1 | CJ1: 2000 Q2 | CK1: 2000 Q3 | CL1: 2000 Q4 | CM1: 2001 Q1 | CN1: 2001 Q2 | CO1: 2001 Q3 | CP1: 2001 Q4 | CQ1: 2002 Q1 | CR1: 2002 Q2 | CS1: 2002 Q3 | CT1: 2002 Q4 | CU1: 2003 Q1 | CV1: 2003 Q2 | CW1: 2003 Q3 | CX1: 2003 Q4 | CY1: 2004 Q1 | CZ1: 2004 Q2 | DA1: 2004 Q3 | DB1: 2004 Q4 | DC1: 2005 Q1 | DD1: 2005 Q2 | DE1: 2005 Q3 | DF1: 2005 Q4 | DG1: 2006 Q1 | DH1: 2006 Q2 | DI1: 2006 Q3 | DJ1: 2006 Q4 | DK1: 2007 Q1 | DL1: 2007 Q2 | DM1: 2007 Q3 | DN1: 2007 Q4 | DO1: 2008 Q1 | DP1: 2008 Q2 | DQ1: 2008 Q3 | DR1: 2008 Q4 | DS1: 2009 Q1 | DT1: 2009 Q2 | DU1: 2009 Q3 | DV1: 2009 Q4 | DW1: 2010 Q1 | DX1: 2010 Q2 | DY1: 2010 Q3 | DZ1: 2010 Q4 | EA1: 2011 Q1 | EB1: 2011 Q2 | EC1: 2011 Q3 | ED1: 2011 Q4 | EE1: 2012 Q1 | EF1: 2012 Q2 | EG1: 2012 Q3 | EH1: 2012 Q4 | EI1: 2013 Q1 | EJ1: 2013 Q2 | EK1: 2013 Q3 | EL1: 2013 Q4 | EM1: 2014 Q1 | EN1: 2014 Q2 | EO1: 2014 Q3 | EP1: 2014 Q4 | EQ1: 2015 Q1 | ER1: 2015 Q2 | ES1: 2015 Q3 | ET1: 2015 Q4 | EU1: 2016 Q1 | EV1: 2016 Q2 | EW1: 2016 Q3 | EX1: 2016 Q4 | EY1: 2017 Q1 | EZ1: 2017 Q2 | FA1: 2017 Q3 | FB1: 2017 Q4 | FC1: 2018 Q1 | FD1: 2018 Q2 | FE1: 2018 Q3 | FF1: 2018 Q4 | FG1: 2019 Q1 | FH1: 2019 Q2 | FI1: 2019 Q3 | FJ1: 2019 Q4 | FK1: 2020 Q1 | FL1: 2020 Q2 | FM1: 2020 Q3 | FN1: 2020 Q4 | FO1: 2021 Q1 | FP1: 2021 Q2 | FQ1: 2021 Q3 | FR1: 2021 Q4 | FS1: 2022 Q1 | FT1: 2022 Q2 | FU1: 2022 Q3 | FV1: 2022 Q4 | FW1: 2023 Q1 | FX1: 2023 Q2 | FY1: 2023 Q3 | FZ1: 2023 Q4 | GA1: 2024 Q1 | GB1: 2024 Q2 | GC1: 2024 Q3 | GD1: 2024 Q4 | GE1: 2025 Q1 | GF1: 2025 Q2 | GG1: 2025 Q3 | GH1: 2025 Q4 | GI1: 2026 Q1 | GJ1: 2026 Q2 | GK1: 2026 Q3 | GL1: 2026 Q4 | GM1: 2027 Q1 | GN1: 2027 Q2 | GO1: 2027 Q3 | GP1: 2027 Q4 | GQ1: 2028 Q1 | GR1: 2028 Q2 | GS1: 2028 Q3 | GT1: 2028 Q4 | GU1: 2029 Q1 | GV1: 2029 Q2 | GW1: 2029 Q3 | GX1: 2029 Q4 | GY1: 2030 Q1 | GZ1: 2030 Q2 | HA1: 2030 Q3 | HB1: 2030 Q4 | HC1: Source | HD1: Seasonally adjusted | HE1: Base year price | HF1: Base year index | HG1: Historical end year | HH1: Historical end quarter | HI1: Date of last update | HJ1: Source details | HK1: Additional source details | HL1: Location code | HM1: Indicator code | HN1: Databank code
A2: United Kingdom | B2: Tax revenue, employer social security contributions, LCU | C2: Oct24_2 | D2: Pound | E2: Millions | F2: Level | G2: 2203.656 | H2: 2273.364 | I2: 2332.952 | J2: 2420.649 | K2: 2498.227 | L2: 2399.287 | M2: 2452.13 | N2: 2560.064 | O2: 2665.75 | P2: 2569.059 | Q2: 2582.55 | R2: 2688.236 | S2: 2872.623 | T2: 2925.466 | U2: 2987.303 | V2: 3060.384 | W2: 3088.492 | X2: 3128.967 | Y2: 3185.183 | Z2: 3267.258 | AA2: 3359.452 | AB2: 3403.3 | AC2: 3447.148 | AD2: 3557.331 | AE2: 3637.157 | AF2: 3792.313 | AG2: 3863.145 | AH2: 3930.603 | AI2: 4305 | AJ2: 4334 | AK2: 4487 | AL2: 4632 | AM2: 4640 | AN2: 4879 | AO2: 5040 | AP2: 5234 | AQ2: 5239 | AR2: 5247 | AS2: 5405 | AT2: 5609 | AU2: 5594 | AV2: 5782 | AW2: 5930 | AX2: 6012 | AY2: 5974 | AZ2: 6126 | BA2: 6125 | BB2: 6492 | BC2: 6453 | BD2: 6234 | BE2: 6198 | BF2: 6517 | BG2: 6477 | BH2: 6646 | BI2: 6727 | BJ2: 6997 | BK2: 6841 | BL2: 6602 | BM2: 6704 | BN2: 6891 | BO2: 6872 | BP2: 6901 | BQ2: 6999 | BR2: 7120 | BS2: 7100 | BT2: 7308 | BU2: 7377 | BV2: 7428 | BW2: 7219 | BX2: 7704 | BY2: 8050 | BZ2: 8065 | CA2: 7887 | CB2: 8048 | CC2: 8448 | CD2: 8468 | CE2: 8757 | CF2: 8818 | CG2: 9094 | CH2: 9184 | CI2: 9313 | CJ2: 9861 | CK2: 9826 | CL2: 10195 | CM2: 10811 | CN2: 9870 | CO2: 10189 | CP2: 10298 | CQ2: 10629 | CR2: 10379 | CS2: 10146 | CT2: 10703 | CU2: 10366 | CV2: 11989 | CW2: 12409 | CX2: 12408 | CY2: 12662 | CZ2: 12920 | DA2: 13279 | DB2: 13669 | DC2: 13668 | DD2: 14205 | DE2: 14681 | DF2: 14643 | DG2: 14713 | DH2: 14863 | DI2: 15292 | DJ2: 15652 | DK2: 15661 | DL2: 16295 | DM2: 16680 | DN2: 17084 | DO2: 17891 | DP2: 17172 | DQ2: 17328 | DR2: 17305 | DS2: 16825 | DT2: 17195 | DU2: 17157 | DV2: 17618 | DW2: 18831 | DX2: 17422 | DY2: 17548 | DZ2: 17762 | EA2: 18475 | EB2: 18242 | EC2: 18350 | ED2: 18382 | EE2: 18603 | EF2: 19029 | EG2: 19095 | EH2: 18982 | EI2: 18597 | EJ2: 19598 | EK2: 19195 | EL2: 19482 | EM2: 19571 | EN2: 19575 | EO2: 19825 | EP2: 19993 | EQ2: 20426 | ER2: 20839 | ES2: 20846 | ET2: 21129 | EU2: 20549 | EV2: 22462 | EW2: 22802 | EX2: 23011 | EY2: 23425 | EZ2: 23645 | FA2: 23594 | FB2: 23997 | FC2: 24296 | FD2: 24403 | FE2: 24535 | FF2: 24830 | FG2: 25806 | FH2: 26406 | FI2: 27085 | FJ2: 27639 | FK2: 27453 | FL2: 27064 | FM2: 27978 | FN2: 28812 | FO2: 28828 | FP2: 29940 | FQ2: 30764 | FR2: 31560 | FS2: 32437 | FT2: 35271 | FU2: 35446 | FV2: 34778 | FW2: 34923 | FX2: 35305 | FY2: 35835 | FZ2: 37193 | GA2: 38998 | GB2: 37308 | GC2: 38127.7 | GD2: 38385.24 | GE2: 38842.31 | GF2: 39239.57 | GG2: 39638.7 | GH2: 40042.66 | GI2: 40448.05 | GJ2: 40902.63 | GK2: 41359.82 | GL2: 41814.05 | GM2: 42274.95 | GN2: 42725.16 | GO2: 43178.24 | GP2: 43638.85 | GQ2: 44019.07 | GR2: 44443.03 | GS2: 44874.24 | GT2: 45316.12 | GU2: 45756.86 | GV2: 46168.63 | GW2: 46582.28 | GX2: 47000.28 | GY2: 47418.72 | GZ2: 47843.01 | HA2: 48273.44 | HB2: 48708.08 | HC2: Office for National Statistics\Haver Analytics | HD2: TRUE | HE2: NA | HF2: NA | HG2: 2024 | HH2: 2 | HI2: NA | HJ2: RNFSQ@UK | HK2: UK: IA: CG: Resources: Employers' Social Contributions (SA, Mil.GBP) | HL2: GBR | HM2: TP | HN2: Oct24_2.db
A3: United Kingdom | B3: GDP, real, LCU | C3: Oct24_2 | D3: Pound | E3: Millions | F3: Level | G3: 269776 | H3: 264448 | I3: 264139 | J3: 261297 | K3: 261131 | L3: 261739 | M3: 264602 | N3: 264902 | O3: 265408 | P3: 268196 | Q3: 268798 | R3: 270653 | S3: 275877 | T3: 277790 | U3: 280996 | V3: 283096 | W3: 285469 | X3: 282605 | Y3: 284676 | Z3: 289829 | AA3: 292612 | AB3: 298873 | AC3: 298814 | AD3: 298979 | AE3: 302117 | AF3: 304797 | AG3: 306708 | AH3: 312615 | AI3: 314804 | AJ3: 319478 | AK3: 327346 | AL3: 331075 | AM3: 336442 | AN3: 338186 | AO3: 342414 | AP3: 345162 | AQ3: 346836 | AR3: 348997 | AS3: 349572 | AT3: 349523 | AU3: 351299 | AV3: 353663 | AW3: 349780 | AX3: 348006 | AY3: 346292 | AZ3: 345892 | BA3: 345216 | BB3: 345643 | BC3: 345523 | BD3: 344987 | BE3: 346628 | BF3: 349299 | BG3: 351046 | BH3: 352612 | BI3: 355841 | BJ3: 358264 | BK3: 361793 | BL3: 365109 | BM3: 368798 | BN3: 370401 | BO3: 372307 | BP3: 373090 | BQ3: 377249 | BR3: 378442 | BS3: 380976 | BT3: 382146 | BU3: 385671 | BV3: 391053 | BW3: 397303 | BX3: 401790 | BY3: 405233 | BZ3: 411352 | CA3: 414377 | CB3: 416909 | CC3: 418294 | CD3: 421074 | CE3: 423875 | CF3: 425920 | CG3: 432860 | CH3: 439093 | CI3: 444540 | CJ3: 447825 | CK3: 450688 | CL3: 453447 | CM3: 457680 | CN3: 459620 | CO3: 462016 | CP3: 463404 | CQ3: 464698 | CR3: 466935 | CS3: 470277 | CT3: 473899 | CU3: 477357 | CV3: 481552 | CW3: 485973 | CX3: 490059 | CY3: 492014 | CZ3: 494824 | DA3: 496642 | DB3: 499020 | DC3: 502702 | DD3: 506906 | DE3: 511132 | DF3: 515935 | DG3: 518495 | DH3: 520318 | DI3: 521780 | DJ3: 524569 | DK3: 529398 | DL3: 533187 | DM3: 537052 | DN3: 540258 | DO3: 542804 | DP3: 539918 | DQ3: 531619 | DR3: 520230 | DS3: 509646 | DT3: 508009 | DU3: 508398 | DV3: 509889 | DW3: 514595 | DX3: 520128 | DY3: 523173 | DZ3: 523515 | EA3: 524955 | EB3: 525418 | EC3: 527034 | ED3: 527698 | EE3: 532300 | EF3: 531663 | EG3: 536720 | EH3: 536188 | EI3: 537974 | EJ3: 541586 | EK3: 546064 | EL3: 549709 | EM3: 554183 | EN3: 559331 | EO3: 563694 | EP3: 567619 | EQ3: 569150 | ER3: 572673 | ES3: 574836 | ET3: 578068 | EU3: 580110 | EV3: 583383 | EW3: 585856 | EX3: 589476 | EY3: 594423 | EZ3: 598176 | FA3: 601961 | FB3: 606396 | FC3: 606785 | FD3: 607775 | FE3: 609653 | FF3: 610481 | FG3: 614936 | FH3: 616853 | FI3: 621227 | FJ3: 621229 | FK3: 604719 | FL3: 481769 | FM3: 562648 | FN3: 570338 | FO3: 564411 | FP3: 605353 | FQ3: 615459 | FR3: 624592 | FS3: 629149 | FT3: 631258 | FU3: 631977 | FV3: 634044 | FW3: 634612 | FX3: 634624 | FY3: 633956 | FZ3: 631825 | GA3: 636222 | GB3: 639095 | GC3: 640741.9 | GD3: 643868.9 | GE3: 646136.9 | GF3: 648529.7 | GG3: 650983.9 | GH3: 653549.4 | GI3: 656294.3 | GJ3: 659051.3 | GK3: 661754 | GL3: 664499.8 | GM3: 667225.6 | GN3: 669961.6 | GO3: 672674.9 | GP3: 675499.9 | GQ3: 678268.4 | GR3: 681049.5 | GS3: 683773.6 | GT3: 686508.3 | GU3: 689254.8 | GV3: 692011.6 | GW3: 694780.4 | GX3: 697559.3 | GY3: 700349.6 | GZ3: 703151.1 | HA3: 705964.2 | HB3: 708788.1 | HC3: Office for National Statistics\Haver Analytics | HD3: TRUE | HE3: chained 2022 | HF3: NA | HG3: 2024 | HH3: 2 | HI3: NA | HJ3: ABMIQ@UK | HK3: U.K.: Real Gross Domestic Product (SA, Mil.Chn.2022.GBP) | HL3: GBR | HM3: GDP | HN3: Oct24_2.db
A4: United Kingdom | B4: Employment, aged 16 and over, ILO definition | C4: Oct24_2 | D4: Person | E4: Thousands | F4: Level | G4: 25250 | H4: 25190 | I4: 25050 | J4: 24855 | K4: 24661 | L4: 24495 | M4: 24355 | N4: 24209 | O4: 24120 | P4: 24027 | Q4: 23901 | R4: 23755 | S4: 23651 | T4: 23647 | U4: 23809 | V4: 23994 | W4: 24125 | X4: 24245 | Y4: 24335 | Z4: 24435 | AA4: 24515 | AB4: 24570 | AC4: 24625 | AD4: 24660 | AE4: 24670 | AF4: 24695 | AG4: 24770 | AH4: 24850 | AI4: 24925 | AJ4: 25110 | AK4: 25345 | AL4: 25575 | AM4: 25795 | AN4: 25970 | AO4: 26160 | AP4: 26355 | AQ4: 26590 | AR4: 26730 | AS4: 26795 | AT4: 26880 | AU4: 26900 | AV4: 26935 | AW4: 26900 | AX4: 26750 | AY4: 26530 | AZ4: 26275 | BA4: 26025 | BB4: 25820 | BC4: 25710 | BD4: 25605 | BE4: 25509 | BF4: 25336 | BG4: 25282 | BH4: 25293 | BI4: 25316 | BJ4: 25320 | BK4: 25408 | BL4: 25451 | BM4: 25559 | BN4: 25600 | BO4: 25670 | BP4: 25770 | BQ4: 25852 | BR4: 25982 | BS4: 25970 | BT4: 26009 | BU4: 26062 | BV4: 26198 | BW4: 26381 | BX4: 26514 | BY4: 26572 | BZ4: 26636 | CA4: 26677 | CB4: 26714 | CC4: 26834 | CD4: 26955 | CE4: 27036 | CF4: 27095 | CG4: 27218 | CH4: 27322 | CI4: 27362 | CJ4: 27468 | CK4: 27555 | CL4: 27549 | CM4: 27623 | CN4: 27707 | CO4: 27715 | CP4: 27803 | CQ4: 27797 | CR4: 27933 | CS4: 27935 | CT4: 28110 | CU4: 28099 | CV4: 28226 | CW4: 28256 | CX4: 28304 | CY4: 28459 | CZ4: 28470 | DA4: 28518 | DB4: 28673 | DC4: 28789 | DD4: 28802 | DE4: 28928 | DF4: 28880 | DG4: 29048 | DH4: 29106 | DI4: 29183 | DJ4: 29214 | DK4: 29194 | DL4: 29322 | DM4: 29420 | DN4: 29576 | DO4: 29684 | DP4: 29722 | DQ4: 29580 | DR4: 29528 | DS4: 29366 | DT4: 29087 | DU4: 29069 | DV4: 29102 | DW4: 29013 | DX4: 29192 | DY4: 29385 | DZ4: 29324 | EA4: 29441 | EB4: 29447 | EC4: 29283 | ED4: 29349 | EE4: 29464 | EF4: 29681 | EG4: 29778 | EH4: 29932 | EI4: 29869 | EJ4: 29974 | EK4: 30144 | EL4: 30330 | EM4: 30573 | EN4: 30747 | EO4: 30873 | EP4: 30981 | EQ4: 31188 | ER4: 31140 | ES4: 31361 | ET4: 31569 | EU4: 31603 | EV4: 31778 | EW4: 31843 | EX4: 31877 | EY4: 31978 | EZ4: 32098 | FA4: 32093 | FB4: 32179 | FC4: 32364 | FD4: 32403 | FE4: 32448 | FF4: 32618 | FG4: 32721 | FH4: 32839 | FI4: 32779 | FJ4: 32954 | FK4: 33000 | FL4: 32571 | FM4: 32354 | FN4: 32198 | FO4: 32221 | FP4: 32377 | FQ4: 32687 | FR4: 32686 | FS4: 32775 | FT4: 32958 | FU4: 32916 | FV4: 33067 | FW4: 33201 | FX4: 33163 | FY4: 33102 | FZ4: 33174 | GA4: 32997 | GB4: 33094 | GC4: 33306.91 | GD4: 33156.91 | GE4: 33260.84 | GF4: 33375.05 | GG4: 33484.89 | GH4: 33600.57 | GI4: 33714.82 | GJ4: 33826.11 | GK4: 33927.58 | GL4: 34027.66 | GM4: 34126.33 | GN4: 34225.34 | GO4: 34322.92 | GP4: 34425.94 | GQ4: 34525.75 | GR4: 34625.88 | GS4: 34718.88 | GT4: 34809.08 | GU4: 34896.14 | GV4: 34979.91 | GW4: 35060.37 | GX4: 35141.01 | GY4: 35218.32 | GZ4: 35295.8 | HA4: 35373.45 | HB4: 35451.27 | HC4: Office for National Statistics\Haver Analytics | HD4: TRUE | HE4: NA | HF4: NA | HG4: 2024 | HH4: 2 | HI4: NA | HJ4: MGRZQ@UK | HK4: UK: LFS: Employment: Aged 16 and Over (SA, Thous) | HL4: GBR | HM4: ETILO | HN4: Oct24_2.db
A5: United Kingdom | B5: Unemployment rate, ILO definition | C5: Oct24_2 | D5: % | E5: NA | F5: Level | G5: 5.8 | H5: 6.3 | I5: 7.1 | J5: 8 | K5: 8.9 | L5: 9.6 | M5: 9.9 | N5: 10.2 | O5: 10.4 | P5: 10.6 | Q5: 10.8 | R5: 11.1 | S5: 11.3 | T5: 11.4 | U5: 11.5 | V5: 11.7 | W5: 11.8 | X5: 11.9 | Y5: 11.7 | Z5: 11.6 | AA5: 11.5 | AB5: 11.4 | AC5: 11.3 | AD5: 11.3 | AE5: 11.3 | AF5: 11.3 | AG5: 11.4 | AH5: 11.3 | AI5: 11.1 | AJ5: 10.7 | AK5: 10.2 | AL5: 9.7 | AM5: 9.2 | AN5: 8.7 | AO5: 8.4 | AP5: 8 | AQ5: 7.6 | AR5: 7.2 | AS5: 7.1 | AT5: 7 | AU5: 6.9 | AV5: 6.9 | AW5: 7.1 | AX5: 7.5 | AY5: 8 | AZ5: 8.7 | BA5: 9.2 | BB5: 9.5 | BC5: 9.7 | BD5: 9.8 | BE5: 9.9 | BF5: 10.4 | BG5: 10.6 | BH5: 10.4 | BI5: 10.2 | BJ5: 10.3 | BK5: 9.9 | BL5: 9.7 | BM5: 9.4 | BN5: 9 | BO5: 8.9 | BP5: 8.7 | BQ5: 8.6 | BR5: 8.3 | BS5: 8.2 | BT5: 8.3 | BU5: 8.1 | BV5: 7.8 | BW5: 7.3 | BX5: 7.2 | BY5: 6.8 | BZ5: 6.5 | CA5: 6.4 | CB5: 6.3 | CC5: 6.2 | CD5: 6.1 | CE5: 6.2 | CF5: 6 | CG5: 5.9 | CH5: 5.8 | CI5: 5.8 | CJ5: 5.5 | CK5: 5.3 | CL5: 5.2 | CM5: 5.1 | CN5: 5 | CO5: 5.1 | CP5: 5.2 | CQ5: 5.2 | CR5: 5.2 | CS5: 5.3 | CT5: 5.1 | CU5: 5.2 | CV5: 4.9 | CW5: 5 | CX5: 4.9 | CY5: 4.8 | CZ5: 4.8 | DA5: 4.7 | DB5: 4.7 | DC5: 4.7 | DD5: 4.8 | DE5: 4.7 | DF5: 5.1 | DG5: 5.2 | DH5: 5.5 | DI5: 5.5 | DJ5: 5.5 | DK5: 5.5 | DL5: 5.4 | DM5: 5.3 | DN5: 5.2 | DO5: 5.2 | DP5: 5.4 | DQ5: 5.9 | DR5: 6.4 | DS5: 7.1 | DT5: 7.8 | DU5: 7.8 | DV5: 7.8 | DW5: 8 | DX5: 7.9 | DY5: 7.8 | DZ5: 7.9 | EA5: 7.8 | EB5: 7.9 | EC5: 8.3 | ED5: 8.4 | EE5: 8.2 | EF5: 8 | EG5: 7.9 | EH5: 7.8 | EI5: 7.9 | EJ5: 7.8 | EK5: 7.6 | EL5: 7.2 | EM5: 6.8 | EN5: 6.3 | EO5: 6 | EP5: 5.7 | EQ5: 5.6 | ER5: 5.6 | ES5: 5.4 | ET5: 5.1 | EU5: 5.1 | EV5: 5 | EW5: 4.9 | EX5: 4.8 | EY5: 4.6 | EZ5: 4.5 | FA5: 4.3 | FB5: 4.4 | FC5: 4.3 | FD5: 4.1 | FE5: 4.2 | FF5: 4.1 | FG5: 3.9 | FH5: 4 | FI5: 3.9 | FJ5: 3.9 | FK5: 4.1 | FL5: 4.2 | FM5: 5 | FN5: 5.3 | FO5: 5.1 | FP5: 4.8 | FQ5: 4.4 | FR5: 4.2 | FS5: 3.9 | FT5: 3.9 | FU5: 3.8 | FV5: 3.9 | FW5: 4 | FX5: 4.2 | FY5: 4.1 | FZ5: 3.8 | GA5: 4.3 | GB5: 4.2 | GC5: 4.243108 | GD5: 4.408679 | GE5: 4.380091 | GF5: 4.351475 | GG5: 4.322893 | GH5: 4.284726 | GI5: 4.2179 | GJ5: 4.151092 | GK5: 4.093759 | GL5: 4.045897 | GM5: 3.998046 | GN5: 3.959662 | GO5: 3.921238 | GP5: 3.882746 | GQ5: 3.844463 | GR5: 3.806106 | GS5: 3.778645 | GT5: 3.75964 | GU5: 3.749948 | GV5: 3.74987 | GW5: 3.749865 | GX5: 3.749873 | GY5: 3.749872 | GZ5: 3.749875 | HA5: 3.74988 | HB5: 3.749879 | HC5: Office for National Statistics\Haver Analytics | HD5: TRUE | HE5: NA | HF5: NA | HG5: 2024 | HH5: 2 | HI5: NA | HJ5: MGSXQ@UK | HK5: UK: LFS: Unemployment Rate: Aged 16 and Over (SA, %) | HL5: GBR | HM5: UPILO | HN5: Oct24_2.db
A6: United Kingdom | B6: Income, personal disposable, real, LCU | C6: Oct24_2 | D6: Pound | E6: Millions | F6: Level | G6: 157780 | H6: 158083 | I6: 160445 | J6: 158931 | K6: 160486 | L6: 158130 | M6: 157598 | N6: 158580 | O6: 157715 | P6: 160483 | Q6: 159367 | R6: 159886 | S6: 158854 | T6: 165111 | U6: 163522 | V6: 164202 | W6: 167088 | X6: 165111 | Y6: 169770 | Z6: 173527 | AA6: 175208 | AB6: 175613 | AC6: 175957 | AD6: 177164 | AE6: 179729 | AF6: 186661 | AG6: 183119 | AH6: 183388 | AI6: 180901 | AJ6: 185020 | AK6: 187551 | AL6: 188860 | AM6: 191709 | AN6: 194935 | AO6: 197179 | AP6: 198740 | AQ6: 201265 | AR6: 204179 | AS6: 209872 | AT6: 207949 | AU6: 213872 | AV6: 211391 | AW6: 213462 | AX6: 216821 | AY6: 218128 | AZ6: 214176 | BA6: 220568 | BB6: 220151 | BC6: 221591 | BD6: 223785 | BE6: 225633 | BF6: 225562 | BG6: 224008 | BH6: 230278 | BI6: 232470 | BJ6: 233411 | BK6: 232541 | BL6: 232173 | BM6: 236870 | BN6: 235558 | BO6: 239669 | BP6: 239943 | BQ6: 242123 | BR6: 243427 | BS6: 247598 | BT6: 247441 | BU6: 250067 | BV6: 245800 | BW6: 249558 | BX6: 251781 | BY6: 254358 | BZ6: 253468 | CA6: 253069 | CB6: 254576 | CC6: 253636 | CD6: 257028 | CE6: 254037 | CF6: 266557 | CG6: 267871 | CH6: 274118 | CI6: 274370 | CJ6: 277466 | CK6: 283106 | CL6: 287523 | CM6: 289476 | CN6: 288052 | CO6: 289545 | CP6: 295002 | CQ6: 295976 | CR6: 298538 | CS6: 297567 | CT6: 298904 | CU6: 301081 | CV6: 302934 | CW6: 304444 | CX6: 308695 | CY6: 309585 | CZ6: 312396 | DA6: 314574 | DB6: 315137 | DC6: 317057 | DD6: 320657 | DE6: 322465 | DF6: 322562 | DG6: 325138 | DH6: 323889 | DI6: 327580 | DJ6: 328682 | DK6: 339067 | DL6: 336009 | DM6: 340647 | DN6: 340314 | DO6: 335815 | DP6: 339732 | DQ6: 333684 | DR6: 340023 | DS6: 335761 | DT6: 344826 | DU6: 343613 | DV6: 346368 | DW6: 346769 | DX6: 347421 | DY6: 346091 | DZ6: 343460 | EA6: 334416 | EB6: 339976 | EC6: 339972 | ED6: 337625 | EE6: 344680 | EF6: 348062 | EG6: 346678 | EH6: 345765 | EI6: 342890 | EJ6: 350923 | EK6: 357263 | EL6: 360126 | EM6: 359009 | EN6: 359599 | EO6: 359708 | EP6: 364730 | EQ6: 372232 | ER6: 381179 | ES6: 388638 | ET6: 388470 | EU6: 386874 | EV6: 387633 | EW6: 384657 | EX6: 381981 | EY6: 382290 | EZ6: 390332 | FA6: 390954 | FB6: 391273 | FC6: 395975 | FD6: 394175 | FE6: 395431 | FF6: 400106 | FG6: 399632 | FH6: 405211 | FI6: 405428 | FJ6: 407970 | FK6: 402584 | FL6: 394596 | FM6: 406593 | FN6: 408367 | FO6: 411074 | FP6: 413832 | FQ6: 410138 | FR6: 402842 | FS6: 401738 | FT6: 398386 | FU6: 400405 | FV6: 408689 | FW6: 407362 | FX6: 412328 | FY6: 413001 | FZ6: 415159 | GA6: 420689 | GB6: 426221 | GC6: 427151.4 | GD6: 427205.6 | GE6: 429422.1 | GF6: 431072.3 | GG6: 432818.3 | GH6: 434694.7 | GI6: 436515.1 | GJ6: 437864.4 | GK6: 439188.4 | GL6: 440408.8 | GM6: 441787.5 | GN6: 443258.1 | GO6: 444859.4 | GP6: 446391.8 | GQ6: 448363 | GR6: 450539.2 | GS6: 452477.2 | GT6: 454341.6 | GU6: 456201.8 | GV6: 458220.1 | GW6: 459983.9 | GX6: 461695.3 | GY6: 463445.7 | GZ6: 465447 | HA6: 467184.9 | HB6: 468872.6 | HC6: Office for National Statistics\Haver Analytics | HD6: TRUE | HE6: chained 2022 | HF6: NA | HG6: 2024 | HH6: 2 | HI6: NA | HJ6: NRJRQ@UK | HK6: UK: HH & NPISH: Real Household Disposable Income (SA, Mil.Chn.2022.Pounds) | HL6: GBR | HM6: PEDY | HN6: Oct24_2.db
A7: United Kingdom | B7: Earnings, quarterly total, whole economy, Gross, LCU | C7: Oct24_2 | D7: Pound per Employee | E7: NA | F7: Level | G7: 1256.656 | H7: 1320.788 | I7: 1377.792 | J7: 1419.042 | K7: 1445.746 | L7: 1481.073 | M7: 1519.57 | N7: 1560.495 | O7: 1588.719 | P7: 1621.852 | Q7: 1645.302 | R7: 1677.714 | S7: 1735.998 | T7: 1757.346 | U7: 1777.221 | V7: 1805.329 | W7: 1833.021 | X7: 1859.965 | Y7: 1876.902 | Z7: 1935.882 | AA7: 1996.246 | AB7: 2015.939 | AC7: 2043.298 | AD7: 2093.281 | AE7: 2142.593 | AF7: 2185.823 | AG7: 2220.435 | AH7: 2251.233 | AI7: 2282.895 | AJ7: 2321.792 | AK7: 2369.95 | AL7: 2418.279 | AM7: 2470.636 | AN7: 2512.313 | AO7: 2569.618 | AP7: 2641.639 | AQ7: 2684.494 | AR7: 2756.293 | AS7: 2816.473 | AT7: 2895.669 | AU7: 2978.668 | AV7: 3042.386 | AW7: 3096.331 | AX7: 3142.508 | AY7: 3224.996 | AZ7: 3293.292 | BA7: 3373.081 | BB7: 3431.946 | BC7: 3467.976 | BD7: 3483.129 | BE7: 3486.288 | BF7: 3519.483 | BG7: 3533.243 | BH7: 3585.394 | BI7: 3630.535 | BJ7: 3662.197 | BK7: 3681.295 | BL7: 3682.575 | BM7: 3730.634 | BN7: 3764.534 | BO7: 3784.689 | BP7: 3813.237 | BQ7: 3825.77 | BR7: 3869.823 | BS7: 3882.18 | BT7: 3914.624 | BU7: 3968.22 | BV7: 3978.247 | BW7: 4081.993 | BX7: 4143.857 | BY7: 4207.873 | BZ7: 4225.691 | CA7: 4229.584 | CB7: 4273.278 | CC7: 4319.682 | CD7: 4319.271 | CE7: 4422.741 | CF7: 4529.62 | CG7: 4579.019 | CH7: 4624.274 | CI7: 4637.771 | CJ7: 4701.495 | CK7: 4802.455 | CL7: 4890.775 | CM7: 5001.369 | CN7: 5002.77 | CO7: 5029.651 | CP7: 5057.922 | CQ7: 5089.49 | CR7: 5073.909 | CS7: 5126.548 | CT7: 5142.66 | CU7: 5215.105 | CV7: 5274.743 | CW7: 5382.108 | CX7: 5458.233 | CY7: 5521.079 | CZ7: 5546.886 | DA7: 5624.504 | DB7: 5694.482 | DC7: 5778.829 | DD7: 5743.093 | DE7: 5808.466 | DF7: 5809.272 | DG7: 5993.517 | DH7: 6001.19 | DI7: 6067.312 | DJ7: 6166.277 | DK7: 6414.875 | DL7: 6339.471 | DM7: 6466.942 | DN7: 6476.04 | DO7: 6580.838 | DP7: 6498.069 | DQ7: 6496.127 | DR7: 6443.408 | DS7: 6371.857 | DT7: 6556.603 | DU7: 6566.035 | DV7: 6577.117 | DW7: 6601.875 | DX7: 6547.224 | DY7: 6603.561 | DZ7: 6617.42 | EA7: 6764.375 | EB7: 6692.795 | EC7: 6733.261 | ED7: 6724.496 | EE7: 6797.859 | EF7: 6797.991 | EG7: 6779.331 | EH7: 6805.55 | EI7: 6831.207 | EJ7: 7064.567 | EK7: 7073.654 | EL7: 7154.167 | EM7: 7221.816 | EN7: 7176 | EO7: 7114.859 | EP7: 7151.244 | EQ7: 7196.032 | ER7: 7235.93 | ES7: 7286.774 | ET7: 7292.882 | EU7: 7378.136 | EV7: 7418.134 | EW7: 7455.118 | EX7: 7453.085 | EY7: 7552.214 | EZ7: 7621.865 | FA7: 7682.057 | FB7: 7709.649 | FC7: 7783.628 | FD7: 7753.096 | FE7: 7876.518 | FF7: 7956.615 | FG7: 7998.079 | FH7: 8102.425 | FI7: 8093.845 | FJ7: 8076.643 | FK7: 8056.795 | FL7: 7842.464 | FM7: 8014.82 | FN7: 8241.492 | FO7: 8267.329 | FP7: 8500.161 | FQ7: 8499.45 | FR7: 8570.438 | FS7: 8762.161 | FT7: 8858.754 | FU7: 8972.382 | FV7: 9187.092 | FW7: 9460.302 | FX7: 9660.59 | FY7: 9771.033 | FZ7: 9774.984 | GA7: 9898.726 | GB7: 10025.21 | GC7: 10139.5 | GD7: 10244.95 | GE7: 10327.93 | GF7: 10399.2 | GG7: 10470.95 | GH7: 10541.84 | GI7: 10611.65 | GJ7: 10680.9 | GK7: 10750.04 | GL7: 10818.11 | GM7: 10887.61 | GN7: 10957.44 | GO7: 11027.81 | GP7: 11097.76 | GQ7: 11168.61 | GR7: 11240.3 | GS7: 11313.43 | GT7: 11387.67 | GU7: 11462.16 | GV7: 11537.54 | GW7: 11614.13 | GX7: 11691.39 | GY7: 11769.48 | GZ7: 11848.68 | HA7: 11928.99 | HB7: 12009.94 | HC7: Oxford Economics calculation using Office for National Statistics data | HD7: TRUE | HE7: NA | HF7: NA | HG7: 2024 | HH7: 2 | HI7: NA | HJ7: Oxford Economics calculation using Office for National Statistics data | HK7: NA | HL7: GBR | HM7: ER | HN7: Oct24_2.db
A8: United Kingdom | B8: Tax revenue, employer social security contributions, LCU | C8: NICS_Scen | D8: Pound | E8: Millions | F8: Level | G8: 2203.656 | H8: 2273.364 | I8: 2332.952 | J8: 2420.649 | K8: 2498.227 | L8: 2399.287 | M8: 2452.13 | N8: 2560.064 | O8: 2665.75 | P8: 2569.059 | Q8: 2582.55 | R8: 2688.236 | S8: 2872.623 | T8: 2925.466 | U8: 2987.303 | V8: 3060.384 | W8: 3088.492 | X8: 3128.967 | Y8: 3185.183 | Z8: 3267.258 | AA8: 3359.452 | AB8: 3403.3 | AC8: 3447.148 | AD8: 3557.331 | AE8: 3637.157 | AF8: 3792.313 | AG8: 3863.145 | AH8: 3930.603 | AI8: 4305 | AJ8: 4334 | AK8: 4487 | AL8: 4632 | AM8: 4640 | AN8: 4879 | AO8: 5040 | AP8: 5234 | AQ8: 5239 | AR8: 5247 | AS8: 5405 | AT8: 5609 | AU8: 5594 | AV8: 5782 | AW8: 5930 | AX8: 6012 | AY8: 5974 | AZ8: 6126 | BA8: 6125 | BB8: 6492 | BC8: 6453 | BD8: 6234 | BE8: 6198 | BF8: 6517 | BG8: 6477 | BH8: 6646 | BI8: 6727 | BJ8: 6997 | BK8: 6841 | BL8: 6602 | BM8: 6704 | BN8: 6891 | BO8: 6872 | BP8: 6901 | BQ8: 6999 | BR8: 7120 | BS8: 7100 | BT8: 7308 | BU8: 7377 | BV8: 7428 | BW8: 7219 | BX8: 7704 | BY8: 8050 | BZ8: 8065 | CA8: 7887 | CB8: 8048 | CC8: 8448 | CD8: 8468 | CE8: 8757 | CF8: 8818 | CG8: 9094 | CH8: 9184 | CI8: 9313 | CJ8: 9861 | CK8: 9826 | CL8: 10195 | CM8: 10811 | CN8: 9870 | CO8: 10189 | CP8: 10298 | CQ8: 10629 | CR8: 10379 | CS8: 10146 | CT8: 10703 | CU8: 10366 | CV8: 11989 | CW8: 12409 | CX8: 12408 | CY8: 12662 | CZ8: 12920 | DA8: 13279 | DB8: 13669 | DC8: 13668 | DD8: 14205 | DE8: 14681 | DF8: 14643 | DG8: 14713 | DH8: 14863 | DI8: 15292 | DJ8: 15652 | DK8: 15661 | DL8: 16295 | DM8: 16680 | DN8: 17084 | DO8: 17891 | DP8: 17172 | DQ8: 17328 | DR8: 17305 | DS8: 16825 | DT8: 17195 | DU8: 17157 | DV8: 17618 | DW8: 18831 | DX8: 17422 | DY8: 17548 | DZ8: 17762 | EA8: 18475 | EB8: 18242 | EC8: 18350 | ED8: 18382 | EE8: 18603 | EF8: 19029 | EG8: 19095 | EH8: 18982 | EI8: 18597 | EJ8: 19598 | EK8: 19195 | EL8: 19482 | EM8: 19571 | EN8: 19575 | EO8: 19825 | EP8: 19993 | EQ8: 20426 | ER8: 20839 | ES8: 20846 | ET8: 21129 | EU8: 20549 | EV8: 22462 | EW8: 22802 | EX8: 23011 | EY8: 23425 | EZ8: 23645 | FA8: 23594 | FB8: 23997 | FC8: 24296 | FD8: 24403 | FE8: 24535 | FF8: 24830 | FG8: 25806 | FH8: 26406 | FI8: 27085 | FJ8: 27639 | FK8: 27453 | FL8: 27064 | FM8: 27978 | FN8: 28812 | FO8: 28828 | FP8: 29940 | FQ8: 30764 | FR8: 31560 | FS8: 32437 | FT8: 35271 | FU8: 35446 | FV8: 34778 | FW8: 34923 | FX8: 35305 | FY8: 35835 | FZ8: 37193 | GA8: 38998 | GB8: 37308 | GC8: 38127.7 | GD8: 38385.24 | GE8: 38842.31 | GF8: 45125.97 | GG8: 45491.81 | GH8: 45860.71 | GI8: 46241.94 | GJ8: 46661.97 | GK8: 47114.59 | GL8: 47570.96 | GM8: 48037.53 | GN8: 48613.55 | GO8: 49073.86 | GP8: 49541.79 | GQ8: 49929.76 | GR8: 50549.02 | GS8: 50986.99 | GT8: 51435.8 | GU8: 51884.1 | GV8: 52496.83 | GW8: 52918.27 | GX8: 53344.36 | GY8: 53771.22 | GZ8: 54261.23 | HA8: 54758.03 | HB8: 55259.36 | HC8: Office for National Statistics\Haver Analytics | HD8: TRUE | HE8: NA | HF8: NA | HG8: 2024 | HH8: 2 | HI8: NA | HJ8: RNFSQ@UK | HK8: UK: IA: CG: Resources: Employers' Social Contributions (SA, Mil.GBP) | HL8: GBR | HM8: TP | HN8: NICS_Scen.db
A9: United Kingdom | B9: GDP, real, LCU | C9: NICS_Scen | D9: Pound | E9: Millions | F9: Level | G9: 269776 | H9: 264448 | I9: 264139 | J9: 261297 | K9: 261131 | L9: 261739 | M9: 264602 | N9: 264902 | O9: 265408 | P9: 268196 | Q9: 268798 | R9: 270653 | S9: 275877 | T9: 277790 | U9: 280996 | V9: 283096 | W9: 285469 | X9: 282605 | Y9: 284676 | Z9: 289829 | AA9: 292612 | AB9: 298873 | AC9: 298814 | AD9: 298979 | AE9: 302117 | AF9: 304797 | AG9: 306708 | AH9: 312615 | AI9: 314804 | AJ9: 319478 | AK9: 327346 | AL9: 331075 | AM9: 336442 | AN9: 338186 | AO9: 342414 | AP9: 345162 | AQ9: 346836 | AR9: 348997 | AS9: 349572 | AT9: 349523 | AU9: 351299 | AV9: 353663 | AW9: 349780 | AX9: 348006 | AY9: 346292 | AZ9: 345892 | BA9: 345216 | BB9: 345643 | BC9: 345523 | BD9: 344987 | BE9: 346628 | BF9: 349299 | BG9: 351046 | BH9: 352612 | BI9: 355841 | BJ9: 358264 | BK9: 361793 | BL9: 365109 | BM9: 368798 | BN9: 370401 | BO9: 372307 | BP9: 373090 | BQ9: 377249 | BR9: 378442 | BS9: 380976 | BT9: 382146 | BU9: 385671 | BV9: 391053 | BW9: 397303 | BX9: 401790 | BY9: 405233 | BZ9: 411352 | CA9: 414377 | CB9: 416909 | CC9: 418294 | CD9: 421074 | CE9: 423875 | CF9: 425920 | CG9: 432860 | CH9: 439093 | CI9: 444540 | CJ9: 447825 | CK9: 450688 | CL9: 453447 | CM9: 457680 | CN9: 459620 | CO9: 462016 | CP9: 463404 | CQ9: 464698 | CR9: 466935 | CS9: 470277 | CT9: 473899 | CU9: 477357 | CV9: 481552 | CW9: 485973 | CX9: 490059 | CY9: 492014 | CZ9: 494824 | DA9: 496642 | DB9: 499020 | DC9: 502702 | DD9: 506906 | DE9: 511132 | DF9: 515935 | DG9: 518495 | DH9: 520318 | DI9: 521780 | DJ9: 524569 | DK9: 529398 | DL9: 533187 | DM9: 537052 | DN9: 540258 | DO9: 542804 | DP9: 539918 | DQ9: 531619 | DR9: 520230 | DS9: 509646 | DT9: 508009 | DU9: 508398 | DV9: 509889 | DW9: 514595 | DX9: 520128 | DY9: 523173 | DZ9: 523515 | EA9: 524955 | EB9: 525418 | EC9: 527034 | ED9: 527698 | EE9: 532300 | EF9: 531663 | EG9: 536720 | EH9: 536188 | EI9: 537974 | EJ9: 541586 | EK9: 546064 | EL9: 549709 | EM9: 554183 | EN9: 559331 | EO9: 563694 | EP9: 567619 | EQ9: 569150 | ER9: 572673 | ES9: 574836 | ET9: 578068 | EU9: 580110 | EV9: 583383 | EW9: 585856 | EX9: 589476 | EY9: 594423 | EZ9: 598176 | FA9: 601961 | FB9: 606396 | FC9: 606785 | FD9: 607775 | FE9: 609653 | FF9: 610481 | FG9: 614936 | FH9: 616853 | FI9: 621227 | FJ9: 621229 | FK9: 604719 | FL9: 481769 | FM9: 562648 | FN9: 570338 | FO9: 564411 | FP9: 605353 | FQ9: 615459 | FR9: 624592 | FS9: 629149 | FT9: 631258 | FU9: 631977 | FV9: 634044 | FW9: 634612 | FX9: 634624 | FY9: 633956 | FZ9: 631825 | GA9: 636222 | GB9: 639095 | GC9: 640741.9 | GD9: 643868.9 | GE9: 646136.9 | GF9: 647772.1 | GG9: 649743.7 | GH9: 652016.3 | GI9: 654585 | GJ9: 657323.1 | GK9: 660047.9 | GL9: 662837.8 | GM9: 665613.3 | GN9: 668386.4 | GO9: 671143.1 | GP9: 674014.1 | GQ9: 676832.3 | GR9: 679646 | GS9: 682417.5 | GT9: 685213.4 | GU9: 688029.5 | GV9: 690845 | GW9: 693682.9 | GX9: 696538.8 | GY9: 699408.1 | GZ9: 702286.3 | HA9: 705169.4 | HB9: 708055.9 | HC9: Office for National Statistics\Haver Analytics | HD9: TRUE | HE9: chained 2022 | HF9: NA | HG9: 2024 | HH9: 2 | HI9: NA | HJ9: ABMIQ@UK | HK9: U.K.: Real Gross Domestic Product (SA, Mil.Chn.2022.GBP) | HL9: GBR | HM9: GDP | HN9: NICS_Scen.db
A10: United Kingdom | B10: Employment, aged 16 and over, ILO definition | C10: NICS_Scen | D10: Person | E10: Thousands | F10: Level | G10: 25250 | H10: 25190 | I10: 25050 | J10: 24855 | K10: 24661 | L10: 24495 | M10: 24355 | N10: 24209 | O10: 24120 | P10: 24027 | Q10: 23901 | R10: 23755 | S10: 23651 | T10: 23647 | U10: 23809 | V10: 23994 | W10: 24125 | X10: 24245 | Y10: 24335 | Z10: 24435 | AA10: 24515 | AB10: 24570 | AC10: 24625 | AD10: 24660 | AE10: 24670 | AF10: 24695 | AG10: 24770 | AH10: 24850 | AI10: 24925 | AJ10: 25110 | AK10: 25345 | AL10: 25575 | AM10: 25795 | AN10: 25970 | AO10: 26160 | AP10: 26355 | AQ10: 26590 | AR10: 26730 | AS10: 26795 | AT10: 26880 | AU10: 26900 | AV10: 26935 | AW10: 26900 | AX10: 26750 | AY10: 26530 | AZ10: 26275 | BA10: 26025 | BB10: 25820 | BC10: 25710 | BD10: 25605 | BE10: 25509 | BF10: 25336 | BG10: 25282 | BH10: 25293 | BI10: 25316 | BJ10: 25320 | BK10: 25408 | BL10: 25451 | BM10: 25559 | BN10: 25600 | BO10: 25670 | BP10: 25770 | BQ10: 25852 | BR10: 25982 | BS10: 25970 | BT10: 26009 | BU10: 26062 | BV10: 26198 | BW10: 26381 | BX10: 26514 | BY10: 26572 | BZ10: 26636 | CA10: 26677 | CB10: 26714 | CC10: 26834 | CD10: 26955 | CE10: 27036 | CF10: 27095 | CG10: 27218 | CH10: 27322 | CI10: 27362 | CJ10: 27468 | CK10: 27555 | CL10: 27549 | CM10: 27623 | CN10: 27707 | CO10: 27715 | CP10: 27803 | CQ10: 27797 | CR10: 27933 | CS10: 27935 | CT10: 28110 | CU10: 28099 | CV10: 28226 | CW10: 28256 | CX10: 28304 | CY10: 28459 | CZ10: 28470 | DA10: 28518 | DB10: 28673 | DC10: 28789 | DD10: 28802 | DE10: 28928 | DF10: 28880 | DG10: 29048 | DH10: 29106 | DI10: 29183 | DJ10: 29214 | DK10: 29194 | DL10: 29322 | DM10: 29420 | DN10: 29576 | DO10: 29684 | DP10: 29722 | DQ10: 29580 | DR10: 29528 | DS10: 29366 | DT10: 29087 | DU10: 29069 | DV10: 29102 | DW10: 29013 | DX10: 29192 | DY10: 29385 | DZ10: 29324 | EA10: 29441 | EB10: 29447 | EC10: 29283 | ED10: 29349 | EE10: 29464 | EF10: 29681 | EG10: 29778 | EH10: 29932 | EI10: 29869 | EJ10: 29974 | EK10: 30144 | EL10: 30330 | EM10: 30573 | EN10: 30747 | EO10: 30873 | EP10: 30981 | EQ10: 31188 | ER10: 31140 | ES10: 31361 | ET10: 31569 | EU10: 31603 | EV10: 31778 | EW10: 31843 | EX10: 31877 | EY10: 31978 | EZ10: 32098 | FA10: 32093 | FB10: 32179 | FC10: 32364 | FD10: 32403 | FE10: 32448 | FF10: 32618 | FG10: 32721 | FH10: 32839 | FI10: 32779 | FJ10: 32954 | FK10: 33000 | FL10: 32571 | FM10: 32354 | FN10: 32198 | FO10: 32221 | FP10: 32377 | FQ10: 32687 | FR10: 32686 | FS10: 32775 | FT10: 32958 | FU10: 32916 | FV10: 33067 | FW10: 33201 | FX10: 33163 | FY10: 33102 | FZ10: 33174 | GA10: 32997 | GB10: 33094 | GC10: 33306.91 | GD10: 33156.91 | GE10: 33260.84 | GF10: 33349.68 | GG10: 33449.47 | GH10: 33554.05 | GI10: 33662.36 | GJ10: 33771.11 | GK10: 33873.27 | GL10: 33975.7 | GM10: 34077.21 | GN10: 34178.63 | GO10: 34278.84 | GP10: 34384.39 | GQ10: 34486.76 | GR10: 34588.66 | GS10: 34683.95 | GT10: 34776.47 | GU10: 34866.05 | GV10: 34951.74 | GW10: 35034.71 | GX10: 35117.85 | GY10: 35197.73 | GZ10: 35277.58 | HA10: 35357.53 | HB10: 35437.45 | HC10: Office for National Statistics\Haver Analytics | HD10: TRUE | HE10: NA | HF10: NA | HG10: 2024 | HH10: 2 | HI10: NA | HJ10: MGRZQ@UK | HK10: UK: LFS: Employment: Aged 16 and Over (SA, Thous) | HL10: GBR | HM10: ETILO | HN10: NICS_Scen.db
