Workbook
Name Annual_Data: GMWA!$A$1:$A$2
Name Annual_Data: GMWQ!$A$1:$A$2

Sheet >>CHARTS
A2: * Start with how inflation is set to be much lower than previously expected - only want a few sentences, and then link to inflation RB. Could possibly include an inflation chart as the opener but that wouldn’t be ideal
A4: * Pay growth has remained strong, can link to various RBs and Penta stuff. January pay settlements still fairly high and NLW uplift in Jan is pretty big
A6: * Therefore, real pay growth now looks stronger
A8: * However, when fiscal drag is taken into account, real pay is set to rise but are still much lower than in 2021 - make a chart with pre vs post tax/NICs real wages to demonstrate this.
A10: * While smaller than previously expected given the fall back in swap/mortgage rates, net interest reciepts will be negative this year (rent inflation has also been high), which adds to households' cost burdens, so eats into disposable incomes
B12: - there's lots in previous RB's about this dymanic as well as the RF's 2024 Q1 macroeconomic policy outlook
A14: * Large part of it is that real income last year looks articifically strong given energy support payments, so looking at calendar year averages is a bit meaningless.
A16: * As a result, disposable income growth will fall on calendar year average terms this year, but this masks a pickup throughout the year and because there's no energy payments.
A18: * Finish with a comment or two on this meaning that we expect consumption to gather pace throughout this year - maybe our consumer spending breakdown forecast chart

Sheet >> DATA

Sheet Chart Data
A1: Real post-tax wages & salaries (2021=100) | M1: Contributions to real income v1 | AB1: Contributions to real income v2 | AP1: Debt interest payments & interest rates | AU1: Debt interest receipts & payments | AZ1: Pay and inflation | BE1: Contributions to consumption growth (annual)
B3: Gross | C3: Post-tax | D3: 100 LINE | F3: Gross salaries | G3: Post-tax salaries | H3: Prices | J3: Gross salaries per head | K3: Post-tax salaries per head | N3: Price inflation | O3: Income tax & NICs | P3: Other income | Q3: Employment growth | R3: Wage inflation | S3: Social benefits | T3: Real income | V3: PEDY! | W3: PC | X3: PEWFP cont | Y3: ER | Z3: PEWFP if EE flat | AC3: Price inflation | AD3: Income tax & NICs | AE3: Wages & salaries | AF3: Other income | AG3: Net interest | AH3: Social benefits | AI3: Real income | AQ3: Personal sector debt interest payments (LHS) | AR3: Average mortgage interest rates (RHS) | AS3: Bank Rate (RHS) | AV3: Interest receipts | AW3: Debt interest payments | AX3: Net interest receipts | BA3: CPI inflation | BB3: Nominal pay growth (incl bonus) | BC3: Real earnings growth | BF3: Nominal income | BG3: Inflation | BH3: Savings | BI3: Consumer spending growth
A4: 2015 | B4: =100*(F4/$H4) -> 93.409403 | C4: =100*(G4/$H4) -> 96.798299 | D4: 100 | F4: =100*(J4/AVERAGE($J$28:$J$31)) -> 84.940761 | G4: =100*(K4/AVERAGE($K$28:$K$31)) -> 88.022415 | H4: =100*(DataQ!I175/AVERAGE(DataQ!I$199:I$202)) -> 90.933844 | J4: =DataQ!F175/DataQ!J175 -> 7.1960317 | K4: =(DataQ!F175-DataQ!G175-DataQ!H175)/DataQ!J175 -> 5.0742929 | M4: 2019 | V4: =100*((DataA!B53/DataA!B52)-1) -> 3.6025096 | W4: =100*((DataA!J53+DataA!K53)/(DataA!L53+DataA!M53)) -> 100 | X4: =100*((DataA!C53-DataA!C52)/DataA!B52) -> 2.1285774 | Y4: =1000*(DataA!C53/DataA!D53) -> 32271.156 | Z4: =(Y4*DataA!$D$53)/1000 -> 892362 | AB4: 2019 | AP4: 2000 | AQ4: =(DataQ!N115/DataQ!P115)*100 -> 5.7792893 | AR4: =DataQ!Q115 -> 7.056667 | AS4: =DataQ!AF115 -> 5.861538 | AU4: 2000 | AV4: =(DataQ!O115/DataQ!P115)*100 -> 5.3684872 | AW4: =(DataQ!N115/DataQ!P115)*100 -> 5.7792893 | AX4: =(DataQ!AG115/DataQ!P115)*100 -> -0.41080207 | AZ4: 2013 | BA4: =((DataQ!E167/DataQ!E163)-1)*100 -> 2.7709541 | BB4: =((DataQ!D167/DataQ!D163)-1)*100 -> 0.51056893 | BC4: =BB4-BA4 -> -2.2603852 | BE4: 2010 | BF4: =((DataA!B44/DataA!B43)-1)*100 -> 1.9526692 | BG4: =-((DataA!E44/DataA!E43)-1)*100 -> -0.92666224 | BH4: =BI4-BF4-BG4 -> 1.150294 | BI4: =((DataA!L44/DataA!L43)-1)*100 -> 2.1763009
B5: =100*(F5/$H5) -> 93.708519 | C5: =100*(G5/H5) -> 96.664998 | D5: 100 | F5: =100*(J5/AVERAGE($J$28:$J$31)) -> 85.411708 | G5: =100*(K5/AVERAGE($K$28:$K$31)) -> 88.106425 | H5: =100*(DataQ!I176/AVERAGE(DataQ!I$199:I$202)) -> 91.146151 | J5: =DataQ!F176/DataQ!J176 -> 7.2359295 | K5: =(DataQ!F176-DataQ!G176-DataQ!H176)/DataQ!J176 -> 5.0791359 | M5: 2020 | N5: =-100*((W5/W4)-1) -> -0.5757341 | O5: =-100*((DataA!F54+DataA!G54)-(DataA!F53+DataA!G53))/DataA!$B53 -> 0.042946753 | P5: =V5-O5-Q5-R5-S5 -> -1.5864145 | Q5: =X5-R5 -> 0.22180141 | R5: =100*((Z5-Z4)/DataA!$B53) -> -0.08422039 | S5: =100*((DataA!H54-DataA!H53)/DataA!$B53) -> 1.4681045 | T5: =SUM(N5:S5) -> -0.51351636 | V5: =100*((DataA!B54/DataA!B53)-1) -> 0.062217732 | W5: =100*((DataA!J54+DataA!K54)/(DataA!L54+DataA!M54)) -> 100.57573 | X5: =100*((DataA!C54-DataA!C53)/DataA!B53) -> 0.13758102 | Y5: =1000*(DataA!C54/DataA!D54) -> 32226.903 | Z5: =(Y5*DataA!$D$53)/1000 -> 891138.31 | AB5: 2020 | AC5: =N5 -> -0.5757341 | AD5: =O5 -> 0.042946753 | AE5: =X5 -> 0.13758102 | AF5: =V5-AD5-AE5-AG5-AH5 -> -1.6659761 | AG5: =100*((DataA!I54-DataA!I53)/DataA!$B53) -> 0.079561613 | AH5: =S5 -> 1.4681045 | AI5: =SUM(AC5:AH5) -> -0.51351636 | AQ5: =(DataQ!N116/DataQ!P116)*100 -> 5.9470557 | AR5: =DataQ!Q116 -> 7.143333 | AS5: =DataQ!AF116 -> 6 | AV5: =(DataQ!O116/DataQ!P116)*100 -> 5.447434 | AW5: =(DataQ!N116/DataQ!P116)*100 -> 5.9470557 | AX5: =(DataQ!AG116/DataQ!P116)*100 -> -0.49962167 | BA5: =((DataQ!E168/DataQ!E164)-1)*100 -> 2.6791962 | BB5: =((DataQ!D168/DataQ!D164)-1)*100 -> 2.0983935 | BC5: =BB5-BA5 -> -0.58080276 | BE5: 2011 | BF5: =((DataA!B45/DataA!B44)-1)*100 -> 1.5023932 | BG5: =-((DataA!E45/DataA!E44)-1)*100 -> -3.9932641 | BH5: =BI5-BF5-BG5 -> 2.1250135 | BI5: =((DataA!L45/DataA!L44)-1)*100 -> -0.36585748
B6: =100*(F6/$H6) -> 94.123382 | C6: =100*(G6/H6) -> 97.664794 | D6: 100 | F6: =100*(J6/AVERAGE($J$28:$J$31)) -> 86.01187 | G6: =100*(K6/AVERAGE($K$28:$K$31)) -> 89.248084 | H6: =100*(DataQ!I177/AVERAGE(DataQ!I$199:I$202)) -> 91.382043 | J6: =DataQ!F177/DataQ!J177 -> 7.2867741 | K6: =(DataQ!F177-DataQ!G177-DataQ!H177)/DataQ!J177 -> 5.1449499 | M6: 2021 | N6: =-100*((W6/W5)-1) -> -2.2832455 | O6: =-100*((DataA!F55+DataA!G55)-(DataA!F54+DataA!G54))/DataA!$B54 -> -2.3153441 | P6: =V6-O6-Q6-R6-S6 -> 1.7245056 | Q6: =X6-R6 -> 0.64316052 | R6: =100*((Z6-Z5)/DataA!$B54) -> 3.1641367 | S6: =100*((DataA!H55-DataA!H54)/DataA!$B54) -> 0.52205637 | T6: =SUM(N6:S6) -> 1.4552696 | V6: =100*((DataA!B55/DataA!B54)-1) -> 3.7385151 | W6: =100*((DataA!J55+DataA!K55)/(DataA!L55+DataA!M55)) -> 102.87213 | X6: =100*((DataA!C55-DataA!C54)/DataA!B54) -> 3.8072972 | Y6: =1000*(DataA!C55/DataA!D55) -> 33890.519 | Z6: =(Y6*DataA!$D$53)/1000 -> 937140.62 | AB6: 2021 | AC6: =N6 -> -2.2832455 | AD6: =O6 -> -2.3153441 | AE6: =X6 -> 3.8072972 | AF6: =V6-AD6-AE6-AG6-AH6 -> 1.6145917 | AG6: =100*((DataA!I55-DataA!I54)/DataA!$B54) -> 0.10991384 | AH6: =S6 -> 0.52205637 | AI6: =SUM(AC6:AH6) -> 1.4552696 | AQ6: =(DataQ!N117/DataQ!P117)*100 -> 5.7773877 | AR6: =DataQ!Q117 -> 7.113333 | AS6: =DataQ!AF117 -> 6 | AV6: =(DataQ!O117/DataQ!P117)*100 -> 5.3145206 | AW6: =(DataQ!N117/DataQ!P117)*100 -> 5.7773877 | AX6: =(DataQ!AG117/DataQ!P117)*100 -> -0.46286705 | BA6: =((DataQ!E169/DataQ!E165)-1)*100 -> 2.7411484 | BB6: =((DataQ!D169/DataQ!D165)-1)*100 -> 0.64794816 | BC6: =BB6-BA6 -> -2.0932002 | BE6: 2012 | BF6: =((DataA!B46/DataA!B45)-1)*100 -> 4.1771019 | BG6: =-((DataA!E46/DataA!E45)-1)*100 -> -1.6745382 | BH6: =BI6-BF6-BG6 -> -0.73697644 | BI6: =((DataA!L46/DataA!L45)-1)*100 -> 1.7655873
B7: =100*(F7/$H7) -> 94.093175 | C7: =100*(G7/H7) -> 97.359528 | D7: 100 | F7: =100*(J7/AVERAGE($J$28:$J$31)) -> 86.08397 | G7: =100*(K7/AVERAGE($K$28:$K$31)) -> 89.072291 | H7: =100*(DataQ!I178/AVERAGE(DataQ!I$199:I$202)) -> 91.488006 | J7: =DataQ!F178/DataQ!J178 -> 7.2928823 | K7: =(DataQ!F178-DataQ!G178-DataQ!H178)/DataQ!J178 -> 5.1348159 | M7: 2022 | N7: =-100*((W7/W6)-1) -> -7.8364037 | O7: =-100*((DataA!F56+DataA!G56)-(DataA!F55+DataA!G55))/DataA!$B55 -> -2.1384825 | P7: =V7-O7-Q7-R7-S7 -> 2.7025916 | Q7: =X7-R7 -> 1.0550845 | R7: =100*((Z7-Z6)/DataA!$B55) -> 3.5800513 | S7: =100*((DataA!H56-DataA!H55)/DataA!$B55) -> 1.1564634 | T7: =SUM(N7:S7) -> -1.4806955 | V7: =100*((DataA!B56/DataA!B55)-1) -> 6.3557083 | W7: =100*((DataA!J56+DataA!K56)/(DataA!L56+DataA!M56)) -> 110.9336 | X7: =100*((DataA!C56-DataA!C55)/DataA!B55) -> 4.6351359 | Y7: =1000*(DataA!C56/DataA!D56) -> 35843.181 | Z7: =(Y7*DataA!$D$53)/1000 -> 991135.63 | AB7: 2022 | AC7: =N7 -> -7.8364037 | AD7: =O7 -> -2.1384825 | AE7: =X7 -> 4.6351359 | AF7: =V7-AD7-AE7-AG7-AH7 -> 2.5175389 | AG7: =100*((DataA!I56-DataA!I55)/DataA!$B55) -> 0.1850527 | AH7: =S7 -> 1.1564634 | AI7: =SUM(AC7:AH7) -> -1.4806955 | AQ7: =(DataQ!N118/DataQ!P118)*100 -> 5.7499034 | AR7: =DataQ!Q118 -> 7.056667 | AS7: =DataQ!AF118 -> 6 | AV7: =(DataQ!O118/DataQ!P118)*100 -> 4.552141 | AW7: =(DataQ!N118/DataQ!P118)*100 -> 5.7499034 | AX7: =(DataQ!AG118/DataQ!P118)*100 -> -1.1977623 | BA7: =((DataQ!E170/DataQ!E166)-1)*100 -> 2.0904694 | BB7: =((DataQ!D170/DataQ!D166)-1)*100 -> 1.0101082 | BC7: =BB7-BA7 -> -1.0803612 | BE7: 2013 | BF7: =((DataA!B47/DataA!B46)-1)*100 -> 4.1516968 | BG7: =-((DataA!E47/DataA!E46)-1)*100 -> -2.2226271 | BH7: =BI7-BF7-BG7 -> 0.89945054 | BI7: =((DataA!L47/DataA!L46)-1)*100 -> 2.8285203
A8: 2016 | B8: =100*(F8/$H8) -> 95.072928 | C8: =100*(G8/H8) -> 98.647093 | D8: 100 | F8: =100*(J8/AVERAGE($J$28:$J$31)) -> 87.090292 | G8: =100*(K8/AVERAGE($K$28:$K$31)) -> 90.364358 | H8: =100*(DataQ!I179/AVERAGE(DataQ!I$199:I$202)) -> 91.603671 | J8: =DataQ!F179/DataQ!J179 -> 7.3781361 | K8: =(DataQ!F179-DataQ!G179-DataQ!H179)/DataQ!J179 -> 5.2093006 | M8: 2023 | N8: =-100*((W8/W7)-1) -> -7.0184089 | O8: =-100*((DataA!F57+DataA!G57)-(DataA!F56+DataA!G56))/DataA!$B56 -> -1.7420286 | P8: =V8-O8-Q8-R8-S8 -> 3.9911164 | Q8: =X8-R8 -> 0.64331081 | R8: =100*((Z8-Z7)/DataA!$B56) -> 4.1668698 | S8: =100*((DataA!H57-DataA!H56)/DataA!$B56) -> 1.7838233 | T8: =SUM(N8:S8) -> 1.8246828 | V8: =100*((DataA!B57/DataA!B56)-1) -> 8.8430917 | W8: =100*((DataA!J57+DataA!K57)/(DataA!L57+DataA!M57)) -> 118.71937 | X8: =100*((DataA!C57-DataA!C56)/DataA!B56) -> 4.8101806 | Y8: =1000*(DataA!C57/DataA!D57) -> 38260.358 | Z8: =(Y8*DataA!$D$53)/1000 -> 1057975.4 | AB8: 2023 | AC8: =N8 -> -7.0184089 | AD8: =O8 -> -1.7420286 | AE8: =X8 -> 4.8101806 | AF8: =V8-AD8-AE8-AG8-AH8 -> 3.7295051 | AG8: =100*((DataA!I57-DataA!I56)/DataA!$B56) -> 0.26161126 | AH8: =S8 -> 1.7838233 | AI8: =SUM(AC8:AH8) -> 1.8246828 | AP8: 2001 | AQ8: =(DataQ!N119/DataQ!P119)*100 -> 5.7614058 | AR8: =DataQ!Q119 -> 6.936666 | AS8: =DataQ!AF119 -> 5.857692 | AU8: 2001 | AV8: =(DataQ!O119/DataQ!P119)*100 -> 5.2053466 | AW8: =(DataQ!N119/DataQ!P119)*100 -> 5.7614058 | AX8: =(DataQ!AG119/DataQ!P119)*100 -> -0.5560592 | AZ8: 2014 | BA8: =((DataQ!E171/DataQ!E167)-1)*100 -> 1.774751 | BB8: =((DataQ!D171/DataQ!D167)-1)*100 -> 1.7416547 | BC8: =BB8-BA8 -> -0.033096276 | BE8: 2014 | BF8: =((DataA!B48/DataA!B47)-1)*100 -> 3.4994719 | BG8: =-((DataA!E48/DataA!E47)-1)*100 -> -1.1496394 | BH8: =BI8-BF8-BG8 -> 0.67155499 | BI8: =((DataA!L48/DataA!L47)-1)*100 -> 3.0213874
B9: =100*(F9/$H9) -> 95.152912 | C9: =100*(G9/H9) -> 98.218701 | D9: 100 | F9: =100*(J9/AVERAGE($J$28:$J$31)) -> 87.562415 | G9: =100*(K9/AVERAGE($K$28:$K$31)) -> 90.383641 | H9: =100*(DataQ!I180/AVERAGE(DataQ!I$199:I$202)) -> 92.022843 | J9: =DataQ!F180/DataQ!J180 -> 7.4181336 | K9: =(DataQ!F180-DataQ!G180-DataQ!H180)/DataQ!J180 -> 5.2104122 | M9: 2024 | N9: =-100*((W9/W8)-1) -> -2.1814376 | O9: =-100*((DataA!F58+DataA!G58)-(DataA!F57+DataA!G57))/DataA!$B57 -> -1.0384226 | P9: =V9-O9-Q9-R9-S9 -> 0.034566165 | Q9: =X9-R9 -> 0.16863956 | R9: =100*((Z9-Z8)/DataA!$B57) -> 2.4975658 | S9: =100*((DataA!H58-DataA!H57)/DataA!$B57) -> 1.6195752 | T9: =SUM(N9:S9) -> 1.1004866 | V9: =100*((DataA!B58/DataA!B57)-1) -> 3.2819242 | W9: =100*((DataA!J58+DataA!K58)/(DataA!L58+DataA!M58)) -> 121.30916 | X9: =100*((DataA!C58-DataA!C57)/DataA!B57) -> 2.6662054 | Y9: =1000*(DataA!C58/DataA!D58) -> 39837.303 | Z9: =(Y9*DataA!$D$53)/1000 -> 1101581.1 | AB9: 2024 | AC9: =N9 -> -2.1814376 | AD9: =O9 -> -1.0384226 | AE9: =X9 -> 2.6662054 | AF9: =V9-AD9-AE9-AG9-AH9 -> 0.53764934 | AG9: =100*((DataA!I58-DataA!I57)/DataA!$B57) -> -0.50308318 | AH9: =S9 -> 1.6195752 | AI9: =SUM(AC9:AH9) -> 1.1004866 | AQ9: =(DataQ!N120/DataQ!P120)*100 -> 5.5112776 | AR9: =DataQ!Q120 -> 6.613333 | AS9: =DataQ!AF120 -> 5.369231 | AV9: =(DataQ!O120/DataQ!P120)*100 -> 4.4893574 | AW9: =(DataQ!N120/DataQ!P120)*100 -> 5.5112776 | AX9: =(DataQ!AG120/DataQ!P120)*100 -> -1.0219202 | BA9: =((DataQ!E172/DataQ!E168)-1)*100 -> 1.7621111 | BB9: =((DataQ!D172/DataQ!D168)-1)*100 -> -0.21261518 | BC9: =BB9-BA9 -> -1.9747263 | BE9: 2015 | BF9: =((DataA!B49/DataA!B48)-1)*100 -> 5.6910168 | BG9: =-((DataA!E49/DataA!E48)-1)*100 -> 0.369247 | BH9: =BI9-BF9-BG9 -> -3.1744905 | BI9: =((DataA!L49/DataA!L48)-1)*100 -> 2.8857733
B10: =100*(F10/$H10) -> 94.882419 | C10: =100*(G10/H10) -> 97.505549 | D10: 100 | F10: =100*(J10/AVERAGE($J$28:$J$31)) -> 87.998975 | G10: =100*(K10/AVERAGE($K$28:$K$31)) -> 90.431804 | H10: =100*(DataQ!I181/AVERAGE(DataQ!I$199:I$202)) -> 92.74529 | J10: =DataQ!F181/DataQ!J181 -> 7.4551182 | K10: =(DataQ!F181-DataQ!G181-DataQ!H181)/DataQ!J181 -> 5.2131887 | M10: 2025 | N10: =-100*((W10/W9)-1) -> -2.1173979 | O10: =-100*((DataA!F59+DataA!G59)-(DataA!F58+DataA!G58))/DataA!$B58 -> -1.2373822 | P10: =V10-O10-Q10-R10-S10 -> 1.7286071 | Q10: =X10-R10 -> 0.73105149 | R10: =100*((Z10-Z9)/DataA!$B58) -> 1.7142868 | S10: =100*((DataA!H59-DataA!H58)/DataA!$B58) -> 1.1545468 | T10: =SUM(N10:S10) -> 1.973712 | V10: =100*((DataA!B59/DataA!B58)-1) -> 4.09111 | W10: =100*((DataA!J59+DataA!K59)/(DataA!L59+DataA!M59)) -> 123.87776 | X10: =100*((DataA!C59-DataA!C58)/DataA!B58) -> 2.4453383 | Y10: =1000*(DataA!C59/DataA!D59) -> 40955.214 | Z10: =(Y10*DataA!$D$53)/1000 -> 1132493.6 | AB10: 2025 | AC10: =N10 -> -2.1173979 | AD10: =O10 -> -1.2373822 | AE10: =X10 -> 2.4453383 | AF10: =V10-AD10-AE10-AG10-AH10 -> 2.1122255 | AG10: =100*((DataA!I59-DataA!I58)/DataA!$B58) -> -0.38361842 | AH10: =S10 -> 1.1545468 | AI10: =SUM(AC10:AH10) -> 1.973712 | AQ10: =(DataQ!N121/DataQ!P121)*100 -> 5.2109808 | AR10: =DataQ!Q121 -> 6.35 | AS10: =DataQ!AF121 -> 5.053846 | AV10: =(DataQ!O121/DataQ!P121)*100 -> 4.1985677 | AW10: =(DataQ!N121/DataQ!P121)*100 -> 5.2109808 | AX10: =(DataQ!AG121/DataQ!P121)*100 -> -1.0124131 | BA10: =((DataQ!E173/DataQ!E169)-1)*100 -> 1.4521783 | BB10: =((DataQ!D173/DataQ!D169)-1)*100 -> 0.8583691 | BC10: =BB10-BA10 -> -0.59380922 | BE10: 2016 | BF10: =((DataA!B50/DataA!B49)-1)*100 -> 1.9559014 | BG10: =-((DataA!E50/DataA!E49)-1)*100 -> -1.2654209 | BH10: =BI10-BF10-BG10 -> 3.1532951 | BI10: =((DataA!L50/DataA!L49)-1)*100 -> 3.8437757
B11: =100*(F11/$H11) -> 94.397398 | C11: =100*(G11/H11) -> 96.787262 | D11: 100 | F11: =100*(J11/AVERAGE($J$28:$J$31)) -> 87.974981 | G11: =100*(K11/AVERAGE($K$28:$K$31)) -> 90.202248 | H11: =100*(DataQ!I182/AVERAGE(DataQ!I$199:I$202)) -> 93.196404 | J11: =DataQ!F182/DataQ!J182 -> 7.4530854 | K11: =(DataQ!F182-DataQ!G182-DataQ!H182)/DataQ!J182 -> 5.1999553 | M11: 2026 | N11: =-100*((W11/W10)-1) -> -2.2077422 | O11: =-100*((DataA!F60+DataA!G60)-(DataA!F59+DataA!G59))/DataA!$B59 -> -1.1740971 | P11: =V11-O11-Q11-R11-S11 -> 1.9262978 | Q11: =X11-R11 -> 0.71122178 | R11: =100*((Z11-Z10)/DataA!$B59) -> 1.6353431 | S11: =100*((DataA!H60-DataA!H59)/DataA!$B59) -> 1.0661806 | T11: =SUM(N11:S11) -> 1.9572041 | V11: =100*((DataA!B60/DataA!B59)-1) -> 4.1649463 | W11: =100*((DataA!J60+DataA!K60)/(DataA!L60+DataA!M60)) -> 126.61266 | X11: =100*((DataA!C60-DataA!C59)/DataA!B59) -> 2.3465649 | Y11: =1000*(DataA!C60/DataA!D60) -> 42065.274 | Z11: =(Y11*DataA!$D$53)/1000 -> 1163189 | AB11: 2026 | AC11: =N11 -> -2.2077422 | AD11: =O11 -> -1.1740971 | AE11: =X11 -> 2.3465649 | AF11: =V11-AD11-AE11-AG11-AH11 -> 2.3162431 | AG11: =100*((DataA!I60-DataA!I59)/DataA!$B59) -> -0.38994533 | AH11: =S11 -> 1.0661806 | AI11: =SUM(AC11:AH11) -> 1.9572041 | AQ11: =(DataQ!N122/DataQ!P122)*100 -> 4.6413811 | AR11: =DataQ!Q122 -> 5.846667 | AS11: =DataQ!AF122 -> 4.223485 | AV11: =(DataQ!O122/DataQ!P122)*100 -> 3.0958216 | AW11: =(DataQ!N122/DataQ!P122)*100 -> 4.6413811 | AX11: =(DataQ!AG122/DataQ!P122)*100 -> -1.5455595 | BA11: =((DataQ!E174/DataQ!E170)-1)*100 -> 0.90634441 | BB11: =((DataQ!D174/DataQ!D170)-1)*100 -> 1.9999927 | BC11: =BB11-BA11 -> 1.0936483 | BE11: 2017 | BF11: =((DataA!B51/DataA!B50)-1)*100 -> 2.7228076 | BG11: =-((DataA!E51/DataA!E50)-1)*100 -> -1.8555014 | BH11: =BI11-BF11-BG11 -> 0.86674481 | BI11: =((DataA!L51/DataA!L50)-1)*100 -> 1.734051
A12: 2017 | B12: =100*(F12/$H12) -> 95.632551 | C12: =100*(G12/H12) -> 96.90261 | D12: 100 | F12: =100*(J12/AVERAGE($J$28:$J$31)) -> 89.145083 | G12: =100*(K12/AVERAGE($K$28:$K$31)) -> 90.328985 | H12: =100*(DataQ!I183/AVERAGE(DataQ!I$199:I$202)) -> 93.216255 | J12: =DataQ!F183/DataQ!J183 -> 7.5522144 | K12: =(DataQ!F183-DataQ!G183-DataQ!H183)/DataQ!J183 -> 5.2072614 | AP12: 2002 | AQ12: =(DataQ!N123/DataQ!P123)*100 -> 4.5625929 | AR12: =DataQ!Q123 -> 5.513333 | AS12: =DataQ!AF123 -> 4 | AU12: 2002 | AV12: =(DataQ!O123/DataQ!P123)*100 -> 3.2817748 | AW12: =(DataQ!N123/DataQ!P123)*100 -> 4.5625929 | AX12: =(DataQ!AG123/DataQ!P123)*100 -> -1.2808181 | AZ12: 2015 | BA12: =((DataQ!E175/DataQ!E171)-1)*100 -> 0.10060362 | BB12: =((DataQ!D175/DataQ!D171)-1)*100 -> 2.2824609 | BC12: =BB12-BA12 -> 2.1818573 | BE12: 2018 | BF12: =((DataA!B52/DataA!B51)-1)*100 -> 4.1100965 | BG12: =-((DataA!E52/DataA!E51)-1)*100 -> -2.1055293 | BH12: =BI12-BF12-BG12 -> -0.34808905 | BI12: =((DataA!L52/DataA!L51)-1)*100 -> 1.6564782
B13: =100*(F13/$H13) -> 95.780085 | C13: =100*(G13/H13) -> 98.678979 | D13: 100 | F13: =100*(J13/AVERAGE($J$28:$J$31)) -> 89.967229 | G13: =100*(K13/AVERAGE($K$28:$K$31)) -> 92.690189 | H13: =100*(DataQ!I184/AVERAGE(DataQ!I$199:I$202)) -> 93.931039 | J13: =DataQ!F184/DataQ!J184 -> 7.6218652 | K13: =(DataQ!F184-DataQ!G184-DataQ!H184)/DataQ!J184 -> 5.3433795 | AQ13: =(DataQ!N124/DataQ!P124)*100 -> 4.6749902 | AR13: =DataQ!Q124 -> 5.436666 | AS13: =DataQ!AF124 -> 4 | AV13: =(DataQ!O124/DataQ!P124)*100 -> 3.4325677 | AW13: =(DataQ!N124/DataQ!P124)*100 -> 4.6749902 | AX13: =(DataQ!AG124/DataQ!P124)*100 -> -1.2424225 | BA13: =((DataQ!E176/DataQ!E172)-1)*100 -> -0.033266733 | BB13: =((DataQ!D176/DataQ!D172)-1)*100 -> 2.5568184 | BC13: =BB13-BA13 -> 2.5900851 | BE13: 2019 | BF13: =((DataA!B53/DataA!B52)-1)*100 -> 3.6025096 | BG13: =-((DataA!E53/DataA!E52)-1)*100 -> -1.4697096 | BH13: =BI13-BF13-BG13 -> -1.0170161 | BI13: =((DataA!L53/DataA!L52)-1)*100 -> 1.1157839
B14: =100*(F14/$H14) -> 96.107743 | C14: =100*(G14/H14) -> 99.286748 | D14: 100 | F14: =100*(J14/AVERAGE($J$28:$J$31)) -> 90.677718 | G14: =100*(K14/AVERAGE($K$28:$K$31)) -> 93.677112 | H14: =100*(DataQ!I185/AVERAGE(DataQ!I$199:I$202)) -> 94.350065 | J14: =DataQ!F185/DataQ!J185 -> 7.6820566 | K14: =(DataQ!F185-DataQ!G185-DataQ!H185)/DataQ!J185 -> 5.4002733 | AQ14: =(DataQ!N125/DataQ!P125)*100 -> 4.7875188 | AR14: =DataQ!Q125 -> 5.313334 | AS14: =DataQ!AF125 -> 4 | AV14: =(DataQ!O125/DataQ!P125)*100 -> 3.5414383 | AW14: =(DataQ!N125/DataQ!P125)*100 -> 4.7875188 | AX14: =(DataQ!AG125/DataQ!P125)*100 -> -1.2460805 | BA14: =((DataQ!E177/DataQ!E173)-1)*100 -> 0.033355537 | BB14: =((DataQ!D177/DataQ!D173)-1)*100 -> 2.9078085 | BC14: =BB14-BA14 -> 2.874453 | BE14: 2020 | BF14: =((DataA!B54/DataA!B53)-1)*100 -> 0.062217732 | BG14: =-((DataA!E54/DataA!E53)-1)*100 -> -0.15584022 | BH14: =BI14-BF14-BG14 -> -12.872187 | BI14: =((DataA!L54/DataA!L53)-1)*100 -> -12.965809
B15: =100*(F15/$H15) -> 95.865558 | C15: =100*(G15/H15) -> 97.828059 | D15: 100 | F15: =100*(J15/AVERAGE($J$28:$J$31)) -> 91.003414 | G15: =100*(K15/AVERAGE($K$28:$K$31)) -> 92.86638 | H15: =100*(DataQ!I186/AVERAGE(DataQ!I$199:I$202)) -> 94.928163 | J15: =DataQ!F186/DataQ!J186 -> 7.7096489 | K15: =(DataQ!F186-DataQ!G186-DataQ!H186)/DataQ!J186 -> 5.3535365 | AQ15: =(DataQ!N126/DataQ!P126)*100 -> 4.8748014 | AR15: =DataQ!Q126 -> 5.296667 | AS15: =DataQ!AF126 -> 4 | AV15: =(DataQ!O126/DataQ!P126)*100 -> 3.5554883 | AW15: =(DataQ!N126/DataQ!P126)*100 -> 4.8748014 | AX15: =(DataQ!AG126/DataQ!P126)*100 -> -1.3193131 | BA15: =((DataQ!E178/DataQ!E174)-1)*100 -> 0.099800399 | BB15: =((DataQ!D178/DataQ!D174)-1)*100 -> 1.8907563 | BC15: =BB15-BA15 -> 1.7909559 | BE15: 2021 | BF15: =((DataA!B55/DataA!B54)-1)*100 -> 3.7385151 | BG15: =-((DataA!E55/DataA!E54)-1)*100 -> -2.4044563 | BH15: =BI15-BF15-BG15 -> 6.1160868 | BI15: =((DataA!L55/DataA!L54)-1)*100 -> 7.4501457
A16: 2018 | B16: =100*(F16/$H16) -> 96.253213 | C16: =100*(G16/H16) -> 99.998493 | D16: 100 | F16: =100*(J16/AVERAGE($J$28:$J$31)) -> 91.876651 | G16: =100*(K16/AVERAGE($K$28:$K$31)) -> 95.451636 | H16: =100*(DataQ!I187/AVERAGE(DataQ!I$199:I$202)) -> 95.453075 | J16: =DataQ!F187/DataQ!J187 -> 7.7836281 | K16: =(DataQ!F187-DataQ!G187-DataQ!H187)/DataQ!J187 -> 5.5025706 | M16: Quarterly contributions to real income v1 | AB16: Quarterly contributions to real income v2 | AP16: 2003 | AQ16: =(DataQ!N127/DataQ!P127)*100 -> 4.8844779 | AR16: =DataQ!Q127 -> 5.173333 | AS16: =DataQ!AF127 -> 3.851563 | AU16: 2003 | AV16: =(DataQ!O127/DataQ!P127)*100 -> 3.5844799 | AW16: =(DataQ!N127/DataQ!P127)*100 -> 4.8844779 | AX16: =(DataQ!AG127/DataQ!P127)*100 -> -1.299998 | AZ16: 2016 | BA16: =((DataQ!E179/DataQ!E175)-1)*100 -> 0.33501508 | BB16: =((DataQ!D179/DataQ!D175)-1)*100 -> 2.1617782 | BC16: =BB16-BA16 -> 1.8267632 | BE16: 2022 | BF16: =((DataA!B56/DataA!B55)-1)*100 -> 6.3557083 | BG16: =-((DataA!E56/DataA!E55)-1)*100 -> -8.3294415 | BH16: =BI16-BF16-BG16 -> 6.7243323 | BI16: =((DataA!L56/DataA!L55)-1)*100 -> 4.7505992
B17: =100*(F17/$H17) -> 95.583106 | C17: =100*(G17/H17) -> 98.256227 | D17: 100 | F17: =100*(J17/AVERAGE($J$28:$J$31)) -> 91.516259 | G17: =100*(K17/AVERAGE($K$28:$K$31)) -> 94.075645 | H17: =100*(DataQ!I188/AVERAGE(DataQ!I$199:I$202)) -> 95.745224 | J17: =DataQ!F188/DataQ!J188 -> 7.7530963 | K17: =(DataQ!F188-DataQ!G188-DataQ!H188)/DataQ!J188 -> 5.4232479 | N17: Price inflation | O17: Income tax & NICs | P17: Other income | Q17: Employment growth | R17: Wage inflation | S17: Social benefits | T17: Real income | V17: PEDY! | W17: PC | X17: PEWFP cont | Y17: ER | Z17: PEWFP if EE flat | AC17: Price inflation | AD17: Income tax & NICs | AE17: Wages & salaries | AF17: Other income | AG17: Net interest | AH17: Social benefits | AI17: Real income | AQ17: =(DataQ!N128/DataQ!P128)*100 -> 4.8031426 | AR17: =DataQ!Q128 -> 5.01 | AS17: =DataQ!AF128 -> 3.75 | AV17: =(DataQ!O128/DataQ!P128)*100 -> 3.5924372 | AW17: =(DataQ!N128/DataQ!P128)*100 -> 4.8031426 | AX17: =(DataQ!AG128/DataQ!P128)*100 -> -1.2107054 | BA17: =((DataQ!E180/DataQ!E176)-1)*100 -> 0.33307784 | BB17: =((DataQ!D180/DataQ!D176)-1)*100 -> 2.5623409 | BC17: =BB17-BA17 -> 2.2292631 | BE17: 2023 | BF17: =((DataA!B57/DataA!B56)-1)*100 -> 8.8430917 | BG17: =-((DataA!E57/DataA!E56)-1)*100 -> -7.1222399 | BH17: =BI17-BF17-BG17 -> -1.4000169 | BI17: =((DataA!L57/DataA!L56)-1)*100 -> 0.32083487
B18: =100*(F18/$H18) -> 96.548701 | C18: =100*(G18/H18) -> 98.813666 | D18: 100 | F18: =100*(J18/AVERAGE($J$28:$J$31)) -> 92.973104 | G18: =100*(K18/AVERAGE($K$28:$K$31)) -> 95.154189 | H18: =100*(DataQ!I189/AVERAGE(DataQ!I$199:I$202)) -> 96.296588 | J18: =DataQ!F189/DataQ!J189 -> 7.8765176 | K18: =(DataQ!F189-DataQ!G189-DataQ!H189)/DataQ!J189 -> 5.4854235 | M18: 2019 01 | N18: =((W22/W18)-1)*-100 -> -1.514639 | O18: =-100*((DataQ!AN191+DataQ!AO191)-(DataQ!AN187+DataQ!AO187))/DataQ!AI187 -> -1.4634455 | S18: =100*((DataQ!AQ191-DataQ!AQ187)/DataQ!AI187) -> 0.53976954 | V18: =((DataQ!AI191/DataQ!AI187)-1)*100 -> 2.4265186 | W18: =100*((DataQ!AR187+DataQ!AS187)/(DataQ!AT187+DataQ!AU187)) -> 97.869959 | X18: =100*((DataQ!AK191-DataQ!AK187)/DataQ!AI187) -> 2.0776958 | Y18: =1000*(DataQ!AK191/DataQ!AM191) -> 7998.0792 | Z18: =(Y18*DataQ!AM191)/1000 -> 220691 | AQ18: =(DataQ!N129/DataQ!P129)*100 -> 4.5972279 | AR18: =DataQ!Q129 -> 4.85 | AS18: =DataQ!AF129 -> 3.526515 | AV18: =(DataQ!O129/DataQ!P129)*100 -> 3.3464683 | AW18: =(DataQ!N129/DataQ!P129)*100 -> 4.5972279 | AX18: =(DataQ!AG129/DataQ!P129)*100 -> -1.2507597 | BA18: =((DataQ!E181/DataQ!E177)-1)*100 -> 0.69883504 | BB18: =((DataQ!D181/DataQ!D177)-1)*100 -> 2.3432045 | BC18: =BB18-BA18 -> 1.6443695 | BE18: 2024 | BF18: =((DataA!B58/DataA!B57)-1)*100 -> 3.2819242 | BG18: =-((DataA!E58/DataA!E57)-1)*100 -> -2.1686235 | BH18: =BI18-BF18-BG18 -> -0.5142773 | BI18: =((DataA!L58/DataA!L57)-1)*100 -> 0.59902338
B19: =100*(F19/$H19) -> 96.966791 | C19: =100*(G19/H19) -> 98.824912 | D19: 100 | F19: =100*(J19/AVERAGE($J$28:$J$31)) -> 93.918557 | G19: =100*(K19/AVERAGE($K$28:$K$31)) -> 95.718266 | H19: =100*(DataQ!I190/AVERAGE(DataQ!I$199:I$202)) -> 96.856414 | J19: =DataQ!F190/DataQ!J190 -> 7.9566147 | K19: =(DataQ!F190-DataQ!G190-DataQ!H190)/DataQ!J190 -> 5.5179413 | M19: 2019 02 | N19: =((W23/W19)-1)*-100 -> -1.7494537 | O19: =-100*((DataQ!AN192+DataQ!AO192)-(DataQ!AN188+DataQ!AO188))/DataQ!AI188 -> -1.053786 | P19: =V19-O19-Q19-R19-S19 -> 1.8844952 | Q19: =X19-R19 -> 2.2863411 | R19: =100*((Z19-Z18)/DataQ!AI190) -> 0.98007874 | S19: =100*((DataQ!AQ192-DataQ!AQ188)/DataQ!AI188) -> 0.5578359 | T19: =SUM(N19:S19) -> 2.9055112 | V19: =((DataQ!AI192/DataQ!AI188)-1)*100 -> 4.654965 | W19: =100*((DataQ!AR188+DataQ!AS188)/(DataQ!AT188+DataQ!AU188)) -> 98.162564 | X19: =100*((DataQ!AK192-DataQ!AK188)/DataQ!AI188) -> 3.2664199 | Y19: =1000*(DataQ!AK192/DataQ!AM192) -> 8102.4251 | Z19: =(Y19*DataQ!AM192)/1000 -> 224186 | AC19: =N19 -> -1.7494537 | AD19: =O19 -> -1.053786 | AE19: =X19 -> 3.2664199 | AF19: =V19-AD19-AE19-AG19-AH19 -> 1.839939 | AG19: =100*((DataQ!AP192-DataQ!AP188)/DataQ!AI192) -> 0.044556171 | AH19: =S19 -> 0.5578359 | AI19: =SUM(AC19:AH19) -> 2.9055112 | AQ19: =(DataQ!N130/DataQ!P130)*100 -> 4.7074177 | AR19: =DataQ!Q130 -> 4.806667 | AS19: =DataQ!AF130 -> 3.651515 | AV19: =(DataQ!O130/DataQ!P130)*100 -> 3.6046058 | AW19: =(DataQ!N130/DataQ!P130)*100 -> 4.7074177 | AX19: =(DataQ!AG130/DataQ!P130)*100 -> -1.1028119 | BA19: =((DataQ!E182/DataQ!E178)-1)*100 -> 1.1964108 | BB19: =((DataQ!D182/DataQ!D178)-1)*100 -> 2.4742268 | BC19: =BB19-BA19 -> 1.277816 | BE19: 2025 | BF19: =((DataA!B59/DataA!B58)-1)*100 -> 4.09111 | BG19: =-((DataA!E59/DataA!E58)-1)*100 -> -2.1044183 | BH19: =BI19-BF19-BG19 -> 0.188089 | BI19: =((DataA!L59/DataA!L58)-1)*100 -> 2.1747807
A20: 2019 | B20: =100*(F20/$H20) -> 97.389031 | C20: =100*(G20/H20) -> 99.251344 | D20: 100 | F20: =100*(J20/AVERAGE($J$28:$J$31)) -> 94.407997 | G20: =100*(K20/AVERAGE($K$28:$K$31)) -> 96.213306 | H20: =100*(DataQ!I191/AVERAGE(DataQ!I$199:I$202)) -> 96.939046 | J20: =DataQ!F191/DataQ!J191 -> 7.9980792 | K20: =(DataQ!F191-DataQ!G191-DataQ!H191)/DataQ!J191 -> 5.5464792 | M20: 2019 03 | N20: =((W24/W20)-1)*-100 -> -1.5658765 | O20: =-100*((DataQ!AN193+DataQ!AO193)-(DataQ!AN189+DataQ!AO189))/DataQ!AI189 -> -0.6113836 | P20: =V20-O20-Q20-R20-S20 -> 2.2436409 | Q20: =X20-R20 -> 2.1367662 | R20: =100*((Z20-Z19)/DataQ!AI191) -> -0.17800039 | S20: =100*((DataQ!AQ193-DataQ!AQ189)/DataQ!AI189) -> 0.55919927 | T20: =SUM(N20:S20) -> 2.5843459 | V20: =((DataQ!AI193/DataQ!AI189)-1)*100 -> 4.1502224 | W20: =100*((DataQ!AR189+DataQ!AS189)/(DataQ!AT189+DataQ!AU189)) -> 98.74048 | X20: =100*((DataQ!AK193-DataQ!AK189)/DataQ!AI189) -> 1.9587658 | Y20: =1000*(DataQ!AK193/DataQ!AM193) -> 8093.845 | Z20: =(Y20*DataQ!AM193)/1000 -> 223552 | AC20: =N20 -> -1.5658765 | AD20: =O20 -> -0.6113836 | AE20: =X20 -> 1.9587658 | AF20: =V20-AD20-AE20-AG20-AH20 -> 2.2524024 | AG20: =100*((DataQ!AP193-DataQ!AP189)/DataQ!AI193) -> -0.0087615063 | AH20: =S20 -> 0.55919927 | AI20: =SUM(AC20:AH20) -> 2.5843459 | AP20: 2004 | AQ20: =(DataQ!N131/DataQ!P131)*100 -> 5.2115924 | AR20: =DataQ!Q131 -> 4.983333 | AS20: =DataQ!AF131 -> 3.903846 | AU20: 2004 | AV20: =(DataQ!O131/DataQ!P131)*100 -> 3.8180392 | AW20: =(DataQ!N131/DataQ!P131)*100 -> 5.2115924 | AX20: =(DataQ!AG131/DataQ!P131)*100 -> -1.3935532 | AZ20: 2017 | BA20: =((DataQ!E183/DataQ!E179)-1)*100 -> 2.170277 | BB20: =((DataQ!D183/DataQ!D179)-1)*100 -> 2.1843073 | BC20: =BB20-BA20 -> 0.014030333 | BE20: 2026 | BF20: =((DataA!B60/DataA!B59)-1)*100 -> 4.1649463 | BG20: =-((DataA!E60/DataA!E59)-1)*100 -> -2.1990121 | BH20: =BI20-BF20-BG20 -> 0.26466546 | BI20: =((DataA!L60/DataA!L59)-1)*100 -> 2.2305997
B21: =100*(F21/$H21) -> 98.207555 | C21: =100*(G21/H21) -> 100.79257 | D21: 100 | F21: =100*(J21/AVERAGE($J$28:$J$31)) -> 95.639678 | G21: =100*(K21/AVERAGE($K$28:$K$31)) -> 98.157105 | H21: =100*(DataQ!I192/AVERAGE(DataQ!I$199:I$202)) -> 97.385255 | J21: =DataQ!F192/DataQ!J192 -> 8.1024251 | K21: =(DataQ!F192-DataQ!G192-DataQ!H192)/DataQ!J192 -> 5.6585348 | M21: 2019 04 | N21: =((W25/W21)-1)*-100 -> -1.2057514 | O21: =-100*((DataQ!AN194+DataQ!AO194)-(DataQ!AN190+DataQ!AO190))/DataQ!AI190 -> 0.0075714238 | P21: =V21-O21-Q21-R21-S21 -> 1.5468138 | Q21: =X21-R21 -> 1.1318764 | R21: =100*((Z21-Z20)/DataQ!AI192) -> 0.10478951 | S21: =100*((DataQ!AQ194-DataQ!AQ190)/DataQ!AI190) -> 0.39427488 | T21: =SUM(N21:S21) -> 1.9795746 | V21: =((DataQ!AI194/DataQ!AI190)-1)*100 -> 3.185326 | W21: =100*((DataQ!AR190+DataQ!AS190)/(DataQ!AT190+DataQ!AU190)) -> 99.285766 | X21: =100*((DataQ!AK194-DataQ!AK190)/DataQ!AI190) -> 1.2366659 | Y21: =1000*(DataQ!AK194/DataQ!AM194) -> 8076.6429 | Z21: =(Y21*DataQ!AM194)/1000 -> 223933 | AC21: =N21 -> -1.2057514 | AD21: =O21 -> 0.0075714238 | AE21: =X21 -> 1.2366659 | AF21: =V21-AD21-AE21-AG21-AH21 -> 1.4739804 | AG21: =100*((DataQ!AP194-DataQ!AP190)/DataQ!AI194) -> 0.07283341 | AH21: =S21 -> 0.39427488 | AI21: =SUM(AC21:AH21) -> 1.9795746 | AQ21: =(DataQ!N132/DataQ!P132)*100 -> 5.6404989 | AR21: =DataQ!Q132 -> 5.103333 | AS21: =DataQ!AF132 -> 4.211538 | AV21: =(DataQ!O132/DataQ!P132)*100 -> 4.2882115 | AW21: =(DataQ!N132/DataQ!P132)*100 -> 5.6404989 | AX21: =(DataQ!AG132/DataQ!P132)*100 -> -1.3522873 | BA21: =((DataQ!E184/DataQ!E180)-1)*100 -> 2.7556773 | BB21: =((DataQ!D184/DataQ!D180)-1)*100 -> 2.1606886 | BC21: =BB21-BA21 -> -0.59498871
B22: =100*(F22/$H22) -> 97.728172 | C22: =100*(G22/H22) -> 99.983057 | D22: 100 | F22: =100*(J22/AVERAGE($J$28:$J$31)) -> 95.538401 | G22: =100*(K22/AVERAGE($K$28:$K$31)) -> 97.742761 | H22: =100*(DataQ!I193/AVERAGE(DataQ!I$199:I$202)) -> 97.759324 | J22: =DataQ!F193/DataQ!J193 -> 8.093845 | K22: =(DataQ!F193-DataQ!G193-DataQ!H193)/DataQ!J193 -> 5.6346488 | M22: 2020 01 | N22: =((W26/W22)-1)*-100 -> -0.76748488 | O22: =-100*((DataQ!AN195+DataQ!AO195)-(DataQ!AN191+DataQ!AO191))/DataQ!AI191 -> -0.26531603 | P22: =V22-O22-Q22-R22-S22 -> -0.34308592 | Q22: =X22-R22 -> 0.91936277 | R22: =100*((Z22-Z21)/DataQ!AI193) -> 0.35976935 | S22: =100*((DataQ!AQ195-DataQ!AQ191)/DataQ!AI191) -> 0.99528608 | T22: =SUM(N22:S22) -> 0.89853136 | V22: =((DataQ!AI195/DataQ!AI191)-1)*100 -> 1.6660162 | W22: =100*((DataQ!AR191+DataQ!AS191)/(DataQ!AT191+DataQ!AU191)) -> 99.352336 | X22: =100*((DataQ!AK195-DataQ!AK191)/DataQ!AI191) -> 1.2791321 | Y22: =1000*(DataQ!AK195/DataQ!AM195) -> 8091.6406 | Z22: =(Y22*DataQ!AM195)/1000 -> 225247 | AB22: 2020 | AC22: =N26 -> -1.71951 | AD22: =O22 -> -0.26531603 | AE22: =X22 -> 1.2791321 | AF22: =V22-AD22-AE22-AG22-AH22 -> -0.44940632 | AG22: =100*((DataQ!AP195-DataQ!AP191)/DataQ!AI195) -> 0.1063204 | AH22: =S22 -> 0.99528608 | AI22: =SUM(AC22:AH22) -> -0.053493787 | AQ22: =(DataQ!N133/DataQ!P133)*100 -> 6.2995609 | AR22: =DataQ!Q133 -> 5.463333 | AS22: =DataQ!AF133 -> 4.655303 | AV22: =(DataQ!O133/DataQ!P133)*100 -> 4.9669167 | AW22: =(DataQ!N133/DataQ!P133)*100 -> 6.2995609 | AX22: =(DataQ!AG133/DataQ!P133)*100 -> -1.3326442 | BA22: =((DataQ!E185/DataQ!E181)-1)*100 -> 2.8089548 | BB22: =((DataQ!D185/DataQ!D181)-1)*100 -> 2.3569091 | BC22: =BB22-BA22 -> -0.4520457
B23: =100*(F23/$H23) -> 97.363932 | C23: =100*(G23/H23) -> 100.11057 | D23: 100 | F23: =100*(J23/AVERAGE($J$28:$J$31)) -> 95.335349 | G23: =100*(K23/AVERAGE($K$28:$K$31)) -> 98.024758 | H23: =100*(DataQ!I194/AVERAGE(DataQ!I$199:I$202)) -> 97.916495 | J23: =DataQ!F194/DataQ!J194 -> 8.0766429 | K23: =(DataQ!F194-DataQ!G194-DataQ!H194)/DataQ!J194 -> 5.6509053 | M23: 2020 02 | N23: =((W27/W23)-1)*-100 -> -0.95483806 | O23: =-100*((DataQ!AN196+DataQ!AO196)-(DataQ!AN192+DataQ!AO192))/DataQ!AI192 -> 0.96785905 | P23: =V23-O23-Q23-R23-S23 -> -2.6783209 | Q23: =X23-R23 -> 0.26676448 | R23: =100*((Z23-Z22)/DataQ!AI194) -> -2.0809157 | S23: =100*((DataQ!AQ196-DataQ!AQ192)/DataQ!AI192) -> 1.494282 | T23: =SUM(N23:S23) -> -2.9851693 | V23: =((DataQ!AI196/DataQ!AI192)-1)*100 -> -2.0303312 | W23: =100*((DataQ!AR192+DataQ!AS192)/(DataQ!AT192+DataQ!AU192)) -> 99.879872 | X23: =100*((DataQ!AK196-DataQ!AK192)/DataQ!AI192) -> -1.8141513 | Y23: =1000*(DataQ!AK196/DataQ!AM196) -> 7847.5854 | Z23: =(Y23*DataQ!AM196)/1000 -> 217590 | AB23: 2020 02 | AC23: =N27 -> -1.0241449 | AD23: =O23 -> 0.96785905 | AE23: =X23 -> -1.8141513 | AF23: =V23-AD23-AE23-AG23-AH23 -> -2.7656305 | AG23: =100*((DataQ!AP196-DataQ!AP192)/DataQ!AI196) -> 0.087309519 | AH23: =S23 -> 1.494282 | AI23: =SUM(AC23:AH23) -> -3.0544761 | AQ23: =(DataQ!N134/DataQ!P134)*100 -> 6.4537855 | AR23: =DataQ!Q134 -> 5.573333 | AS23: =DataQ!AF134 -> 4.75 | AV23: =(DataQ!O134/DataQ!P134)*100 -> 5.0730722 | AW23: =(DataQ!N134/DataQ!P134)*100 -> 6.4537855 | AX23: =(DataQ!AG134/DataQ!P134)*100 -> -1.3807134 | BA23: =((DataQ!E186/DataQ!E182)-1)*100 -> 3.0213793 | BB23: =((DataQ!D186/DataQ!D182)-1)*100 -> 2.6827565 | BC23: =BB23-BA23 -> -0.33862277
A24: 2020 | B24: =100*(F24/$H24) -> 98.083586 | C24: =100*(G24/H24) -> 100.24812 | D24: 100 | F24: =100*(J24/AVERAGE($J$28:$J$31)) -> 95.51238 | G24: =100*(K24/AVERAGE($K$28:$K$31)) -> 97.620175 | H24: =100*(DataQ!I195/AVERAGE(DataQ!I$199:I$202)) -> 97.378557 | J24: =DataQ!F195/DataQ!J195 -> 8.0916406 | K24: =(DataQ!F195-DataQ!G195-DataQ!H195)/DataQ!J195 -> 5.627582 | M24: 2020 03 | N24: =((W28/W24)-1)*-100 -> -0.43518509 | O24: =-100*((DataQ!AN197+DataQ!AO197)-(DataQ!AN193+DataQ!AO193))/DataQ!AI193 -> 0.86656773 | P24: =V24-O24-Q24-R24-S24 -> -1.7060296 | Q24: =X24-R24 -> -1.6441631 | R24: =100*((Z24-Z23)/DataQ!AI195) -> 1.3791275 | S24: =100*((DataQ!AQ197-DataQ!AQ193)/DataQ!AI193) -> 1.669067 | T24: =SUM(N24:S24) -> 0.12938448 | V24: =((DataQ!AI197/DataQ!AI193)-1)*100 -> 0.56456956 | W24: =100*((DataQ!AR193+DataQ!AS193)/(DataQ!AT193+DataQ!AU193)) -> 100.28663 | X24: =100*((DataQ!AK197-DataQ!AK193)/DataQ!AI193) -> -0.26503557 | Y24: =1000*(DataQ!AK197/DataQ!AM197) -> 8025.9619 | Z24: =(Y24*DataQ!AM197)/1000 -> 222584 | AB24: 2020 03 | AC24: =N28 -> -2.3665684 | AD24: =O24 -> 0.86656773 | AE24: =X24 -> -0.26503557 | AF24: =V24-AD24-AE24-AG24-AH24 -> -1.8465157 | AG24: =100*((DataQ!AP197-DataQ!AP193)/DataQ!AI197) -> 0.14048615 | AH24: =S24 -> 1.669067 | AI24: =SUM(AC24:AH24) -> -1.8019989 | AP24: 2005 | AQ24: =(DataQ!N135/DataQ!P135)*100 -> 6.3325732 | AR24: =DataQ!Q135 -> 5.53 | AS24: =DataQ!AF135 -> 4.75 | AU24: 2005 | AV24: =(DataQ!O135/DataQ!P135)*100 -> 4.6846509 | AW24: =(DataQ!N135/DataQ!P135)*100 -> 6.3325732 | AX24: =(DataQ!AG135/DataQ!P135)*100 -> -1.6479223 | AZ24: 2018 | BA24: =((DataQ!E187/DataQ!E183)-1)*100 -> 2.712451 | BB24: =((DataQ!D187/DataQ!D183)-1)*100 -> 2.6052104 | BC24: =BB24-BA24 -> -0.10724056
B25: =100*(F25/$H25) -> 95.074737 | C25: =100*(G25/H25) -> 98.559417 | D25: 100 | F25: =100*(J25/AVERAGE($J$28:$J$31)) -> 92.631593 | G25: =100*(K25/AVERAGE($K$28:$K$31)) -> 96.026726 | H25: =100*(DataQ!I196/AVERAGE(DataQ!I$199:I$202)) -> 97.43029 | J25: =DataQ!F196/DataQ!J196 -> 7.8475854 | K25: =(DataQ!F196-DataQ!G196-DataQ!H196)/DataQ!J196 -> 5.5357233 | M25: 2020 04 | N25: =((W29/W25)-1)*-100 -> -0.23410065 | O25: =-100*((DataQ!AN198+DataQ!AO198)-(DataQ!AN194+DataQ!AO194))/DataQ!AI194 -> -1.3900854 | P25: =V25-O25-Q25-R25-S25 -> -1.5922797 | Q25: =X25-R25 -> -0.42363611 | R25: =100*((Z25-Z24)/DataQ!AI196) -> 1.7843708 | S25: =100*((DataQ!AQ198-DataQ!AQ194)/DataQ!AI194) -> 1.7004427 | T25: =SUM(N25:S25) -> -0.15528837 | V25: =((DataQ!AI198/DataQ!AI194)-1)*100 -> 0.078812272 | W25: =100*((DataQ!AR194+DataQ!AS194)/(DataQ!AT194+DataQ!AU194)) -> 100.48291 | X25: =100*((DataQ!AK198-DataQ!AK194)/DataQ!AI194) -> 1.3607346 | Y25: =1000*(DataQ!AK198/DataQ!AM198) -> 8261.7011 | Z25: =(Y25*DataQ!AM198)/1000 -> 228940 | AB25: 2020 04 | AC25: =N29 -> -3.7649328 | AD25: =O25 -> -1.3900854 | AE25: =X25 -> 1.3607346 | AF25: =V25-AD25-AE25-AG25-AH25 -> -1.5770727 | AG25: =100*((DataQ!AP198-DataQ!AP194)/DataQ!AI198) -> -0.015206937 | AH25: =S25 -> 1.7004427 | AI25: =SUM(AC25:AH25) -> -3.6861205 | AQ25: =(DataQ!N136/DataQ!P136)*100 -> 6.670821 | AR25: =DataQ!Q136 -> 5.503334 | AS25: =DataQ!AF136 -> 4.75 | AV25: =(DataQ!O136/DataQ!P136)*100 -> 4.8799541 | AW25: =(DataQ!N136/DataQ!P136)*100 -> 6.670821 | AX25: =(DataQ!AG136/DataQ!P136)*100 -> -1.7908668 | BA25: =((DataQ!E188/DataQ!E184)-1)*100 -> 2.4232625 | BB25: =((DataQ!D188/DataQ!D184)-1)*100 -> 2.445486 | BC25: =BB25-BA25 -> 0.022223406
B26: =100*(F26/$H26) -> 96.799624 | C26: =100*(G26/H26) -> 100.86789 | D26: 100 | F26: =100*(J26/AVERAGE($J$28:$J$31)) -> 94.737119 | G26: =100*(K26/AVERAGE($K$28:$K$31)) -> 98.718705 | H26: =100*(DataQ!I197/AVERAGE(DataQ!I$199:I$202)) -> 97.869304 | J26: =DataQ!F197/DataQ!J197 -> 8.0259619 | K26: =(DataQ!F197-DataQ!G197-DataQ!H197)/DataQ!J197 -> 5.6909097 | M26: 2021 01 | N26: =((W30/W26)-1)*-100 -> -1.71951 | O26: =-100*((DataQ!AN199+DataQ!AO199)-(DataQ!AN195+DataQ!AO195))/DataQ!AI195 -> -1.0858489 | P26: =V26-O26-Q26-R26-S26 -> 1.5456501 | Q26: =X26-R26 -> 1.0227545 | R26: =100*((Z26-Z25)/DataQ!AI197) -> 0.20310594 | S26: =100*((DataQ!AQ199-DataQ!AQ195)/DataQ!AI195) -> 1.5194152 | T26: =SUM(N26:S26) -> 1.4855668 | V26: =((DataQ!AI199/DataQ!AI195)-1)*100 -> 3.2050769 | W26: =100*((DataQ!AR195+DataQ!AS195)/(DataQ!AT195+DataQ!AU195)) -> 100.11485 | X26: =100*((DataQ!AK199-DataQ!AK195)/DataQ!AI195) -> 1.2258604 | Y26: =1000*(DataQ!AK199/DataQ!AM199) -> 8270.7141 | Z26: =(Y26*DataQ!AM199)/1000 -> 229686 | AB26: 2021 | AC26: =N30 -> -4.7942558 | AD26: =O26 -> -1.0858489 | AE26: =X26 -> 1.2258604 | AF26: =V26-AD26-AE26-AG26-AH26 -> 1.5036399 | AG26: =100*((DataQ!AP199-DataQ!AP195)/DataQ!AI199) -> 0.042010173 | AH26: =S26 -> 1.5194152 | AI26: =SUM(AC26:AH26) -> -1.5891789 | AQ26: =(DataQ!N137/DataQ!P137)*100 -> 6.6230333 | AR26: =DataQ!Q137 -> 5.476666 | AS26: =DataQ!AF137 -> 4.590909 | AV26: =(DataQ!O137/DataQ!P137)*100 -> 5.0670329 | AW26: =(DataQ!N137/DataQ!P137)*100 -> 6.6230333 | AX26: =(DataQ!AG137/DataQ!P137)*100 -> -1.5560004 | BA26: =((DataQ!E189/DataQ!E185)-1)*100 -> 2.5072324 | BB26: =((DataQ!D189/DataQ!D185)-1)*100 -> 3.0920919 | BC26: =BB26-BA26 -> 0.5848595
B27: =100*(F27/$H27) -> 99.581324 | C27: =100*(G27/H27) -> 100.08216 | D27: 100 | F27: =100*(J27/AVERAGE($J$28:$J$31)) -> 97.519746 | G27: =100*(K27/AVERAGE($K$28:$K$31)) -> 98.010212 | H27: =100*(DataQ!I198/AVERAGE(DataQ!I$199:I$202)) -> 97.929755 | J27: =DataQ!F198/DataQ!J198 -> 8.2617011 | K27: =(DataQ!F198-DataQ!G198-DataQ!H198)/DataQ!J198 -> 5.6500668 | M27: 2021 02 | N27: =((W31/W27)-1)*-100 -> -1.0241449 | O27: =-100*((DataQ!AN200+DataQ!AO200)-(DataQ!AN196+DataQ!AO196))/DataQ!AI196 -> -3.2051858 | P27: =V27-O27-Q27-R27-S27 -> 2.9109724 | Q27: =X27-R27 -> 3.4589209 | R27: =100*((Z27-Z26)/DataQ!AI198) -> 1.8658368 | S27: =100*((DataQ!AQ200-DataQ!AQ196)/DataQ!AI196) -> 0.40819306 | T27: =SUM(N27:S27) -> 4.4145924 | V27: =((DataQ!AI200/DataQ!AI196)-1)*100 -> 5.4387374 | W27: =100*((DataQ!AR196+DataQ!AS196)/(DataQ!AT196+DataQ!AU196)) -> 100.83356 | X27: =100*((DataQ!AK200-DataQ!AK196)/DataQ!AI196) -> 5.3247577 | Y27: =1000*(DataQ!AK200/DataQ!AM200) -> 8477.8339 | Z27: =(Y27*DataQ!AM200)/1000 -> 236557 | AB27: 2021 02 | AC27: =N31 -> -7.770287 | AD27: =O27 -> -3.2051858 | AE27: =X27 -> 5.3247577 | AF27: =V27-AD27-AE27-AG27-AH27 -> 2.81938 | AG27: =100*((DataQ!AP200-DataQ!AP196)/DataQ!AI200) -> 0.091592403 | AH27: =S27 -> 0.40819306 | AI27: =SUM(AC27:AH27) -> -2.3315496 | AQ27: =(DataQ!N138/DataQ!P138)*100 -> 6.5978371 | AR27: =DataQ!Q138 -> 5.35 | AS27: =DataQ!AF138 -> 4.5 | AV27: =(DataQ!O138/DataQ!P138)*100 -> 4.78819 | AW27: =(DataQ!N138/DataQ!P138)*100 -> 6.5978371 | AX27: =(DataQ!AG138/DataQ!P138)*100 -> -1.809647 | BA27: =((DataQ!E190/DataQ!E186)-1)*100 -> 2.2632444 | BB27: =((DataQ!D190/DataQ!D186)-1)*100 -> 3.4617964 | BC27: =BB27-BA27 -> 1.198552
A28: 2021 | B28: =100*(F28/$H28) -> 98.762031 | C28: =100*(G28/H28) -> 99.31108 | D28: 100 | F28: =100*(J28/AVERAGE($J$28:$J$31)) -> 97.626133 | G28: =100*(K28/AVERAGE($K$28:$K$31)) -> 98.168867 | H28: =100*(DataQ!I199/AVERAGE(DataQ!I$199:I$202)) -> 98.849864 | J28: =DataQ!F199/DataQ!J199 -> 8.2707141 | K28: =(DataQ!F199-DataQ!G199-DataQ!H199)/DataQ!J199 -> 5.6592128 | M28: 2021 03 | N28: =((W32/W28)-1)*-100 -> -2.3665684 | O28: =-100*((DataQ!AN201+DataQ!AO201)-(DataQ!AN197+DataQ!AO197))/DataQ!AI197 -> -3.1527705 | P28: =V28-O28-Q28-R28-S28 -> 1.1846032 | Q28: =X28-R28 -> 3.8196132 | R28: =100*((Z28-Z27)/DataQ!AI199) -> 0.87632687 | S28: =100*((DataQ!AQ201-DataQ!AQ197)/DataQ!AI197) -> 0.238772 | T28: =SUM(N28:S28) -> 0.59997626 | V28: =((DataQ!AI201/DataQ!AI197)-1)*100 -> 2.9665447 | W28: =100*((DataQ!AR197+DataQ!AS197)/(DataQ!AT197+DataQ!AU197)) -> 100.72307 | X28: =100*((DataQ!AK201-DataQ!AK197)/DataQ!AI197) -> 4.6959401 | Y28: =1000*(DataQ!AK201/DataQ!AM201) -> 8512.8314 | Z28: =(Y28*DataQ!AM201)/1000 -> 239832 | AB28: 2021 03 | AC28: =N32 -> -8.9569193 | AD28: =O28 -> -3.1527705 | AE28: =X28 -> 4.6959401 | AF28: =V28-AD28-AE28-AG28-AH28 -> 1.0973459 | AG28: =100*((DataQ!AP201-DataQ!AP197)/DataQ!AI201) -> 0.087257266 | AH28: =S28 -> 0.238772 | AI28: =SUM(AC28:AH28) -> -5.9903746 | AP28: 2006 | AQ28: =(DataQ!N139/DataQ!P139)*100 -> 6.624246 | AR28: =DataQ!Q139 -> 5.326667 | AS28: =DataQ!AF139 -> 4.5 | AU28: 2006 | AV28: =(DataQ!O139/DataQ!P139)*100 -> 4.7810343 | AW28: =(DataQ!N139/DataQ!P139)*100 -> 6.624246 | AX28: =(DataQ!AG139/DataQ!P139)*100 -> -1.8432117 | AZ28: 2019 | BA28: =((DataQ!E191/DataQ!E187)-1)*100 -> 1.8453383 | BB28: =((DataQ!D191/DataQ!D187)-1)*100 -> 3.2552148 | BC28: =BB28-BA28 -> 1.4098766
B29: =100*(F29/$H29) -> 100.97484 | C29: =100*(G29/H29) -> 101.01901 | D29: 100 | F29: =100*(J29/AVERAGE($J$28:$J$31)) -> 100.07094 | G29: =100*(K29/AVERAGE($K$28:$K$31)) -> 100.11472 | H29: =100*(DataQ!I200/AVERAGE(DataQ!I$199:I$202)) -> 99.104827 | J29: =DataQ!F200/DataQ!J200 -> 8.4778339 | K29: =(DataQ!F200-DataQ!G200-DataQ!H200)/DataQ!J200 -> 5.7713866 | M29: 2021 04 | N29: =((W33/W29)-1)*-100 -> -3.7649328 | O29: =-100*((DataQ!AN202+DataQ!AO202)-(DataQ!AN198+DataQ!AO198))/DataQ!AI198 -> -1.8283626 | P29: =V29-O29-Q29-R29-S29 -> 1.2912318 | Q29: =X29-R29 -> 2.9779089 | R29: =100*((Z29-Z28)/DataQ!AI200) -> 1.0136403 | S29: =100*((DataQ!AQ202-DataQ!AQ198)/DataQ!AI198) -> -0.065987242 | T29: =SUM(N29:S29) -> -0.37650149 | V29: =((DataQ!AI202/DataQ!AI198)-1)*100 -> 3.3884313 | W29: =100*((DataQ!AR198+DataQ!AS198)/(DataQ!AT198+DataQ!AU198)) -> 100.71814 | X29: =100*((DataQ!AK202-DataQ!AK198)/DataQ!AI198) -> 3.9915493 | Y29: =1000*(DataQ!AK202/DataQ!AM202) -> 8625.9161 | Z29: =(Y29*DataQ!AM202)/1000 -> 243639 | AB29: 2021 04 | AC29: =N33 -> -9.9682814 | AD29: =O29 -> -1.8283626 | AE29: =X29 -> 3.9915493 | AF29: =V29-AD29-AE29-AG29-AH29 -> 1.0897773 | AG29: =100*((DataQ!AP202-DataQ!AP198)/DataQ!AI202) -> 0.20145457 | AH29: =S29 -> -0.065987242 | AI29: =SUM(AC29:AH29) -> -6.5798501 | AQ29: =(DataQ!N140/DataQ!P140)*100 -> 6.6959106 | AR29: =DataQ!Q140 -> 5.31 | AS29: =DataQ!AF140 -> 4.5 | AV29: =(DataQ!O140/DataQ!P140)*100 -> 4.7506287 | AW29: =(DataQ!N140/DataQ!P140)*100 -> 6.6959106 | AX29: =(DataQ!AG140/DataQ!P140)*100 -> -1.9452819 | BA29: =((DataQ!E192/DataQ!E188)-1)*100 -> 2.0188953 | BB29: =((DataQ!D192/DataQ!D188)-1)*100 -> 3.9354772 | BC29: =BB29-BA29 -> 1.9165819
B30: =100*(F30/$H30) -> 100.14798 | C30: =100*(G30/H30) -> 100.33017 | D30: 100 | F30: =100*(J30/AVERAGE($J$28:$J$31)) -> 100.48405 | G30: =100*(K30/AVERAGE($K$28:$K$31)) -> 100.66685 | H30: =100*(DataQ!I201/AVERAGE(DataQ!I$199:I$202)) -> 100.33557 | J30: =DataQ!F201/DataQ!J201 -> 8.5128314 | K30: =(DataQ!F201-DataQ!G201-DataQ!H201)/DataQ!J201 -> 5.8032158 | M30: 2022 01 | N30: =((W34/W30)-1)*-100 -> -4.7942558 | O30: =-100*((DataQ!AN203+DataQ!AO203)-(DataQ!AN199+DataQ!AO199))/DataQ!AI199 -> -2.4406038 | P30: =V30-O30-Q30-R30-S30 -> 1.1182198 | Q30: =X30-R30 -> 3.7522512 | R30: =100*((Z30-Z29)/DataQ!AI201) -> 1.5621695 | S30: =100*((DataQ!AQ203-DataQ!AQ199)/DataQ!AI199) -> -0.064754535 | T30: =SUM(N30:S30) -> -0.86697353 | V30: =((DataQ!AI203/DataQ!AI199)-1)*100 -> 3.9272823 | W30: =100*((DataQ!AR199+DataQ!AS199)/(DataQ!AT199+DataQ!AU199)) -> 101.83633 | X30: =100*((DataQ!AK203-DataQ!AK199)/DataQ!AI199) -> 5.3144207 | Y30: =1000*(DataQ!AK203/DataQ!AM203) -> 8834.7731 | Z30: =(Y30*DataQ!AM203)/1000 -> 249547 | AB30: 2022 | AC30: =N34 -> -9.6638336 | AD30: =O30 -> -2.4406038 | AE30: =X30 -> 5.3144207 | AF30: =V30-AD30-AE30-AG30-AH30 -> 0.90349054 | AG30: =100*((DataQ!AP203-DataQ!AP199)/DataQ!AI203) -> 0.2147293 | AH30: =S30 -> -0.064754535 | AI30: =SUM(AC30:AH30) -> -5.7365513 | AQ30: =(DataQ!N141/DataQ!P141)*100 -> 6.8891299 | AR30: =DataQ!Q141 -> 5.33 | AS30: =DataQ!AF141 -> 4.661539 | AV30: =(DataQ!O141/DataQ!P141)*100 -> 5.2905637 | AW30: =(DataQ!N141/DataQ!P141)*100 -> 6.8891299 | AX30: =(DataQ!AG141/DataQ!P141)*100 -> -1.5985662 | BA30: =((DataQ!E193/DataQ!E189)-1)*100 -> 1.8501411 | BB30: =((DataQ!D193/DataQ!D189)-1)*100 -> 3.8289728 | BC30: =BB30-BA30 -> 1.9788317
B31: =100*(F31/$H31) -> 100.10731 | C31: =100*(G31/H31) -> 99.350928 | D31: 100 | F31: =100*(J31/AVERAGE($J$28:$J$31)) -> 101.81888 | G31: =100*(K31/AVERAGE($K$28:$K$31)) -> 101.04957 | H31: =100*(DataQ!I202/AVERAGE(DataQ!I$199:I$202)) -> 101.70974 | J31: =DataQ!F202/DataQ!J202 -> 8.6259161 | K31: =(DataQ!F202-DataQ!G202-DataQ!H202)/DataQ!J202 -> 5.8252788 | M31: 2022 02 | N31: =((W35/W31)-1)*-100 -> -7.770287 | O31: =-100*((DataQ!AN204+DataQ!AO204)-(DataQ!AN200+DataQ!AO200))/DataQ!AI200 -> -1.7594262 | P31: =V31-O31-Q31-R31-S31 -> 2.1747871 | Q31: =X31-R31 -> 3.4664636 | R31: =100*((Z31-Z30)/DataQ!AI202) -> 0.56732969 | S31: =100*((DataQ!AQ204-DataQ!AQ200)/DataQ!AI200) -> 0.69067062 | T31: =SUM(N31:S31) -> -2.6304621 | V31: =((DataQ!AI204/DataQ!AI200)-1)*100 -> 5.1398249 | W31: =100*((DataQ!AR200+DataQ!AS200)/(DataQ!AT200+DataQ!AU200)) -> 101.86625 | X31: =100*((DataQ!AK204-DataQ!AK200)/DataQ!AI200) -> 4.0337933 | Y31: =1000*(DataQ!AK204/DataQ!AM204) -> 8870.4187 | Z31: =(Y31*DataQ!AM204)/1000 -> 251707 | AB31: 2022 02 | AC31: =N35 -> -8.0213928 | AD31: =O31 -> -1.7594262 | AE31: =X31 -> 4.0337933 | AF31: =V31-AD31-AE31-AG31-AH31 -> 2.0628546 | AG31: =100*((DataQ!AP204-DataQ!AP200)/DataQ!AI204) -> 0.11193246 | AH31: =S31 -> 0.69067062 | AI31: =SUM(AC31:AH31) -> -2.881568 | AQ31: =(DataQ!N142/DataQ!P142)*100 -> 7.2942365 | AR31: =DataQ!Q142 -> 5.45 | AS31: =DataQ!AF142 -> 4.892308 | AV31: =(DataQ!O142/DataQ!P142)*100 -> 5.5256178 | AW31: =(DataQ!N142/DataQ!P142)*100 -> 7.2942365 | AX31: =(DataQ!AG142/DataQ!P142)*100 -> -1.7686187 | BA31: =((DataQ!E194/DataQ!E190)-1)*100 -> 1.4027436 | BB31: =((DataQ!D194/DataQ!D190)-1)*100 -> 2.7146402 | BC31: =BB31-BA31 -> 1.3118966
A32: 2022 | B32: =100*(F32/$H32) -> 100.20082 | C32: =100*(G32/H32) -> 99.076225 | D32: 100 | F32: =100*(J32/AVERAGE($J$28:$J$31)) -> 104.28419 | G32: =100*(K32/AVERAGE($K$28:$K$31)) -> 103.11377 | H32: =100*(DataQ!I203/AVERAGE(DataQ!I$199:I$202)) -> 104.07519 | J32: =DataQ!F203/DataQ!J203 -> 8.8347731 | K32: =(DataQ!F203-DataQ!G203-DataQ!H203)/DataQ!J203 -> 5.9442753 | M32: 2022 03 | N32: =((W36/W32)-1)*-100 -> -8.9569193 | O32: =-100*((DataQ!AN205+DataQ!AO205)-(DataQ!AN201+DataQ!AO201))/DataQ!AI201 -> -2.3437831 | P32: =V32-O32-Q32-R32-S32 -> 2.3049139 | Q32: =X32-R32 -> 3.171853 | R32: =100*((Z32-Z31)/DataQ!AI203) -> 1.1828134 | S32: =100*((DataQ!AQ205-DataQ!AQ201)/DataQ!AI201) -> 2.0746076 | T32: =SUM(N32:S32) -> -2.5665144 | V32: =((DataQ!AI205/DataQ!AI201)-1)*100 -> 6.3904049 | W32: =100*((DataQ!AR201+DataQ!AS201)/(DataQ!AT201+DataQ!AU201)) -> 103.10675 | X32: =100*((DataQ!AK205-DataQ!AK201)/DataQ!AI201) -> 4.3546664 | Y32: =1000*(DataQ!AK205/DataQ!AM205) -> 8982.9314 | Z32: =(Y32*DataQ!AM205)/1000 -> 256301 | AB32: 2022 03 | AC32: =N36 -> -6.2151367 | AD32: =O32 -> -2.3437831 | AE32: =X32 -> 4.3546664 | AF32: =V32-AD32-AE32-AG32-AH32 -> 2.2390525 | AG32: =100*((DataQ!AP205-DataQ!AP201)/DataQ!AI205) -> 0.065861418 | AH32: =S32 -> 2.0746076 | AI32: =SUM(AC32:AH32) -> 0.17526817 | AP32: 2007 | AQ32: =(DataQ!N143/DataQ!P143)*100 -> 7.5613869 | AR32: =DataQ!Q143 -> 5.623333 | AS32: =DataQ!AF143 -> 5.219231 | AU32: 2007 | AV32: =(DataQ!O143/DataQ!P143)*100 -> 5.4106856 | AW32: =(DataQ!N143/DataQ!P143)*100 -> 7.5613869 | AX32: =(DataQ!AG143/DataQ!P143)*100 -> -2.1507013 | AZ32: 2020 | BA32: =((DataQ!E195/DataQ!E191)-1)*100 -> 1.6557638 | BB32: =((DataQ!D195/DataQ!D191)-1)*100 -> 2.2067968 | BC32: =BB32-BA32 -> 0.55103301
B33: =100*(F33/$H33) -> 97.676192 | C33: =100*(G33/H33) -> 96.708642 | D33: 100 | F33: =100*(J33/AVERAGE($J$28:$J$31)) -> 104.70495 | G33: =100*(K33/AVERAGE($K$28:$K$31)) -> 103.66777 | H33: =100*(DataQ!I204/AVERAGE(DataQ!I$199:I$202)) -> 107.19598 | J33: =DataQ!F204/DataQ!J204 -> 8.8704187 | K33: =(DataQ!F204-DataQ!G204-DataQ!H204)/DataQ!J204 -> 5.9762123 | M33: 2022 04 | N33: =((W37/W33)-1)*-100 -> -9.9682814 | O33: =-100*((DataQ!AN206+DataQ!AO206)-(DataQ!AN202+DataQ!AO202))/DataQ!AI202 -> -2.0119192 | P33: =V33-O33-Q33-R33-S33 -> 5.1734689 | Q33: =X33-R33 -> 3.379976 | R33: =100*((Z33-Z32)/DataQ!AI204) -> 1.4601867 | S33: =100*((DataQ!AQ206-DataQ!AQ202)/DataQ!AI202) -> 1.9026557 | T33: =SUM(N33:S33) -> -0.063913221 | V33: =((DataQ!AI206/DataQ!AI202)-1)*100 -> 9.9043682 | W33: =100*((DataQ!AR202+DataQ!AS202)/(DataQ!AT202+DataQ!AU202)) -> 104.51011 | X33: =100*((DataQ!AK206-DataQ!AK202)/DataQ!AI202) -> 4.8401627 | Y33: =1000*(DataQ!AK206/DataQ!AM206) -> 9152.6211 | Z33: =(Y33*DataQ!AM206)/1000 -> 262067 | AB33: 2022 04 | AC33: =N37 -> -4.3632095 | AD33: =O33 -> -2.0119192 | AE33: =X33 -> 4.8401627 | AF33: =V33-AD33-AE33-AG33-AH33 -> 4.8747403 | AG33: =100*((DataQ!AP206-DataQ!AP202)/DataQ!AI206) -> 0.29872861 | AH33: =S33 -> 1.9026557 | AI33: =SUM(AC33:AH33) -> 5.5411586 | AQ33: =(DataQ!N144/DataQ!P144)*100 -> 7.9824457 | AR33: =DataQ!Q144 -> 5.703333 | AS33: =DataQ!AF144 -> 5.392308 | AV33: =(DataQ!O144/DataQ!P144)*100 -> 5.7448088 | AW33: =(DataQ!N144/DataQ!P144)*100 -> 7.9824457 | AX33: =(DataQ!AG144/DataQ!P144)*100 -> -2.237637 | BA33: =((DataQ!E196/DataQ!E192)-1)*100 -> 0.68024119 | BB33: =((DataQ!D196/DataQ!D192)-1)*100 -> -1.1173184 | BC33: =BB33-BA33 -> -1.7975596
B34: =100*(F34/$H34) -> 96.62801 | C34: =100*(G34/H34) -> 94.797061 | D34: 100 | F34: =100*(J34/AVERAGE($J$28:$J$31)) -> 106.03303 | G34: =100*(K34/AVERAGE($K$28:$K$31)) -> 104.02387 | H34: =100*(DataQ!I205/AVERAGE(DataQ!I$199:I$202)) -> 109.73322 | J34: =DataQ!F205/DataQ!J205 -> 8.9829314 | K34: =(DataQ!F205-DataQ!G205-DataQ!H205)/DataQ!J205 -> 5.9967405 | M34: 2023 01 | N34: =((W38/W34)-1)*-100 -> -9.6638336 | O34: =-100*((DataQ!AN207+DataQ!AO207)-(DataQ!AN203+DataQ!AO203))/DataQ!AI203 -> -2.61048 | P34: =V34-O34-Q34-R34-S34 -> 6.1921338 | Q34: =X34-R34 -> 3.2713014 | R34: =100*((Z34-Z33)/DataQ!AI205) -> 1.329158 | S34: =100*((DataQ!AQ207-DataQ!AQ203)/DataQ!AI203) -> 0.96113245 | T34: =SUM(N34:S34) -> -0.520588 | V34: =((DataQ!AI207/DataQ!AI203)-1)*100 -> 9.1432456 | W34: =100*((DataQ!AR203+DataQ!AS203)/(DataQ!AT203+DataQ!AU203)) -> 106.71863 | X34: =100*((DataQ!AK207-DataQ!AK203)/DataQ!AI203) -> 4.6004593 | Y34: =1000*(DataQ!AK207/DataQ!AM207) -> 9328.6472 | Z34: =(Y34*DataQ!AM207)/1000 -> 267415 | AB34: 2023 | AC34: =N38 -> -2.9376676 | AD34: =O34 -> -2.61048 | AE34: =X34 -> 4.6004593 | AF34: =V34-AD34-AE34-AG34-AH34 -> 5.8953713 | AG34: =100*((DataQ!AP207-DataQ!AP203)/DataQ!AI207) -> 0.29676251 | AH34: =S34 -> 0.96113245 | AI34: =SUM(AC34:AH34) -> 6.205578 | AQ34: =(DataQ!N145/DataQ!P145)*100 -> 8.1673707 | AR34: =DataQ!Q145 -> 5.883333 | AS34: =DataQ!AF145 -> 5.738461 | AV34: =(DataQ!O145/DataQ!P145)*100 -> 6.2496989 | AW34: =(DataQ!N145/DataQ!P145)*100 -> 8.1673707 | AX34: =(DataQ!AG145/DataQ!P145)*100 -> -1.9176718 | BA34: =((DataQ!E197/DataQ!E193)-1)*100 -> 0.61570178 | BB34: =((DataQ!D197/DataQ!D193)-1)*100 -> 1.4751077 | BC34: =BB34-BA34 -> 0.85940587
B35: =100*(F35/$H35) -> 96.191591 | C35: =100*(G35/H35) -> 94.560288 | D35: 100 | F35: =100*(J35/AVERAGE($J$28:$J$31)) -> 108.03602 | G35: =100*(K35/AVERAGE($K$28:$K$31)) -> 106.20385 | H35: =100*(DataQ!I206/AVERAGE(DataQ!I$199:I$202)) -> 112.31337 | J35: =DataQ!F206/DataQ!J206 -> 9.1526211 | K35: =(DataQ!F206-DataQ!G206-DataQ!H206)/DataQ!J206 -> 6.1224112 | M35: 2023 02 | N35: =((W39/W35)-1)*-100 -> -8.0213928 | O35: =-100*((DataQ!AN208+DataQ!AO208)-(DataQ!AN204+DataQ!AO204))/DataQ!AI204 -> -1.5457821 | P35: =V35-O35-Q35-R35-S35 -> 4.1516305 | Q35: =X35-R35 -> 4.0574809 | R35: =100*((Z35-Z34)/DataQ!AI206) -> 1.3337635 | S35: =100*((DataQ!AQ208-DataQ!AQ204)/DataQ!AI204) -> 3.0216698 | T35: =SUM(N35:S35) -> 2.9973698 | V35: =((DataQ!AI208/DataQ!AI204)-1)*100 -> 11.018763 | W35: =100*((DataQ!AR204+DataQ!AS204)/(DataQ!AT204+DataQ!AU204)) -> 109.78154 | X35: =100*((DataQ!AK208-DataQ!AK204)/DataQ!AI204) -> 5.3912445 | Y35: =1000*(DataQ!AK208/DataQ!AM208) -> 9516.0346 | Z35: =(Y35*DataQ!AM208)/1000 -> 272996 | AB35: 2023 02 | AC35: =N39 -> -2.0465873 | AD35: =O35 -> -1.5457821 | AE35: =X35 -> 5.3912445 | AF35: =V35-AD35-AE35-AG35-AH35 -> 3.8959233 | AG35: =100*((DataQ!AP208-DataQ!AP204)/DataQ!AI208) -> 0.25570722 | AH35: =S35 -> 3.0216698 | AI35: =SUM(AC35:AH35) -> 8.9721753 | AQ35: =(DataQ!N146/DataQ!P146)*100 -> 8.8841006 | AR35: =DataQ!Q146 -> 5.95 | AS35: =DataQ!AF146 -> 5.681818 | AV35: =(DataQ!O146/DataQ!P146)*100 -> 6.1089706 | AW35: =(DataQ!N146/DataQ!P146)*100 -> 8.8841006 | AX35: =(DataQ!AG146/DataQ!P146)*100 -> -2.7751296 | BA35: =((DataQ!E198/DataQ!E194)-1)*100 -> 0.5841379 | BB35: =((DataQ!D198/DataQ!D194)-1)*100 -> 4.5482547 | BC35: =BB35-BA35 -> 3.9641168
A36: 2023 | B36: =100*(F36/$H36) -> 96.255397 | C36: =100*(G36/H36) -> 92.904162 | D36: 100 | F36: =100*(J36/AVERAGE($J$28:$J$31)) -> 110.1138 | G36: =100*(K36/AVERAGE($K$28:$K$31)) -> 106.28007 | H36: =100*(DataQ!I207/AVERAGE(DataQ!I$199:I$202)) -> 114.39753 | J36: =DataQ!F207/DataQ!J207 -> 9.3286472 | K36: =(DataQ!F207-DataQ!G207-DataQ!H207)/DataQ!J207 -> 6.1268053 | M36: 2023 03 | N36: =((W40/W36)-1)*-100 -> -6.2151367 | O36: =-100*((DataQ!AN209+DataQ!AO209)-(DataQ!AN205+DataQ!AO205))/DataQ!AI205 -> -1.4971667 | P36: =V36-O36-Q36-R36-S36 -> 4.9505418 | Q36: =X36-R36 -> 4.2076736 | R36: =100*((Z36-Z35)/DataQ!AI207) -> 1.0905668 | S36: =100*((DataQ!AQ209-DataQ!AQ205)/DataQ!AI205) -> 1.3656924 | T36: =SUM(N36:S36) -> 3.9021712 | V36: =((DataQ!AI209/DataQ!AI205)-1)*100 -> 10.117308 | W36: =100*((DataQ!AR205+DataQ!AS205)/(DataQ!AT205+DataQ!AU205)) -> 112.34193 | X36: =100*((DataQ!AK209-DataQ!AK205)/DataQ!AI205) -> 5.2982404 | Y36: =1000*(DataQ!AK209/DataQ!AM209) -> 9695.7706 | Z36: =(Y36*DataQ!AM209)/1000 -> 277619 | AB36: 2023 03 | AC36: =N40 -> -1.8774803 | AD36: =O36 -> -1.4971667 | AE36: =X36 -> 5.2982404 | AF36: =V36-AD36-AE36-AG36-AH36 -> 4.5975486 | AG36: =100*((DataQ!AP209-DataQ!AP205)/DataQ!AI209) -> 0.35299322 | AH36: =S36 -> 1.3656924 | AI36: =SUM(AC36:AH36) -> 8.2398276 | AP36: 2008 | AQ36: =(DataQ!N147/DataQ!P147)*100 -> 9.2970603 | AR36: =DataQ!Q147 -> 5.856667 | AS36: =DataQ!AF147 -> 5.353846 | AU36: 2008 | AV36: =(DataQ!O147/DataQ!P147)*100 -> 6.7445888 | AW36: =(DataQ!N147/DataQ!P147)*100 -> 9.2970603 | AX36: =(DataQ!AG147/DataQ!P147)*100 -> -2.5524715 | AZ36: 2021 | BA36: =((DataQ!E199/DataQ!E195)-1)*100 -> 0.64535936 | BB36: =((DataQ!D199/DataQ!D195)-1)*100 -> 4.1949478 | BC36: =BB36-BA36 -> 3.5495885
B37: =100*(F37/$H37) -> 96.896549 | C37: =100*(G37/H37) -> 96.375967 | D37: 100 | F37: =100*(J37/AVERAGE($J$28:$J$31)) -> 112.32569 | G37: =100*(K37/AVERAGE($K$28:$K$31)) -> 111.72221 | H37: =100*(DataQ!I208/AVERAGE(DataQ!I$199:I$202)) -> 115.92331 | J37: =DataQ!F208/DataQ!J208 -> 9.5160346 | K37: =(DataQ!F208-DataQ!G208-DataQ!H208)/DataQ!J208 -> 6.4405326 | M37: 2023 04 | N37: =((W41/W37)-1)*-100 -> -4.3632095 | O37: =-100*((DataQ!AN210+DataQ!AO210)-(DataQ!AN206+DataQ!AO206))/DataQ!AI206 -> -1.356584 | P37: =V37-O37-Q37-R37-S37 -> 0.87420658 | Q37: =X37-R37 -> 3.7289687 | R37: =100*((Z37-Z36)/DataQ!AI208) -> 0.25810234 | S37: =100*((DataQ!AQ210-DataQ!AQ206)/DataQ!AI206) -> 1.781345 | T37: =SUM(N37:S37) -> 0.92282908 | V37: =((DataQ!AI210/DataQ!AI206)-1)*100 -> 5.2860386 | W37: =100*((DataQ!AR206+DataQ!AS206)/(DataQ!AT206+DataQ!AU206)) -> 114.92797 | X37: =100*((DataQ!AK210-DataQ!AK206)/DataQ!AI206) -> 3.987071 | Y37: =1000*(DataQ!AK210/DataQ!AM210) -> 9720.0119 | Z37: =(Y37*DataQ!AM210)/1000 -> 278750.5 | AB37: 2023 04 | AC37: =N41 -> -1.8625328 | AD37: =O37 -> -1.356584 | AE37: =X37 -> 3.987071 | AF37: =V37-AD37-AE37-AG37-AH37 -> 0.81667829 | AG37: =100*((DataQ!AP210-DataQ!AP206)/DataQ!AI210) -> 0.05752829 | AH37: =S37 -> 1.781345 | AI37: =SUM(AC37:AH37) -> 3.4235059 | AQ37: =(DataQ!N148/DataQ!P148)*100 -> 8.8889149 | AR37: =DataQ!Q148 -> 5.763333 | AS37: =DataQ!AF148 -> 5.026923 | AV37: =(DataQ!O148/DataQ!P148)*100 -> 6.464488 | AW37: =(DataQ!N148/DataQ!P148)*100 -> 8.8889149 | AX37: =(DataQ!AG148/DataQ!P148)*100 -> -2.4244269 | BA37: =((DataQ!E200/DataQ!E196)-1)*100 -> 2.0270276 | BB37: =((DataQ!D200/DataQ!D196)-1)*100 -> 8.8512241 | BC37: =BB37-BA37 -> 6.8241965
B38: =100*(F38/$H38) -> 98.122922 | C38: =100*(G38/H38) -> 96.815647 | D38: 100 | F38: =100*(J38/AVERAGE($J$28:$J$31)) -> 114.44726 | G38: =100*(K38/AVERAGE($K$28:$K$31)) -> 112.9225 | H38: =100*(DataQ!I209/AVERAGE(DataQ!I$199:I$202)) -> 116.63662 | J38: =DataQ!F209/DataQ!J209 -> 9.6957706 | K38: =(DataQ!F209-DataQ!G209-DataQ!H209)/DataQ!J209 -> 6.5097265 | M38: 2024 01 | N38: =((W42/W38)-1)*-100 -> -2.9376676 | O38: =-100*((DataQ!AN211+DataQ!AO211)-(DataQ!AN207+DataQ!AO207))/DataQ!AI207 -> -0.27815469 | P38: =V38-O38-Q38-R38-S38 -> -0.87247705 | Q38: =X38-R38 -> 2.690006 | R38: =100*((Z38-Z37)/DataQ!AI209) -> 0.3530835 | S38: =100*((DataQ!AQ211-DataQ!AQ207)/DataQ!AI207) -> 2.5089689 | T38: =SUM(N38:S38) -> 1.4637591 | V38: =((DataQ!AI211/DataQ!AI207)-1)*100 -> 4.4014267 | W38: =100*((DataQ!AR207+DataQ!AS207)/(DataQ!AT207+DataQ!AU207)) -> 117.03174 | X38: =100*((DataQ!AK211-DataQ!AK207)/DataQ!AI207) -> 3.0430895 | Y38: =1000*(DataQ!AK211/DataQ!AM211) -> 9797.7705 | Z38: =(Y38*DataQ!AM211)/1000 -> 280314.9 | AB38: 2024 | AC38: =N42 -> -1.9749801 | AD38: =O38 -> -0.27815469 | AE38: =X38 -> 3.0430895 | AF38: =V38-AD38-AE38-AG38-AH38 -> -0.57148598 | AG38: =100*((DataQ!AP211-DataQ!AP207)/DataQ!AI211) -> -0.30099107 | AH38: =S38 -> 2.5089689 | AI38: =SUM(AC38:AH38) -> 2.4264467 | AQ38: =(DataQ!N149/DataQ!P149)*100 -> 8.9038713 | AR38: =DataQ!Q149 -> 5.796667 | AS38: =DataQ!AF149 -> 5 | AV38: =(DataQ!O149/DataQ!P149)*100 -> 6.6541596 | AW38: =(DataQ!N149/DataQ!P149)*100 -> 8.9038713 | AX38: =(DataQ!AG149/DataQ!P149)*100 -> -2.2497118 | BA38: =((DataQ!E201/DataQ!E197)-1)*100 -> 2.7539788 | BB38: =((DataQ!D201/DataQ!D197)-1)*100 -> 6.0569477 | BC38: =BB38-BA38 -> 3.3029689
