Workbook
Name _DLX1.INC: HAVERQ!$B$1:$K$6
Name _DLX2.INC: HAVERM!$A$1:$H$6
Name Data: [1]sheet0!$C$2

Sheet >> CHARTS

Sheet >> DATA

Sheet Chart Data
A1: GDP forecasts vs consensus | S1: GDP - OE vs consensus | Y1: C cont to GDP | AG1: Real wages | AN1: CONTRIBUTIONS TO CPI INFLATION >> | BK1: Quoted mortgage rates | CA1: Change in interest rates
AN2: Unchained indices | AS2: Rescaled indices | AX2: Price-updated item weights | BC2: Contributions to CPI inflation | BQ2: Margins | BW2: Diff vs expiring deal
B3: =DataA!C1 -> JAN011B.db | C3: =DataA!D1 -> JAN024B.db | D3: =DataA!E1 -> FEB006C.db | E3: =DataA!F1 -> FEB019C.db | F3: =DataA!G1 -> MAR011D.db | G3: =DataA!H1 -> MAR020B.db | H3: =DataA!I1 -> APR009C.db | I3: =DataA!J1 -> APR023B.db | ... P3: =DataA!Q1 -> AUG008C.db | Q3: =DataA!B1 -> SEP002A.db | T3: OE (Sep24) | U3: Consensus (Aug24)* | W3: Consensus | Z3: C | AA3: IF | AB3: GC | AC3: NX | AD3: Oth | AE3: GDP | AH3: Average weekly earnings | AI3: CPI inflation | AJ3: Real wages | AK3: ZERO LINE | AN3: Food | AO3: Petrol | AP3: Energy | AQ3: CPI | AS3: Food | AT3: Petrol | AU3: Energy | AV3: CPI | AX3: Food | AY3: Petrol | AZ3: Energy | BA3: CPI | BC3: Food | BD3: Petrol | BE3: Energy | BF3: Other | BG3: CPI | BH3: CPI check | BI3: 2% TARGET | BL3: 2 year fix, 75% LTV | BM3: 5 year fix, 75% LTV | BN3: 2yr | BO3: 5yr | BQ3: 2 year fix, 75% LTV | BR3: 5 year fix, 75% LTV | BT3: 2 year swap | BU3: 5 year swap | BW3: 2 year fix, 75% LTV | BX3: 5 year fix, 75% LTV | BY3: ZERO LINE | CB3: Non-financial corporations | CC3: Secured household | CD3: ZERO LINE
B4: 45302 | C4: 45315 | D4: 45328 | E4: 45341 | F4: 45362 | G4: 45371 | H4: 45391 | I4: 45405 | J4: 45419 | K4: 45399 | L4: 45393 | M4: 45400 | N4: 45483 | O4: 45497 | P4: 45512 | Q4: 45519 | S4: Q1 2023 | T4: =100*((DataQ!D207/DataQ!D206)-1) -> 0.17481348 | U4: =T4 -> 0.17481348 | W4: =DataQ!D207 -> 569027 | Y4: 45200 | Z4: =DataQ!AA210 -> 336957 | AA4: =DataQ!AB210 -> 107170 | AB4: =DataQ!AC210 -> 117343 | AC4: =DataQ!AD210-DataQ!AE210 -> -7718 | AD4: =AE4-Z4-AA4-AB4-AC4 -> 12874 | AE4: =DataQ!D210 -> 566626 | AG4: 40179 | AH4: =100*((DataQ!U155/DataQ!U151)-1) -> 4.9881235 | AI4: =100*((DataQ!V155/DataQ!V151)-1) -> 3.2774094 | AJ4: =AH4-AI4 -> 1.7107141 | AK4: 0 | AM4: 40179 | AN4: =DataQ!W155/DataQ!W154*100 -> 101.95374 | AO4: =DataQ!X155/DataQ!X154*100 -> 104.81632 | AP4: =DataQ!Y155/DataQ!Y154*100 -> 99.747155 | AQ4: =DataQ!V155/DataQ!V154*100 -> 100.76132 | AS4: =DataQ!W154/DataQ!W151*100 -> 100.72289 | AT4: =DataQ!X154/DataQ!X151*100 -> 118.27868 | AU4: =DataQ!Y154/DataQ!Y151*100 -> 94.882043 | AV4: =DataQ!V154/DataQ!V151*100 -> 102.49708 | AX4: =HAVERQ!C47*AN4/$AQ4 -> 149.75146 | AY4: =HAVERQ!D47*AO4/$AQ4 -> 42.64999 | AZ4: =HAVERQ!E47*AP4/$AQ4 -> 46.526946 | BA4: =1000*AQ4/$AQ4 -> 1000 | BC4: =$AV4/100*(AN4-100)*HAVERQ!C47/1000+(AS4-100)*AX4/$BA4 -> 0.40462859 | BD4: =$AV4/100*(AO4-100)*HAVERQ!D47/1000+(AT4-100)*AY4/$BA4 -> 0.98198555 | BE4: =$AV4/100*(AP4-100)*HAVERQ!E47/1000+(AU4-100)*AZ4/$BA4 -> -0.25030333 | BF4: =BG4-BE4-BD4-BC4 -> 2.1410986 | BG4: =$AV4/100*(AQ4-100)*1000/1000+(AV4-100)*BA4/$BA4 -> 3.2774094 | BH4: =100*((DataQ!V155/DataQ!V151)-1) -> 3.2774094 | BI4: 2 | BK4: 41640 | BL4: =HAVERM!B295 -> 2.37 | BM4: =HAVERM!C295 -> 3.34 | BQ4: =BL4-BT4 -> #N/A | BR4: =BM4-BU4 -> #N/A | BT4: =HAVERM!D295 -> #N/A | BU4: =HAVERM!E295 -> #N/A | BY4: 0 | CA4: 44531 | CB4: =HAVERM!G390-HAVERM!G$389 -> 0.05 | CC4: =HAVERM!H390-HAVERM!H$389 -> -0.01 | CD4: 0
A5: OE | B5: =100*((DataA!C58/DataA!C57)-1) -> 0.55733861 | C5: =100*((DataA!D58/DataA!D57)-1) -> 0.607622 | D5: =100*((DataA!E58/DataA!E57)-1) -> 0.607622 | E5: =100*((DataA!F58/DataA!F57)-1) -> 0.38200567 | F5: =100*((DataA!G58/DataA!G57)-1) -> 0.52154526 | G5: =100*((DataA!H58/DataA!H57)-1) -> 0.52442558 | H5: =100*((DataA!I58/DataA!I57)-1) -> 0.54016363 | I5: =100*((DataA!J58/DataA!J57)-1) -> 0.61547842 | ... P5: =100*((DataA!Q58/DataA!Q57)-1) -> 1.0829668 | Q5: =100*((DataA!B58/DataA!B57)-1) -> 1.1412126 | S5: Q2 2023 | T5: =100*((DataQ!D208/DataQ!D207)-1) -> 0.0086111907 | U5: =T5 -> 0.0086111907 | W5: =DataQ!D208 -> 569076 | Y5: 45292 | Z5: =DataQ!AA211 -> 338388 | AA5: =DataQ!AB211 -> 108142 | AB5: =DataQ!AC211 -> 117324 | AC5: =DataQ!AD211-DataQ!AE211 -> -4531 | AD5: =AE5-Z5-AA5-AB5-AC5 -> 11371 | AE5: =DataQ!D211 -> 570694 | AG5: 40269 | AH5: =100*((DataQ!U156/DataQ!U152)-1) -> 0.99009132 | AI5: =100*((DataQ!V156/DataQ!V152)-1) -> 3.4735622 | AJ5: =AH5-AI5 -> -2.4834709 | AK5: 0 | AM5: 40269 | AN5: =DataQ!W156/DataQ!W154*100 -> 103.11005 | AO5: =DataQ!X156/DataQ!X154*100 -> 111.29595 | AP5: =DataQ!Y156/DataQ!Y154*100 -> 97.724399 | AQ5: =DataQ!V156/DataQ!V154*100 -> 102.05558 | AS5: =DataQ!W154/DataQ!W152*100 -> 100.03988 | AT5: =DataQ!X154/DataQ!X152*100 -> 108.86458 | AU5: =DataQ!Y154/DataQ!Y152*100 -> 99.789735 | AV5: =DataQ!V154/DataQ!V152*100 -> 101.38942 | AX5: =HAVERQ!C48*AN5/$AQ5 -> 149.52918 | AY5: =HAVERQ!D48*AO5/$AQ5 -> 44.712243 | AZ5: =HAVERQ!E48*AP5/$AQ5 -> 45.005348 | BA5: =1000*AQ5/$AQ5 -> 1000 | BC5: =$AV5/100*(AN5-100)*HAVERQ!C48/1000+(AS5-100)*AX5/$BA5 -> 0.47264629 | BD5: =$AV5/100*(AO5-100)*HAVERQ!D48/1000+(AT5-100)*AY5/$BA5 -> 0.86592373 | BE5: =$AV5/100*(AP5-100)*HAVERQ!E48/1000+(AU5-100)*AZ5/$BA5 -> -0.1179023 | BF5: =BG5-BE5-BD5-BC5 -> 2.2528945 | BG5: =$AV5/100*(AQ5-100)*1000/1000+(AV5-100)*BA5/$BA5 -> 3.4735622 | BH5: =100*((DataQ!V156/DataQ!V152)-1) -> 3.4735622 | BI5: 2 | BK5: 41671 | BL5: =HAVERM!B296 -> 2.38 | BM5: =HAVERM!C296 -> 3.45 | BQ5: =BL5-BT5 -> #N/A | BR5: =BM5-BU5 -> #N/A | BT5: =HAVERM!D296 -> #N/A | BU5: =HAVERM!E296 -> #N/A | BY5: 0 | CA5: 44562 | CB5: =HAVERM!G391-HAVERM!G$389 -> 0.11 | CC5: =HAVERM!H391-HAVERM!H$389 -> -0.01 | CD5: 0
A6: Consensus | B6: 0.4 | C6: =B6 -> 0.4 | D6: 0.4 | E6: =D6 -> 0.4 | F6: 0.4 | G6: =F6 -> 0.4 | H6: 0.4 | I6: =H6 -> 0.4 | J6: 0.6 | K6: =J6 -> 0.6 | L6: 0.8 | M6: =L6 -> 0.8 | N6: 0.9 | O6: =N6 -> 0.9 | P6: =O6 -> 0.9 | Q6: =P6 -> 0.9 | S6: Q3 2023 | T6: =100*((DataQ!D209/DataQ!D208)-1) -> -0.11931622 | U6: =T6 -> -0.11931622 | W6: =DataQ!D209 -> 568397 | Y6: 45383 | Z6: =DataQ!AA212 -> 339057 | AA6: =DataQ!AB212 -> 108571 | AB6: =DataQ!AC212 -> 119020 | AC6: =DataQ!AD212-DataQ!AE212 -> -17105 | AD6: =AE6-Z6-AA6-AB6-AC6 -> 24413 | AE6: =DataQ!D212 -> 573956 | AG6: 40360 | AH6: =100*((DataQ!U157/DataQ!U153)-1) -> 1.5220776 | AI6: =100*((DataQ!V157/DataQ!V153)-1) -> 3.1058283 | AJ6: =AH6-AI6 -> -1.5837507 | AK6: 0 | AM6: 40360 | AN6: =DataQ!W157/DataQ!W154*100 -> 103.82775 | AO6: =DataQ!X157/DataQ!X154*100 -> 108.24667 | AP6: =DataQ!Y157/DataQ!Y154*100 -> 97.471555 | AQ6: =DataQ!V157/DataQ!V154*100 -> 102.3601 | AS6: =DataQ!W154/DataQ!W153*100 -> 100.56135 | AT6: =DataQ!X154/DataQ!X153*100 -> 103.1451 | AU6: =DataQ!Y154/DataQ!Y153*100 -> 100.33826 | AV6: =DataQ!V154/DataQ!V153*100 -> 100.72854 | AX6: =HAVERQ!C49*AN6/$AQ6 -> 150.12204 | AY6: =HAVERQ!D49*AO6/$AQ6 -> 43.357848 | AZ6: =HAVERQ!E49*AP6/$AQ6 -> 44.75536 | BA6: =1000*AQ6/$AQ6 -> 1000 | BC6: =$AV6/100*(AN6-100)*HAVERQ!C49/1000+(AS6-100)*AX6/$BA6 -> 0.65490558 | BD6: =$AV6/100*(AO6-100)*HAVERQ!D49/1000+(AT6-100)*AY6/$BA6 -> 0.47694166 | BE6: =$AV6/100*(AP6-100)*HAVERQ!E49/1000+(AU6-100)*AZ6/$BA6 -> -0.10456383 | BF6: =BG6-BE6-BD6-BC6 -> 2.0785449 | BG6: =$AV6/100*(AQ6-100)*1000/1000+(AV6-100)*BA6/$BA6 -> 3.1058283 | BH6: =100*((DataQ!V157/DataQ!V153)-1) -> 3.1058283 | BI6: 2 | BK6: 41699 | BL6: =HAVERM!B297 -> 2.37 | BM6: =HAVERM!C297 -> 3.48 | BQ6: =BL6-BT6 -> #N/A | BR6: =BM6-BU6 -> #N/A | BT6: =HAVERM!D297 -> #N/A | BU6: =HAVERM!E297 -> #N/A | BY6: 0 | CA6: 44593 | CB6: =HAVERM!G392-HAVERM!G$389 -> 0.25 | CC6: =HAVERM!H392-HAVERM!H$389 -> 0 | CD6: 0
S7: Q4 2023 | T7: =100*((DataQ!D210/DataQ!D209)-1) -> -0.311578 | U7: =T7 -> -0.311578 | W7: =DataQ!D210 -> 566626 | AG7: 40452 | AH7: =100*((DataQ!U158/DataQ!U154)-1) -> 1.8953676 | AI7: =100*((DataQ!V158/DataQ!V154)-1) -> 3.3498248 | AJ7: =AH7-AI7 -> -1.4544572 | AK7: 0 | AM7: 40452 | AN7: =DataQ!W158/DataQ!W154*100 -> 105.58214 | AO7: =DataQ!X158/DataQ!X154*100 -> 111.46913 | AP7: =DataQ!Y158/DataQ!Y154*100 -> 99.030771 | AQ7: =DataQ!V158/DataQ!V154*100 -> 103.34982 | AS7: =DataQ!W154/DataQ!W154*100 -> 100 | AT7: =DataQ!X154/DataQ!X154*100 -> 100 | AU7: =DataQ!Y154/DataQ!Y154*100 -> 100 | AV7: =DataQ!V154/DataQ!V154*100 -> 100 | AX7: =HAVERQ!C50*AN7/$AQ7 -> 151.19674 | AY7: =HAVERQ!D50*AO7/$AQ7 -> 44.221015 | AZ7: =HAVERQ!E50*AP7/$AQ7 -> 45.035841 | BA7: =1000*AQ7/$AQ7 -> 1000 | BC7: =$AV7/100*(AN7-100)*HAVERQ!C50/1000+(AS7-100)*AX7/$BA7 -> 0.82615689 | BD7: =$AV7/100*(AO7-100)*HAVERQ!D50/1000+(AT7-100)*AY7/$BA7 -> 0.4702342 | BE7: =$AV7/100*(AP7-100)*HAVERQ!E50/1000+(AU7-100)*AZ7/$BA7 -> -0.045553755 | BF7: =BG7-BE7-BD7-BC7 -> 2.0989874 | BG7: =$AV7/100*(AQ7-100)*1000/1000+(AV7-100)*BA7/$BA7 -> 3.3498248 | BH7: =100*((DataQ!V158/DataQ!V154)-1) -> 3.3498248 | BI7: 2 | BK7: 41730 | BL7: =HAVERM!B298 -> 2.54 | BM7: =HAVERM!C298 -> 3.69 | BQ7: =BL7-BT7 -> #N/A | BR7: =BM7-BU7 -> #N/A | BT7: =HAVERM!D298 -> #N/A | BU7: =HAVERM!E298 -> #N/A | BY7: 0 | CA7: 44621 | CB7: =HAVERM!G393-HAVERM!G$389 -> 0.35 | CC7: =HAVERM!H393-HAVERM!H$389 -> 0.03 | CD7: 0
S8: Q1 2024 | T8: =100*((DataQ!D211/DataQ!D210)-1) -> 0.71793388 | U8: =T8 -> 0.71793388 | W8: =DataQ!D211 -> 570694 | Y8: Cont | Z8: =100*((Z6-Z4)/$AE4) -> 0.37061483 | AA8: =100*((AA6-AA4)/$AE4) -> 0.24725304 | AB8: =100*((AB6-AB4)/$AE4) -> 0.29596242 | AC8: =100*((AC6-AC4)/$AE4) -> -1.6566483 | AD8: =100*((AD6-AD4)/$AE4) -> 2.0364403 | AE8: =SUM(Z8:AD8) -> 1.2936222 | AG8: 40544 | AH8: =100*((DataQ!U159/DataQ!U155)-1) -> 2.8657692 | AI8: =100*((DataQ!V159/DataQ!V155)-1) -> 4.0801022 | AJ8: =AH8-AI8 -> -1.2143329 | AK8: 0 | AM8: 40544 | AN8: =DataQ!W159/DataQ!W158*100 -> 102.15256 | AO8: =DataQ!X159/DataQ!X158*100 -> 108.82813 | AP8: =DataQ!Y159/DataQ!Y158*100 -> 104.2553 | AQ8: =DataQ!V159/DataQ!V158*100 -> 101.4733 | AS8: =DataQ!W158/DataQ!W155*100 -> 103.55887 | AT8: =DataQ!X158/DataQ!X155*100 -> 106.34711 | AU8: =DataQ!Y158/DataQ!Y155*100 -> 99.2818 | AV8: =DataQ!V158/DataQ!V155*100 -> 102.56895 | AX8: =HAVERQ!C51*AN8/$AQ8 -> 161.07102 | AY8: =HAVERQ!D51*AO8/$AQ8 -> 46.116659 | AZ8: =HAVERQ!E51*AP8/$AQ8 -> 45.206307 | BA8: =1000*AQ8/$AQ8 -> 1000 | BC8: =$AV8/100*(AN8-100)*HAVERQ!C51/1000+(AS8-100)*AX8/$BA8 -> 0.92648694 | BD8: =$AV8/100*(AO8-100)*HAVERQ!D51/1000+(AT8-100)*AY8/$BA8 -> 0.68206926 | BE8: =$AV8/100*(AP8-100)*HAVERQ!E51/1000+(AU8-100)*AZ8/$BA8 -> 0.15957603 | BF8: =BG8-BE8-BD8-BC8 -> 2.3119699 | BG8: =$AV8/100*(AQ8-100)*1000/1000+(AV8-100)*BA8/$BA8 -> 4.0801022 | BH8: =100*((DataQ!V159/DataQ!V155)-1) -> 4.0801022 | BI8: 2 | BK8: 41760 | BL8: =HAVERM!B299 -> 2.56 | BM8: =HAVERM!C299 -> 3.72 | BQ8: =BL8-BT8 -> #N/A | BR8: =BM8-BU8 -> #N/A | BT8: =HAVERM!D299 -> #N/A | BU8: =HAVERM!E299 -> #N/A | BY8: 0 | CA8: 44652 | CB8: =HAVERM!G394-HAVERM!G$389 -> 0.45 | CC8: =HAVERM!H394-HAVERM!H$389 -> 0.03 | CD8: 0
S9: Q2 2024 | T9: =100*((DataQ!D212/DataQ!D211)-1) -> 0.57158477 | U9: =T9 -> 0.57158477 | W9: =DataQ!D212 -> 573956 | Y9: Growth | AE9: =100*((AE6/AE4)-1) -> 1.2936222 | AG9: 40634 | AH9: =100*((DataQ!U160/DataQ!U156)-1) -> 2.564095 | AI9: =100*((DataQ!V160/DataQ!V156)-1) -> 4.4013389 | AJ9: =AH9-AI9 -> -1.8372439 | AK9: 0 | AM9: 40634 | AN9: =DataQ!W160/DataQ!W158*100 -> 104.19184 | AO9: =DataQ!X160/DataQ!X158*100 -> 113.64632 | AP9: =DataQ!Y160/DataQ!Y158*100 -> 105.06382 | AQ9: =DataQ!V160/DataQ!V158*100 -> 103.09392 | AS9: =DataQ!W158/DataQ!W156*100 -> 102.39753 | AT9: =DataQ!X158/DataQ!X156*100 -> 100.1556 | AU9: =DataQ!Y158/DataQ!Y156*100 -> 101.33679 | AV9: =DataQ!V158/DataQ!V156*100 -> 101.26818 | AX9: =HAVERQ!C52*AN9/$AQ9 -> 161.70395 | AY9: =HAVERQ!D52*AO9/$AQ9 -> 47.401357 | AZ9: =HAVERQ!E52*AP9/$AQ9 -> 44.840743 | BA9: =1000*AQ9/$AQ9 -> 1000 | BC9: =$AV9/100*(AN9-100)*HAVERQ!C52/1000+(AS9-100)*AX9/$BA9 -> 1.0668904 | BD9: =$AV9/100*(AO9-100)*HAVERQ!D52/1000+(AT9-100)*AY9/$BA9 -> 0.6016092 | BE9: =$AV9/100*(AP9-100)*HAVERQ!E52/1000+(AU9-100)*AZ9/$BA9 -> 0.28557646 | BF9: =BG9-BE9-BD9-BC9 -> 2.4472629 | BG9: =$AV9/100*(AQ9-100)*1000/1000+(AV9-100)*BA9/$BA9 -> 4.4013389 | BH9: =100*((DataQ!V160/DataQ!V156)-1) -> 4.4013389 | BI9: 2 | BK9: 41791 | BL9: =HAVERM!B300 -> 2.6 | BM9: =HAVERM!C300 -> 3.69 | BQ9: =BL9-BT9 -> #N/A | BR9: =BM9-BU9 -> #N/A | BT9: =HAVERM!D300 -> #N/A | BU9: =HAVERM!E300 -> #N/A | BY9: 0 | CA9: 44682 | CB9: =HAVERM!G395-HAVERM!G$389 -> 0.65 | CC9: =HAVERM!H395-HAVERM!H$389 -> 0.06 | CD9: 0
S10: Q3 2024 | T10: =100*((DataQ!D213/DataQ!D212)-1) -> 0.36912237 | U10: =T10 -> 0.36912237 | W10: =W9*(1+U10/100) -> 576074.6 | AE10: =Z8/AE9 -> 0.28649386 | AG10: 40725 | AH10: =100*((DataQ!U161/DataQ!U157)-1) -> 2.2488754 | AI10: =100*((DataQ!V161/DataQ!V157)-1) -> 4.6857681 | AJ10: =AH10-AI10 -> -2.4368927 | AK10: 0 | AM10: 40725 | AN10: =DataQ!W161/DataQ!W158*100 -> 105.43807 | AO10: =DataQ!X161/DataQ!X158*100 -> 113.2733 | AP10: =DataQ!Y161/DataQ!Y158*100 -> 109.14893 | AQ10: =DataQ!V161/DataQ!V158*100 -> 103.68325 | AS10: =DataQ!W158/DataQ!W157*100 -> 101.68971 | AT10: =DataQ!X158/DataQ!X157*100 -> 102.97695 | AU10: =DataQ!Y158/DataQ!Y157*100 -> 101.59966 | AV10: =DataQ!V158/DataQ!V157*100 -> 100.96691 | AX10: =HAVERQ!C53*AN10/$AQ10 -> 162.70797 | AY10: =HAVERQ!D53*AO10/$AQ10 -> 46.977232 | AZ10: =HAVERQ!E53*AP10/$AQ10 -> 46.319467 | BA10: =1000*AQ10/$AQ10 -> 1000 | BC10: =$AV10/100*(AN10-100)*HAVERQ!C53/1000+(AS10-100)*AX10/$BA10 -> 1.1534332 | BD10: =$AV10/100*(AO10-100)*HAVERQ!D53/1000+(AT10-100)*AY10/$BA10 -> 0.71611967 | BE10: =$AV10/100*(AP10-100)*HAVERQ!E53/1000+(AU10-100)*AZ10/$BA10 -> 0.48054062 | BF10: =BG10-BE10-BD10-BC10 -> 2.3356747 | BG10: =$AV10/100*(AQ10-100)*1000/1000+(AV10-100)*BA10/$BA10 -> 4.6857681 | BH10: =100*((DataQ!V161/DataQ!V157)-1) -> 4.6857681 | BI10: 2 | BK10: 41821 | BL10: =HAVERM!B301 -> 2.54 | BM10: =HAVERM!C301 -> 3.78 | BQ10: =BL10-BT10 -> #N/A | BR10: =BM10-BU10 -> #N/A | BT10: =HAVERM!D301 -> #N/A | BU10: =HAVERM!E301 -> #N/A | BY10: 0 | CA10: 44713 | CB10: =HAVERM!G396-HAVERM!G$389 -> 0.78 | CC10: =HAVERM!H396-HAVERM!H$389 -> 0.1 | CD10: 0
S11: Q4 2024 | T11: =100*((DataQ!D214/DataQ!D213)-1) -> 0.39369901 | U11: =T11 -> 0.39369901 | W11: =W10*(1+U11/100) -> 578342.6 | AG11: 40817 | AH11: =100*((DataQ!U162/DataQ!U158)-1) -> 1.9345313 | AI11: =100*((DataQ!V162/DataQ!V158)-1) -> 4.6777127 | AJ11: =AH11-AI11 -> -2.7431815 | AK11: 0 | AM11: 40817 | AN11: =DataQ!W162/DataQ!W158*100 -> 105.58912 | AO11: =DataQ!X162/DataQ!X158*100 -> 112.58937 | AP11: =DataQ!Y162/DataQ!Y158*100 -> 118.97871 | AQ11: =DataQ!V162/DataQ!V158*100 -> 104.67771 | AS11: =DataQ!W158/DataQ!W158*100 -> 100 | AT11: =DataQ!X158/DataQ!X158*100 -> 100 | AU11: =DataQ!Y158/DataQ!Y158*100 -> 100 | AV11: =DataQ!V158/DataQ!V158*100 -> 100 | AX11: =HAVERQ!C54*AN11/$AQ11 -> 161.39309 | AY11: =HAVERQ!D54*AO11/$AQ11 -> 46.249989 | AZ11: =HAVERQ!E54*AP11/$AQ11 -> 50.011251 | BA11: =1000*AQ11/$AQ11 -> 1000 | BC11: =$AV11/100*(AN11-100)*HAVERQ!C54/1000+(AS11-100)*AX11/$BA11 -> 0.89425918 | BD11: =$AV11/100*(AO11-100)*HAVERQ!D54/1000+(AT11-100)*AY11/$BA11 -> 0.54134303 | BE11: =$AV11/100*(AP11-100)*HAVERQ!E54/1000+(AU11-100)*AZ11/$BA11 -> 0.83506338 | BF11: =BG11-BE11-BD11-BC11 -> 2.4070471 | BG11: =$AV11/100*(AQ11-100)*1000/1000+(AV11-100)*BA11/$BA11 -> 4.6777127 | BH11: =100*((DataQ!V162/DataQ!V158)-1) -> 4.6777127 | BI11: 2 | BK11: 41852 | BL11: =HAVERM!B302 -> 2.54 | BM11: =HAVERM!C302 -> 3.76 | BQ11: =BL11-BT11 -> 1.5588 | BR11: =BM11-BU11 -> 2.15 | BT11: =HAVERM!D302 -> 0.9812 | BU11: =HAVERM!E302 -> 1.61 | BY11: 0 | CA11: 44743 | CB11: =HAVERM!G397-HAVERM!G$389 -> 0.86 | CC11: =HAVERM!H397-HAVERM!H$389 -> 0.11 | CD11: 0
S12: Q1 2025 | T12: =100*((DataQ!D215/DataQ!D214)-1) -> 0.41191847 | U12: 0.3 | W12: =W11*(1+U12/100) -> 580077.63 | AG12: 40909 | AH12: =100*((DataQ!U163/DataQ!U159)-1) -> 0.51318911 | AI12: =100*((DataQ!V163/DataQ!V159)-1) -> 3.4845624 | AJ12: =AH12-AI12 -> -2.9713732 | AK12: 0 | AM12: 40909 | AN12: =DataQ!W163/DataQ!W162*100 -> 101.46638 | AO12: =DataQ!X163/DataQ!X162*100 -> 101.60138 | AP12: =DataQ!Y163/DataQ!Y162*100 -> 99.606588 | AQ12: =DataQ!V163/DataQ!V162*100 -> 100.31668 | AS12: =DataQ!W162/DataQ!W159*100 -> 103.36415 | AT12: =DataQ!X162/DataQ!X159*100 -> 103.45613 | AU12: =DataQ!Y162/DataQ!Y159*100 -> 114.12246 | AV12: =DataQ!V162/DataQ!V159*100 -> 103.15788 | AX12: =HAVERQ!C55*AN12/$AQ12 -> 155.76496 | AY12: =HAVERQ!D55*AO12/$AQ12 -> 46.589098 | AZ12: =HAVERQ!E55*AP12/$AQ12 -> 55.603605 | BA12: =1000*AQ12/$AQ12 -> 1000 | BC12: =$AV12/100*(AN12-100)*HAVERQ!C55/1000+(AS12-100)*AX12/$BA12 -> 0.75697078 | BD12: =$AV12/100*(AO12-100)*HAVERQ!D55/1000+(AT12-100)*AY12/$BA12 -> 0.23700756 | BE12: =$AV12/100*(AP12-100)*HAVERQ!E55/1000+(AU12-100)*AZ12/$BA12 -> 0.7625328 | BF12: =BG12-BE12-BD12-BC12 -> 1.7280512 | BG12: =$AV12/100*(AQ12-100)*1000/1000+(AV12-100)*BA12/$BA12 -> 3.4845624 | BH12: =100*((DataQ!V163/DataQ!V159)-1) -> 3.4845624 | BI12: 2 | BK12: 41883 | BL12: =HAVERM!B303 -> 2.46 | BM12: =HAVERM!C303 -> 3.61 | BQ12: =BL12-BT12 -> 1.4812727 | BR12: =BM12-BU12 -> 1.9375955 | BT12: =HAVERM!D303 -> 0.97872727 | BU12: =HAVERM!E303 -> 1.6724045 | BY12: 0 | CA12: 44774 | CB12: =HAVERM!G398-HAVERM!G$389 -> 1.17 | CC12: =HAVERM!H398-HAVERM!H$389 -> 0.16 | CD12: 0
S13: Q2 2025 | T13: =100*((DataQ!D216/DataQ!D215)-1) -> 0.4400879 | U13: 0.3 | W13: =W12*(1+U13/100) -> 581817.86 | AG13: 41000 | AH13: =100*((DataQ!U164/DataQ!U160)-1) -> 1.6176619 | AI13: =100*((DataQ!V164/DataQ!V160)-1) -> 2.6795284 | AJ13: =AH13-AI13 -> -1.0618665 | AK13: 0 | AM13: 41000 | AN13: =DataQ!W164/DataQ!W162*100 -> 102.43205 | AO13: =DataQ!X164/DataQ!X162*100 -> 102.45723 | AP13: =DataQ!Y164/DataQ!Y162*100 -> 98.140204 | AQ13: =DataQ!V164/DataQ!V162*100 -> 101.12597 | AS13: =DataQ!W162/DataQ!W160*100 -> 101.34106 | AT13: =DataQ!X162/DataQ!X160*100 -> 99.069967 | AU13: =DataQ!Y162/DataQ!Y160*100 -> 113.24423 | AV13: =DataQ!V162/DataQ!V160*100 -> 101.53626 | AX13: =HAVERQ!C56*AN13/$AQ13 -> 155.98897 | AY13: =HAVERQ!D56*AO13/$AQ13 -> 46.605563 | AZ13: =HAVERQ!E56*AP13/$AQ13 -> 54.346587 | BA13: =1000*AQ13/$AQ13 -> 1000 | BC13: =$AV13/100*(AN13-100)*HAVERQ!C56/1000+(AS13-100)*AX13/$BA13 -> 0.5894803 | BD13: =$AV13/100*(AO13-100)*HAVERQ!D56/1000+(AT13-100)*AY13/$BA13 -> 0.071424561 | BE13: =$AV13/100*(AP13-100)*HAVERQ!E56/1000+(AU13-100)*AZ13/$BA13 -> 0.61403004 | BF13: =BG13-BE13-BD13-BC13 -> 1.4045935 | BG13: =$AV13/100*(AQ13-100)*1000/1000+(AV13-100)*BA13/$BA13 -> 2.6795284 | BH13: =100*((DataQ!V164/DataQ!V160)-1) -> 2.6795284 | BI13: 2 | BK13: 41913 | BL13: =HAVERM!B304 -> 2.21 | BM13: =HAVERM!C304 -> 3.27 | BQ13: =BL13-BT13 -> 1.3656522 | BR13: =BM13-BU13 -> 1.8341696 | BT13: =HAVERM!D304 -> 0.84434783 | BU13: =HAVERM!E304 -> 1.4358304 | BY13: 0 | CA13: 44805 | CB13: =HAVERM!G399-HAVERM!G$389 -> 1.38 | CC13: =HAVERM!H399-HAVERM!H$389 -> 0.23 | CD13: 0
S14: Q3 2025 | T14: =100*((DataQ!D217/DataQ!D216)-1) -> 0.43003316 | U14: 0.3 | W14: =W13*(1+U14/100) -> 583563.31 | AG14: 41091 | AH14: =100*((DataQ!U165/DataQ!U161)-1) -> 1.8328371 | AI14: =100*((DataQ!V165/DataQ!V161)-1) -> 2.3801029 | AJ14: =AH14-AI14 -> -0.54726574 | AK14: 0 | AM14: 41091 | AN14: =DataQ!W165/DataQ!W162*100 -> 102.93276 | AO14: =DataQ!X165/DataQ!X162*100 -> 100.85594 | AP14: =DataQ!Y165/DataQ!Y162*100 -> 98.140204 | AQ14: =DataQ!V165/DataQ!V162*100 -> 101.40747 | AS14: =DataQ!W162/DataQ!W161*100 -> 100.14326 | AT14: =DataQ!X162/DataQ!X161*100 -> 99.396213 | AU14: =DataQ!Y162/DataQ!Y161*100 -> 109.00585 | AV14: =DataQ!V162/DataQ!V161*100 -> 100.95914 | AX14: =HAVERQ!C57*AN14/$AQ14 -> 156.31635 | AY14: =HAVERQ!D57*AO14/$AQ14 -> 45.749817 | AZ14: =HAVERQ!E57*AP14/$AQ14 -> 54.195727 | BA14: =1000*AQ14/$AQ14 -> 1000 | BC14: =$AV14/100*(AN14-100)*HAVERQ!C57/1000+(AS14-100)*AX14/$BA14 -> 0.47837088 | BD14: =$AV14/100*(AO14-100)*HAVERQ!D57/1000+(AT14-100)*AY14/$BA14 -> 0.012127566 | BE14: =$AV14/100*(AP14-100)*HAVERQ!E57/1000+(AU14-100)*AZ14/$BA14 -> 0.38293097 | BF14: =BG14-BE14-BD14-BC14 -> 1.5066734 | BG14: =$AV14/100*(AQ14-100)*1000/1000+(AV14-100)*BA14/$BA14 -> 2.3801029 | BH14: =100*((DataQ!V165/DataQ!V161)-1) -> 2.3801029 | BI14: 2 | BK14: 41944 | BL14: =HAVERM!B305 -> 2.17 | BM14: =HAVERM!C305 -> 3.21 | BQ14: =BL14-BT14 -> 1.4026833 | BR14: =BM14-BU14 -> 1.8787167 | BT14: =HAVERM!D305 -> 0.76731667 | BU14: =HAVERM!E305 -> 1.3312833 | BY14: 0 | CA14: 44835 | CB14: =HAVERM!G400-HAVERM!G$389 -> 1.63 | CC14: =HAVERM!H400-HAVERM!H$389 -> 0.27 | CD14: 0
S15: Q4 2025 | T15: =100*((DataQ!D218/DataQ!D217)-1) -> 0.4449043 | U15: 0.3 | W15: =W14*(1+U15/100) -> 585314 | AG15: 41183 | AH15: =100*((DataQ!U166/DataQ!U162)-1) -> 1.1678758 | AI15: =100*((DataQ!V166/DataQ!V162)-1) -> 2.6741802 | AJ15: =AH15-AI15 -> -1.5063044 | AK15: 0 | AM15: 41183 | AN15: =DataQ!W166/DataQ!W162*100 -> 104.32761 | AO15: =DataQ!X166/DataQ!X162*100 -> 101.04917 | AP15: =DataQ!Y166/DataQ!Y162*100 -> 101.03719 | AQ15: =DataQ!V166/DataQ!V162*100 -> 102.67418 | AS15: =DataQ!W162/DataQ!W162*100 -> 100 | AT15: =DataQ!X162/DataQ!X162*100 -> 100 | AU15: =DataQ!Y162/DataQ!Y162*100 -> 100 | AV15: =DataQ!V162/DataQ!V162*100 -> 100 | AX15: =HAVERQ!C58*AN15/$AQ15 -> 156.47996 | AY15: =HAVERQ!D58*AO15/$AQ15 -> 45.271965 | AZ15: =HAVERQ!E58*AP15/$AQ15 -> 55.107161 | BA15: =1000*AQ15/$AQ15 -> 1000 | BC15: =$AV15/100*(AN15-100)*HAVERQ!C58/1000+(AS15-100)*AX15/$BA15 -> 0.66645152 | BD15: =$AV15/100*(AO15-100)*HAVERQ!D58/1000+(AT15-100)*AY15/$BA15 -> 0.048261913 | BE15: =$AV15/100*(AP15-100)*HAVERQ!E58/1000+(AU15-100)*AZ15/$BA15 -> 0.058082575 | BF15: =BG15-BE15-BD15-BC15 -> 1.9013842 | BG15: =$AV15/100*(AQ15-100)*1000/1000+(AV15-100)*BA15/$BA15 -> 2.6741802 | BH15: =100*((DataQ!V166/DataQ!V162)-1) -> 2.6741802 | BI15: 2 | BK15: 41974 | BL15: =HAVERM!B306 -> 2.08 | BM15: =HAVERM!C306 -> 3.21 | BQ15: =BL15-BT15 -> 1.3790636 | BR15: =BM15-BU15 -> 2.0094227 | BT15: =HAVERM!D306 -> 0.70093636 | BU15: =HAVERM!E306 -> 1.2005773 | BY15: 0 | CA15: 44866 | CB15: =HAVERM!G401-HAVERM!G$389 -> 2.12 | CC15: =HAVERM!H401-HAVERM!H$389 -> 0.37 | CD15: 0
AG16: 41275 | AH16: =100*((DataQ!U167/DataQ!U163)-1) -> 0.51056893 | AI16: =100*((DataQ!V167/DataQ!V163)-1) -> 2.7709541 | AJ16: =AH16-AI16 -> -2.2603852 | AK16: 0 | AM16: 41275 | AN16: =DataQ!W167/DataQ!W166*100 -> 101.98834 | AO16: =DataQ!X167/DataQ!X166*100 -> 100.57377 | AP16: =DataQ!Y167/DataQ!Y166*100 -> 104.63717 | AQ16: =DataQ!V167/DataQ!V166*100 -> 100.41123 | AS16: =DataQ!W166/DataQ!W163*100 -> 102.81987 | AT16: =DataQ!X166/DataQ!X163*100 -> 99.456495 | AU16: =DataQ!Y166/DataQ!Y163*100 -> 101.43625 | AV16: =DataQ!V166/DataQ!V163*100 -> 102.35006 | AX16: =HAVERQ!C59*AN16/$AQ16 -> 152.35598 | AY16: =HAVERQ!D59*AO16/$AQ16 -> 40.06475 | AZ16: =HAVERQ!E59*AP16/$AQ16 -> 50.020145 | BA16: =1000*AQ16/$AQ16 -> 1000 | BC16: =$AV16/100*(AN16-100)*HAVERQ!C59/1000+(AS16-100)*AX16/$BA16 -> 0.73488471 | BD16: =$AV16/100*(AO16-100)*HAVERQ!D59/1000+(AT16-100)*AY16/$BA16 -> 0.0017147743 | BE16: =$AV16/100*(AP16-100)*HAVERQ!E59/1000+(AU16-100)*AZ16/$BA16 -> 0.29965661 | BF16: =BG16-BE16-BD16-BC16 -> 1.734698 | BG16: =$AV16/100*(AQ16-100)*1000/1000+(AV16-100)*BA16/$BA16 -> 2.7709541 | BH16: =100*((DataQ!V167/DataQ!V163)-1) -> 2.7709541 | BI16: 2 | BK16: 42005 | BL16: =HAVERM!B307 -> 2.01 | BM16: =HAVERM!C307 -> 3.09 | BQ16: =BL16-BT16 -> 1.4174286 | BR16: =BM16-BU16 -> 2.1329952 | BT16: =HAVERM!D307 -> 0.59257143 | BU16: =HAVERM!E307 -> 0.95700476 | BY16: 0 | CA16: 44896 | CB16: =HAVERM!G402-HAVERM!G$389 -> 2.44 | CC16: =HAVERM!H402-HAVERM!H$389 -> 0.49 | CD16: 0
S17: 2023 | W17: =SUM(W4:W7) -> 2273126 | AG17: 41365 | AH17: =100*((DataQ!U168/DataQ!U164)-1) -> 2.0983935 | AI17: =100*((DataQ!V168/DataQ!V164)-1) -> 2.6791962 | AJ17: =AH17-AI17 -> -0.58080276 | AK17: 0 | AM17: 41365 | AN17: =DataQ!W168/DataQ!W166*100 -> 102.91399 | AO17: =DataQ!X168/DataQ!X166*100 -> 99.398934 | AP17: =DataQ!Y168/DataQ!Y166*100 -> 104.60178 | AQ17: =DataQ!V168/DataQ!V166*100 -> 101.13091 | AS17: =DataQ!W166/DataQ!W164*100 -> 101.85055 | AT17: =DataQ!X166/DataQ!X164*100 -> 98.625707 | AU17: =DataQ!Y166/DataQ!Y164*100 -> 102.95188 | AV17: =DataQ!V166/DataQ!V164*100 -> 101.53097 | AX17: =HAVERQ!C60*AN17/$AQ17 -> 152.64471 | AY17: =HAVERQ!D60*AO17/$AQ17 -> 39.314956 | AZ17: =HAVERQ!E60*AP17/$AQ17 -> 49.647385 | BA17: =1000*AQ17/$AQ17 -> 1000 | BC17: =$AV17/100*(AN17-100)*HAVERQ!C60/1000+(AS17-100)*AX17/$BA17 -> 0.72626734 | BD17: =$AV17/100*(AO17-100)*HAVERQ!D60/1000+(AT17-100)*AY17/$BA17 -> -0.078440964 | BE17: =$AV17/100*(AP17-100)*HAVERQ!E60/1000+(AU17-100)*AZ17/$BA17 -> 0.37082032 | BF17: =BG17-BE17-BD17-BC17 -> 1.6605495 | BG17: =$AV17/100*(AQ17-100)*1000/1000+(AV17-100)*BA17/$BA17 -> 2.6791962 | BH17: =100*((DataQ!V168/DataQ!V164)-1) -> 2.6791962 | BI17: 2 | BK17: 42036 | BL17: =HAVERM!B308 -> 1.96 | BM17: =HAVERM!C308 -> 3.05 | BQ17: =BL17-BT17 -> 1.280755 | BR17: =BM17-BU17 -> 1.92882 | BT17: =HAVERM!D308 -> 0.679245 | BU17: =HAVERM!E308 -> 1.12118 | BY17: 0 | CA17: 44927 | CB17: =HAVERM!G403-HAVERM!G$389 -> 2.6 | CC17: =HAVERM!H403-HAVERM!H$389 -> 0.53 | CD17: 0
S18: 2024 | T18: =100*((DataA!B58/DataA!B57)-1) -> 1.1412126 | U18: =100*((W18/W17)-1) -> 1.1412126 | W18: =SUM(W8:W11) -> 2299067.2 | AG18: 41456 | AH18: =100*((DataQ!U169/DataQ!U165)-1) -> 0.64794816 | AI18: =100*((DataQ!V169/DataQ!V165)-1) -> 2.7411484 | AJ18: =AH18-AI18 -> -2.0932002 | AK18: 0 | AM18: 41456 | AN18: =DataQ!W169/DataQ!W166*100 -> 103.32537 | AO18: =DataQ!X169/DataQ!X166*100 -> 100.43713 | AP18: =DataQ!Y169/DataQ!Y166*100 -> 104.84956 | AQ18: =DataQ!V169/DataQ!V166*100 -> 101.47361 | AS18: =DataQ!W166/DataQ!W165*100 -> 101.35511 | AT18: =DataQ!X166/DataQ!X165*100 -> 100.1916 | AU18: =DataQ!Y166/DataQ!Y165*100 -> 102.95188 | AV18: =DataQ!V166/DataQ!V165*100 -> 101.24913 | AX18: =HAVERQ!C61*AN18/$AQ18 -> 152.73731 | AY18: =HAVERQ!D61*AO18/$AQ18 -> 39.59143 | AZ18: =HAVERQ!E61*AP18/$AQ18 -> 49.596925 | BA18: =1000*AQ18/$AQ18 -> 1000 | BC18: =$AV18/100*(AN18-100)*HAVERQ!C61/1000+(AS18-100)*AX18/$BA18 -> 0.71201207 | BD18: =$AV18/100*(AO18-100)*HAVERQ!D61/1000+(AT18-100)*AY18/$BA18 -> 0.025289215 | BE18: =$AV18/100*(AP18-100)*HAVERQ!E61/1000+(AU18-100)*AZ18/$BA18 -> 0.38209103 | BF18: =BG18-BE18-BD18-BC18 -> 1.6217561 | BG18: =$AV18/100*(AQ18-100)*1000/1000+(AV18-100)*BA18/$BA18 -> 2.7411484 | BH18: =100*((DataQ!V169/DataQ!V165)-1) -> 2.7411484 | BI18: 2 | BK18: 42064 | BL18: =HAVERM!B309 -> 1.99 | BM18: =HAVERM!C309 -> 2.98 | BQ18: =BL18-BT18 -> 1.3028524 | BR18: =BM18-BU18 -> 1.8285952 | BT18: =HAVERM!D309 -> 0.68714762 | BU18: =HAVERM!E309 -> 1.1514048 | BY18: 0 | CA18: 44958 | CB18: =HAVERM!G404-HAVERM!G$389 -> 2.95 | CC18: =HAVERM!H404-HAVERM!H$389 -> 0.63 | CD18: 0
S19: 2025 | T19: =100*((DataA!B59/DataA!B58)-1) -> 1.7016597 | U19: =100*((W19/W18)-1) -> 1.379064 | W19: =SUM(W12:W15) -> 2330772.8 | AG19: 41548 | AH19: =100*((DataQ!U170/DataQ!U166)-1) -> 1.0101082 | AI19: =100*((DataQ!V170/DataQ!V166)-1) -> 2.0904694 | AJ19: =AH19-AI19 -> -1.0803612 | AK19: 0 | AM19: 41548 | AN19: =DataQ!W170/DataQ!W166*100 -> 103.73675 | AO19: =DataQ!X170/DataQ!X166*100 -> 96.967213 | AP19: =DataQ!Y170/DataQ!Y166*100 -> 106.97342 | AQ19: =DataQ!V170/DataQ!V166*100 -> 102.09047 | AS19: =DataQ!W166/DataQ!W166*100 -> 100 | AT19: =DataQ!X166/DataQ!X166*100 -> 100 | AU19: =DataQ!Y166/DataQ!Y166*100 -> 100 | AV19: =DataQ!V166/DataQ!V166*100 -> 100 | AX19: =HAVERQ!C62*AN19/$AQ19 -> 152.41886 | AY19: =HAVERQ!D62*AO19/$AQ19 -> 37.99266 | AZ19: =HAVERQ!E62*AP19/$AQ19 -> 50.295824 | BA19: =1000*AQ19/$AQ19 -> 1000 | BC19: =$AV19/100*(AN19-100)*HAVERQ!C62/1000+(AS19-100)*AX19/$BA19 -> 0.56051305 | BD19: =$AV19/100*(AO19-100)*HAVERQ!D62/1000+(AT19-100)*AY19/$BA19 -> -0.12131148 | BE19: =$AV19/100*(AP19-100)*HAVERQ!E62/1000+(AU19-100)*AZ19/$BA19 -> 0.33472433 | BF19: =BG19-BE19-BD19-BC19 -> 1.3165435 | BG19: =$AV19/100*(AQ19-100)*1000/1000+(AV19-100)*BA19/$BA19 -> 2.0904694 | BH19: =100*((DataQ!V170/DataQ!V166)-1) -> 2.0904694 | BI19: 2 | BK19: 42095 | BL19: =HAVERM!B310 -> 1.95 | BM19: =HAVERM!C310 -> 2.92 | BQ19: =BL19-BT19 -> 1.3036476 | BR19: =BM19-BU19 -> 1.8594333 | BT19: =HAVERM!D310 -> 0.64635238 | BU19: =HAVERM!E310 -> 1.0605667 | BY19: 0 | CA19: 44986 | CB19: =HAVERM!G405-HAVERM!G$389 -> 3.09 | CC19: =HAVERM!H405-HAVERM!H$389 -> 0.73 | CD19: 0
AG20: 41640 | AH20: =100*((DataQ!U171/DataQ!U167)-1) -> 1.7416547 | AI20: =100*((DataQ!V171/DataQ!V167)-1) -> 1.774751 | AJ20: =AH20-AI20 -> -0.033096276 | AK20: 0 | AM20: 41640 | AN20: =DataQ!W171/DataQ!W170*100 -> 100.89227 | AO20: =DataQ!X171/DataQ!X170*100 -> 98.98563 | AP20: =DataQ!Y171/DataQ!Y170*100 -> 103.44146 | AQ20: =DataQ!V171/DataQ!V170*100 -> 100.1007 | AS20: =DataQ!W170/DataQ!W167*100 -> 101.71433 | AT20: =DataQ!X170/DataQ!X167*100 -> 96.414018 | AU20: =DataQ!Y170/DataQ!Y167*100 -> 102.23272 | AV20: =DataQ!V170/DataQ!V167*100 -> 101.67236 | AX20: =HAVERQ!C63*AN20/$AQ20 -> 158.2415 | AY20: =HAVERQ!D63*AO20/$AQ20 -> 34.610116 | AZ20: =HAVERQ!E63*AP20/$AQ20 -> 46.501829 | BA20: =1000*AQ20/$AQ20 -> 1000 | BC20: =$AV20/100*(AN20-100)*HAVERQ!C63/1000+(AS20-100)*AX20/$BA20 -> 0.41370617 | BD20: =$AV20/100*(AO20-100)*HAVERQ!D63/1000+(AT20-100)*AY20/$BA20 -> -0.16020795 | BE20: =$AV20/100*(AP20-100)*HAVERQ!E63/1000+(AU20-100)*AZ20/$BA20 -> 0.26128119 | BF20: =BG20-BE20-BD20-BC20 -> 1.2599716 | BG20: =$AV20/100*(AQ20-100)*1000/1000+(AV20-100)*BA20/$BA20 -> 1.774751 | BH20: =100*((DataQ!V171/DataQ!V167)-1) -> 1.774751 | BI20: 2 | BK20: 42125 | BL20: =HAVERM!B311 -> 1.9 | BM20: =HAVERM!C311 -> 2.86 | BQ20: =BL20-BT20 -> 1.1638524 | BR20: =BM20-BU20 -> 1.5970476 | BT20: =HAVERM!D311 -> 0.73614762 | BU20: =HAVERM!E311 -> 1.2629524 | BY20: 0 | CA20: 45017 | CB20: =HAVERM!G406-HAVERM!G$389 -> 3.21 | CC20: =HAVERM!H406-HAVERM!H$389 -> 0.74 | CD20: 0
U21: HMT survey - https://assets.publishing.service.gov.uk/media/66c4ce002e8f04b086cdf4f7/Forecasts_for_the_UK_economy_August_2024.pdf | AG21: 41730 | AH21: =100*((DataQ!U172/DataQ!U168)-1) -> -0.21261518 | AI21: =100*((DataQ!V172/DataQ!V168)-1) -> 1.7621111 | AJ21: =AH21-AI21 -> -1.9747263 | AK21: 0 | AM21: 41730 | AN21: =DataQ!W172/DataQ!W170*100 -> 100.39656 | AO21: =DataQ!X172/DataQ!X170*100 -> 98.901099 | AP21: =DataQ!Y172/DataQ!Y170*100 -> 102.61423 | AQ21: =DataQ!V172/DataQ!V170*100 -> 100.80564 | AS21: =DataQ!W170/DataQ!W168*100 -> 100.79947 | AT21: =DataQ!X170/DataQ!X168*100 -> 97.553574 | AU21: =DataQ!Y170/DataQ!Y168*100 -> 102.26731 | AV21: =DataQ!V170/DataQ!V168*100 -> 100.94883 | AX21: =HAVERQ!C64*AN21/$AQ21 -> 156.36288 | AY21: =HAVERQ!D64*AO21/$AQ21 -> 34.338738 | AZ21: =HAVERQ!E64*AP21/$AQ21 -> 45.807361 | BA21: =1000*AQ21/$AQ21 -> 1000 | BC21: =$AV21/100*(AN21-100)*HAVERQ!C64/1000+(AS21-100)*AX21/$BA21 -> 0.18785806 | BD21: =$AV21/100*(AO21-100)*HAVERQ!D64/1000+(AT21-100)*AY21/$BA21 -> -0.12283365 | BE21: =$AV21/100*(AP21-100)*HAVERQ!E64/1000+(AU21-100)*AZ21/$BA21 -> 0.22261602 | BF21: =BG21-BE21-BD21-BC21 -> 1.4744707 | BG21: =$AV21/100*(AQ21-100)*1000/1000+(AV21-100)*BA21/$BA21 -> 1.7621111 | BH21: =100*((DataQ!V172/DataQ!V168)-1) -> 1.7621111 | BI21: 2 | BK21: 42156 | BL21: =HAVERM!B312 -> 1.83 | BM21: =HAVERM!C312 -> 2.82 | BQ21: =BL21-BT21 -> 1.0497955 | BR21: =BM21-BU21 -> 1.4679636 | BT21: =HAVERM!D312 -> 0.78020455 | BU21: =HAVERM!E312 -> 1.3520364 | BY21: 0 | CA21: 45047 | CB21: =HAVERM!G407-HAVERM!G$389 -> 3.34 | CC21: =HAVERM!H407-HAVERM!H$389 -> 0.81 | CD21: 0
S22: 2024 | U22: 1.1 | AG22: 41821 | AH22: =100*((DataQ!U173/DataQ!U169)-1) -> 0.8583691 | AI22: =100*((DataQ!V173/DataQ!V169)-1) -> 1.4521783 | AJ22: =AH22-AI22 -> -0.59380922 | AK22: 0 | AM22: 41821 | AN22: =DataQ!W173/DataQ!W170*100 -> 100.13215 | AO22: =DataQ!X173/DataQ!X170*100 -> 98.506593 | AP22: =DataQ!Y173/DataQ!Y170*100 -> 102.51496 | AQ22: =DataQ!V173/DataQ!V170*100 -> 100.83917 | AS22: =DataQ!W170/DataQ!W169*100 -> 100.39814 | AT22: =DataQ!X170/DataQ!X169*100 -> 96.545184 | AU22: =DataQ!Y170/DataQ!Y169*100 -> 102.02563 | AV22: =DataQ!V170/DataQ!V169*100 -> 100.6079 | AX22: =HAVERQ!C65*AN22/$AQ22 -> 155.89922 | AY22: =HAVERQ!D65*AO22/$AQ22 -> 34.190391 | AZ22: =HAVERQ!E65*AP22/$AQ22 -> 45.747827 | BA22: =1000*AQ22/$AQ22 -> 1000 | BC22: =$AV22/100*(AN22-100)*HAVERQ!C65/1000+(AS22-100)*AX22/$BA22 -> 0.08294441 | BD22: =$AV22/100*(AO22-100)*HAVERQ!D65/1000+(AT22-100)*AY22/$BA22 -> -0.17070848 | BE22: =$AV22/100*(AP22-100)*HAVERQ!E65/1000+(AU22-100)*AZ22/$BA22 -> 0.20652916 | BF22: =BG22-BE22-BD22-BC22 -> 1.3334132 | BG22: =$AV22/100*(AQ22-100)*1000/1000+(AV22-100)*BA22/$BA22 -> 1.4521783 | BH22: =100*((DataQ!V173/DataQ!V169)-1) -> 1.4521783 | BI22: 2 | BK22: 42186 | BL22: =HAVERM!B313 -> 1.87 | BM22: =HAVERM!C313 -> 2.83 | BQ22: =BL22-BT22 -> 1.0242609 | BR22: =BM22-BU22 -> 1.422013 | BT22: =HAVERM!D313 -> 0.84573913 | BU22: =HAVERM!E313 -> 1.407987 | BY22: 0 | CA22: 45078 | CB22: =HAVERM!G408-HAVERM!G$389 -> 3.62 | CC22: =HAVERM!H408-HAVERM!H$389 -> 0.91 | CD22: 0
S23: 2025 | U23: 1.4 | AG23: 41913 | AH23: =100*((DataQ!U174/DataQ!U170)-1) -> 1.9999927 | AI23: =100*((DataQ!V174/DataQ!V170)-1) -> 0.90634441 | AJ23: =AH23-AI23 -> 1.0936483 | AK23: 0 | AM23: 41913 | AN23: =DataQ!W174/DataQ!W170*100 -> 100.19828 | AO23: =DataQ!X174/DataQ!X170*100 -> 92.927557 | AP23: =DataQ!Y174/DataQ!Y170*100 -> 102.18398 | AQ23: =DataQ!V174/DataQ!V170*100 -> 100.90634 | AS23: =DataQ!W170/DataQ!W170*100 -> 100 | AT23: =DataQ!X170/DataQ!X170*100 -> 100 | AU23: =DataQ!Y170/DataQ!Y170*100 -> 100 | AV23: =DataQ!V170/DataQ!V170*100 -> 100 | AX23: =HAVERQ!C66*AN23/$AQ23 -> 155.89833 | AY23: =HAVERQ!D66*AO23/$AQ23 -> 32.232507 | AZ23: =HAVERQ!E66*AP23/$AQ23 -> 45.569774 | BA23: =1000*AQ23/$AQ23 -> 1000 | BC23: =$AV23/100*(AN23-100)*HAVERQ!C66/1000+(AS23-100)*AX23/$BA23 -> 0.031130195 | BD23: =$AV23/100*(AO23-100)*HAVERQ!D66/1000+(AT23-100)*AY23/$BA23 -> -0.2475355 | BE23: =$AV23/100*(AP23-100)*HAVERQ!E66/1000+(AU23-100)*AZ23/$BA23 -> 0.098279318 | BF23: =BG23-BE23-BD23-BC23 -> 1.0244704 | BG23: =$AV23/100*(AQ23-100)*1000/1000+(AV23-100)*BA23/$BA23 -> 0.90634441 | BH23: =100*((DataQ!V174/DataQ!V170)-1) -> 0.90634441 | BI23: 2 | BK23: 42217 | BL23: =HAVERM!B314 -> 1.95 | BM23: =HAVERM!C314 -> 2.92 | BQ23: =BL23-BT23 -> 1.1439048 | BR23: =BM23-BU23 -> 1.5978381 | BT23: =HAVERM!D314 -> 0.80609524 | BU23: =HAVERM!E314 -> 1.3221619 | BY23: 0 | CA23: 45108 | CB23: =HAVERM!G409-HAVERM!G$389 -> 3.81 | CC23: =HAVERM!H409-HAVERM!H$389 -> 0.96 | CD23: 0
AG24: 42005 | AH24: =100*((DataQ!U175/DataQ!U171)-1) -> 2.2824609 | AI24: =100*((DataQ!V175/DataQ!V171)-1) -> 0.10060362 | AJ24: =AH24-AI24 -> 2.1818573 | AK24: 0 | AM24: 42005 | AN24: =DataQ!W175/DataQ!W174*100 -> 99.571174 | AO24: =DataQ!X175/DataQ!X174*100 -> 89.99396 | AP24: =DataQ!Y175/DataQ!Y174*100 -> 98.639896 | AQ24: =DataQ!V175/DataQ!V174*100 -> 99.301397 | AS24: =DataQ!W174/DataQ!W171*100 -> 99.312152 | AT24: =DataQ!X174/DataQ!X171*100 -> 93.879846 | AU24: =DataQ!Y174/DataQ!Y171*100 -> 98.784357 | AV24: =DataQ!V174/DataQ!V171*100 -> 100.80483 | AX24: =HAVERQ!C67*AN24/$AQ24 -> 153.41566 | AY24: =HAVERQ!D67*AO24/$AQ24 -> 30.813208 | AZ24: =HAVERQ!E67*AP24/$AQ24 -> 41.720215 | BA24: =1000*AQ24/$AQ24 -> 1000 | BC24: =$AV24/100*(AN24-100)*HAVERQ!C67/1000+(AS24-100)*AX24/$BA24 -> -0.17166501 | BD24: =$AV24/100*(AO24-100)*HAVERQ!D67/1000+(AT24-100)*AY24/$BA24 -> -0.531525 | BE24: =$AV24/100*(AP24-100)*HAVERQ!E67/1000+(AU24-100)*AZ24/$BA24 -> -0.10830101 | BF24: =BG24-BE24-BD24-BC24 -> 0.91209465 | BG24: =$AV24/100*(AQ24-100)*1000/1000+(AV24-100)*BA24/$BA24 -> 0.10060362 | BH24: =100*((DataQ!V175/DataQ!V171)-1) -> 0.10060362 | BI24: 2 | BK24: 42248 | BL24: =HAVERM!B315 -> 1.91 | BM24: =HAVERM!C315 -> 2.84 | BQ24: =BL24-BT24 -> 1.1834227 | BR24: =BM24-BU24 -> 1.6508136 | BT24: =HAVERM!D315 -> 0.72657727 | BU24: =HAVERM!E315 -> 1.1891864 | BY24: 0 | CA24: 45139 | CB24: =HAVERM!G410-HAVERM!G$389 -> 4.01 | CC24: =HAVERM!H410-HAVERM!H$389 -> 1.05 | CD24: 0
S25: H1 2024 | T25: =AVERAGE(T8:T9) -> 0.64475932 | U25: =AVERAGE(U8:U9) -> 0.64475932 | AG25: 42095 | AH25: =100*((DataQ!U176/DataQ!U172)-1) -> 2.5568184 | AI25: =100*((DataQ!V176/DataQ!V172)-1) -> -0.033266733 | AJ25: =AH25-AI25 -> 2.5900851 | AK25: 0 | AM25: 42095 | AN25: =DataQ!W176/DataQ!W174*100 -> 99.274341 | AO25: =DataQ!X176/DataQ!X174*100 -> 94.451181 | AP25: =DataQ!Y176/DataQ!Y174*100 -> 97.40939 | AQ25: =DataQ!V176/DataQ!V174*100 -> 99.866966 | AS25: =DataQ!W174/DataQ!W172*100 -> 99.802502 | AT25: =DataQ!X174/DataQ!X172*100 -> 93.960085 | AU25: =DataQ!Y174/DataQ!Y172*100 -> 99.580716 | AV25: =DataQ!V174/DataQ!V172*100 -> 100.0999 | AX25: =HAVERQ!C68*AN25/$AQ25 -> 152.09208 | AY25: =HAVERQ!D68*AO25/$AQ25 -> 32.15618 | AZ25: =HAVERQ!E68*AP25/$AQ25 -> 40.966443 | BA25: =1000*AQ25/$AQ25 -> 1000 | BC25: =$AV25/100*(AN25-100)*HAVERQ!C68/1000+(AS25-100)*AX25/$BA25 -> -0.14117473 | BD25: =$AV25/100*(AO25-100)*HAVERQ!D68/1000+(AT25-100)*AY25/$BA25 -> -0.3830689 | BE25: =$AV25/100*(AP25-100)*HAVERQ!E68/1000+(AU25-100)*AZ25/$BA25 -> -0.12609087 | BF25: =BG25-BE25-BD25-BC25 -> 0.61706777 | BG25: =$AV25/100*(AQ25-100)*1000/1000+(AV25-100)*BA25/$BA25 -> -0.033266733 | BH25: =100*((DataQ!V176/DataQ!V172)-1) -> -0.033266733 | BI25: 2 | BK25: 42278 | BL25: =HAVERM!B316 -> 1.87 | BM25: =HAVERM!C316 -> 2.78 | BQ25: =BL25-BT25 -> 1.2124818 | BR25: =BM25-BU25 -> 1.6863545 | BT25: =HAVERM!D316 -> 0.65751818 | BU25: =HAVERM!E316 -> 1.0936455 | BY25: 0 | CA25: 45170 | CB25: =HAVERM!G411-HAVERM!G$389 -> 4.11 | CC25: =HAVERM!H411-HAVERM!H$389 -> 1.14 | CD25: 0
S26: H2 2024 & 2025 | T26: =AVERAGE(T10:T15) -> 0.41496087 | U26: =AVERAGE(U10:U15) -> 0.3271369 | AG26: 42186 | AH26: =100*((DataQ!U177/DataQ!U173)-1) -> 2.9078085 | AI26: =100*((DataQ!V177/DataQ!V173)-1) -> 0.033355537 | AJ26: =AH26-AI26 -> 2.874453 | AK26: 0 | AM26: 42186 | AN26: =DataQ!W177/DataQ!W174*100 -> 98.680703 | AO26: =DataQ!X177/DataQ!X174*100 -> 92.207457 | AP26: =DataQ!Y177/DataQ!Y174*100 -> 96.664539 | AQ26: =DataQ!V177/DataQ!V174*100 -> 99.966766 | AS26: =DataQ!W174/DataQ!W173*100 -> 100.06604 | AT26: =DataQ!X174/DataQ!X173*100 -> 94.336383 | AU26: =DataQ!Y174/DataQ!Y173*100 -> 99.677147 | AV26: =DataQ!V174/DataQ!V173*100 -> 100.06661 | AX26: =HAVERQ!C69*AN26/$AQ26 -> 151.03167 | AY26: =HAVERQ!D69*AO26/$AQ26 -> 31.360958 | AZ26: =HAVERQ!E69*AP26/$AQ26 -> 40.612603 | BA26: =1000*AQ26/$AQ26 -> 1000 | BC26: =$AV26/100*(AN26-100)*HAVERQ!C69/1000+(AS26-100)*AX26/$BA26 -> -0.19201283 | BD26: =$AV26/100*(AO26-100)*HAVERQ!D69/1000+(AT26-100)*AY26/$BA26 -> -0.44273941 | BE26: =$AV26/100*(AP26-100)*HAVERQ!E69/1000+(AU26-100)*AZ26/$BA26 -> -0.15329459 | BF26: =BG26-BE26-BD26-BC26 -> 0.82140238 | BG26: =$AV26/100*(AQ26-100)*1000/1000+(AV26-100)*BA26/$BA26 -> 0.033355537 | BH26: =100*((DataQ!V177/DataQ!V173)-1) -> 0.033355537 | BI26: 2 | BK26: 42309 | BL26: =HAVERM!B317 -> 1.92 | BM26: =HAVERM!C317 -> 2.77 | BQ26: =BL26-BT26 -> 1.1974619 | BR26: =BM26-BU26 -> 1.5989381 | BT26: =HAVERM!D317 -> 0.7225381 | BU26: =HAVERM!E317 -> 1.1710619 | BY26: 0 | CA26: 45200 | CB26: =HAVERM!G412-HAVERM!G$389 -> 4.08 | CC26: =HAVERM!H412-HAVERM!H$389 -> 1.2 | CD26: 0
AG27: 42278 | AH27: =100*((DataQ!U178/DataQ!U174)-1) -> 1.8907563 | AI27: =100*((DataQ!V178/DataQ!V174)-1) -> 0.099800399 | AJ27: =AH27-AI27 -> 1.7909559 | AK27: 0 | AM27: 42278 | AN27: =DataQ!W178/DataQ!W174*100 -> 98.251946 | AO27: =DataQ!X178/DataQ!X174*100 -> 87.204396 | AP27: =DataQ!Y178/DataQ!Y174*100 -> 95.887337 | AQ27: =DataQ!V178/DataQ!V174*100 -> 100.0998 | AS27: =DataQ!W174/DataQ!W174*100 -> 100 | AT27: =DataQ!X174/DataQ!X174*100 -> 100 | AU27: =DataQ!Y174/DataQ!Y174*100 -> 100 | AV27: =DataQ!V174/DataQ!V174*100 -> 100 | AX27: =HAVERQ!C70*AN27/$AQ27 -> 150.1756 | AY27: =HAVERQ!D70*AO27/$AQ27 -> 29.619934 | AZ27: =HAVERQ!E70*AP27/$AQ27 -> 40.232529 | BA27: =1000*AQ27/$AQ27 -> 1000 | BC27: =$AV27/100*(AN27-100)*HAVERQ!C70/1000+(AS27-100)*AX27/$BA27 -> -0.26745219 | BD27: =$AV27/100*(AO27-100)*HAVERQ!D70/1000+(AT27-100)*AY27/$BA27 -> -0.43505054 | BE27: =$AV27/100*(AP27-100)*HAVERQ!E70/1000+(AU27-100)*AZ27/$BA27 -> -0.17273186 | BF27: =BG27-BE27-BD27-BC27 -> 0.97503499 | BG27: =$AV27/100*(AQ27-100)*1000/1000+(AV27-100)*BA27/$BA27 -> 0.099800399 | BH27: =100*((DataQ!V178/DataQ!V174)-1) -> 0.099800399 | BI27: 2 | BK27: 42339 | BL27: =HAVERM!B318 -> 1.9 | BM27: =HAVERM!C318 -> 2.75 | BQ27: =BL27-BT27 -> 1.1574739 | BR27: =BM27-BU27 -> 1.5918435 | BT27: =HAVERM!D318 -> 0.74252609 | BU27: =HAVERM!E318 -> 1.1581565 | BY27: 0 | CA27: 45231 | CB27: =HAVERM!G413-HAVERM!G$389 -> 4.1 | CC27: =HAVERM!H413-HAVERM!H$389 -> 1.26 | CD27: 0
AG28: 42370 | AH28: =100*((DataQ!U179/DataQ!U175)-1) -> 2.1617782 | AI28: =100*((DataQ!V179/DataQ!V175)-1) -> 0.33501508 | AJ28: =AH28-AI28 -> 1.8267632 | AK28: 0 | AM28: 42370 | AN28: =DataQ!W179/DataQ!W178*100 -> 99.832155 | AO28: =DataQ!X179/DataQ!X178*100 -> 94.993046 | AP28: =DataQ!Y179/DataQ!Y178*100 -> 98.986829 | AQ28: =DataQ!V179/DataQ!V178*100 -> 99.534736 | AS28: =DataQ!W178/DataQ!W175*100 -> 98.675091 | AT28: =DataQ!X178/DataQ!X175*100 -> 96.900276 | AU28: =DataQ!Y178/DataQ!Y175*100 -> 97.209487 | AV28: =DataQ!V178/DataQ!V175*100 -> 100.80402 | AX28: =HAVERQ!C71*AN28/$AQ28 -> 145.43327 | AY28: =HAVERQ!D71*AO28/$AQ28 -> 30.539866 | AZ28: =HAVERQ!E71*AP28/$AQ28 -> 34.807336 | BA28: =1000*AQ28/$AQ28 -> 1000 | BC28: =$AV28/100*(AN28-100)*HAVERQ!C71/1000+(AS28-100)*AX28/$BA28 -> -0.2172191 | BD28: =$AV28/100*(AO28-100)*HAVERQ!D71/1000+(AT28-100)*AY28/$BA28 -> -0.2561759 | BE28: =$AV28/100*(AP28-100)*HAVERQ!E71/1000+(AU28-100)*AZ28/$BA28 -> -0.13287643 | BF28: =BG28-BE28-BD28-BC28 -> 0.9412865 | BG28: =$AV28/100*(AQ28-100)*1000/1000+(AV28-100)*BA28/$BA28 -> 0.33501508 | BH28: =100*((DataQ!V179/DataQ!V175)-1) -> 0.33501508 | BI28: 2 | BK28: 42370 | BL28: =HAVERM!B319 -> 1.93 | BM28: =HAVERM!C319 -> 2.68 | BQ28: =BL28-BT28 -> 1.3224 | BR28: =BM28-BU28 -> 1.6969905 | BT28: =HAVERM!D319 -> 0.6076 | BU28: =HAVERM!E319 -> 0.98300952 | BW28: =BL28-BL4 -> -0.44 | BY28: 0 | CA28: 45261 | CB28: =HAVERM!G414-HAVERM!G$389 -> 4.12 | CC28: =HAVERM!H414-HAVERM!H$389 -> 1.35 | CD28: 0
AG29: 42461 | AH29: =100*((DataQ!U180/DataQ!U176)-1) -> 2.5623409 | AI29: =100*((DataQ!V180/DataQ!V176)-1) -> 0.33307784 | AJ29: =AH29-AI29 -> 2.2292631 | AK29: 0 | AM29: 42461 | AN29: =DataQ!W180/DataQ!W178*100 -> 99.32863 | AO29: =DataQ!X180/DataQ!X178*100 -> 101.18219 | AP29: =DataQ!Y180/DataQ!Y178*100 -> 97.737254 | AQ29: =DataQ!V180/DataQ!V178*100 -> 100.0997 | AS29: =DataQ!W178/DataQ!W176*100 -> 98.970133 | AT29: =DataQ!X178/DataQ!X176*100 -> 92.327481 | AU29: =DataQ!Y178/DataQ!Y176*100 -> 98.437467 | AV29: =DataQ!V178/DataQ!V176*100 -> 100.23314 | AX29: =HAVERQ!C72*AN29/$AQ29 -> 143.88306 | AY29: =HAVERQ!D72*AO29/$AQ29 -> 32.346053 | AZ29: =HAVERQ!E72*AP29/$AQ29 -> 34.173967 | BA29: =1000*AQ29/$AQ29 -> 1000 | BC29: =$AV29/100*(AN29-100)*HAVERQ!C72/1000+(AS29-100)*AX29/$BA29 -> -0.24575603 | BD29: =$AV29/100*(AO29-100)*HAVERQ!D72/1000+(AT29-100)*AY29/$BA29 -> -0.21025731 | BE29: =$AV29/100*(AP29-100)*HAVERQ!E72/1000+(AU29-100)*AZ29/$BA29 -> -0.13277868 | BF29: =BG29-BE29-BD29-BC29 -> 0.92186986 | BG29: =$AV29/100*(AQ29-100)*1000/1000+(AV29-100)*BA29/$BA29 -> 0.33307784 | BH29: =100*((DataQ!V180/DataQ!V176)-1) -> 0.33307784 | BI29: 2 | BK29: 42401 | BL29: =HAVERM!B320 -> 1.95 | BM29: =HAVERM!C320 -> 2.73 | BQ29: =BL29-BT29 -> 1.5433238 | BR29: =BM29-BU29 -> 2.1155333 | BT29: =HAVERM!D320 -> 0.40667619 | BU29: =HAVERM!E320 -> 0.61446667 | BW29: =BL29-BL5 -> -0.43 | BY29: 0 | CA29: 45292 | CB29: =HAVERM!G415-HAVERM!G$389 -> 4.14 | CC29: =HAVERM!H415-HAVERM!H$389 -> 1.4 | CD29: 0
AG30: 42552 | AH30: =100*((DataQ!U181/DataQ!U177)-1) -> 2.3432045 | AI30: =100*((DataQ!V181/DataQ!V177)-1) -> 0.69883504 | AJ30: =AH30-AI30 -> 1.6443695 | AK30: 0 | AM30: 42552 | AN30: =DataQ!W181/DataQ!W178*100 -> 99.227925 | AO30: =DataQ!X181/DataQ!X178*100 -> 103.75522 | AP30: =DataQ!Y181/DataQ!Y178*100 -> 97.973658 | AQ30: =DataQ!V181/DataQ!V178*100 -> 100.565 | AS30: =DataQ!W178/DataQ!W177*100 -> 99.565511 | AT30: =DataQ!X178/DataQ!X177*100 -> 94.574125 | AU30: =DataQ!Y178/DataQ!Y177*100 -> 99.19598 | AV30: =DataQ!V178/DataQ!V177*100 -> 100.13308 | AX30: =HAVERQ!C73*AN30/$AQ30 -> 143.07213 | AY30: =HAVERQ!D73*AO30/$AQ30 -> 33.015132 | AZ30: =HAVERQ!E73*AP30/$AQ30 -> 34.098124 | BA30: =1000*AQ30/$AQ30 -> 1000 | BC30: =$AV30/100*(AN30-100)*HAVERQ!C73/1000+(AS30-100)*AX30/$BA30 -> -0.174263 | BD30: =$AV30/100*(AO30-100)*HAVERQ!D73/1000+(AT30-100)*AY30/$BA30 -> -0.058809154 | BE30: =$AV30/100*(AP30-100)*HAVERQ!E73/1000+(AU30-100)*AZ30/$BA30 -> -0.098431945 | BF30: =BG30-BE30-BD30-BC30 -> 1.0303391 | BG30: =$AV30/100*(AQ30-100)*1000/1000+(AV30-100)*BA30/$BA30 -> 0.69883504 | BH30: =100*((DataQ!V181/DataQ!V177)-1) -> 0.69883504 | BI30: 2 | BK30: 42430 | BL30: =HAVERM!B321 -> 1.9 | BM30: =HAVERM!C321 -> 2.7 | BQ30: =BL30-BT30 -> 1.4501435 | BR30: =BM30-BU30 -> 2.0500696 | BT30: =HAVERM!D321 -> 0.44985652 | BU30: =HAVERM!E321 -> 0.64993043 | BW30: =BL30-BL6 -> -0.47 | BY30: 0 | CA30: 45323 | CB30: =HAVERM!G416-HAVERM!G$389 -> 4.15 | CC30: =HAVERM!H416-HAVERM!H$389 -> 1.47 | CD30: 0
AG31: 42644 | AH31: =100*((DataQ!U182/DataQ!U178)-1) -> 2.4742268 | AI31: =100*((DataQ!V182/DataQ!V178)-1) -> 1.1964108 | AJ31: =AH31-AI31 -> 1.277816 | AK31: 0 | AM31: 42644 | AN31: =DataQ!W182/DataQ!W178*100 -> 99.295065 | AO31: =DataQ!X182/DataQ!X178*100 -> 107.37131 | AP31: =DataQ!Y182/DataQ!Y178*100 -> 98.615339 | AQ31: =DataQ!V182/DataQ!V178*100 -> 101.19641 | AS31: =DataQ!W178/DataQ!W178*100 -> 100 | AT31: =DataQ!X178/DataQ!X178*100 -> 100 | AU31: =DataQ!Y178/DataQ!Y178*100 -> 100 | AV31: =DataQ!V178/DataQ!V178*100 -> 100 | AX31: =HAVERQ!C74*AN31/$AQ31 -> 142.27564 | AY31: =HAVERQ!D74*AO31/$AQ31 -> 33.952607 | AZ31: =HAVERQ!E74*AP31/$AQ31 -> 34.107305 | BA31: =1000*AQ31/$AQ31 -> 1000 | BC31: =$AV31/100*(AN31-100)*HAVERQ!C74/1000+(AS31-100)*AX31/$BA31 -> -0.10221551 | BD31: =$AV31/100*(AO31-100)*HAVERQ!D74/1000+(AT31-100)*AY31/$BA31 -> 0.23588194 | BE31: =$AV31/100*(AP31-100)*HAVERQ!E74/1000+(AU31-100)*AZ31/$BA31 -> -0.048463121 | BF31: =BG31-BE31-BD31-BC31 -> 1.1112075 | BG31: =$AV31/100*(AQ31-100)*1000/1000+(AV31-100)*BA31/$BA31 -> 1.1964108 | BH31: =100*((DataQ!V182/DataQ!V178)-1) -> 1.1964108 | BI31: 2 | BK31: 42461 | BL31: =HAVERM!B322 -> 1.84 | BM31: =HAVERM!C322 -> 2.71 | BQ31: =BL31-BT31 -> 1.3879619 | BR31: =BM31-BU31 -> 2.0608476 | BT31: =HAVERM!D322 -> 0.4520381 | BU31: =HAVERM!E322 -> 0.64915238 | BW31: =BL31-BL7 -> -0.7 | BY31: 0 | CA31: 45352 | CB31: =HAVERM!G417-HAVERM!G$389 -> 4.18 | CC31: =HAVERM!H417-HAVERM!H$389 -> 1.49 | CD31: 0
AG32: 42736 | AH32: =100*((DataQ!U183/DataQ!U179)-1) -> 2.1843073 | AI32: =100*((DataQ!V183/DataQ!V179)-1) -> 2.170277 | AJ32: =AH32-AI32 -> 0.014030333 | AK32: 0 | AM32: 42736 | AN32: =DataQ!W183/DataQ!W182*100 -> 101.72414 | AO32: =DataQ!X183/DataQ!X182*100 -> 104.17746 | AP32: =DataQ!Y183/DataQ!Y182*100 -> 100.27397 | AQ32: =DataQ!V183/DataQ!V182*100 -> 100.49261 | AS32: =DataQ!W182/DataQ!W179*100 -> 99.462007 | AT32: =DataQ!X182/DataQ!X179*100 -> 113.03071 | AU32: =DataQ!Y182/DataQ!Y179*100 -> 99.624708 | AV32: =DataQ!V182/DataQ!V179*100 -> 101.66944 | AX32: =HAVERQ!C75*AN32/$AQ32 -> 146.77696 | AY32: =HAVERQ!D75*AO32/$AQ32 -> 33.864484 | AZ32: =HAVERQ!E75*AP32/$AQ32 -> 33.593417 | BA32: =1000*AQ32/$AQ32 -> 1000 | BC32: =$AV32/100*(AN32-100)*HAVERQ!C75/1000+(AS32-100)*AX32/$BA32 -> 0.17520868 | BD32: =$AV32/100*(AO32-100)*HAVERQ!D75/1000+(AT32-100)*AY32/$BA32 -> 0.5800201 | BE32: =$AV32/100*(AP32-100)*HAVERQ!E75/1000+(AU32-100)*AZ32/$BA32 -> -0.0032298366 | BF32: =BG32-BE32-BD32-BC32 -> 1.418278 | BG32: =$AV32/100*(AQ32-100)*1000/1000+(AV32-100)*BA32/$BA32 -> 2.170277 | BH32: =100*((DataQ!V183/DataQ!V179)-1) -> 2.170277 | BI32: 2 | BK32: 42491 | BL32: =HAVERM!B323 -> 1.91 | BM32: =HAVERM!C323 -> 2.64 | BQ32: =BL32-BT32 -> 1.4411136 | BR32: =BM32-BU32 -> 1.9507182 | BT32: =HAVERM!D323 -> 0.46888636 | BU32: =HAVERM!E323 -> 0.68928182 | BW32: =BL32-BL8 -> -0.65 | BY32: 0 | CA32: 45383 | CB32: =HAVERM!G418-HAVERM!G$389 -> 4.17 | CC32: =HAVERM!H418-HAVERM!H$389 -> 1.56 | CD32: 0
AG33: 42826 | AH33: =100*((DataQ!U184/DataQ!U180)-1) -> 2.1606886 | AI33: =100*((DataQ!V184/DataQ!V180)-1) -> 2.7556773 | AJ33: =AH33-AI33 -> -0.59498871 | AK33: 0 | AM33: 42826 | AN33: =DataQ!W184/DataQ!W182*100 -> 102.83976 | AO33: =DataQ!X184/DataQ!X182*100 -> 101.4249 | AP33: =DataQ!Y184/DataQ!Y182*100 -> 102.87667 | AQ33: =DataQ!V184/DataQ!V182*100 -> 101.64207 | AS33: =DataQ!W182/DataQ!W180*100 -> 99.966208 | AT33: =DataQ!X182/DataQ!X180*100 -> 106.1168 | AU33: =DataQ!Y182/DataQ!Y180*100 -> 100.89841 | AV33: =DataQ!V182/DataQ!V180*100 -> 101.09562 | AX33: =HAVERQ!C76*AN33/$AQ33 -> 147.72037 | AY33: =HAVERQ!D76*AO33/$AQ33 -> 32.929493 | AZ33: =HAVERQ!E76*AP33/$AQ33 -> 34.412983 | BA33: =1000*AQ33/$AQ33 -> 1000 | BC33: =$AV33/100*(AN33-100)*HAVERQ!C76/1000+(AS33-100)*AX33/$BA33 -> 0.4141552 | BD33: =$AV33/100*(AO33-100)*HAVERQ!D76/1000+(AT33-100)*AY33/$BA33 -> 0.24896025 | BE33: =$AV33/100*(AP33-100)*HAVERQ!E76/1000+(AU33-100)*AZ33/$BA33 -> 0.12979551 | BF33: =BG33-BE33-BD33-BC33 -> 1.9627663 | BG33: =$AV33/100*(AQ33-100)*1000/1000+(AV33-100)*BA33/$BA33 -> 2.7556773 | BH33: =100*((DataQ!V184/DataQ!V180)-1) -> 2.7556773 | BI33: 2 | BK33: 42522 | BL33: =HAVERM!B324 -> 1.75 | BM33: =HAVERM!C324 -> 2.54 | BQ33: =BL33-BT33 -> 1.3929045 | BR33: =BM33-BU33 -> 2.0278727 | BT33: =HAVERM!D324 -> 0.35709545 | BU33: =HAVERM!E324 -> 0.51212727 | BW33: =BL33-BL9 -> -0.85 | BY33: 0 | CA33: 45413 | CB33: =HAVERM!G419-HAVERM!G$389 -> 4.18 | CC33: =HAVERM!H419-HAVERM!H$389 -> 1.6 | CD33: 0
AG34: 42917 | AH34: =100*((DataQ!U185/DataQ!U181)-1) -> 2.3569091 | AI34: =100*((DataQ!V185/DataQ!V181)-1) -> 2.8089548 | AJ34: =AH34-AI34 -> -0.4520457 | AK34: 0 | AM34: 42917 | AN34: =DataQ!W185/DataQ!W182*100 -> 103.11024 | AO34: =DataQ!X185/DataQ!X182*100 -> 100.9068 | AP34: =DataQ!Y185/DataQ!Y182*100 -> 104.48629 | AQ34: =DataQ!V185/DataQ!V182*100 -> 102.16749 | AS34: =DataQ!W182/DataQ!W181*100 -> 100.06766 | AT34: =DataQ!X182/DataQ!X181*100 -> 103.48522 | AU34: =DataQ!Y182/DataQ!Y181*100 -> 100.65495 | AV34: =DataQ!V182/DataQ!V181*100 -> 100.62786 | AX34: =HAVERQ!C77*AN34/$AQ34 -> 147.34722 | AY34: =HAVERQ!D77*AO34/$AQ34 -> 32.592799 | AZ34: =HAVERQ!E77*AP34/$AQ34 -> 34.771668 | BA34: =1000*AQ34/$AQ34 -> 1000 | BC34: =$AV34/100*(AN34-100)*HAVERQ!C77/1000+(AS34-100)*AX34/$BA34 -> 0.46691648 | BD34: =$AV34/100*(AO34-100)*HAVERQ!D77/1000+(AT34-100)*AY34/$BA34 -> 0.14370531 | BE34: =$AV34/100*(AP34-100)*HAVERQ!E77/1000+(AU34-100)*AZ34/$BA34 -> 0.17626553 | BF34: =BG34-BE34-BD34-BC34 -> 2.0220675 | BG34: =$AV34/100*(AQ34-100)*1000/1000+(AV34-100)*BA34/$BA34 -> 2.8089548 | BH34: =100*((DataQ!V185/DataQ!V181)-1) -> 2.8089548 | BI34: 2 | BK34: 42552 | BL34: =HAVERM!B325 -> 1.72 | BM34: =HAVERM!C325 -> 2.51 | BQ34: =BL34-BT34 -> 1.5872619 | BR34: =BM34-BU34 -> 2.2893238 | BT34: =HAVERM!D325 -> 0.1327381 | BU34: =HAVERM!E325 -> 0.22067619 | BW34: =BL34-BL10 -> -0.82 | BY34: 0 | CA34: 45444 | CB34: =HAVERM!G420-HAVERM!G$389 -> 4.22 | CC34: =HAVERM!H420-HAVERM!H$389 -> 1.64 | CD34: 0
AG35: 43009 | AH35: =100*((DataQ!U186/DataQ!U182)-1) -> 2.6827565 | AI35: =100*((DataQ!V186/DataQ!V182)-1) -> 3.0213793 | AJ35: =AH35-AI35 -> -0.33862277 | AK35: 0 | AM35: 43009 | AN35: =DataQ!W186/DataQ!W182*100 -> 104.22586 | AO35: =DataQ!X186/DataQ!X182*100 -> 103.85366 | AP35: =DataQ!Y186/DataQ!Y182*100 -> 106.19866 | AQ35: =DataQ!V186/DataQ!V182*100 -> 103.02138 | AS35: =DataQ!W182/DataQ!W182*100 -> 100 | AT35: =DataQ!X182/DataQ!X182*100 -> 100 | AU35: =DataQ!Y182/DataQ!Y182*100 -> 100 | AV35: =DataQ!V182/DataQ!V182*100 -> 100 | AX35: =HAVERQ!C78*AN35/$AQ35 -> 147.70697 | AY35: =HAVERQ!D78*AO35/$AQ35 -> 33.266598 | AZ35: =HAVERQ!E78*AP35/$AQ35 -> 35.048592 | BA35: =1000*AQ35/$AQ35 -> 1000 | BC35: =$AV35/100*(AN35-100)*HAVERQ!C78/1000+(AS35-100)*AX35/$BA35 -> 0.61697586 | BD35: =$AV35/100*(AO35-100)*HAVERQ!D78/1000+(AT35-100)*AY35/$BA35 -> 0.1271708 | BE35: =$AV35/100*(AP35-100)*HAVERQ!E78/1000+(AU35-100)*AZ35/$BA35 -> 0.21075434 | BF35: =BG35-BE35-BD35-BC35 -> 2.0664783 | BG35: =$AV35/100*(AQ35-100)*1000/1000+(AV35-100)*BA35/$BA35 -> 3.0213793 | BH35: =100*((DataQ!V186/DataQ!V182)-1) -> 3.0213793 | BI35: 2 | BK35: 42583 | BL35: =HAVERM!B326 -> 1.69 | BM35: =HAVERM!C326 -> 2.39 | BQ35: =BL35-BT35 -> 1.5824 | BR35: =BM35-BU35 -> 2.2147217 | BT35: =HAVERM!D326 -> 0.1076 | BU35: =HAVERM!E326 -> 0.17527826 | BW35: =BL35-BL11 -> -0.85 | BY35: 0 | CA35: 45474 | CB35: =HAVERM!G421-HAVERM!G$389 -> 4.18 | CC35: =HAVERM!H421-HAVERM!H$389 -> 1.68 | CD35: 0
AG36: 43101 | AH36: =100*((DataQ!U187/DataQ!U183)-1) -> 2.6052104 | AI36: =100*((DataQ!V187/DataQ!V183)-1) -> 2.712451 | AJ36: =AH36-AI36 -> -0.10724056 | AK36: 0 | AM36: 43101 | AN36: =DataQ!W187/DataQ!W186*100 -> 101.2325 | AO36: =DataQ!X187/DataQ!X186*100 -> 101.37203 | AP36: =DataQ!Y187/DataQ!Y186*100 -> 100.35466 | AQ36: =DataQ!V187/DataQ!V186*100 -> 100.19127 | AS36: =DataQ!W186/DataQ!W183*100 -> 102.45932 | AT36: =DataQ!X186/DataQ!X183*100 -> 99.689182 | AU36: =DataQ!Y186/DataQ!Y183*100 -> 105.9085 | AV36: =DataQ!V186/DataQ!V183*100 -> 102.51637 | AX36: =HAVERQ!C79*AN36/$AQ36 -> 144.14933 | AY36: =HAVERQ!D79*AO36/$AQ36 -> 31.028077 | AZ36: =HAVERQ!E79*AP36/$AQ36 -> 34.055448 | BA36: =1000*AQ36/$AQ36 -> 1000 | BC36: =$AV36/100*(AN36-100)*HAVERQ!C79/1000+(AS36-100)*AX36/$BA36 -> 0.53477105 | BD36: =$AV36/100*(AO36-100)*HAVERQ!D79/1000+(AT36-100)*AY36/$BA36 -> 0.03349029 | BE36: =$AV36/100*(AP36-100)*HAVERQ!E79/1000+(AU36-100)*AZ36/$BA36 -> 0.21357862 | BF36: =BG36-BE36-BD36-BC36 -> 1.930611 | BG36: =$AV36/100*(AQ36-100)*1000/1000+(AV36-100)*BA36/$BA36 -> 2.712451 | BH36: =100*((DataQ!V187/DataQ!V183)-1) -> 2.712451 | BI36: 2 | BK36: 42614 | BL36: =HAVERM!B327 -> 1.59 | BM36: =HAVERM!C327 -> 2.34 | BQ36: =BL36-BT36 -> 1.4666318 | BR36: =BM36-BU36 -> 2.1336091 | BT36: =HAVERM!D327 -> 0.12336818 | BU36: =HAVERM!E327 -> 0.20639091 | BW36: =BL36-BL12 -> -0.87 | BY36: 0
AG37: 43191 | AH37: =100*((DataQ!U188/DataQ!U184)-1) -> 2.445486 | AI37: =100*((DataQ!V188/DataQ!V184)-1) -> 2.4232625 | AJ37: =AH37-AI37 -> 0.022223406 | AK37: 0 | AM37: 43191 | AN37: =DataQ!W188/DataQ!W186*100 -> 101.42712 | AO37: =DataQ!X188/DataQ!X186*100 -> 105.0203 | AP37: =DataQ!Y188/DataQ!Y186*100 -> 101.90255 | AQ37: =DataQ!V188/DataQ!V186*100 -> 101.05196 | AS37: =DataQ!W186/DataQ!W184*100 -> 101.34783 | AT37: =DataQ!X186/DataQ!X184*100 -> 102.39464 | AU37: =DataQ!Y186/DataQ!Y184*100 -> 103.2291 | AV37: =DataQ!V186/DataQ!V184*100 -> 101.35703 | AX37: =HAVERQ!C80*AN37/$AQ37 -> 143.53089 | AY37: =HAVERQ!D80*AO37/$AQ37 -> 32.217379 | AZ37: =HAVERQ!E80*AP37/$AQ37 -> 34.286189 | BA37: =1000*AQ37/$AQ37 -> 1000 | BC37: =$AV37/100*(AN37-100)*HAVERQ!C80/1000+(AS37-100)*AX37/$BA37 -> 0.40030226 | BD37: =$AV37/100*(AO37-100)*HAVERQ!D80/1000+(AT37-100)*AY37/$BA37 -> 0.23489011 | BE37: =$AV37/100*(AP37-100)*HAVERQ!E80/1000+(AU37-100)*AZ37/$BA37 -> 0.17627779 | BF37: =BG37-BE37-BD37-BC37 -> 1.6117924 | BG37: =$AV37/100*(AQ37-100)*1000/1000+(AV37-100)*BA37/$BA37 -> 2.4232625 | BH37: =100*((DataQ!V188/DataQ!V184)-1) -> 2.4232625 | BI37: 2 | BK37: 42644 | BL37: =HAVERM!B328 -> 1.52 | BM37: =HAVERM!C328 -> 2.27 | BQ37: =BL37-BT37 -> 1.3240381 | BR37: =BM37-BU37 -> 1.9146571 | BT37: =HAVERM!D328 -> 0.1959619 | BU37: =HAVERM!E328 -> 0.35534286 | BW37: =BL37-BL13 -> -0.69 | BY37: 0
AG38: 43282 | AH38: =100*((DataQ!U189/DataQ!U185)-1) -> 3.0920919 | AI38: =100*((DataQ!V189/DataQ!V185)-1) -> 2.5072324 | AJ38: =AH38-AI38 -> 0.5848595 | AK38: 0 | AM38: 43282 | AN38: =DataQ!W189/DataQ!W186*100 -> 101.52442 | AO38: =DataQ!X189/DataQ!X186*100 -> 108.45023 | AP38: =DataQ!Y189/DataQ!Y186*100 -> 105.32086 | AQ38: =DataQ!V189/DataQ!V186*100 -> 101.6576 | AS38: =DataQ!W186/DataQ!W185*100 -> 101.08197 | AT38: =DataQ!X186/DataQ!X185*100 -> 102.92038 | AU38: =DataQ!Y186/DataQ!Y185*100 -> 101.63884 | AV38: =DataQ!V186/DataQ!V185*100 -> 100.83578 | AX38: =HAVERQ!C81*AN38/$AQ38 -> 142.81266 | AY38: =HAVERQ!D81*AO38/$AQ38 -> 33.071381 | AZ38: =HAVERQ!E81*AP38/$AQ38 -> 35.2252 | BA38: =1000*AQ38/$AQ38 -> 1000 | BC38: =$AV38/100*(AN38-100)*HAVERQ!C81/1000+(AS38-100)*AX38/$BA38 -> 0.37433309 | BD38: =$AV38/100*(AO38-100)*HAVERQ!D81/1000+(AT38-100)*AY38/$BA38 -> 0.36072755 | BE38: =$AV38/100*(AP38-100)*HAVERQ!E81/1000+(AU38-100)*AZ38/$BA38 -> 0.24014978 | BF38: =BG38-BE38-BD38-BC38 -> 1.532022 | BG38: =$AV38/100*(AQ38-100)*1000/1000+(AV38-100)*BA38/$BA38 -> 2.5072324 | BH38: =100*((DataQ!V189/DataQ!V185)-1) -> 2.5072324 | BI38: 2 | BK38: 42675 | BL38: =HAVERM!B329 -> 1.43 | BM38: =HAVERM!C329 -> 2.25 | BQ38: =BL38-BT38 -> 1.1526455 | BR38: =BM38-BU38 -> 1.6863136 | BT38: =HAVERM!D329 -> 0.27735455 | BU38: =HAVERM!E329 -> 0.56368636 | BW38: =BL38-BL14 -> -0.74 | BY38: 0
AG39: 43374 | AH39: =100*((DataQ!U190/DataQ!U186)-1) -> 3.4617964 | AI39: =100*((DataQ!V190/DataQ!V186)-1) -> 2.2632444 | AJ39: =AH39-AI39 -> 1.198552 | AK39: 0 | AM39: 43374 | AN39: =DataQ!W190/DataQ!W186*100 -> 101.81635 | AO39: =DataQ!X190/DataQ!X186*100 -> 108.01375 | AP39: =DataQ!Y190/DataQ!Y186*100 -> 108.5456 | AQ39: =DataQ!V190/DataQ!V186*100 -> 102.26324 | AS39: =DataQ!W186/DataQ!W186*100 -> 100 | AT39: =DataQ!X186/DataQ!X186*100 -> 100 | AU39: =DataQ!Y186/DataQ!Y186*100 -> 100 | AV39: =DataQ!V186/DataQ!V186*100 -> 100 | AX39: =HAVERQ!C82*AN39/$AQ39 -> 142.37508 | AY39: =HAVERQ!D82*AO39/$AQ39 -> 32.743204 | AZ39: =HAVERQ!E82*AP39/$AQ39 -> 36.088726 | BA39: =1000*AQ39/$AQ39 -> 1000 | BC39: =$AV39/100*(AN39-100)*HAVERQ!C82/1000+(AS39-100)*AX39/$BA39 -> 0.25973764 | BD39: =$AV39/100*(AO39-100)*HAVERQ!D82/1000+(AT39-100)*AY39/$BA39 -> 0.24842629 | BE39: =$AV39/100*(AP39-100)*HAVERQ!E82/1000+(AU39-100)*AZ39/$BA39 -> 0.29055024 | BF39: =BG39-BE39-BD39-BC39 -> 1.4645302 | BG39: =$AV39/100*(AQ39-100)*1000/1000+(AV39-100)*BA39/$BA39 -> 2.2632444 | BH39: =100*((DataQ!V190/DataQ!V186)-1) -> 2.2632444 | BI39: 2 | BK39: 42705 | BL39: =HAVERM!B330 -> 1.45 | BM39: =HAVERM!C330 -> 2.26 | BQ39: =BL39-BT39 -> 1.1509364 | BR39: =BM39-BU39 -> 1.6513864 | BT39: =HAVERM!D330 -> 0.29906364 | BU39: =HAVERM!E330 -> 0.60861364 | BW39: =BL39-BL15 -> -0.63 | BY39: 0
AG40: 43466 | AH40: =100*((DataQ!U191/DataQ!U187)-1) -> 3.2552148 | AI40: =100*((DataQ!V191/DataQ!V187)-1) -> 1.8453383 | AJ40: =AH40-AI40 -> 1.4098766 | AK40: 0 | AM40: 43466 | AN40: =DataQ!W191/DataQ!W190*100 -> 101.4655 | AO40: =DataQ!X191/DataQ!X190*100 -> 95.150117 | AP40: =DataQ!Y191/DataQ!Y190*100 -> 93.879947 | AQ40: =DataQ!V191/DataQ!V190*100 -> 99.781827 | AS40: =DataQ!W190/DataQ!W187*100 -> 100.57674 | AT40: =DataQ!X190/DataQ!X187*100 -> 106.55183 | AU40: =DataQ!Y190/DataQ!Y187*100 -> 108.16199 | AV40: =DataQ!V190/DataQ!V187*100 -> 102.06802 | AX40: =HAVERQ!C83*AN40/$AQ40 -> 142.3623 | AY40: =HAVERQ!D83*AO40/$AQ40 -> 28.607449 | AZ40: =HAVERQ!E83*AP40/$AQ40 -> 29.793652 | BA40: =1000*AQ40/$AQ40 -> 1000 | BC40: =$AV40/100*(AN40-100)*HAVERQ!C83/1000+(AS40-100)*AX40/$BA40 -> 0.29151863 | BD40: =$AV40/100*(AO40-100)*HAVERQ!D83/1000+(AT40-100)*AY40/$BA40 -> 0.038925695 | BE40: =$AV40/100*(AP40-100)*HAVERQ!E83/1000+(AU40-100)*AZ40/$BA40 -> 0.045365883 | BF40: =BG40-BE40-BD40-BC40 -> 1.4695281 | BG40: =$AV40/100*(AQ40-100)*1000/1000+(AV40-100)*BA40/$BA40 -> 1.8453383 | BH40: =100*((DataQ!V191/DataQ!V187)-1) -> 1.8453383 | BI40: 2 | BK40: 42736 | BL40: =HAVERM!B331 -> 1.45 | BM40: =HAVERM!C331 -> 2.22 | BQ40: =BL40-BT40 -> 1.1252182 | BR40: =BM40-BU40 -> 1.61045 | BT40: =HAVERM!D331 -> 0.32478182 | BU40: =HAVERM!E331 -> 0.60955 | BW40: =BL40-BL16 -> -0.56 | BY40: 0
...

Sheet DataA
B1: =DataQ!D1 -> SEP002A.db | C1: =DataQ!E1 -> JAN011B.db | D1: =DataQ!F1 -> JAN024B.db | E1: =DataQ!G1 -> FEB006C.db | F1: =DataQ!H1 -> FEB019C.db | G1: =DataQ!I1 -> MAR011D.db | H1: =DataQ!J1 -> MAR020B.db | I1: =DataQ!K1 -> APR009C.db | ... AE1: =DataQ!AG1 -> SEP002A.db
B2: =DataQ!D2 -> UK | C2: =DataQ!E2 -> UK | D2: =DataQ!F2 -> UK | E2: =DataQ!G2 -> UK | F2: =DataQ!H2 -> UK | G2: =DataQ!I2 -> UK | H2: =DataQ!J2 -> UK | I2: =DataQ!K2 -> UK | ... AE2: =DataQ!AG2 -> UK
B3: =DataQ!D3 -> GDP | C3: =DataQ!E3 -> GDP | D3: =DataQ!F3 -> GDP | E3: =DataQ!G3 -> GDP | F3: =DataQ!H3 -> GDP | G3: =DataQ!I3 -> GDP | H3: =DataQ!J3 -> GDP | I3: =DataQ!K3 -> GDP | ... AE3: =DataQ!AG3 -> RSWAP5YR_RFR
