Workbook
Name _DLX1.INC: HAVERM!$A$1:$W$6
Name _DLX2.INC: HAVERQ!$A$1:$S$6
Name Annual_Data: GMWA!$A$1:$A$2

Sheet >> CHARTS

Sheet >> DATA

Sheet Chart Data
A1: Potential output | L1: GDP by decade | O1: Migration | V1: Working age population | AC1: Population ageing | AN1: Employment change by age band since Q4 2009 | AX1: Inactivity | BE1: Output per hour worked long-term (5yr ma) | BQ1: Output per worker long-term (5yr ma) | CC1: Potential output vs BoE/OBR - 2024-2028 | CH1: GDP forecasts - LT
W2: Working age population (LHS) | Z2: State pension age - males (RHS) | AA2: State pension age - females (RHS) | BB2: Levels | CO2: growth rates
B3: ESTAR * AVHR | C3: EDUC / POP15_64 | D3: K | E3: TREND | F3: YHAT | G3: GDP | I3: Potential output | J3: GDP | M3: Decade average | P3: Historical | Q3: OE baseline (ONS low migration variant) | R3: ONS principal projection | S3: ONS high migration variant | T3: Average 2010-2019 | W3: Working age population | X3: Rolling 10 year average | Y3: ZERO LINE | Z3: State pension age - males | AA3: State pension age - females | AD3: 2023 | AE3: 2030 | AF3: 2040 | AG3: 2050 | AJ3: {=TRANSPOSE('ONS pop proj 2021-based'!B230:B232)} -> 0-15 | AK3: 16-64 | AL3: 65+ | AO3: 16-24 | AP3: 25-34 | AQ3: 35-49 | AR3: 50-64 | AS3: 65+ | AT3: Total | AV3: Check | AY3: % of inactive | AZ3: Average 1993-2023 | BB3: LT sick | BC3: Other | BF3: 5yr ma | BG3: 1972-2007 average | BH3: 2008-2019 average | BI3: ZERO LINE | BL3: Pre-GFC trend calc | BO3: GFC-pandemic | BR3: 5yr ma | BS3: 1972-2007 average | BT3: 2008-2019 average | BU3: ZERO LINE | BX3: Pre-GFC trend calc | CA3: GFC-pandemic | CD3: Oxford Economics | CE3: Office for Budget Responsibility | CF3: Bank of England * | CI3: OE | CJ3: OBR | CK3: 100 LINE | CM3: Difference | CO3: OBR
A4: 1980 | B4: =DataA!F14*DataA!G14 -> 24.76553 | C4: =DataA!H14/DataA!I14 -> 8.4961659 | D4: =DataA!E14 -> 1149523 | E4: =DataA!J14 -> -1.978074 | F4: =DataA!D14 -> 975762 | G4: =DataA!B14 -> 956533 | L4: 1910 | M4: =100*(('BoE A8. UK Real GDP(A)'!D237/'BoE A8. UK Real GDP(A)'!D227)^(1/10)-1) -> 1.4233534 | O4: 2000 | P4: ='[1]2021-based'!H7 -> 139.3 | V4: 1974 | W4: =100*((DataA!M8/DataA!M7)-1) -> 0.028023783 | Y4: 0 | Z4: 65 | AA4: 60 | AC4: 0 | AD4: ='ONS pop proj 2021-based'!E2+'ONS pop proj 2021-based'!E109 -> 665729 | AE4: ='ONS pop proj 2021-based'!L2+'ONS pop proj 2021-based'!L109 -> 730321 | AF4: ='ONS pop proj 2021-based'!V2+'ONS pop proj 2021-based'!V109 -> 751416 | AG4: ='ONS pop proj 2021-based'!AF2+'ONS pop proj 2021-based'!AF109 -> 747150 | AI4: 2010 | AJ4: =('ONS pop est 2010'!B9+'ONS pop est 2010'!B16+'ONS pop est 2010'!B23+'ONS pop est 2010'!B31)/'ONS pop est 2010'!B7 -> 0.18643956 | AK4: =1-AL4-AJ4 -> 0.6480566 | AL4: =('ONS pop est 2010'!G37+'ONS pop est 2010'!G44+'ONS pop est 2010'!G51+'ONS pop est 2010'!G58+'ONS pop est 2010'!G65+'ONS pop est 2010'!G72)/'ONS pop est 2010'!B7 -> 0.16550384 | AN4: 40179 | AO4: =HAVERQ!F167-HAVERQ!F$166 -> -21 | AP4: =HAVERQ!G167-HAVERQ!G$166 -> -35 | AQ4: =HAVERQ!H167-HAVERQ!H$166 -> -87 | AR4: =HAVERQ!I167-HAVERQ!I$166 -> 44 | AS4: =HAVERQ!J167-HAVERQ!J$166 -> 10 | AT4: =SUM(AO4:AS4) -> -89 | AV4: =HAVERQ!D167-HAVERQ!D$166-'Chart Data'!AT4 -> 0 | AX4: 33970 | AZ4: =AVERAGE($AY$7:$AY$374) -> 24.595806 | BE4: 1971 | BG4: =$BL$6 -> 2.2155011 | BI4: 0 | BK4: 1971 | BL4: =AVERAGE(HAVERQ!B11:B14) -> 43.675 | BN4: 2007 | BO4: =AVERAGE(HAVERQ!B155:B158) -> 96.125 | BQ4: 1971 | BS4: =$BX$6 -> 1.9448021 | BU4: 0 | BW4: 1971 | BX4: =AVERAGE(HAVERQ!C11:C14) -> 47.975 | BZ4: 2007 | CA4: =AVERAGE(HAVERQ!C155:C158) -> 95.975 | CC4: Labour | CD4: =0.65*(100*((B52/B47)^(1/5)-1)) -> 0.83941879 | CE4: ='OBR AS23 - C2.7'!C35+'OBR AS23 - C2.7'!D35 -> 0.66521683 | CF4: =AVERAGE('MPR Feb24 - Chart 3.1'!D10:D12) -> 0.46666667 | CH4: 2015 | CI4: =100*(DataA!B49/DataA!$B$53) -> 92.732062 | CJ4: =CI4 -> 92.732062 | CK4: 100 | CM4: =100*((CJ4/CI4)-1) -> 0
A5: 1981 | B5: =DataA!F15*DataA!G15 -> 24.65965 | C5: =DataA!H15/DataA!I15 -> 8.5228971 | D5: =DataA!E15 -> 1157411 | E5: =DataA!J15 -> -1.965721 | F5: =DataA!D15 -> 990112 | G5: =DataA!B15 -> 949961 | I5: =100*((F5/F4)-1) -> 1.4706455 | J5: =100*((G5/G4)-1) -> -0.68706464 | L5: 1920 | M5: =100*(('BoE A8. UK Real GDP(A)'!D247/'BoE A8. UK Real GDP(A)'!D237)^(1/10)-1) -> 0.79533427 | O5: 2001 | P5: ='[1]2021-based'!H8 -> 153.2 | V5: 1975 | W5: =100*((DataA!M9/DataA!M8)-1) -> -0.015228704 | Y5: 0 | Z5: 65 | AA5: 60 | AC5: 1 | AD5: ='ONS pop proj 2021-based'!E3+'ONS pop proj 2021-based'!E110 -> 700228 | AE5: ='ONS pop proj 2021-based'!L3+'ONS pop proj 2021-based'!L110 -> 734201 | AF5: ='ONS pop proj 2021-based'!V3+'ONS pop proj 2021-based'!V110 -> 751454 | AG5: ='ONS pop proj 2021-based'!AF3+'ONS pop proj 2021-based'!AF110 -> 754216 | AN5: 40269 | AO5: =HAVERQ!F168-HAVERQ!F$166 -> 26 | AP5: =HAVERQ!G168-HAVERQ!G$166 -> 52 | AQ5: =HAVERQ!H168-HAVERQ!H$166 -> -72 | AR5: =HAVERQ!I168-HAVERQ!I$166 -> 32 | AS5: =HAVERQ!J168-HAVERQ!J$166 -> 54 | AT5: =SUM(AO5:AS5) -> 92 | AV5: =HAVERQ!D168-HAVERQ!D$166-'Chart Data'!AT5 -> -2 | AX5: 34001 | AZ5: =AVERAGE($AY$7:$AY$374) -> 24.595806 | BG5: =$BL$6 -> 2.2155011 | BI5: 0 | BK5: 2007 | BL5: =AVERAGE(HAVERQ!B155:B158) -> 96.125 | BN5: 2023 | BO5: =AVERAGE(HAVERQ!B219:B222) -> 102.26825 | BS5: =$BX$6 -> 1.9448021 | BU5: 0 | BW5: 2007 | BX5: =AVERAGE(HAVERQ!C155:C158) -> 95.975 | BZ5: 2019 | CA5: =AVERAGE(HAVERQ!C203:C206) -> 99.975 | CC5: Productivity | CD5: =CD6-CD4 -> 0.77999694 | CE5: =+'OBR AS23 - C2.7'!E35+'OBR AS23 - C2.7'!F35 -> 0.95453827 | CF5: =AVERAGE('MPR Feb24 - Chart 3.1'!C10:C12) -> 0.7 | CH5: 2016 | CI5: =100*(DataA!B50/DataA!$B$53) -> 94.513503 | CJ5: =CI5 -> 94.513503 | CK5: 100 | CM5: =100*((CJ5/CI5)-1) -> 0
A6: 1982 | B6: =DataA!F16*DataA!G16 -> 24.29771 | C6: =DataA!H16/DataA!I16 -> 8.5398108 | D6: =DataA!E16 -> 1167835 | E6: =DataA!J16 -> -1.953444 | F6: =DataA!D16 -> 996004.9 | G6: =DataA!B16 -> 968629 | I6: =100*((F6/F5)-1) -> 0.59517509 | J6: =100*((G6/G5)-1) -> 1.9651333 | L6: 1930 | M6: =100*(('BoE A8. UK Real GDP(A)'!D257/'BoE A8. UK Real GDP(A)'!D247)^(1/10)-1) -> 2.0461093 | O6: 2002 | P6: ='[1]2021-based'!H9 -> 190.9 | V6: 1976 | W6: =100*((DataA!M10/DataA!M9)-1) -> 0.10264916 | Y6: 0 | Z6: 65 | AA6: 60 | AC6: 2 | AD6: ='ONS pop proj 2021-based'!E4+'ONS pop proj 2021-based'!E111 -> 691721 | AE6: ='ONS pop proj 2021-based'!L4+'ONS pop proj 2021-based'!L111 -> 739401 | AF6: ='ONS pop proj 2021-based'!V4+'ONS pop proj 2021-based'!V111 -> 752653 | AG6: ='ONS pop proj 2021-based'!AF4+'ONS pop proj 2021-based'!AF111 -> 762458 | AI6: {=TRANSPOSE('ONS pop proj 2021-based'!E1:AF1)} -> 2023 | AJ6: {=TRANSPOSE('ONS pop proj 2021-based'!E230:AF232)} -> 0.17987297 | AK6: 0.63099918 | AL6: 0.18912785 | AN6: 40360 | AO6: =HAVERQ!F169-HAVERQ!F$166 -> 75 | AP6: =HAVERQ!G169-HAVERQ!G$166 -> 97 | AQ6: =HAVERQ!H169-HAVERQ!H$166 -> -83 | AR6: =HAVERQ!I169-HAVERQ!I$166 -> 107 | AS6: =HAVERQ!J169-HAVERQ!J$166 -> 88 | AT6: =SUM(AO6:AS6) -> 284 | AV6: =HAVERQ!D169-HAVERQ!D$166-'Chart Data'!AT6 -> -1 | AX6: 34029 | AZ6: =AVERAGE($AY$7:$AY$374) -> 24.595806 | BG6: =$BL$6 -> 2.2155011 | BI6: 0 | BK6: y/y | BL6: =100*((BL5/BL4)^(1/36)-1) -> 2.2155011 | BN6: y/y | BO6: =100*((BO5/BO4)^(1/16)-1) -> 0.38793701 | BS6: =$BX$6 -> 1.9448021 | BU6: 0 | BW6: y/y | BX6: =100*((BX5/BX4)^(1/36)-1) -> 1.9448021 | BZ6: y/y | CA6: =100*((CA5/CA4)^(1/12)-1) -> 0.34084969 | CC6: Potential output | CD6: =100*((DataA!D62/DataA!D57)^(1/5)-1) -> 1.6194157 | CE6: ='OBR AS23 - C2.7'!G35 -> 1.6197551 | CF6: =AVERAGE('MPR Feb24 - Chart 3.1'!B10:B12) -> 1.1666667 | CH6: 2017 | CI6: =100*(DataA!B51/DataA!$B$53) -> 97.022903 | CJ6: =CI6 -> 97.022903 | CK6: 100 | CM6: =100*((CJ6/CI6)-1) -> 0
A7: 1983 | B7: =DataA!F17*DataA!G17 -> 24.30468 | C7: =DataA!H17/DataA!I17 -> 8.5563186 | D7: =DataA!E17 -> 1180230 | E7: =DataA!J17 -> -1.941244 | F7: =DataA!D17 -> 1012416 | G7: =DataA!B17 -> 1008981 | I7: =100*((F7/F6)-1) -> 1.6476927 | J7: =100*((G7/G6)-1) -> 4.1658881 | L7: 1940 | M7: =100*(('BoE A8. UK Real GDP(A)'!D267/'BoE A8. UK Real GDP(A)'!D257)^(1/10)-1) -> 1.4936364 | O7: 2003 | P7: ='[1]2021-based'!H10 -> 194.3 | V7: 1977 | W7: =100*((DataA!M11/DataA!M10)-1) -> 0.58379587 | Y7: 0 | Z7: 65 | AA7: 60 | AC7: 3 | AD7: ='ONS pop proj 2021-based'!E5+'ONS pop proj 2021-based'!E112 -> 719113 | AE7: ='ONS pop proj 2021-based'!L5+'ONS pop proj 2021-based'!L112 -> 742134 | AF7: ='ONS pop proj 2021-based'!V5+'ONS pop proj 2021-based'!V112 -> 751976 | AG7: ='ONS pop proj 2021-based'!AF5+'ONS pop proj 2021-based'!AF112 -> 768470 | AI7: 2024 | AJ7: 0.17770521 | AK7: 0.63152053 | AL7: 0.19077426 | AN7: 40452 | AO7: =HAVERQ!F170-HAVERQ!F$166 -> -8 | AP7: =HAVERQ!G170-HAVERQ!G$166 -> 142 | AQ7: =HAVERQ!H170-HAVERQ!H$166 -> -103 | AR7: =HAVERQ!I170-HAVERQ!I$166 -> 84 | AS7: =HAVERQ!J170-HAVERQ!J$166 -> 109 | AT7: =SUM(AO7:AS7) -> 224 | AV7: =HAVERQ!D170-HAVERQ!D$166-'Chart Data'!AT7 -> -2 | AX7: 34060 | AY7: =100*(HAVERM!C46/HAVERM!B46) -> 21.187332 | AZ7: =AVERAGE($AY$7:$AY$374) -> 24.595806 | BB7: =HAVERM!C46 -> 1813 | BC7: =HAVERM!B46-HAVERM!C46 -> 6744 | BG7: =$BL$6 -> 2.2155011 | BI7: 0 | BK7: q/q | BL7: =100*((BL5/BL4)^(1/144)-1) -> 0.5493322 | BN7: q/q | BO7: =100*((BO5/BO4)^(1/64)-1) -> 0.096843481 | BS7: =$BX$6 -> 1.9448021 | BU7: 0 | BW7: q/q | BX7: =100*((BX5/BX4)^(1/144)-1) -> 0.48269436 | BZ7: q/q | CA7: =100*((CA5/CA4)^(1/48)-1) -> 0.085103722 | CF7: =+CD6-CF6 -> 0.45274907 | CH7: 2018 | CI7: =100*(DataA!B52/DataA!$B$53) -> 98.384903 | CJ7: =CI7 -> 98.384903 | CK7: 100 | CM7: =100*((CJ7/CI7)-1) -> 0
A8: 1984 | B8: =DataA!F18*DataA!G18 -> 24.9108 | C8: =DataA!H18/DataA!I18 -> 8.5981658 | D8: =DataA!E18 -> 1202767 | E8: =DataA!J18 -> -1.929121 | F8: =DataA!D18 -> 1047849 | G8: =DataA!B18 -> 1031385 | I8: =100*((F8/F7)-1) -> 3.4998459 | J8: =100*((G8/G7)-1) -> 2.2204581 | L8: 1950 | M8: =100*(('BoE A8. UK Real GDP(A)'!D277/'BoE A8. UK Real GDP(A)'!D267)^(1/10)-1) -> 3.1113357 | O8: 2004 | P8: ='[1]2021-based'!H11 -> 209.5 | V8: 1978 | W8: =100*((DataA!M12/DataA!M11)-1) -> 0.62030177 | Y8: 0 | Z8: 65 | AA8: 60 | AC8: 4 | AD8: ='ONS pop proj 2021-based'!E6+'ONS pop proj 2021-based'!E113 -> 732580 | AE8: ='ONS pop proj 2021-based'!L6+'ONS pop proj 2021-based'!L113 -> 743188 | AF8: ='ONS pop proj 2021-based'!V6+'ONS pop proj 2021-based'!V113 -> 750860 | AG8: ='ONS pop proj 2021-based'!AF6+'ONS pop proj 2021-based'!AF113 -> 773414 | AI8: 2025 | AJ8: 0.17578298 | AK8: 0.63154095 | AL8: 0.19267607 | AN8: 40544 | AO8: =HAVERQ!F171-HAVERQ!F$166 -> -2 | AP8: =HAVERQ!G171-HAVERQ!G$166 -> 180 | AQ8: =HAVERQ!H171-HAVERQ!H$166 -> -100 | AR8: =HAVERQ!I171-HAVERQ!I$166 -> 144 | AS8: =HAVERQ!J171-HAVERQ!J$166 -> 118 | AT8: =SUM(AO8:AS8) -> 340 | AV8: =HAVERQ!D171-HAVERQ!D$166-'Chart Data'!AT8 -> -1 | AX8: 34090 | AY8: =100*(HAVERM!C47/HAVERM!B47) -> 21.412726 | AZ8: =AVERAGE($AY$7:$AY$374) -> 24.595806 | BB8: =HAVERM!C47 -> 1834 | BC8: =HAVERM!B47-HAVERM!C47 -> 6731 | BE8: 1972 | BG8: =$BL$6 -> 2.2155011 | BI8: 0 | BQ8: 1972 | BS8: =$BX$6 -> 1.9448021 | BU8: 0 | CH8: 2019 | CI8: =100*(DataA!B53/DataA!$B$53) -> 100 | CJ8: =CI8 -> 100 | CK8: 100 | CM8: =100*((CJ8/CI8)-1) -> 0
A9: 1985 | B9: =DataA!F19*DataA!G19 -> 25.10787 | C9: =DataA!H19/DataA!I19 -> 8.6987754 | D9: =DataA!E19 -> 1226994 | E9: =DataA!J19 -> -1.917073 | F9: =DataA!D19 -> 1076968 | G9: =DataA!B19 -> 1073547 | I9: =100*((F9/F8)-1) -> 2.7789309 | J9: =100*((G9/G8)-1) -> 4.0879012 | L9: 1960 | M9: =100*(('BoE A8. UK Real GDP(A)'!D287/'BoE A8. UK Real GDP(A)'!D277)^(1/10)-1) -> 3.4155468 | O9: 2005 | P9: ='[1]2021-based'!H12 -> 335.6 | V9: 1979 | W9: =100*((DataA!M13/DataA!M12)-1) -> 0.61644762 | Y9: 0 | Z9: 65 | AA9: 60 | AC9: 5 | AD9: ='ONS pop proj 2021-based'!E7+'ONS pop proj 2021-based'!E114 -> 744262 | AE9: ='ONS pop proj 2021-based'!L7+'ONS pop proj 2021-based'!L114 -> 743139 | AF9: ='ONS pop proj 2021-based'!V7+'ONS pop proj 2021-based'!V114 -> 751083 | AG9: ='ONS pop proj 2021-based'!AF7+'ONS pop proj 2021-based'!AF114 -> 777784 | AI9: 2026 | AJ9: 0.17389989 | AK9: 0.63106006 | AL9: 0.19504004 | AN9: 40634 | AO9: =HAVERQ!F172-HAVERQ!F$166 -> 11 | AP9: =HAVERQ!G172-HAVERQ!G$166 -> 165 | AQ9: =HAVERQ!H172-HAVERQ!H$166 -> -109 | AR9: =HAVERQ!I172-HAVERQ!I$166 -> 162 | AS9: =HAVERQ!J172-HAVERQ!J$166 -> 117 | AT9: =SUM(AO9:AS9) -> 346 | AV9: =HAVERQ!D172-HAVERQ!D$166-'Chart Data'!AT9 -> -1 | AX9: 34121 | AY9: =100*(HAVERM!C48/HAVERM!B48) -> 21.681261 | AZ9: =AVERAGE($AY$7:$AY$374) -> 24.595806 | BB9: =HAVERM!C48 -> 1857 | BC9: =HAVERM!B48-HAVERM!C48 -> 6708 | BG9: =$BL$6 -> 2.2155011 | BI9: 0 | BS9: =$BX$6 -> 1.9448021 | BU9: 0 | CH9: 2020 | CI9: =100*(DataA!B54/DataA!$B$53) -> 89.640099 | CJ9: =CI9 -> 89.640099 | CK9: 100 | CM9: =100*((CJ9/CI9)-1) -> 0
A10: 1986 | B10: =DataA!F20*DataA!G20 -> 846672.61 | C10: =DataA!H20/DataA!I20 -> 8.8112396 | D10: =DataA!E20 -> 1246573 | E10: =DataA!J20 -> -1.905234 | F10: =DataA!D20 -> 1104492 | G10: =DataA!B20 -> 1106912 | I10: =100*((F10/F9)-1) -> 2.5556934 | J10: =100*((G10/G9)-1) -> 3.1079217 | L10: 1970 | M10: =100*(('BoE A8. UK Real GDP(A)'!D297/'BoE A8. UK Real GDP(A)'!D287)^(1/10)-1) -> 2.6038111 | O10: 2006 | P10: ='[1]2021-based'!H13 -> 254.5 | V10: 1980 | W10: =100*((DataA!M14/DataA!M13)-1) -> 0.61267083 | Y10: 0 | Z10: 65 | AA10: 60 | AC10: 6 | AD10: ='ONS pop proj 2021-based'!E8+'ONS pop proj 2021-based'!E115 -> 762489 | AE10: ='ONS pop proj 2021-based'!L8+'ONS pop proj 2021-based'!L115 -> 738873 | AF10: ='ONS pop proj 2021-based'!V8+'ONS pop proj 2021-based'!V115 -> 752658 | AG10: ='ONS pop proj 2021-based'!AF8+'ONS pop proj 2021-based'!AF115 -> 780457 | AI10: 2027 | AJ10: 0.17190755 | AK10: 0.63027351 | AL10: 0.19781894 | AN10: 40725 | AO10: =HAVERQ!F173-HAVERQ!F$166 -> -87 | AP10: =HAVERQ!G173-HAVERQ!G$166 -> 142 | AQ10: =HAVERQ!H173-HAVERQ!H$166 -> -138 | AR10: =HAVERQ!I173-HAVERQ!I$166 -> 182 | AS10: =HAVERQ!J173-HAVERQ!J$166 -> 83 | AT10: =SUM(AO10:AS10) -> 182 | AV10: =HAVERQ!D173-HAVERQ!D$166-'Chart Data'!AT10 -> -1 | AX10: 34151 | AY10: =100*(HAVERM!C49/HAVERM!B49) -> 21.949802 | AZ10: =AVERAGE($AY$7:$AY$374) -> 24.595806 | BB10: =HAVERM!C49 -> 1889 | BC10: =HAVERM!B49-HAVERM!C49 -> 6717 | BG10: =$BL$6 -> 2.2155011 | BI10: 0 | BS10: =$BX$6 -> 1.9448021 | BU10: 0 | CH10: 2021 | CI10: =100*(DataA!B55/DataA!$B$53) -> 97.416292 | CJ10: =CI10 -> 97.416292 | CK10: 100 | CM10: =100*((CJ10/CI10)-1) -> 0
A11: 1987 | B11: =DataA!F21*DataA!G21 -> 854924.91 | C11: =DataA!H21/DataA!I21 -> 8.9162753 | D11: =DataA!E21 -> 1274603 | E11: =DataA!J21 -> -1.894 | F11: =DataA!D21 -> 1135284 | G11: =DataA!B21 -> 1166905 | I11: =100*((F11/F10)-1) -> 2.787888 | J11: =100*((G11/G10)-1) -> 5.4198527 | L11: 1980 | M11: =100*((DataA!B23/DataA!B13)^(1/10)-1) -> 2.5744037 | O11: 2007 | P11: ='[1]2021-based'!H14 -> 304.6 | V11: 1981 | W11: =100*((DataA!M15/DataA!M14)-1) -> 0.57075665 | Y11: 0 | Z11: 65 | AA11: 60 | AC11: 7 | AD11: ='ONS pop proj 2021-based'!E9+'ONS pop proj 2021-based'!E116 -> 785492 | AE11: ='ONS pop proj 2021-based'!L9+'ONS pop proj 2021-based'!L116 -> 696386 | AF11: ='ONS pop proj 2021-based'!V9+'ONS pop proj 2021-based'!V116 -> 754625 | AG11: ='ONS pop proj 2021-based'!AF9+'ONS pop proj 2021-based'!AF116 -> 781599 | AI11: 2028 | AJ11: 0.17002282 | AK11: 0.62909493 | AL11: 0.20088225 | AN11: 40817 | AO11: =HAVERQ!F174-HAVERQ!F$166 -> -81 | AP11: =HAVERQ!G174-HAVERQ!G$166 -> 159 | AQ11: =HAVERQ!H174-HAVERQ!H$166 -> -137 | AR11: =HAVERQ!I174-HAVERQ!I$166 -> 197 | AS11: =HAVERQ!J174-HAVERQ!J$166 -> 109 | AT11: =SUM(AO11:AS11) -> 247 | AV11: =HAVERQ!D174-HAVERQ!D$166-'Chart Data'!AT11 -> 0 | AX11: 34182 | AY11: =100*(HAVERM!C50/HAVERM!B50) -> 21.950367 | AZ11: =AVERAGE($AY$7:$AY$374) -> 24.595806 | BB11: =HAVERM!C50 -> 1884 | BC11: =HAVERM!B50-HAVERM!C50 -> 6699 | BG11: =$BL$6 -> 2.2155011 | BI11: 0 | BS11: =$BX$6 -> 1.9448021 | BU11: 0 | CH11: 2022 | CI11: =100*(DataA!B56/DataA!$B$53) -> 101.64925 | CJ11: =CJ10*(1+CO11/100) -> 101.65055 | CK11: 100 | CM11: =100*((CJ11/CI11)-1) -> 0.0012771032 | CO11: {=TRANSPOSE('OBR AS23 - TA.1'!C8:I8)} -> 4.3465614
A12: 1988 | B12: =DataA!F22*DataA!G22 -> 869416.83 | C12: =DataA!H22/DataA!I22 -> 9.0335852 | D12: =DataA!E22 -> 1314888 | E12: =DataA!J22 -> -1.882876 | F12: =DataA!D22 -> 1175653 | G12: =DataA!B22 -> 1229650 | I12: =100*((F12/F11)-1) -> 3.5558503 | J12: =100*((G12/G11)-1) -> 5.3770444 | L12: 1990 | M12: =100*((DataA!B33/DataA!B23)^(1/10)-1) -> 2.1292548 | O12: 2008 | P12: ='[1]2021-based'!H15 -> 283.6 | V12: 1982 | W12: =100*((DataA!M16/DataA!M15)-1) -> 0.4752789 | Y12: 0 | Z12: 65 | AA12: 60 | AC12: 8 | AD12: ='ONS pop proj 2021-based'!E10+'ONS pop proj 2021-based'!E117 -> 780395 | AE12: ='ONS pop proj 2021-based'!L10+'ONS pop proj 2021-based'!L117 -> 729840 | AF12: ='ONS pop proj 2021-based'!V10+'ONS pop proj 2021-based'!V117 -> 756645 | AG12: ='ONS pop proj 2021-based'!AF10+'ONS pop proj 2021-based'!AF117 -> 782305 | AI12: 2029 | AJ12: 0.16845782 | AK12: 0.62750419 | AL12: 0.20403798 | AN12: 40909 | AO12: =HAVERQ!F175-HAVERQ!F$166 -> -62 | AP12: =HAVERQ!G175-HAVERQ!G$166 -> 204 | AQ12: =HAVERQ!H175-HAVERQ!H$166 -> -142 | AR12: =HAVERQ!I175-HAVERQ!I$166 -> 232 | AS12: =HAVERQ!J175-HAVERQ!J$166 -> 131 | AT12: =SUM(AO12:AS12) -> 363 | AV12: =HAVERQ!D175-HAVERQ!D$166-'Chart Data'!AT12 -> -1 | AX12: 34213 | AY12: =100*(HAVERM!C51/HAVERM!B51) -> 22.187282 | AZ12: =AVERAGE($AY$7:$AY$374) -> 24.595806 | BB12: =HAVERM!C51 -> 1905 | BC12: =HAVERM!B51-HAVERM!C51 -> 6681 | BE12: 1973 | BG12: =$BL$6 -> 2.2155011 | BI12: 0 | BQ12: 1973 | BS12: =$BX$6 -> 1.9448021 | BU12: 0 | CH12: 2023 | CI12: =100*(DataA!B57/DataA!$B$53) -> 101.79635 | CJ12: =CJ11*(1+CO12/100) -> 102.21375 | CK12: 100 | CM12: =100*((CJ12/CI12)-1) -> 0.41003534 | CO12: 0.55405353
A13: 1989 | B13: =DataA!F23*DataA!G23 -> 881201.46 | C13: =DataA!H23/DataA!I23 -> 9.1558688 | D13: =DataA!E23 -> 1362920 | E13: =DataA!J23 -> -1.871818 | F13: =DataA!D23 -> 1217964 | G13: =DataA!B23 -> 1259191 | I13: =100*((F13/F12)-1) -> 3.5989361 | J13: =100*((G13/G12)-1) -> 2.4023909 | L13: 2000 | M13: =100*((DataA!B43/DataA!B33)^(1/10)-1) -> 1.6882802 | O13: 2009 | P13: ='[1]2021-based'!H16 -> 219.8 | V13: 1983 | W13: =100*((DataA!M17/DataA!M16)-1) -> 0.70478951 | X13: =AVERAGE(W4:W13) -> 0.42994854 | Y13: 0 | Z13: 65 | AA13: 60 | AC13: 9 | AD13: ='ONS pop proj 2021-based'!E11+'ONS pop proj 2021-based'!E118 -> 785418 | AE13: ='ONS pop proj 2021-based'!L11+'ONS pop proj 2021-based'!L118 -> 718056 | AF13: ='ONS pop proj 2021-based'!V11+'ONS pop proj 2021-based'!V118 -> 758544 | AG13: ='ONS pop proj 2021-based'!AF11+'ONS pop proj 2021-based'!AF118 -> 782577 | AI13: 2030 | AJ13: 0.16717205 | AK13: 0.62564887 | AL13: 0.20717908 | AN13: 41000 | AO13: =HAVERQ!F176-HAVERQ!F$166 -> 4 | AP13: =HAVERQ!G176-HAVERQ!G$166 -> 231 | AQ13: =HAVERQ!H176-HAVERQ!H$166 -> -128 | AR13: =HAVERQ!I176-HAVERQ!I$166 -> 296 | AS13: =HAVERQ!J176-HAVERQ!J$166 -> 176 | AT13: =SUM(AO13:AS13) -> 579 | AV13: =HAVERQ!D176-HAVERQ!D$166-'Chart Data'!AT13 -> 0 | AX13: 34243 | AY13: =100*(HAVERM!C52/HAVERM!B52) -> 22.563744 | AZ13: =AVERAGE($AY$7:$AY$374) -> 24.595806 | BB13: =HAVERM!C52 -> 1938 | BC13: =HAVERM!B52-HAVERM!C52 -> 6651 | BG13: =$BL$6 -> 2.2155011 | BI13: 0 | BS13: =$BX$6 -> 1.9448021 | BU13: 0 | CH13: 2024 | CI13: =100*(DataA!B58/DataA!$B$53) -> 102.18522 | CJ13: =CJ12*(1+CO13/100) -> 102.93622 | CK13: 100 | CM13: =100*((CJ13/CI13)-1) -> 0.73494613 | CO13: 0.70682576
A14: 1990 | B14: =DataA!F24*DataA!G24 -> 879722.49 | C14: =DataA!H24/DataA!I24 -> 9.2673112 | D14: =DataA!E24 -> 1416727 | E14: =DataA!J24 -> -1.860825 | F14: =DataA!D24 -> 1250609 | G14: =DataA!B24 -> 1266248 | I14: =100*((F14/F13)-1) -> 2.6802927 | J14: =100*((G14/G13)-1) -> 0.5604392 | L14: 2010 | M14: =100*((DataA!B53/DataA!B43)^(1/10)-1) -> 1.970971 | O14: 2010 | P14: ='[1]2021-based'!H17 -> 255.4 | T14: =AVERAGE($P$14:$P$23) -> 240.77 | V14: 1984 | W14: =100*((DataA!M18/DataA!M17)-1) -> 0.697956 | X14: =AVERAGE(W5:W14) -> 0.49694176 | Y14: 0 | Z14: 65 | AA14: 60 | AC14: 10 | AD14: ='ONS pop proj 2021-based'!E12+'ONS pop proj 2021-based'!E119 -> 805383 | AE14: ='ONS pop proj 2021-based'!L12+'ONS pop proj 2021-based'!L119 -> 744196 | AF14: ='ONS pop proj 2021-based'!V12+'ONS pop proj 2021-based'!V119 -> 760801 | AG14: ='ONS pop proj 2021-based'!AF12+'ONS pop proj 2021-based'!AF119 -> 781989 | AI14: 2031 | AJ14: 0.1659553 | AK14: 0.62397312 | AL14: 0.21007159 | AN14: 41091 | AO14: =HAVERQ!F177-HAVERQ!F$166 -> 1 | AP14: =HAVERQ!G177-HAVERQ!G$166 -> 275 | AQ14: =HAVERQ!H177-HAVERQ!H$166 -> -124 | AR14: =HAVERQ!I177-HAVERQ!I$166 -> 346 | AS14: =HAVERQ!J177-HAVERQ!J$166 -> 177 | AT14: =SUM(AO14:AS14) -> 675 | AV14: =HAVERQ!D177-HAVERQ!D$166-'Chart Data'!AT14 -> 1 | AX14: 34274 | AY14: =100*(HAVERM!C53/HAVERM!B53) -> 22.481072 | AZ14: =AVERAGE($AY$7:$AY$374) -> 24.595806 | BB14: =HAVERM!C53 -> 1930 | BC14: =HAVERM!B53-HAVERM!C53 -> 6655 | BG14: =$BL$6 -> 2.2155011 | BI14: 0 | BS14: =$BX$6 -> 1.9448021 | BU14: 0 | CH14: 2025 | CI14: =100*(DataA!B59/DataA!$B$53) -> 104.04012 | CJ14: =CJ13*(1+CO14/100) -> 104.35675 | CK14: 100 | CM14: =100*((CJ14/CI14)-1) -> 0.30433561 | CO14: 1.3800048
A15: 1991 | B15: =DataA!F25*DataA!G25 -> 861885.45 | C15: =DataA!H25/DataA!I25 -> 9.3754123 | D15: =DataA!E25 -> 1462646 | E15: =DataA!J25 -> -1.849896 | F15: =DataA!D25 -> 1267882 | G15: =DataA!B25 -> 1248461 | I15: =100*((F15/F14)-1) -> 1.3811671 | J15: =100*((G15/G14)-1) -> -1.4047011 | O15: 2011 | P15: ='[1]2021-based'!H18 -> 270.3 | T15: =AVERAGE($P$14:$P$23) -> 240.77 | V15: 1985 | W15: =100*((DataA!M19/DataA!M18)-1) -> 0.49341661 | X15: =AVERAGE(W6:W15) -> 0.54780629 | Y15: 0 | Z15: 65 | AA15: 60 | AC15: 11 | AD15: ='ONS pop proj 2021-based'!E13+'ONS pop proj 2021-based'!E120 -> 827802 | AE15: ='ONS pop proj 2021-based'!L13+'ONS pop proj 2021-based'!L120 -> 757155 | AF15: ='ONS pop proj 2021-based'!V13+'ONS pop proj 2021-based'!V120 -> 763215 | AG15: ='ONS pop proj 2021-based'!AF13+'ONS pop proj 2021-based'!AF120 -> 780531 | AI15: 2032 | AJ15: 0.16466727 | AK15: 0.62248656 | AL15: 0.21284617 | AN15: 41183 | AO15: =HAVERQ!F178-HAVERQ!F$166 -> 13 | AP15: =HAVERQ!G178-HAVERQ!G$166 -> 321 | AQ15: =HAVERQ!H178-HAVERQ!H$166 -> -148 | AR15: =HAVERQ!I178-HAVERQ!I$166 -> 430 | AS15: =HAVERQ!J178-HAVERQ!J$166 -> 208 | AT15: =SUM(AO15:AS15) -> 824 | AV15: =HAVERQ!D178-HAVERQ!D$166-'Chart Data'!AT15 -> 6 | AX15: 34304 | AY15: =100*(HAVERM!C54/HAVERM!B54) -> 22.434479 | AZ15: =AVERAGE($AY$7:$AY$374) -> 24.595806 | BB15: =HAVERM!C54 -> 1926 | BC15: =HAVERM!B54-HAVERM!C54 -> 6659 | BG15: =$BL$6 -> 2.2155011 | BI15: 0 | BS15: =$BX$6 -> 1.9448021 | BU15: 0 | CH15: 2026 | CI15: =100*(DataA!B60/DataA!$B$53) -> 106.12784 | CJ15: =CJ14*(1+CO15/100) -> 106.41169 | CK15: 100 | CM15: =100*((CJ15/CI15)-1) -> 0.26746493 | CO15: 1.969152
A16: 1992 | B16: =DataA!F26*DataA!G26 -> 848974.43 | C16: =DataA!H26/DataA!I26 -> 9.4785328 | D16: =DataA!E26 -> 1490253 | E16: =DataA!J26 -> -1.839032 | F16: =DataA!D26 -> 1285429 | G16: =DataA!B26 -> 1251525 | I16: =100*((F16/F15)-1) -> 1.3839616 | J16: =100*((G16/G15)-1) -> 0.24542216 | O16: 2012 | P16: ='ONS migration estimates'!C96/1000 -> 162 | T16: =AVERAGE($P$14:$P$23) -> 240.77 | V16: 1986 | W16: =100*((DataA!M20/DataA!M19)-1) -> 0.41478282 | X16: =AVERAGE(W7:W16) -> 0.57901966 | Y16: 0 | Z16: 65 | AA16: 60 | AC16: 12 | AD16: ='ONS pop proj 2021-based'!E14+'ONS pop proj 2021-based'!E121 -> 831944 | AE16: ='ONS pop proj 2021-based'!L14+'ONS pop proj 2021-based'!L121 -> 768410 | AF16: ='ONS pop proj 2021-based'!V14+'ONS pop proj 2021-based'!V121 -> 765547 | AG16: ='ONS pop proj 2021-based'!AF14+'ONS pop proj 2021-based'!AF121 -> 778853 | AI16: 2033 | AJ16: 0.16369371 | AK16: 0.62091942 | AL16: 0.21538687 | AN16: 41275 | AO16: =HAVERQ!F179-HAVERQ!F$166 -> -30 | AP16: =HAVERQ!G179-HAVERQ!G$166 -> 332 | AQ16: =HAVERQ!H179-HAVERQ!H$166 -> -204 | AR16: =HAVERQ!I179-HAVERQ!I$166 -> 435 | AS16: =HAVERQ!J179-HAVERQ!J$166 -> 224 | AT16: =SUM(AO16:AS16) -> 757 | AV16: =HAVERQ!D179-HAVERQ!D$166-'Chart Data'!AT16 -> 10 | AX16: 34335 | AY16: =100*(HAVERM!C55/HAVERM!B55) -> 22.336089 | AZ16: =AVERAGE($AY$7:$AY$374) -> 24.595806 | BB16: =HAVERM!C55 -> 1918 | BC16: =HAVERM!B55-HAVERM!C55 -> 6669 | BE16: 1974 | BG16: =$BL$6 -> 2.2155011 | BI16: 0 | BQ16: 1974 | BS16: =$BX$6 -> 1.9448021 | BU16: 0 | CH16: 2027 | CI16: =100*(DataA!B61/DataA!$B$53) -> 107.96505 | CJ16: =CJ15*(1+CO16/100) -> 108.50375 | CK16: 100 | CM16: =100*((CJ16/CI16)-1) -> 0.49895658 | CO16: 1.9660077
A17: 1993 | B17: =DataA!F27*DataA!G27 -> 843846.96 | C17: =DataA!H27/DataA!I27 -> 9.5656692 | D17: =DataA!E27 -> 1518284 | E17: =DataA!J27 -> -1.828231 | F17: =DataA!D27 -> 1306377 | G17: =DataA!B27 -> 1279802 | I17: =100*((F17/F16)-1) -> 1.6296505 | J17: =100*((G17/G16)-1) -> 2.2594035 | O17: 2013 | P17: ='ONS migration estimates'!C100/1000 -> 215 | T17: =AVERAGE($P$14:$P$23) -> 240.77 | V17: 1987 | W17: =100*((DataA!M21/DataA!M20)-1) -> 0.4090401 | X17: =AVERAGE(W8:W17) -> 0.56154408 | Y17: 0 | Z17: 65 | AA17: 60 | AC17: 13 | AD17: ='ONS pop proj 2021-based'!E15+'ONS pop proj 2021-based'!E122 -> 819595 | AE17: ='ONS pop proj 2021-based'!L15+'ONS pop proj 2021-based'!L122 -> 786414 | AF17: ='ONS pop proj 2021-based'!V15+'ONS pop proj 2021-based'!V122 -> 767453 | AG17: ='ONS pop proj 2021-based'!AF15+'ONS pop proj 2021-based'!AF122 -> 777340 | AI17: 2034 | AJ17: 0.16296485 | AK17: 0.61924143 | AL17: 0.21779372 | AN17: 41365 | AO17: =HAVERQ!F180-HAVERQ!F$166 -> -95 | AP17: =HAVERQ!G180-HAVERQ!G$166 -> 398 | AQ17: =HAVERQ!H180-HAVERQ!H$166 -> -204 | AR17: =HAVERQ!I180-HAVERQ!I$166 -> 504 | AS17: =HAVERQ!J180-HAVERQ!J$166 -> 254 | AT17: =SUM(AO17:AS17) -> 857 | AV17: =HAVERQ!D180-HAVERQ!D$166-'Chart Data'!AT17 -> 15 | AX17: 34366 | AY17: =100*(HAVERM!C56/HAVERM!B56) -> 22.272727 | AZ17: =AVERAGE($AY$7:$AY$374) -> 24.595806 | BB17: =HAVERM!C56 -> 1911 | BC17: =HAVERM!B56-HAVERM!C56 -> 6669 | BG17: =$BL$6 -> 2.2155011 | BI17: 0 | BS17: =$BX$6 -> 1.9448021 | BU17: 0 | CH17: 2028 | CI17: =100*(DataA!B62/DataA!$B$53) -> 109.75191 | CJ17: =CJ16*(1+CO17/100) -> 110.39467 | CK17: 100 | CM17: =100*((CJ17/CI17)-1) -> 0.58564887 | CO17: 1.7427234
A18: 1994 | B18: =DataA!F28*DataA!G28 -> 851546.12 | C18: =DataA!H28/DataA!I28 -> 9.6325984 | D18: =DataA!E28 -> 1551666 | E18: =DataA!J28 -> -1.817494 | F18: =DataA!D28 -> 1340362 | G18: =DataA!B28 -> 1323443 | I18: =100*((F18/F17)-1) -> 2.6014696 | J18: =100*((G18/G17)-1) -> 3.4099806 | O18: 2014 | P18: ='ONS migration estimates'!C104/1000 -> 248 | T18: =AVERAGE($P$14:$P$23) -> 240.77 | V18: 1988 | W18: =100*((DataA!M22/DataA!M21)-1) -> 0.30865471 | X18: =AVERAGE(W9:W18) -> 0.53037937 | Y18: 0 | Z18: 65 | AA18: 60 | AC18: 14 | AD18: ='ONS pop proj 2021-based'!E16+'ONS pop proj 2021-based'!E123 -> 816974 | AE18: ='ONS pop proj 2021-based'!L16+'ONS pop proj 2021-based'!L123 -> 809733 | AF18: ='ONS pop proj 2021-based'!V16+'ONS pop proj 2021-based'!V123 -> 769049 | AG18: ='ONS pop proj 2021-based'!AF16+'ONS pop proj 2021-based'!AF123 -> 776764 | AI18: 2035 | AJ18: 0.16239107 | AK18: 0.6178263 | AL18: 0.21978263 | AN18: 41456 | AO18: =HAVERQ!F181-HAVERQ!F$166 -> -36 | AP18: =HAVERQ!G181-HAVERQ!G$166 -> 431 | AQ18: =HAVERQ!H181-HAVERQ!H$166 -> -223 | AR18: =HAVERQ!I181-HAVERQ!I$166 -> 579 | AS18: =HAVERQ!J181-HAVERQ!J$166 -> 275 | AT18: =SUM(AO18:AS18) -> 1026 | AV18: =HAVERQ!D181-HAVERQ!D$166-'Chart Data'!AT18 -> 16 | AX18: 34394 | AY18: =100*(HAVERM!C57/HAVERM!B57) -> 22.571628 | AZ18: =AVERAGE($AY$7:$AY$374) -> 24.595806 | BB18: =HAVERM!C57 -> 1938 | BC18: =HAVERM!B57-HAVERM!C57 -> 6648 | BG18: =$BL$6 -> 2.2155011 | BI18: 0 | BS18: =$BX$6 -> 1.9448021 | BU18: 0 | CH18: 2029 | CI18: =100*(DataA!B63/DataA!$B$53) -> 111.474 | CJ18: =CJ17*(1+CO18/100) -> 112.42767 | CK18: 100 | CM18: =100*((CJ18/CI18)-1) -> 0.85551576 | CO18: {=TRANSPOSE('OBR LT economic determinants'!J7:AE7)} -> 1.8415752
A19: 1995 | B19: =DataA!F29*DataA!G29 -> 858185.82 | C19: =DataA!H29/DataA!I29 -> 9.6889063 | D19: =DataA!E29 -> 1589698 | E19: =DataA!J29 -> -1.806819 | F19: =DataA!D29 -> 1374846 | G19: =DataA!B29 -> 1355023 | I19: =100*((F19/F18)-1) -> 2.5727378 | J19: =100*((G19/G18)-1) -> 2.3862002 | O19: 2015 | P19: ='ONS migration estimates'!C108/1000 -> 296 | T19: =AVERAGE($P$14:$P$23) -> 240.77 | V19: 1989 | W19: =100*((DataA!M23/DataA!M22)-1) -> 0.26095485 | X19: =AVERAGE(W10:W19) -> 0.4948301 | Y19: 0 | Z19: 65 | AA19: 60 | AC19: 15 | AD19: ='ONS pop proj 2021-based'!E17+'ONS pop proj 2021-based'!E124 -> 825235 | AE19: ='ONS pop proj 2021-based'!L17+'ONS pop proj 2021-based'!L124 -> 805672 | AF19: ='ONS pop proj 2021-based'!V17+'ONS pop proj 2021-based'!V124 -> 770439 | AG19: ='ONS pop proj 2021-based'!AF17+'ONS pop proj 2021-based'!AF124 -> 778431 | AI19: 2036 | AJ19: 0.16200698 | AK19: 0.61606488 | AL19: 0.22192813 | AN19: 41548 | AO19: =HAVERQ!F182-HAVERQ!F$166 -> -4 | AP19: =HAVERQ!G182-HAVERQ!G$166 -> 463 | AQ19: =HAVERQ!H182-HAVERQ!H$166 -> -220 | AR19: =HAVERQ!I182-HAVERQ!I$166 -> 674 | AS19: =HAVERQ!J182-HAVERQ!J$166 -> 298 | AT19: =SUM(AO19:AS19) -> 1211 | AV19: =HAVERQ!D182-HAVERQ!D$166-'Chart Data'!AT19 -> 17 | AX19: 34425 | AY19: =100*(HAVERM!C58/HAVERM!B58) -> 22.539793 | AZ19: =AVERAGE($AY$7:$AY$374) -> 24.595806 | BB19: =HAVERM!C58 -> 1940 | BC19: =HAVERM!B58-HAVERM!C58 -> 6667 | BG19: =$BL$6 -> 2.2155011 | BI19: 0 | BS19: =$BX$6 -> 1.9448021 | BU19: 0 | CH19: 2030 | CI19: =100*(DataA!B64/DataA!$B$53) -> 113.17808 | CJ19: =CJ18*(1+CO19/100) -> 114.55137 | CK19: 100 | CM19: =100*((CJ19/CI19)-1) -> 1.2133812 | CO19: 1.8889414
A20: 1996 | B20: =DataA!F30*DataA!G30 -> 866753.2 | C20: =DataA!H30/DataA!I30 -> 9.720396 | D20: =DataA!E30 -> 1628714 | E20: =DataA!J30 -> -1.796208 | F20: =DataA!D30 -> 1411804 | G20: =DataA!B30 -> 1390010 | I20: =100*((F20/F19)-1) -> 2.6881556 | J20: =100*((G20/G19)-1) -> 2.5820226 | O20: 2016 | P20: ='ONS migration estimates'!C112/1000 -> 321 | T20: =AVERAGE($P$14:$P$23) -> 240.77 | V20: 1990 | W20: =100*((DataA!M24/DataA!M23)-1) -> 0.1888224 | X20: =AVERAGE(W11:W20) -> 0.45244525 | Y20: 0 | Z20: 65 | AA20: 60 | AC20: 16 | AD20: ='ONS pop proj 2021-based'!E18+'ONS pop proj 2021-based'!E125 -> 794768 | AE20: ='ONS pop proj 2021-based'!L18+'ONS pop proj 2021-based'!L125 -> 812369 | AF20: ='ONS pop proj 2021-based'!V18+'ONS pop proj 2021-based'!V125 -> 768164 | AG20: ='ONS pop proj 2021-based'!AF18+'ONS pop proj 2021-based'!AF125 -> 782003 | AI20: 2037 | AJ20: 0.1620056 | AK20: 0.61447081 | AL20: 0.22352359 | AN20: 41640 | AO20: =HAVERQ!F183-HAVERQ!F$166 -> 15 | AP20: =HAVERQ!G183-HAVERQ!G$166 -> 534 | AQ20: =HAVERQ!H183-HAVERQ!H$166 -> -140 | AR20: =HAVERQ!I183-HAVERQ!I$166 -> 717 | AS20: =HAVERQ!J183-HAVERQ!J$166 -> 328 | AT20: =SUM(AO20:AS20) -> 1454 | AV20: =HAVERQ!D183-HAVERQ!D$166-'Chart Data'!AT20 -> 17 | AX20: 34455 | AY20: =100*(HAVERM!C59/HAVERM!B59) -> 22.62926 | AZ20: =AVERAGE($AY$7:$AY$374) -> 24.595806 | BB20: =HAVERM!C59 -> 1952 | BC20: =HAVERM!B59-HAVERM!C59 -> 6674 | BE20: 1975 | BG20: =$BL$6 -> 2.2155011 | BI20: 0 | BQ20: 1975 | BS20: =$BX$6 -> 1.9448021 | BU20: 0 | CH20: 2031 | CI20: =100*(DataA!B65/DataA!$B$53) -> 114.90823 | CJ20: =CJ19*(1+CO20/100) -> 116.65136 | CK20: 100 | CM20: =100*((CJ20/CI20)-1) -> 1.5169821 | CO20: 1.8332364
A21: 1997 | B21: =DataA!F31*DataA!G31 -> 877828.41 | C21: =DataA!H31/DataA!I31 -> 9.7395726 | D21: =DataA!E31 -> 1679000 | E21: =DataA!J31 -> -1.786856 | F21: =DataA!D31 -> 1451153 | G21: =DataA!B31 -> 1458467 | I21: =100*((F21/F20)-1) -> 2.7871433 | J21: =100*((G21/G20)-1) -> 4.9249286 | O21: 2017 | P21: ='ONS migration estimates'!C116/1000 -> 200 | T21: =AVERAGE($P$14:$P$23) -> 240.77 | V21: 1991 | W21: =100*((DataA!M25/DataA!M24)-1) -> 0.1228944 | X21: =AVERAGE(W12:W21) -> 0.40765903 | Y21: 0 | Z21: 65 | AA21: 60 | AC21: 17 | AD21: ='ONS pop proj 2021-based'!E19+'ONS pop proj 2021-based'!E126 -> 780765 | AE21: ='ONS pop proj 2021-based'!L19+'ONS pop proj 2021-based'!L126 -> 835043 | AF21: ='ONS pop proj 2021-based'!V19+'ONS pop proj 2021-based'!V126 -> 728702 | AG21: ='ONS pop proj 2021-based'!AF19+'ONS pop proj 2021-based'!AF126 -> 786972 | AI21: 2038 | AJ21: 0.16187525 | AK21: 0.61354371 | AL21: 0.22458104 | AN21: 41730 | AO21: =HAVERQ!F184-HAVERQ!F$166 -> 92 | AP21: =HAVERQ!G184-HAVERQ!G$166 -> 556 | AQ21: =HAVERQ!H184-HAVERQ!H$166 -> -88 | AR21: =HAVERQ!I184-HAVERQ!I$166 -> 739 | AS21: =HAVERQ!J184-HAVERQ!J$166 -> 328 | AT21: =SUM(AO21:AS21) -> 1627 | AV21: =HAVERQ!D184-HAVERQ!D$166-'Chart Data'!AT21 -> 18 | AX21: 34486 | AY21: =100*(HAVERM!C60/HAVERM!B60) -> 22.55814 | AZ21: =AVERAGE($AY$7:$AY$374) -> 24.595806 | BB21: =HAVERM!C60 -> 1940 | BC21: =HAVERM!B60-HAVERM!C60 -> 6660 | BG21: =$BL$6 -> 2.2155011 | BI21: 0 | BS21: =$BX$6 -> 1.9448021 | BU21: 0 | CH21: 2032 | CI21: =100*(DataA!B66/DataA!$B$53) -> 116.65314 | CJ21: =CJ20*(1+CO21/100) -> 118.75425 | CK21: 100 | CM21: =100*((CJ21/CI21)-1) -> 1.8011571 | CO21: 1.8027076
A22: 1998 | B22: =DataA!F32*DataA!G32 -> 884900.46 | C22: =DataA!H32/DataA!I32 -> 9.7651529 | D22: =DataA!E32 -> 1730000 | E22: =DataA!J32 -> -1.782333 | F22: =DataA!D32 -> 1482073 | G22: =DataA!B32 -> 1508263 | I22: =100*((F22/F21)-1) -> 2.1307195 | J22: =100*((G22/G21)-1) -> 3.4142699 | O22: 2018 | P22: ='ONS migration estimates'!C120/1000 -> 216 | T22: =AVERAGE($P$14:$P$23) -> 240.77 | V22: 1992 | W22: =100*((DataA!M26/DataA!M25)-1) -> 0.029350485 | X22: =AVERAGE(W13:W22) -> 0.36306619 | Y22: 0 | Z22: 65 | AA22: 60 | AC22: 18 | AD22: ='ONS pop proj 2021-based'!E20+'ONS pop proj 2021-based'!E127 -> 788007 | AE22: ='ONS pop proj 2021-based'!L20+'ONS pop proj 2021-based'!L127 -> 864795 | AF22: ='ONS pop proj 2021-based'!V20+'ONS pop proj 2021-based'!V127 -> 769670 | AG22: ='ONS pop proj 2021-based'!AF20+'ONS pop proj 2021-based'!AF127 -> 796533 | AI22: 2039 | AJ22: 0.16222178 | AK22: 0.61265417 | AL22: 0.22512405 | AN22: 41821 | AO22: =HAVERQ!F185-HAVERQ!F$166 -> 106 | AP22: =HAVERQ!G185-HAVERQ!G$166 -> 565 | AQ22: =HAVERQ!H185-HAVERQ!H$166 -> -74 | AR22: =HAVERQ!I185-HAVERQ!I$166 -> 820 | AS22: =HAVERQ!J185-HAVERQ!J$166 -> 338 | AT22: =SUM(AO22:AS22) -> 1755 | AV22: =HAVERQ!D185-HAVERQ!D$166-'Chart Data'!AT22 -> 16 | AX22: 34516 | AY22: =100*(HAVERM!C61/HAVERM!B61) -> 22.628161 | AZ22: =AVERAGE($AY$7:$AY$374) -> 24.595806 | BB22: =HAVERM!C61 -> 1951 | BC22: =HAVERM!B61-HAVERM!C61 -> 6671 | BG22: =$BL$6 -> 2.2155011 | BI22: 0 | BS22: =$BX$6 -> 1.9448021 | BU22: 0 | CH22: 2033 | CI22: =100*(DataA!B67/DataA!$B$53) -> 118.35248 | CJ22: =CJ21*(1+CO22/100) -> 120.86934 | CK22: 100 | CM22: =100*((CJ22/CI22)-1) -> 2.1265778 | CO22: 1.7810692
A23: 1999 | B23: =DataA!F33*DataA!G33 -> 895986.1 | C23: =DataA!H33/DataA!I33 -> 9.832806 | D23: =DataA!E33 -> 1817000 | E23: =DataA!J33 -> -1.778219 | F23: =DataA!D33 -> 1523159 | G23: =DataA!B33 -> 1554509 | I23: =100*((F23/F22)-1) -> 2.7721981 | J23: =100*((G23/G22)-1) -> 3.0661761 | O23: 2019 | P23: ='ONS migration estimates'!C124/1000 -> 224 | T23: =AVERAGE($P$14:$P$23) -> 240.77 | V23: 1993 | W23: =100*((DataA!M27/DataA!M26)-1) -> 0.031557426 | X23: =AVERAGE(W14:W23) -> 0.29574298 | Y23: 0 | Z23: 65 | AA23: 60 | AC23: 19 | AD23: ='ONS pop proj 2021-based'!E21+'ONS pop proj 2021-based'!E128 -> 804525 | AE23: ='ONS pop proj 2021-based'!L21+'ONS pop proj 2021-based'!L128 -> 886517 | AF23: ='ONS pop proj 2021-based'!V21+'ONS pop proj 2021-based'!V128 -> 775509 | AG23: ='ONS pop proj 2021-based'!AF21+'ONS pop proj 2021-based'!AF128 -> 816057 | AI23: 2040 | AJ23: 0.16202365 | AK23: 0.61252084 | AL23: 0.22545551 | AN23: 41913 | AO23: =HAVERQ!F186-HAVERQ!F$166 -> 114 | AP23: =HAVERQ!G186-HAVERQ!G$166 -> 575 | AQ23: =HAVERQ!H186-HAVERQ!H$166 -> -47 | AR23: =HAVERQ!I186-HAVERQ!I$166 -> 876 | AS23: =HAVERQ!J186-HAVERQ!J$166 -> 345 | AT23: =SUM(AO23:AS23) -> 1863 | AV23: =HAVERQ!D186-HAVERQ!D$166-'Chart Data'!AT23 -> 16 | AX23: 34547 | AY23: =100*(HAVERM!C62/HAVERM!B62) -> 22.804582 | AZ23: =AVERAGE($AY$7:$AY$374) -> 24.595806 | BB23: =HAVERM!C62 -> 1971 | BC23: =HAVERM!B62-HAVERM!C62 -> 6672 | BG23: =$BL$6 -> 2.2155011 | BI23: 0 | BS23: =$BX$6 -> 1.9448021 | BU23: 0 | CH23: 2034 | CI23: =100*(DataA!B68/DataA!$B$53) -> 120.0482 | CJ23: =CJ22*(1+CO23/100) -> 122.98949 | CK23: 100 | CM23: =100*((CJ23/CI23)-1) -> 2.4500857 | CO23: 1.7540793
A24: 2000 | B24: =DataA!F34*DataA!G34 -> 897004.65 | C24: =DataA!H34/DataA!I34 -> 9.9743903 | D24: =DataA!E34 -> 1891000 | E24: =DataA!J34 -> -1.774115 | F24: =DataA!D34 -> 1561852 | G24: =DataA!B34 -> 1621644 | I24: =100*((F24/F23)-1) -> 2.5403126 | J24: =100*((G24/G23)-1) -> 4.318727 | O24: 2020 | P24: ='ONS migration estimates'!C128/1000 -> 111 | V24: 1994 | W24: =100*((DataA!M28/DataA!M27)-1) -> 0.16043493 | X24: =AVERAGE(W15:W24) -> 0.24199087 | Y24: 0 | Z24: 65 | AA24: 60 | AC24: 20 | AD24: ='ONS pop proj 2021-based'!E22+'ONS pop proj 2021-based'!E129 -> 814061 | AE24: ='ONS pop proj 2021-based'!L22+'ONS pop proj 2021-based'!L129 -> 894682 | AF24: ='ONS pop proj 2021-based'!V22+'ONS pop proj 2021-based'!V129 -> 822003 | AG24: ='ONS pop proj 2021-based'!AF22+'ONS pop proj 2021-based'!AF129 -> 838704 | AI24: 2041 | AJ24: 0.16178482 | AK24: 0.61268007 | AL24: 0.22553511 | AN24: 42005 | AO24: =HAVERQ!F187-HAVERQ!F$166 -> 157 | AP24: =HAVERQ!G187-HAVERQ!G$166 -> 611 | AQ24: =HAVERQ!H187-HAVERQ!H$166 -> -55 | AR24: =HAVERQ!I187-HAVERQ!I$166 -> 934 | AS24: =HAVERQ!J187-HAVERQ!J$166 -> 424 | AT24: =SUM(AO24:AS24) -> 2071 | AV24: =HAVERQ!D187-HAVERQ!D$166-'Chart Data'!AT24 -> 15 | AX24: 34578 | AY24: =100*(HAVERM!C63/HAVERM!B63) -> 22.978576 | AZ24: =AVERAGE($AY$7:$AY$374) -> 24.595806 | BB24: =HAVERM!C63 -> 1995 | BC24: =HAVERM!B63-HAVERM!C63 -> 6687 | BE24: 1976 | BG24: =$BL$6 -> 2.2155011 | BI24: 0 | BQ24: 1976 | BS24: =$BX$6 -> 1.9448021 | BU24: 0 | CH24: 2035 | CI24: =100*(DataA!B69/DataA!$B$53) -> 121.76827 | CJ24: =CJ23*(1+CO24/100) -> 125.12677 | CK24: 100 | CM24: =100*((CJ24/CI24)-1) -> 2.7581029 | CO24: 1.7377747
A25: 2001 | B25: =DataA!F35*DataA!G35 -> 906197.99 | C25: =DataA!H35/DataA!I35 -> 10.222141 | D25: =DataA!E35 -> 1959000 | E25: =DataA!J35 -> -1.77002 | F25: =DataA!D35 -> 1611689 | G25: =DataA!B35 -> 1663462 | I25: =100*((F25/F24)-1) -> 3.1908913 | J25: =100*((G25/G24)-1) -> 2.5787411 | O25: 2021 | P25: ='ONS migration estimates'!C132/1000 -> 221 | V25: 1995 | W25: =100*((DataA!M29/DataA!M28)-1) -> 0.31204932 | X25: =AVERAGE(W16:W25) -> 0.22385414 | Y25: 0 | Z25: 65 | AA25: 60 | AC25: 21 | AD25: ='ONS pop proj 2021-based'!E23+'ONS pop proj 2021-based'!E130 -> 819436 | AE25: ='ONS pop proj 2021-based'!L23+'ONS pop proj 2021-based'!L130 -> 905811 | AF25: ='ONS pop proj 2021-based'!V23+'ONS pop proj 2021-based'!V130 -> 848567 | AG25: ='ONS pop proj 2021-based'!AF23+'ONS pop proj 2021-based'!AF130 -> 854757 | AI25: 2042 | AJ25: 0.16154952 | AK25: 0.61310503 | AL25: 0.22534545 | AN25: 42095 | AO25: =HAVERQ!F188-HAVERQ!F$166 -> 172 | AP25: =HAVERQ!G188-HAVERQ!G$166 -> 607 | AQ25: =HAVERQ!H188-HAVERQ!H$166 -> -99 | AR25: =HAVERQ!I188-HAVERQ!I$166 -> 980 | AS25: =HAVERQ!J188-HAVERQ!J$166 -> 363 | AT25: =SUM(AO25:AS25) -> 2023 | AV25: =HAVERQ!D188-HAVERQ!D$166-'Chart Data'!AT25 -> 15 | AX25: 34608 | AY25: =100*(HAVERM!C64/HAVERM!B64) -> 23.105148 | AZ25: =AVERAGE($AY$7:$AY$374) -> 24.595806 | BB25: =HAVERM!C64 -> 2015 | BC25: =HAVERM!B64-HAVERM!C64 -> 6706 | BG25: =$BL$6 -> 2.2155011 | BI25: 0 | BS25: =$BX$6 -> 1.9448021 | BU25: 0 | CH25: 2036 | CI25: =100*(DataA!B70/DataA!$B$53) -> 123.56265 | CJ25: =CJ24*(1+CO25/100) -> 127.46356 | CK25: 100 | CM25: =100*((CJ25/CI25)-1) -> 3.1570302 | CO25: 1.8675416
A26: 2002 | B26: =DataA!F36*DataA!G36 -> 905078.99 | C26: =DataA!H36/DataA!I36 -> 10.553831 | D26: =DataA!E36 -> 2015000 | E26: =DataA!J36 -> -1.765935 | F26: =DataA!D36 -> 1651285 | G26: =DataA!B36 -> 1693271 | I26: =100*((F26/F25)-1) -> 2.4568015 | J26: =100*((G26/G25)-1) -> 1.7919856 | O26: 2022 | P26: ='ONS migration estimates'!C136/1000 -> 607 | V26: 1996 | W26: =100*((DataA!M30/DataA!M29)-1) -> 0.36678279 | X26: =AVERAGE(W17:W26) -> 0.21905414 | Y26: 0 | Z26: 65 | AA26: 60 | AC26: 22 | AD26: ='ONS pop proj 2021-based'!E24+'ONS pop proj 2021-based'!E131 -> 823721 | AE26: ='ONS pop proj 2021-based'!L24+'ONS pop proj 2021-based'!L131 -> 925826 | AF26: ='ONS pop proj 2021-based'!V24+'ONS pop proj 2021-based'!V131 -> 870793 | AG26: ='ONS pop proj 2021-based'!AF24+'ONS pop proj 2021-based'!AF131 -> 868097 | AI26: 2043 | AJ26: 0.16132481 | AK26: 0.61336626 | AL26: 0.22530894 | AN26: 42186 | AO26: =HAVERQ!F189-HAVERQ!F$166 -> 259 | AP26: =HAVERQ!G189-HAVERQ!G$166 -> 681 | AQ26: =HAVERQ!H189-HAVERQ!H$166 -> -140 | AR26: =HAVERQ!I189-HAVERQ!I$166 -> 1056 | AS26: =HAVERQ!J189-HAVERQ!J$166 -> 387 | AT26: =SUM(AO26:AS26) -> 2243 | AV26: =HAVERQ!D189-HAVERQ!D$166-'Chart Data'!AT26 -> 16 | AX26: 34639 | AY26: =100*(HAVERM!C65/HAVERM!B65) -> 23.182285 | AZ26: =AVERAGE($AY$7:$AY$374) -> 24.595806 | BB26: =HAVERM!C65 -> 2031 | BC26: =HAVERM!B65-HAVERM!C65 -> 6730 | BG26: =$BL$6 -> 2.2155011 | BI26: 0 | BS26: =$BX$6 -> 1.9448021 | BU26: 0 | CH26: 2037 | CI26: =100*(DataA!B71/DataA!$B$53) -> 125.41061 | CJ26: =CJ25*(1+CO26/100) -> 129.80908 | CK26: 100 | CM26: =100*((CJ26/CI26)-1) -> 3.5072509 | CO26: 1.8401465
A27: 2003 | B27: =DataA!F37*DataA!G37 -> 907433.11 | C27: =DataA!H37/DataA!I37 -> 10.921335 | D27: =DataA!E37 -> 2062000 | E27: =DataA!J37 -> -1.761859 | F27: =DataA!D37 -> 1693448 | G27: =DataA!B37 -> 1746551 | I27: =100*((F27/F26)-1) -> 2.5533448 | J27: =100*((G27/G26)-1) -> 3.1465725 | O27: 2023 | P27: ='ONS migration estimates'!C140/1000 -> 672 | Q27: ='ONS pop proj migration'!B8/1000 -> 670 | R27: ='ONS pop proj migration'!C8/1000 -> 670 | S27: ='ONS pop proj migration'!D8/1000 -> 670 | V27: 1997 | W27: =100*((DataA!M31/DataA!M30)-1) -> 0.35389738 | X27: =AVERAGE(W18:W27) -> 0.21353987 | Y27: 0 | Z27: 65 | AA27: 60 | AC27: 23 | AD27: ='ONS pop proj 2021-based'!E25+'ONS pop proj 2021-based'!E132 -> 841152 | AE27: ='ONS pop proj 2021-based'!L25+'ONS pop proj 2021-based'!L132 -> 910149 | AF27: ='ONS pop proj 2021-based'!V25+'ONS pop proj 2021-based'!V132 -> 901140 | AG27: ='ONS pop proj 2021-based'!AF25+'ONS pop proj 2021-based'!AF132 -> 882396 | AI27: 2044 | AJ27: 0.16111701 | AK27: 0.6129077 | AL27: 0.22597529 | AN27: 42278 | AO27: =HAVERQ!F190-HAVERQ!F$166 -> 251 | AP27: =HAVERQ!G190-HAVERQ!G$166 -> 735 | AQ27: =HAVERQ!H190-HAVERQ!H$166 -> -100 | AR27: =HAVERQ!I190-HAVERQ!I$166 -> 1144 | AS27: =HAVERQ!J190-HAVERQ!J$166 -> 418 | AT27: =SUM(AO27:AS27) -> 2448 | AV27: =HAVERQ!D190-HAVERQ!D$166-'Chart Data'!AT27 -> 19 | AX27: 34669 | AY27: =100*(HAVERM!C66/HAVERM!B66) -> 23.554798 | AZ27: =AVERAGE($AY$7:$AY$374) -> 24.595806 | BB27: =HAVERM!C66 -> 2074 | BC27: =HAVERM!B66-HAVERM!C66 -> 6731 | BF27: =100*((AVERAGE(HAVERQ!B15:B34)/AVERAGE(HAVERQ!B11:B30))-1) -> 2.0347883 | BG27: =$BL$6 -> 2.2155011 | BI27: 0 | BR27: =100*((AVERAGE(HAVERQ!C15:C34)/AVERAGE(HAVERQ!C11:C30))-1) -> 1.7352504 | BS27: =$BX$6 -> 1.9448021 | BU27: 0 | CH27: 2038 | CI27: =100*(DataA!B72/DataA!$B$53) -> 127.32474 | CJ27: =CJ26*(1+CO27/100) -> 132.14613 | CK27: 100 | CM27: =100*((CJ27/CI27)-1) -> 3.7866942 | CO27: 1.8003801
A28: 2004 | B28: =DataA!F38*DataA!G38 -> 912728.12 | C28: =DataA!H38/DataA!I38 -> 11.276552 | D28: =DataA!E38 -> 2113000 | E28: =DataA!J38 -> -1.757793 | F28: =DataA!D38 -> 1737570 | G28: =DataA!B38 -> 1788931 | I28: =100*((F28/F27)-1) -> 2.6054535 | J28: =100*((G28/G27)-1) -> 2.4264966 | O28: 2024 | Q28: ='ONS pop proj migration'!B9/1000 -> 586.6 | R28: ='ONS pop proj migration'!C9/1000 -> 599 | S28: ='ONS pop proj migration'!D9/1000 -> 611.8 | V28: 1998 | W28: =100*((DataA!M32/DataA!M31)-1) -> 0.37481621 | X28: =AVERAGE(W19:W28) -> 0.22015602 | Y28: 0 | Z28: 65 | AA28: 60 | AC28: 24 | AD28: ='ONS pop proj 2021-based'!E26+'ONS pop proj 2021-based'!E133 -> 867946 | AE28: ='ONS pop proj 2021-based'!L26+'ONS pop proj 2021-based'!L133 -> 903921 | AF28: ='ONS pop proj 2021-based'!V26+'ONS pop proj 2021-based'!V133 -> 928929 | AG28: ='ONS pop proj 2021-based'!AF26+'ONS pop proj 2021-based'!AF133 -> 888523 | AI28: 2045 | AJ28: 0.16091588 | AK28: 0.61201421 | AL28: 0.22706991 | AN28: 42370 | AO28: =HAVERQ!F191-HAVERQ!F$166 -> 241 | AP28: =HAVERQ!G191-HAVERQ!G$166 -> 752 | AQ28: =HAVERQ!H191-HAVERQ!H$166 -> -78 | AR28: =HAVERQ!I191-HAVERQ!I$166 -> 1162 | AS28: =HAVERQ!J191-HAVERQ!J$166 -> 403 | AT28: =SUM(AO28:AS28) -> 2480 | AV28: =HAVERQ!D191-HAVERQ!D$166-'Chart Data'!AT28 -> 21 | AX28: 34700 | AY28: =100*(HAVERM!C67/HAVERM!B67) -> 23.656895 | AZ28: =AVERAGE($AY$7:$AY$374) -> 24.595806 | BB28: =HAVERM!C67 -> 2074 | BC28: =HAVERM!B67-HAVERM!C67 -> 6693 | BE28: 1977 | BF28: =100*((AVERAGE(HAVERQ!B16:B35)/AVERAGE(HAVERQ!B12:B31))-1) -> 2.0013052 | BG28: =$BL$6 -> 2.2155011 | BI28: 0 | BQ28: 1977 | BR28: =100*((AVERAGE(HAVERQ!C16:C35)/AVERAGE(HAVERQ!C12:C31))-1) -> 1.7067877 | BS28: =$BX$6 -> 1.9448021 | BU28: 0 | CH28: 2039 | CI28: =100*(DataA!B73/DataA!$B$53) -> 129.29701 | CJ28: =CJ27*(1+CO28/100) -> 134.48301 | CK28: 100 | CM28: =100*((CJ28/CI28)-1) -> 4.010921 | CO28: 1.7684017
A29: 2005 | B29: =DataA!F39*DataA!G39 -> 926585.3 | C29: =DataA!H39/DataA!I39 -> 11.571259 | D29: =DataA!E39 -> 2168000 | E29: =DataA!J39 -> -1.753736 | F29: =DataA!D39 -> 1791043 | G29: =DataA!B39 -> 1837927 | I29: =100*((F29/F28)-1) -> 3.0774587 | J29: =100*((G29/G28)-1) -> 2.7388424 | O29: 2025 | Q29: ='ONS pop proj migration'!B10/1000 -> 503.2 | R29: ='ONS pop proj migration'!C10/1000 -> 528 | S29: ='ONS pop proj migration'!D10/1000 -> 553.6 | V29: 1999 | W29: =100*((DataA!M33/DataA!M32)-1) -> 0.51355263 | X29: =AVERAGE(W20:W29) -> 0.2454158 | Y29: 0 | Z29: 65 | AA29: 60 | AC29: 25 | AD29: ='ONS pop proj 2021-based'!E27+'ONS pop proj 2021-based'!E134 -> 867168 | AE29: ='ONS pop proj 2021-based'!L27+'ONS pop proj 2021-based'!L134 -> 908515 | AF29: ='ONS pop proj 2021-based'!V27+'ONS pop proj 2021-based'!V134 -> 923106 | AG29: ='ONS pop proj 2021-based'!AF27+'ONS pop proj 2021-based'!AF134 -> 888175 | AI29: 2046 | AJ29: 0.16070322 | AK29: 0.61117682 | AL29: 0.22811996 | AN29: 42461 | AO29: =HAVERQ!F192-HAVERQ!F$166 -> 223 | AP29: =HAVERQ!G192-HAVERQ!G$166 -> 814 | AQ29: =HAVERQ!H192-HAVERQ!H$166 -> -83 | AR29: =HAVERQ!I192-HAVERQ!I$166 -> 1277 | AS29: =HAVERQ!J192-HAVERQ!J$166 -> 424 | AT29: =SUM(AO29:AS29) -> 2655 | AV29: =HAVERQ!D192-HAVERQ!D$166-'Chart Data'!AT29 -> 21 | AX29: 34731 | AY29: =100*(HAVERM!C68/HAVERM!B68) -> 23.809524 | AZ29: =AVERAGE($AY$7:$AY$374) -> 24.595806 | BB29: =HAVERM!C68 -> 2080 | BC29: =HAVERM!B68-HAVERM!C68 -> 6656 | BF29: =100*((AVERAGE(HAVERQ!B17:B36)/AVERAGE(HAVERQ!B13:B32))-1) -> 1.9159991 | BG29: =$BL$6 -> 2.2155011 | BI29: 0 | BR29: =100*((AVERAGE(HAVERQ!C17:C36)/AVERAGE(HAVERQ!C13:C32))-1) -> 1.5916683 | BS29: =$BX$6 -> 1.9448021 | BU29: 0 | CH29: 2040 | CI29: =100*(DataA!B74/DataA!$B$53) -> 131.30961 | CJ29: =CJ28*(1+CO29/100) -> 136.80817 | CK29: 100 | CM29: =100*((CJ29/CI29)-1) -> 4.1874784 | CO29: 1.7289661
A30: 2006 | B30: =DataA!F40*DataA!G40 -> 938041.64 | C30: =DataA!H40/DataA!I40 -> 11.80839 | D30: =DataA!E40 -> 2230000 | E30: =DataA!J40 -> -1.749689 | F30: =DataA!D40 -> 1840881 | G30: =DataA!B40 -> 1881785 | I30: =100*((F30/F29)-1) -> 2.7826244 | J30: =100*((G30/G29)-1) -> 2.3862754 | O30: 2026 | Q30: ='ONS pop proj migration'!B11/1000 -> 419.8 | R30: ='ONS pop proj migration'!C11/1000 -> 457 | S30: ='ONS pop proj migration'!D11/1000 -> 495.4 | V30: 2000 | W30: =100*((DataA!M34/DataA!M33)-1) -> 0.6089928 | X30: =AVERAGE(W21:W30) -> 0.28743284 | Y30: 0 | Z30: 65 | AA30: 60 | AC30: 26 | AD30: ='ONS pop proj 2021-based'!E28+'ONS pop proj 2021-based'!E135 -> 884339 | AE30: ='ONS pop proj 2021-based'!L28+'ONS pop proj 2021-based'!L135 -> 915404 | AF30: ='ONS pop proj 2021-based'!V28+'ONS pop proj 2021-based'!V135 -> 932764 | AG30: ='ONS pop proj 2021-based'!AF28+'ONS pop proj 2021-based'!AF135 -> 888908 | AI30: 2047 | AJ30: 0.16047403 | AK30: 0.61045971 | AL30: 0.22906626 | AN30: 42552 | AO30: =HAVERQ!F193-HAVERQ!F$166 -> 196 | AP30: =HAVERQ!G193-HAVERQ!G$166 -> 811 | AQ30: =HAVERQ!H193-HAVERQ!H$166 -> -77 | AR30: =HAVERQ!I193-HAVERQ!I$166 -> 1338 | AS30: =HAVERQ!J193-HAVERQ!J$166 -> 450 | AT30: =SUM(AO30:AS30) -> 2718 | AV30: =HAVERQ!D193-HAVERQ!D$166-'Chart Data'!AT30 -> 23 | AX30: 34759 | AY30: =100*(HAVERM!C69/HAVERM!B69) -> 23.821539 | AZ30: =AVERAGE($AY$7:$AY$374) -> 24.595806 | BB30: =HAVERM!C69 -> 2077 | BC30: =HAVERM!B69-HAVERM!C69 -> 6642 | BF30: =100*((AVERAGE(HAVERQ!B18:B37)/AVERAGE(HAVERQ!B14:B33))-1) -> 1.8642241 | BG30: =$BL$6 -> 2.2155011 | BI30: 0 | BR30: =100*((AVERAGE(HAVERQ!C18:C37)/AVERAGE(HAVERQ!C14:C33))-1) -> 1.5172279 | BS30: =$BX$6 -> 1.9448021 | BU30: 0 | CH30: 2041 | CI30: =100*(DataA!B75/DataA!$B$53) -> 133.32826 | CJ30: =CJ29*(1+CO30/100) -> 139.13269 | CK30: 100 | CM30: =100*((CJ30/CI30)-1) -> 4.3534917 | CO30: 1.6991097
A31: 2007 | B31: =DataA!F41*DataA!G41 -> 945614.3 | C31: =DataA!H41/DataA!I41 -> 12.020055 | D31: =DataA!E41 -> 2305000 | E31: =DataA!J41 -> -1.747736 | F31: =DataA!D41 -> 1883737 | G31: =DataA!B41 -> 1931094 | I31: =100*((F31/F30)-1) -> 2.3280158 | J31: =100*((G31/G30)-1) -> 2.6203312 | O31: 2027 | Q31: ='ONS pop proj migration'!B12/1000 -> 336.4 | R31: ='ONS pop proj migration'!C12/1000 -> 386 | S31: ='ONS pop proj migration'!D12/1000 -> 437.2 | V31: 2001 | W31: =100*((DataA!M35/DataA!M34)-1) -> 0.72055167 | X31: =AVERAGE(W22:W31) -> 0.34719856 | Y31: 0 | Z31: 65 | AA31: 60 | AC31: 27 | AD31: ='ONS pop proj 2021-based'!E29+'ONS pop proj 2021-based'!E136 -> 879278 | AE31: ='ONS pop proj 2021-based'!L29+'ONS pop proj 2021-based'!L136 -> 915443 | AF31: ='ONS pop proj 2021-based'!V29+'ONS pop proj 2021-based'!V136 -> 960740 | AG31: ='ONS pop proj 2021-based'!AF29+'ONS pop proj 2021-based'!AF136 -> 854905 | AI31: 2048 | AJ31: 0.16022167 | AK31: 0.60972283 | AL31: 0.2300555 | AN31: 42644 | AO31: =HAVERQ!F194-HAVERQ!F$166 -> 217 | AP31: =HAVERQ!G194-HAVERQ!G$166 -> 829 | AQ31: =HAVERQ!H194-HAVERQ!H$166 -> -86 | AR31: =HAVERQ!I194-HAVERQ!I$166 -> 1377 | AS31: =HAVERQ!J194-HAVERQ!J$166 -> 416 | AT31: =SUM(AO31:AS31) -> 2753 | AV31: =HAVERQ!D194-HAVERQ!D$166-'Chart Data'!AT31 -> 22 | AX31: 34790 | AY31: =100*(HAVERM!C70/HAVERM!B70) -> 24.216328 | AZ31: =AVERAGE($AY$7:$AY$374) -> 24.595806 | BB31: =HAVERM!C70 -> 2109 | BC31: =HAVERM!B70-HAVERM!C70 -> 6600 | BF31: =100*((AVERAGE(HAVERQ!B19:B38)/AVERAGE(HAVERQ!B15:B34))-1) -> 1.7797791 | BG31: =$BL$6 -> 2.2155011 | BI31: 0 | BR31: =100*((AVERAGE(HAVERQ!C19:C38)/AVERAGE(HAVERQ!C15:C34))-1) -> 1.4035088 | BS31: =$BX$6 -> 1.9448021 | BU31: 0 | CH31: 2042 | CI31: =100*(DataA!B76/DataA!$B$53) -> 135.35788 | CJ31: =CJ30*(1+CO31/100) -> 141.44641 | CK31: 100 | CM31: =100*((CJ31/CI31)-1) -> 4.4981049 | CO31: 1.662959
A32: 2008 | B32: =DataA!F42*DataA!G42 -> 954262.22 | C32: =DataA!H42/DataA!I42 -> 12.201911 | D32: =DataA!E42 -> 2365000 | E32: =DataA!J42 -> -1.747867 | F32: =DataA!D42 -> 1923485 | G32: =DataA!B42 -> 1926735 | I32: =100*((F32/F31)-1) -> 2.110061 | J32: =100*((G32/G31)-1) -> -0.22572697 | O32: 2028 | Q32: ='ONS pop proj migration'!B13/1000 -> 253 | R32: ='ONS pop proj migration'!C13/1000 -> 315 | S32: ='ONS pop proj migration'!D13/1000 -> 379 | V32: 2002 | W32: =100*((DataA!M36/DataA!M35)-1) -> 0.68498715 | X32: =AVERAGE(W23:W32) -> 0.41276223 | Y32: 0 | Z32: 65 | AA32: 60 | AC32: 28 | AD32: ='ONS pop proj 2021-based'!E30+'ONS pop proj 2021-based'!E137 -> 897977 | AE32: ='ONS pop proj 2021-based'!L30+'ONS pop proj 2021-based'!L137 -> 920518 | AF32: ='ONS pop proj 2021-based'!V30+'ONS pop proj 2021-based'!V137 -> 992214 | AG32: ='ONS pop proj 2021-based'!AF30+'ONS pop proj 2021-based'!AF137 -> 897638 | AI32: 2049 | AJ32: 0.15994334 | AK32: 0.60901183 | AL32: 0.23104483 | AN32: 42736 | AO32: =HAVERQ!F195-HAVERQ!F$166 -> 209 | AP32: =HAVERQ!G195-HAVERQ!G$166 -> 873 | AQ32: =HAVERQ!H195-HAVERQ!H$166 -> -87 | AR32: =HAVERQ!I195-HAVERQ!I$166 -> 1445 | AS32: =HAVERQ!J195-HAVERQ!J$166 -> 414 | AT32: =SUM(AO32:AS32) -> 2854 | AV32: =HAVERQ!D195-HAVERQ!D$166-'Chart Data'!AT32 -> 22 | AX32: 34820 | AY32: =100*(HAVERM!C71/HAVERM!B71) -> 24.320294 | AZ32: =AVERAGE($AY$7:$AY$374) -> 24.595806 | BB32: =HAVERM!C71 -> 2120 | BC32: =HAVERM!B71-HAVERM!C71 -> 6597 | BE32: 1978 | BF32: =100*((AVERAGE(HAVERQ!B20:B39)/AVERAGE(HAVERQ!B16:B35))-1) -> 1.5035189 | BG32: =$BL$6 -> 2.2155011 | BI32: 0 | BQ32: 1978 | BR32: =100*((AVERAGE(HAVERQ!C20:C39)/AVERAGE(HAVERQ!C16:C35))-1) -> 1.0864293 | BS32: =$BX$6 -> 1.9448021 | BU32: 0 | CH32: 2043 | CI32: =100*(DataA!B77/DataA!$B$53) -> 137.41148 | CJ32: =CJ31*(1+CO32/100) -> 143.74677 | CK32: 100 | CM32: =100*((CJ32/CI32)-1) -> 4.6104502 | CO32: 1.6263103
A33: 2009 | B33: =DataA!F43*DataA!G43 -> 945894.56 | C33: =DataA!H43/DataA!I43 -> 12.349724 | D33: =DataA!E43 -> 2387000 | E33: =DataA!J43 -> -1.74876 | F33: =DataA!D43 -> 1930839 | G33: =DataA!B43 -> 1837817 | I33: =100*((F33/F32)-1) -> 0.38232687 | J33: =100*((G33/G32)-1) -> -4.6149574 | O33: 2029 | Q33: ='ONS pop proj migration'!B14/1000 -> 253 | R33: ='ONS pop proj migration'!C14/1000 -> 315 | S33: ='ONS pop proj migration'!D14/1000 -> 379 | V33: 2003 | W33: =100*((DataA!M37/DataA!M36)-1) -> 0.63017067 | X33: =AVERAGE(W24:W33) -> 0.47262356 | Y33: 0 | Z33: 65 | AA33: 60 | AC33: 29 | AD33: ='ONS pop proj 2021-based'!E31+'ONS pop proj 2021-based'!E138 -> 925149 | AE33: ='ONS pop proj 2021-based'!L31+'ONS pop proj 2021-based'!L138 -> 926072 | AF33: ='ONS pop proj 2021-based'!V31+'ONS pop proj 2021-based'!V138 -> 1005597 | AG33: ='ONS pop proj 2021-based'!AF31+'ONS pop proj 2021-based'!AF138 -> 895214 | AI33: 2050 | AJ33: 0.15963834 | AK33: 0.60796284 | AL33: 0.23239882 | AN33: 42826 | AO33: =HAVERQ!F196-HAVERQ!F$166 -> 181 | AP33: =HAVERQ!G196-HAVERQ!G$166 -> 958 | AQ33: =HAVERQ!H196-HAVERQ!H$166 -> -33 | AR33: =HAVERQ!I196-HAVERQ!I$166 -> 1493 | AS33: =HAVERQ!J196-HAVERQ!J$166 -> 376 | AT33: =SUM(AO33:AS33) -> 2975 | AV33: =HAVERQ!D196-HAVERQ!D$166-'Chart Data'!AT33 -> 21 | AX33: 34851 | AY33: =100*(HAVERM!C72/HAVERM!B72) -> 24.358532 | AZ33: =AVERAGE($AY$7:$AY$374) -> 24.595806 | BB33: =HAVERM!C72 -> 2117 | BC33: =HAVERM!B72-HAVERM!C72 -> 6574 | BF33: =100*((AVERAGE(HAVERQ!B21:B40)/AVERAGE(HAVERQ!B17:B36))-1) -> 1.4232608 | BG33: =$BL$6 -> 2.2155011 | BI33: 0 | BR33: =100*((AVERAGE(HAVERQ!C21:C40)/AVERAGE(HAVERQ!C17:C36))-1) -> 0.98646035 | BS33: =$BX$6 -> 1.9448021 | BU33: 0 | CH33: 2044 | CI33: =100*(DataA!B78/DataA!$B$53) -> 139.48765 | CJ33: =CJ32*(1+CO33/100) -> 146.03948 | CK33: 100 | CM33: =100*((CJ33/CI33)-1) -> 4.6970682 | CO33: 1.5949661
A34: 2010 | B34: =DataA!F44*DataA!G44 -> 952641.9 | C34: =DataA!H44/DataA!I44 -> 12.459158 | D34: =DataA!E44 -> 2416000 | E34: =DataA!J44 -> -1.748997 | F34: =DataA!D44 -> 1951515 | G34: =DataA!B44 -> 1878960 | I34: =100*((F34/F33)-1) -> 1.0708298 | J34: =100*((G34/G33)-1) -> 2.2386886 | O34: 2030 | Q34: ='ONS pop proj migration'!B15/1000 -> 253 | R34: ='ONS pop proj migration'!C15/1000 -> 315 | S34: ='ONS pop proj migration'!D15/1000 -> 379 | V34: 2004 | W34: =100*((DataA!M38/DataA!M37)-1) -> 0.75987743 | X34: =AVERAGE(W25:W34) -> 0.53256781 | Y34: 0 | Z34: 65 | AA34: 60 | AC34: 30 | AD34: ='ONS pop proj 2021-based'!E32+'ONS pop proj 2021-based'!E139 -> 930732 | AE34: ='ONS pop proj 2021-based'!L32+'ONS pop proj 2021-based'!L139 -> 938301 | AF34: ='ONS pop proj 2021-based'!V32+'ONS pop proj 2021-based'!V139 -> 1002002 | AG34: ='ONS pop proj 2021-based'!AF32+'ONS pop proj 2021-based'!AF139 -> 929885 | AN34: 42917 | AO34: =HAVERQ!F197-HAVERQ!F$166 -> 103 | AP34: =HAVERQ!G197-HAVERQ!G$166 -> 987 | AQ34: =HAVERQ!H197-HAVERQ!H$166 -> -49 | AR34: =HAVERQ!I197-HAVERQ!I$166 -> 1534 | AS34: =HAVERQ!J197-HAVERQ!J$166 -> 394 | AT34: =SUM(AO34:AS34) -> 2969 | AV34: =HAVERQ!D197-HAVERQ!D$166-'Chart Data'!AT34 -> 22 | AX34: 34881 | AY34: =100*(HAVERM!C73/HAVERM!B73) -> 24.500404 | AZ34: =AVERAGE($AY$7:$AY$374) -> 24.595806 | BB34: =HAVERM!C73 -> 2121 | BC34: =HAVERM!B73-HAVERM!C73 -> 6536 | BF34: =100*((AVERAGE(HAVERQ!B22:B41)/AVERAGE(HAVERQ!B18:B37))-1) -> 1.4492754 | BG34: =$BL$6 -> 2.2155011 | BI34: 0 | BR34: =100*((AVERAGE(HAVERQ!C22:C41)/AVERAGE(HAVERQ!C18:C37))-1) -> 1.0027963 | BS34: =$BX$6 -> 1.9448021 | BU34: 0 | CH34: 2045 | CI34: =100*(DataA!B79/DataA!$B$53) -> 141.58598 | CJ34: =CJ33*(1+CO34/100) -> 148.33897 | CK34: 100 | CM34: =100*((CJ34/CI34)-1) -> 4.7695292 | CO34: 1.5745626
A35: 2011 | B35: =DataA!F45*DataA!G45 -> 956189.83 | C35: =DataA!H45/DataA!I45 -> 12.56887 | D35: =DataA!E45 -> 2443000 | E35: =DataA!J45 -> -1.749272 | F35: =DataA!D45 -> 1968889 | G35: =DataA!B45 -> 1900476 | I35: =100*((F35/F34)-1) -> 0.89028268 | J35: =100*((G35/G34)-1) -> 1.1451015 | O35: 2031 | Q35: =Q34 -> 253 | R35: =R34 -> 315 | S35: =S34 -> 379 | V35: 2005 | W35: =100*((DataA!M39/DataA!M38)-1) -> 0.97276662 | X35: =AVERAGE(W26:W35) -> 0.59863954 | Y35: 0 | Z35: 65 | AA35: 60 | AC35: 31 | AD35: ='ONS pop proj 2021-based'!E33+'ONS pop proj 2021-based'!E140 -> 961261 | AE35: ='ONS pop proj 2021-based'!L33+'ONS pop proj 2021-based'!L140 -> 964364 | AF35: ='ONS pop proj 2021-based'!V33+'ONS pop proj 2021-based'!V140 -> 1007491 | AG35: ='ONS pop proj 2021-based'!AF33+'ONS pop proj 2021-based'!AF140 -> 950808 | AN35: 43009 | AO35: =HAVERQ!F198-HAVERQ!F$166 -> 103 | AP35: =HAVERQ!G198-HAVERQ!G$166 -> 985 | AQ35: =HAVERQ!H198-HAVERQ!H$166 -> -12 | AR35: =HAVERQ!I198-HAVERQ!I$166 -> 1584 | AS35: =HAVERQ!J198-HAVERQ!J$166 -> 396 | AT35: =SUM(AO35:AS35) -> 3056 | AV35: =HAVERQ!D198-HAVERQ!D$166-'Chart Data'!AT35 -> 21 | AX35: 34912 | AY35: =100*(HAVERM!C74/HAVERM!B74) -> 24.667515 | AZ35: =AVERAGE($AY$7:$AY$374) -> 24.595806 | BB35: =HAVERM!C74 -> 2133 | BC35: =HAVERM!B74-HAVERM!C74 -> 6514 | BF35: =100*((AVERAGE(HAVERQ!B23:B42)/AVERAGE(HAVERQ!B19:B38))-1) -> 1.485305 | BG35: =$BL$6 -> 2.2155011 | BI35: 0 | BR35: =100*((AVERAGE(HAVERQ!C23:C42)/AVERAGE(HAVERQ!C19:C38))-1) -> 1.047674 | BS35: =$BX$6 -> 1.9448021 | BU35: 0 | CH35: 2046 | CI35: =100*(DataA!B80/DataA!$B$53) -> 143.70651 | CJ35: =CJ34*(1+CO35/100) -> 150.65784 | CK35: 100 | CM35: =100*((CJ35/CI35)-1) -> 4.8371654 | CO35: 1.5632227
A36: 2012 | B36: =DataA!F46*DataA!G46 -> 973104.43 | C36: =DataA!H46/DataA!I46 -> 12.676121 | D36: =DataA!E46 -> 2469000 | E36: =DataA!J46 -> -1.749547 | F36: =DataA!D46 -> 2003656 | G36: =DataA!B46 -> 1929229 | I36: =100*((F36/F35)-1) -> 1.7658182 | J36: =100*((G36/G35)-1) -> 1.5129368 | O36: 2032 | Q36: =Q35 -> 253 | R36: =R35 -> 315 | S36: =S35 -> 379 | V36: 2006 | W36: =100*((DataA!M40/DataA!M39)-1) -> 0.84869501 | X36: =AVERAGE(W27:W36) -> 0.64683076 | Y36: 0 | Z36: 65 | AA36: 60 | AC36: 32 | AD36: ='ONS pop proj 2021-based'!E34+'ONS pop proj 2021-based'!E141 -> 972793 | AE36: ='ONS pop proj 2021-based'!L34+'ONS pop proj 2021-based'!L141 -> 968296 | AF36: ='ONS pop proj 2021-based'!V34+'ONS pop proj 2021-based'!V141 -> 1023231 | AG36: ='ONS pop proj 2021-based'!AF34+'ONS pop proj 2021-based'!AF141 -> 968790 | AN36: 43101 | AO36: =HAVERQ!F199-HAVERQ!F$166 -> 137 | AP36: =HAVERQ!G199-HAVERQ!G$166 -> 995 | AQ36: =HAVERQ!H199-HAVERQ!H$166 -> 46 | AR36: =HAVERQ!I199-HAVERQ!I$166 -> 1655 | AS36: =HAVERQ!J199-HAVERQ!J$166 -> 408 | AT36: =SUM(AO36:AS36) -> 3241 | AV36: =HAVERQ!D199-HAVERQ!D$166-'Chart Data'!AT36 -> 21 | AX36: 34943 | AY36: =100*(HAVERM!C75/HAVERM!B75) -> 24.702209 | AZ36: =AVERAGE($AY$7:$AY$374) -> 24.595806 | BB36: =HAVERM!C75 -> 2136 | BC36: =HAVERM!B75-HAVERM!C75 -> 6511 | BE36: 1979 | BF36: =100*((AVERAGE(HAVERQ!B24:B43)/AVERAGE(HAVERQ!B20:B39))-1) -> 1.7438807 | BG36: =$BL$6 -> 2.2155011 | BI36: 0 | BQ36: 1979 | BR36: =100*((AVERAGE(HAVERQ!C24:C43)/AVERAGE(HAVERQ!C20:C39))-1) -> 1.3242491 | BS36: =$BX$6 -> 1.9448021 | BU36: 0 | CH36: 2047 | CI36: =100*(DataA!B81/DataA!$B$53) -> 145.84956 | CJ36: =CJ35*(1+CO36/100) -> 152.97304 | CK36: 100 | CM36: =100*((CJ36/CI36)-1) -> 4.8841239 | CO36: 1.536727
