Workbook
Name Data: [1]sheet0!$C$2
Name IQ_CH: 110000
Name IQ_CQ: 5000
Name IQ_CY: 10000
Name IQ_DAILY: 500000
Name IQ_FH: 100000
Name IQ_FQ: 500
Name IQ_FY: 1000
Name IQ_LTM: 2000
Name IQ_MONTH: 15000
Name IQ_NTM: 6000
Name IQ_WEEK: 50000
Name IQ_YTD: 3000

Sheet >> CHARTS

Sheet >> DATA

Sheet Chart Data
A1: AE debt dynamics (2024-2028) | Z1: Manifestos | AI1: Real government spending | CO1: PSCEX (% of GDP) | CU1: PSNIX (% of GDP) | DA1: Government revenues (% of GDP) | DG1: GDP (2023-2024=100) | DL1: Labour likely | EA1: Labour likely - net debt calculation
AA2: % of GDP | AD2: £mn (2028-2029) | AI2: Real PSCE in RDEL per head (2023-2024=100) | AN2: Real PSGI in RDEL per head (2023-2024=100) | AS2: Real PSCE in RDEL per head (2023-2024 prices) | AW2: Real PSGI in RDEL per head (2023-2024 prices) | BA2: PSCE in RDEL per head | BE2: PSGI in RDEL per head | BI2: PSCE in RDEL | BM2: PSCE spending pledges | BP2: PSGI in RDEL | BT2: PSNI spending pledges | BW2: GDP deflator (2023-2024 = 100) | CA2: GDP deflator (raw) | CE2: Population | CJ2: Real £ | CK2: Real £ | CL2: Index | CM2: Index | DM2: GDP | DQ2: PSCEX | DV2: PSNIX
B3: =X3 -> UK (OBR) | C3: =DataA!BK2&" (OE)" -> UK (OE) | D3: =DataA!BL2 -> US | E3: =DataA!BM2 -> Japan | F3: =DataA!BN2 -> Canada | G3: =DataA!BO2 -> Australia | H3: =DataA!BP2 -> Denmark | I3: =DataA!BQ2 -> Sweden | J3: =DataA!BR2 -> Switzerland | K3: =DataA!BS2 -> S Korea | ... V3: =DataA!CD2 -> Portugal | X3: UK (OBR) | AA3: Conservative | AB3: Labour | AD3: Conservative | AE3: Labour | AI3: Budget 2024 | AJ3: Conservative | AK3: Labour manifesto | AL3: 100 LINE | AN3: Budget 2024 | AO3: Conservative | AP3: Labour manifesto | AQ3: 100 LINE | AS3: Budget 2024 | AT3: Conservative | AU3: Labour | AW3: Budget 2024 | AX3: Conservative | AY3: Labour | BA3: Budget 2024 | BB3: Conservative | BC3: Labour | BE3: Budget 2024 | BF3: Conservative | BG3: Labour | BI3: Budget 2024 | BJ3: Conservative | BK3: Labour | BM3: Conservative | BN3: Labour | BP3: Budget 2024 | BQ3: Conservative | BR3: Labour | BT3: Conservative | BU3: Labour | BW3: Budget 2024 | BX3: Conservative | BY3: Labour | CA3: Budget 2024 | CB3: Conservative | CC3: Labour | CE3: Budget 2024 | CF3: Conservative | CG3: Labour | CJ3: PSCE | CK3: PSGI | CL3: PSCE | CM3: PSGI | CQ3: Budget 2024 | CR3: Conservative | CS3: Labour | CW3: Budget 2024 | CX3: Conservative | CY3: Labour | DC3: Budget 2024 | DD3: Conservative | DE3: Labour | DH3: Budget 2024 | DI3: Conservative | DJ3: Labour | DM3: Budget 2024 | DN3: Labour manifesto | DO3: Labour extra spending | DR3: Budget 2024 | DS3: Labour manifesto | DT3: Labour extra spending | DW3: Budget 2024 | DX3: Labour manifesto | DY3: Labour extra spending | EB3: GNDBTX | EC3: BoE | ED3: GNDBTX exc BoE | EE3: GDP! | EF3: % of GDP | EG3: Y/Y change (%) | EH3: Y/Y change (£bn) | EI3: APF losses | EJ3: y/y ex APF
A4: Expected effective interest rates on government debt (r) | B4: =X4 -> 4.0670842 | C4: =AVERAGE(DataA!BK58:BK62) -> 3.9726327 | D4: =AVERAGE(DataA!BL58:BL62) -> 3.4292239 | E4: =AVERAGE(DataA!BM58:BM62) -> 0.75030083 | F4: =AVERAGE(DataA!BN58:BN62) -> 3.3279579 | G4: =AVERAGE(DataA!BO58:BO62) -> 2.7255229 | H4: =AVERAGE(DataA!BP58:BP62) -> 2.8058555 | I4: =AVERAGE(DataA!BQ58:BQ62) -> 1.5458391 | J4: =AVERAGE(DataA!BR58:BR62) -> 1.1900635 | ... V4: =AVERAGE(DataA!CD58:CD62) -> 2.3325724 | X4: =AVERAGE(DataOBR!F58:F62) -> 4.0670842 | Z4: NICs | AA4: =100*(AD4/$AA$12) -> 0.363744 | AB4: =100*(AE4/$AA$12) -> 0 | AD4: ='[2]Top level assumptions'!$F$5 -> 11667 | AE4: 0 | AG4: ="20"&LEFT(AH4,2) -> 2007 | AH4: =RIGHT(CI4,5) -> 07-08 | AI4: =CL4 -> 100.43541 | AL4: 100 | AN4: =CM4 -> 83.985641 | AQ4: 100 | CI4: {=TRANSPOSE(OBR_MAR24_ST4.3!E4:Z4)} -> 2007-08 | CJ4: {=TRANSPOSE(OBR_MAR24_ST4.3!E11:Z11)} -> 6193.1143 | CK4: {=TRANSPOSE(OBR_MAR24_ST4.3!E17:Z17)} -> 1170.3834 | CL4: =100*(CJ4/CJ$20) -> 100.43541 | CM4: =100*(CK4/CK$20) -> 83.985641 | CO4: ="20"&LEFT(CP4,2) -> 2007 | CP4: =RIGHT(CI4,5) -> 07-08 | CQ4: =100*(DataScen!CG34/DataScen!CL34) -> 36.148169 | CR4: =100*(DataScen!CY34/DataScen!DD34) -> 36.148169 | CS4: =100*(DataScen!DQ34/DataScen!DV34) -> 36.148169 | CU4: ="20"&LEFT(CV4,2) -> 2007 | CV4: =RIGHT(CI4,5) -> 07-08 | CW4: =100*(DataScen!CH34/DataScen!CL34) -> 1.7932627 | CX4: =100*(DataScen!CZ34/DataScen!DD34) -> 1.7932627 | CY4: =100*(DataScen!DR34/DataScen!DV34) -> 1.7932627 | DA4: ="20"&LEFT(DB4,2) -> 2007 | DB4: =RIGHT(CI4,5) -> 07-08 | DC4: =100*(DataScen!CJ34/DataScen!CL34) -> 37.334264 | DD4: =100*(DataScen!DB34/DataScen!DD34) -> 37.334264 | DE4: =100*(DataScen!DT34/DataScen!DV34) -> 37.334264 | DG4: 2022- 2023 | DH4: =100*(DataScen!CD49/DataScen!$CD$50) -> 99.916458 | DI4: =100*(DataScen!CV49/DataScen!$CV$50) -> 99.916458 | DJ4: =100*(DataScen!DN49/DataScen!$DN$50) -> 99.916458 | DL4: 22-23 | DM4: =100*(DataScen!CD49/DataScen!$CD$50) -> 99.916458 | DN4: =100*(DataScen!DN49/DataScen!$DN$50) -> 99.916458 | DO4: =100*(DataScen!EF49/DataScen!$EF$50) -> 99.916458 | DQ4: 22-23 | DR4: =100*(DataScen!CG49/DataScen!CL49) -> 41.129001 | DS4: =100*(DataScen!DQ49/DataScen!DV49) -> 41.129001 | DT4: =100*(DataScen!EI49/DataScen!EN49) -> 41.129001 | DV4: 22-23 | DW4: =100*(DataScen!CH49/DataScen!CL49) -> 1.797143 | DX4: =100*(DataScen!DR49/DataScen!DV49) -> 1.797143 | DY4: =100*(DataScen!EJ49/DataScen!EN49) -> 1.797143 | EA4: 2022- 2023 | EB4: =DataScen!EM49 -> 2539700 | EC4: 322300 | ED4: =+EB4-EC4 -> 2217400 | EE4: =DataScen!EN49 -> 2555445 | EF4: =100*(ED4/EE4) -> 86.77158
A5: Expected annual average nominal GDP growth (g) | B5: =X5 -> 3.3581279 | C5: =100*((DataA!AP62/DataA!AP57)^(1/5)-1) -> 3.7171817 | D5: =100*((DataA!AQ62/DataA!AQ57)^(1/5)-1) -> 4.1837418 | E5: =100*((DataA!AR62/DataA!AR57)^(1/5)-1) -> 1.8517227 | F5: =100*((DataA!AS62/DataA!AS57)^(1/5)-1) -> 4.3318505 | G5: =100*((DataA!AT62/DataA!AT57)^(1/5)-1) -> 4.8381108 | H5: =100*((DataA!AU62/DataA!AU57)^(1/5)-1) -> 4.1112533 | I5: =100*((DataA!AV62/DataA!AV57)^(1/5)-1) -> 3.9943263 | J5: =100*((DataA!AW62/DataA!AW57)^(1/5)-1) -> 2.6377391 | ... V5: =100*((DataA!BI62/DataA!BI57)^(1/5)-1) -> 3.4715938 | X5: =100*((DataOBR!D62/DataOBR!D57)^(1/5)-1) -> 3.3581279 | Z5: Reducing tax avoidance | AA5: =100*(AD5/$AA$12) -> -0.15588583 | AB5: =100*(AE5/$AA$12) -> -0.16305658 | AD5: ='[2]Top level assumptions'!$F$11 -> -5000 | AE5: =-'[3]Top level assumptions'!$F$8 -> -5230 | AG5: ="20"&LEFT(AH5,2) -> 2008 | AH5: =RIGHT(CI5,5) -> 08-09 | AI5: =CL5 -> 100.66341 | AL5: 100 | AN5: =CM5 -> 86.761543 | AQ5: 100 | CI5: 2008-09 | CJ5: 6207.1735 | CK5: 1209.067 | CL5: =100*(CJ5/CJ$20) -> 100.66341 | CM5: =100*(CK5/CK$20) -> 86.761543 | CO5: ="20"&LEFT(CP5,2) -> 2008 | CP5: =RIGHT(CI5,5) -> 08-09 | CQ5: =100*(DataScen!CG35/DataScen!CL35) -> 37.933751 | CR5: =100*(DataScen!CY35/DataScen!DD35) -> 37.933751 | CS5: =100*(DataScen!DQ35/DataScen!DV35) -> 37.933751 | CU5: ="20"&LEFT(CV5,2) -> 2008 | CV5: =RIGHT(CI5,5) -> 08-09 | CW5: =100*(DataScen!CH35/DataScen!CL35) -> 3.0057032 | CX5: =100*(DataScen!CZ35/DataScen!DD35) -> 3.0057032 | CY5: =100*(DataScen!DR35/DataScen!DV35) -> 3.0057032 | DA5: ="20"&LEFT(DB5,2) -> 2008 | DB5: =RIGHT(CI5,5) -> 08-09 | DC5: =100*(DataScen!CJ35/DataScen!CL35) -> 36.020864 | DD5: =100*(DataScen!DB35/DataScen!DD35) -> 36.020864 | DE5: =100*(DataScen!DT35/DataScen!DV35) -> 36.020864 | DG5: 2023- 2024 | DH5: =100*(DataScen!CD50/DataScen!$CD$50) -> 100 | DI5: =100*(DataScen!CV50/DataScen!$CV$50) -> 100 | DJ5: =100*(DataScen!DN50/DataScen!$DN$50) -> 100 | DL5: 23-24 | DM5: =100*(DataScen!CD50/DataScen!$CD$50) -> 100 | DN5: =100*(DataScen!DN50/DataScen!$DN$50) -> 100 | DO5: =100*(DataScen!EF50/DataScen!$EF$50) -> 100 | DQ5: 23-24 | DR5: =100*(DataScen!CG50/DataScen!CL50) -> 39.823317 | DS5: =100*(DataScen!DQ50/DataScen!DV50) -> 39.823317 | DT5: =100*(DataScen!EI50/DataScen!EN50) -> 39.823317 | DV5: 23-24 | DW5: =100*(DataScen!CH50/DataScen!CL50) -> 2.5808861 | DX5: =100*(DataScen!DR50/DataScen!DV50) -> 2.5808861 | DY5: =100*(DataScen!EJ50/DataScen!EN50) -> 2.5808861 | EA5: 2023- 2024 | EB5: =DataScen!EM50 -> 2694300 | EC5: 278070.92 | ED5: =+EB5-EC5 -> 2416229.1 | EE5: =DataScen!EN50 -> 2714804 | EF5: =100*(ED5/EE5) -> 89.001971 | EG5: =EF5-EF4 -> 2.2303915 | EH5: =(EG5/100)*EE5 -> 60550.758 | EJ5: =EH5-EI5 -> 60550.758
Z6: Other taxation | AA6: =100*(AD6/$AA$12) -> 0.12265097 | AB6: =100*(AE6/$AA$12) -> -0.10335231 | AD6: ='[2]Top level assumptions'!$F$9+'[2]Top level assumptions'!$F$10 -> 3934 | AE6: =-'[3]Top level assumptions'!$F$5-'[3]Top level assumptions'!$F$6+-'[3]Top level assumptions'!$F$7 -> -3315 | AG6: ="20"&LEFT(AH6,2) -> 2009 | AH6: =RIGHT(CI6,5) -> 09-10 | AI6: =CL6 -> 104.95422 | AL6: 100 | AN6: =CM6 -> 96.7349 | AQ6: 100 | CI6: 2009-10 | CJ6: 6471.7565 | CK6: 1348.0509 | CL6: =100*(CJ6/CJ$20) -> 104.95422 | CM6: =100*(CK6/CK$20) -> 96.7349 | CO6: ="20"&LEFT(CP6,2) -> 2009 | CP6: =RIGHT(CI6,5) -> 09-10 | CQ6: =100*(DataScen!CG36/DataScen!CL36) -> 40.740006 | CR6: =100*(DataScen!CY36/DataScen!DD36) -> 40.740006 | CS6: =100*(DataScen!DQ36/DataScen!DV36) -> 40.740006 | CU6: ="20"&LEFT(CV6,2) -> 2009 | CV6: =RIGHT(CI6,5) -> 09-10 | CW6: =100*(DataScen!CH36/DataScen!CL36) -> 3.000688 | CX6: =100*(DataScen!CZ36/DataScen!DD36) -> 3.000688 | CY6: =100*(DataScen!DR36/DataScen!DV36) -> 3.000688 | DA6: ="20"&LEFT(DB6,2) -> 2009 | DB6: =RIGHT(CI6,5) -> 09-10 | DC6: =100*(DataScen!CJ36/DataScen!CL36) -> 36.093805 | DD6: =100*(DataScen!DB36/DataScen!DD36) -> 36.093805 | DE6: =100*(DataScen!DT36/DataScen!DV36) -> 36.093805 | DG6: 2024- 2025 | DH6: =100*(DataScen!CD51/DataScen!$CD$50) -> 101.26127 | DI6: =100*(DataScen!CV51/DataScen!$CV$50) -> 101.26117 | DJ6: =100*(DataScen!DN51/DataScen!$DN$50) -> 101.26117 | DL6: 24-25 | DM6: =100*(DataScen!CD51/DataScen!$CD$50) -> 101.26127 | DN6: =100*(DataScen!DN51/DataScen!$DN$50) -> 101.26117 | DO6: =100*(DataScen!EF51/DataScen!$EF$50) -> 101.26117 | DQ6: 24-25 | DR6: =100*(DataScen!CG51/DataScen!CL51) -> 39.455399 | DS6: =100*(DataScen!DQ51/DataScen!DV51) -> 39.455681 | DT6: =100*(DataScen!EI51/DataScen!EN51) -> 39.455681 | DV6: 24-25 | DW6: =100*(DataScen!CH51/DataScen!CL51) -> 2.3916702 | DX6: =100*(DataScen!DR51/DataScen!DV51) -> 2.3916733 | DY6: =100*(DataScen!EJ51/DataScen!EN51) -> 2.3916733 | EA6: 2024- 2025 | EB6: =DataScen!EM51 -> 2804618 | EC6: 234782.39 | ED6: =+EB6-EC6 -> 2569835.6 | EE6: =DataScen!EN51 -> 2783071.2 | EF6: =100*(ED6/EE6) -> 92.33812 | EG6: =EF6-EF5 -> 3.3361482 | EH6: =(EG6/100)*EE6 -> 92847.381 | EI6: {=-TRANSPOSE(OBR_MAR24_ST6.6!O10:S10)*1000} -> 19049.878 | EJ6: =EH6-EI6 -> 73797.503
Z7: Welfare spending | AA7: =100*(AD7/$AA$12) -> -0.34294883 | AB7: =100*(AE7/$AA$12) -> 0 | AD7: ='[2]Top level assumptions'!$F$17 -> -11000 | AE7: 0 | AG7: ="20"&LEFT(AH7,2) -> 2010 | AH7: =RIGHT(CI7,5) -> 10-11 | AI7: =CL7 -> 104.32871 | AL7: 100 | AN7: =CM7 -> 80.784526 | AQ7: 100 | CI7: 2010-11 | CJ7: 6433.1857 | CK7: 1125.7742 | CL7: =100*(CJ7/CJ$20) -> 104.32871 | CM7: =100*(CK7/CK$20) -> 80.784526 | CO7: ="20"&LEFT(CP7,2) -> 2010 | CP7: =RIGHT(CI7,5) -> 10-11 | CQ7: =100*(DataScen!CG37/DataScen!CL37) -> 40.719727 | CR7: =100*(DataScen!CY37/DataScen!DD37) -> 40.719727 | CS7: =100*(DataScen!DQ37/DataScen!DV37) -> 40.719727 | CU7: ="20"&LEFT(CV7,2) -> 2010 | CV7: =RIGHT(CI7,5) -> 10-11 | CW7: =100*(DataScen!CH37/DataScen!CL37) -> 2.4455927 | CX7: =100*(DataScen!CZ37/DataScen!DD37) -> 2.4455927 | CY7: =100*(DataScen!DR37/DataScen!DV37) -> 2.4455927 | DA7: ="20"&LEFT(DB7,2) -> 2010 | DB7: =RIGHT(CI7,5) -> 10-11 | DC7: =100*(DataScen!CJ37/DataScen!CL37) -> 37.025281 | DD7: =100*(DataScen!DB37/DataScen!DD37) -> 37.025281 | DE7: =100*(DataScen!DT37/DataScen!DV37) -> 37.025281 | DG7: 2025- 2026 | DH7: =100*(DataScen!CD52/DataScen!$CD$50) -> 103.09176 | DI7: =100*(DataScen!CV52/DataScen!$CV$50) -> 103.16699 | DJ7: =100*(DataScen!DN52/DataScen!$DN$50) -> 103.31837 | DL7: 25-26 | DM7: =100*(DataScen!CD52/DataScen!$CD$50) -> 103.09176 | DN7: =100*(DataScen!DN52/DataScen!$DN$50) -> 103.31837 | DO7: =100*(DataScen!EF52/DataScen!$EF$50) -> 103.68554 | DQ7: 25-26 | DR7: =100*(DataScen!CG52/DataScen!CL52) -> 39.315972 | DS7: =100*(DataScen!DQ52/DataScen!DV52) -> 39.25918 | DT7: =100*(DataScen!EI52/DataScen!EN52) -> 39.242652 | DV7: 25-26 | DW7: =100*(DataScen!CH52/DataScen!CL52) -> 2.1220676 | DX7: =100*(DataScen!DR52/DataScen!DV52) -> 2.2813384 | DY7: =100*(DataScen!EJ52/DataScen!EN52) -> 2.3503227 | EA7: 2025- 2026 | EB7: =DataScen!EM52 -> 2846965 | EC7: 139577.23 | ED7: =+EB7-EC7 -> 2707387.8 | EE7: =DataScen!EN52 -> 2893863 | EF7: =100*(ED7/EE7) -> 93.556183 | EG7: =EF7-EF6 -> 1.2180637 | EH7: =(EG7/100)*EE7 -> 35249.094 | EI7: 9152.3991 | EJ7: =EH7-EI7 -> 26096.695
Z8: Other current spending | AA8: =100*(AD8/$AA$12) -> -0.012003209 | AB8: =100*(AE8/$AA$12) -> 0.1507416 | AD8: ='[2]Top level assumptions'!$F$19 -> -385 | AE8: ='[3]Top level assumptions'!$F$14+'[3]Top level assumptions'!$F$15 -> 4835 | AG8: ="20"&LEFT(AH8,2) -> 2011 | AH8: =RIGHT(CI8,5) -> 11-12 | AI8: =CL8 -> 100.33174 | AL8: 100 | AN8: =CM8 -> 68.060388 | AQ8: 100 | CI8: 2011-12 | CJ8: 6186.7218 | CK8: 948.45675 | CL8: =100*(CJ8/CJ$20) -> 100.33174 | CM8: =100*(CK8/CK$20) -> 68.060388 | CO8: ="20"&LEFT(CP8,2) -> 2011 | CP8: =RIGHT(CI8,5) -> 11-12 | CQ8: =100*(DataScen!CG38/DataScen!CL38) -> 40.14769 | CR8: =100*(DataScen!CY38/DataScen!DD38) -> 40.14769 | CS8: =100*(DataScen!DQ38/DataScen!DV38) -> 40.14769 | CU8: ="20"&LEFT(CV8,2) -> 2011 | CV8: =RIGHT(CI8,5) -> 11-12 | CW8: =100*(DataScen!CH38/DataScen!CL38) -> 1.8428614 | CX8: =100*(DataScen!CZ38/DataScen!DD38) -> 1.8428614 | CY8: =100*(DataScen!DR38/DataScen!DV38) -> 1.8428614 | DA8: ="20"&LEFT(DB8,2) -> 2011 | DB8: =RIGHT(CI8,5) -> 11-12 | DC8: =100*(DataScen!CJ38/DataScen!CL38) -> 37.340559 | DD8: =100*(DataScen!DB38/DataScen!DD38) -> 37.340559 | DE8: =100*(DataScen!DT38/DataScen!DV38) -> 37.340559 | DG8: 2026- 2027 | DH8: =100*(DataScen!CD53/DataScen!$CD$50) -> 105.08799 | DI8: =100*(DataScen!CV53/DataScen!$CV$50) -> 105.08974 | DJ8: =100*(DataScen!DN53/DataScen!$DN$50) -> 105.27839 | DL8: 26-27 | DM8: =100*(DataScen!CD53/DataScen!$CD$50) -> 105.08799 | DN8: =100*(DataScen!DN53/DataScen!$DN$50) -> 105.27839 | DO8: =100*(DataScen!EF53/DataScen!$EF$50) -> 105.81967 | DQ8: 26-27 | DR8: =100*(DataScen!CG53/DataScen!CL53) -> 39.196978 | DS8: =100*(DataScen!DQ53/DataScen!DV53) -> 39.181183 | DT8: =100*(DataScen!EI53/DataScen!EN53) -> 39.18609 | DV8: 26-27 | DW8: =100*(DataScen!CH53/DataScen!CL53) -> 1.9838395 | DX8: =100*(DataScen!DR53/DataScen!DV53) -> 2.1387945 | DY8: =100*(DataScen!EJ53/DataScen!EN53) -> 2.2579542 | EA8: 2026- 2027 | EB8: =DataScen!EM53 -> 2946197 | EC8: 104897.13 | ED8: =+EB8-EC8 -> 2841299.9 | EE8: =DataScen!EN53 -> 3011923.4 | EF8: =100*(ED8/EE8) -> 94.335064 | EG8: =EF8-EF7 -> 0.77888063 | EH8: =(EG8/100)*EE8 -> 23459.288 | EI8: 15970.596 | EJ8: =EH8-EI8 -> 7488.6917
Z9: Capital spending | AA9: =100*(AD9/$AA$12) -> 0 | AB9: =100*(AE9/$AA$12) -> 0.14653268 | AD9: 0 | AE9: ='[3]Top level assumptions'!$F$19 -> 4700 | AG9: ="20"&LEFT(AH9,2) -> 2012 | AH9: =RIGHT(CI9,5) -> 12-13 | AI9: =CL9 -> 96.544117 | AL9: 100 | AN9: =CM9 -> 64.3172 | AQ9: 100 | CI9: 2012-13 | CJ9: 5953.1669 | CK9: 896.29347 | CL9: =100*(CJ9/CJ$20) -> 96.544117 | CM9: =100*(CK9/CK$20) -> 64.3172 | CO9: ="20"&LEFT(CP9,2) -> 2012 | CP9: =RIGHT(CI9,5) -> 12-13 | CQ9: =100*(DataScen!CG39/DataScen!CL39) -> 39.560156 | CR9: =100*(DataScen!CY39/DataScen!DD39) -> 39.560156 | CS9: =100*(DataScen!DQ39/DataScen!DV39) -> 39.560156 | CU9: ="20"&LEFT(CV9,2) -> 2012 | CV9: =RIGHT(CI9,5) -> 12-13 | CW9: =100*(DataScen!CH39/DataScen!CL39) -> 1.8779305 | CX9: =100*(DataScen!CZ39/DataScen!DD39) -> 1.8779305 | CY9: =100*(DataScen!DR39/DataScen!DV39) -> 1.8779305 | DA9: ="20"&LEFT(DB9,2) -> 2012 | DB9: =RIGHT(CI9,5) -> 12-13 | DC9: =100*(DataScen!CJ39/DataScen!CL39) -> 36.818357 | DD9: =100*(DataScen!DB39/DataScen!DD39) -> 36.818357 | DE9: =100*(DataScen!DT39/DataScen!DV39) -> 36.818357 | DG9: 2027- 2028 | DH9: =100*(DataScen!CD54/DataScen!$CD$50) -> 106.95727 | DI9: =100*(DataScen!CV54/DataScen!$CV$50) -> 106.97349 | DJ9: =100*(DataScen!DN54/DataScen!$DN$50) -> 107.12585 | DL9: 27-28 | DM9: =100*(DataScen!CD54/DataScen!$CD$50) -> 106.95727 | DN9: =100*(DataScen!DN54/DataScen!$DN$50) -> 107.12585 | DO9: =100*(DataScen!EF54/DataScen!$EF$50) -> 107.57942 | DQ9: 27-28 | DR9: =100*(DataScen!CG54/DataScen!CL54) -> 38.85815 | DS9: =100*(DataScen!DQ54/DataScen!DV54) -> 38.900601 | DT9: =100*(DataScen!EI54/DataScen!EN54) -> 39.003616 | DV9: 27-28 | DW9: =100*(DataScen!CH54/DataScen!CL54) -> 1.8228113 | DX9: =100*(DataScen!DR54/DataScen!DV54) -> 1.9730193 | DY9: =100*(DataScen!EJ54/DataScen!EN54) -> 2.1039041 | EA9: 2027- 2028 | EB9: =DataScen!EM54 -> 3057814 | EC9: 93282.767 | ED9: =+EB9-EC9 -> 2964531.2 | EE9: =DataScen!EN54 -> 3124122.9 | EF9: =100*(ED9/EE9) -> 94.891633 | EG9: =EF9-EF8 -> 0.55656891 | EH9: =(EG9/100)*EE9 -> 17387.897 | EI9: 17644.314 | EJ9: =EH9-EI9 -> -256.41716
Z10: Total | AA10: =SUM(AA4:AA9) -> -0.024442899 | AB10: =SUM(AB4:AB9) -> 0.030865395 | AD10: =SUM(AD4:AD9) -> -784 | AE10: =SUM(AE4:AE9) -> 990 | AG10: ="20"&LEFT(AH10,2) -> 2013 | AH10: =RIGHT(CI10,5) -> 13-14 | AI10: =CL10 -> 95.557909 | AL10: 100 | AN10: =CM10 -> 67.741493 | AQ10: 100 | CI10: 2013-14 | CJ10: 5892.3547 | CK10: 944.01278 | CL10: =100*(CJ10/CJ$20) -> 95.557909 | CM10: =100*(CK10/CK$20) -> 67.741493 | CO10: ="20"&LEFT(CP10,2) -> 2013 | CP10: =RIGHT(CI10,5) -> 13-14 | CQ10: =100*(DataScen!CG40/DataScen!CL40) -> 38.579764 | CR10: =100*(DataScen!CY40/DataScen!DD40) -> 38.579764 | CS10: =100*(DataScen!DQ40/DataScen!DV40) -> 38.579764 | CU10: ="20"&LEFT(CV10,2) -> 2013 | CV10: =RIGHT(CI10,5) -> 13-14 | CW10: =100*(DataScen!CH40/DataScen!CL40) -> 1.4547675 | CX10: =100*(DataScen!CZ40/DataScen!DD40) -> 1.4547675 | CY10: =100*(DataScen!DR40/DataScen!DV40) -> 1.4547675 | DA10: ="20"&LEFT(DB10,2) -> 2013 | DB10: =RIGHT(CI10,5) -> 13-14 | DC10: =100*(DataScen!CJ40/DataScen!CL40) -> 36.800222 | DD10: =100*(DataScen!DB40/DataScen!DD40) -> 36.800222 | DE10: =100*(DataScen!DT40/DataScen!DV40) -> 36.800222 | DG10: 2028- 2029 | DH10: =100*(DataScen!CD55/DataScen!$CD$50) -> 108.77442 | DI10: =100*(DataScen!CV55/DataScen!$CV$50) -> 108.81754 | DJ10: =100*(DataScen!DN55/DataScen!$DN$50) -> 108.96377 | DL10: 28-29 | DM10: =100*(DataScen!CD55/DataScen!$CD$50) -> 108.77442 | DN10: =100*(DataScen!DN55/DataScen!$DN$50) -> 108.96377 | DO10: =100*(DataScen!EF55/DataScen!$EF$50) -> 109.4142 | DQ10: 28-29 | DR10: =100*(DataScen!CG55/DataScen!CL55) -> 38.693797 | DS10: =100*(DataScen!DQ55/DataScen!DV55) -> 38.76017 | DT10: =100*(DataScen!EI55/DataScen!EN55) -> 38.950111 | DV10: 28-29 | DW10: =100*(DataScen!CH55/DataScen!CL55) -> 1.6559616 | DX10: =100*(DataScen!DR55/DataScen!DV55) -> 1.800856 | DY10: =100*(DataScen!EJ55/DataScen!EN55) -> 1.9490527 | EA10: 2028- 2029 | EB10: =DataScen!EM55 -> 3163102 | EC10: 79450.758 | ED10: =+EB10-EC10 -> 3083651.2 | EE10: =DataScen!EN55 -> 3243345.3 | EF10: =100*(ED10/EE10) -> 95.076255 | EG10: =EF10-EF9 -> 0.18462196 | EH10: =(EG10/100)*EE10 -> 5987.9278 | EI10: 20408.856 | EJ10: =EH10-EI10 -> -14420.929
AG11: ="20"&LEFT(AH11,2) -> 2014 | AH11: =RIGHT(CI11,5) -> 14-15 | AI11: =CL11 -> 94.289963 | AL11: 100 | AN11: =CM11 -> 72.034572 | AQ11: 100 | CI11: 2014-15 | CJ11: 5814.1698 | CK11: 1003.839 | CL11: =100*(CJ11/CJ$20) -> 94.289963 | CM11: =100*(CK11/CK$20) -> 72.034572 | CO11: ="20"&LEFT(CP11,2) -> 2014 | CP11: =RIGHT(CI11,5) -> 14-15 | CQ11: =100*(DataScen!CG41/DataScen!CL41) -> 37.539989 | CR11: =100*(DataScen!CY41/DataScen!DD41) -> 37.539989 | CS11: =100*(DataScen!DQ41/DataScen!DV41) -> 37.539989 | CU11: ="20"&LEFT(CV11,2) -> 2014 | CV11: =RIGHT(CI11,5) -> 14-15 | CW11: =100*(DataScen!CH41/DataScen!CL41) -> 1.9251727 | CX11: =100*(DataScen!CZ41/DataScen!DD41) -> 1.9251727 | CY11: =100*(DataScen!DR41/DataScen!DV41) -> 1.9251727 | DA11: ="20"&LEFT(DB11,2) -> 2014 | DB11: =RIGHT(CI11,5) -> 14-15 | DC11: =100*(DataScen!CJ41/DataScen!CL41) -> 36.695827 | DD11: =100*(DataScen!DB41/DataScen!DD41) -> 36.695827 | DE11: =100*(DataScen!DT41/DataScen!DV41) -> 36.695827
Z12: GDP! | AA12: =[4]TA.3!$I$10*1000 -> 3207475.6 | AG12: ="20"&LEFT(AH12,2) -> 2015 | AH12: =RIGHT(CI12,5) -> 15-16 | AI12: =CL12 -> 92.40396 | AL12: 100 | AN12: =CM12 -> 68.29393 | AQ12: 100 | CI12: 2015-16 | CJ12: 5697.8739 | CK12: 951.71127 | CL12: =100*(CJ12/CJ$20) -> 92.40396 | CM12: =100*(CK12/CK$20) -> 68.29393 | CO12: ="20"&LEFT(CP12,2) -> 2015 | CP12: =RIGHT(CI12,5) -> 15-16 | CQ12: =100*(DataScen!CG42/DataScen!CL42) -> 37.084294 | CR12: =100*(DataScen!CY42/DataScen!DD42) -> 37.084294 | CS12: =100*(DataScen!DQ42/DataScen!DV42) -> 37.084294 | CU12: ="20"&LEFT(CV12,2) -> 2015 | CV12: =RIGHT(CI12,5) -> 15-16 | CW12: =100*(DataScen!CH42/DataScen!CL42) -> 1.669736 | CX12: =100*(DataScen!CZ42/DataScen!DD42) -> 1.669736 | CY12: =100*(DataScen!DR42/DataScen!DV42) -> 1.669736 | DA12: ="20"&LEFT(DB12,2) -> 2015 | DB12: =RIGHT(CI12,5) -> 15-16 | DC12: =100*(DataScen!CJ42/DataScen!CL42) -> 36.984731 | DD12: =100*(DataScen!DB42/DataScen!DD42) -> 36.984731 | DE12: =100*(DataScen!DT42/DataScen!DV42) -> 36.984731
AG13: ="20"&LEFT(AH13,2) -> 2016 | AH13: =RIGHT(CI13,5) -> 16-17 | AI13: =CL13 -> 90.751464 | AL13: 100 | AN13: =CM13 -> 67.698326 | AQ13: 100 | CI13: 2016-17 | CJ13: 5595.9765 | CK13: 943.41122 | CL13: =100*(CJ13/CJ$20) -> 90.751464 | CM13: =100*(CK13/CK$20) -> 67.698326 | CO13: ="20"&LEFT(CP13,2) -> 2016 | CP13: =RIGHT(CI13,5) -> 16-17 | CQ13: =100*(DataScen!CG43/DataScen!CL43) -> 36.103244 | CR13: =100*(DataScen!CY43/DataScen!DD43) -> 36.103244 | CS13: =100*(DataScen!DQ43/DataScen!DV43) -> 36.103244 | CU13: ="20"&LEFT(CV13,2) -> 2016 | CV13: =RIGHT(CI13,5) -> 16-17 | CW13: =100*(DataScen!CH43/DataScen!CL43) -> 1.8081783 | CX13: =100*(DataScen!CZ43/DataScen!DD43) -> 1.8081783 | CY13: =100*(DataScen!DR43/DataScen!DV43) -> 1.8081783 | DA13: ="20"&LEFT(DB13,2) -> 2016 | DB13: =RIGHT(CI13,5) -> 16-17 | DC13: =100*(DataScen!CJ43/DataScen!CL43) -> 37.484306 | DD13: =100*(DataScen!DB43/DataScen!DD43) -> 37.484306 | DE13: =100*(DataScen!DT43/DataScen!DV43) -> 37.484306
AG14: ="20"&LEFT(AH14,2) -> 2017 | AH14: =RIGHT(CI14,5) -> 17-18 | AI14: =CL14 -> 89.829709 | AL14: 100 | AN14: =CM14 -> 70.926661 | AQ14: 100 | CI14: 2017-18 | CJ14: 5539.1387 | CK14: 988.39974 | CL14: =100*(CJ14/CJ$20) -> 89.829709 | CM14: =100*(CK14/CK$20) -> 70.926661 | CO14: ="20"&LEFT(CP14,2) -> 2017 | CP14: =RIGHT(CI14,5) -> 17-18 | CQ14: =100*(DataScen!CG44/DataScen!CL44) -> 35.467482 | CR14: =100*(DataScen!CY44/DataScen!DD44) -> 35.467482 | CS14: =100*(DataScen!DQ44/DataScen!DV44) -> 35.467482 | CU14: ="20"&LEFT(CV14,2) -> 2017 | CV14: =RIGHT(CI14,5) -> 17-18 | CW14: =100*(DataScen!CH44/DataScen!CL44) -> 2.2078538 | CX14: =100*(DataScen!CZ44/DataScen!DD44) -> 2.2078538 | CY14: =100*(DataScen!DR44/DataScen!DV44) -> 2.2078538 | DA14: ="20"&LEFT(DB14,2) -> 2017 | DB14: =RIGHT(CI14,5) -> 17-18 | DC14: =100*(DataScen!CJ44/DataScen!CL44) -> 37.174722 | DD14: =100*(DataScen!DB44/DataScen!DD44) -> 37.174722 | DE14: =100*(DataScen!DT44/DataScen!DV44) -> 37.174722
AG15: ="20"&LEFT(AH15,2) -> 2018 | AH15: =RIGHT(CI15,5) -> 18-19 | AI15: =CL15 -> 89.519645 | AL15: 100 | AN15: =CM15 -> 73.803986 | AQ15: 100 | CI15: 2018-19 | CJ15: 5520.0193 | CK15: 1028.4968 | CL15: =100*(CJ15/CJ$20) -> 89.519645 | CM15: =100*(CK15/CK$20) -> 73.803986 | CO15: ="20"&LEFT(CP15,2) -> 2018 | CP15: =RIGHT(CI15,5) -> 18-19 | CQ15: =100*(DataScen!CG45/DataScen!CL45) -> 35.087439 | CR15: =100*(DataScen!CY45/DataScen!DD45) -> 35.087439 | CS15: =100*(DataScen!DQ45/DataScen!DV45) -> 35.087439 | CU15: ="20"&LEFT(CV15,2) -> 2018 | CV15: =RIGHT(CI15,5) -> 18-19 | CW15: =100*(DataScen!CH45/DataScen!CL45) -> 2.1032679 | CX15: =100*(DataScen!CZ45/DataScen!DD45) -> 2.1032679 | CY15: =100*(DataScen!DR45/DataScen!DV45) -> 2.1032679 | DA15: ="20"&LEFT(DB15,2) -> 2018 | DB15: =RIGHT(CI15,5) -> 18-19 | DC15: =100*(DataScen!CJ45/DataScen!CL45) -> 37.46761 | DD15: =100*(DataScen!DB45/DataScen!DD45) -> 37.46761 | DE15: =100*(DataScen!DT45/DataScen!DV45) -> 37.46761
AG16: ="20"&LEFT(AH16,2) -> 2019 | AH16: =RIGHT(CI16,5) -> 19-20 | AI16: =CL16 -> 93.503228 | AL16: 100 | AN16: =CM16 -> 75.285142 | AQ16: 100 | BW16: =100*(CA16/CA$20) -> 84.011728 | BX16: =100*(CB16/CB$20) -> 84.011728 | BY16: =100*(CC16/CC$20) -> 84.011728 | CA16: =OBR_MAR24_1.2!X122 -> 100.73409 | CB16: =$CA16 -> 100.73409 | CC16: =$CA16 -> 100.73409 | CE16: {=TRANSPOSE(OBR_MAR24_ST4.3!Q34:Z34)} -> 66903.5 | CF16: =$CE16 -> 66903.5 | CG16: =$CE16 -> 66903.5 | CI16: 2019-20 | CJ16: 5765.6577 | CK16: 1049.1374 | CL16: =100*(CJ16/CJ$20) -> 93.503228 | CM16: =100*(CK16/CK$20) -> 75.285142 | CO16: ="20"&LEFT(CP16,2) -> 2019 | CP16: =RIGHT(CI16,5) -> 19-20 | CQ16: =100*(DataScen!CG46/DataScen!CL46) -> 35.404422 | CR16: =100*(DataScen!CY46/DataScen!DD46) -> 35.404422 | CS16: =100*(DataScen!DQ46/DataScen!DV46) -> 35.404422 | CU16: ="20"&LEFT(CV16,2) -> 2019 | CV16: =RIGHT(CI16,5) -> 19-20 | CW16: =100*(DataScen!CH46/DataScen!CL46) -> 1.8992228 | CX16: =100*(DataScen!CZ46/DataScen!DD46) -> 1.8992228 | CY16: =100*(DataScen!DR46/DataScen!DV46) -> 1.8992228 | DA16: ="20"&LEFT(DB16,2) -> 2019 | DB16: =RIGHT(CI16,5) -> 19-20 | DC16: =100*(DataScen!CJ46/DataScen!CL46) -> 36.946346 | DD16: =100*(DataScen!DB46/DataScen!DD46) -> 36.946346 | DE16: =100*(DataScen!DT46/DataScen!DV46) -> 36.946346
AG17: ="20"&LEFT(AH17,2) -> 2020 | AH17: =RIGHT(CI17,5) -> 20-21 | AI17: =CL17 -> 112.15508 | AL17: 100 | AN17: =CM17 -> 91.228347 | AQ17: 100 | BW17: =100*(CA17/CA$20) -> 88.488253 | BX17: =100*(CB17/CB$20) -> 88.488253 | BY17: =100*(CC17/CC$20) -> 88.488253 | CA17: =OBR_MAR24_1.2!X123 -> 106.10166 | CB17: =$CA17 -> 106.10166 | CC17: =$CA17 -> 106.10166 | CE17: 67060.5 | CF17: =$CE17 -> 67060.5 | CG17: =$CE17 -> 67060.5 | CI17: 2020-21 | CJ17: 6915.7804 | CK17: 1271.3142 | CL17: =100*(CJ17/CJ$20) -> 112.15508 | CM17: =100*(CK17/CK$20) -> 91.228347 | CO17: ="20"&LEFT(CP17,2) -> 2020 | CP17: =RIGHT(CI17,5) -> 20-21 | CQ17: =100*(DataScen!CG47/DataScen!CL47) -> 47.055132 | CR17: =100*(DataScen!CY47/DataScen!DD47) -> 47.055132 | CS17: =100*(DataScen!DQ47/DataScen!DV47) -> 47.055132 | CU17: ="20"&LEFT(CV17,2) -> 2020 | CV17: =RIGHT(CI17,5) -> 20-21 | CW17: =100*(DataScen!CH47/DataScen!CL47) -> 3.4502793 | CX17: =100*(DataScen!CZ47/DataScen!DD47) -> 3.4502793 | CY17: =100*(DataScen!DR47/DataScen!DV47) -> 3.4502793 | DA17: ="20"&LEFT(DB17,2) -> 2020 | DB17: =RIGHT(CI17,5) -> 20-21 | DC17: =100*(DataScen!CJ47/DataScen!CL47) -> 37.988017 | DD17: =100*(DataScen!DB47/DataScen!DD47) -> 37.988017 | DE17: =100*(DataScen!DT47/DataScen!DV47) -> 37.988017
AG18: ="20"&LEFT(AH18,2) -> 2021 | AH18: =RIGHT(CI18,5) -> 21-22 | AI18: =CL18 -> 110.01328 | AL18: 100 | AN18: =CM18 -> 93.606097 | AQ18: 100 | BW18: =100*(CA18/CA$20) -> 87.880815 | BX18: =100*(CB18/CB$20) -> 87.880815 | BY18: =100*(CC18/CC$20) -> 87.880815 | CA18: =OBR_MAR24_1.2!X124 -> 105.37331 | CB18: =$CA18 -> 105.37331 | CC18: =$CA18 -> 105.37331 | CE18: 67313.25 | CF18: =$CE18 -> 67313.25 | CG18: =$CE18 -> 67313.25 | CI18: 2021-22 | CJ18: 6783.7111 | CK18: 1304.4494 | CL18: =100*(CJ18/CJ$20) -> 110.01328 | CM18: =100*(CK18/CK$20) -> 93.606097 | CO18: ="20"&LEFT(CP18,2) -> 2021 | CP18: =RIGHT(CI18,5) -> 21-22 | CQ18: =100*(DataScen!CG48/DataScen!CL48) -> 39.822995 | CR18: =100*(DataScen!CY48/DataScen!DD48) -> 39.822995 | CS18: =100*(DataScen!DQ48/DataScen!DV48) -> 39.822995 | CU18: ="20"&LEFT(CV18,2) -> 2021 | CV18: =RIGHT(CI18,5) -> 21-22 | CW18: =100*(DataScen!CH48/DataScen!CL48) -> 2.309637 | CX18: =100*(DataScen!CZ48/DataScen!DD48) -> 2.309637 | CY18: =100*(DataScen!DR48/DataScen!DV48) -> 2.309637 | DA18: ="20"&LEFT(DB18,2) -> 2021 | DB18: =RIGHT(CI18,5) -> 21-22 | DC18: =100*(DataScen!CJ48/DataScen!CL48) -> 39.116614 | DD18: =100*(DataScen!DB48/DataScen!DD48) -> 39.116614 | DE18: =100*(DataScen!DT48/DataScen!DV48) -> 39.116614
AG19: ="20"&LEFT(AH19,2) -> 2022 | AH19: =RIGHT(CI19,5) -> 22-23 | AI19: =100*(AS19/AS$20) -> 103.6084 | AL19: 100 | AN19: =100*(AW19/AW$20) -> 101.02944 | AQ19: 100 | AS19: =100*(BA19/BW19) -> 6.3887696 | AW19: =100*(BE19/BW19) -> 1.4078975 | BA19: =BI19/(CE19/1000) -> 5.9957062 | BE19: =BP19/(CE19/1000) -> 1.3212779 | BI19: {=TRANSPOSE(OBR_MAR24_TA.7!C8:I8)} -> 407.4577 | BJ19: =$BI19+BM19 -> 407.4577 | BK19: =$BI19+BN19 -> 407.4577 | BP19: {=TRANSPOSE(OBR_MAR24_TA.7!C32:I32)} -> 89.791733 | BW19: =100*(CA19/CA$20) -> 93.847589 | BX19: =100*(CB19/CB$20) -> 93.847589 | BY19: =100*(CC19/CC$20) -> 93.847589 | CA19: =OBR_MAR24_1.2!X125 -> 112.52776 | CB19: =$CA19 -> 112.52776 | CC19: =$CA19 -> 112.52776 | CE19: 67958.25 | CF19: =$CE19 -> 67958.25 | CG19: =$CE19 -> 67958.25 | CI19: 2022-23 | CJ19: 6388.0887 | CK19: 1407.7475 | CL19: =100*(CJ19/CJ$20) -> 103.59736 | CM19: =100*(CK19/CK$20) -> 101.01867 | CO19: ="20"&LEFT(CP19,2) -> 2022 | CP19: =RIGHT(CI19,5) -> 22-23 | CQ19: =100*(DataScen!CG49/DataScen!CL49) -> 41.129001 | CR19: =100*(DataScen!CY49/DataScen!DD49) -> 41.129001 | CS19: =100*(DataScen!DQ49/DataScen!DV49) -> 41.129001 | CU19: ="20"&LEFT(CV19,2) -> 2022 | CV19: =RIGHT(CI19,5) -> 22-23 | CW19: =100*(DataScen!CH49/DataScen!CL49) -> 1.797143 | CX19: =100*(DataScen!CZ49/DataScen!DD49) -> 1.797143 | CY19: =100*(DataScen!DR49/DataScen!DV49) -> 1.797143 | DA19: ="20"&LEFT(DB19,2) -> 2022 | DB19: =RIGHT(CI19,5) -> 22-23 | DC19: =100*(DataScen!CJ49/DataScen!CL49) -> 40.286682 | DD19: =100*(DataScen!DB49/DataScen!DD49) -> 40.286682 | DE19: =100*(DataScen!DT49/DataScen!DV49) -> 40.286682
AG20: ="20"&LEFT(AH20,2) -> 2023 | AH20: =RIGHT(CI20,5) -> 23-24 | AI20: =100*(AS20/AS$20) -> 100 | AJ20: =100*(AT20/AT$20) -> 100 | AK20: =100*(AU20/AU$20) -> 100 | AL20: 100 | AN20: =100*(AW20/AW$20) -> 100 | AO20: =100*(AX20/AX$20) -> 100 | AP20: =100*(AY20/AY$20) -> 100 | AQ20: 100 | AS20: =100*(BA20/BW20) -> 6.1662659 | AT20: =100*(BB20/BX20) -> 6.1662659 | AU20: =100*(BC20/BY20) -> 6.1662659 | AW20: =100*(BE20/BW20) -> 1.3935518 | AX20: =100*(BF20/BX20) -> 1.3935518 | AY20: =100*(BG20/BY20) -> 1.3935518 | BA20: =BI20/(CE20/1000) -> 6.1662659 | BB20: =BJ20/(CF20/1000) -> 6.1662659 | BC20: =BK20/(CG20/1000) -> 6.1662659 | BE20: =BP20/(CE20/1000) -> 1.3935518 | BF20: =BQ20/(CF20/1000) -> 1.3935518 | BG20: =BR20/(CG20/1000) -> 1.3935518 | BI20: 422.94449 | BJ20: =$BI20+BM20 -> 422.94449 | BK20: =$BI20+BN20 -> 422.94449 | BM20: {=TRANSPOSE('[2]Top level assumptions'!$B$19:$G$19)/1000} -> 0 | BN20: {=TRANSPOSE('[3]Top level assumptions'!$B$17:$G$17)/1000} -> 0 | BP20: 95.583786 | BQ20: =$BP20+BT20 -> 95.583786 | BR20: =$BP20+BU20 -> 95.583786 | BT20: 0 | BU20: {=TRANSPOSE('[3]Top level assumptions'!$B$19:$G$19)/1000} -> 0 | BW20: =100*(CA20/CA$20) -> 100 | BX20: =100*(CB20/CB$20) -> 100 | BY20: =100*(CC20/CC$20) -> 100 | CA20: =OBR_MAR24_1.2!X126 -> 119.9048 | CB20: =$CA20 -> 119.9048 | CC20: =$CA20 -> 119.9048 | CE20: 68590.05 | CF20: =$CE20 -> 68590.05 | CG20: =$CE20 -> 68590.05 | CI20: 2023-24 | CJ20: 6166.2659 | CK20: 1393.5518 | CL20: =100*(CJ20/CJ$20) -> 100 | CM20: =100*(CK20/CK$20) -> 100 | CO20: ="20"&LEFT(CP20,2) -> 2023 | CP20: =RIGHT(CI20,5) -> 23-24 | CQ20: =100*(DataScen!CG50/DataScen!CL50) -> 39.823317 | CR20: =100*(DataScen!CY50/DataScen!DD50) -> 39.823317 | CS20: =100*(DataScen!DQ50/DataScen!DV50) -> 39.823317 | CU20: ="20"&LEFT(CV20,2) -> 2023 | CV20: =RIGHT(CI20,5) -> 23-24 | CW20: =100*(DataScen!CH50/DataScen!CL50) -> 2.5808861 | CX20: =100*(DataScen!CZ50/DataScen!DD50) -> 2.5808861 | CY20: =100*(DataScen!DR50/DataScen!DV50) -> 2.5808861 | DA20: ="20"&LEFT(DB20,2) -> 2023 | DB20: =RIGHT(CI20,5) -> 23-24 | DC20: =100*(DataScen!CJ50/DataScen!CL50) -> 40.332967 | DD20: =100*(DataScen!DB50/DataScen!DD50) -> 40.332967 | DE20: =100*(DataScen!DT50/DataScen!DV50) -> 40.332967
AG21: ="20"&LEFT(AH21,2) -> 2024 | AH21: =RIGHT(CI21,5) -> 24-25 | AI21: =100*(AS21/AS$20) -> 100.11566 | AJ21: =100*(AT21/AT$20) -> 100.30812 | AK21: =100*(AU21/AU$20) -> 100.39697 | AL21: 100 | AN21: =100*(AW21/AW$20) -> 102.15208 | AO21: =100*(AX21/AX$20) -> 102.15208 | AP21: =100*(AY21/AY$20) -> 106.99195 | AQ21: 100 | AS21: =100*(BA21/BW21) -> 6.173398 | AT21: =100*(BB21/BX21) -> 6.1852657 | AU21: =100*(BC21/BY21) -> 6.1907439 | AW21: =100*(BE21/BW21) -> 1.4235422 | AX21: =100*(BF21/BX21) -> 1.4235422 | AY21: =100*(BG21/BY21) -> 1.4909882 | BA21: =BI21/(CE21/1000) -> 6.2223006 | BB21: =BJ21/(CF21/1000) -> 6.2342623 | BC21: =BK21/(CG21/1000) -> 6.2397839 | BE21: =BP21/(CE21/1000) -> 1.4348188 | BF21: =BQ21/(CF21/1000) -> 1.4348188 | BG21: =BR21/(CG21/1000) -> 1.5027991 | BI21: 430.19538 | BJ21: =$BI21+BM21 -> 431.02238 | BK21: =$BI21+BN21 -> 431.40413 | BM21: 0.827 | BN21: 1.20875 | BP21: 99.20003 | BQ21: =$BP21+BT21 -> 99.20003 | BR21: =$BP21+BU21 -> 103.90003 | BT21: 0 | BU21: 4.7 | BW21: =100*(CA21/CA$20) -> 100.79215 | BX21: =100*(CB21/CB$20) -> 100.79215 | BY21: =100*(CC21/CC$20) -> 100.79215 | CA21: =OBR_MAR24_1.2!X127 -> 120.85462 | CB21: =$CA21 -> 120.85462 | CC21: =$CA21 -> 120.85462 | CE21: 69137.672 | CF21: =$CE21 -> 69137.672 | CG21: =$CE21 -> 69137.672 | CI21: 2024-25 | CJ21: 6172.6818 | CK21: 1423.377 | CL21: =100*(CJ21/CJ$20) -> 100.10405 | CM21: =100*(CK21/CK$20) -> 102.14023 | CO21: ="20"&LEFT(CP21,2) -> 2024 | CP21: =RIGHT(CI21,5) -> 24-25 | CQ21: =100*(DataScen!CG51/DataScen!CL51) -> 39.455399 | CR21: =100*(DataScen!CY51/DataScen!DD51) -> 39.455696 | CS21: =100*(DataScen!DQ51/DataScen!DV51) -> 39.455681 | CU21: ="20"&LEFT(CV21,2) -> 2024 | CV21: =RIGHT(CI21,5) -> 24-25 | CW21: =100*(DataScen!CH51/DataScen!CL51) -> 2.3916702 | CX21: =100*(DataScen!CZ51/DataScen!DD51) -> 2.3916729 | CY21: =100*(DataScen!DR51/DataScen!DV51) -> 2.3916733 | DA21: ="20"&LEFT(DB21,2) -> 2024 | DB21: =RIGHT(CI21,5) -> 24-25 | DC21: =100*(DataScen!CJ51/DataScen!CL51) -> 40.918356 | DD21: =100*(DataScen!DB51/DataScen!DD51) -> 40.918382 | DE21: =100*(DataScen!DT51/DataScen!DV51) -> 40.918378
AG22: ="20"&LEFT(AH22,2) -> 2025 | AH22: =RIGHT(CI22,5) -> 25-26 | AI22: =100*(AS22/AS$20) -> 100.47952 | AJ22: =100*(AT22/AT$20) -> 100.62452 | AK22: =100*(AU22/AU$20) -> 101.03154 | AL22: 100 | AN22: =100*(AW22/AW$20) -> 99.081719 | AO22: =100*(AX22/AX$20) -> 99.081719 | AP22: =100*(AY22/AY$20) -> 103.83055 | AQ22: 100 | AS22: =100*(BA22/BW22) -> 6.1958343 | AT22: =100*(BB22/BX22) -> 6.2047753 | AU22: =100*(BC22/BY22) -> 6.2298734 | AW22: =100*(BE22/BW22) -> 1.380755 | AX22: =100*(BF22/BX22) -> 1.380755 | AY22: =100*(BG22/BY22) -> 1.4469325 | BA22: =BI22/(CE22/1000) -> 6.3291723 | BB22: =BJ22/(CF22/1000) -> 6.3383057 | BC22: =BK22/(CG22/1000) -> 6.363944 | BE22: =BP22/(CE22/1000) -> 1.4104697 | BF22: =BQ22/(CF22/1000) -> 1.4104697 | BG22: =BR22/(CG22/1000) -> 1.4780713 | BI22: 440.03535 | BJ22: =$BI22+BM22 -> 440.67035 | BK22: =$BI22+BN22 -> 442.45285 | BM22: 0.635 | BN22: 2.4175 | BP22: 98.062828 | BQ22: =$BP22+BT22 -> 98.062828 | BR22: =$BP22+BU22 -> 102.76283 | BT22: 0 | BU22: 4.7 | BW22: =100*(CA22/CA$20) -> 102.15206 | BX22: =100*(CB22/CB$20) -> 102.15206 | BY22: =100*(CC22/CC$20) -> 102.15206 | CA22: =OBR_MAR24_1.2!X128 -> 122.48522 | CB22: =$CA22 -> 122.48522 | CC22: =$CA22 -> 122.48522 | CE22: 69524.944 | CF22: =$CE22 -> 69524.944 | CG22: =$CE22 -> 69524.944 | CI22: 2025-26 | CJ22: 6195.1797 | CK22: 1380.6092 | CL22: =100*(CJ22/CJ$20) -> 100.4689 | CM22: =100*(CK22/CK$20) -> 99.07125 | CO22: ="20"&LEFT(CP22,2) -> 2025 | CP22: =RIGHT(CI22,5) -> 25-26 | CQ22: =100*(DataScen!CG52/DataScen!CL52) -> 39.315972 | CR22: =100*(DataScen!CY52/DataScen!DD52) -> 39.190745 | CS22: =100*(DataScen!DQ52/DataScen!DV52) -> 39.25918 | CU22: ="20"&LEFT(CV22,2) -> 2025 | CV22: =RIGHT(CI22,5) -> 25-26 | CW22: =100*(DataScen!CH52/DataScen!CL52) -> 2.1220676 | CX22: =100*(DataScen!CZ52/DataScen!DD52) -> 2.1212355 | CY22: =100*(DataScen!DR52/DataScen!DV52) -> 2.2813384 | DA22: ="20"&LEFT(DB22,2) -> 2025 | DB22: =RIGHT(CI22,5) -> 25-26 | DC22: =100*(DataScen!CJ52/DataScen!CL52) -> 40.84992 | DD22: =100*(DataScen!DB52/DataScen!DD52) -> 40.659409 | DE22: =100*(DataScen!DT52/DataScen!DV52) -> 40.901883
AG23: ="20"&LEFT(AH23,2) -> 2026 | AH23: =RIGHT(CI23,5) -> 26-27 | AI23: =100*(AS23/AS$20) -> 100.99373 | AJ23: =100*(AT23/AT$20) -> 100.87828 | AK23: =100*(AU23/AU$20) -> 101.80347 | AL23: 100 | AN23: =100*(AW23/AW$20) -> 97.174292 | AO23: =100*(AX23/AX$20) -> 97.174292 | AP23: =100*(AY23/AY$20) -> 101.8182 | AQ23: 100 | AS23: =100*(BA23/BW23) -> 6.2275418 | AT23: =100*(BB23/BX23) -> 6.2204231 | AU23: =100*(BC23/BY23) -> 6.2774723 | AW23: =100*(BE23/BW23) -> 1.3541741 | AX23: =100*(BF23/BX23) -> 1.3541741 | AY23: =100*(BG23/BY23) -> 1.4188893 | BA23: =BI23/(CE23/1000) -> 6.472483 | BB23: =BJ23/(CF23/1000) -> 6.4650843 | BC23: =BK23/(CG23/1000) -> 6.5243774 | BE23: =BP23/(CE23/1000) -> 1.4074363 | BF23: =BQ23/(CF23/1000) -> 1.4074363 | BG23: =BR23/(CG23/1000) -> 1.4746969 | BI23: 452.28089 | BJ23: =$BI23+BM23 -> 451.76389 | BK23: =$BI23+BN23 -> 455.90714 | BM23: -0.517 | BN23: 3.62625 | BP23: 98.348124 | BQ23: =$BP23+BT23 -> 98.348124 | BR23: =$BP23+BU23 -> 103.04812 | BT23: 0 | BU23: 4.7 | BW23: =100*(CA23/CA$20) -> 103.93319 | BX23: =100*(CB23/CB$20) -> 103.93319 | BY23: =100*(CC23/CC$20) -> 103.93319 | CA23: =OBR_MAR24_1.2!X129 -> 124.62088 | CB23: =$CA23 -> 124.62088 | CC23: =$CA23 -> 124.62088 | CE23: 69877.494 | CF23: =$CE23 -> 69877.494 | CG23: =$CE23 -> 69877.494 | CI23: 2026-27 | CJ23: 6226.8892 | CK23: 1354.0321 | CL23: =100*(CJ23/CJ$20) -> 100.98314 | CM23: =100*(CK23/CK$20) -> 97.164108 | CO23: ="20"&LEFT(CP23,2) -> 2026 | CP23: =RIGHT(CI23,5) -> 26-27 | CQ23: =100*(DataScen!CG53/DataScen!CL53) -> 39.196978 | CR23: =100*(DataScen!CY53/DataScen!DD53) -> 39.049251 | CS23: =100*(DataScen!DQ53/DataScen!DV53) -> 39.181183 | CU23: ="20"&LEFT(CV23,2) -> 2026 | CV23: =RIGHT(CI23,5) -> 26-27 | CW23: =100*(DataScen!CH53/DataScen!CL53) -> 1.9838395 | CX23: =100*(DataScen!CZ53/DataScen!DD53) -> 1.9865244 | CY23: =100*(DataScen!DR53/DataScen!DV53) -> 2.1387945 | DA23: ="20"&LEFT(DB23,2) -> 2026 | DB23: =RIGHT(CI23,5) -> 26-27 | DC23: =100*(DataScen!CJ53/DataScen!CL53) -> 40.961169 | DD23: =100*(DataScen!DB53/DataScen!DD53) -> 40.713521 | DE23: =100*(DataScen!DT53/DataScen!DV53) -> 41.097252
AG24: ="20"&LEFT(AH24,2) -> 2027 | AH24: =RIGHT(CI24,5) -> 27-28 | AI24: =100*(AS24/AS$20) -> 101.5171 | AJ24: =100*(AT24/AT$20) -> 101.43315 | AK24: =100*(AU24/AU$20) -> 102.57139 | AL24: 100 | AN24: =100*(AW24/AW$20) -> 94.884158 | AO24: =100*(AX24/AX$20) -> 94.884158 | AP24: =100*(AY24/AY$20) -> 99.419005 | AQ24: 100 | AS24: =100*(BA24/BW24) -> 6.2598142 | AT24: =100*(BB24/BX24) -> 6.2546376 | AU24: =100*(BC24/BY24) -> 6.3248248 | AW24: =100*(BE24/BW24) -> 1.3222599 | AX24: =100*(BF24/BX24) -> 1.3222599 | AY24: =100*(BG24/BY24) -> 1.3854553 | BA24: =BI24/(CE24/1000) -> 6.6278684 | BB24: =BJ24/(CF24/1000) -> 6.6223874 | BC24: =BK24/(CG24/1000) -> 6.6967014 | BE24: =BP24/(CE24/1000) -> 1.4000039 | BF24: =BQ24/(CF24/1000) -> 1.4000039 | BG24: =BR24/(CG24/1000) -> 1.466915 | BI24: 465.55777 | BJ24: =$BI24+BM24 -> 465.17277 | BK24: =$BI24+BN24 -> 470.39277 | BM24: -0.385 | BN24: 4.835 | BP24: 98.339717 | BQ24: =$BP24+BT24 -> 98.339717 | BR24: =$BP24+BU24 -> 103.03972 | BT24: 0 | BU24: 4.7 | BW24: =100*(CA24/CA$20) -> 105.87963 | BX24: =100*(CB24/CB$20) -> 105.87963 | BY24: =100*(CC24/CC$20) -> 105.87963 | CA24: =OBR_MAR24_1.2!X130 -> 126.95476 | CB24: =$CA24 -> 126.95476 | CC24: =$CA24 -> 126.95476 | CE24: 70242.459 | CF24: =$CE24 -> 70242.459 | CG24: =$CE24 -> 70242.459 | CI24: 2027-28 | CJ24: 6259.1505 | CK24: 1322.1197 | CL24: =100*(CJ24/CJ$20) -> 101.50633 | CM24: =100*(CK24/CK$20) -> 94.874097 | CO24: ="20"&LEFT(CP24,2) -> 2027 | CP24: =RIGHT(CI24,5) -> 27-28 | CQ24: =100*(DataScen!CG54/DataScen!CL54) -> 38.85815 | CR24: =100*(DataScen!CY54/DataScen!DD54) -> 38.580237 | CS24: =100*(DataScen!DQ54/DataScen!DV54) -> 38.900601 | CU24: ="20"&LEFT(CV24,2) -> 2027 | CV24: =RIGHT(CI24,5) -> 27-28 | CW24: =100*(DataScen!CH54/DataScen!CL54) -> 1.8228113 | CX24: =100*(DataScen!CZ54/DataScen!DD54) -> 1.8246417 | CY24: =100*(DataScen!DR54/DataScen!DV54) -> 1.9730193 | DA24: ="20"&LEFT(DB24,2) -> 2027 | DB24: =RIGHT(CI24,5) -> 27-28 | DC24: =100*(DataScen!CJ54/DataScen!CL54) -> 41.142867 | DD24: =100*(DataScen!DB54/DataScen!DD54) -> 40.738068 | DE24: =100*(DataScen!DT54/DataScen!DV54) -> 41.319094
AG25: ="20"&LEFT(AH25,2) -> 2028 | AH25: =RIGHT(CI25,5) -> 28-29 | AI25: =100*(AS25/AS$20) -> 101.97236 | AJ25: =100*(AT25/AT$20) -> 102.07983 | AK25: =100*(AU25/AU$20) -> 103.34431 | AL25: 100 | AN25: =100*(AW25/AW$20) -> 91.679851 | AO25: =100*(AX25/AX$20) -> 91.679851 | AP25: =100*(AY25/AY$20) -> 96.105734 | AQ25: 100 | AS25: =100*(BA25/BW25) -> 6.2878867 | AT25: =100*(BB25/BX25) -> 6.2945137 | AU25: =100*(BC25/BY25) -> 6.3724847 | AW25: =100*(BE25/BW25) -> 1.2776062 | AX25: =100*(BF25/BX25) -> 1.2776062 | AY25: =100*(BG25/BY25) -> 1.3392832 | BA25: =BI25/(CE25/1000) -> 6.7862634 | BB25: =BJ25/(CF25/1000) -> 6.7934156 | BC25: =BK25/(CG25/1000) -> 6.8775666 | BE25: =BP25/(CE25/1000) -> 1.378869 | BF25: =BQ25/(CF25/1000) -> 1.378869 | BG25: =BR25/(CG25/1000) -> 1.4454345 | BI25: 479.15889 | BJ25: =$BI25+BM25 -> 479.66389 | BK25: =$BI25+BN25 -> 485.60556 | BM25: 0.505 | BN25: 6.4466667 | BP25: 97.358047 | BQ25: =$BP25+BT25 -> 97.358047 | BR25: =$BP25+BU25 -> 102.05805 | BT25: 0 | BU25: 4.7 | BW25: =100*(CA25/CA$20) -> 107.92598 | BX25: =100*(CB25/CB$20) -> 107.92598 | BY25: =100*(CC25/CC$20) -> 107.92598 | CA25: =OBR_MAR24_1.2!X131 -> 129.40843 | CB25: =$CA25 -> 129.40843 | CC25: =$CA25 -> 129.40843 | CE25: 70607.176 | CF25: =$CE25 -> 70607.176 | CG25: =$CE25 -> 70607.176 | CI25: 2028-29 | CJ25: 6287.2179 | CK25: 1277.4703 | CL25: =100*(CJ25/CJ$20) -> 101.96151 | CM25: =100*(CK25/CK$20) -> 91.6701 | CO25: ="20"&LEFT(CP25,2) -> 2028 | CP25: =RIGHT(CI25,5) -> 28-29 | CQ25: =100*(DataScen!CG55/DataScen!CL55) -> 38.693797 | CR25: =100*(DataScen!CY55/DataScen!DD55) -> 38.404761 | CS25: =100*(DataScen!DQ55/DataScen!DV55) -> 38.76017 | CU25: ="20"&LEFT(CV25,2) -> 2028 | CV25: =RIGHT(CI25,5) -> 28-29 | CW25: =100*(DataScen!CH55/DataScen!CL55) -> 1.6559616 | CX25: =100*(DataScen!CZ55/DataScen!DD55) -> 1.6580935 | CY25: =100*(DataScen!DR55/DataScen!DV55) -> 1.800856 | DA25: ="20"&LEFT(DB25,2) -> 2028 | DB25: =RIGHT(CI25,5) -> 28-29 | DC25: =100*(DataScen!CJ55/DataScen!CL55) -> 41.239421 | DD25: =100*(DataScen!DB55/DataScen!DD55) -> 40.835838 | DE25: =100*(DataScen!DT55/DataScen!DV55) -> 41.451861
AI30: =AI19-EU19 -> 103.6084
AI31: =AI20-EU20 -> 100
AI32: =AI21-EU21 -> 100.11566
AI33: =AI22-EU22 -> 100.47952
AI34: =AI23-EU23 -> 100.99373
AI35: =AI24-EU24 -> 101.5171
AI36: =AI25-EU25 -> 101.97236

Sheet DataA
B1: =GMWA!$CR$2 -> JUN011A.db | C1: =$B$1 -> JUN011A.db | D1: =$B$1 -> JUN011A.db | E1: =$B$1 -> JUN011A.db | F1: =$B$1 -> JUN011A.db | G1: =$B$1 -> JUN011A.db | H1: =$B$1 -> JUN011A.db | I1: =$B$1 -> JUN011A.db | J1: =$B$1 -> JUN011A.db | ... BI1: =$B$1 -> JUN011A.db
B2: UK | C2: US | D2: Japan | E2: Canada | F2: Australia | G2: Denmark | H2: Sweden | I2: Switzerland | J2: S Korea | K2: Germany | L2: France | M2: Italy | N2: Spain | O2: Netherlands | P2: Belgium | Q2: Austria | R2: Finland | S2: Ireland | T2: Greece | U2: Portugal | V2: UK | W2: US | X2: Japan | Y2: Canada | Z2: Australia | AA2: Denmark | AB2: Sweden | AC2: Switzerland | AD2: S Korea | AE2: Germany | AF2: France | AG2: Italy | AH2: Spain | AI2: Netherlands | AJ2: Belgium | AK2: Austria | AL2: Finland | AM2: Ireland | AN2: Greece | AO2: Portugal | AP2: UK | AQ2: US | AR2: Japan | AS2: Canada | AT2: Australia | AU2: Denmark | AV2: Sweden | AW2: Switzerland | AX2: S Korea | AY2: Germany | AZ2: France | BA2: Italy | BB2: Spain | BC2: Netherlands | BD2: Belgium | BE2: Austria | BF2: Finland | BG2: Ireland | BH2: Greece | BI2: Portugal | BK2: =B2 -> UK | BL2: =C2 -> US | BM2: =D2 -> Japan | BN2: =E2 -> Canada | BO2: =F2 -> Australia | BP2: =G2 -> Denmark | BQ2: =H2 -> Sweden | BR2: =I2 -> Switzerland | ... CD2: =U2 -> Portugal
B3: GDIP | C3: GDIP | D3: GDIP | E3: GDIP | F3: GDIP | G3: GDIP | H3: GDIP | I3: GDIP | J3: GDIP | K3: GDIP | L3: GDIP | M3: GDIP | N3: GDIP | O3: GDIP | P3: GDIP | Q3: GDIP | R3: GDIP | S3: GDIP | T3: GDIP | U3: GDIP | V3: GGDBT | W3: GGDBT | X3: GGDBT | Y3: GGDBT | Z3: GGDBT | AA3: GGDBT | AB3: GGDBT | AC3: GGDBT | AD3: GGDBT | AE3: GGDBT | AF3: GGDBT | AG3: GGDBT | AH3: GGDBT | AI3: GGDBT | AJ3: GGDBT | AK3: GGDBT | AL3: GGDBT | AM3: GGDBT | AN3: GGDBT | AO3: GGDBT | AP3: GDP! | AQ3: GDP! | AR3: GDP! | AS3: GDP! | AT3: GDP! | AU3: GDP! | AV3: GDP! | AW3: GDP! | AX3: GDP! | AY3: GDP! | AZ3: GDP! | BA3: GDP! | BB3: GDP! | BC3: GDP! | BD3: GDP! | BE3: GDP! | BF3: GDP! | BG3: GDP! | BH3: GDP! | BI3: GDP! | BK3: GDIP/GGDBT | BL3: GDIP/GGDBT | BM3: GDIP/GGDBT | BN3: GDIP/GGDBT | BO3: GDIP/GGDBT | BP3: GDIP/GGDBT | BQ3: GDIP/GGDBT | BR3: GDIP/GGDBT | BS3: GDIP/GGDBT | BT3: GDIP/GGDBT | BU3: GDIP/GGDBT | BV3: GDIP/GGDBT | BW3: GDIP/GGDBT | BX3: GDIP/GGDBT | BY3: GDIP/GGDBT | BZ3: GDIP/GGDBT | CA3: GDIP/GGDBT | CB3: GDIP/GGDBT | CC3: GDIP/GGDBT | CD3: GDIP/GGDBT
B4: GBR | C4: USA | D4: JPN | E4: CAN | F4: AUS | G4: DNK | H4: SWE | I4: CHE | J4: KOR | K4: DEU | L4: FRA | M4: ITA | N4: ESP | O4: NLD | P4: BEL | Q4: AUT | R4: FIN | S4: IRL | T4: GRC | U4: PRT | V4: GBR | W4: USA | X4: JPN | Y4: CAN | Z4: AUS | AA4: DNK | AB4: SWE | AC4: CHE | AD4: KOR | AE4: DEU | AF4: FRA | AG4: ITA | AH4: ESP | AI4: NLD | AJ4: BEL | AK4: AUT | AL4: FIN | AM4: IRL | AN4: GRC | AO4: PRT | AP4: GBR | AQ4: USA | AR4: JPN | AS4: CAN | AT4: AUS | AU4: DNK | AV4: SWE | AW4: CHE | AX4: KOR | AY4: DEU | AZ4: FRA | BA4: ITA | BB4: ESP | BC4: NLD | BD4: BEL | BE4: AUT | BF4: FIN | BG4: IRL | BH4: GRC | BI4: PRT | BK4: =B4 -> GBR | BL4: =C4 -> USA | BM4: =D4 -> JPN | BN4: =E4 -> CAN | BO4: =F4 -> AUS | BP4: =G4 -> DNK | BQ4: =H4 -> SWE | BR4: =I4 -> CHE | ... CD4: =U4 -> PRT
B5: L | C5: L | D5: L | E5: L | F5: L | G5: L | H5: L | I5: L | J5: L | K5: L | L5: L | M5: L | N5: L | O5: L | P5: L | Q5: L | R5: L | S5: L | T5: L | U5: L | V5: L | W5: L | X5: L | Y5: L | Z5: L | AA5: L | AB5: L | AC5: L | AD5: L | AE5: L | AF5: L | AG5: L | AH5: L | AI5: L | AJ5: L | AK5: L | AL5: L | AM5: L | AN5: L | AO5: L | AP5: L | AQ5: L | AR5: L | AS5: L | AT5: L | AU5: L | AV5: L | AW5: L | AX5: L | AY5: L | AZ5: L | BA5: L | BB5: L | BC5: L | BD5: L | BE5: L | BF5: L | BG5: L | BH5: L | BI5: L
A6: =A84+5 -> 2055 | B6: {=_xlfn.CONCAT(INDEX(GMWA!$A$2:$CR$600,MATCH(1,(GMWA!$CQ$2:$CQ$600=B$3)*(GMWA!$CP$2:$CP$600=B$4)*(GMWA!$CR$2:$CR$600=B$1),0),$A6-1966),"0",(INDEX(GMWA!$A$2:$LR$600,MATCH(1,(GMWA!$CQ$2:$CQ$600=B$3)*(GMWA!$CP$2:$CP$600=B$4)*(GMWA!$CR$2:$CR$600=B$1),0),$A6-1965)))} -> 202401 | C6: {=_xlfn.CONCAT(INDEX(GMWA!$A$2:$CR$600,MATCH(1,(GMWA!$CQ$2:$CQ$600=C$3)*(GMWA!$CP$2:$CP$600=C$4)*(GMWA!$CR$2:$CR$600=C$1),0),$A6-1966),"0",(INDEX(GMWA!$A$2:$LR$600,MATCH(1,(GMWA!$CQ$2:$CQ$600=C$3)*(GMWA!$CP$2:$CP$600=C$4)*(GMWA!$CR$2:$CR$600=C$1),0),$A6-1965)))} -> 202401 | D6: {=_xlfn.CONCAT(INDEX(GMWA!$A$2:$CR$600,MATCH(1,(GMWA!$CQ$2:$CQ$600=D$3)*(GMWA!$CP$2:$CP$600=D$4)*(GMWA!$CR$2:$CR$600=D$1),0),$A6-1966),"0",(INDEX(GMWA!$A$2:$LR$600,MATCH(1,(GMWA!$CQ$2:$CQ$600=D$3)*(GMWA!$CP$2:$CP$600=D$4)*(GMWA!$CR$2:$CR$600=D$1),0),$A6-1965)))} -> 202301 | E6: {=_xlfn.CONCAT(INDEX(GMWA!$A$2:$CR$600,MATCH(1,(GMWA!$CQ$2:$CQ$600=E$3)*(GMWA!$CP$2:$CP$600=E$4)*(GMWA!$CR$2:$CR$600=E$1),0),$A6-1966),"0",(INDEX(GMWA!$A$2:$LR$600,MATCH(1,(GMWA!$CQ$2:$CQ$600=E$3)*(GMWA!$CP$2:$CP$600=E$4)*(GMWA!$CR$2:$CR$600=E$1),0),$A6-1965)))} -> 202401 | F6: {=_xlfn.CONCAT(INDEX(GMWA!$A$2:$CR$600,MATCH(1,(GMWA!$CQ$2:$CQ$600=F$3)*(GMWA!$CP$2:$CP$600=F$4)*(GMWA!$CR$2:$CR$600=F$1),0),$A6-1966),"0",(INDEX(GMWA!$A$2:$LR$600,MATCH(1,(GMWA!$CQ$2:$CQ$600=F$3)*(GMWA!$CP$2:$CP$600=F$4)*(GMWA!$CR$2:$CR$600=F$1),0),$A6-1965)))} -> 202401 | G6: {=_xlfn.CONCAT(INDEX(GMWA!$A$2:$CR$600,MATCH(1,(GMWA!$CQ$2:$CQ$600=G$3)*(GMWA!$CP$2:$CP$600=G$4)*(GMWA!$CR$2:$CR$600=G$1),0),$A6-1966),"0",(INDEX(GMWA!$A$2:$LR$600,MATCH(1,(GMWA!$CQ$2:$CQ$600=G$3)*(GMWA!$CP$2:$CP$600=G$4)*(GMWA!$CR$2:$CR$600=G$1),0),$A6-1965)))} -> 202304 | H6: {=_xlfn.CONCAT(INDEX(GMWA!$A$2:$CR$600,MATCH(1,(GMWA!$CQ$2:$CQ$600=H$3)*(GMWA!$CP$2:$CP$600=H$4)*(GMWA!$CR$2:$CR$600=H$1),0),$A6-1966),"0",(INDEX(GMWA!$A$2:$LR$600,MATCH(1,(GMWA!$CQ$2:$CQ$600=H$3)*(GMWA!$CP$2:$CP$600=H$4)*(GMWA!$CR$2:$CR$600=H$1),0),$A6-1965)))} -> 202304 | I6: {=_xlfn.CONCAT(INDEX(GMWA!$A$2:$CR$600,MATCH(1,(GMWA!$CQ$2:$CQ$600=I$3)*(GMWA!$CP$2:$CP$600=I$4)*(GMWA!$CR$2:$CR$600=I$1),0),$A6-1966),"0",(INDEX(GMWA!$A$2:$LR$600,MATCH(1,(GMWA!$CQ$2:$CQ$600=I$3)*(GMWA!$CP$2:$CP$600=I$4)*(GMWA!$CR$2:$CR$600=I$1),0),$A6-1965)))} -> 202004 | ... BI6: {=_xlfn.CONCAT(INDEX(GMWA!$A$2:$CR$600,MATCH(1,(GMWA!$CQ$2:$CQ$600=BI$3)*(GMWA!$CP$2:$CP$600=BI$4)*(GMWA!$CR$2:$CR$600=BI$1),0),$A6-1966),"0",(INDEX(GMWA!$A$2:$LR$600,MATCH(1,(GMWA!$CQ$2:$CQ$600=BI$3)*(GMWA!$CP$2:$CP$600=BI$4)*(GMWA!$CR$2:$CR$600=BI$1),0),$A6-1965)))} -> 202401
A7: 1973 | B7: {=INDEX(GMWA!$A$2:$CR$600,MATCH(1,(GMWA!$CQ$2:$CQ$600=B$3)*(GMWA!$CP$2:$CP$600=B$4)*(GMWA!$CR$2:$CR$600=B$1),0),$A7-1966)} -> 3087 | C7: {=INDEX(GMWA!$A$2:$CR$600,MATCH(1,(GMWA!$CQ$2:$CQ$600=C$3)*(GMWA!$CP$2:$CP$600=C$4)*(GMWA!$CR$2:$CR$600=C$1),0),$A7-1966)} -> 61.95 | D7: {=INDEX(GMWA!$A$2:$CR$600,MATCH(1,(GMWA!$CQ$2:$CQ$600=D$3)*(GMWA!$CP$2:$CP$600=D$4)*(GMWA!$CR$2:$CR$600=D$1),0),$A7-1966)} -> 922.9716 | E7: {=INDEX(GMWA!$A$2:$CR$600,MATCH(1,(GMWA!$CQ$2:$CQ$600=E$3)*(GMWA!$CP$2:$CP$600=E$4)*(GMWA!$CR$2:$CR$600=E$1),0),$A7-1966)} -> 4910 | F7: {=INDEX(GMWA!$A$2:$CR$600,MATCH(1,(GMWA!$CQ$2:$CQ$600=F$3)*(GMWA!$CP$2:$CP$600=F$4)*(GMWA!$CR$2:$CR$600=F$1),0),$A7-1966)} -> 738.1701 | G7: {=INDEX(GMWA!$A$2:$CR$600,MATCH(1,(GMWA!$CQ$2:$CQ$600=G$3)*(GMWA!$CP$2:$CP$600=G$4)*(GMWA!$CR$2:$CR$600=G$1),0),$A7-1966)} -> 2.120414 | H7: {=INDEX(GMWA!$A$2:$CR$600,MATCH(1,(GMWA!$CQ$2:$CQ$600=H$3)*(GMWA!$CP$2:$CP$600=H$4)*(GMWA!$CR$2:$CR$600=H$1),0),$A7-1966)} -> 3553.037 | I7: {=INDEX(GMWA!$A$2:$CR$600,MATCH(1,(GMWA!$CQ$2:$CQ$600=I$3)*(GMWA!$CP$2:$CP$600=I$4)*(GMWA!$CR$2:$CR$600=I$1),0),$A7-1966)} -> 1.915308 | ... BI7: {=INDEX(GMWA!$A$2:$CR$600,MATCH(1,(GMWA!$CQ$2:$CQ$600=BI$3)*(GMWA!$CP$2:$CP$600=BI$4)*(GMWA!$CR$2:$CR$600=BI$1),0),$A7-1966)} -> 23.33717 | BK7: =100*(B7/V7) -> 8.5822878 | BL7: =100*(C7/W7) -> 5.4078119 | BM7: =100*(D7/X7) -> 5.1939876 | BN7: =100*(E7/Y7) -> 7.5628052 | BO7: =100*(F7/Z7) -> 73817010 | BP7: =100*(G7/AA7) -> 1.269709 | BQ7: =100*(H7/AB7) -> 5.1925969 | BR7: =100*(I7/AC7) -> 1.8912737 | ... CD7: =100*(U7/AO7) -> 1.3545299
A8: =+A7+1 -> 1974 | B8: {=INDEX(GMWA!$A$2:$CR$600,MATCH(1,(GMWA!$CQ$2:$CQ$600=B$3)*(GMWA!$CP$2:$CP$600=B$4)*(GMWA!$CR$2:$CR$600=B$1),0),$A8-1966)} -> 4131 | C8: {=INDEX(GMWA!$A$2:$CR$600,MATCH(1,(GMWA!$CQ$2:$CQ$600=C$3)*(GMWA!$CP$2:$CP$600=C$4)*(GMWA!$CR$2:$CR$600=C$1),0),$A8-1966)} -> 69.55 | D8: {=INDEX(GMWA!$A$2:$CR$600,MATCH(1,(GMWA!$CQ$2:$CQ$600=D$3)*(GMWA!$CP$2:$CP$600=D$4)*(GMWA!$CR$2:$CR$600=D$1),0),$A8-1966)} -> 1196.62 | E8: {=INDEX(GMWA!$A$2:$CR$600,MATCH(1,(GMWA!$CQ$2:$CQ$600=E$3)*(GMWA!$CP$2:$CP$600=E$4)*(GMWA!$CR$2:$CR$600=E$1),0),$A8-1966)} -> 5488 | F8: {=INDEX(GMWA!$A$2:$CR$600,MATCH(1,(GMWA!$CQ$2:$CQ$600=F$3)*(GMWA!$CP$2:$CP$600=F$4)*(GMWA!$CR$2:$CR$600=F$1),0),$A8-1966)} -> 807 | G8: {=INDEX(GMWA!$A$2:$CR$600,MATCH(1,(GMWA!$CQ$2:$CQ$600=G$3)*(GMWA!$CP$2:$CP$600=G$4)*(GMWA!$CR$2:$CR$600=G$1),0),$A8-1966)} -> 2.308616 | H8: {=INDEX(GMWA!$A$2:$CR$600,MATCH(1,(GMWA!$CQ$2:$CQ$600=H$3)*(GMWA!$CP$2:$CP$600=H$4)*(GMWA!$CR$2:$CR$600=H$1),0),$A8-1966)} -> 4397.595 | I8: {=INDEX(GMWA!$A$2:$CR$600,MATCH(1,(GMWA!$CQ$2:$CQ$600=I$3)*(GMWA!$CP$2:$CP$600=I$4)*(GMWA!$CR$2:$CR$600=I$1),0),$A8-1966)} -> 2.263996 | ... BI8: {=INDEX(GMWA!$A$2:$CR$600,MATCH(1,(GMWA!$CQ$2:$CQ$600=BI$3)*(GMWA!$CP$2:$CP$600=BI$4)*(GMWA!$CR$2:$CR$600=BI$1),0),$A8-1966)} -> 23.33717 | BK8: =100*(B8/V8) -> 8.4599839 | BL8: =100*(C8/W8) -> 5.617306 | BM8: =100*(D8/X8) -> 7.2509241 | BN8: =100*(E8/Y8) -> 7.4126101 | BO8: =100*(F8/Z8) -> 80700000 | BP8: =100*(G8/AA8) -> 1.3824048 | BQ8: =100*(H8/AB8) -> 5.6173231 | BR8: =100*(I8/AC8) -> 2.1942007 | ... CD8: =100*(U8/AO8) -> 1.1515709
A9: =+A8+1 -> 1975 | B9: {=INDEX(GMWA!$A$2:$CR$600,MATCH(1,(GMWA!$CQ$2:$CQ$600=B$3)*(GMWA!$CP$2:$CP$600=B$4)*(GMWA!$CR$2:$CR$600=B$1),0),$A9-1966)} -> 4939 | C9: {=INDEX(GMWA!$A$2:$CR$600,MATCH(1,(GMWA!$CQ$2:$CQ$600=C$3)*(GMWA!$CP$2:$CP$600=C$4)*(GMWA!$CR$2:$CR$600=C$1),0),$A9-1966)} -> 77.425 | D9: {=INDEX(GMWA!$A$2:$CR$600,MATCH(1,(GMWA!$CQ$2:$CQ$600=D$3)*(GMWA!$CP$2:$CP$600=D$4)*(GMWA!$CR$2:$CR$600=D$1),0),$A9-1966)} -> 1681.87 | E9: {=INDEX(GMWA!$A$2:$CR$600,MATCH(1,(GMWA!$CQ$2:$CQ$600=E$3)*(GMWA!$CP$2:$CP$600=E$4)*(GMWA!$CR$2:$CR$600=E$1),0),$A9-1966)} -> 6639 | F9: {=INDEX(GMWA!$A$2:$CR$600,MATCH(1,(GMWA!$CQ$2:$CQ$600=F$3)*(GMWA!$CP$2:$CP$600=F$4)*(GMWA!$CR$2:$CR$600=F$1),0),$A9-1966)} -> 916 | G9: {=INDEX(GMWA!$A$2:$CR$600,MATCH(1,(GMWA!$CQ$2:$CQ$600=G$3)*(GMWA!$CP$2:$CP$600=G$4)*(GMWA!$CR$2:$CR$600=G$1),0),$A9-1966)} -> 2.534459 | H9: {=INDEX(GMWA!$A$2:$CR$600,MATCH(1,(GMWA!$CQ$2:$CQ$600=H$3)*(GMWA!$CP$2:$CP$600=H$4)*(GMWA!$CR$2:$CR$600=H$1),0),$A9-1966)} -> 5346.4 | I9: {=INDEX(GMWA!$A$2:$CR$600,MATCH(1,(GMWA!$CQ$2:$CQ$600=I$3)*(GMWA!$CP$2:$CP$600=I$4)*(GMWA!$CR$2:$CR$600=I$1),0),$A9-1966)} -> 2.686347 | ... BI9: {=INDEX(GMWA!$A$2:$CR$600,MATCH(1,(GMWA!$CQ$2:$CQ$600=BI$3)*(GMWA!$CP$2:$CP$600=BI$4)*(GMWA!$CR$2:$CR$600=BI$1),0),$A9-1966)} -> 23.33717 | BK9: =100*(B9/V9) -> 7.883983 | BL9: =100*(C9/W9) -> 5.53676 | BM9: =100*(D9/X9) -> 5.7659502 | BN9: =100*(E9/Y9) -> 8.0669267 | BO9: =100*(F9/Z9) -> 91600000 | BP9: =100*(G9/AA9) -> 1.5176401 | BQ9: =100*(H9/AB9) -> 5.9833203 | BR9: =100*(I9/AC9) -> 2.5110529 | ... CD9: =100*(U9/AO9) -> 0.71420664
A10: =+A9+1 -> 1976 | B10: {=INDEX(GMWA!$A$2:$CR$600,MATCH(1,(GMWA!$CQ$2:$CQ$600=B$3)*(GMWA!$CP$2:$CP$600=B$4)*(GMWA!$CR$2:$CR$600=B$1),0),$A10-1966)} -> 6380 | C10: {=INDEX(GMWA!$A$2:$CR$600,MATCH(1,(GMWA!$CQ$2:$CQ$600=C$3)*(GMWA!$CP$2:$CP$600=C$4)*(GMWA!$CR$2:$CR$600=C$1),0),$A10-1966)} -> 86.725 | D10: {=INDEX(GMWA!$A$2:$CR$600,MATCH(1,(GMWA!$CQ$2:$CQ$600=D$3)*(GMWA!$CP$2:$CP$600=D$4)*(GMWA!$CR$2:$CR$600=D$1),0),$A10-1966)} -> 2416.859 | E10: {=INDEX(GMWA!$A$2:$CR$600,MATCH(1,(GMWA!$CQ$2:$CQ$600=E$3)*(GMWA!$CP$2:$CP$600=E$4)*(GMWA!$CR$2:$CR$600=E$1),0),$A10-1966)} -> 8242 | F10: {=INDEX(GMWA!$A$2:$CR$600,MATCH(1,(GMWA!$CQ$2:$CQ$600=F$3)*(GMWA!$CP$2:$CP$600=F$4)*(GMWA!$CR$2:$CR$600=F$1),0),$A10-1966)} -> 1191 | G10: {=INDEX(GMWA!$A$2:$CR$600,MATCH(1,(GMWA!$CQ$2:$CQ$600=G$3)*(GMWA!$CP$2:$CP$600=G$4)*(GMWA!$CR$2:$CR$600=G$1),0),$A10-1966)} -> 3.290406 | H10: {=INDEX(GMWA!$A$2:$CR$600,MATCH(1,(GMWA!$CQ$2:$CQ$600=H$3)*(GMWA!$CP$2:$CP$600=H$4)*(GMWA!$CR$2:$CR$600=H$1),0),$A10-1966)} -> 5906.224 | I10: {=INDEX(GMWA!$A$2:$CR$600,MATCH(1,(GMWA!$CQ$2:$CQ$600=I$3)*(GMWA!$CP$2:$CP$600=I$4)*(GMWA!$CR$2:$CR$600=I$1),0),$A10-1966)} -> 2.877871 | ... BI10: {=INDEX(GMWA!$A$2:$CR$600,MATCH(1,(GMWA!$CQ$2:$CQ$600=BI$3)*(GMWA!$CP$2:$CP$600=BI$4)*(GMWA!$CR$2:$CR$600=BI$1),0),$A10-1966)} -> 23.33717 | BK10: =100*(B10/V10) -> 8.6917724 | BL10: =100*(C10/W10) -> 5.7520703 | BM10: =100*(D10/X10) -> 5.4923621 | BN10: =100*(E10/Y10) -> 9.0138565 | BO10: =100*(F10/Z10) -> 119100000 | BP10: =100*(G10/AA10) -> 1.970303 | BQ10: =100*(H10/AB10) -> 6.2641779 | BR10: =100*(I10/AC10) -> 2.6295615 | ... CD10: =100*(U10/AO10) -> 0.47137638
A11: =+A10+1 -> 1977 | B11: {=INDEX(GMWA!$A$2:$CR$600,MATCH(1,(GMWA!$CQ$2:$CQ$600=B$3)*(GMWA!$CP$2:$CP$600=B$4)*(GMWA!$CR$2:$CR$600=B$1),0),$A11-1966)} -> 7333 | C11: {=INDEX(GMWA!$A$2:$CR$600,MATCH(1,(GMWA!$CQ$2:$CQ$600=C$3)*(GMWA!$CP$2:$CP$600=C$4)*(GMWA!$CR$2:$CR$600=C$1),0),$A11-1966)} -> 95.75 | D11: {=INDEX(GMWA!$A$2:$CR$600,MATCH(1,(GMWA!$CQ$2:$CQ$600=D$3)*(GMWA!$CP$2:$CP$600=D$4)*(GMWA!$CR$2:$CR$600=D$1),0),$A11-1966)} -> 3374.968 | E11: {=INDEX(GMWA!$A$2:$CR$600,MATCH(1,(GMWA!$CQ$2:$CQ$600=E$3)*(GMWA!$CP$2:$CP$600=E$4)*(GMWA!$CR$2:$CR$600=E$1),0),$A11-1966)} -> 9432 | F11: {=INDEX(GMWA!$A$2:$CR$600,MATCH(1,(GMWA!$CQ$2:$CQ$600=F$3)*(GMWA!$CP$2:$CP$600=F$4)*(GMWA!$CR$2:$CR$600=F$1),0),$A11-1966)} -> 1532 | G11: {=INDEX(GMWA!$A$2:$CR$600,MATCH(1,(GMWA!$CQ$2:$CQ$600=G$3)*(GMWA!$CP$2:$CP$600=G$4)*(GMWA!$CR$2:$CR$600=G$1),0),$A11-1966)} -> 4.972726 | H11: {=INDEX(GMWA!$A$2:$CR$600,MATCH(1,(GMWA!$CQ$2:$CQ$600=H$3)*(GMWA!$CP$2:$CP$600=H$4)*(GMWA!$CR$2:$CR$600=H$1),0),$A11-1966)} -> 7658.689 | I11: {=INDEX(GMWA!$A$2:$CR$600,MATCH(1,(GMWA!$CQ$2:$CQ$600=I$3)*(GMWA!$CP$2:$CP$600=I$4)*(GMWA!$CR$2:$CR$600=I$1),0),$A11-1966)} -> 3.113591 | ... BI11: {=INDEX(GMWA!$A$2:$CR$600,MATCH(1,(GMWA!$CQ$2:$CQ$600=BI$3)*(GMWA!$CP$2:$CP$600=BI$4)*(GMWA!$CR$2:$CR$600=BI$1),0),$A11-1966)} -> 23.33717 | BK11: =100*(B11/V11) -> 8.7542007 | BL11: =100*(C11/W11) -> 5.8924092 | BM11: =100*(D11/X11) -> 5.7381801 | BN11: =100*(E11/Y11) -> 9.0254918 | BO11: =100*(F11/Z11) -> 153200000 | BP11: =100*(G11/AA11) -> 2.9776802 | BQ11: =100*(H11/AB11) -> 6.8816601 | BR11: =100*(I11/AC11) -> 2.8045341 | ... CD11: =100*(U11/AO11) -> 0.33766216
A12: =+A11+1 -> 1978 | B12: {=INDEX(GMWA!$A$2:$CR$600,MATCH(1,(GMWA!$CQ$2:$CQ$600=B$3)*(GMWA!$CP$2:$CP$600=B$4)*(GMWA!$CR$2:$CR$600=B$1),0),$A12-1966)} -> 8160 | C12: {=INDEX(GMWA!$A$2:$CR$600,MATCH(1,(GMWA!$CQ$2:$CQ$600=C$3)*(GMWA!$CP$2:$CP$600=C$4)*(GMWA!$CR$2:$CR$600=C$1),0),$A12-1966)} -> 112.45 | D12: {=INDEX(GMWA!$A$2:$CR$600,MATCH(1,(GMWA!$CQ$2:$CQ$600=D$3)*(GMWA!$CP$2:$CP$600=D$4)*(GMWA!$CR$2:$CR$600=D$1),0),$A12-1966)} -> 4369.668 | E12: {=INDEX(GMWA!$A$2:$CR$600,MATCH(1,(GMWA!$CQ$2:$CQ$600=E$3)*(GMWA!$CP$2:$CP$600=E$4)*(GMWA!$CR$2:$CR$600=E$1),0),$A12-1966)} -> 11741 | F12: {=INDEX(GMWA!$A$2:$CR$600,MATCH(1,(GMWA!$CQ$2:$CQ$600=F$3)*(GMWA!$CP$2:$CP$600=F$4)*(GMWA!$CR$2:$CR$600=F$1),0),$A12-1966)} -> 1796 | G12: {=INDEX(GMWA!$A$2:$CR$600,MATCH(1,(GMWA!$CQ$2:$CQ$600=G$3)*(GMWA!$CP$2:$CP$600=G$4)*(GMWA!$CR$2:$CR$600=G$1),0),$A12-1966)} -> 6.626816 | H12: {=INDEX(GMWA!$A$2:$CR$600,MATCH(1,(GMWA!$CQ$2:$CQ$600=H$3)*(GMWA!$CP$2:$CP$600=H$4)*(GMWA!$CR$2:$CR$600=H$1),0),$A12-1966)} -> 9006.922 | I12: {=INDEX(GMWA!$A$2:$CR$600,MATCH(1,(GMWA!$CQ$2:$CQ$600=I$3)*(GMWA!$CP$2:$CP$600=I$4)*(GMWA!$CR$2:$CR$600=I$1),0),$A12-1966)} -> 3.064492 | ... BI12: {=INDEX(GMWA!$A$2:$CR$600,MATCH(1,(GMWA!$CQ$2:$CQ$600=BI$3)*(GMWA!$CP$2:$CP$600=BI$4)*(GMWA!$CR$2:$CR$600=BI$1),0),$A12-1966)} -> 23.33717 | BK12: =100*(B12/V12) -> 8.6681716 | BL12: =100*(C12/W12) -> 6.3736507 | BM12: =100*(D12/X12) -> 5.3282786 | BN12: =100*(E12/Y12) -> 9.5232302 | BO12: =100*(F12/Z12) -> 179600000 | BP12: =100*(G12/AA12) -> 3.9681533 | BQ12: =100*(H12/AB12) -> 6.285795 | BR12: =100*(I12/AC12) -> 2.7169626 | ... CD12: =100*(U12/AO12) -> 0.2391964
