Workbook
Name _DLX1.INC: HAVERM!$A$1:$AG$6
Name _DLX2.INC: HAVERD!$G$2:$BW$7
Name _DLX3.INC: HAVERQ!$A$1:$G$6
Name Data: [15]sheet0!$C$2

Sheet Chart Data
A1: Services inflation | E1: Private sector pay growth | I1: Inflation forecasts | P1: BoE DMP | V1: BoE DMP | AB1: APF run down
B2: Outturn | C2: BoE forecast | F2: Outturn | G2: BoE forecast | J2: CPI inflation | K2: BoE market expectations (Aug) | L2: OE (Aug) | M2: HMT consensus (Jul) | N2: 2% LINE | Q2: Prices - past year | R2: Prices - next year | S2: Wages - past year | T2: Wages - next year | W2: Prices - past year | X2: Prices - next year | Y2: Wages - past year | Z2: Wages - next year | AC2: Redemptions | AD2: Gilt sales | AE2: Gilt sales implied by BoE MaPS | AF2: Total run down
A3: 44562 | B3: =100*((HAVERM!C151/HAVERM!C139)-1) -> 3.2685512 | E3: 44562 | F3: =HAVERM!D151 -> 4.2 | I3: 44927 | J3: =100*((HAVERQ!E39/HAVERQ!E35)-1) -> 10.178263 | N3: 2 | P3: 43466 | Q3: =HAVERM!E115 -> 2.79 | R3: =HAVERM!F115 -> 2.532 | S3: =HAVERM!G115 -> #N/A | T3: =HAVERM!H115 -> #N/A | V3: 43466 | W3: =HAVERM!I115 -> 2.528 | X3: =HAVERM!J115 -> 2.465 | Y3: =HAVERM!K115 -> #N/A | Z3: =HAVERM!L115 -> #N/A | AB3: 2022/ 2023 | AC3: 37 | AD3: =80-AC3 -> 43 | AF3: =SUM(AC3:AD3) -> 80 | AH3: =SUM('APF gilt sales'!H3:H592)/1000 -> 41.994
A4: 44593 | B4: =100*((HAVERM!C152/HAVERM!C140)-1) -> 3.4391534 | E4: 44593 | F4: =HAVERM!D152 -> 4.6 | I4: 45017 | J4: =100*((HAVERQ!E40/HAVERQ!E36)-1) -> 8.4390513 | N4: 2 | P4: 43497 | Q4: =HAVERM!E116 -> 2.23 | R4: =HAVERM!F116 -> 2.561 | S4: =HAVERM!G116 -> #N/A | T4: =HAVERM!H116 -> #N/A | V4: 43497 | W4: =HAVERM!I116 -> 2.412 | X4: =HAVERM!J116 -> 2.423 | Y4: =HAVERM!K116 -> #N/A | Z4: =HAVERM!L116 -> #N/A | AB4: 2023/ 2024 | AC4: 50 | AD4: =100-AC4 -> 50 | AF4: =SUM(AC4:AD4) -> 100 | AH4: =SUM('APF gilt sales'!H593:H1125)/1000 -> 40.9895
A5: 44621 | B5: =100*((HAVERM!C153/HAVERM!C141)-1) -> 3.9612676 | E5: 44621 | F5: =HAVERM!D153 -> 4.9 | I5: 45108 | J5: =100*((HAVERQ!E41/HAVERQ!E37)-1) -> 6.7135896 | N5: 2 | P5: 43525 | Q5: =HAVERM!E117 -> 2.39 | R5: =HAVERM!F117 -> 2.068 | S5: =HAVERM!G117 -> #N/A | T5: =HAVERM!H117 -> #N/A | V5: 43525 | W5: =HAVERM!I117 -> 2.47 | X5: =HAVERM!J117 -> 2.387 | Y5: =HAVERM!K117 -> #N/A | Z5: =HAVERM!L117 -> #N/A | AB5: 2024/ 2025 | AC5: ='Maturity Profile of APF (Table)'!H4 -> 87.187539 | AE5: =100-AC5 -> 12.812461 | AF5: =SUM(AC5:AE5) -> 100
A6: 44652 | B6: =100*((HAVERM!C154/HAVERM!C142)-1) -> 4.7244094 | E6: 44652 | F6: =HAVERM!D154 -> 4.8 | I6: 45200 | J6: =100*((HAVERQ!E42/HAVERQ!E38)-1) -> 4.1568008 | N6: 2 | P6: 43556 | Q6: =HAVERM!E118 -> 2.88 | R6: =HAVERM!F118 -> 2.715 | S6: =HAVERM!G118 -> #N/A | T6: =HAVERM!H118 -> #N/A | V6: 43556 | W6: =HAVERM!I118 -> 2.499 | X6: =HAVERM!J118 -> 2.448 | Y6: =HAVERM!K118 -> #N/A | Z6: =HAVERM!L118 -> #N/A | AB6: 2025/ 2026 | AC6: ='Maturity Profile of APF (Table)'!H5 -> 49.127841 | AE6: =75-AC6 -> 25.872159 | AF6: =SUM(AC6:AE6) -> 75
A7: 44682 | B7: =100*((HAVERM!C155/HAVERM!C143)-1) -> 4.886562 | E7: 44682 | F7: =HAVERM!D155 -> 5.1 | I7: 45292 | J7: =100*((HAVERQ!E43/HAVERQ!E39)-1) -> 3.5490605 | L7: =100*((GMW!B211/GMW!B207)-1) -> 3.5491137 | N7: 2 | P7: 43586 | Q7: =HAVERM!E119 -> 1.82 | R7: =HAVERM!F119 -> 2.332 | S7: =HAVERM!G119 -> #N/A | T7: =HAVERM!H119 -> #N/A | V7: 43586 | W7: =HAVERM!I119 -> 2.362 | X7: =HAVERM!J119 -> 2.372 | Y7: =HAVERM!K119 -> #N/A | Z7: =HAVERM!L119 -> #N/A | AB7: 2026/ 2027 | AC7: ='Maturity Profile of APF (Table)'!H6 -> 30.505274 | AE7: =50-AC7 -> 19.494726 | AF7: =SUM(AC7:AE7) -> 50
A8: 44713 | B8: =100*((HAVERM!C156/HAVERM!C144)-1) -> 5.2173913 | E8: 44713 | F8: =HAVERM!D156 -> 5.4 | I8: 45383 | J8: =100*((HAVERQ!E44/HAVERQ!E40)-1) -> 2.110885 | L8: =100*((GMW!B212/GMW!B208)-1) -> 2.1108336 | N8: 2 | P8: 43617 | Q8: =HAVERM!E120 -> 2.69 | R8: =HAVERM!F120 -> 2.154 | S8: =HAVERM!G120 -> #N/A | T8: =HAVERM!H120 -> #N/A | V8: 43617 | W8: =HAVERM!I120 -> 2.462 | X8: =HAVERM!J120 -> 2.4 | Y8: =HAVERM!K120 -> #N/A | Z8: =HAVERM!L120 -> #N/A | AB8: 2027/ 2028 | AC8: ='Maturity Profile of APF (Table)'!H7 -> 29.223226 | AE8: =31-AC8 -> 1.7767736 | AF8: =SUM(AC8:AE8) -> 31
A9: 44743 | B9: =100*((HAVERM!C157/HAVERM!C145)-1) -> 5.7241977 | E9: 44743 | F9: =HAVERM!D157 -> 6 | I9: 45474 | K9: =HAVERQ!B45 -> 2.3 | L9: =100*((GMW!B213/GMW!B209)-1) -> 2.1209285 | N9: 2 | P9: 43647 | Q9: =HAVERM!E121 -> 2.26 | R9: =HAVERM!F121 -> 2.098 | S9: =HAVERM!G121 -> #N/A | T9: =HAVERM!H121 -> #N/A | V9: 43647 | W9: =HAVERM!I121 -> 2.256 | X9: =HAVERM!J121 -> 2.195 | Y9: =HAVERM!K121 -> #N/A | Z9: =HAVERM!L121 -> #N/A
A10: 44774 | B10: =100*((HAVERM!C158/HAVERM!C146)-1) -> 5.9585492 | E10: 44774 | F10: =HAVERM!D158 -> 6.2 | I10: 45566 | K10: =HAVERQ!B46 -> 2.7 | L10: =100*((GMW!B214/GMW!B210)-1) -> 2.5595093 | M10: 2.4 | N10: 2 | P10: 43678 | Q10: =HAVERM!E122 -> 1.94 | R10: =HAVERM!F122 -> 2.289 | S10: =HAVERM!G122 -> #N/A | T10: =HAVERM!H122 -> #N/A | V10: 43678 | W10: =HAVERM!I122 -> 2.296 | X10: =HAVERM!J122 -> 2.18 | Y10: =HAVERM!K122 -> #N/A | Z10: =HAVERM!L122 -> #N/A
A11: 44805 | B11: =100*((HAVERM!C159/HAVERM!C147)-1) -> 6.1312608 | E11: 44805 | F11: =HAVERM!D159 -> 6.6 | I11: 45658 | K11: =HAVERQ!B47 -> 2.7 | L11: =100*((GMW!B215/GMW!B211)-1) -> 2.5444802 | N11: 2 | P11: 43709 | Q11: =HAVERM!E123 -> 2.27 | R11: =HAVERM!F123 -> 2.355 | S11: =HAVERM!G123 -> #N/A | T11: =HAVERM!H123 -> #N/A | V11: 43709 | W11: =HAVERM!I123 -> 2.156 | X11: =HAVERM!J123 -> 2.247 | Y11: =HAVERM!K123 -> #N/A | Z11: =HAVERM!L123 -> #N/A
A12: 44835 | B12: =100*((HAVERM!C160/HAVERM!C148)-1) -> 6.2660944 | E12: 44835 | F12: =HAVERM!D160 -> 6.9 | I12: 45748 | K12: =HAVERQ!B48 -> 2.6 | L12: =100*((GMW!B216/GMW!B212)-1) -> 2.3549445 | N12: 2 | P12: 43739 | Q12: =HAVERM!E124 -> 1.99 | R12: =HAVERM!F124 -> 2.216 | S12: =HAVERM!G124 -> #N/A | T12: =HAVERM!H124 -> #N/A | V12: 43739 | W12: =HAVERM!I124 -> 2.067 | X12: =HAVERM!J124 -> 2.287 | Y12: =HAVERM!K124 -> #N/A | Z12: =HAVERM!L124 -> #N/A
A13: 44866 | B13: =100*((HAVERM!C161/HAVERM!C149)-1) -> 6.3464837 | E13: 44866 | F13: =HAVERM!D161 -> 7.3 | I13: 45839 | K13: =HAVERQ!B49 -> 2.4 | L13: =100*((GMW!B217/GMW!B213)-1) -> 2.6438497 | N13: 2 | P13: 43770 | Q13: =HAVERM!E125 -> 1.89 | R13: =HAVERM!F125 -> 2.181 | S13: =HAVERM!G125 -> #N/A | T13: =HAVERM!H125 -> #N/A | V13: 43770 | W13: =HAVERM!I125 -> 2.051 | X13: =HAVERM!J125 -> 2.251 | Y13: =HAVERM!K125 -> #N/A | Z13: =HAVERM!L125 -> #N/A
A14: 44896 | B14: =100*((HAVERM!C162/HAVERM!C150)-1) -> 6.8376068 | E14: 44896 | F14: =HAVERM!D162 -> 7.3 | I14: 45931 | K14: =HAVERQ!B50 -> 2.2 | L14: =100*((GMW!B218/GMW!B214)-1) -> 2.4348994 | M14: 2.1 | N14: 2 | P14: 43800 | Q14: =HAVERM!E126 -> 1.99 | R14: =HAVERM!F126 -> 2.371 | S14: =HAVERM!G126 -> #N/A | T14: =HAVERM!H126 -> #N/A | V14: 43800 | W14: =HAVERM!I126 -> 1.958 | X14: =HAVERM!J126 -> 2.256 | Y14: =HAVERM!K126 -> #N/A | Z14: =HAVERM!L126 -> #N/A
A15: 44927 | B15: =100*((HAVERM!C163/HAVERM!C151)-1) -> 5.9024808 | E15: 44927 | F15: =HAVERM!D163 -> 7.1 | I15: 46023 | K15: =HAVERQ!B51 -> 2 | L15: =100*((GMW!B219/GMW!B215)-1) -> 2.3920573 | N15: 2 | P15: 43831 | Q15: =HAVERM!E127 -> 2.07 | R15: =HAVERM!F127 -> 2.121 | S15: =HAVERM!G127 -> #N/A | T15: =HAVERM!H127 -> #N/A | V15: 43831 | W15: =HAVERM!I127 -> 1.982 | X15: =HAVERM!J127 -> 2.224 | Y15: =HAVERM!K127 -> #N/A | Z15: =HAVERM!L127 -> #N/A
A16: 44958 | B16: =100*((HAVERM!C164/HAVERM!C152)-1) -> 6.6496164 | E16: 44958 | F16: =HAVERM!D164 -> 7.1 | I16: 46113 | K16: =HAVERQ!B52 -> 1.7 | L16: =100*((GMW!B220/GMW!B216)-1) -> 2.3063109 | N16: 2 | P16: 43862 | Q16: =HAVERM!E128 -> 1.79 | R16: =HAVERM!F128 -> 2.126 | S16: =HAVERM!G128 -> #N/A | T16: =HAVERM!H128 -> #N/A | V16: 43862 | W16: =HAVERM!I128 -> 1.949 | X16: =HAVERM!J128 -> 2.206 | Y16: =HAVERM!K128 -> #N/A | Z16: =HAVERM!L128 -> #N/A
A17: 44986 | B17: =100*((HAVERM!C165/HAVERM!C153)-1) -> 6.6892464 | E17: 44986 | F17: =HAVERM!D165 -> 7.2 | I17: 46204 | K17: =HAVERQ!B53 -> 1.7 | L17: =100*((GMW!B221/GMW!B217)-1) -> 2.2260202 | N17: 2 | P17: 43891 | Q17: =HAVERM!E129 -> 1.82 | R17: =HAVERM!F129 -> 1.615 | S17: =HAVERM!G129 -> #N/A | T17: =HAVERM!H129 -> #N/A | V17: 43891 | W17: =HAVERM!I129 -> 1.893 | X17: =HAVERM!J129 -> 1.954 | Y17: =HAVERM!K129 -> #N/A | Z17: =HAVERM!L129 -> #N/A
A18: 45017 | B18: =100*((HAVERM!C166/HAVERM!C154)-1) -> 6.9340017 | E18: 45017 | F18: =HAVERM!D166 -> 7.7 | I18: 46296 | K18: =HAVERQ!B54 -> 1.6 | L18: =100*((GMW!B222/GMW!B218)-1) -> 2.0986743 | N18: 2 | P18: 43922 | Q18: =HAVERM!E130 -> 1.86 | R18: =HAVERM!F130 -> 1.207 | S18: =HAVERM!G130 -> #N/A | T18: =HAVERM!H130 -> #N/A | V18: 43922 | W18: =HAVERM!I130 -> 1.824 | X18: =HAVERM!J130 -> 1.649 | Y18: =HAVERM!K130 -> #N/A | Z18: =HAVERM!L130 -> #N/A
A19: 45047 | B19: =100*((HAVERM!C167/HAVERM!C155)-1) -> 7.3211314 | E19: 45047 | F19: =HAVERM!D167 -> 7.9 | I19: 46388 | K19: =HAVERQ!B55 -> 1.5 | L19: =100*((GMW!B223/GMW!B219)-1) -> 2.1633594 | N19: 2 | P19: 43952 | Q19: =HAVERM!E131 -> 1.76 | R19: =HAVERM!F131 -> 1.387 | S19: =HAVERM!G131 -> #N/A | T19: =HAVERM!H131 -> #N/A | V19: 43952 | W19: =HAVERM!I131 -> 1.813 | X19: =HAVERM!J131 -> 1.403 | Y19: =HAVERM!K131 -> #N/A | Z19: =HAVERM!L131 -> #N/A
A20: 45078 | B20: =100*((HAVERM!C168/HAVERM!C156)-1) -> 7.1900826 | E20: 45078 | F20: =HAVERM!D168 -> 8.1 | I20: 46478 | K20: =HAVERQ!B56 -> 1.5 | L20: =100*((GMW!B224/GMW!B220)-1) -> 2.1882445 | N20: 2 | P20: 43983 | Q20: =HAVERM!E132 -> 1.19 | R20: =HAVERM!F132 -> 1.45 | S20: =HAVERM!G132 -> #N/A | T20: =HAVERM!H132 -> #N/A | V20: 43983 | W20: =HAVERM!I132 -> 1.6 | X20: =HAVERM!J132 -> 1.348 | Y20: =HAVERM!K132 -> #N/A | Z20: =HAVERM!L132 -> #N/A
A21: 45108 | B21: =100*((HAVERM!C169/HAVERM!C157)-1) -> 7.4651354 | E21: 45108 | F21: =HAVERM!D169 -> 8.1 | I21: 46569 | K21: =HAVERQ!B57 -> 1.5 | L21: =100*((GMW!B225/GMW!B221)-1) -> 2.2367092 | N21: 2 | P21: 44013 | Q21: =HAVERM!E133 -> 1.34 | R21: =HAVERM!F133 -> 1.663 | S21: =HAVERM!G133 -> #N/A | T21: =HAVERM!H133 -> #N/A | V21: 44013 | W21: =HAVERM!I133 -> 1.427 | X21: =HAVERM!J133 -> 1.5 | Y21: =HAVERM!K133 -> #N/A | Z21: =HAVERM!L133 -> #N/A
A22: 45139 | B22: =100*((HAVERM!C170/HAVERM!C158)-1) -> 6.7644662 | E22: 45139 | F22: =HAVERM!D170 -> 8.1 | I22: 46661 | L22: =100*((GMW!B226/GMW!B222)-1) -> 2.2573022 | N22: 2 | P22: 44044 | Q22: =HAVERM!E134 -> 1.08 | R22: =HAVERM!F134 -> 2.181 | S22: =HAVERM!G134 -> #N/A | T22: =HAVERM!H134 -> #N/A | V22: 44044 | W22: =HAVERM!I134 -> 1.2 | X22: =HAVERM!J134 -> 1.764 | Y22: =HAVERM!K134 -> #N/A | Z22: =HAVERM!L134 -> #N/A
A23: 45170 | B23: =100*((HAVERM!C171/HAVERM!C159)-1) -> 6.916192 | E23: 45170 | F23: =HAVERM!D171 -> 7.9 | P23: 44075 | Q23: =HAVERM!E135 -> 1.44 | R23: =HAVERM!F135 -> 1.887 | S23: =HAVERM!G135 -> #N/A | T23: =HAVERM!H135 -> #N/A | V23: 44075 | W23: =HAVERM!I135 -> 1.286 | X23: =HAVERM!J135 -> 1.91 | Y23: =HAVERM!K135 -> #N/A | Z23: =HAVERM!L135 -> #N/A
A24: 45200 | B24: =100*((HAVERM!C172/HAVERM!C160)-1) -> 6.542811 | E24: 45200 | F24: =HAVERM!D172 -> 7.2 | P24: 44105 | Q24: =HAVERM!E136 -> 2.21 | R24: =HAVERM!F136 -> 2.364 | S24: =HAVERM!G136 -> #N/A | T24: =HAVERM!H136 -> #N/A | V24: 44105 | W24: =HAVERM!I136 -> 1.576 | X24: =HAVERM!J136 -> 2.144 | Y24: =HAVERM!K136 -> #N/A | Z24: =HAVERM!L136 -> #N/A
A25: 45231 | B25: =100*((HAVERM!C173/HAVERM!C161)-1) -> 6.2096774 | E25: 45231 | F25: =HAVERM!D173 -> 6.6 | P25: 44136 | Q25: =HAVERM!E137 -> 1.69 | R25: =HAVERM!F137 -> 2.092 | S25: =HAVERM!G137 -> #N/A | T25: =HAVERM!H137 -> #N/A | V25: 44136 | W25: =HAVERM!I137 -> 1.78 | X25: =HAVERM!J137 -> 2.115 | Y25: =HAVERM!K137 -> #N/A | Z25: =HAVERM!L137 -> #N/A
A26: 45261 | B26: =100*((HAVERM!C174/HAVERM!C162)-1) -> 6.4 | E26: 45261 | F26: =HAVERM!D174 -> 6.2 | P26: 44166 | Q26: =HAVERM!E138 -> 0.85 | R26: =HAVERM!F138 -> 2.696 | S26: =HAVERM!G138 -> #N/A | T26: =HAVERM!H138 -> #N/A | V26: 44166 | W26: =HAVERM!I138 -> 1.582 | X26: =HAVERM!J138 -> 2.384 | Y26: =HAVERM!K138 -> #N/A | Z26: =HAVERM!L138 -> #N/A
A27: 45292 | B27: =100*((HAVERM!C175/HAVERM!C163)-1) -> 6.542811 | E27: 45292 | F27: =HAVERM!D175 -> 6.1 | P27: 44197 | Q27: =HAVERM!E139 -> 1.83 | R27: =HAVERM!F139 -> 2.509 | S27: =HAVERM!G139 -> #N/A | T27: =HAVERM!H139 -> #N/A | V27: 44197 | W27: =HAVERM!I139 -> 1.456 | X27: =HAVERM!J139 -> 2.433 | Y27: =HAVERM!K139 -> #N/A | Z27: =HAVERM!L139 -> #N/A
A28: 45323 | B28: =100*((HAVERM!C176/HAVERM!C164)-1) -> 6.0751399 | E28: 45323 | F28: =HAVERM!D176 -> 6 | P28: 44228 | Q28: =HAVERM!E140 -> 2.07 | R28: =HAVERM!F140 -> 2.719 | S28: =HAVERM!G140 -> #N/A | T28: =HAVERM!H140 -> #N/A | V28: 44228 | W28: =HAVERM!I140 -> 1.585 | X28: =HAVERM!J140 -> 2.642 | Y28: =HAVERM!K140 -> #N/A | Z28: =HAVERM!L140 -> #N/A
A29: 45352 | B29: =100*((HAVERM!C177/HAVERM!C165)-1) -> 5.952381 | E29: 45352 | F29: =HAVERM!D177 -> 5.9 | P29: 44256 | Q29: =HAVERM!E141 -> 1.65 | R29: =HAVERM!F141 -> 2.978 | S29: =HAVERM!G141 -> #N/A | T29: =HAVERM!H141 -> #N/A | V29: 44256 | W29: =HAVERM!I141 -> 1.852 | X29: =HAVERM!J141 -> 2.735 | Y29: =HAVERM!K141 -> #N/A | Z29: =HAVERM!L141 -> #N/A
A30: 45383 | B30: =100*((HAVERM!C178/HAVERM!C166)-1) -> 5.859375 | E30: 45383 | F30: =HAVERM!D178 -> 5.9 | P30: 44287 | Q30: =HAVERM!E142 -> 2.78 | R30: =HAVERM!F142 -> 3.137 | S30: =HAVERM!G142 -> #N/A | T30: =HAVERM!H142 -> #N/A | V30: 44287 | W30: =HAVERM!I142 -> 2.168 | X30: =HAVERM!J142 -> 2.945 | Y30: =HAVERM!K142 -> #N/A | Z30: =HAVERM!L142 -> #N/A
A31: 45413 | B31: =100*((HAVERM!C179/HAVERM!C167)-1) -> 5.7364341 | E31: 45413 | F31: =HAVERM!D179 -> 5.6 | P31: 44317 | Q31: =HAVERM!E143 -> 2.84 | R31: =HAVERM!F143 -> 3.449 | S31: =HAVERM!G143 -> #N/A | T31: =HAVERM!H143 -> #N/A | V31: 44317 | W31: =HAVERM!I143 -> 2.425 | X31: =HAVERM!J143 -> 3.188 | Y31: =HAVERM!K143 -> #N/A | Z31: =HAVERM!L143 -> #N/A
A32: 45444 | B32: =100*((HAVERM!C180/HAVERM!C168)-1) -> 5.7054742 | E32: 45444 | F32: =HAVERM!D180 -> 5.2 | G32: ='MPR Chart 2.21'!B32 -> 5.141 | P32: 44348 | Q32: =HAVERM!E144 -> 3.13 | R32: =HAVERM!F144 -> 3.255 | S32: =HAVERM!G144 -> #N/A | T32: =HAVERM!H144 -> #N/A | V32: 44348 | W32: =HAVERM!I144 -> 2.917 | X32: =HAVERM!J144 -> 3.28 | Y32: =HAVERM!K144 -> #N/A | Z32: =HAVERM!L144 -> #N/A
A33: 45474 | B33: =100*((HAVERM!C181/HAVERM!C169)-1) -> 5.1908397 | C33: ='MPR Chart 2.16'!L49 -> 5.563 | E33: 45474 | P33: 44378 | Q33: =HAVERM!E145 -> 3.76 | R33: =HAVERM!F145 -> 2.922 | S33: =HAVERM!G145 -> #N/A | T33: =HAVERM!H145 -> #N/A | V33: 44378 | W33: =HAVERM!I145 -> 3.244 | X33: =HAVERM!J145 -> 3.209 | Y33: =HAVERM!K145 -> #N/A | Z33: =HAVERM!L145 -> #N/A
A34: 45505 | C34: ='MPR Chart 2.16'!L50 -> 5.84 | E34: 45505 | P34: 44409 | Q34: =HAVERM!E146 -> 3.45 | R34: =HAVERM!F146 -> 3.223 | S34: =HAVERM!G146 -> #N/A | T34: =HAVERM!H146 -> #N/A | V34: 44409 | W34: =HAVERM!I146 -> 3.446 | X34: =HAVERM!J146 -> 3.133 | Y34: =HAVERM!K146 -> #N/A | Z34: =HAVERM!L146 -> #N/A
A35: 45536 | C35: ='MPR Chart 2.16'!L51 -> 5.52 | E35: 45536 | G35: ='MPR Chart 2.21'!B33 -> 4.83 | P35: 44440 | Q35: =HAVERM!E147 -> 4.54 | R35: =HAVERM!F147 -> 4.106 | S35: =HAVERM!G147 -> #N/A | T35: =HAVERM!H147 -> #N/A | V35: 44440 | W35: =HAVERM!I147 -> 3.916 | X35: =HAVERM!J147 -> 3.417 | Y35: =HAVERM!K147 -> #N/A | Z35: =HAVERM!L147 -> #N/A
A36: 45566 | C36: ='MPR Chart 2.16'!L52 -> 5.502 | E36: 45566 | P36: 44470 | Q36: =HAVERM!E148 -> 5.42 | R36: =HAVERM!F148 -> 4.707 | S36: =HAVERM!G148 -> #N/A | T36: =HAVERM!H148 -> #N/A | V36: 44470 | W36: =HAVERM!I148 -> 4.469 | X36: =HAVERM!J148 -> 4.012 | Y36: =HAVERM!K148 -> #N/A | Z36: =HAVERM!L148 -> #N/A
A37: 45597 | C37: ='MPR Chart 2.16'!L53 -> 5.395 | E37: 45597 | P37: 44501 | Q37: =HAVERM!E149 -> 4.82 | R37: =HAVERM!F149 -> 4.444 | S37: =HAVERM!G149 -> #N/A | T37: =HAVERM!H149 -> #N/A | V37: 44501 | W37: =HAVERM!I149 -> 4.925 | X37: =HAVERM!J149 -> 4.419 | Y37: =HAVERM!K149 -> #N/A | Z37: =HAVERM!L149 -> #N/A
A38: 45627 | C38: ='MPR Chart 2.16'!L54 -> 5.286 | E38: 45627 | P38: 44531 | Q38: =HAVERM!E150 -> 5.48 | R38: =HAVERM!F150 -> 5.099 | S38: =HAVERM!G150 -> #N/A | T38: =HAVERM!H150 -> #N/A | V38: 44531 | W38: =HAVERM!I150 -> 5.24 | X38: =HAVERM!J150 -> 4.75 | Y38: =HAVERM!K150 -> #N/A | Z38: =HAVERM!L150 -> #N/A
P39: 44562 | Q39: =HAVERM!E151 -> 5.41 | R39: =HAVERM!F151 -> 4.527 | S39: =HAVERM!G151 -> #N/A | T39: =HAVERM!H151 -> #N/A | V39: 44562 | W39: =HAVERM!I151 -> 5.235 | X39: =HAVERM!J151 -> 4.69 | Y39: =HAVERM!K151 -> #N/A | Z39: =HAVERM!L151 -> #N/A
P40: 44593 | Q40: =HAVERM!E152 -> 5.26 | R40: =HAVERM!F152 -> 4.892 | S40: =HAVERM!G152 -> #N/A | T40: =HAVERM!H152 -> #N/A | V40: 44593 | W40: =HAVERM!I152 -> 5.383 | X40: =HAVERM!J152 -> 4.839 | Y40: =HAVERM!K152 -> #N/A | Z40: =HAVERM!L152 -> #N/A
...

Sheet Market expectations
A1: August MPR | C1: 15 working days to 22 July 2024 | BA1: November MPR | BC1: 15 working days to 28 October 2024
A2: Column # | B2: 9 | C2: =+B2+1 -> 10 | D2: =+C2+1 -> 11 | E2: =+D2+1 -> 12 | F2: =+E2+1 -> 13 | G2: =+F2+1 -> 14 | H2: =+G2+1 -> 15 | I2: =+H2+1 -> 16 | J2: =+I2+1 -> 17 | ... AX2: =+AW2+1 -> 57 | BA2: Column # | BB2: 9 | BC2: =+BB2+1 -> 10 | BD2: =+BC2+1 -> 11 | BE2: =+BD2+1 -> 12 | BF2: =+BE2+1 -> 13 | BG2: =+BF2+1 -> 14 | BH2: =+BG2+1 -> 15 | BI2: =+BH2+1 -> 16 | BJ2: =+BI2+1 -> 17 | ... CW2: =+CV2+1 -> 56
A3: Months | B3: =HAVERD!I$1 -> Overnight | C3: =HAVERD!J$1 -> 1 | D3: =HAVERD!K$1 -> 2 | E3: =HAVERD!L$1 -> 3 | F3: =HAVERD!M$1 -> 4 | G3: =HAVERD!N$1 -> 5 | H3: =HAVERD!O$1 -> 6 | I3: =HAVERD!P$1 -> 7 | ... AX3: =HAVERD!BE$1 -> 48 | BA3: Months | BB3: =HAVERD!J$1 -> 1 | BC3: =HAVERD!K$1 -> 2 | BD3: =HAVERD!L$1 -> 3 | BE3: =HAVERD!M$1 -> 4 | BF3: =HAVERD!N$1 -> 5 | BG3: =HAVERD!O$1 -> 6 | BH3: =HAVERD!P$1 -> 7 | BI3: =HAVERD!Q$1 -> 8 | ... CW3: =HAVERD!BE$1 -> 48
A4: Days | C4: 30.416667 | D4: =+C4+30.4166667 -> 60.833333 | E4: =+D4+30.4166667 -> 91.25 | F4: =+E4+30.4166667 -> 121.66667 | G4: =+F4+30.4166667 -> 152.08333 | H4: =+G4+30.4166667 -> 182.5 | I4: =+H4+30.4166667 -> 212.91667 | J4: =+I4+30.4166667 -> 243.33333 | K4: =+J4+30.4166667 -> 273.75 | ... AX4: =+AW4+30.4166667 -> 1460 | BA4: Days | BC4: 30.416667 | BD4: =+BC4+30.4166667 -> 60.833333 | BE4: =+BD4+30.4166667 -> 91.25 | BF4: =+BE4+30.4166667 -> 121.66667 | BG4: =+BF4+30.4166667 -> 152.08333 | BH4: =+BG4+30.4166667 -> 182.5 | BI4: =+BH4+30.4166667 -> 212.91667 | BJ4: =+BI4+30.4166667 -> 243.33333 | BK4: =+BJ4+30.4166667 -> 273.75 | ... CW4: =+CV4+30.4166667 -> 1429.5833
A5: Dates | BA5: Dates
A6: =A11-7 -> 45475 | B6: =A6 -> 45475 | C6: =$B6+C$4 -> 45505.417 | D6: =$B6+D$4 -> 45535.833 | E6: =$B6+E$4 -> 45566.25 | F6: =$B6+F$4 -> 45596.667 | G6: =$B6+G$4 -> 45627.083 | H6: =$B6+H$4 -> 45657.5 | I6: =$B6+I$4 -> 45687.917 | J6: =$B6+J$4 -> 45718.333 | ... AX6: =$B6+AX$4 -> 46935 | BA6: =BA11-7 -> 45573 | BB6: =BA6 -> 45573 | BC6: =$BA6+BC$4 -> 45603.417 | BD6: =$BA6+BD$4 -> 45633.833 | BE6: =$BA6+BE$4 -> 45664.25 | BF6: =$BA6+BF$4 -> 45694.667 | BG6: =$BA6+BG$4 -> 45725.083 | BH6: =$BA6+BH$4 -> 45755.5 | BI6: =$BA6+BI$4 -> 45785.917 | BJ6: =$BA6+BJ$4 -> 45816.333 | ... CW6: =$BA6+CW$4 -> 47002.583
A7: =A12-7 -> 45476 | B7: =A7 -> 45476 | C7: =$B7+C$4 -> 45506.417 | D7: =$B7+D$4 -> 45536.833 | E7: =$B7+E$4 -> 45567.25 | F7: =$B7+F$4 -> 45597.667 | G7: =$B7+G$4 -> 45628.083 | H7: =$B7+H$4 -> 45658.5 | I7: =$B7+I$4 -> 45688.917 | J7: =$B7+J$4 -> 45719.333 | ... AX7: =$B7+AX$4 -> 46936 | BA7: =BA12-7 -> 45574 | BB7: =BA7 -> 45574 | BC7: =$BA7+BC$4 -> 45604.417 | BD7: =$BA7+BD$4 -> 45634.833 | BE7: =$BA7+BE$4 -> 45665.25 | BF7: =$BA7+BF$4 -> 45695.667 | BG7: =$BA7+BG$4 -> 45726.083 | BH7: =$BA7+BH$4 -> 45756.5 | BI7: =$BA7+BI$4 -> 45786.917 | BJ7: =$BA7+BJ$4 -> 45817.333 | ... CW7: =$BA7+CW$4 -> 47003.583
A8: =A13-7 -> 45477 | B8: =A8 -> 45477 | C8: =$B8+C$4 -> 45507.417 | D8: =$B8+D$4 -> 45537.833 | E8: =$B8+E$4 -> 45568.25 | F8: =$B8+F$4 -> 45598.667 | G8: =$B8+G$4 -> 45629.083 | H8: =$B8+H$4 -> 45659.5 | I8: =$B8+I$4 -> 45689.917 | J8: =$B8+J$4 -> 45720.333 | ... AX8: =$B8+AX$4 -> 46937 | BA8: =BA13-7 -> 45575 | BB8: =BA8 -> 45575 | BC8: =$BA8+BC$4 -> 45605.417 | BD8: =$BA8+BD$4 -> 45635.833 | BE8: =$BA8+BE$4 -> 45666.25 | BF8: =$BA8+BF$4 -> 45696.667 | BG8: =$BA8+BG$4 -> 45727.083 | BH8: =$BA8+BH$4 -> 45757.5 | BI8: =$BA8+BI$4 -> 45787.917 | BJ8: =$BA8+BJ$4 -> 45818.333 | ... CW8: =$BA8+CW$4 -> 47004.583
A9: =A14-7 -> 45478 | B9: =A9 -> 45478 | C9: =$B9+C$4 -> 45508.417 | D9: =$B9+D$4 -> 45538.833 | E9: =$B9+E$4 -> 45569.25 | F9: =$B9+F$4 -> 45599.667 | G9: =$B9+G$4 -> 45630.083 | H9: =$B9+H$4 -> 45660.5 | I9: =$B9+I$4 -> 45690.917 | J9: =$B9+J$4 -> 45721.333 | ... AX9: =$B9+AX$4 -> 46938 | BA9: =BA14-7 -> 45576 | BB9: =BA9 -> 45576 | BC9: =$BA9+BC$4 -> 45606.417 | BD9: =$BA9+BD$4 -> 45636.833 | BE9: =$BA9+BE$4 -> 45667.25 | BF9: =$BA9+BF$4 -> 45697.667 | BG9: =$BA9+BG$4 -> 45728.083 | BH9: =$BA9+BH$4 -> 45758.5 | BI9: =$BA9+BI$4 -> 45788.917 | BJ9: =$BA9+BJ$4 -> 45819.333 | ... CW9: =$BA9+CW$4 -> 47005.583
A10: =A15-7 -> 45481 | B10: =A10 -> 45481 | C10: =$B10+C$4 -> 45511.417 | D10: =$B10+D$4 -> 45541.833 | E10: =$B10+E$4 -> 45572.25 | F10: =$B10+F$4 -> 45602.667 | G10: =$B10+G$4 -> 45633.083 | H10: =$B10+H$4 -> 45663.5 | I10: =$B10+I$4 -> 45693.917 | J10: =$B10+J$4 -> 45724.333 | ... AX10: =$B10+AX$4 -> 46941 | BA10: =BA15-7 -> 45579 | BB10: =BA10 -> 45579 | BC10: =$BA10+BC$4 -> 45609.417 | BD10: =$BA10+BD$4 -> 45639.833 | BE10: =$BA10+BE$4 -> 45670.25 | BF10: =$BA10+BF$4 -> 45700.667 | BG10: =$BA10+BG$4 -> 45731.083 | BH10: =$BA10+BH$4 -> 45761.5 | BI10: =$BA10+BI$4 -> 45791.917 | BJ10: =$BA10+BJ$4 -> 45822.333 | ... CW10: =$BA10+CW$4 -> 47008.583
A11: =A16-7 -> 45482 | B11: =A11 -> 45482 | C11: =$B11+C$4 -> 45512.417 | D11: =$B11+D$4 -> 45542.833 | E11: =$B11+E$4 -> 45573.25 | F11: =$B11+F$4 -> 45603.667 | G11: =$B11+G$4 -> 45634.083 | H11: =$B11+H$4 -> 45664.5 | I11: =$B11+I$4 -> 45694.917 | J11: =$B11+J$4 -> 45725.333 | ... AX11: =$B11+AX$4 -> 46942 | BA11: =BA16-7 -> 45580 | BB11: =BA11 -> 45580 | BC11: =$BA11+BC$4 -> 45610.417 | BD11: =$BA11+BD$4 -> 45640.833 | BE11: =$BA11+BE$4 -> 45671.25 | BF11: =$BA11+BF$4 -> 45701.667 | BG11: =$BA11+BG$4 -> 45732.083 | BH11: =$BA11+BH$4 -> 45762.5 | BI11: =$BA11+BI$4 -> 45792.917 | BJ11: =$BA11+BJ$4 -> 45823.333 | ... CW11: =$BA11+CW$4 -> 47009.583
A12: =A17-7 -> 45483 | B12: =A12 -> 45483 | C12: =$B12+C$4 -> 45513.417 | D12: =$B12+D$4 -> 45543.833 | E12: =$B12+E$4 -> 45574.25 | F12: =$B12+F$4 -> 45604.667 | G12: =$B12+G$4 -> 45635.083 | H12: =$B12+H$4 -> 45665.5 | I12: =$B12+I$4 -> 45695.917 | J12: =$B12+J$4 -> 45726.333 | ... AX12: =$B12+AX$4 -> 46943 | BA12: =BA17-7 -> 45581 | BB12: =BA12 -> 45581 | BC12: =$BA12+BC$4 -> 45611.417 | BD12: =$BA12+BD$4 -> 45641.833 | BE12: =$BA12+BE$4 -> 45672.25 | BF12: =$BA12+BF$4 -> 45702.667 | BG12: =$BA12+BG$4 -> 45733.083 | BH12: =$BA12+BH$4 -> 45763.5 | BI12: =$BA12+BI$4 -> 45793.917 | BJ12: =$BA12+BJ$4 -> 45824.333 | ... CW12: =$BA12+CW$4 -> 47010.583
A13: =A18-7 -> 45484 | B13: =A13 -> 45484 | C13: =$B13+C$4 -> 45514.417 | D13: =$B13+D$4 -> 45544.833 | E13: =$B13+E$4 -> 45575.25 | F13: =$B13+F$4 -> 45605.667 | G13: =$B13+G$4 -> 45636.083 | H13: =$B13+H$4 -> 45666.5 | I13: =$B13+I$4 -> 45696.917 | J13: =$B13+J$4 -> 45727.333 | ... AX13: =$B13+AX$4 -> 46944 | BA13: =BA18-7 -> 45582 | BB13: =BA13 -> 45582 | BC13: =$BA13+BC$4 -> 45612.417 | BD13: =$BA13+BD$4 -> 45642.833 | BE13: =$BA13+BE$4 -> 45673.25 | BF13: =$BA13+BF$4 -> 45703.667 | BG13: =$BA13+BG$4 -> 45734.083 | BH13: =$BA13+BH$4 -> 45764.5 | BI13: =$BA13+BI$4 -> 45794.917 | BJ13: =$BA13+BJ$4 -> 45825.333 | ... CW13: =$BA13+CW$4 -> 47011.583
A14: =A19-7 -> 45485 | B14: =A14 -> 45485 | C14: =$B14+C$4 -> 45515.417 | D14: =$B14+D$4 -> 45545.833 | E14: =$B14+E$4 -> 45576.25 | F14: =$B14+F$4 -> 45606.667 | G14: =$B14+G$4 -> 45637.083 | H14: =$B14+H$4 -> 45667.5 | I14: =$B14+I$4 -> 45697.917 | J14: =$B14+J$4 -> 45728.333 | ... AX14: =$B14+AX$4 -> 46945 | BA14: =BA19-7 -> 45583 | BB14: =BA14 -> 45583 | BC14: =$BA14+BC$4 -> 45613.417 | BD14: =$BA14+BD$4 -> 45643.833 | BE14: =$BA14+BE$4 -> 45674.25 | BF14: =$BA14+BF$4 -> 45704.667 | BG14: =$BA14+BG$4 -> 45735.083 | BH14: =$BA14+BH$4 -> 45765.5 | BI14: =$BA14+BI$4 -> 45795.917 | BJ14: =$BA14+BJ$4 -> 45826.333 | ... CW14: =$BA14+CW$4 -> 47012.583
A15: =A20-7 -> 45488 | B15: =A15 -> 45488 | C15: =$B15+C$4 -> 45518.417 | D15: =$B15+D$4 -> 45548.833 | E15: =$B15+E$4 -> 45579.25 | F15: =$B15+F$4 -> 45609.667 | G15: =$B15+G$4 -> 45640.083 | H15: =$B15+H$4 -> 45670.5 | I15: =$B15+I$4 -> 45700.917 | J15: =$B15+J$4 -> 45731.333 | ... AX15: =$B15+AX$4 -> 46948 | BA15: =BA20-7 -> 45586 | BB15: =BA15 -> 45586 | BC15: =$BA15+BC$4 -> 45616.417 | BD15: =$BA15+BD$4 -> 45646.833 | BE15: =$BA15+BE$4 -> 45677.25 | BF15: =$BA15+BF$4 -> 45707.667 | BG15: =$BA15+BG$4 -> 45738.083 | BH15: =$BA15+BH$4 -> 45768.5 | BI15: =$BA15+BI$4 -> 45798.917 | BJ15: =$BA15+BJ$4 -> 45829.333 | ... CW15: =$BA15+CW$4 -> 47015.583
A16: =+A17-1 -> 45489 | B16: =A16 -> 45489 | C16: =$B16+C$4 -> 45519.417 | D16: =$B16+D$4 -> 45549.833 | E16: =$B16+E$4 -> 45580.25 | F16: =$B16+F$4 -> 45610.667 | G16: =$B16+G$4 -> 45641.083 | H16: =$B16+H$4 -> 45671.5 | I16: =$B16+I$4 -> 45701.917 | J16: =$B16+J$4 -> 45732.333 | ... AX16: =$B16+AX$4 -> 46949 | BA16: =+BA17-1 -> 45587 | BB16: =BA16 -> 45587 | BC16: =$BA16+BC$4 -> 45617.417 | BD16: =$BA16+BD$4 -> 45647.833 | BE16: =$BA16+BE$4 -> 45678.25 | BF16: =$BA16+BF$4 -> 45708.667 | BG16: =$BA16+BG$4 -> 45739.083 | BH16: =$BA16+BH$4 -> 45769.5 | BI16: =$BA16+BI$4 -> 45799.917 | BJ16: =$BA16+BJ$4 -> 45830.333 | ... CW16: =$BA16+CW$4 -> 47016.583
A17: =+A18-1 -> 45490 | B17: =A17 -> 45490 | C17: =$B17+C$4 -> 45520.417 | D17: =$B17+D$4 -> 45550.833 | E17: =$B17+E$4 -> 45581.25 | F17: =$B17+F$4 -> 45611.667 | G17: =$B17+G$4 -> 45642.083 | H17: =$B17+H$4 -> 45672.5 | I17: =$B17+I$4 -> 45702.917 | J17: =$B17+J$4 -> 45733.333 | ... AX17: =$B17+AX$4 -> 46950 | BA17: =+BA18-1 -> 45588 | BB17: =BA17 -> 45588 | BC17: =$BA17+BC$4 -> 45618.417 | BD17: =$BA17+BD$4 -> 45648.833 | BE17: =$BA17+BE$4 -> 45679.25 | BF17: =$BA17+BF$4 -> 45709.667 | BG17: =$BA17+BG$4 -> 45740.083 | BH17: =$BA17+BH$4 -> 45770.5 | BI17: =$BA17+BI$4 -> 45800.917 | BJ17: =$BA17+BJ$4 -> 45831.333 | ... CW17: =$BA17+CW$4 -> 47017.583
A18: =+A19-1 -> 45491 | B18: =A18 -> 45491 | C18: =$B18+C$4 -> 45521.417 | D18: =$B18+D$4 -> 45551.833 | E18: =$B18+E$4 -> 45582.25 | F18: =$B18+F$4 -> 45612.667 | G18: =$B18+G$4 -> 45643.083 | H18: =$B18+H$4 -> 45673.5 | I18: =$B18+I$4 -> 45703.917 | J18: =$B18+J$4 -> 45734.333 | ... AX18: =$B18+AX$4 -> 46951 | BA18: =+BA19-1 -> 45589 | BB18: =BA18 -> 45589 | BC18: =$BA18+BC$4 -> 45619.417 | BD18: =$BA18+BD$4 -> 45649.833 | BE18: =$BA18+BE$4 -> 45680.25 | BF18: =$BA18+BF$4 -> 45710.667 | BG18: =$BA18+BG$4 -> 45741.083 | BH18: =$BA18+BH$4 -> 45771.5 | BI18: =$BA18+BI$4 -> 45801.917 | BJ18: =$BA18+BJ$4 -> 45832.333 | ... CW18: =$BA18+CW$4 -> 47018.583
A19: 45492 | B19: =A19 -> 45492 | C19: =$B19+C$4 -> 45522.417 | D19: =$B19+D$4 -> 45552.833 | E19: =$B19+E$4 -> 45583.25 | F19: =$B19+F$4 -> 45613.667 | G19: =$B19+G$4 -> 45644.083 | H19: =$B19+H$4 -> 45674.5 | I19: =$B19+I$4 -> 45704.917 | J19: =$B19+J$4 -> 45735.333 | ... AX19: =$B19+AX$4 -> 46952 | BA19: 45590 | BB19: =BA19 -> 45590 | BC19: =$BA19+BC$4 -> 45620.417 | BD19: =$BA19+BD$4 -> 45650.833 | BE19: =$BA19+BE$4 -> 45681.25 | BF19: =$BA19+BF$4 -> 45711.667 | BG19: =$BA19+BG$4 -> 45742.083 | BH19: =$BA19+BH$4 -> 45772.5 | BI19: =$BA19+BI$4 -> 45802.917 | BJ19: =$BA19+BJ$4 -> 45833.333 | ... CW19: =$BA19+CW$4 -> 47019.583
A20: 45495 | B20: =A20 -> 45495 | C20: =$B20+C$4 -> 45525.417 | D20: =$B20+D$4 -> 45555.833 | E20: =$B20+E$4 -> 45586.25 | F20: =$B20+F$4 -> 45616.667 | G20: =$B20+G$4 -> 45647.083 | H20: =$B20+H$4 -> 45677.5 | I20: =$B20+I$4 -> 45707.917 | J20: =$B20+J$4 -> 45738.333 | ... AX20: =$B20+AX$4 -> 46955 | BA20: 45593 | BB20: =BA20 -> 45593 | BC20: =$BA20+BC$4 -> 45623.417 | BD20: =$BA20+BD$4 -> 45653.833 | BE20: =$BA20+BE$4 -> 45684.25 | BF20: =$BA20+BF$4 -> 45714.667 | BG20: =$BA20+BG$4 -> 45745.083 | BH20: =$BA20+BH$4 -> 45775.5 | BI20: =$BA20+BI$4 -> 45805.917 | BJ20: =$BA20+BJ$4 -> 45836.333 | ... CW20: =$BA20+CW$4 -> 47022.583
A22: Market expectations | BA22: Market expectations
A23: =A6 -> 45475 | B23: =VLOOKUP($A23,HAVERD!$A:$BS,B$2,FALSE) -> 5.2 | C23: =VLOOKUP($A23,HAVERD!$A:$BS,C$2,FALSE) -> 5.136252 | D23: =VLOOKUP($A23,HAVERD!$A:$BS,D$2,FALSE) -> 5.0458777 | E23: =VLOOKUP($A23,HAVERD!$A:$BS,E$2,FALSE) -> 4.9812657 | F23: =VLOOKUP($A23,HAVERD!$A:$BS,F$2,FALSE) -> 4.9207792 | G23: =VLOOKUP($A23,HAVERD!$A:$BS,G$2,FALSE) -> 4.8541057 | H23: =VLOOKUP($A23,HAVERD!$A:$BS,H$2,FALSE) -> 4.7827699 | I23: =VLOOKUP($A23,HAVERD!$A:$BS,I$2,FALSE) -> 4.7105142 | ... AX23: =VLOOKUP($A23,HAVERD!$A:$BS,AX$2,FALSE) -> 3.5194949 | BA23: =BA6 -> 45573 | BB23: =VLOOKUP($BA23,HAVERD!$A:$BS,BB$2,FALSE) -> #N/A | BC23: =VLOOKUP($BA23,HAVERD!$A:$BS,BC$2,FALSE) -> #N/A | BD23: =VLOOKUP($BA23,HAVERD!$A:$BS,BD$2,FALSE) -> #N/A | BE23: =VLOOKUP($BA23,HAVERD!$A:$BS,BE$2,FALSE) -> #N/A | BF23: =VLOOKUP($BA23,HAVERD!$A:$BS,BF$2,FALSE) -> #N/A | BG23: =VLOOKUP($BA23,HAVERD!$A:$BS,BG$2,FALSE) -> #N/A | BH23: =VLOOKUP($BA23,HAVERD!$A:$BS,BH$2,FALSE) -> #N/A | BI23: =VLOOKUP($BA23,HAVERD!$A:$BS,BI$2,FALSE) -> #N/A | ... CW23: =VLOOKUP($BA23,HAVERD!$A:$BS,CW$2,FALSE) -> #N/A
A24: =A7 -> 45476 | B24: =VLOOKUP($A24,HAVERD!$A:$BS,B$2,FALSE) -> 5.2 | C24: =VLOOKUP($A24,HAVERD!$A:$BS,C$2,FALSE) -> 5.1234718 | D24: =VLOOKUP($A24,HAVERD!$A:$BS,D$2,FALSE) -> 5.0360844 | E24: =VLOOKUP($A24,HAVERD!$A:$BS,E$2,FALSE) -> 4.9704607 | F24: =VLOOKUP($A24,HAVERD!$A:$BS,F$2,FALSE) -> 4.9070404 | G24: =VLOOKUP($A24,HAVERD!$A:$BS,G$2,FALSE) -> 4.8371358 | H24: =VLOOKUP($A24,HAVERD!$A:$BS,H$2,FALSE) -> 4.7628149 | I24: =VLOOKUP($A24,HAVERD!$A:$BS,I$2,FALSE) -> 4.687981 | ... AX24: =VLOOKUP($A24,HAVERD!$A:$BS,AX$2,FALSE) -> 3.4500435 | BA24: =BA7 -> 45574 | BB24: =VLOOKUP($BA24,HAVERD!$A:$BS,BB$2,FALSE) -> #N/A | BC24: =VLOOKUP($BA24,HAVERD!$A:$BS,BC$2,FALSE) -> #N/A | BD24: =VLOOKUP($BA24,HAVERD!$A:$BS,BD$2,FALSE) -> #N/A | BE24: =VLOOKUP($BA24,HAVERD!$A:$BS,BE$2,FALSE) -> #N/A | BF24: =VLOOKUP($BA24,HAVERD!$A:$BS,BF$2,FALSE) -> #N/A | BG24: =VLOOKUP($BA24,HAVERD!$A:$BS,BG$2,FALSE) -> #N/A | BH24: =VLOOKUP($BA24,HAVERD!$A:$BS,BH$2,FALSE) -> #N/A | BI24: =VLOOKUP($BA24,HAVERD!$A:$BS,BI$2,FALSE) -> #N/A | ... CW24: =VLOOKUP($BA24,HAVERD!$A:$BS,CW$2,FALSE) -> #N/A
A25: =A8 -> 45477 | B25: =VLOOKUP($A25,HAVERD!$A:$BS,B$2,FALSE) -> 5.2 | C25: =VLOOKUP($A25,HAVERD!$A:$BS,C$2,FALSE) -> 5.1204583 | D25: =VLOOKUP($A25,HAVERD!$A:$BS,D$2,FALSE) -> 5.0323288 | E25: =VLOOKUP($A25,HAVERD!$A:$BS,E$2,FALSE) -> 4.9651069 | F25: =VLOOKUP($A25,HAVERD!$A:$BS,F$2,FALSE) -> 4.8999988 | G25: =VLOOKUP($A25,HAVERD!$A:$BS,G$2,FALSE) -> 4.8292264 | H25: =VLOOKUP($A25,HAVERD!$A:$BS,H$2,FALSE) -> 4.7546948 | I25: =VLOOKUP($A25,HAVERD!$A:$BS,I$2,FALSE) -> 4.6797389 | ... AX25: =VLOOKUP($A25,HAVERD!$A:$BS,AX$2,FALSE) -> 3.499697 | BA25: =BA8 -> 45575 | BB25: =VLOOKUP($BA25,HAVERD!$A:$BS,BB$2,FALSE) -> #N/A | BC25: =VLOOKUP($BA25,HAVERD!$A:$BS,BC$2,FALSE) -> #N/A | BD25: =VLOOKUP($BA25,HAVERD!$A:$BS,BD$2,FALSE) -> #N/A | BE25: =VLOOKUP($BA25,HAVERD!$A:$BS,BE$2,FALSE) -> #N/A | BF25: =VLOOKUP($BA25,HAVERD!$A:$BS,BF$2,FALSE) -> #N/A | BG25: =VLOOKUP($BA25,HAVERD!$A:$BS,BG$2,FALSE) -> #N/A | BH25: =VLOOKUP($BA25,HAVERD!$A:$BS,BH$2,FALSE) -> #N/A | BI25: =VLOOKUP($BA25,HAVERD!$A:$BS,BI$2,FALSE) -> #N/A | ... CW25: =VLOOKUP($BA25,HAVERD!$A:$BS,CW$2,FALSE) -> #N/A
A26: =A9 -> 45478 | B26: =VLOOKUP($A26,HAVERD!$A:$BS,B$2,FALSE) -> 5.2 | C26: =VLOOKUP($A26,HAVERD!$A:$BS,C$2,FALSE) -> 5.1110264 | D26: =VLOOKUP($A26,HAVERD!$A:$BS,D$2,FALSE) -> 5.0182524 | E26: =VLOOKUP($A26,HAVERD!$A:$BS,E$2,FALSE) -> 4.9469981 | F26: =VLOOKUP($A26,HAVERD!$A:$BS,F$2,FALSE) -> 4.8774441 | G26: =VLOOKUP($A26,HAVERD!$A:$BS,G$2,FALSE) -> 4.8016677 | H26: =VLOOKUP($A26,HAVERD!$A:$BS,H$2,FALSE) -> 4.7220228 | I26: =VLOOKUP($A26,HAVERD!$A:$BS,I$2,FALSE) -> 4.6420148 | ... AX26: =VLOOKUP($A26,HAVERD!$A:$BS,AX$2,FALSE) -> 3.4525486 | BA26: =BA9 -> 45576 | BB26: =VLOOKUP($BA26,HAVERD!$A:$BS,BB$2,FALSE) -> #N/A | BC26: =VLOOKUP($BA26,HAVERD!$A:$BS,BC$2,FALSE) -> #N/A | BD26: =VLOOKUP($BA26,HAVERD!$A:$BS,BD$2,FALSE) -> #N/A | BE26: =VLOOKUP($BA26,HAVERD!$A:$BS,BE$2,FALSE) -> #N/A | BF26: =VLOOKUP($BA26,HAVERD!$A:$BS,BF$2,FALSE) -> #N/A | BG26: =VLOOKUP($BA26,HAVERD!$A:$BS,BG$2,FALSE) -> #N/A | BH26: =VLOOKUP($BA26,HAVERD!$A:$BS,BH$2,FALSE) -> #N/A | BI26: =VLOOKUP($BA26,HAVERD!$A:$BS,BI$2,FALSE) -> #N/A | ... CW26: =VLOOKUP($BA26,HAVERD!$A:$BS,CW$2,FALSE) -> #N/A
A27: =A10 -> 45481 | B27: =VLOOKUP($A27,HAVERD!$A:$BS,B$2,FALSE) -> 5.2 | C27: =VLOOKUP($A27,HAVERD!$A:$BS,C$2,FALSE) -> 5.1003777 | D27: =VLOOKUP($A27,HAVERD!$A:$BS,D$2,FALSE) -> 5.0193512 | E27: =VLOOKUP($A27,HAVERD!$A:$BS,E$2,FALSE) -> 4.9524209 | F27: =VLOOKUP($A27,HAVERD!$A:$BS,F$2,FALSE) -> 4.8817792 | G27: =VLOOKUP($A27,HAVERD!$A:$BS,G$2,FALSE) -> 4.8028356 | H27: =VLOOKUP($A27,HAVERD!$A:$BS,H$2,FALSE) -> 4.7200436 | I27: =VLOOKUP($A27,HAVERD!$A:$BS,I$2,FALSE) -> 4.6378883 | ... AX27: =VLOOKUP($A27,HAVERD!$A:$BS,AX$2,FALSE) -> 3.4001976 | BA27: =BA10 -> 45579 | BB27: =VLOOKUP($BA27,HAVERD!$A:$BS,BB$2,FALSE) -> #N/A | BC27: =VLOOKUP($BA27,HAVERD!$A:$BS,BC$2,FALSE) -> #N/A | BD27: =VLOOKUP($BA27,HAVERD!$A:$BS,BD$2,FALSE) -> #N/A | BE27: =VLOOKUP($BA27,HAVERD!$A:$BS,BE$2,FALSE) -> #N/A | BF27: =VLOOKUP($BA27,HAVERD!$A:$BS,BF$2,FALSE) -> #N/A | BG27: =VLOOKUP($BA27,HAVERD!$A:$BS,BG$2,FALSE) -> #N/A | BH27: =VLOOKUP($BA27,HAVERD!$A:$BS,BH$2,FALSE) -> #N/A | BI27: =VLOOKUP($BA27,HAVERD!$A:$BS,BI$2,FALSE) -> #N/A | ... CW27: =VLOOKUP($BA27,HAVERD!$A:$BS,CW$2,FALSE) -> #N/A
A28: =A11 -> 45482 | B28: =VLOOKUP($A28,HAVERD!$A:$BS,B$2,FALSE) -> 5.2 | C28: =VLOOKUP($A28,HAVERD!$A:$BS,C$2,FALSE) -> 5.096547 | D28: =VLOOKUP($A28,HAVERD!$A:$BS,D$2,FALSE) -> 5.0182862 | E28: =VLOOKUP($A28,HAVERD!$A:$BS,E$2,FALSE) -> 4.9517053 | F28: =VLOOKUP($A28,HAVERD!$A:$BS,F$2,FALSE) -> 4.8809924 | G28: =VLOOKUP($A28,HAVERD!$A:$BS,G$2,FALSE) -> 4.8026843 | H28: =VLOOKUP($A28,HAVERD!$A:$BS,H$2,FALSE) -> 4.7214162 | I28: =VLOOKUP($A28,HAVERD!$A:$BS,I$2,FALSE) -> 4.641473 | ... AX28: =VLOOKUP($A28,HAVERD!$A:$BS,AX$2,FALSE) -> 3.4410117 | BA28: =BA11 -> 45580 | BB28: =VLOOKUP($BA28,HAVERD!$A:$BS,BB$2,FALSE) -> #N/A | BC28: =VLOOKUP($BA28,HAVERD!$A:$BS,BC$2,FALSE) -> #N/A | BD28: =VLOOKUP($BA28,HAVERD!$A:$BS,BD$2,FALSE) -> #N/A | BE28: =VLOOKUP($BA28,HAVERD!$A:$BS,BE$2,FALSE) -> #N/A | BF28: =VLOOKUP($BA28,HAVERD!$A:$BS,BF$2,FALSE) -> #N/A | BG28: =VLOOKUP($BA28,HAVERD!$A:$BS,BG$2,FALSE) -> #N/A | BH28: =VLOOKUP($BA28,HAVERD!$A:$BS,BH$2,FALSE) -> #N/A | BI28: =VLOOKUP($BA28,HAVERD!$A:$BS,BI$2,FALSE) -> #N/A | ... CW28: =VLOOKUP($BA28,HAVERD!$A:$BS,CW$2,FALSE) -> #N/A
A29: =A12 -> 45483 | B29: =VLOOKUP($A29,HAVERD!$A:$BS,B$2,FALSE) -> 5.2 | C29: =VLOOKUP($A29,HAVERD!$A:$BS,C$2,FALSE) -> 5.1042224 | D29: =VLOOKUP($A29,HAVERD!$A:$BS,D$2,FALSE) -> 5.0320985 | E29: =VLOOKUP($A29,HAVERD!$A:$BS,E$2,FALSE) -> 4.9630142 | F29: =VLOOKUP($A29,HAVERD!$A:$BS,F$2,FALSE) -> 4.8865742 | G29: =VLOOKUP($A29,HAVERD!$A:$BS,G$2,FALSE) -> 4.8036903 | H29: =VLOOKUP($A29,HAVERD!$A:$BS,H$2,FALSE) -> 4.7199091 | I29: =VLOOKUP($A29,HAVERD!$A:$BS,I$2,FALSE) -> 4.6387821 | ... AX29: =VLOOKUP($A29,HAVERD!$A:$BS,AX$2,FALSE) -> 3.4171134 | BA29: =BA12 -> 45581 | BB29: =VLOOKUP($BA29,HAVERD!$A:$BS,BB$2,FALSE) -> #N/A | BC29: =VLOOKUP($BA29,HAVERD!$A:$BS,BC$2,FALSE) -> #N/A | BD29: =VLOOKUP($BA29,HAVERD!$A:$BS,BD$2,FALSE) -> #N/A | BE29: =VLOOKUP($BA29,HAVERD!$A:$BS,BE$2,FALSE) -> #N/A | BF29: =VLOOKUP($BA29,HAVERD!$A:$BS,BF$2,FALSE) -> #N/A | BG29: =VLOOKUP($BA29,HAVERD!$A:$BS,BG$2,FALSE) -> #N/A | BH29: =VLOOKUP($BA29,HAVERD!$A:$BS,BH$2,FALSE) -> #N/A | BI29: =VLOOKUP($BA29,HAVERD!$A:$BS,BI$2,FALSE) -> #N/A | ... CW29: =VLOOKUP($BA29,HAVERD!$A:$BS,CW$2,FALSE) -> #N/A
A30: =A13 -> 45484 | B30: =VLOOKUP($A30,HAVERD!$A:$BS,B$2,FALSE) -> 5.2 | C30: =VLOOKUP($A30,HAVERD!$A:$BS,C$2,FALSE) -> 5.0945082 | D30: =VLOOKUP($A30,HAVERD!$A:$BS,D$2,FALSE) -> 5.0217773 | E30: =VLOOKUP($A30,HAVERD!$A:$BS,E$2,FALSE) -> 4.9511235 | F30: =VLOOKUP($A30,HAVERD!$A:$BS,F$2,FALSE) -> 4.8706331 | G30: =VLOOKUP($A30,HAVERD!$A:$BS,G$2,FALSE) -> 4.7813489 | H30: =VLOOKUP($A30,HAVERD!$A:$BS,H$2,FALSE) -> 4.6895095 | I30: =VLOOKUP($A30,HAVERD!$A:$BS,I$2,FALSE) -> 4.5990318 | ... AX30: =VLOOKUP($A30,HAVERD!$A:$BS,AX$2,FALSE) -> 3.3787976 | BA30: =BA13 -> 45582 | BB30: =VLOOKUP($BA30,HAVERD!$A:$BS,BB$2,FALSE) -> #N/A | BC30: =VLOOKUP($BA30,HAVERD!$A:$BS,BC$2,FALSE) -> #N/A | BD30: =VLOOKUP($BA30,HAVERD!$A:$BS,BD$2,FALSE) -> #N/A | BE30: =VLOOKUP($BA30,HAVERD!$A:$BS,BE$2,FALSE) -> #N/A | BF30: =VLOOKUP($BA30,HAVERD!$A:$BS,BF$2,FALSE) -> #N/A | BG30: =VLOOKUP($BA30,HAVERD!$A:$BS,BG$2,FALSE) -> #N/A | BH30: =VLOOKUP($BA30,HAVERD!$A:$BS,BH$2,FALSE) -> #N/A | BI30: =VLOOKUP($BA30,HAVERD!$A:$BS,BI$2,FALSE) -> #N/A | ... CW30: =VLOOKUP($BA30,HAVERD!$A:$BS,CW$2,FALSE) -> #N/A
A31: =A14 -> 45485 | B31: =VLOOKUP($A31,HAVERD!$A:$BS,B$2,FALSE) -> 5.2 | C31: =VLOOKUP($A31,HAVERD!$A:$BS,C$2,FALSE) -> 5.1031083 | D31: =VLOOKUP($A31,HAVERD!$A:$BS,D$2,FALSE) -> 5.0352073 | E31: =VLOOKUP($A31,HAVERD!$A:$BS,E$2,FALSE) -> 4.9632403 | F31: =VLOOKUP($A31,HAVERD!$A:$BS,F$2,FALSE) -> 4.8806377 | G31: =VLOOKUP($A31,HAVERD!$A:$BS,G$2,FALSE) -> 4.7906448 | H31: =VLOOKUP($A31,HAVERD!$A:$BS,H$2,FALSE) -> 4.6995387 | I31: =VLOOKUP($A31,HAVERD!$A:$BS,I$2,FALSE) -> 4.6110254 | ... AX31: =VLOOKUP($A31,HAVERD!$A:$BS,AX$2,FALSE) -> 3.4355071 | BA31: =BA14 -> 45583 | BB31: =VLOOKUP($BA31,HAVERD!$A:$BS,BB$2,FALSE) -> #N/A | BC31: =VLOOKUP($BA31,HAVERD!$A:$BS,BC$2,FALSE) -> #N/A | BD31: =VLOOKUP($BA31,HAVERD!$A:$BS,BD$2,FALSE) -> #N/A | BE31: =VLOOKUP($BA31,HAVERD!$A:$BS,BE$2,FALSE) -> #N/A | BF31: =VLOOKUP($BA31,HAVERD!$A:$BS,BF$2,FALSE) -> #N/A | BG31: =VLOOKUP($BA31,HAVERD!$A:$BS,BG$2,FALSE) -> #N/A | BH31: =VLOOKUP($BA31,HAVERD!$A:$BS,BH$2,FALSE) -> #N/A | BI31: =VLOOKUP($BA31,HAVERD!$A:$BS,BI$2,FALSE) -> #N/A | ... CW31: =VLOOKUP($BA31,HAVERD!$A:$BS,CW$2,FALSE) -> #N/A
A32: =A15 -> 45488 | B32: =VLOOKUP($A32,HAVERD!$A:$BS,B$2,FALSE) -> 5.2 | C32: =VLOOKUP($A32,HAVERD!$A:$BS,C$2,FALSE) -> 5.0946079 | D32: =VLOOKUP($A32,HAVERD!$A:$BS,D$2,FALSE) -> 5.0373513 | E32: =VLOOKUP($A32,HAVERD!$A:$BS,E$2,FALSE) -> 4.9645256 | F32: =VLOOKUP($A32,HAVERD!$A:$BS,F$2,FALSE) -> 4.8771415 | G32: =VLOOKUP($A32,HAVERD!$A:$BS,G$2,FALSE) -> 4.7822119 | H32: =VLOOKUP($A32,HAVERD!$A:$BS,H$2,FALSE) -> 4.6868572 | I32: =VLOOKUP($A32,HAVERD!$A:$BS,I$2,FALSE) -> 4.5953285 | ... AX32: =VLOOKUP($A32,HAVERD!$A:$BS,AX$2,FALSE) -> 3.3980712 | BA32: =BA15 -> 45586 | BB32: =VLOOKUP($BA32,HAVERD!$A:$BS,BB$2,FALSE) -> #N/A | BC32: =VLOOKUP($BA32,HAVERD!$A:$BS,BC$2,FALSE) -> #N/A | BD32: =VLOOKUP($BA32,HAVERD!$A:$BS,BD$2,FALSE) -> #N/A | BE32: =VLOOKUP($BA32,HAVERD!$A:$BS,BE$2,FALSE) -> #N/A | BF32: =VLOOKUP($BA32,HAVERD!$A:$BS,BF$2,FALSE) -> #N/A | BG32: =VLOOKUP($BA32,HAVERD!$A:$BS,BG$2,FALSE) -> #N/A | BH32: =VLOOKUP($BA32,HAVERD!$A:$BS,BH$2,FALSE) -> #N/A | BI32: =VLOOKUP($BA32,HAVERD!$A:$BS,BI$2,FALSE) -> #N/A | ... CW32: =VLOOKUP($BA32,HAVERD!$A:$BS,CW$2,FALSE) -> #N/A
A33: =A16 -> 45489 | B33: =VLOOKUP($A33,HAVERD!$A:$BS,B$2,FALSE) -> 5.2 | C33: =VLOOKUP($A33,HAVERD!$A:$BS,C$2,FALSE) -> 5.0913668 | D33: =VLOOKUP($A33,HAVERD!$A:$BS,D$2,FALSE) -> 5.0388587 | E33: =VLOOKUP($A33,HAVERD!$A:$BS,E$2,FALSE) -> 4.9656485 | F33: =VLOOKUP($A33,HAVERD!$A:$BS,F$2,FALSE) -> 4.8757257 | G33: =VLOOKUP($A33,HAVERD!$A:$BS,G$2,FALSE) -> 4.7770689 | H33: =VLOOKUP($A33,HAVERD!$A:$BS,H$2,FALSE) -> 4.6770052 | I33: =VLOOKUP($A33,HAVERD!$A:$BS,I$2,FALSE) -> 4.5801525 | ... AX33: =VLOOKUP($A33,HAVERD!$A:$BS,AX$2,FALSE) -> 3.3356155 | BA33: =BA16 -> 45587 | BB33: =VLOOKUP($BA33,HAVERD!$A:$BS,BB$2,FALSE) -> #N/A | BC33: =VLOOKUP($BA33,HAVERD!$A:$BS,BC$2,FALSE) -> #N/A | BD33: =VLOOKUP($BA33,HAVERD!$A:$BS,BD$2,FALSE) -> #N/A | BE33: =VLOOKUP($BA33,HAVERD!$A:$BS,BE$2,FALSE) -> #N/A | BF33: =VLOOKUP($BA33,HAVERD!$A:$BS,BF$2,FALSE) -> #N/A | BG33: =VLOOKUP($BA33,HAVERD!$A:$BS,BG$2,FALSE) -> #N/A | BH33: =VLOOKUP($BA33,HAVERD!$A:$BS,BH$2,FALSE) -> #N/A | BI33: =VLOOKUP($BA33,HAVERD!$A:$BS,BI$2,FALSE) -> #N/A | ... CW33: =VLOOKUP($BA33,HAVERD!$A:$BS,CW$2,FALSE) -> #N/A
A34: =A17 -> 45490 | B34: =VLOOKUP($A34,HAVERD!$A:$BS,B$2,FALSE) -> 5.2 | C34: =VLOOKUP($A34,HAVERD!$A:$BS,C$2,FALSE) -> 5.114171 | D34: =VLOOKUP($A34,HAVERD!$A:$BS,D$2,FALSE) -> 5.0628366 | E34: =VLOOKUP($A34,HAVERD!$A:$BS,E$2,FALSE) -> 4.9891878 | F34: =VLOOKUP($A34,HAVERD!$A:$BS,F$2,FALSE) -> 4.9001319 | G34: =VLOOKUP($A34,HAVERD!$A:$BS,G$2,FALSE) -> 4.8037042 | H34: =VLOOKUP($A34,HAVERD!$A:$BS,H$2,FALSE) -> 4.7062092 | I34: =VLOOKUP($A34,HAVERD!$A:$BS,I$2,FALSE) -> 4.6115039 | ... AX34: =VLOOKUP($A34,HAVERD!$A:$BS,AX$2,FALSE) -> 3.3739323 | BA34: =BA17 -> 45588 | BB34: =VLOOKUP($BA34,HAVERD!$A:$BS,BB$2,FALSE) -> #N/A | BC34: =VLOOKUP($BA34,HAVERD!$A:$BS,BC$2,FALSE) -> #N/A | BD34: =VLOOKUP($BA34,HAVERD!$A:$BS,BD$2,FALSE) -> #N/A | BE34: =VLOOKUP($BA34,HAVERD!$A:$BS,BE$2,FALSE) -> #N/A | BF34: =VLOOKUP($BA34,HAVERD!$A:$BS,BF$2,FALSE) -> #N/A | BG34: =VLOOKUP($BA34,HAVERD!$A:$BS,BG$2,FALSE) -> #N/A | BH34: =VLOOKUP($BA34,HAVERD!$A:$BS,BH$2,FALSE) -> #N/A | BI34: =VLOOKUP($BA34,HAVERD!$A:$BS,BI$2,FALSE) -> #N/A | ... CW34: =VLOOKUP($BA34,HAVERD!$A:$BS,CW$2,FALSE) -> #N/A
... A37: =A20 -> 45495 | B37: =VLOOKUP($A37,HAVERD!$A:$BS,B$2,FALSE) -> 5.2 | C37: =VLOOKUP($A37,HAVERD!$A:$BS,C$2,FALSE) -> 5.0981736 | D37: =VLOOKUP($A37,HAVERD!$A:$BS,D$2,FALSE) -> 5.0525574 | E37: =VLOOKUP($A37,HAVERD!$A:$BS,E$2,FALSE) -> 4.9866557 | F37: =VLOOKUP($A37,HAVERD!$A:$BS,F$2,FALSE) -> 4.9069106 | G37: =VLOOKUP($A37,HAVERD!$A:$BS,G$2,FALSE) -> 4.8212351 | H37: =VLOOKUP($A37,HAVERD!$A:$BS,H$2,FALSE) -> 4.7344874 | I37: =VLOOKUP($A37,HAVERD!$A:$BS,I$2,FALSE) -> 4.6498897 | ... AX37: =VLOOKUP($A37,HAVERD!$A:$BS,AX$2,FALSE) -> 3.4707482 | BA37: =BA20 -> 45593 | BB37: =VLOOKUP($BA37,HAVERD!$A:$BS,BB$2,FALSE) -> #N/A | BC37: =VLOOKUP($BA37,HAVERD!$A:$BS,BC$2,FALSE) -> #N/A | BD37: =VLOOKUP($BA37,HAVERD!$A:$BS,BD$2,FALSE) -> #N/A | BE37: =VLOOKUP($BA37,HAVERD!$A:$BS,BE$2,FALSE) -> #N/A | BF37: =VLOOKUP($BA37,HAVERD!$A:$BS,BF$2,FALSE) -> #N/A | BG37: =VLOOKUP($BA37,HAVERD!$A:$BS,BG$2,FALSE) -> #N/A | BH37: =VLOOKUP($BA37,HAVERD!$A:$BS,BH$2,FALSE) -> #N/A | BI37: =VLOOKUP($BA37,HAVERD!$A:$BS,BI$2,FALSE) -> #N/A | ... CW37: =VLOOKUP($BA37,HAVERD!$A:$BS,CW$2,FALSE) -> #N/A
A39: Average | BA39: Average
A40: Month | B40: =MONTH(B20) -> 7 | C40: =MONTH(C20) -> 8 | D40: =MONTH(D20) -> 9 | E40: =MONTH(E20) -> 10 | F40: =MONTH(F20) -> 11 | G40: =MONTH(G20) -> 12 | H40: =MONTH(H20) -> 1 | I40: =MONTH(I20) -> 2 | ... AX40: =MONTH(AX20) -> 7 | BA40: Month | BB40: =MONTH(BB20) -> 10 | BC40: =MONTH(BC20) -> 11 | BD40: =MONTH(BD20) -> 12 | BE40: =MONTH(BE20) -> 1 | BF40: =MONTH(BF20) -> 2 | BG40: =MONTH(BG20) -> 3 | BH40: =MONTH(BH20) -> 4 | BI40: =MONTH(BI20) -> 5 | ... CW40: =MONTH(CW20) -> 9
A41: Year | B41: =YEAR(B20) -> 2024 | C41: =YEAR(C20) -> 2024 | D41: =YEAR(D20) -> 2024 | E41: =YEAR(E20) -> 2024 | F41: =YEAR(F20) -> 2024 | G41: =YEAR(G20) -> 2024 | H41: =YEAR(H20) -> 2025 | I41: =YEAR(I20) -> 2025 | ... AX41: =YEAR(AX20) -> 2028 | BA41: Year | BB41: =YEAR(BB20) -> 2024 | BC41: =YEAR(BC20) -> 2024 | BD41: =YEAR(BD20) -> 2024 | BE41: =YEAR(BE20) -> 2025 | BF41: =YEAR(BF20) -> 2025 | BG41: =YEAR(BG20) -> 2025 | BH41: =YEAR(BH20) -> 2025 | BI41: =YEAR(BI20) -> 2025 | ... CW41: =YEAR(CW20) -> 2028
A42: YYYYMM | B42: =B41*100+B40 -> 202407 | C42: =C41*100+C40 -> 202408 | D42: =D41*100+D40 -> 202409 | E42: =E41*100+E40 -> 202410 | F42: =F41*100+F40 -> 202411 | G42: =G41*100+G40 -> 202412 | H42: =H41*100+H40 -> 202501 | I42: =I41*100+I40 -> 202502 | ... AX42: =AX41*100+AX40 -> 202807 | BA42: YYYYMM | BB42: =BB41*100+BB40 -> 202410 | BC42: =BC41*100+BC40 -> 202411 | BD42: =BD41*100+BD40 -> 202412 | BE42: =BE41*100+BE40 -> 202501 | BF42: =BF41*100+BF40 -> 202502 | BG42: =BG41*100+BG40 -> 202503 | BH42: =BH41*100+BH40 -> 202504 | BI42: =BI41*100+BI40 -> 202505 | ... CW42: =CW41*100+CW40 -> 202809
A43: Quarter | B43: =IF(B40<4,1,IF(B40<7,2,IF(B40<10,3,4))) -> 3 | C43: =IF(C40<4,1,IF(C40<7,2,IF(C40<10,3,4))) -> 3 | D43: =IF(D40<4,1,IF(D40<7,2,IF(D40<10,3,4))) -> 3 | E43: =IF(E40<4,1,IF(E40<7,2,IF(E40<10,3,4))) -> 4 | F43: =IF(F40<4,1,IF(F40<7,2,IF(F40<10,3,4))) -> 4 | G43: =IF(G40<4,1,IF(G40<7,2,IF(G40<10,3,4))) -> 4 | H43: =IF(H40<4,1,IF(H40<7,2,IF(H40<10,3,4))) -> 1 | I43: =IF(I40<4,1,IF(I40<7,2,IF(I40<10,3,4))) -> 1 | ... AX43: =IF(AX40<4,1,IF(AX40<7,2,IF(AX40<10,3,4))) -> 3 | BA43: Quarter | BB43: =IF(BB40<4,1,IF(BB40<7,2,IF(BB40<10,3,4))) -> 4 | BC43: =IF(BC40<4,1,IF(BC40<7,2,IF(BC40<10,3,4))) -> 4 | BD43: =IF(BD40<4,1,IF(BD40<7,2,IF(BD40<10,3,4))) -> 4 | BE43: =IF(BE40<4,1,IF(BE40<7,2,IF(BE40<10,3,4))) -> 1 | BF43: =IF(BF40<4,1,IF(BF40<7,2,IF(BF40<10,3,4))) -> 1 | BG43: =IF(BG40<4,1,IF(BG40<7,2,IF(BG40<10,3,4))) -> 1 | BH43: =IF(BH40<4,1,IF(BH40<7,2,IF(BH40<10,3,4))) -> 2 | BI43: =IF(BI40<4,1,IF(BI40<7,2,IF(BI40<10,3,4))) -> 2 | ... CW43: =IF(CW40<4,1,IF(CW40<7,2,IF(CW40<10,3,4))) -> 3
A44: YYYYQQ | B44: =B41*100+B43 -> 202403 | C44: =C41*100+C43 -> 202403 | D44: =D41*100+D43 -> 202403 | E44: =E41*100+E43 -> 202404 | F44: =F41*100+F43 -> 202404 | G44: =G41*100+G43 -> 202404 | H44: =H41*100+H43 -> 202501 | I44: =I41*100+I43 -> 202501 | ... AX44: =AX41*100+AX43 -> 202803 | BA44: YYYYQQ | BB44: =BB41*100+BB43 -> 202404 | BC44: =BC41*100+BC43 -> 202404 | BD44: =BD41*100+BD43 -> 202404 | BE44: =BE41*100+BE43 -> 202501 | BF44: =BF41*100+BF43 -> 202501 | BG44: =BG41*100+BG43 -> 202501 | BH44: =BH41*100+BH43 -> 202502 | BI44: =BI41*100+BI43 -> 202502 | ... CW44: =CW41*100+CW43 -> 202803
...

Sheet MPR Chart 2.16
A1: Section 2: Current economic conditions
A3: Chart 2.16 - Contributions to CPI inflation
B5: Contributions | H5: Inflation rates
A6: Date | B6: Food | C6: Electricity and gas | D6: Fuels and lubricants | E6: Other goods | F6: Services | H6: Food | I6: Electricity and gas | J6: Fuels and lubricants | K6: Other goods | L6: Services | M6: Total CPI
A7: 44227 | B7: -0.1 | C7: -0.3 | D7: -0.3 | E7: 0.4 | F7: 0.8 | H7: -0.7 | I7: -8.4 | J7: -8.2 | K7: 1.4 | L7: 1.7 | M7: 0.7
A8: 44255 | B8: 0 | C8: -0.3 | D8: -0.1 | E8: 0.1 | F8: 0.7 | H8: -0.6 | I8: -7.9 | J8: -3.5 | K8: 0.5 | L8: 1.5 | M8: 0.4
A9: 44286 | B9: -0.1 | C9: -0.2 | D9: 0.1 | E9: 0.3 | F9: 0.7 | H9: -1.4 | I9: -7.3 | J9: 3.5 | K9: 0.9 | L9: 1.5 | M9: 0.7
A10: 44316 | B10: 0 | C10: 0.1 | D10: 0.4 | E10: 0.4 | F10: 0.7 | H10: -0.4 | I10: 2.4 | J10: 13.6 | K10: 1.2 | L10: 1.6 | M10: 1.5
A11: 44347 | B11: -0.1 | C11: 0.1 | D11: 0.5 | E11: 0.8 | F11: 0.9 | H11: -1.3 | I11: 2.6 | J11: 17.9 | K11: 2.2 | L11: 1.9 | M11: 2.1
A12: 44377 | B12: 0 | C12: 0.1 | D12: 0.5 | E12: 1 | F12: 0.9 | H12: -0.6 | I12: 2.5 | J12: 20.3 | K12: 2.7 | L12: 2.1 | M12: 2.5
A13: 44408 | B13: -0.1 | C13: 0.1 | D13: 0.5 | E13: 0.8 | F13: 0.7 | H13: -0.6 | I13: 2.6 | J13: 17.7 | K13: 2.3 | L13: 1.6 | M13: 2
A14: 44439 | B14: 0.1 | C14: 0.1 | D14: 0.5 | E14: 1.2 | F14: 1.4 | H14: 0.3 | I14: 2.6 | J14: 17.7 | K14: 3.2 | L14: 3 | M14: 3.2
A15: 44469 | B15: 0.1 | C15: 0.1 | D15: 0.5 | E15: 1.3 | F15: 1.1 | H15: 0.8 | I15: 2.8 | J15: 17.8 | K15: 3.3 | L15: 2.6 | M15: 3.1
A16: 44500 | B16: 0.2 | C16: 0.8 | D16: 0.6 | E16: 1.3 | F16: 1.4 | H16: 1.2 | I16: 22.9 | J16: 21.5 | K16: 3.4 | L16: 3.2 | M16: 4.2
A17: 44530 | B17: 0.3 | C17: 0.8 | D17: 0.7 | E17: 1.9 | F17: 1.5 | H17: 2.5 | I17: 23.2 | J17: 28.5 | K17: 4.8 | L17: 3.3 | M17: 5.1
A18: 44561 | B18: 0.5 | C18: 0.7 | D18: 0.7 | E18: 2 | F18: 1.5 | H18: 4.2 | I18: 22.7 | J18: 26.8 | K18: 5 | L18: 3.4 | M18: 5.4
... A48: 45444 | B48: 0.2 | C48: -1.3 | D48: 0.1 | E48: 0.3 | F48: 2.7 | H48: 1.5 | I48: -27.2 | J48: 2.6 | K48: 0.8 | L48: 5.7 | M48: 2
A49: July 2024 (Bank staff projections) | B49: 0.159 | C49: -0.828 | D49: 0.054 | E49: 0.281 | F49: 2.7 | H49: 1.31 | I49: -20.122 | J49: 1.894 | K49: 0.831 | L49: 5.563 | M49: 2.366
A50: August 2024 (Bank staff projections) | B50: 0.156 | C50: -0.838 | D50: -0.024 | E50: 0.245 | F50: 2.827 | H50: 1.313 | I50: -20.372 | J50: -1.018 | K50: 0.735 | L50: 5.84 | M50: 2.367
A51: September 2024 (Bank staff projections) | B51: 0.142 | C51: -0.84 | D51: -0.086 | E51: 0.21 | F51: 2.67 | H51: 1.191 | I51: -20.502 | J51: -3.285 | K51: 0.647 | L51: 5.52 | M51: 2.097
A52: October 2024 (Bank staff projections) | B52: 0.112 | C52: -0.329 | D52: -0.109 | E52: 0.249 | F52: 2.675 | H52: 0.928 | I52: -8.466 | J52: -4.125 | K52: 0.768 | L52: 5.502 | M52: 2.6
A53: November 2024 (Bank staff projections) | B53: 0.091 | C53: -0.324 | D53: -0.025 | E53: 0.396 | F53: 2.625 | H53: 0.764 | I53: -8.329 | J53: -1.368 | K53: 1.207 | L53: 5.395 | M53: 2.763
A54: December 2024 (Bank staff projections) | B54: 0.081 | C54: -0.32 | D54: 0.132 | E54: 0.31 | F54: 2.596 | H54: 0.719 | I54: -8.249 | J54: 4.225 | K54: 0.953 | L54: 5.286 | M54: 2.8
A56: 2025 Q1 (Bank staff projection) | B56: n.a. | C56: n.a. | D56: n.a. | E56: n.a. | F56: n.a. | H56: n.a. | I56: n.a. | J56: n.a. | K56: n.a. | L56: n.a. | M56: 2.67

Sheet MPR Chart 2.21
A1: Section 2: Current economic conditions
A3: Chart 2.21 - Measures of annual pay growth
B5: Quarterly frequency | F5: Monthly frequency
A6: Date | B6: AWE private sector regular pay | C6: Indicator-based model | E6: Date | F6: AWE private sector regular pay | G6: KPMG/REC survey (advanced 12 months) | H6: HMRC RTI private sector median | I6: Indeed Wage Tracker
A7: 2018 Q1 | B7: 3 | C7: 2.9 | E7: 43131 | F7: 2.7 | G7: No permissions | H7: 3.1 | I7: n.a.
A8: 2018 Q2 | B8: 2.8 | C8: 3 | E8: 43159 | F8: 2.9 | H8: 3.2 | I8: n.a.
A9: 2018 Q3 | B9: 3.3 | C9: 3.2 | E9: 43190 | F9: 3 | H9: 3.2 | I9: n.a.
A10: 2018 Q4 | B10: 3.5 | C10: 3.4 | E10: 43220 | F10: 3 | H10: 3 | I10: n.a.
A11: 2019 Q1 | B11: 3.6 | C11: 3.4 | E11: 43251 | F11: 2.9 | H11: 3.2 | I11: n.a.
A12: 2019 Q2 | B12: 3.9 | C12: 3.5 | E12: 43281 | F12: 2.8 | H12: 3.4 | I12: n.a.
A13: 2019 Q3 | B13: 3.7 | C13: 3.4 | E13: 43312 | F13: 3 | H13: 3.7 | I13: n.a.
A14: 2019 Q4 | B14: 3.2 | C14: 3.2 | E14: 43343 | F14: 3.2 | H14: 3.9 | I14: n.a.
A15: 2020 Q1 | B15: 2.5 | C15: 3 | E15: 43373 | F15: 3.3 | H15: 3.8 | I15: n.a.
A16: 2020 Q2 | B16: -1.2 | C16: 2.2 | E16: 43404 | F16: 3.4 | H16: 3.8 | I16: n.a.
A17: 2020 Q3 | B17: 1.4 | C17: 1.4 | E17: 43434 | F17: 3.4 | H17: 3.7 | I17: n.a.
A18: 2020 Q4 | B18: 4 | C18: 1.3 | E18: 43465 | F18: 3.5 | H18: 3.7 | I18: n.a.
A19: 2021 Q1 | B19: 4.3 | C19: 1.1 | E19: 43496 | F19: 3.6 | H19: 3.7 | I19: n.a.
... A31: 2024 Q1 | B31: 5.9 | C31: 5.6 | E31: 43861 | F31: 3 | H31: 3.3 | I31: n.a.
A32: 2024 Q2 (Bank Staff Projection) | B32: 5.141 | C32: n.a. | E32: 43890 | F32: 2.9 | H32: 3.7 | I32: n.a.
A33: 2024 Q3 (Bank Staff Projection) | B33: 4.83 | C33: n.a. | E33: 43921 | F33: 2.5 | H33: 3.2 | I33: n.a.
E34: 43951 | F34: 1.3 | H34: 1.2 | I34: 5.5
E35: 43982 | F35: -0.1 | H35: -1 | I35: 4.6
E36: 44012 | F36: -1.2 | H36: -1.8 | I36: 3.8
E37: 44043 | F37: -0.8 | H37: -0.6 | I37: 3.5
E38: 44074 | F38: 0.1 | H38: 1.2 | I38: 3.2
E39: 44104 | F39: 1.4 | H39: 2.7 | I39: 3.2
E40: 44135 | F40: 2.5 | H40: 3.7 | I40: 3.2
E41: 44165 | F41: 3.3 | H41: 4.3 | I41: 3.2
E42: 44196 | F42: 4 | H42: 4.5 | I42: 3.4
E43: 44227 | F43: 4.1 | H43: 4.3 | I43: 3.6
E44: 44255 | F44: 4.2 | H44: 4 | I44: 3.3
E45: 44286 | F45: 4.3 | H45: 4.5 | I45: 2.8
... E83: 45443 | F83: 5.6 | H83: 6.3 | I83: 6.9
E84: 45473 | F84: n.a. | H84: 6.2 | I84: 6.8

Sheet HAVERM
A1: 201001 !M | B1: D7BT@UK | C1: D7F5@UK | D1: KAJ4@UK | E1: UNVDPR1@UK | F1: UNVDPE1@UK | G1: UNVDWR@UK | H1: UNVDWE@UK | I1: UNVDPR3@UK | J1: UNVDPE3@UK | K1: UNVDWR3@UK | L1: UNVDWE3@UK
A2: .DESC | B2: UK: Consumer Price Index: All Items (NSA, 2015=100) | C2: UK: Consumer Price Index: All Services (NSA, 2015=100) | D2: Great Britain: AWE, Regular Pay: Private Sector [3Mo Mvg Avg vs Yr Ago] (SA, %) | E2: UK: BoE DMP: Realized Price Growth Over the Past Year: Single Month (%) | F2: UK: BoE DMP: Expected Price Growth Over the Next Year: Single Month (%) | G2: UK: BoE DMP: Realized Wage Growth Over the Past Year: Single Month (%) | H2: UK: BoE DMP: Expected Wage Growth Over the Next Year: Single Month (%) | I2: UK: BoE DMP: Realized Price Growth Over the Past Year: 3 Month Average (%) | J2: UK: BoE DMP: Expected Price Growth Over the Next Year: 3 Month Average (%) | K2: UK: BoE DMP: Realized Wage Growth Over the Past Year: 3 Month Average (%) | L2: UK: BoE DMP: Expected Wage Growth Over the Past Year: 3 Month Average (%)
A3: .T1 | B3: Jan-1988 | C3: Jan-1988 | D3: Mar-2001 | E3: Jan-2017 | F3: Jan-2017 | G3: Aug-2017 | H3: Aug-2017 | I3: Jan-2017 | J3: Jan-2017 | K3: Aug-2017 | L3: Aug-2017
A4: .TN | B4: Jul-2024 | C4: Jul-2024 | D4: Jun-2024 | E4: Aug-2024 | F4: Aug-2024 | G4: Aug-2024 | H4: Aug-2024 | I4: Aug-2024 | J4: Aug-2024 | K4: Aug-2024 | L4: Aug-2024
A5: .LSOURCE | B5: Office for National Statistics | C5: Office for National Statistics | D5: Office for National Statistics | E5: Bank of England | F5: Bank of England | G5: Bank of England | H5: Bank of England | I5: Bank of England | J5: Bank of England | K5: Bank of England | L5: Bank of England
A6: .DTLM | B6: Aug-14-2024 07:02 | C6: Aug-14-2024 07:02 | D6: Aug-13-2024 07:03 | E6: Sep-05-2024 09:34 | F6: Sep-05-2024 09:34 | G6: Sep-05-2024 09:34 | H6: Sep-05-2024 09:34 | I6: Sep-05-2024 09:34 | J6: Sep-05-2024 09:34 | K6: Sep-05-2024 09:34 | L6: Sep-05-2024 09:34
A7: 201001 | B7: 87.8 | C7: 83.9 | D7: 0.5 | E7: #N/A | F7: #N/A | G7: #N/A | H7: #N/A | I7: #N/A | J7: #N/A | K7: #N/A | L7: #N/A
A8: 201002 | B8: 88.2 | C8: 84.1 | D8: 0.7 | E8: #N/A | F8: #N/A | G8: #N/A | H8: #N/A | I8: #N/A | J8: #N/A | K8: #N/A | L8: #N/A
A9: 201003 | B9: 88.7 | C9: 84.4 | D9: 1 | E9: #N/A | F9: #N/A | G9: #N/A | H9: #N/A | I9: #N/A | J9: #N/A | K9: #N/A | L9: #N/A
A10: 201004 | B10: 89.2 | C10: 84.9 | D10: 0.9 | E10: #N/A | F10: #N/A | G10: #N/A | H10: #N/A | I10: #N/A | J10: #N/A | K10: #N/A | L10: #N/A
A11: 201005 | B11: 89.4 | C11: 85.2 | D11: 0.8 | E11: #N/A | F11: #N/A | G11: #N/A | H11: #N/A | I11: #N/A | J11: #N/A | K11: #N/A | L11: #N/A
A12: 201006 | B12: 89.5 | C12: 85.7 | D12: 0.6 | E12: #N/A | F12: #N/A | G12: #N/A | H12: #N/A | I12: #N/A | J12: #N/A | K12: #N/A | L12: #N/A
A13: 201007 | B13: 89.3 | C13: 86.1 | D13: 1 | E13: #N/A | F13: #N/A | G13: #N/A | H13: #N/A | I13: #N/A | J13: #N/A | K13: #N/A | L13: #N/A
A14: 201008 | B14: 89.8 | C14: 86.7 | D14: 1.6 | E14: #N/A | F14: #N/A | G14: #N/A | H14: #N/A | I14: #N/A | J14: #N/A | K14: #N/A | L14: #N/A
A15: 201009 | B15: 89.8 | C15: 85.9 | D15: 2 | E15: #N/A | F15: #N/A | G15: #N/A | H15: #N/A | I15: #N/A | J15: #N/A | K15: #N/A | L15: #N/A
A16: 201010 | B16: 90 | C16: 86.3 | D16: 2 | E16: #N/A | F16: #N/A | G16: #N/A | H16: #N/A | I16: #N/A | J16: #N/A | K16: #N/A | L16: #N/A
A17: 201011 | B17: 90.3 | C17: 86.1 | D17: 2 | E17: #N/A | F17: #N/A | G17: #N/A | H17: #N/A | I17: #N/A | J17: #N/A | K17: #N/A | L17: #N/A
A18: 201012 | B18: 91.2 | C18: 87.2 | D18: 1.9 | E18: #N/A | F18: #N/A | G18: #N/A | H18: #N/A | I18: #N/A | J18: #N/A | K18: #N/A | L18: #N/A
... A90: 201612 | B90: 101.9 | C90: 104 | D90: 2.8 | E90: #N/A | F90: #N/A | G90: #N/A | H90: #N/A | I90: #N/A | J90: #N/A | K90: #N/A | L90: #N/A
A91: 201701 | B91: 101.4 | C91: 103.3 | D91: 2.6 | E91: 3.495 | F91: 3.346 | G91: #N/A | H91: #N/A | I91: 2.649 | J91: 2.963 | K91: #N/A | L91: #N/A
A92: 201702 | B92: 102.1 | C92: 103.9 | D92: 2.2 | E92: 2.069 | F92: 2.748 | G92: #N/A | H92: #N/A | I92: 2.649 | J92: 2.841 | K92: #N/A | L92: #N/A
A93: 201703 | B93: 102.5 | C93: 103.8 | D93: 2.1 | E93: 2.008 | F93: 2.282 | G93: #N/A | H93: #N/A | I93: 2.524 | J93: 2.792 | K93: #N/A | L93: #N/A
A94: 201704 | B94: 102.9 | C94: 105 | D94: 2 | E94: 4.144 | F94: 3.279 | G94: #N/A | H94: #N/A | I94: 2.74 | J94: 2.77 | K94: #N/A | L94: #N/A
A95: 201705 | B95: 103.3 | C95: 105.1 | D95: 2.2 | E95: 2.456 | F95: 2.447 | G95: #N/A | H95: #N/A | I95: 2.869 | J95: 2.669 | K95: #N/A | L95: #N/A
A96: 201706 | B96: 103.3 | C96: 105.5 | D96: 2.2 | E96: 2.66 | F96: 2.074 | G96: #N/A | H96: #N/A | I96: 3.087 | J96: 2.6 | K96: #N/A | L96: #N/A
A97: 201707 | B97: 103.2 | C97: 106 | D97: 2.3 | E97: 3.673 | F97: 2.828 | G97: #N/A | H97: #N/A | I97: 2.93 | J97: 2.45 | K97: #N/A | L97: #N/A
A98: 201708 | B98: 103.8 | C98: 106.5 | D98: 2.3 | E98: 3.074 | F98: 2.461 | G98: 2.6 | H98: 2.4 | I98: 3.135 | J98: 2.455 | K98: 2.635 | L98: 2.43
A99: 201709 | B99: 104.1 | C99: 106.1 | D99: 2.4 | E99: 2.525 | F99: 2.394 | G99: 2.5 | H99: 2.3 | I99: 3.09 | J99: 2.561 | K99: 2.548 | L99: 2.345
A100: 201710 | B100: 104.2 | C100: 105.9 | D100: 2.4 | E100: 2.853 | F100: 2.581 | G100: 2.7 | H100: 2.6 | I100: 2.817 | J100: 2.479 | K100: 2.613 | L100: 2.419
A101: 201711 | B101: 104.6 | C101: 105.9 | D101: 2.4 | E101: 2.867 | F101: 2.421 | G101: #N/A | H101: #N/A | I101: 2.748 | J101: 2.465 | K101: #N/A | L101: #N/A
A102: 201712 | B102: 104.9 | C102: 106.6 | D102: 2.6 | E102: 2.939 | F102: 2.442 | G102: #N/A | H102: #N/A | I102: 2.886 | J102: 2.481 | K102: #N/A | L102: #N/A
A103: 201801 | B103: 104.4 | C103: 106.1 | D103: 2.7 | E103: 3.01 | F103: 2.463 | G103: #N/A | H103: #N/A | I103: 2.939 | J103: 2.442 | K103: #N/A | L103: #N/A
A104: 201802 | B104: 104.9 | C104: 106.4 | D104: 2.9 | E104: 2.95 | F104: 2.408 | G104: #N/A | H104: #N/A | I104: 2.966 | J104: 2.438 | K104: #N/A | L104: #N/A
A105: 201803 | B105: 105 | C105: 106.5 | D105: 3 | E105: 2.56 | F105: 2.135 | G105: #N/A | H105: #N/A | I105: 2.838 | J105: 2.335 | K105: #N/A | L105: #N/A
A106: 201804 | B106: 105.4 | C106: 107.2 | D106: 3 | E106: 3.25 | F106: 2.444 | G106: #N/A | H106: #N/A | I106: 2.919 | J106: 2.329 | K106: #N/A | L106: #N/A
A107: 201805 | B107: 105.8 | C107: 107.6 | D107: 2.9 | E107: 2.47 | F107: 1.977 | G107: #N/A | H107: #N/A | I107: 2.76 | J107: 2.186 | K107: #N/A | L107: #N/A
A108: 201806 | B108: 105.8 | C108: 107.9 | D108: 2.8 | E108: 2.79 | F108: 2.317 | G108: #N/A | H108: #N/A | I108: 2.835 | J108: 2.246 | K108: #N/A | L108: #N/A
A109: 201807 | B109: 105.8 | C109: 108.5 | D109: 3 | E109: 2.79 | F109: 2.424 | G109: #N/A | H109: #N/A | I109: 2.68 | J109: 2.239 | K109: #N/A | L109: #N/A
A110: 201808 | B110: 106.5 | C110: 109.2 | D110: 3.2 | E110: 2.28 | F110: 2.254 | G110: #N/A | H110: #N/A | I110: 2.616 | J110: 2.332 | K110: #N/A | L110: #N/A
A111: 201809 | B111: 106.6 | C111: 108.6 | D111: 3.3 | E111: 2.41 | F111: 2.002 | G111: #N/A | H111: #N/A | I111: 2.491 | J111: 2.226 | K111: #N/A | L111: #N/A
...

Sheet HAVERD
A1: Date | B1: Month | C1: Year | D1: YYYYMM | E1: Quarter | F1: YYYYQQ | H1: Bank Rate | I1: Overnight | J1: 1 | K1: 2 | L1: 3 | M1: 4 | N1: 5 | O1: 6 | P1: 7 | Q1: 8 | R1: 9 | S1: 10 | T1: 11 | U1: 12 | V1: 13 | W1: 14 | X1: 15 | Y1: 16 | Z1: 17 | AA1: 18 | AB1: 19 | AC1: 20 | AD1: 21 | AE1: 22 | AF1: 23 | AG1: 24 | AH1: 25 | AI1: 26 | AJ1: 27 | AK1: 28 | AL1: 29 | AM1: 30 | AN1: 31 | AO1: 32 | AP1: 33 | AQ1: 34 | AR1: 35 | AS1: 36 | AT1: 37 | AU1: 38 | AV1: 39 | AW1: 40 | AX1: 41 | AY1: 42 | AZ1: 43 | BA1: 44 | BB1: 45 | BC1: 46 | BD1: 47 | BE1: 48 | BF1: 49 | BG1: 50 | BH1: 51 | BI1: 52 | BJ1: 53 | BK1: 54 | BL1: 55 | BM1: 56 | BN1: 57 | BO1: 58 | BP1: 59 | BQ1: 60 | BR1: 5.5yrs | BS1: 6yrs
