Workbook
Name _DLX1.INC: HAVERM!$B$1:$AN$6

Sheet Chart Data
A1: GDP | G1: Retail sales | P1: Total | Q1: Food | R1: Non-food | S1: Non-store | T1: Fuel | V1: Food sales as % of annual total | AE1: AWE vs other sources
B2: 2025 | C2: 2024 | D2: 2023 | E2: 2022 | H2: Food | I2: Non-food | J2: Non-store | K2: Fuel | L2: Total | M2: January | O2: Sales in 2022 | P2: 494298 | Q2: 185685 | R2: 189472 | S2: 64417 | T2: 54723 | W2: Food sales | X2: Av month | Y2: Diff vs av | AB2: Av 10-19 | AC2: Av 23-24 | AF2: ONS AWE private sector regular pay | AG2: HMRC median monthly pay | AH2: BoE Decision Maker Panel | AI2: Indeed wage tracker | AJ2: Brightmine median pay settlement
A3: Jan | B3: =100*((AVERAGE(HAVERM!C305:C307)/AVERAGE(HAVERM!C302:C304))-1) -> 0.19756338 | C3: =100*((AVERAGE(HAVERM!C293:C295)/AVERAGE(HAVERM!C290:C292))-1) -> 0.066533599 | D3: =100*((AVERAGE(HAVERM!C281:C283)/AVERAGE(HAVERM!C278:C280))-1) -> 0.1998002 | E3: =100*((AVERAGE(HAVERM!C269:C271)/AVERAGE(HAVERM!C266:C268))-1) -> 0.91463415 | G3: 44562 | H3: =100*((HAVERM!E271/HAVERM!E270)-1)*'Chart Data'!Q$3 -> -1.2474303 | I3: =100*((HAVERM!F271/HAVERM!F270)-1)*'Chart Data'!R$3 -> 0.15120951 | J3: =100*((HAVERM!G271/HAVERM!G270)-1)*'Chart Data'!S$3 -> -0.48147944 | K3: =100*((HAVERM!H271/HAVERM!H270)-1)*'Chart Data'!T$3 -> 0.26650049 | L3: =HAVERM!D271 -> -1.5 | M3: 100 | O3: Weights | P3: =SUM(Q3:T3) -> 1 | Q3: =Q2/SUM($Q$2:$T$2) -> 0.37565472 | R3: =R2/SUM($Q$2:$T$2) -> 0.3833161 | S3: =S2/SUM($Q$2:$T$2) -> 0.13032043 | T3: =T2/SUM($Q$2:$T$2) -> 0.11070874 | V3: 40179 | W3: =HAVERM!J127/SUM(HAVERM!J127:J138) -> 0.071029016 | X3: =1/12 -> 0.083333333 | Y3: =W3-X3 -> -0.012304317 | AA3: Jan | AB3: =AVERAGE(Y3,Y15,Y27,Y39,Y51,Y63,Y75,Y87,Y99,Y111) -> -0.01161865 | AC3: =AVERAGE(Y159,Y171) -> -0.013539395 | AE3: 43831 | AF3: =100*((AVERAGE(HAVERM!M245:M247)/AVERAGE(HAVERM!M233:M235))-1) -> 3.0013643 | AG3: =100*((AVERAGE(HAVERM!O245:O247)/AVERAGE(HAVERM!O233:O235))-1) -> 3.4495688 | AH3: =HAVERM!Q247 -> #N/A | AI3: =HAVERM!S247 -> 2.806165 | AJ3: ='[1]Manual Monthly DATA'!D575 -> 2.3
A4: Feb | C4: =100*((AVERAGE(HAVERM!C294:C296)/AVERAGE(HAVERM!C291:C293))-1) -> 0.29960053 | D4: =100*((AVERAGE(HAVERM!C282:C284)/AVERAGE(HAVERM!C279:C281))-1) -> 0.166334 | E4: =100*((AVERAGE(HAVERM!C270:C272)/AVERAGE(HAVERM!C267:C269))-1) -> 0.67430883 | G4: 44593 | H4: =100*((HAVERM!E272/HAVERM!E271)-1)*'Chart Data'!Q$3 -> -0.36865036 | I4: =100*((HAVERM!F272/HAVERM!F271)-1)*'Chart Data'!R$3 -> 0.11296152 | J4: =100*((HAVERM!G272/HAVERM!G271)-1)*'Chart Data'!S$3 -> -0.82214085 | K4: =100*((HAVERM!H272/HAVERM!H271)-1)*'Chart Data'!T$3 -> 0.19517702 | L4: =HAVERM!D272 -> -1 | V4: 40210 | W4: =HAVERM!J128/SUM(HAVERM!J127:J138) -> 0.072968387 | X4: =1/12 -> 0.083333333 | Y4: =W4-X4 -> -0.010364947 | AA4: Feb | AB4: =AVERAGE(Y4,Y16,Y28,Y40,Y52,Y64,Y76,Y88,Y100,Y112) -> -0.010543298 | AC4: =AVERAGE(Y160,Y172) -> -0.0093506192 | AE4: 43862 | AF4: =100*((AVERAGE(HAVERM!M246:M248)/AVERAGE(HAVERM!M234:M236))-1) -> 2.8571429 | AG4: =100*((AVERAGE(HAVERM!O246:O248)/AVERAGE(HAVERM!O234:O236))-1) -> 3.7778193 | AH4: =HAVERM!Q248 -> #N/A | AI4: =HAVERM!S248 -> 2.2930915 | AJ4: ='[1]Manual Monthly DATA'!D576 -> 2.4
A5: Mar | C5: =100*((AVERAGE(HAVERM!C295:C297)/AVERAGE(HAVERM!C292:C294))-1) -> 0.7661559 | D5: =100*((AVERAGE(HAVERM!C283:C285)/AVERAGE(HAVERM!C280:C282))-1) -> 0.099634673 | E5: =100*((AVERAGE(HAVERM!C271:C273)/AVERAGE(HAVERM!C268:C270))-1) -> 0.67272116 | G5: 44621 | H5: =100*((HAVERM!E273/HAVERM!E272)-1)*'Chart Data'!Q$3 -> 0.11169119 | I5: =100*((HAVERM!F273/HAVERM!F272)-1)*'Chart Data'!R$3 -> 0.82595047 | J5: =100*((HAVERM!G273/HAVERM!G272)-1)*'Chart Data'!S$3 -> -1.3399644 | K5: =100*((HAVERM!H273/HAVERM!H272)-1)*'Chart Data'!T$3 -> -0.34097014 | L5: =HAVERM!D273 -> -0.8 | V5: 40238 | W5: =HAVERM!J129/SUM(HAVERM!J127:J138) -> 0.094772297 | X5: =1/12 -> 0.083333333 | Y5: =W5-X5 -> 0.011438963 | AA5: Mar | AB5: =AVERAGE(Y5,Y17,Y29,Y41,Y53,Y65,Y77,Y89,Y101,Y113) -> 0.010509594 | AC5: =AVERAGE(Y161,Y173) -> 0.012029719 | AE5: 43891 | AF5: =100*((AVERAGE(HAVERM!M247:M249)/AVERAGE(HAVERM!M235:M237))-1) -> 2.5762712 | AG5: =100*((AVERAGE(HAVERM!O247:O249)/AVERAGE(HAVERM!O235:O237))-1) -> 3.4238928 | AH5: =HAVERM!Q249 -> #N/A | AI5: =HAVERM!S249 -> 1.9478381 | AJ5: ='[1]Manual Monthly DATA'!D577 -> 2.4
A6: Apr | C6: =100*((AVERAGE(HAVERM!C296:C298)/AVERAGE(HAVERM!C293:C295))-1) -> 0.76462766 | D6: =100*((AVERAGE(HAVERM!C284:C286)/AVERAGE(HAVERM!C281:C283))-1) -> 0.23263543 | E6: =100*((AVERAGE(HAVERM!C272:C274)/AVERAGE(HAVERM!C269:C271))-1) -> 0.63779792 | G6: 44652 | H6: =100*((HAVERM!E274/HAVERM!E273)-1)*'Chart Data'!Q$3 -> -0.22272019 | I6: =100*((HAVERM!F274/HAVERM!F273)-1)*'Chart Data'!R$3 -> -1.1025391 | J6: =100*((HAVERM!G274/HAVERM!G273)-1)*'Chart Data'!S$3 -> 0.83267621 | K6: =100*((HAVERM!H274/HAVERM!H273)-1)*'Chart Data'!T$3 -> 0.19789051 | L6: =HAVERM!D274 -> -0.4 | V6: 40269 | W6: =HAVERM!J130/SUM(HAVERM!J127:J138) -> 0.074526653 | X6: =1/12 -> 0.083333333 | Y6: =W6-X6 -> -0.0088066806 | AA6: Apr | AB6: =AVERAGE(Y6,Y18,Y30,Y42,Y54,Y66,Y78,Y90,Y102,Y114) -> -0.0079071647 | AC6: =AVERAGE(Y162,Y174) -> -0.0080997062 | AE6: 43922 | AF6: =100*((AVERAGE(HAVERM!M248:M250)/AVERAGE(HAVERM!M236:M238))-1) -> 1.35318 | AG6: =100*((AVERAGE(HAVERM!O248:O250)/AVERAGE(HAVERM!O236:O238))-1) -> 1.8340126 | AH6: =HAVERM!Q250 -> #N/A | AI6: =HAVERM!S250 -> 3.1703821 | AJ6: ='[1]Manual Monthly DATA'!D578 -> 2.2
A7: May | C7: =100*((AVERAGE(HAVERM!C297:C299)/AVERAGE(HAVERM!C294:C296))-1) -> 0.8297378 | D7: =100*((AVERAGE(HAVERM!C285:C287)/AVERAGE(HAVERM!C282:C284))-1) -> -0.033211558 | E7: =100*((AVERAGE(HAVERM!C273:C275)/AVERAGE(HAVERM!C270:C272))-1) -> 0.56932351 | G7: 44682 | H7: =100*((HAVERM!E275/HAVERM!E274)-1)*'Chart Data'!Q$3 -> -0.93353558 | I7: =100*((HAVERM!F275/HAVERM!F274)-1)*'Chart Data'!R$3 -> -0.26487786 | J7: =100*((HAVERM!G275/HAVERM!G274)-1)*'Chart Data'!S$3 -> -0.36027575 | K7: =100*((HAVERM!H275/HAVERM!H274)-1)*'Chart Data'!T$3 -> 0.032402559 | L7: =HAVERM!D275 -> -1.6 | V7: 40299 | W7: =HAVERM!J131/SUM(HAVERM!J127:J138) -> 0.077284482 | X7: =1/12 -> 0.083333333 | Y7: =W7-X7 -> -0.0060488512 | AA7: May | AB7: =AVERAGE(Y7,Y19,Y31,Y43,Y55,Y67,Y79,Y91,Y103,Y115) -> -0.0064390784 | AC7: =AVERAGE(Y163,Y175) -> -0.0053046457 | AE7: 43952 | AF7: =100*((AVERAGE(HAVERM!M249:M251)/AVERAGE(HAVERM!M237:M239))-1) -> 0 | AG7: =100*((AVERAGE(HAVERM!O249:O251)/AVERAGE(HAVERM!O237:O239))-1) -> 0.22132055 | AH7: =HAVERM!Q251 -> #N/A | AI7: =HAVERM!S251 -> 4.0756324 | AJ7: ='[1]Manual Monthly DATA'!D579 -> 2.1
A8: Jun | C8: =100*((AVERAGE(HAVERM!C298:C300)/AVERAGE(HAVERM!C295:C297))-1) -> 0.42975207 | D8: =100*((AVERAGE(HAVERM!C286:C288)/AVERAGE(HAVERM!C283:C285))-1) -> 0 | E8: =100*((AVERAGE(HAVERM!C274:C276)/AVERAGE(HAVERM!C271:C273))-1) -> 0.20046776 | G8: 44713 | H8: =100*((HAVERM!E276/HAVERM!E275)-1)*'Chart Data'!Q$3 -> 1.0722051 | I8: =100*((HAVERM!F276/HAVERM!F275)-1)*'Chart Data'!R$3 -> -0.22861795 | J8: =100*((HAVERM!G276/HAVERM!G275)-1)*'Chart Data'!S$3 -> -0.52383704 | K8: =100*((HAVERM!H276/HAVERM!H275)-1)*'Chart Data'!T$3 -> -0.43077332 | L8: =HAVERM!D276 -> -0.1 | V8: 40330 | W8: =HAVERM!J132/SUM(HAVERM!J127:J138) -> 0.097729448 | X8: =1/12 -> 0.083333333 | Y8: =W8-X8 -> 0.014396115 | AA8: Jun | AB8: =AVERAGE(Y8,Y20,Y32,Y44,Y56,Y68,Y80,Y92,Y104,Y116) -> 0.012625729 | AC8: =AVERAGE(Y164,Y176) -> 0.013336778 | AE8: 43983 | AF8: =100*((AVERAGE(HAVERM!M250:M252)/AVERAGE(HAVERM!M238:M240))-1) -> -1.1424731 | AG8: =100*((AVERAGE(HAVERM!O250:O252)/AVERAGE(HAVERM!O238:O240))-1) -> -0.31278749 | AH8: =HAVERM!Q252 -> #N/A | AI8: =HAVERM!S252 -> 4.4872712 | AJ8: ='[1]Manual Monthly DATA'!D580 -> 2
A9: Jul | C9: =100*((AVERAGE(HAVERM!C299:C301)/AVERAGE(HAVERM!C296:C298))-1) -> 0.26393929 | D9: =100*((AVERAGE(HAVERM!C287:C289)/AVERAGE(HAVERM!C284:C286))-1) -> -0.099469496 | E9: =100*((AVERAGE(HAVERM!C275:C277)/AVERAGE(HAVERM!C272:C274))-1) -> 0.10006671 | G9: 44743 | H9: =100*((HAVERM!E277/HAVERM!E276)-1)*'Chart Data'!Q$3 -> 0.37230398 | I9: =100*((HAVERM!F277/HAVERM!F276)-1)*'Chart Data'!R$3 -> -0.03833161 | J9: =100*((HAVERM!G277/HAVERM!G276)-1)*'Chart Data'!S$3 -> 0.066557934 | K9: =100*((HAVERM!H277/HAVERM!H276)-1)*'Chart Data'!T$3 -> 0.011205338 | L9: =HAVERM!D277 -> 0.5 | V9: 40360 | W9: =HAVERM!J133/SUM(HAVERM!J127:J138) -> 0.076141523 | X9: =1/12 -> 0.083333333 | Y9: =W9-X9 -> -0.0071918105 | AA9: Jul | AB9: =AVERAGE(Y9,Y21,Y33,Y45,Y57,Y69,Y81,Y93,Y105,Y117) -> -0.006415933 | AC9: =AVERAGE(Y165,Y177) -> -0.0061518052 | AE9: 44013 | AF9: =100*((AVERAGE(HAVERM!M251:M253)/AVERAGE(HAVERM!M239:M241))-1) -> -0.80375084 | AG9: =100*((AVERAGE(HAVERM!O251:O253)/AVERAGE(HAVERM!O239:O241))-1) -> 0.73448402 | AH9: =HAVERM!Q253 -> #N/A | AI9: =HAVERM!S253 -> 3.9409057 | AJ9: ='[1]Manual Monthly DATA'!D581 -> 0
A10: Aug | C10: =100*((AVERAGE(HAVERM!C300:C302)/AVERAGE(HAVERM!C297:C299))-1) -> 2.220446e-14 | D10: =100*((AVERAGE(HAVERM!C288:C290)/AVERAGE(HAVERM!C285:C287))-1) -> 0.19933555 | E10: =100*((AVERAGE(HAVERM!C276:C278)/AVERAGE(HAVERM!C273:C275))-1) -> -0.16650017 | G10: 44774 | H10: =100*((HAVERM!E278/HAVERM!E277)-1)*'Chart Data'!Q$3 -> -0.25805525 | I10: =100*((HAVERM!F278/HAVERM!F277)-1)*'Chart Data'!R$3 -> -0.99761949 | J10: =100*((HAVERM!G278/HAVERM!G277)-1)*'Chart Data'!S$3 -> -0.14568341 | K10: =100*((HAVERM!H278/HAVERM!H277)-1)*'Chart Data'!T$3 -> -0.12313409 | L10: =HAVERM!D278 -> -1.5 | V10: 40391 | W10: =HAVERM!J134/SUM(HAVERM!J127:J138) -> 0.07497561 | X10: =1/12 -> 0.083333333 | Y10: =W10-X10 -> -0.0083577237 | AA10: Aug | AB10: =AVERAGE(Y10,Y22,Y34,Y46,Y58,Y70,Y82,Y94,Y106,Y118) -> -0.0081183534 | AC10: =AVERAGE(Y166,Y178) -> -0.0069174705 | AE10: 44044 | AF10: =100*((AVERAGE(HAVERM!M252:M254)/AVERAGE(HAVERM!M240:M242))-1) -> 0.13360053 | AG10: =100*((AVERAGE(HAVERM!O252:O254)/AVERAGE(HAVERM!O240:O242))-1) -> 2.0524097 | AH10: =HAVERM!Q254 -> #N/A | AI10: =HAVERM!S254 -> 3.5114274 | AJ10: ='[1]Manual Monthly DATA'!D582 -> 1.1
A11: Sep | C11: =100*((AVERAGE(HAVERM!C301:C303)/AVERAGE(HAVERM!C298:C300))-1) -> 0 | D11: =100*((AVERAGE(HAVERM!C289:C291)/AVERAGE(HAVERM!C286:C288))-1) -> -0.099535501 | E11: =100*((AVERAGE(HAVERM!C277:C279)/AVERAGE(HAVERM!C274:C276))-1) -> 0 | G11: 44805 | H11: =100*((HAVERM!E279/HAVERM!E278)-1)*'Chart Data'!Q$3 -> -0.96512082 | I11: =100*((HAVERM!F279/HAVERM!F278)-1)*'Chart Data'!R$3 -> 0.078790566 | J11: =100*((HAVERM!G279/HAVERM!G278)-1)*'Chart Data'!S$3 -> -0.22769244 | K11: =100*((HAVERM!H279/HAVERM!H278)-1)*'Chart Data'!T$3 -> -0.079239387 | L11: =HAVERM!D279 -> -1.2 | V11: 40422 | W11: =HAVERM!J135/SUM(HAVERM!J127:J138) -> 0.093096469 | X11: =1/12 -> 0.083333333 | Y11: =W11-X11 -> 0.0097631356 | AA11: Sep | AB11: =AVERAGE(Y11,Y23,Y35,Y47,Y59,Y71,Y83,Y95,Y107,Y119) -> 0.010301643 | AC11: =AVERAGE(Y167,Y179) -> 0.0100873 | AE11: 44075 | AF11: =100*((AVERAGE(HAVERM!M253:M255)/AVERAGE(HAVERM!M241:M243))-1) -> 1.3333333 | AG11: =100*((AVERAGE(HAVERM!O253:O255)/AVERAGE(HAVERM!O241:O243))-1) -> 3.183315 | AH11: =HAVERM!Q255 -> #N/A | AI11: =HAVERM!S255 -> 3.3418835 | AJ11: ='[1]Manual Monthly DATA'!D583 -> 1.5
A12: Oct | C12: =100*((AVERAGE(HAVERM!C302:C304)/AVERAGE(HAVERM!C299:C301))-1) -> -0.065811122 | D12: =100*((AVERAGE(HAVERM!C290:C292)/AVERAGE(HAVERM!C287:C289))-1) -> -0.23232658 | E12: =100*((AVERAGE(HAVERM!C278:C280)/AVERAGE(HAVERM!C275:C277))-1) -> 0.066644452 | G12: 44835 | H12: =100*((HAVERM!E280/HAVERM!E279)-1)*'Chart Data'!Q$3 -> -0.076197712 | I12: =100*((HAVERM!F280/HAVERM!F279)-1)*'Chart Data'!R$3 -> 0.66834603 | J12: =100*((HAVERM!G280/HAVERM!G279)-1)*'Chart Data'!S$3 -> 0.027263689 | K12: =100*((HAVERM!H280/HAVERM!H279)-1)*'Chart Data'!T$3 -> 0.41045466 | L12: =HAVERM!D280 -> 1 | V12: 40452 | W12: =HAVERM!J136/SUM(HAVERM!J127:J138) -> 0.075921604 | X12: =1/12 -> 0.083333333 | Y12: =W12-X12 -> -0.0074117291 | AA12: Oct | AB12: =AVERAGE(Y12,Y24,Y36,Y48,Y60,Y72,Y84,Y96,Y108,Y120) -> -0.0072461606 | AC12: =AVERAGE(Y168,Y180) -> -0.0070060929 | AE12: 44105 | AF12: =100*((AVERAGE(HAVERM!M254:M256)/AVERAGE(HAVERM!M242:M244))-1) -> 2.3968043 | AG12: =100*((AVERAGE(HAVERM!O254:O256)/AVERAGE(HAVERM!O242:O244))-1) -> 4.0204678 | AH12: =HAVERM!Q256 -> #N/A | AI12: =HAVERM!S256 -> 3.269976 | AJ12: ='[1]Manual Monthly DATA'!D584 -> 2
A13: Nov | C13: =100*((AVERAGE(HAVERM!C303:C305)/AVERAGE(HAVERM!C300:C302))-1) -> -0.065832785 | D13: =100*((AVERAGE(HAVERM!C291:C293)/AVERAGE(HAVERM!C288:C290))-1) -> -0.39787798 | E13: =100*((AVERAGE(HAVERM!C279:C281)/AVERAGE(HAVERM!C276:C278))-1) -> 0.26684456 | G13: 44866 | H13: =100*((HAVERM!E281/HAVERM!E280)-1)*'Chart Data'!Q$3 -> 0.076352585 | I13: =100*((HAVERM!F281/HAVERM!F280)-1)*'Chart Data'!R$3 -> -0.27048515 | J13: =100*((HAVERM!G281/HAVERM!G280)-1)*'Chart Data'!S$3 -> -0.54413543 | K13: =100*((HAVERM!H281/HAVERM!H280)-1)*'Chart Data'!T$3 -> -0.27484792 | L13: =HAVERM!D281 -> -1 | V13: 40483 | W13: =HAVERM!J137/SUM(HAVERM!J127:J138) -> 0.081072652 | X13: =1/12 -> 0.083333333 | Y13: =W13-X13 -> -0.0022606811 | AA13: Nov | AB13: =AVERAGE(Y13,Y25,Y37,Y49,Y61,Y73,Y85,Y97,Y109,Y121) -> -0.0035818756 | AC13: =AVERAGE(Y169,Y181) -> -0.0039671932 | AE13: 44136 | AF13: =100*((AVERAGE(HAVERM!M255:M257)/AVERAGE(HAVERM!M243:M245))-1) -> 3.2579787 | AG13: =100*((AVERAGE(HAVERM!O255:O257)/AVERAGE(HAVERM!O243:O245))-1) -> 4.5105917 | AH13: =HAVERM!Q257 -> #N/A | AI13: =HAVERM!S257 -> 3.2996835 | AJ13: ='[1]Manual Monthly DATA'!D585 -> 2
A14: Dec | C14: =100*((AVERAGE(HAVERM!C304:C306)/AVERAGE(HAVERM!C301:C303))-1) -> 0.032916392 | D14: =100*((AVERAGE(HAVERM!C292:C294)/AVERAGE(HAVERM!C289:C291))-1) -> -0.29890402 | E14: =100*((AVERAGE(HAVERM!C280:C282)/AVERAGE(HAVERM!C277:C279))-1) -> 0.40013338 | G14: 44896 | H14: =100*((HAVERM!E282/HAVERM!E281)-1)*'Chart Data'!Q$3 -> -0.19049428 | I14: =100*((HAVERM!F282/HAVERM!F281)-1)*'Chart Data'!R$3 -> -0.31132272 | J14: =100*((HAVERM!G282/HAVERM!G281)-1)*'Chart Data'!S$3 -> 0.29811864 | K14: =100*((HAVERM!H282/HAVERM!H281)-1)*'Chart Data'!T$3 -> -0.033821409 | L14: =HAVERM!D282 -> -0.2 | M14: 100 | V14: 40513 | W14: =HAVERM!J138/SUM(HAVERM!J127:J138) -> 0.11048186 | X14: =1/12 -> 0.083333333 | Y14: =W14-X14 -> 0.027148527 | AA14: Dec | AB14: =AVERAGE(Y14,Y26,Y38,Y50,Y62,Y74,Y86,Y98,Y110,Y122) -> 0.02843355 | AC14: =AVERAGE(Y170,Y182) -> 0.024883131 | AE14: 44166 | AF14: =100*((AVERAGE(HAVERM!M256:M258)/AVERAGE(HAVERM!M244:M246))-1) -> 3.9176627 | AG14: =100*((AVERAGE(HAVERM!O256:O258)/AVERAGE(HAVERM!O244:O246))-1) -> 4.6803861 | AH14: =HAVERM!Q258 -> #N/A | AI14: =HAVERM!S258 -> 3.3910826 | AJ14: ='[1]Manual Monthly DATA'!D586 -> 1
G15: 44927 | H15: =100*((HAVERM!E283/HAVERM!E282)-1)*'Chart Data'!Q$3 -> -0.1914652 | I15: =100*((HAVERM!F283/HAVERM!F282)-1)*'Chart Data'!R$3 -> 0.039233992 | J15: =100*((HAVERM!G283/HAVERM!G282)-1)*'Chart Data'!S$3 -> 0.23593689 | K15: =100*((HAVERM!H283/HAVERM!H282)-1)*'Chart Data'!T$3 -> 0.12439185 | L15: =HAVERM!D283 -> 0.2 | M15: 100 | V15: 40544 | W15: =HAVERM!J139/SUM(HAVERM!J139:J150) -> 0.069435668 | X15: =1/12 -> 0.083333333 | Y15: =W15-X15 -> -0.013897665 | AE15: 44197 | AF15: =100*((AVERAGE(HAVERM!M257:M259)/AVERAGE(HAVERM!M245:M247))-1) -> 4.1059603 | AG15: =100*((AVERAGE(HAVERM!O257:O259)/AVERAGE(HAVERM!O245:O247))-1) -> 4.5125045 | AH15: =HAVERM!Q259 -> #N/A | AI15: =HAVERM!S259 -> 3.558895 | AJ15: ='[1]Manual Monthly DATA'!D587 -> 1
G16: 44958 | H16: =100*((HAVERM!E284/HAVERM!E283)-1)*'Chart Data'!Q$3 -> 0.11546764 | I16: =100*((HAVERM!F284/HAVERM!F283)-1)*'Chart Data'!R$3 -> 0.62710201 | J16: =100*((HAVERM!G284/HAVERM!G283)-1)*'Chart Data'!S$3 -> 0.068159223 | K16: =100*((HAVERM!H284/HAVERM!H283)-1)*'Chart Data'!T$3 -> -0.19010592 | L16: =HAVERM!D284 -> 0.6 | V16: 40575 | W16: =HAVERM!J140/SUM(HAVERM!J139:J150) -> 0.071818449 | X16: =1/12 -> 0.083333333 | Y16: =W16-X16 -> -0.011514884 | AE16: 44228 | AF16: =100*((AVERAGE(HAVERM!M258:M260)/AVERAGE(HAVERM!M246:M248))-1) -> 4.1666667 | AG16: =100*((AVERAGE(HAVERM!O258:O260)/AVERAGE(HAVERM!O246:O248))-1) -> 4.4692737 | AH16: =HAVERM!Q260 -> #N/A | AI16: =HAVERM!S260 -> 3.6596001 | AJ16: ='[1]Manual Monthly DATA'!D588 -> 1
G17: 44986 | H17: =100*((HAVERM!E285/HAVERM!E284)-1)*'Chart Data'!Q$3 -> -0.19185634 | I17: =100*((HAVERM!F285/HAVERM!F284)-1)*'Chart Data'!R$3 -> -0.57844482 | J17: =100*((HAVERM!G285/HAVERM!G284)-1)*'Chart Data'!S$3 -> 0.040682758 | K17: =100*((HAVERM!H285/HAVERM!H284)-1)*'Chart Data'!T$3 -> -0.079646578 | L17: =HAVERM!D285 -> -0.8 | V17: 40603 | W17: =HAVERM!J141/SUM(HAVERM!J139:J150) -> 0.091703807 | X17: =1/12 -> 0.083333333 | Y17: =W17-X17 -> 0.0083704736 | AE17: 44256 | AF17: =100*((AVERAGE(HAVERM!M259:M261)/AVERAGE(HAVERM!M247:M249))-1) -> 4.2300066 | AG17: =100*((AVERAGE(HAVERM!O259:O261)/AVERAGE(HAVERM!O247:O249))-1) -> 4.7139259 | AH17: =HAVERM!Q261 -> #N/A | AI17: =HAVERM!S261 -> 3.4812523 | AJ17: ='[1]Manual Monthly DATA'!D589 -> 1.2
G18: 45017 | H18: =100*((HAVERM!E286/HAVERM!E285)-1)*'Chart Data'!Q$3 -> 0.23140948 | I18: =100*((HAVERM!F286/HAVERM!F285)-1)*'Chart Data'!R$3 -> 0.58730762 | J18: =100*((HAVERM!G286/HAVERM!G285)-1)*'Chart Data'!S$3 -> 0.081112304 | K18: =100*((HAVERM!H286/HAVERM!H285)-1)*'Chart Data'!T$3 -> -0.09168426 | L18: =HAVERM!D286 -> 0.8 | V18: 40634 | W18: =HAVERM!J142/SUM(HAVERM!J139:J150) -> 0.078220649 | X18: =1/12 -> 0.083333333 | Y18: =W18-X18 -> -0.0051126848 | AE18: 44287 | AF18: =100*((AVERAGE(HAVERM!M260:M262)/AVERAGE(HAVERM!M248:M250))-1) -> 5.6742323 | AG18: =100*((AVERAGE(HAVERM!O260:O262)/AVERAGE(HAVERM!O248:O250))-1) -> 6.4762598 | AH18: =HAVERM!Q262 -> #N/A | AI18: =HAVERM!S262 -> 2.3222687 | AJ18: ='[1]Manual Monthly DATA'!D590 -> 2
G19: 45047 | H19: =100*((HAVERM!E287/HAVERM!E286)-1)*'Chart Data'!Q$3 -> -0.30665691 | I19: =100*((HAVERM!F287/HAVERM!F286)-1)*'Chart Data'!R$3 -> -0.50131885 | J19: =100*((HAVERM!G287/HAVERM!G286)-1)*'Chart Data'!S$3 -> 0.053740386 | K19: =100*((HAVERM!H287/HAVERM!H286)-1)*'Chart Data'!T$3 -> 0.092449891 | L19: =HAVERM!D287 -> -0.7 | V19: 40664 | W19: =HAVERM!J143/SUM(HAVERM!J139:J150) -> 0.075617002 | X19: =1/12 -> 0.083333333 | Y19: =W19-X19 -> -0.0077163316 | AE19: 44317 | AF19: =100*((AVERAGE(HAVERM!M261:M263)/AVERAGE(HAVERM!M249:M251))-1) -> 7.1476736 | AG19: =100*((AVERAGE(HAVERM!O261:O263)/AVERAGE(HAVERM!O249:O251))-1) -> 8.0787633 | AH19: =HAVERM!Q263 -> #N/A | AI19: =HAVERM!S263 -> 1.591551 | AJ19: ='[1]Manual Monthly DATA'!D591 -> 2
G20: 45078 | H20: =100*((HAVERM!E288/HAVERM!E287)-1)*'Chart Data'!Q$3 -> 0.38647605 | I20: =100*((HAVERM!F288/HAVERM!F287)-1)*'Chart Data'!R$3 -> 0.39074017 | J20: =100*((HAVERM!G288/HAVERM!G287)-1)*'Chart Data'!S$3 -> -0.013379921 | K20: =100*((HAVERM!H288/HAVERM!H287)-1)*'Chart Data'!T$3 -> -0.022921065 | L20: =HAVERM!D288 -> 0.7 | V20: 40695 | W20: =HAVERM!J144/SUM(HAVERM!J139:J150) -> 0.09535485 | X20: =1/12 -> 0.083333333 | Y20: =W20-X20 -> 0.012021516 | AE20: 44348 | AF20: =100*((AVERAGE(HAVERM!M262:M264)/AVERAGE(HAVERM!M250:M252))-1) -> 8.3616587 | AG20: =100*((AVERAGE(HAVERM!O262:O264)/AVERAGE(HAVERM!O250:O252))-1) -> 8.8962717 | AH20: =HAVERM!Q264 -> #N/A | AI20: =HAVERM!S264 -> 1.3784246 | AJ20: ='[1]Manual Monthly DATA'!D592 -> 2
G21: 45108 | H21: =100*((HAVERM!E289/HAVERM!E288)-1)*'Chart Data'!Q$3 -> -0.87984303 | I21: =100*((HAVERM!F289/HAVERM!F288)-1)*'Chart Data'!R$3 -> -0.61887565 | J21: =100*((HAVERM!G289/HAVERM!G288)-1)*'Chart Data'!S$3 -> 0.13393673 | K21: =100*((HAVERM!H289/HAVERM!H288)-1)*'Chart Data'!T$3 -> 0.14929602 | L21: =HAVERM!D289 -> -1.2 | V21: 40725 | W21: =HAVERM!J145/SUM(HAVERM!J139:J150) -> 0.076519606 | X21: =1/12 -> 0.083333333 | Y21: =W21-X21 -> -0.0068137276 | AE21: 44378 | AF21: =100*((AVERAGE(HAVERM!M263:M265)/AVERAGE(HAVERM!M251:M253))-1) -> 7.7650236 | AG21: =100*((AVERAGE(HAVERM!O263:O265)/AVERAGE(HAVERM!O251:O253))-1) -> 7.8381334 | AH21: =HAVERM!Q265 -> #N/A | AI21: =HAVERM!S265 -> 2.3226758 | AJ21: ='[1]Manual Monthly DATA'!D593 -> 2
G22: 45139 | H22: =100*((HAVERM!E290/HAVERM!E289)-1)*'Chart Data'!Q$3 -> 0.50922954 | I22: =100*((HAVERM!F290/HAVERM!F289)-1)*'Chart Data'!R$3 -> -0.15725789 | J22: =100*((HAVERM!G290/HAVERM!G289)-1)*'Chart Data'!S$3 -> 0.026514839 | K22: =100*((HAVERM!H290/HAVERM!H289)-1)*'Chart Data'!T$3 -> -0.12464649 | L22: =HAVERM!D290 -> 0.2 | V22: 40756 | W22: =HAVERM!J146/SUM(HAVERM!J139:J150) -> 0.075726884 | X22: =1/12 -> 0.083333333 | Y22: =W22-X22 -> -0.0076064493 | AE22: 44409 | AF22: =100*((AVERAGE(HAVERM!M264:M266)/AVERAGE(HAVERM!M252:M254))-1) -> 6.7378252 | AG22: =100*((AVERAGE(HAVERM!O264:O266)/AVERAGE(HAVERM!O252:O254))-1) -> 6.6798348 | AH22: =HAVERM!Q266 -> #N/A | AI22: =HAVERM!S266 -> 3.0648798 | AJ22: ='[1]Manual Monthly DATA'!D594 -> 2
G23: 45170 | H23: =100*((HAVERM!E291/HAVERM!E290)-1)*'Chart Data'!Q$3 -> 0 | I23: =100*((HAVERM!F291/HAVERM!F290)-1)*'Chart Data'!R$3 -> -0.94743424 | J23: =100*((HAVERM!G291/HAVERM!G290)-1)*'Chart Data'!S$3 -> -0.25137952 | K23: =100*((HAVERM!H291/HAVERM!H290)-1)*'Chart Data'!T$3 -> 0.09168426 | L23: =HAVERM!D291 -> -1.1 | V23: 40787 | W23: =HAVERM!J147/SUM(HAVERM!J139:J150) -> 0.094451766 | X23: =1/12 -> 0.083333333 | Y23: =W23-X23 -> 0.011118433 | AE23: 44440 | AF23: =100*((AVERAGE(HAVERM!M265:M267)/AVERAGE(HAVERM!M253:M255))-1) -> 5.5263158 | AG23: =100*((AVERAGE(HAVERM!O265:O267)/AVERAGE(HAVERM!O253:O255))-1) -> 5.9219858 | AH23: =HAVERM!Q267 -> #N/A | AI23: =HAVERM!S267 -> 3.5096753 | AJ23: ='[1]Manual Monthly DATA'!D595 -> 2
G24: 45200 | H24: =100*((HAVERM!E292/HAVERM!E291)-1)*'Chart Data'!Q$3 -> 0.11594281 | I24: =100*((HAVERM!F292/HAVERM!F291)-1)*'Chart Data'!R$3 -> 0.20238443 | J24: =100*((HAVERM!G292/HAVERM!G291)-1)*'Chart Data'!S$3 -> 0.080944369 | K24: =100*((HAVERM!H292/HAVERM!H291)-1)*'Chart Data'!T$3 -> -0.26142722 | L24: =HAVERM!D292 -> 0.1 | V24: 40817 | W24: =HAVERM!J148/SUM(HAVERM!J139:J150) -> 0.076735679 | X24: =1/12 -> 0.083333333 | Y24: =W24-X24 -> -0.0065976546 | AE24: 44470 | AF24: =100*((AVERAGE(HAVERM!M266:M268)/AVERAGE(HAVERM!M254:M256))-1) -> 4.6814044 | AG24: =100*((AVERAGE(HAVERM!O266:O268)/AVERAGE(HAVERM!O254:O256))-1) -> 5.4813774 | AH24: =HAVERM!Q268 -> #N/A | AI24: =HAVERM!S268 -> 3.7667383 | AJ24: ='[1]Manual Monthly DATA'!D596 -> 2
G25: 45231 | H25: =100*((HAVERM!E293/HAVERM!E292)-1)*'Chart Data'!Q$3 -> 0.11558607 | I25: =100*((HAVERM!F293/HAVERM!F292)-1)*'Chart Data'!R$3 -> 1.2079289 | J25: =100*((HAVERM!G293/HAVERM!G292)-1)*'Chart Data'!S$3 -> 0.13407452 | K25: =100*((HAVERM!H293/HAVERM!H292)-1)*'Chart Data'!T$3 -> 0.15133687 | L25: =HAVERM!D293 -> 1.6 | V25: 40848 | W25: =HAVERM!J149/SUM(HAVERM!J139:J150) -> 0.080404092 | X25: =1/12 -> 0.083333333 | Y25: =W25-X25 -> -0.0029292415 | AE25: 44501 | AF25: =100*((AVERAGE(HAVERM!M267:M269)/AVERAGE(HAVERM!M255:M257))-1) -> 4.121056 | AG25: =100*((AVERAGE(HAVERM!O267:O269)/AVERAGE(HAVERM!O255:O257))-1) -> 5.3992661 | AH25: =HAVERM!Q269 -> #N/A | AI25: =HAVERM!S269 -> 3.8531328 | AJ25: ='[1]Manual Monthly DATA'!D597 -> 2.5
G26: 45261 | H26: =100*((HAVERM!E294/HAVERM!E293)-1)*'Chart Data'!Q$3 -> -1.4595991 | I26: =100*((HAVERM!F294/HAVERM!F293)-1)*'Chart Data'!R$3 -> -1.4833006 | J26: =100*((HAVERM!G294/HAVERM!G293)-1)*'Chart Data'!S$3 -> -0.22560564 | K26: =100*((HAVERM!H294/HAVERM!H293)-1)*'Chart Data'!T$3 -> -0.37898221 | L26: =HAVERM!D294 -> -3.6 | M26: 100 | V26: 40878 | W26: =HAVERM!J150/SUM(HAVERM!J139:J150) -> 0.11401155 | X26: =1/12 -> 0.083333333 | Y26: =W26-X26 -> 0.030678216 | AE26: 44531 | AF26: =100*((AVERAGE(HAVERM!M268:M270)/AVERAGE(HAVERM!M256:M258))-1) -> 3.9616613 | AG26: =100*((AVERAGE(HAVERM!O268:O270)/AVERAGE(HAVERM!O256:O258))-1) -> 5.4279749 | AH26: =HAVERM!Q270 -> #N/A | AI26: =HAVERM!S270 -> 3.9664769 | AJ26: ='[1]Manual Monthly DATA'!D598 -> 2.3
G27: 45292 | H27: =100*((HAVERM!E295/HAVERM!E294)-1)*'Chart Data'!Q$3 -> 1.3987144 | I27: =100*((HAVERM!F295/HAVERM!F294)-1)*'Chart Data'!R$3 -> 1.0557435 | J27: =100*((HAVERM!G295/HAVERM!G294)-1)*'Chart Data'!S$3 -> 0.18906592 | K27: =100*((HAVERM!H295/HAVERM!H294)-1)*'Chart Data'!T$3 -> 0.85617933 | L27: =HAVERM!D295 -> 3.5 | M27: 100 | V27: 40909 | W27: =HAVERM!J151/SUM(HAVERM!J151:J162) -> 0.069880969 | X27: =1/12 -> 0.083333333 | Y27: =W27-X27 -> -0.013452364 | AE27: 44562 | AF27: =100*((AVERAGE(HAVERM!M269:M271)/AVERAGE(HAVERM!M257:M259))-1) -> 4.2620865 | AG27: =100*((AVERAGE(HAVERM!O269:O271)/AVERAGE(HAVERM!O257:O259))-1) -> 5.7742327 | AH27: =HAVERM!Q271 -> #N/A | AI27: =HAVERM!S271 -> 4.0191961 | AJ27: ='[1]Manual Monthly DATA'!D599 -> 3.5
G28: 45323 | H28: =100*((HAVERM!E296/HAVERM!E295)-1)*'Chart Data'!Q$3 -> -0.15411476 | I28: =100*((HAVERM!F296/HAVERM!F295)-1)*'Chart Data'!R$3 -> 0.39517124 | J28: =100*((HAVERM!G296/HAVERM!G295)-1)*'Chart Data'!S$3 -> 0.013311587 | K28: =100*((HAVERM!H296/HAVERM!H295)-1)*'Chart Data'!T$3 -> -0.1986797 | L28: =HAVERM!D296 -> 0 | V28: 40940 | W28: =HAVERM!J152/SUM(HAVERM!J151:J162) -> 0.073256024 | X28: =1/12 -> 0.083333333 | Y28: =W28-X28 -> -0.010077309 | AE28: 44593 | AF28: =100*((AVERAGE(HAVERM!M270:M272)/AVERAGE(HAVERM!M258:M260))-1) -> 4.6349206 | AG28: =100*((AVERAGE(HAVERM!O270:O272)/AVERAGE(HAVERM!O258:O260))-1) -> 5.9168535 | AH28: =HAVERM!Q272 -> #N/A | AI28: =HAVERM!S272 -> 4.1673631 | AJ28: ='[1]Manual Monthly DATA'!D600 -> 3.5
G29: 45352 | H29: =100*((HAVERM!E297/HAVERM!E296)-1)*'Chart Data'!Q$3 -> -0.54162369 | I29: =100*((HAVERM!F297/HAVERM!F296)-1)*'Chart Data'!R$3 -> 0.039113888 | J29: =100*((HAVERM!G297/HAVERM!G296)-1)*'Chart Data'!S$3 -> -0.079788021 | K29: =100*((HAVERM!H297/HAVERM!H296)-1)*'Chart Data'!T$3 -> 0.33718399 | L29: =HAVERM!D297 -> -0.3 | V29: 40969 | W29: =HAVERM!J153/SUM(HAVERM!J151:J162) -> 0.093251743 | X29: =1/12 -> 0.083333333 | Y29: =W29-X29 -> 0.0099184098 | AE29: 44621 | AF29: =100*((AVERAGE(HAVERM!M271:M273)/AVERAGE(HAVERM!M259:M261))-1) -> 5.0095117 | AG29: =100*((AVERAGE(HAVERM!O271:O273)/AVERAGE(HAVERM!O259:O261))-1) -> 6.1683849 | AH29: =HAVERM!Q273 -> #N/A | AI29: =HAVERM!S273 -> 4.6858817 | AJ29: ='[1]Manual Monthly DATA'!D601 -> 3.7
G30: 45383 | H30: =100*((HAVERM!E298/HAVERM!E297)-1)*'Chart Data'!Q$3 -> -0.2355202 | I30: =100*((HAVERM!F298/HAVERM!F297)-1)*'Chart Data'!R$3 -> -0.9377764 | J30: =100*((HAVERM!G298/HAVERM!G297)-1)*'Chart Data'!S$3 -> 0.053519686 | K30: =100*((HAVERM!H298/HAVERM!H297)-1)*'Chart Data'!T$3 -> -0.55627054 | L30: =HAVERM!D298 -> -1.7 | V30: 41000 | W30: =HAVERM!J154/SUM(HAVERM!J151:J162) -> 0.075831686 | X30: =1/12 -> 0.083333333 | Y30: =W30-X30 -> -0.0075016473 | AE30: 44652 | AF30: =100*((AVERAGE(HAVERM!M272:M274)/AVERAGE(HAVERM!M260:M262))-1) -> 4.9273531 | AG30: =100*((AVERAGE(HAVERM!O272:O274)/AVERAGE(HAVERM!O260:O262))-1) -> 6.0652657 | AH30: =HAVERM!Q274 -> #N/A | AI30: =HAVERM!S274 -> 5.5117091 | AJ30: ='[1]Manual Monthly DATA'!D602 -> 4
G31: 45413 | H31: =100*((HAVERM!E299/HAVERM!E298)-1)*'Chart Data'!Q$3 -> 0.39501022 | I31: =100*((HAVERM!F299/HAVERM!F298)-1)*'Chart Data'!R$3 -> 1.1615639 | J31: =100*((HAVERM!G299/HAVERM!G298)-1)*'Chart Data'!S$3 -> 0.79951187 | K31: =100*((HAVERM!H299/HAVERM!H298)-1)*'Chart Data'!T$3 -> 0.29859205 | L31: =HAVERM!D299 -> 2.7 | V31: 41030 | W31: =HAVERM!J155/SUM(HAVERM!J151:J162) -> 0.076585776 | X31: =1/12 -> 0.083333333 | Y31: =W31-X31 -> -0.0067475578 | AE31: 44682 | AF31: =100*((AVERAGE(HAVERM!M273:M275)/AVERAGE(HAVERM!M261:M263))-1) -> 5.223411 | AG31: =100*((AVERAGE(HAVERM!O273:O275)/AVERAGE(HAVERM!O261:O263))-1) -> 6.1978546 | AH31: =HAVERM!Q275 -> 5.465 | AI31: =HAVERM!S275 -> 6.2663686 | AJ31: ='[1]Manual Monthly DATA'!D603 -> 4
G32: 45444 | H32: =100*((HAVERM!E300/HAVERM!E299)-1)*'Chart Data'!Q$3 -> -0.46907977 | I32: =100*((HAVERM!F300/HAVERM!F299)-1)*'Chart Data'!R$3 -> -0.69976571 | J32: =100*((HAVERM!G300/HAVERM!G299)-1)*'Chart Data'!S$3 -> -0.28876397 | K32: =100*((HAVERM!H300/HAVERM!H299)-1)*'Chart Data'!T$3 -> 0.20128863 | L32: =HAVERM!D300 -> -1.3 | V32: 41061 | W32: =HAVERM!J156/SUM(HAVERM!J151:J162) -> 0.096084743 | X32: =1/12 -> 0.083333333 | Y32: =W32-X32 -> 0.01275141 | AE32: 44713 | AF32: =100*((AVERAGE(HAVERM!M274:M276)/AVERAGE(HAVERM!M262:M264))-1) -> 5.4579674 | AG32: =100*((AVERAGE(HAVERM!O274:O276)/AVERAGE(HAVERM!O262:O264))-1) -> 6.1864407 | AH32: =HAVERM!Q276 -> 5.578 | AI32: =HAVERM!S276 -> 6.6071351 | AJ32: ='[1]Manual Monthly DATA'!D604 -> 4
G33: 45474 | H33: =100*((HAVERM!E301/HAVERM!E300)-1)*'Chart Data'!Q$3 -> 0.27708989 | I33: =100*((HAVERM!F301/HAVERM!F300)-1)*'Chart Data'!R$3 -> 0.51478402 | J33: =100*((HAVERM!G301/HAVERM!G300)-1)*'Chart Data'!S$3 -> 0.07703671 | K33: =100*((HAVERM!H301/HAVERM!H300)-1)*'Chart Data'!T$3 -> -0.12081311 | L33: =HAVERM!D301 -> 0.7 | V33: 41091 | W33: =HAVERM!J157/SUM(HAVERM!J151:J162) -> 0.076477716 | X33: =1/12 -> 0.083333333 | Y33: =W33-X33 -> -0.0068556173 | AE33: 44743 | AF33: =100*((AVERAGE(HAVERM!M275:M277)/AVERAGE(HAVERM!M263:M265))-1) -> 6.0150376 | AG33: =100*((AVERAGE(HAVERM!O275:O277)/AVERAGE(HAVERM!O263:O265))-1) -> 6.4570656 | AH33: =HAVERM!Q277 -> 5.541 | AI33: =HAVERM!S277 -> 6.5019789 | AJ33: ='[1]Manual Monthly DATA'!D605 -> 4.4
G34: 45505 | H34: =100*((HAVERM!E302/HAVERM!E301)-1)*'Chart Data'!Q$3 -> 0.82518296 | I34: =100*((HAVERM!F302/HAVERM!F301)-1)*'Chart Data'!R$3 -> 0.2344441 | J34: =100*((HAVERM!G302/HAVERM!G301)-1)*'Chart Data'!S$3 -> -0.15316799 | K34: =100*((HAVERM!H302/HAVERM!H301)-1)*'Chart Data'!T$3 -> 0.066625122 | L34: =HAVERM!D302 -> 1 | V34: 41122 | W34: =HAVERM!J158/SUM(HAVERM!J151:J162) -> 0.075876537 | X34: =1/12 -> 0.083333333 | Y34: =W34-X34 -> -0.0074567964 | AE34: 44774 | AF34: =100*((AVERAGE(HAVERM!M276:M278)/AVERAGE(HAVERM!M264:M266))-1) -> 6.25 | AG34: =100*((AVERAGE(HAVERM!O276:O278)/AVERAGE(HAVERM!O264:O266))-1) -> 6.615048 | AH34: =HAVERM!Q278 -> 5.844 | AI34: =HAVERM!S278 -> 6.4925227 | AJ34: ='[1]Manual Monthly DATA'!D606 -> 4.4
G35: 45536 | H35: =100*((HAVERM!E303/HAVERM!E302)-1)*'Chart Data'!Q$3 -> -0.96124544 | I35: =100*((HAVERM!F303/HAVERM!F302)-1)*'Chart Data'!R$3 -> 0.77672969 | J35: =100*((HAVERM!G303/HAVERM!G302)-1)*'Chart Data'!S$3 -> 0.051663205 | K35: =100*((HAVERM!H303/HAVERM!H302)-1)*'Chart Data'!T$3 -> -0.044151044 | L35: =HAVERM!D303 -> -0.1 | V35: 41153 | W35: =HAVERM!J159/SUM(HAVERM!J151:J162) -> 0.094385112 | X35: =1/12 -> 0.083333333 | Y35: =W35-X35 -> 0.011051779 | AE35: 44805 | AF35: =100*((AVERAGE(HAVERM!M277:M279)/AVERAGE(HAVERM!M265:M267))-1) -> 6.6708229 | AG35: =100*((AVERAGE(HAVERM!O277:O279)/AVERAGE(HAVERM!O265:O267))-1) -> 6.7626381 | AH35: =HAVERM!Q279 -> 6.098 | AI35: =HAVERM!S279 -> 6.3844677 | AJ35: ='[1]Manual Monthly DATA'!D607 -> 4.5
G36: 45566 | H36: =100*((HAVERM!E304/HAVERM!E303)-1)*'Chart Data'!Q$3 -> -0.19729765 | I36: =100*((HAVERM!F304/HAVERM!F303)-1)*'Chart Data'!R$3 -> -0.60904247 | J36: =100*((HAVERM!G304/HAVERM!G303)-1)*'Chart Data'!S$3 -> -0.090053608 | K36: =100*((HAVERM!H304/HAVERM!H303)-1)*'Chart Data'!T$3 -> 0.077573694 | L36: =HAVERM!D304 -> -0.8 | V36: 41183 | W36: =HAVERM!J160/SUM(HAVERM!J151:J162) -> 0.07587191 | X36: =1/12 -> 0.083333333 | Y36: =W36-X36 -> -0.0074614236 | AE36: 44835 | AF36: =100*((AVERAGE(HAVERM!M278:M280)/AVERAGE(HAVERM!M266:M268))-1) -> 6.9565217 | AG36: =100*((AVERAGE(HAVERM!O278:O280)/AVERAGE(HAVERM!O266:O268))-1) -> 6.8121252 | AH36: =HAVERM!Q280 -> 6.306 | AI36: =HAVERM!S280 -> 6.4100252 | AJ36: ='[1]Manual Monthly DATA'!D608 -> 5
G37: 45597 | H37: =100*((HAVERM!E305/HAVERM!E304)-1)*'Chart Data'!Q$3 -> -0.039667869 | I37: =100*((HAVERM!F305/HAVERM!F304)-1)*'Chart Data'!R$3 -> -0.077359456 | J37: =100*((HAVERM!G305/HAVERM!G304)-1)*'Chart Data'!S$3 -> 0.012954318 | K37: =100*((HAVERM!H305/HAVERM!H304)-1)*'Chart Data'!T$3 -> -0.022009691 | L37: =HAVERM!D305 -> -0.1 | V37: 41214 | W37: =HAVERM!J161/SUM(HAVERM!J151:J162) -> 0.079905881 | X37: =1/12 -> 0.083333333 | Y37: =W37-X37 -> -0.0034274522 | AE37: 44866 | AF37: =100*((AVERAGE(HAVERM!M279:M281)/AVERAGE(HAVERM!M267:M269))-1) -> 7.2974644 | AG37: =100*((AVERAGE(HAVERM!O279:O281)/AVERAGE(HAVERM!O267:O269))-1) -> 7.443634 | AH37: =HAVERM!Q281 -> 6.219 | AI37: =HAVERM!S281 -> 6.3297544 | AJ37: ='[1]Manual Monthly DATA'!D609 -> 5
G38: 45627 | H38: =100*((HAVERM!E306/HAVERM!E305)-1)*'Chart Data'!Q$3 -> -0.75448622 | I38: =100*((HAVERM!F306/HAVERM!F305)-1)*'Chart Data'!R$3 -> 0.42633743 | J38: =100*((HAVERM!G306/HAVERM!G305)-1)*'Chart Data'!S$3 -> -0.44000941 | K38: =100*((HAVERM!H306/HAVERM!H305)-1)*'Chart Data'!T$3 -> 0.12129444 | L38: =HAVERM!D306 -> -0.6 | M38: 100 | V38: 41244 | W38: =HAVERM!J162/SUM(HAVERM!J151:J162) -> 0.1125919 | X38: =1/12 -> 0.083333333 | Y38: =W38-X38 -> 0.02925857 | AE38: 44896 | AF38: =100*((AVERAGE(HAVERM!M280:M282)/AVERAGE(HAVERM!M268:M270))-1) -> 7.314075 | AG38: =100*((AVERAGE(HAVERM!O280:O282)/AVERAGE(HAVERM!O268:O270))-1) -> 7.640264 | AH38: =HAVERM!Q282 -> 6.26 | AI38: =HAVERM!S282 -> 6.3690215 | AJ38: ='[1]Manual Monthly DATA'!D610 -> 5
G39: 45658 | H39: =100*((HAVERM!E307/HAVERM!E306)-1)*'Chart Data'!Q$3 -> 2.1072325 | I39: =100*((HAVERM!F307/HAVERM!F306)-1)*'Chart Data'!R$3 -> -0.49831093 | J39: =100*((HAVERM!G307/HAVERM!G306)-1)*'Chart Data'!S$3 -> 0.30805447 | K39: =100*((HAVERM!H307/HAVERM!H306)-1)*'Chart Data'!T$3 -> -0.13088718 | L39: =HAVERM!D307 -> 1.7 | M39: 100 | V39: 41275 | W39: =HAVERM!J163/SUM(HAVERM!J163:J174) -> 0.069640758 | X39: =1/12 -> 0.083333333 | Y39: =W39-X39 -> -0.013692575 | AE39: 44927 | AF39: =100*((AVERAGE(HAVERM!M281:M283)/AVERAGE(HAVERM!M269:M271))-1) -> 7.0774863 | AG39: =100*((AVERAGE(HAVERM!O281:O283)/AVERAGE(HAVERM!O269:O271))-1) -> 7.704918 | AH39: =HAVERM!Q283 -> 6.339 | AI39: =HAVERM!S283 -> 6.3690215 | AJ39: ='[1]Manual Monthly DATA'!D611 -> 6
V40: 41306 | W40: =HAVERM!J164/SUM(HAVERM!J163:J174) -> 0.072464108 | X40: =1/12 -> 0.083333333 | Y40: =W40-X40 -> -0.010869226 | AE40: 44958 | AF40: =100*((AVERAGE(HAVERM!M282:M284)/AVERAGE(HAVERM!M270:M272))-1) -> 7.0995146 | AG40: =100*((AVERAGE(HAVERM!O282:O284)/AVERAGE(HAVERM!O270:O272))-1) -> 7.3452769 | AH40: =HAVERM!Q284 -> 6.51 | AI40: =HAVERM!S284 -> 6.452748 | AJ40: ='[1]Manual Monthly DATA'!D612 -> 6
...

Sheet HAVERM
B1: 200001 !M | C1: ECY2@UK | D1: J5EC@UK | E1: EAPT@UK | F1: EAPV@UK | G1: J5DZ@UK | H1: JO5A@UK | I1: UKSRFN@UK | J1: UKNRFN@UK | K1: KAB9@UK | L1: KAI7@UK | M1: KAJ2@UK | N1: UKSEPPM@UK | O1: UKSEPPD@UK | P1: UNVDWR@UK | Q1: UNVDWR3@UK | R1: UKNVYY@UK | S1: UKNVYM@UK
B2: .DESC | C2: UK: Gross Value Added Chained Volume Index (SA, 2022=100) | D2: Great Britain: Retail Sales Volume: Retailing Inc Auto Fuel(SA, Mo/Mo %Chg) | E2: Great Britain: Retail Sales Volume: Predominantly Food Stores (SA, 2022=100) | F2: Great Britain: Retail Sales Volume: Predominantly Nonfood Stores (SA, 2022=100) | G2: Great Britain: Retail Sales Volume: Nonstore Retailing (SA, 2022=100) | H2: Great Britain: Retail Sales Volume: Predominantly Automotive Fuel (SA, 2022=100) | I2: Great Britain: Retail Sales Value: Predominantly Food Stores(SA, Thous.GBP) | J2: Great Britain: Retail Sales Value: Predominantly Food Stores (NSA, Thous.GBP) | K2: Great Britain: AWE, Total Pay: Whole Economy (SA, GBP) | L2: Great Britain: AWE, Regular Pay: Whole Economy (SA, GBP) | M2: Great Britain: Average Weekly Earnings, Regular Pay: Private Sector (SA, GBP) | N2: UK: Mean Monthly Pay: Pay As You Earn Real Time Information [RTI] (SA, GBP) | O2: UK: Median Monthly Pay: PAYE Real Time Information [RTI] (SA, GBP) | P2: UK: BoE DMP: Realized Wage Growth Over the Past Year: Single Month (%) | Q2: UK: BoE DMP: Realized Wage Growth Over the Past Year: 3 Month Average (%) | R2: UK: Indeed Wage Tracker: Posted Wage Growth (NSA, Y/Y% Chg) | S2: UK: Indeed Wage Tracker: Posted Wage Growth: 3 Month MA (NSA, Y/Y% Chg)
B3: .T1 | C3: Jan-1997 | D3: Feb-1996 | E3: Jan-1989 | F3: Jan-1989 | G3: Jan-1989 | H3: Jan-1996 | I3: Jan-1994 | J3: Jan-1986 | K3: Jan-2000 | L3: Jan-2000 | M3: Jan-2000 | N3: Jul-2014 | O3: Jul-2014 | P3: Aug-2017 | Q3: Aug-2017 | R3: Jan-2019 | S3: Mar-2019
B4: .TN | C4: Jan-2025 | D4: Jan-2025 | E4: Jan-2025 | F4: Jan-2025 | G4: Jan-2025 | H4: Jan-2025 | I4: Jan-2025 | J4: Jan-2025 | K4: Jan-2025 | L4: Jan-2025 | M4: Jan-2025 | N4: Jan-2025 | O4: Feb-2025 | P4: Feb-2025 | Q4: Feb-2025 | R4: Feb-2025 | S4: Feb-2025
B5: .LSOURCE | C5: Office for National Statistics | D5: Office for National Statistics | E5: Office for National Statistics | F5: Office for National Statistics | G5: Office for National Statistics | H5: Office for National Statistics | I5: Office for National Statistics | J5: Office for National Statistics | K5: Office for National Statistics | L5: Office for National Statistics | M5: Office for National Statistics | N5: Office for National Statistics | O5: Office for National Statistics | P5: Bank of England | Q5: Bank of England | R5: Indeed Hiring Lab | S5: Indeed Hiring Lab
B6: .DTLM | C6: Mar-14-2025 07:01 | D6: Feb-21-2025 07:01 | E6: Feb-21-2025 07:01 | F6: Feb-21-2025 07:01 | G6: Feb-21-2025 07:01 | H6: Feb-21-2025 07:01 | I6: Feb-21-2025 07:11 | J6: Feb-21-2025 07:11 | K6: Mar-20-2025 07:02 | L6: Mar-20-2025 07:02 | M6: Mar-20-2025 07:02 | N6: Mar-20-2025 07:02 | O6: Mar-20-2025 07:02 | P6: Mar-06-2025 09:31 | Q6: Mar-06-2025 09:31 | R6: Mar-17-2025 12:56 | S6: Mar-17-2025 12:56
A7: 36526 | B7: 200001 | C7: 69.9 | D7: 2 | E7: 79.5 | F7: 63.5 | G7: 25.3 | H7: 89 | I7: 6950432 | J7: 6494866 | K7: 305 | L7: 293 | M7: 289 | N7: #N/A | O7: #N/A | P7: #N/A | Q7: #N/A | R7: #N/A | S7: #N/A
A8: 36557 | B8: 200002 | C8: 69.7 | D8: -1.9 | E8: 78.6 | F8: 61.4 | G8: 25.9 | H8: 89.2 | I8: 6896586 | J8: 6657275 | K8: 300 | L8: 293 | M8: 289 | N8: #N/A | O8: #N/A | P8: #N/A | Q8: #N/A | R8: #N/A | S8: #N/A
A9: 36586 | B9: 200003 | C9: 69.5 | D9: 0.4 | E9: 78.9 | F9: 62.3 | G9: 25.7 | H9: 84.7 | I9: 8596415 | J9: 8422866 | K9: 311 | L9: 293 | M9: 289 | N9: #N/A | O9: #N/A | P9: #N/A | Q9: #N/A | R9: #N/A | S9: #N/A
A10: 36617 | B10: 200004 | C10: 69.9 | D10: 1.8 | E10: 80.1 | F10: 61.4 | G10: 25.2 | H10: 105.6 | I10: 6985467 | J10: 7028461 | K10: 309 | L10: 293 | M10: 289 | N10: #N/A | O10: #N/A | P10: #N/A | Q10: #N/A | R10: #N/A | S10: #N/A
A11: 36647 | B11: 200005 | C11: 70.4 | D11: -1.4 | E11: 78 | F11: 62.3 | G11: 26 | H11: 93.1 | I11: 6830203 | J11: 6848854 | K11: 311 | L11: 294 | M11: 291 | N11: #N/A | O11: #N/A | P11: #N/A | Q11: #N/A | R11: #N/A | S11: #N/A
A12: 36678 | B12: 200006 | C12: 70.6 | D12: 0 | E12: 78.6 | F12: 62.6 | G12: 25 | H12: 89.5 | I12: 8634738 | J12: 8602626 | K12: 311 | L12: 295 | M12: 291 | N12: #N/A | O12: #N/A | P12: #N/A | Q12: #N/A | R12: #N/A | S12: #N/A
A13: 36708 | B13: 200007 | C13: 70.4 | D13: -0.4 | E13: 78.1 | F13: 63.3 | G13: 25.1 | H13: 83.1 | I13: 6934980 | J13: 6904056 | K13: 313 | L13: 296 | M13: 292 | N13: #N/A | O13: #N/A | P13: #N/A | Q13: #N/A | R13: #N/A | S13: #N/A
A14: 36739 | B14: 200008 | C14: 71.1 | D14: 1.5 | E14: 79.3 | F14: 63.7 | G14: 25.7 | H14: 87.5 | I14: 7006450 | J14: 6888786 | K14: 315 | L14: 297 | M14: 293 | N14: #N/A | O14: #N/A | P14: #N/A | Q14: #N/A | R14: #N/A | S14: #N/A
A15: 36770 | B15: 200009 | C15: 70.9 | D15: -0.1 | E15: 79.5 | F15: 63.4 | G15: 25.8 | H15: 87.6 | I15: 8787261 | J15: 8452164 | K15: 317 | L15: 299 | M15: 296 | N15: #N/A | O15: #N/A | P15: #N/A | Q15: #N/A | R15: #N/A | S15: #N/A
A16: 36800 | B16: 200010 | C16: 71 | D16: 0.7 | E16: 79.4 | F16: 64.3 | G16: 26.4 | H16: 87.3 | I16: 7030927 | J16: 6831758 | K16: 318 | L16: 300 | M16: 297 | N16: #N/A | O16: #N/A | P16: #N/A | Q16: #N/A | R16: #N/A | S16: #N/A
A17: 36831 | B17: 200011 | C17: 71.3 | D17: 0 | E17: 79.7 | F17: 64 | G17: 26.6 | H17: 87.8 | I17: 7091000 | J17: 7209019 | K17: 320 | L17: 302 | M17: 298 | N17: #N/A | O17: #N/A | P17: #N/A | Q17: #N/A | R17: #N/A | S17: #N/A
A18: 36861 | B18: 200012 | C18: 71.6 | D18: 0.1 | E18: 79.7 | F18: 64.2 | G18: 27.7 | H18: 85.1 | I18: 8885448 | J18: 10322477 | K18: 323 | L18: 303 | M18: 299 | N18: #N/A | O18: #N/A | P18: #N/A | Q18: #N/A | R18: #N/A | S18: #N/A
... A180: 41791 | B180: 201406 | C180: 88.6 | D180: 0.7 | E180: 94.2 | F180: 91.3 | G180: 46.1 | H180: 91.3 | I180: 14664916 | J180: 14665758 | K180: 470 | L180: 441 | M180: 430 | N180: #N/A | O180: #N/A | P180: #N/A | Q180: #N/A | R180: #N/A | S180: #N/A
A181: 41821 | B181: 201407 | C181: 89.1 | D181: -0.2 | E181: 94.9 | F181: 90.8 | G181: 46.4 | H181: 89.1 | I181: 11774952 | J181: 11650889 | K181: 468 | L181: 442 | M181: 430 | N181: 2188 | O181: 1598 | P181: #N/A | Q181: #N/A | R181: #N/A | S181: #N/A
A182: 41852 | B182: 201408 | C182: 89 | D182: -0.1 | E182: 93.6 | F182: 91.8 | G182: 45.8 | H182: 89.9 | I182: 11626347 | J182: 11346221 | K182: 469 | L182: 443 | M182: 432 | N182: 2195 | O182: 1602 | P182: #N/A | Q182: #N/A | R182: #N/A | S182: #N/A
A183: 41883 | B183: 201409 | C183: 89.2 | D183: -0.2 | E183: 94 | F183: 91.1 | G183: 46.5 | H183: 88.6 | I183: 14575190 | J183: 14133458 | K183: 473 | L183: 445 | M183: 435 | N183: 2199 | O183: 1601 | P183: #N/A | Q183: #N/A | R183: #N/A | S183: #N/A
A184: 41913 | B184: 201410 | C184: 89.6 | D184: 0.8 | E184: 94.5 | F184: 92.4 | G184: 46.3 | H184: 89.1 | I184: 11737193 | J184: 11569175 | K184: 475 | L184: 447 | M184: 437 | N184: 2198 | O184: 1605 | P184: #N/A | Q184: #N/A | R184: #N/A | S184: #N/A
A185: 41944 | B185: 201411 | C185: 89.7 | D185: 0.7 | E185: 95.1 | F185: 93.1 | G185: 46.9 | H185: 89.5 | I185: 11763600 | J185: 12209857 | K185: 475 | L185: 445 | M185: 436 | N185: 2215 | O185: 1607 | P185: #N/A | Q185: #N/A | R185: #N/A | S185: #N/A
A186: 41974 | B186: 201412 | C186: 89.7 | D186: 1.4 | E186: 95.3 | F186: 94.9 | G186: 48.8 | H186: 91.3 | I186: 14700695 | J186: 16669044 | K186: 478 | L186: 447 | M186: 437 | N186: 2237 | O186: 1616 | P186: #N/A | Q186: #N/A | R186: #N/A | S186: #N/A
A187: 42005 | B187: 201501 | C187: 89.6 | D187: 0 | E187: 94.9 | F187: 93 | G187: 48.9 | H187: 101.2 | I187: 11630099 | J187: 10871133 | K187: 476 | L187: 448 | M187: 439 | N187: 2236 | O187: 1620 | P187: #N/A | Q187: #N/A | R187: #N/A | S187: #N/A
A188: 42036 | B188: 201502 | C188: 89.9 | D188: 0.3 | E188: 95 | F188: 95 | G188: 49.9 | H188: 93.9 | I188: 11610747 | J188: 11138337 | K188: 478 | L188: 450 | M188: 440 | N188: 2234 | O188: 1620 | P188: #N/A | Q188: #N/A | R188: #N/A | S188: #N/A
A189: 42064 | B189: 201503 | C189: 89.9 | D189: 0.3 | E189: 95.6 | F189: 95.1 | G189: 50.8 | H189: 92.2 | I189: 14601769 | J189: 14616896 | K189: 480 | L189: 452 | M189: 443 | N189: 2219 | O189: 1618 | P189: #N/A | Q189: #N/A | R189: #N/A | S189: #N/A
A190: 42095 | B190: 201504 | C190: 90.4 | D190: 0.7 | E190: 95.7 | F190: 95.6 | G190: 51.4 | H190: 95.5 | I190: 11640310 | J190: 11221112 | K190: 481 | L190: 452 | M190: 442 | N190: 2228 | O190: 1613 | P190: #N/A | Q190: #N/A | R190: #N/A | S190: #N/A
A191: 42125 | B191: 201505 | C191: 90.3 | D191: -0.5 | E191: 95.9 | F191: 95.1 | G191: 51.1 | H191: 92.6 | I191: 11700266 | J191: 11747408 | K191: 482 | L191: 453 | M191: 443 | N191: 2222 | O191: 1615 | P191: #N/A | Q191: #N/A | R191: #N/A | S191: #N/A
A192: 42156 | B192: 201506 | C192: 90.2 | D192: 0.7 | E192: 96 | F192: 95.3 | G192: 52.7 | H192: 95.6 | I192: 14662580 | J192: 14653525 | K192: 481 | L192: 453 | M192: 444 | N192: 2222 | O192: 1617 | P192: #N/A | Q192: #N/A | R192: #N/A | S192: #N/A
... A217: 42917 | B217: 201707 | C217: 94.8 | D217: 0.2 | E217: 98.7 | F217: 99.8 | G217: 68.9 | H217: 102.5 | I217: 12125706 | J217: 12130531 | K217: 504 | L217: 474 | M217: 465 | N217: 2330 | O217: 1693 | P217: #N/A | Q217: #N/A | R217: #N/A | S217: #N/A
A218: 42948 | B218: 201708 | C218: 95 | D218: 0.9 | E218: 99.1 | F218: 100.8 | G218: 71.1 | H218: 102.7 | I218: 12149385 | J218: 11857642 | K218: 507 | L218: 475 | M218: 467 | N218: 2336 | O218: 1700 | P218: 2.6 | Q218: 2.634 | R218: #N/A | S218: #N/A
A219: 42979 | B219: 201709 | C219: 95.4 | D219: -0.2 | E219: 99.2 | F219: 98.8 | G219: 75.1 | H219: 103 | I219: 15280740 | J219: 14745776 | K219: 509 | L219: 476 | M219: 468 | N219: 2346 | O219: 1704 | P219: 2.5 | Q219: 2.556 | R219: #N/A | S219: #N/A
A220: 43009 | B220: 201710 | C220: 95.4 | D220: 0.5 | E220: 99.6 | F220: 100 | G220: 72.9 | H220: 104.3 | I220: 12336150 | J220: 12123767 | K220: 509 | L220: 476 | M220: 468 | N220: 2345 | O220: 1706 | P220: 2.7 | Q220: 2.619 | R220: #N/A | S220: #N/A
A221: 43040 | B221: 201711 | C221: 95.6 | D221: 0 | E221: 99.5 | F221: 100 | G221: 73 | H221: 104.7 | I221: 12355864 | J221: 12623267 | K221: 510 | L221: 478 | M221: 470 | N221: 2351 | O221: 1713 | P221: #N/A | Q221: #N/A | R221: #N/A | S221: #N/A
A222: 43070 | B222: 201712 | C222: 95.9 | D222: 0.1 | E222: 99.7 | F222: 100.5 | G222: 72.4 | H222: 103.3 | I222: 15489601 | J222: 18018148 | K222: 512 | L222: 479 | M222: 472 | N222: 2360 | O222: 1721 | P222: #N/A | Q222: #N/A | R222: #N/A | S222: #N/A
A223: 43101 | B223: 201801 | C223: 95.7 | D223: -0.7 | E223: 98.5 | F223: 100.2 | G223: 71.4 | H223: 103.9 | I223: 12306623 | J223: 11195224 | K223: 510 | L223: 480 | M223: 473 | N223: 2367 | O223: 1725 | P223: #N/A | Q223: #N/A | R223: #N/A | S223: #N/A
A224: 43132 | B224: 201802 | C224: 95.8 | D224: 0.3 | E224: 99.4 | F224: 99.4 | G224: 72.7 | H224: 104.8 | I224: 12415147 | J224: 11854367 | K224: 513 | L224: 482 | M224: 475 | N224: 2380 | O224: 1728 | P224: #N/A | Q224: #N/A | R224: #N/A | S224: #N/A
A225: 43160 | B225: 201803 | C225: 95.7 | D225: -1.7 | E225: 98.2 | F225: 98.3 | G225: 70.8 | H225: 99.7 | I225: 15362030 | J225: 15546592 | K225: 513 | L225: 484 | M225: 476 | N225: 2388 | O225: 1729 | P225: #N/A | Q225: #N/A | R225: #N/A | S225: #N/A
...
