Workbook
Name _DLX1.INC: HAVERM!$B$2:$AH$7
Name _DLX2.INC: HAVERD!$G$3:$GV$8
Name _DLX3.INC: HAVERQ!$B$2:$H$7
Name Data: [1]sheet0!$C$2

Sheet >> MARKET PRICING CHARTS

Sheet >> DATA

Sheet Chart Data
A1: Services inflation | G1: Private sector pay growth | K1: Inflation forecasts | R1: BoE DMP | X1: BoE DMP | AD1: Trade policy uncertainty
B2: Outturn | C2: BoE staff forecast (May) | D2: BoE staff forecast (Aug) | E2: BoE staff forecast (Nov)
B3: Outturn | E3: BoE forecast | H3: Outturn | I3: BoE forecast | L3: CPI inflation | M3: BoE market expectations (Aug) | N3: OE (Oct) | O3: HMT consensus (Oct) | P3: 2% LINE | S3: Prices - past year | T3: Prices - next year | U3: Wages - past year | V3: Wages - next year | Y3: Prices - past year | Z3: Prices - next year | AA3: Wages - past year | AB3: Wages - next year | AE3: UK economic policy uncertainty (LHS) | AF3: US trade policy uncertainty (RHS)
A4: 44562 | B4: =100*((HAVERM!D152/HAVERM!D140)-1) -> 3.2685512 | G4: 44562 | H4: =HAVERM!E152 -> 4.5 | K4: 44927 | L4: =100*((HAVERQ!F40/HAVERQ!F36)-1) -> 10.178263 | P4: 2 | R4: 43466 | S4: =HAVERM!F116 -> 2.79 | T4: =HAVERM!G116 -> 2.531 | U4: =HAVERM!H116 -> #N/A | V4: =HAVERM!I116 -> #N/A | X4: 43466 | Y4: =HAVERM!J116 -> 2.525 | Z4: =HAVERM!K116 -> 2.471 | AA4: =HAVERM!L116 -> #N/A | AB4: =HAVERM!M116 -> #N/A | AD4: 42005 | AE4: =HAVERM!P68 -> 135.73044 | AF4: ='Bloom - Monthly US data'!M362 -> 33.807758
A5: 44593 | B5: =100*((HAVERM!D153/HAVERM!D141)-1) -> 3.4391534 | G5: 44593 | H5: =HAVERM!E153 -> 4.9 | K5: 45017 | L5: =100*((HAVERQ!F41/HAVERQ!F37)-1) -> 8.4390513 | P5: 2 | R5: 43497 | S5: =HAVERM!F117 -> 2.23 | T5: =HAVERM!G117 -> 2.56 | U5: =HAVERM!H117 -> #N/A | V5: =HAVERM!I117 -> #N/A | X5: 43497 | Y5: =HAVERM!J117 -> 2.415 | Z5: =HAVERM!K117 -> 2.424 | AA5: =HAVERM!L117 -> #N/A | AB5: =HAVERM!M117 -> #N/A | AD5: 42036 | AE5: =HAVERM!P69 -> 119.08362 | AF5: ='Bloom - Monthly US data'!M363 -> 15.410779
A6: 44621 | B6: =100*((HAVERM!D154/HAVERM!D142)-1) -> 3.9612676 | G6: 44621 | H6: =HAVERM!E154 -> 5.3 | K6: 45108 | L6: =100*((HAVERQ!F42/HAVERQ!F38)-1) -> 6.7135896 | P6: 2 | R6: 43525 | S6: =HAVERM!F118 -> 2.4 | T6: =HAVERM!G118 -> 2.066 | U6: =HAVERM!H118 -> #N/A | V6: =HAVERM!I118 -> #N/A | X6: 43525 | Y6: =HAVERM!J118 -> 2.474 | Z6: =HAVERM!K118 -> 2.386 | AA6: =HAVERM!L118 -> #N/A | AB6: =HAVERM!M118 -> #N/A | AD6: 42064 | AE6: =HAVERM!P70 -> 131.49865 | AF6: ='Bloom - Monthly US data'!M364 -> 27.907613
A7: 44652 | B7: =100*((HAVERM!D155/HAVERM!D143)-1) -> 4.7244094 | G7: 44652 | H7: =HAVERM!E155 -> 5.2 | K7: 45200 | L7: =100*((HAVERQ!F43/HAVERQ!F39)-1) -> 4.1568008 | P7: 2 | R7: 43556 | S7: =HAVERM!F119 -> 2.87 | T7: =HAVERM!G119 -> 2.705 | U7: =HAVERM!H119 -> #N/A | V7: =HAVERM!I119 -> #N/A | X7: 43556 | Y7: =HAVERM!J119 -> 2.501 | Z7: =HAVERM!K119 -> 2.444 | AA7: =HAVERM!L119 -> #N/A | AB7: =HAVERM!M119 -> #N/A | AD7: 42095 | AE7: =HAVERM!P71 -> 170.47333 | AF7: ='Bloom - Monthly US data'!M365 -> 41.600503
A8: 44682 | B8: =100*((HAVERM!D156/HAVERM!D144)-1) -> 4.886562 | G8: 44682 | H8: =HAVERM!E156 -> 5.4 | K8: 45292 | L8: =100*((HAVERQ!F44/HAVERQ!F40)-1) -> 3.5490605 | N8: =100*((GMW!B211/GMW!B207)-1) -> 3.5491137 | P8: 2 | R8: 43586 | S8: =HAVERM!F120 -> 1.78 | T8: =HAVERM!G120 -> 2.318 | U8: =HAVERM!H120 -> #N/A | V8: =HAVERM!I120 -> #N/A | X8: 43586 | Y8: =HAVERM!J120 -> 2.348 | Z8: =HAVERM!K120 -> 2.363 | AA8: =HAVERM!L120 -> #N/A | AB8: =HAVERM!M120 -> #N/A | AD8: 42125 | AE8: =HAVERM!P72 -> 140.91246 | AF8: ='Bloom - Monthly US data'!M366 -> 88.91986
A9: 44713 | B9: =100*((HAVERM!D157/HAVERM!D145)-1) -> 5.2173913 | G9: 44713 | H9: =HAVERM!E157 -> 5.7 | K9: 45383 | L9: =100*((HAVERQ!F45/HAVERQ!F41)-1) -> 2.110885 | N9: =100*((GMW!B212/GMW!B208)-1) -> 2.1108336 | P9: 2 | R9: 43617 | S9: =HAVERM!F121 -> 2.7 | T9: =HAVERM!G121 -> 2.158 | U9: =HAVERM!H121 -> #N/A | V9: =HAVERM!I121 -> #N/A | X9: 43617 | Y9: =HAVERM!J121 -> 2.449 | Z9: =HAVERM!K121 -> 2.394 | AA9: =HAVERM!L121 -> #N/A | AB9: =HAVERM!M121 -> #N/A | AD9: 42156 | AE9: =HAVERM!P73 -> 148.81656 | AF9: ='Bloom - Monthly US data'!M367 -> 100.80304
A10: 44743 | B10: =100*((HAVERM!D158/HAVERM!D146)-1) -> 5.7241977 | G10: 44743 | H10: =HAVERM!E158 -> 6.1 | K10: 45474 | L10: =100*((HAVERQ!F46/HAVERQ!F42)-1) -> 2.0547945 | M10: =HAVERQ!C46 -> #N/A | N10: =100*((GMW!B213/GMW!B209)-1) -> 2.0547945 | P10: 2 | R10: 43647 | S10: =HAVERM!F122 -> 2.26 | T10: =HAVERM!G122 -> 2.099 | U10: =HAVERM!H122 -> #N/A | V10: =HAVERM!I122 -> #N/A | X10: 43647 | Y10: =HAVERM!J122 -> 2.246 | Z10: =HAVERM!K122 -> 2.192 | AA10: =HAVERM!L122 -> #N/A | AB10: =HAVERM!M122 -> #N/A | AD10: 42186 | AE10: =HAVERM!P74 -> 136.10011 | AF10: ='Bloom - Monthly US data'!M368 -> 51.49282
A11: 44774 | B11: =100*((HAVERM!D159/HAVERM!D147)-1) -> 5.9585492 | G11: 44774 | H11: =HAVERM!E159 -> 6.4 | K11: 45566 | M11: =HAVERQ!C47 -> #N/A | N11: =100*((GMW!B214/GMW!B210)-1) -> 2.4753214 | O11: 2.6 | P11: 2 | R11: 43678 | S11: =HAVERM!F123 -> 1.91 | T11: =HAVERM!G123 -> 2.281 | U11: =HAVERM!H123 -> #N/A | V11: =HAVERM!I123 -> #N/A | X11: 43678 | Y11: =HAVERM!J123 -> 2.291 | Z11: =HAVERM!K123 -> 2.179 | AA11: =HAVERM!L123 -> #N/A | AB11: =HAVERM!M123 -> #N/A | AD11: 42217 | AE11: =HAVERM!P75 -> 86.14368 | AF11: ='Bloom - Monthly US data'!M369 -> 20.829576
A12: 44805 | B12: =100*((HAVERM!D160/HAVERM!D148)-1) -> 6.1312608 | G12: 44805 | H12: =HAVERM!E160 -> 6.7 | K12: 45658 | M12: =HAVERQ!C48 -> 2.8 | N12: =100*((GMW!B215/GMW!B211)-1) -> 2.6789056 | P12: 2 | R12: 43709 | S12: =HAVERM!F124 -> 2.26 | T12: =HAVERM!G124 -> 2.345 | U12: =HAVERM!H124 -> #N/A | V12: =HAVERM!I124 -> #N/A | X12: 43709 | Y12: =HAVERM!J124 -> 2.142 | Z12: =HAVERM!K124 -> 2.241 | AA12: =HAVERM!L124 -> #N/A | AB12: =HAVERM!M124 -> #N/A | AD12: 42248 | AE12: =HAVERM!P76 -> 135.07501 | AF12: ='Bloom - Monthly US data'!M370 -> 19.60964
A13: 44835 | B13: =100*((HAVERM!D161/HAVERM!D149)-1) -> 6.2660944 | G13: 44835 | H13: =HAVERM!E161 -> 7 | K13: 45748 | M13: =HAVERQ!C49 -> 3.5 | N13: =100*((GMW!B216/GMW!B212)-1) -> 2.8477965 | P13: 2 | R13: 43739 | S13: =HAVERM!F125 -> 1.99 | T13: =HAVERM!G125 -> 2.214 | U13: =HAVERM!H125 -> #N/A | V13: =HAVERM!I125 -> #N/A | X13: 43739 | Y13: =HAVERM!J125 -> 2.053 | Z13: =HAVERM!K125 -> 2.28 | AA13: =HAVERM!L125 -> #N/A | AB13: =HAVERM!M125 -> #N/A | AD13: 42278 | AE13: =HAVERM!P77 -> 89.91453 | AF13: ='Bloom - Monthly US data'!M371 -> 68.608963
A14: 44866 | B14: =100*((HAVERM!D162/HAVERM!D150)-1) -> 6.3464837 | G14: 44866 | H14: =HAVERM!E162 -> 7.3 | K14: 45839 | M14: =HAVERQ!C50 -> 3.7 | N14: =100*((GMW!B217/GMW!B213)-1) -> 3.2950783 | P14: 2 | R14: 43770 | S14: =HAVERM!F126 -> 1.86 | T14: =HAVERM!G126 -> 2.152 | U14: =HAVERM!H126 -> #N/A | V14: =HAVERM!I126 -> #N/A | X14: 43770 | Y14: =HAVERM!J126 -> 2.037 | Z14: =HAVERM!K126 -> 2.237 | AA14: =HAVERM!L126 -> #N/A | AB14: =HAVERM!M126 -> #N/A | AD14: 42309 | AE14: =HAVERM!P78 -> 120.86215 | AF14: ='Bloom - Monthly US data'!M372 -> 20.503122
A15: 44896 | B15: =100*((HAVERM!D163/HAVERM!D151)-1) -> 6.8376068 | G15: 44896 | H15: =HAVERM!E163 -> 7.3 | K15: 45931 | M15: =HAVERQ!C51 -> 3.5 | N15: =100*((GMW!B218/GMW!B214)-1) -> 3.1315512 | O15: 2.2 | P15: 2 | R15: 43800 | S15: =HAVERM!F127 -> 1.99 | T15: =HAVERM!G127 -> 2.372 | U15: =HAVERM!H127 -> #N/A | V15: =HAVERM!I127 -> #N/A | X15: 43800 | Y15: =HAVERM!J127 -> 1.948 | Z15: =HAVERM!K127 -> 2.246 | AA15: =HAVERM!L127 -> #N/A | AB15: =HAVERM!M127 -> #N/A | AD15: 42339 | AE15: =HAVERM!P79 -> 82.87279 | AF15: ='Bloom - Monthly US data'!M373 -> 20.475546
A16: 44927 | B16: =100*((HAVERM!D164/HAVERM!D152)-1) -> 5.9024808 | G16: 44927 | H16: =HAVERM!E164 -> 7.1 | K16: 46023 | M16: =HAVERQ!C52 -> 3 | N16: =100*((GMW!B219/GMW!B215)-1) -> 2.9609749 | P16: 2 | R16: 43831 | S16: =HAVERM!F128 -> 2.06 | T16: =HAVERM!G128 -> 2.117 | U16: =HAVERM!H128 -> #N/A | V16: =HAVERM!I128 -> #N/A | X16: 43831 | Y16: =HAVERM!J128 -> 1.971 | Z16: =HAVERM!K128 -> 2.214 | AA16: =HAVERM!L128 -> #N/A | AB16: =HAVERM!M128 -> #N/A | AD16: 42370 | AE16: =HAVERM!P80 -> 135.63232 | AF16: ='Bloom - Monthly US data'!M374 -> 42.781123
A17: 44958 | B17: =100*((HAVERM!D165/HAVERM!D153)-1) -> 6.6496164 | G17: 44958 | H17: =HAVERM!E165 -> 7.1 | K17: 46113 | M17: =HAVERQ!C53 -> 2.6 | N17: =100*((GMW!B220/GMW!B216)-1) -> 2.5644304 | P17: 2 | R17: 43862 | S17: =HAVERM!F129 -> 1.74 | T17: =HAVERM!G129 -> 2.094 | U17: =HAVERM!H129 -> #N/A | V17: =HAVERM!I129 -> #N/A | X17: 43862 | Y17: =HAVERM!J129 -> 1.931 | Z17: =HAVERM!K129 -> 2.195 | AA17: =HAVERM!L129 -> #N/A | AB17: =HAVERM!M129 -> #N/A | AD17: 42401 | AE17: =HAVERM!P81 -> 190.81671 | AF17: ='Bloom - Monthly US data'!M375 -> 26.272142
A18: 44986 | B18: =100*((HAVERM!D166/HAVERM!D154)-1) -> 6.6892464 | G18: 44986 | H18: =HAVERM!E166 -> 7.2 | K18: 46204 | M18: =HAVERQ!C54 -> 2.6 | N18: =100*((GMW!B221/GMW!B217)-1) -> 2.3642295 | P18: 2 | R18: 43891 | S18: =HAVERM!F130 -> 1.69 | T18: =HAVERM!G130 -> 1.598 | U18: =HAVERM!H130 -> #N/A | V18: =HAVERM!I130 -> #N/A | X18: 43891 | Y18: =HAVERM!J130 -> 1.83 | Z18: =HAVERM!K130 -> 1.937 | AA18: =HAVERM!L130 -> #N/A | AB18: =HAVERM!M130 -> #N/A | AD18: 42430 | AE18: =HAVERM!P82 -> 290.92952 | AF18: ='Bloom - Monthly US data'!M376 -> 49.187943
A19: 45017 | B19: =100*((HAVERM!D167/HAVERM!D155)-1) -> 6.9340017 | G19: 45017 | H19: =HAVERM!E167 -> 7.7 | K19: 46296 | M19: =HAVERQ!C55 -> 2.4 | N19: =100*((GMW!B222/GMW!B218)-1) -> 2.2010035 | P19: 2 | R19: 43922 | S19: =HAVERM!F131 -> 1.87 | T19: =HAVERM!G131 -> 1.213 | U19: =HAVERM!H131 -> #N/A | V19: =HAVERM!I131 -> #N/A | X19: 43922 | Y19: =HAVERM!J131 -> 1.765 | Z19: =HAVERM!K131 -> 1.635 | AA19: =HAVERM!L131 -> #N/A | AB19: =HAVERM!M131 -> #N/A | AD19: 42461 | AE19: =HAVERM!P83 -> 197.1708 | AF19: ='Bloom - Monthly US data'!M377 -> 42.923388
A20: 45047 | B20: =100*((HAVERM!D168/HAVERM!D156)-1) -> 7.3211314 | G20: 45047 | H20: =HAVERM!E168 -> 7.9 | K20: 46388 | M20: =HAVERQ!C56 -> 2.3 | N20: =100*((GMW!B223/GMW!B219)-1) -> 2.1744059 | P20: 2 | R20: 43952 | S20: =HAVERM!F132 -> 1.72 | T20: =HAVERM!G132 -> 1.389 | U20: =HAVERM!H132 -> #N/A | V20: =HAVERM!I132 -> #N/A | X20: 43952 | Y20: =HAVERM!J132 -> 1.759 | Z20: =HAVERM!K132 -> 1.4 | AA20: =HAVERM!L132 -> #N/A | AB20: =HAVERM!M132 -> #N/A | AD20: 42491 | AE20: =HAVERM!P84 -> 246.75491 | AF20: ='Bloom - Monthly US data'!M378 -> 76.848017
A21: 45078 | B21: =100*((HAVERM!D169/HAVERM!D157)-1) -> 7.1900826 | G21: 45078 | H21: =HAVERM!E169 -> 8.2 | K21: 46478 | M21: =HAVERQ!C57 -> 2.2 | N21: =100*((GMW!B224/GMW!B220)-1) -> 2.128077 | P21: 2 | R21: 43983 | S21: =HAVERM!F133 -> 1.18 | T21: =HAVERM!G133 -> 1.431 | U21: =HAVERM!H133 -> #N/A | V21: =HAVERM!I133 -> #N/A | X21: 43983 | Y21: =HAVERM!J133 -> 1.59 | Z21: =HAVERM!K133 -> 1.344 | AA21: =HAVERM!L133 -> #N/A | AB21: =HAVERM!M133 -> #N/A | AD21: 42522 | AE21: =HAVERM!P85 -> 503.94249 | AF21: ='Bloom - Monthly US data'!M379 -> 271.07246
A22: 45108 | B22: =100*((HAVERM!D170/HAVERM!D158)-1) -> 7.4651354 | G22: 45108 | H22: =HAVERM!E170 -> 8.1 | K22: 46569 | M22: =HAVERQ!C58 -> 2.1 | N22: =100*((GMW!B225/GMW!B221)-1) -> 2.1274585 | P22: 2 | R22: 44013 | S22: =HAVERM!F134 -> 1.34 | T22: =HAVERM!G134 -> 1.661 | U22: =HAVERM!H134 -> #N/A | V22: =HAVERM!I134 -> #N/A | X22: 44013 | Y22: =HAVERM!J134 -> 1.414 | Z22: =HAVERM!K134 -> 1.494 | AA22: =HAVERM!L134 -> #N/A | AB22: =HAVERM!M134 -> #N/A | AD22: 42552 | AE22: =HAVERM!P86 -> 558.22364 | AF22: ='Bloom - Monthly US data'!M380 -> 116.30264
A23: 45139 | B23: =100*((HAVERM!D171/HAVERM!D159)-1) -> 6.7644662 | G23: 45139 | H23: =HAVERM!E171 -> 8.1 | K23: 46661 | N23: =100*((GMW!B226/GMW!B222)-1) -> 2.1133327 | P23: 2 | R23: 44044 | S23: =HAVERM!F135 -> 1.04 | T23: =HAVERM!G135 -> 2.16 | U23: =HAVERM!H135 -> #N/A | V23: =HAVERM!I135 -> #N/A | X23: 44044 | Y23: =HAVERM!J135 -> 1.187 | Z23: =HAVERM!K135 -> 1.751 | AA23: =HAVERM!L135 -> #N/A | AB23: =HAVERM!M135 -> #N/A | AD23: 42583 | AE23: =HAVERM!P87 -> 311.36483 | AF23: ='Bloom - Monthly US data'!M381 -> 155.27431
A24: 45170 | B24: =100*((HAVERM!D172/HAVERM!D160)-1) -> 6.916192 | G24: 45170 | H24: =HAVERM!E172 -> 7.8 | R24: 44075 | S24: =HAVERM!F136 -> 1.57 | T24: =HAVERM!G136 -> 1.853 | U24: =HAVERM!H136 -> #N/A | V24: =HAVERM!I136 -> #N/A | X24: 44075 | Y24: =HAVERM!J136 -> 1.317 | Z24: =HAVERM!K136 -> 1.891 | AA24: =HAVERM!L136 -> #N/A | AB24: =HAVERM!M136 -> #N/A | AD24: 42614 | AE24: =HAVERM!P88 -> 209.63794 | AF24: ='Bloom - Monthly US data'!M382 -> 93.079444
A25: 45200 | B25: =100*((HAVERM!D173/HAVERM!D161)-1) -> 6.542811 | G25: 45200 | H25: =HAVERM!E173 -> 7.2 | R25: 44105 | S25: =HAVERM!F137 -> 2.21 | T25: =HAVERM!G137 -> 2.354 | U25: =HAVERM!H137 -> #N/A | V25: =HAVERM!I137 -> #N/A | X25: 44105 | Y25: =HAVERM!J137 -> 1.606 | Z25: =HAVERM!K137 -> 2.122 | AA25: =HAVERM!L137 -> #N/A | AB25: =HAVERM!M137 -> #N/A | AD25: 42644 | AE25: =HAVERM!P89 -> 270.02349 | AF25: ='Bloom - Monthly US data'!M383 -> 83.538371
A26: 45231 | B26: =100*((HAVERM!D174/HAVERM!D162)-1) -> 6.2096774 | G26: 45231 | H26: =HAVERM!E174 -> 6.6 | R26: 44136 | S26: =HAVERM!F138 -> 1.69 | T26: =HAVERM!G138 -> 2.092 | U26: =HAVERM!H138 -> #N/A | V26: =HAVERM!I138 -> #N/A | X26: 44136 | Y26: =HAVERM!J138 -> 1.823 | Z26: =HAVERM!K138 -> 2.099 | AA26: =HAVERM!L138 -> #N/A | AB26: =HAVERM!M138 -> #N/A | AD26: 42675 | AE26: =HAVERM!P90 -> 358.82841 | AF26: ='Bloom - Monthly US data'!M384 -> 540.4187
A27: 45261 | B27: =100*((HAVERM!D175/HAVERM!D163)-1) -> 6.4 | G27: 45261 | H27: =HAVERM!E175 -> 6.2 | R27: 44166 | S27: =HAVERM!F139 -> 0.88 | T27: =HAVERM!G139 -> 2.705 | U27: =HAVERM!H139 -> #N/A | V27: =HAVERM!I139 -> #N/A | X27: 44166 | Y27: =HAVERM!J139 -> 1.591 | Z27: =HAVERM!K139 -> 2.383 | AA27: =HAVERM!L139 -> #N/A | AB27: =HAVERM!M139 -> #N/A | AD27: 42705 | AE27: =HAVERM!P91 -> 196.34369 | AF27: ='Bloom - Monthly US data'!M385 -> 275.12017
A28: 45292 | B28: =100*((HAVERM!D176/HAVERM!D164)-1) -> 6.542811 | G28: 45292 | H28: =HAVERM!E176 -> 6.1 | R28: 44197 | S28: =HAVERM!F140 -> 1.83 | T28: =HAVERM!G140 -> 2.517 | U28: =HAVERM!H140 -> #N/A | V28: =HAVERM!I140 -> #N/A | X28: 44197 | Y28: =HAVERM!J140 -> 1.467 | Z28: =HAVERM!K140 -> 2.438 | AA28: =HAVERM!L140 -> #N/A | AB28: =HAVERM!M140 -> #N/A | AD28: 42736 | AE28: =HAVERM!P92 -> 257.8484 | AF28: ='Bloom - Monthly US data'!M386 -> 474.80271
A29: 45323 | B29: =100*((HAVERM!D177/HAVERM!D165)-1) -> 6.0751399 | G29: 45323 | H29: =HAVERM!E177 -> 5.9 | R29: 44228 | S29: =HAVERM!F141 -> 2.05 | T29: =HAVERM!G141 -> 2.719 | U29: =HAVERM!H141 -> #N/A | V29: =HAVERM!I141 -> #N/A | X29: 44228 | Y29: =HAVERM!J141 -> 1.589 | Z29: =HAVERM!K141 -> 2.647 | AA29: =HAVERM!L141 -> #N/A | AB29: =HAVERM!M141 -> #N/A | AD29: 42767 | AE29: =HAVERM!P93 -> 194.0447 | AF29: ='Bloom - Monthly US data'!M387 -> 250.13309
A30: 45352 | B30: =100*((HAVERM!D178/HAVERM!D166)-1) -> 5.952381 | G30: 45352 | H30: =HAVERM!E178 -> 5.8 | R30: 44256 | S30: =HAVERM!F142 -> 1.65 | T30: =HAVERM!G142 -> 2.973 | U30: =HAVERM!H142 -> #N/A | V30: =HAVERM!I142 -> #N/A | X30: 44256 | Y30: =HAVERM!J142 -> 1.847 | Z30: =HAVERM!K142 -> 2.736 | AA30: =HAVERM!L142 -> #N/A | AB30: =HAVERM!M142 -> #N/A | AD30: 42795 | AE30: =HAVERM!P94 -> 232.45973 | AF30: ='Bloom - Monthly US data'!M388 -> 151.94312
A31: 45383 | B31: =100*((HAVERM!D179/HAVERM!D167)-1) -> 5.859375 | C31: ='MPR Chart 2.16 (May)'!L70 -> 5.52 | G31: 45383 | H31: =HAVERM!E179 -> 5.7 | R31: 44287 | S31: =HAVERM!F143 -> 2.79 | T31: =HAVERM!G143 -> 3.139 | U31: =HAVERM!H143 -> #N/A | V31: =HAVERM!I143 -> #N/A | X31: 44287 | Y31: =HAVERM!J143 -> 2.165 | Z31: =HAVERM!K143 -> 2.944 | AA31: =HAVERM!L143 -> #N/A | AB31: =HAVERM!M143 -> #N/A | AD31: 42826 | AE31: =HAVERM!P95 -> 169.17604 | AF31: ='Bloom - Monthly US data'!M389 -> 153.35011
A32: 45413 | B32: =100*((HAVERM!D180/HAVERM!D168)-1) -> 5.7364341 | C32: ='MPR Chart 2.16 (May)'!L71 -> 5.258 | G32: 45413 | H32: =HAVERM!E180 -> 5.6 | R32: 44317 | S32: =HAVERM!F144 -> 2.83 | T32: =HAVERM!G144 -> 3.442 | U32: =HAVERM!H144 -> #N/A | V32: =HAVERM!I144 -> #N/A | X32: 44317 | Y32: =HAVERM!J144 -> 2.424 | Z32: =HAVERM!K144 -> 3.185 | AA32: =HAVERM!L144 -> #N/A | AB32: =HAVERM!M144 -> #N/A | AD32: 42856 | AE32: =HAVERM!P96 -> 159.40145 | AF32: ='Bloom - Monthly US data'!M390 -> 87.267511
A33: 45444 | B33: =100*((HAVERM!D181/HAVERM!D169)-1) -> 5.7054742 | C33: ='MPR Chart 2.16 (May)'!L72 -> 5.134 | G33: 45444 | H33: =HAVERM!E181 -> 5.4 | R33: 44348 | S33: =HAVERM!F145 -> 3.13 | T33: =HAVERM!G145 -> 3.258 | U33: =HAVERM!H145 -> #N/A | V33: =HAVERM!I145 -> #N/A | X33: 44348 | Y33: =HAVERM!J145 -> 2.915 | Z33: =HAVERM!K145 -> 3.28 | AA33: =HAVERM!L145 -> #N/A | AB33: =HAVERM!M145 -> #N/A | AD33: 42887 | AE33: =HAVERM!P97 -> 318.99116 | AF33: ='Bloom - Monthly US data'!M391 -> 86.858279
A34: 45474 | B34: =100*((HAVERM!D182/HAVERM!D170)-1) -> 5.1908397 | C34: ='MPR Chart 2.16 (May)'!L73 -> 4.949 | D34: ='MPR Chart 2.16 (Aug)'!L49 -> 5.563 | G34: 45474 | H34: =HAVERM!E182 -> 5.2 | R34: 44378 | S34: =HAVERM!F146 -> 3.77 | T34: =HAVERM!G146 -> 2.931 | U34: =HAVERM!H146 -> #N/A | V34: =HAVERM!I146 -> #N/A | X34: 44378 | Y34: =HAVERM!J146 -> 3.24 | Z34: =HAVERM!K146 -> 3.21 | AA34: =HAVERM!L146 -> #N/A | AB34: =HAVERM!M146 -> #N/A | AD34: 42917 | AE34: =HAVERM!P98 -> 183.65895 | AF34: ='Bloom - Monthly US data'!M392 -> 92.143455
A35: 45505 | B35: =100*((HAVERM!D183/HAVERM!D171)-1) -> 5.5725191 | C35: ='MPR Chart 2.16 (May)'!L74 -> 5.001 | D35: ='MPR Chart 2.16 (Aug)'!L50 -> 5.84 | G35: 45505 | H35: =HAVERM!E183 -> 5.1 | R35: 44409 | S35: =HAVERM!F147 -> 3.45 | T35: =HAVERM!G147 -> 3.23 | U35: =HAVERM!H147 -> #N/A | V35: =HAVERM!I147 -> #N/A | X35: 44409 | Y35: =HAVERM!J147 -> 3.445 | Z35: =HAVERM!K147 -> 3.14 | AA35: =HAVERM!L147 -> #N/A | AB35: =HAVERM!M147 -> #N/A | AD35: 42948 | AE35: =HAVERM!P99 -> 151.2043 | AF35: ='Bloom - Monthly US data'!M393 -> 91.351067
A36: 45536 | B36: =100*((HAVERM!D184/HAVERM!D172)-1) -> 4.9467275 | C36: ='MPR Chart 2.16 (May)'!L75 -> 4.728 | D36: ='MPR Chart 2.16 (Aug)'!L51 -> 5.52 | G36: 45536 | H36: =HAVERM!E184 -> 5.1 | I36: ='MPR Chart 2.29 (Nov)'!B32 -> 4.753 | R36: 44440 | S36: =HAVERM!F148 -> 4.53 | T36: =HAVERM!G148 -> 4.098 | U36: =HAVERM!H148 -> #N/A | V36: =HAVERM!I148 -> #N/A | X36: 44440 | Y36: =HAVERM!J148 -> 3.913 | Z36: =HAVERM!K148 -> 3.42 | AA36: =HAVERM!L148 -> #N/A | AB36: =HAVERM!M148 -> #N/A | AD36: 42979 | AE36: =HAVERM!P100 -> 140.77882 | AF36: ='Bloom - Monthly US data'!M394 -> 76.291078
A37: 45566 | B37: =100*((HAVERM!D185/HAVERM!D173)-1) -> 5.0037908 | D37: ='MPR Chart 2.16 (Aug)'!L52 -> 5.502 | E37: ='MPR Chart 2.22 (Nov)'!L52 -> 4.972 | G37: 45566 | R37: 44470 | S37: =HAVERM!F149 -> 5.41 | T37: =HAVERM!G149 -> 4.724 | U37: =HAVERM!H149 -> #N/A | V37: =HAVERM!I149 -> #N/A | X37: 44470 | Y37: =HAVERM!J149 -> 4.461 | Z37: =HAVERM!K149 -> 4.017 | AA37: =HAVERM!L149 -> #N/A | AB37: =HAVERM!M149 -> #N/A | AD37: 43009 | AE37: =HAVERM!P101 -> 184.03005 | AF37: ='Bloom - Monthly US data'!M395 -> 96.872971
A38: 45597 | B38: =100*((HAVERM!D186/HAVERM!D174)-1) -> 5.0113895 | D38: ='MPR Chart 2.16 (Aug)'!L53 -> 5.395 | E38: ='MPR Chart 2.22 (Nov)'!L53 -> 4.913 | G38: 45597 | R38: 44501 | S38: =HAVERM!F150 -> 4.81 | T38: =HAVERM!G150 -> 4.411 | U38: =HAVERM!H150 -> #N/A | V38: =HAVERM!I150 -> #N/A | X38: 44501 | Y38: =HAVERM!J150 -> 4.916 | Z38: =HAVERM!K150 -> 4.411 | AA38: =HAVERM!L150 -> #N/A | AB38: =HAVERM!M150 -> #N/A | AD38: 43040 | AE38: =HAVERM!P102 -> 214.97008 | AF38: ='Bloom - Monthly US data'!M396 -> 49.481161
A39: 45627 | B39: =100*((HAVERM!D187/HAVERM!D175)-1) -> 4.3609023 | D39: ='MPR Chart 2.16 (Aug)'!L54 -> 5.286 | E39: ='MPR Chart 2.22 (Nov)'!L54 -> 4.739 | G39: 45627 | I39: ='MPR Chart 2.29 (Nov)'!B33 -> 5.065 | R39: 44531 | S39: =HAVERM!F151 -> 5.48 | T39: =HAVERM!G151 -> 5.094 | U39: =HAVERM!H151 -> #N/A | V39: =HAVERM!I151 -> #N/A | X39: 44531 | Y39: =HAVERM!J151 -> 5.233 | Z39: =HAVERM!K151 -> 4.743 | AA39: =HAVERM!L151 -> #N/A | AB39: =HAVERM!M151 -> #N/A | AD39: 43070 | AE39: =HAVERM!P103 -> 160.7223 | AF39: ='Bloom - Monthly US data'!M397 -> 182.29972
A40: 45658 | E40: ='MPR Chart 2.22 (Nov)'!L55 -> 5.112 | G40: 45658 | R40: 44562 | S40: =HAVERM!F152 -> 5.41 | T40: =HAVERM!G152 -> 4.542 | U40: =HAVERM!H152 -> #N/A | V40: =HAVERM!I152 -> #N/A | X40: 44562 | Y40: =HAVERM!J152 -> 5.235 | Z40: =HAVERM!K152 -> 4.682 | AA40: =HAVERM!L152 -> #N/A | AB40: =HAVERM!M152 -> #N/A | AD40: 43101 | AE40: =HAVERM!P104 -> 123.16 | AF40: ='Bloom - Monthly US data'!M398 -> 247.78682
...

Sheet Market pricing dates
A2: February 2025 MPR | B2: 45688 | D2: May 2025 MPR | E2: 45776
A4: Last 5 working days | D4: Last 5 working days
A5: =TEXT(B5,"dddd") -> Monday | B5: =IF(A6="Monday",B6-3,B6-1) -> 45684 | D5: =TEXT(E5,"dddd") -> Wednesday | E5: =IF(D6="Monday",E6-3,E6-1) -> 45770
A6: =TEXT(B6,"dddd") -> Tuesday | B6: =IF(A7="Monday",B7-3,B7-1) -> 45685 | D6: =TEXT(E6,"dddd") -> Thursday | E6: =IF(D7="Monday",E7-3,E7-1) -> 45771
A7: =TEXT(B7,"dddd") -> Wednesday | B7: =IF(A8="Monday",B8-3,B8-1) -> 45686 | D7: =TEXT(E7,"dddd") -> Friday | E7: =IF(D8="Monday",E8-3,E8-1) -> 45772
A8: =TEXT(B8,"dddd") -> Thursday | B8: =IF(A9="Monday",B9-3,B9-1) -> 45687 | D8: =TEXT(E8,"dddd") -> Monday | E8: =IF(D9="Monday",E9-3,E9-1) -> 45775
A9: =TEXT(B9,"dddd") -> Friday | B9: =B2 -> 45688 | D9: =TEXT(E9,"dddd") -> Tuesday | E9: =E2 -> 45776
B11: =TEXT(B9,"dd mmm yyyy") -> 31 Jan 2025 | E11: =TEXT(E9,"dd mmm yyyy") -> 29 Apr 2025
A12: ="15 working days to "&B11 -> 15 working days to 31 Jan 2025 | D12: ="15 working days to "&E11 -> 15 working days to 29 Apr 2025

Sheet Bloom - Monthly US data
A1: Year | B1: Month | C1: 1. Economic Policy Uncertainty | D1: 2. Monetary policy | E1: Fiscal Policy (Taxes OR Spending) | F1: 3. Taxes | G1: 4. Government spending | H1: 5. Health care | I1: 6. National security | J1: 7. Entitlement programs | K1: 8. Regulation | L1: Financial Regulation | M1: 9. Trade policy | N1: 10. Sovereign debt, currency crises
A2: 1985 | B2: 1 | C2: 213.67883 | D2: 270.46923 | E2: 292.61456 | F2: 295.79079 | G2: 394.09975 | H2: 107.84824 | I2: 179.69985 | J2: 258.34622 | K2: 129.63282 | L2: 113.24718 | M2: 122.61396 | N2: 0
A3: 1985 | B3: 2 | C3: 155.42602 | D3: 219.83568 | E3: 164.23554 | F3: 139.1256 | G3: 225.03278 | H3: 36.73303 | I3: 124.8595 | J3: 82.492997 | K3: 55.191052 | L3: 0 | M3: 41.762223 | N3: 128.389
A4: 1985 | B4: 3 | C4: 121.13737 | D4: 119.03452 | E4: 108.82881 | F4: 115.71434 | G4: 102.02634 | H4: 31.642944 | I4: 63.269264 | J4: 113.69914 | K4: 85.577836 | L4: 149.52152 | M4: 107.92573 | N4: 110.59817
A5: 1985 | B5: 4 | C5: 104.98235 | D5: 122.04476 | E5: 104.73733 | F5: 85.760217 | G5: 138.08053 | H5: 38.066636 | I5: 85.627432 | J5: 51.29276 | K5: 60.054521 | L5: 44.968804 | M5: 194.75287 | N5: 0
A6: 1985 | B6: 5 | C6: 115.73678 | D6: 107.57358 | E6: 134.83997 | F6: 132.17777 | G6: 167.56891 | H6: 54.705931 | I6: 109.38312 | J6: 98.284429 | K6: 65.75614 | L6: 129.25021 | M6: 124.39166 | N6: 95.603868
A7: 1985 | B7: 6 | C7: 139.79243 | D7: 156.64302 | E7: 197.6899 | F7: 190.02239 | G7: 182.43723 | H7: 26.943794 | I7: 161.6203 | J7: 108.91597 | K7: 89.062184 | L7: 42.43892 | M7: 153.16361 | N7: 0
A8: 1985 | B8: 7 | C8: 120.50515 | D8: 173.40758 | E8: 134.14929 | F8: 122.26014 | G8: 201.22261 | H8: 26.003398 | I8: 155.97941 | J8: 116.79397 | K8: 39.069875 | L8: 0 | M8: 59.127152 | N8: 181.77374
A9: 1985 | B9: 8 | C9: 122.68383 | D9: 111.33082 | E9: 118.87554 | F9: 122.82737 | G9: 217.70667 | H9: 56.267169 | I9: 106.07593 | J9: 151.63401 | K9: 57.970918 | L9: 37.982527 | M9: 109.66426 | N9: 168.56963
A10: 1985 | B10: 9 | C10: 91.711134 | D10: 113.58992 | E10: 81.798704 | F10: 67.479869 | G10: 126.92818 | H10: 24.603827 | I10: 83.631037 | J10: 11.050781 | K10: 51.753844 | L10: 77.506519 | M10: 279.72386 | N10: 85.9951
A11: 1985 | B11: 10 | C11: 86.338619 | D11: 69.607238 | E11: 108.07516 | F11: 89.542597 | G11: 103.62251 | H11: 7.1417751 | I11: 42.839395 | J11: 67.362126 | K11: 64.382722 | L11: 33.746831 | M11: 121.79355 | N11: 74.885628
A12: 1985 | B12: 11 | C12: 115.88343 | D12: 70.245579 | E12: 96.548438 | F12: 83.162896 | G12: 99.344154 | H12: 34.234531 | I12: 114.99781 | J12: 36.903362 | K12: 117.27654 | L12: 32.353495 | M12: 93.411958 | N12: 287.17503
A13: 1985 | B13: 12 | C13: 126.42213 | D13: 112.56385 | E13: 150.93895 | F13: 137.02444 | G13: 225.52253 | H13: 6.8573188 | I13: 119.28601 | J13: 55.439227 | K13: 98.909382 | L13: 64.805396 | M13: 70.165513 | N13: 0
... A481: 2024 | B481: 12 | C481: 178.71316 | D481: 155.29582 | E481: 182.71297 | F481: 184.80943 | G481: 144.52786 | H481: 310.54932 | I481: 154.64808 | J481: 277.64988 | K481: 258.82961 | L481: 46.145599 | M481: 1319.0059 | N481: 51.199505
A482: 2025 | B482: 1 | C482: 236.44342 | D482: 222.12527 | E482: 291.74046 | F482: 293.14729 | G482: 208.06876 | H482: 415.24587 | I482: 159.32277 | J482: 448.62547 | K482: 345.67612 | L482: 97.223638 | M482: 1725.7097 | N482: 9.8065141
A483: 2025 | B483: 2 | C483: 313.488 | D483: 229.40616 | E483: 363.177 | F483: 384.39439 | G483: 318.74367 | H483: 500.7028 | I483: 299.05925 | J483: 503.11952 | K483: 335.64221 | L483: 252.77319 | M483: 2481.3681 | N483: 123.40114
A484: 2025 | B484: 3 | C484: 485.18364 | D484: 431.34234 | E484: 630.57542 | F484: 649.70766 | G484: 522.94972 | H484: 613.28823 | I484: 619.74976 | J484: 742.87203 | K484: 351.56754 | L484: 242.3376 | M484: 5735.9528 | N484: 78.422933
A485: Source: “Measuring Economic Policy Uncertainty” by Scott Baker, Nicholas Bloom and Steven J. Davis at www.PolicyUncertainty.com. These data can be used freely with attribution to the authors, the paper, and the website.

Sheet Market expectations - RCB
A1: ='Market pricing dates'!A2 -> February 2025 MPR | C1: ='Market pricing dates'!A12 -> 15 working days to 31 Jan 2025 | BA1: ='Market pricing dates'!D2 -> May 2025 MPR | BC1: ='Market pricing dates'!D12 -> 15 working days to 29 Apr 2025
A2: Column # | B2: =HAVERD!I$1 -> 9 | C2: =+B2+1 -> 10 | D2: =+C2+1 -> 11 | E2: =+D2+1 -> 12 | F2: =+E2+1 -> 13 | G2: =+F2+1 -> 14 | H2: =+G2+1 -> 15 | I2: =+H2+1 -> 16 | J2: =+I2+1 -> 17 | ... AX2: =+AW2+1 -> 57 | BA2: Column # | BB2: =HAVERD!I$1 -> 9 | BC2: =+BB2+1 -> 10 | BD2: =+BC2+1 -> 11 | BE2: =+BD2+1 -> 12 | BF2: =+BE2+1 -> 13 | BG2: =+BF2+1 -> 14 | BH2: =+BG2+1 -> 15 | BI2: =+BH2+1 -> 16 | BJ2: =+BI2+1 -> 17 | ... CX2: =+CW2+1 -> 57
A3: Months | B3: =HAVERD!I$2 -> Overnight | C3: =HAVERD!J$2 -> 1 | D3: =HAVERD!K$2 -> 2 | E3: =HAVERD!L$2 -> 3 | F3: =HAVERD!M$2 -> 4 | G3: =HAVERD!N$2 -> 5 | H3: =HAVERD!O$2 -> 6 | I3: =HAVERD!P$2 -> 7 | ... AX3: =HAVERD!BE$2 -> 48 | BA3: Months | BB3: =HAVERD!I$2 -> Overnight | BC3: =HAVERD!J$2 -> 1 | BD3: =HAVERD!K$2 -> 2 | BE3: =HAVERD!L$2 -> 3 | BF3: =HAVERD!M$2 -> 4 | BG3: =HAVERD!N$2 -> 5 | BH3: =HAVERD!O$2 -> 6 | BI3: =HAVERD!P$2 -> 7 | ... CX3: =HAVERD!BE$2 -> 48
A4: Days | C4: 30.416667 | D4: =+C4+30.4166667 -> 60.833333 | E4: =+D4+30.4166667 -> 91.25 | F4: =+E4+30.4166667 -> 121.66667 | G4: =+F4+30.4166667 -> 152.08333 | H4: =+G4+30.4166667 -> 182.5 | I4: =+H4+30.4166667 -> 212.91667 | J4: =+I4+30.4166667 -> 243.33333 | K4: =+J4+30.4166667 -> 273.75 | ... AX4: =+AW4+30.4166667 -> 1460 | BA4: Days | BC4: 30.416667 | BD4: =+BC4+30.4166667 -> 60.833333 | BE4: =+BD4+30.4166667 -> 91.25 | BF4: =+BE4+30.4166667 -> 121.66667 | BG4: =+BF4+30.4166667 -> 152.08333 | BH4: =+BG4+30.4166667 -> 182.5 | BI4: =+BH4+30.4166667 -> 212.91667 | BJ4: =+BI4+30.4166667 -> 243.33333 | BK4: =+BJ4+30.4166667 -> 273.75 | ... CX4: =+CW4+30.4166667 -> 1460
A5: Dates | BA5: Dates
A6: =A11-7 -> 45670 | B6: =A6 -> 45670 | C6: =$B6+C$4 -> 45700.417 | D6: =$B6+D$4 -> 45730.833 | E6: =$B6+E$4 -> 45761.25 | F6: =$B6+F$4 -> 45791.667 | G6: =$B6+G$4 -> 45822.083 | H6: =$B6+H$4 -> 45852.5 | I6: =$B6+I$4 -> 45882.917 | J6: =$B6+J$4 -> 45913.333 | ... AX6: =$B6+AX$4 -> 47130 | BA6: =BA11-7 -> 45756 | BB6: =BA6 -> 45756 | BC6: =$BA6+BC$4 -> 45786.417 | BD6: =$BA6+BD$4 -> 45816.833 | BE6: =$BA6+BE$4 -> 45847.25 | BF6: =$BA6+BF$4 -> 45877.667 | BG6: =$BA6+BG$4 -> 45908.083 | BH6: =$BA6+BH$4 -> 45938.5 | BI6: =$BA6+BI$4 -> 45968.917 | BJ6: =$BA6+BJ$4 -> 45999.333 | ... CX6: =$BA6+CX$4 -> 47216
A7: =A12-7 -> 45671 | B7: =A7 -> 45671 | C7: =$B7+C$4 -> 45701.417 | D7: =$B7+D$4 -> 45731.833 | E7: =$B7+E$4 -> 45762.25 | F7: =$B7+F$4 -> 45792.667 | G7: =$B7+G$4 -> 45823.083 | H7: =$B7+H$4 -> 45853.5 | I7: =$B7+I$4 -> 45883.917 | J7: =$B7+J$4 -> 45914.333 | ... AX7: =$B7+AX$4 -> 47131 | BA7: =BA12-7 -> 45757 | BB7: =BA7 -> 45757 | BC7: =$BA7+BC$4 -> 45787.417 | BD7: =$BA7+BD$4 -> 45817.833 | BE7: =$BA7+BE$4 -> 45848.25 | BF7: =$BA7+BF$4 -> 45878.667 | BG7: =$BA7+BG$4 -> 45909.083 | BH7: =$BA7+BH$4 -> 45939.5 | BI7: =$BA7+BI$4 -> 45969.917 | BJ7: =$BA7+BJ$4 -> 46000.333 | ... CX7: =$BA7+CX$4 -> 47217
A8: =A13-7 -> 45672 | B8: =A8 -> 45672 | C8: =$B8+C$4 -> 45702.417 | D8: =$B8+D$4 -> 45732.833 | E8: =$B8+E$4 -> 45763.25 | F8: =$B8+F$4 -> 45793.667 | G8: =$B8+G$4 -> 45824.083 | H8: =$B8+H$4 -> 45854.5 | I8: =$B8+I$4 -> 45884.917 | J8: =$B8+J$4 -> 45915.333 | ... AX8: =$B8+AX$4 -> 47132 | BA8: =BA13-7 -> 45758 | BB8: =BA8 -> 45758 | BC8: =$BA8+BC$4 -> 45788.417 | BD8: =$BA8+BD$4 -> 45818.833 | BE8: =$BA8+BE$4 -> 45849.25 | BF8: =$BA8+BF$4 -> 45879.667 | BG8: =$BA8+BG$4 -> 45910.083 | BH8: =$BA8+BH$4 -> 45940.5 | BI8: =$BA8+BI$4 -> 45970.917 | BJ8: =$BA8+BJ$4 -> 46001.333 | ... CX8: =$BA8+CX$4 -> 47218
A9: =A14-7 -> 45673 | B9: =A9 -> 45673 | C9: =$B9+C$4 -> 45703.417 | D9: =$B9+D$4 -> 45733.833 | E9: =$B9+E$4 -> 45764.25 | F9: =$B9+F$4 -> 45794.667 | G9: =$B9+G$4 -> 45825.083 | H9: =$B9+H$4 -> 45855.5 | I9: =$B9+I$4 -> 45885.917 | J9: =$B9+J$4 -> 45916.333 | ... AX9: =$B9+AX$4 -> 47133 | BA9: =BA14-7 -> 45761 | BB9: =BA9 -> 45761 | BC9: =$BA9+BC$4 -> 45791.417 | BD9: =$BA9+BD$4 -> 45821.833 | BE9: =$BA9+BE$4 -> 45852.25 | BF9: =$BA9+BF$4 -> 45882.667 | BG9: =$BA9+BG$4 -> 45913.083 | BH9: =$BA9+BH$4 -> 45943.5 | BI9: =$BA9+BI$4 -> 45973.917 | BJ9: =$BA9+BJ$4 -> 46004.333 | ... CX9: =$BA9+CX$4 -> 47221
A10: =A15-7 -> 45674 | B10: =A10 -> 45674 | C10: =$B10+C$4 -> 45704.417 | D10: =$B10+D$4 -> 45734.833 | E10: =$B10+E$4 -> 45765.25 | F10: =$B10+F$4 -> 45795.667 | G10: =$B10+G$4 -> 45826.083 | H10: =$B10+H$4 -> 45856.5 | I10: =$B10+I$4 -> 45886.917 | J10: =$B10+J$4 -> 45917.333 | ... AX10: =$B10+AX$4 -> 47134 | BA10: =BA15-7 -> 45762 | BB10: =BA10 -> 45762 | BC10: =$BA10+BC$4 -> 45792.417 | BD10: =$BA10+BD$4 -> 45822.833 | BE10: =$BA10+BE$4 -> 45853.25 | BF10: =$BA10+BF$4 -> 45883.667 | BG10: =$BA10+BG$4 -> 45914.083 | BH10: =$BA10+BH$4 -> 45944.5 | BI10: =$BA10+BI$4 -> 45974.917 | BJ10: =$BA10+BJ$4 -> 46005.333 | ... CX10: =$BA10+CX$4 -> 47222
A11: =A16-7 -> 45677 | B11: =A11 -> 45677 | C11: =$B11+C$4 -> 45707.417 | D11: =$B11+D$4 -> 45737.833 | E11: =$B11+E$4 -> 45768.25 | F11: =$B11+F$4 -> 45798.667 | G11: =$B11+G$4 -> 45829.083 | H11: =$B11+H$4 -> 45859.5 | I11: =$B11+I$4 -> 45889.917 | J11: =$B11+J$4 -> 45920.333 | ... AX11: =$B11+AX$4 -> 47137 | BA11: =BA16-7 -> 45763 | BB11: =BA11 -> 45763 | BC11: =$BA11+BC$4 -> 45793.417 | BD11: =$BA11+BD$4 -> 45823.833 | BE11: =$BA11+BE$4 -> 45854.25 | BF11: =$BA11+BF$4 -> 45884.667 | BG11: =$BA11+BG$4 -> 45915.083 | BH11: =$BA11+BH$4 -> 45945.5 | BI11: =$BA11+BI$4 -> 45975.917 | BJ11: =$BA11+BJ$4 -> 46006.333 | ... CX11: =$BA11+CX$4 -> 47223
A12: =A17-7 -> 45678 | B12: =A12 -> 45678 | C12: =$B12+C$4 -> 45708.417 | D12: =$B12+D$4 -> 45738.833 | E12: =$B12+E$4 -> 45769.25 | F12: =$B12+F$4 -> 45799.667 | G12: =$B12+G$4 -> 45830.083 | H12: =$B12+H$4 -> 45860.5 | I12: =$B12+I$4 -> 45890.917 | J12: =$B12+J$4 -> 45921.333 | ... AX12: =$B12+AX$4 -> 47138 | BA12: =BA17-7 -> 45764 | BB12: =BA12 -> 45764 | BC12: =$BA12+BC$4 -> 45794.417 | BD12: =$BA12+BD$4 -> 45824.833 | BE12: =$BA12+BE$4 -> 45855.25 | BF12: =$BA12+BF$4 -> 45885.667 | BG12: =$BA12+BG$4 -> 45916.083 | BH12: =$BA12+BH$4 -> 45946.5 | BI12: =$BA12+BI$4 -> 45976.917 | BJ12: =$BA12+BJ$4 -> 46007.333 | ... CX12: =$BA12+CX$4 -> 47224
A13: =A18-7 -> 45679 | B13: =A13 -> 45679 | C13: =$B13+C$4 -> 45709.417 | D13: =$B13+D$4 -> 45739.833 | E13: =$B13+E$4 -> 45770.25 | F13: =$B13+F$4 -> 45800.667 | G13: =$B13+G$4 -> 45831.083 | H13: =$B13+H$4 -> 45861.5 | I13: =$B13+I$4 -> 45891.917 | J13: =$B13+J$4 -> 45922.333 | ... AX13: =$B13+AX$4 -> 47139 | BA13: =BA18-7 -> 45765 | BB13: =BA13 -> 45765 | BC13: =$BA13+BC$4 -> 45795.417 | BD13: =$BA13+BD$4 -> 45825.833 | BE13: =$BA13+BE$4 -> 45856.25 | BF13: =$BA13+BF$4 -> 45886.667 | BG13: =$BA13+BG$4 -> 45917.083 | BH13: =$BA13+BH$4 -> 45947.5 | BI13: =$BA13+BI$4 -> 45977.917 | BJ13: =$BA13+BJ$4 -> 46008.333 | ... CX13: =$BA13+CX$4 -> 47225
A14: =A19-7 -> 45680 | B14: =A14 -> 45680 | C14: =$B14+C$4 -> 45710.417 | D14: =$B14+D$4 -> 45740.833 | E14: =$B14+E$4 -> 45771.25 | F14: =$B14+F$4 -> 45801.667 | G14: =$B14+G$4 -> 45832.083 | H14: =$B14+H$4 -> 45862.5 | I14: =$B14+I$4 -> 45892.917 | J14: =$B14+J$4 -> 45923.333 | ... AX14: =$B14+AX$4 -> 47140 | BA14: =BA19-7 -> 45768 | BB14: =BA14 -> 45768 | BC14: =$BA14+BC$4 -> 45798.417 | BD14: =$BA14+BD$4 -> 45828.833 | BE14: =$BA14+BE$4 -> 45859.25 | BF14: =$BA14+BF$4 -> 45889.667 | BG14: =$BA14+BG$4 -> 45920.083 | BH14: =$BA14+BH$4 -> 45950.5 | BI14: =$BA14+BI$4 -> 45980.917 | BJ14: =$BA14+BJ$4 -> 46011.333 | ... CX14: =$BA14+CX$4 -> 47228
A15: =A20-7 -> 45681 | B15: =A15 -> 45681 | C15: =$B15+C$4 -> 45711.417 | D15: =$B15+D$4 -> 45741.833 | E15: =$B15+E$4 -> 45772.25 | F15: =$B15+F$4 -> 45802.667 | G15: =$B15+G$4 -> 45833.083 | H15: =$B15+H$4 -> 45863.5 | I15: =$B15+I$4 -> 45893.917 | J15: =$B15+J$4 -> 45924.333 | ... AX15: =$B15+AX$4 -> 47141 | BA15: =BA20-7 -> 45769 | BB15: =BA15 -> 45769 | BC15: =$BA15+BC$4 -> 45799.417 | BD15: =$BA15+BD$4 -> 45829.833 | BE15: =$BA15+BE$4 -> 45860.25 | BF15: =$BA15+BF$4 -> 45890.667 | BG15: =$BA15+BG$4 -> 45921.083 | BH15: =$BA15+BH$4 -> 45951.5 | BI15: =$BA15+BI$4 -> 45981.917 | BJ15: =$BA15+BJ$4 -> 46012.333 | ... CX15: =$BA15+CX$4 -> 47229
A16: ='Market pricing dates'!B5 -> 45684 | B16: =A16 -> 45684 | C16: =$B16+C$4 -> 45714.417 | D16: =$B16+D$4 -> 45744.833 | E16: =$B16+E$4 -> 45775.25 | F16: =$B16+F$4 -> 45805.667 | G16: =$B16+G$4 -> 45836.083 | H16: =$B16+H$4 -> 45866.5 | I16: =$B16+I$4 -> 45896.917 | J16: =$B16+J$4 -> 45927.333 | ... AX16: =$B16+AX$4 -> 47144 | BA16: ='Market pricing dates'!E5 -> 45770 | BB16: =BA16 -> 45770 | BC16: =$BA16+BC$4 -> 45800.417 | BD16: =$BA16+BD$4 -> 45830.833 | BE16: =$BA16+BE$4 -> 45861.25 | BF16: =$BA16+BF$4 -> 45891.667 | BG16: =$BA16+BG$4 -> 45922.083 | BH16: =$BA16+BH$4 -> 45952.5 | BI16: =$BA16+BI$4 -> 45982.917 | BJ16: =$BA16+BJ$4 -> 46013.333 | ... CX16: =$BA16+CX$4 -> 47230
A17: ='Market pricing dates'!B6 -> 45685 | B17: =A17 -> 45685 | C17: =$B17+C$4 -> 45715.417 | D17: =$B17+D$4 -> 45745.833 | E17: =$B17+E$4 -> 45776.25 | F17: =$B17+F$4 -> 45806.667 | G17: =$B17+G$4 -> 45837.083 | H17: =$B17+H$4 -> 45867.5 | I17: =$B17+I$4 -> 45897.917 | J17: =$B17+J$4 -> 45928.333 | ... AX17: =$B17+AX$4 -> 47145 | BA17: ='Market pricing dates'!E6 -> 45771 | BB17: =BA17 -> 45771 | BC17: =$BA17+BC$4 -> 45801.417 | BD17: =$BA17+BD$4 -> 45831.833 | BE17: =$BA17+BE$4 -> 45862.25 | BF17: =$BA17+BF$4 -> 45892.667 | BG17: =$BA17+BG$4 -> 45923.083 | BH17: =$BA17+BH$4 -> 45953.5 | BI17: =$BA17+BI$4 -> 45983.917 | BJ17: =$BA17+BJ$4 -> 46014.333 | ... CX17: =$BA17+CX$4 -> 47231
A18: ='Market pricing dates'!B7 -> 45686 | B18: =A18 -> 45686 | C18: =$B18+C$4 -> 45716.417 | D18: =$B18+D$4 -> 45746.833 | E18: =$B18+E$4 -> 45777.25 | F18: =$B18+F$4 -> 45807.667 | G18: =$B18+G$4 -> 45838.083 | H18: =$B18+H$4 -> 45868.5 | I18: =$B18+I$4 -> 45898.917 | J18: =$B18+J$4 -> 45929.333 | ... AX18: =$B18+AX$4 -> 47146 | BA18: ='Market pricing dates'!E7 -> 45772 | BB18: =BA18 -> 45772 | BC18: =$BA18+BC$4 -> 45802.417 | BD18: =$BA18+BD$4 -> 45832.833 | BE18: =$BA18+BE$4 -> 45863.25 | BF18: =$BA18+BF$4 -> 45893.667 | BG18: =$BA18+BG$4 -> 45924.083 | BH18: =$BA18+BH$4 -> 45954.5 | BI18: =$BA18+BI$4 -> 45984.917 | BJ18: =$BA18+BJ$4 -> 46015.333 | ... CX18: =$BA18+CX$4 -> 47232
A19: ='Market pricing dates'!B8 -> 45687 | B19: =A19 -> 45687 | C19: =$B19+C$4 -> 45717.417 | D19: =$B19+D$4 -> 45747.833 | E19: =$B19+E$4 -> 45778.25 | F19: =$B19+F$4 -> 45808.667 | G19: =$B19+G$4 -> 45839.083 | H19: =$B19+H$4 -> 45869.5 | I19: =$B19+I$4 -> 45899.917 | J19: =$B19+J$4 -> 45930.333 | ... AX19: =$B19+AX$4 -> 47147 | BA19: ='Market pricing dates'!E8 -> 45775 | BB19: =BA19 -> 45775 | BC19: =$BA19+BC$4 -> 45805.417 | BD19: =$BA19+BD$4 -> 45835.833 | BE19: =$BA19+BE$4 -> 45866.25 | BF19: =$BA19+BF$4 -> 45896.667 | BG19: =$BA19+BG$4 -> 45927.083 | BH19: =$BA19+BH$4 -> 45957.5 | BI19: =$BA19+BI$4 -> 45987.917 | BJ19: =$BA19+BJ$4 -> 46018.333 | ... CX19: =$BA19+CX$4 -> 47235
A20: ='Market pricing dates'!B9 -> 45688 | B20: =A20 -> 45688 | C20: =$B20+C$4 -> 45718.417 | D20: =$B20+D$4 -> 45748.833 | E20: =$B20+E$4 -> 45779.25 | F20: =$B20+F$4 -> 45809.667 | G20: =$B20+G$4 -> 45840.083 | H20: =$B20+H$4 -> 45870.5 | I20: =$B20+I$4 -> 45900.917 | J20: =$B20+J$4 -> 45931.333 | ... AX20: =$B20+AX$4 -> 47148 | BA20: ='Market pricing dates'!E9 -> 45776 | BB20: =BA20 -> 45776 | BC20: =$BA20+BC$4 -> 45806.417 | BD20: =$BA20+BD$4 -> 45836.833 | BE20: =$BA20+BE$4 -> 45867.25 | BF20: =$BA20+BF$4 -> 45897.667 | BG20: =$BA20+BG$4 -> 45928.083 | BH20: =$BA20+BH$4 -> 45958.5 | BI20: =$BA20+BI$4 -> 45988.917 | BJ20: =$BA20+BJ$4 -> 46019.333 | ... CX20: =$BA20+CX$4 -> 47236
A22: Market expectations | BA22: Market expectations
A23: =A6 -> 45670 | B23: =VLOOKUP($A23,HAVERD!$A:$BS,B$2,FALSE) -> 4.7 | C23: =VLOOKUP($A23,HAVERD!$A:$BS,C$2,FALSE) -> 4.583527 | D23: =VLOOKUP($A23,HAVERD!$A:$BS,D$2,FALSE) -> 4.5112586 | E23: =VLOOKUP($A23,HAVERD!$A:$BS,E$2,FALSE) -> 4.4690879 | F23: =VLOOKUP($A23,HAVERD!$A:$BS,F$2,FALSE) -> 4.438039 | G23: =VLOOKUP($A23,HAVERD!$A:$BS,G$2,FALSE) -> 4.4093316 | H23: =VLOOKUP($A23,HAVERD!$A:$BS,H$2,FALSE) -> 4.3818388 | I23: =VLOOKUP($A23,HAVERD!$A:$BS,I$2,FALSE) -> 4.3565668 | ... AX23: =VLOOKUP($A23,HAVERD!$A:$BS,AX$2,FALSE) -> 4.0874707 | BA23: =BA6 -> 45756 | BB23: =_xlfn.IFNA(VLOOKUP($BA23,HAVERD!$A:$BS,BB$2,FALSE),"") -> 4.4565 | BC23: =_xlfn.IFNA(VLOOKUP($BA23,HAVERD!$A:$BS,BC$2,FALSE),"") -> 4.3106983 | BD23: =_xlfn.IFNA(VLOOKUP($BA23,HAVERD!$A:$BS,BD$2,FALSE),"") -> 4.1417456 | BE23: =_xlfn.IFNA(VLOOKUP($BA23,HAVERD!$A:$BS,BE$2,FALSE),"") -> 4.0256197 | BF23: =_xlfn.IFNA(VLOOKUP($BA23,HAVERD!$A:$BS,BF$2,FALSE),"") -> 3.9364484 | BG23: =_xlfn.IFNA(VLOOKUP($BA23,HAVERD!$A:$BS,BG$2,FALSE),"") -> 3.8589194 | BH23: =_xlfn.IFNA(VLOOKUP($BA23,HAVERD!$A:$BS,BH$2,FALSE),"") -> 3.7904365 | BI23: =_xlfn.IFNA(VLOOKUP($BA23,HAVERD!$A:$BS,BI$2,FALSE),"") -> 3.7327137 | ... CX23: =_xlfn.IFNA(VLOOKUP($BA23,HAVERD!$A:$BS,CX$2,FALSE),"") -> 4.0012642
A24: =A7 -> 45671 | B24: =VLOOKUP($A24,HAVERD!$A:$BS,B$2,FALSE) -> 4.7 | C24: =VLOOKUP($A24,HAVERD!$A:$BS,C$2,FALSE) -> 4.5928108 | D24: =VLOOKUP($A24,HAVERD!$A:$BS,D$2,FALSE) -> 4.5365359 | E24: =VLOOKUP($A24,HAVERD!$A:$BS,E$2,FALSE) -> 4.5032957 | F24: =VLOOKUP($A24,HAVERD!$A:$BS,F$2,FALSE) -> 4.4752949 | G24: =VLOOKUP($A24,HAVERD!$A:$BS,G$2,FALSE) -> 4.446087 | H24: =VLOOKUP($A24,HAVERD!$A:$BS,H$2,FALSE) -> 4.4172097 | I24: =VLOOKUP($A24,HAVERD!$A:$BS,I$2,FALSE) -> 4.3922553 | ... AX24: =VLOOKUP($A24,HAVERD!$A:$BS,AX$2,FALSE) -> 4.1407446 | BA24: =BA7 -> 45757 | BB24: =_xlfn.IFNA(VLOOKUP($BA24,HAVERD!$A:$BS,BB$2,FALSE),"") -> 4.4579 | BC24: =_xlfn.IFNA(VLOOKUP($BA24,HAVERD!$A:$BS,BC$2,FALSE),"") -> 4.3190332 | BD24: =_xlfn.IFNA(VLOOKUP($BA24,HAVERD!$A:$BS,BD$2,FALSE),"") -> 4.1664726 | BE24: =_xlfn.IFNA(VLOOKUP($BA24,HAVERD!$A:$BS,BE$2,FALSE),"") -> 4.0489946 | BF24: =_xlfn.IFNA(VLOOKUP($BA24,HAVERD!$A:$BS,BF$2,FALSE),"") -> 3.9435279 | BG24: =_xlfn.IFNA(VLOOKUP($BA24,HAVERD!$A:$BS,BG$2,FALSE),"") -> 3.8419045 | BH24: =_xlfn.IFNA(VLOOKUP($BA24,HAVERD!$A:$BS,BH$2,FALSE),"") -> 3.7480781 | BI24: =_xlfn.IFNA(VLOOKUP($BA24,HAVERD!$A:$BS,BI$2,FALSE),"") -> 3.6674148 | ... CX24: =_xlfn.IFNA(VLOOKUP($BA24,HAVERD!$A:$BS,CX$2,FALSE),"") -> 3.7975574
A25: =A8 -> 45672 | B25: =VLOOKUP($A25,HAVERD!$A:$BS,B$2,FALSE) -> 4.7001 | C25: =VLOOKUP($A25,HAVERD!$A:$BS,C$2,FALSE) -> 4.5407893 | D25: =VLOOKUP($A25,HAVERD!$A:$BS,D$2,FALSE) -> 4.4591869 | E25: =VLOOKUP($A25,HAVERD!$A:$BS,E$2,FALSE) -> 4.406464 | F25: =VLOOKUP($A25,HAVERD!$A:$BS,F$2,FALSE) -> 4.3616584 | G25: =VLOOKUP($A25,HAVERD!$A:$BS,G$2,FALSE) -> 4.3170663 | H25: =VLOOKUP($A25,HAVERD!$A:$BS,H$2,FALSE) -> 4.2738664 | I25: =VLOOKUP($A25,HAVERD!$A:$BS,I$2,FALSE) -> 4.2354391 | ... AX25: =VLOOKUP($A25,HAVERD!$A:$BS,AX$2,FALSE) -> 3.9786814 | BA25: =BA8 -> 45758 | BB25: =_xlfn.IFNA(VLOOKUP($BA25,HAVERD!$A:$BS,BB$2,FALSE),"") -> 4.4584 | BC25: =_xlfn.IFNA(VLOOKUP($BA25,HAVERD!$A:$BS,BC$2,FALSE),"") -> 4.3184361 | BD25: =_xlfn.IFNA(VLOOKUP($BA25,HAVERD!$A:$BS,BD$2,FALSE),"") -> 4.1965726 | BE25: =_xlfn.IFNA(VLOOKUP($BA25,HAVERD!$A:$BS,BE$2,FALSE),"") -> 4.1021144 | BF25: =_xlfn.IFNA(VLOOKUP($BA25,HAVERD!$A:$BS,BF$2,FALSE),"") -> 4.0153237 | BG25: =_xlfn.IFNA(VLOOKUP($BA25,HAVERD!$A:$BS,BG$2,FALSE),"") -> 3.931199 | BH25: =_xlfn.IFNA(VLOOKUP($BA25,HAVERD!$A:$BS,BH$2,FALSE),"") -> 3.8543074 | BI25: =_xlfn.IFNA(VLOOKUP($BA25,HAVERD!$A:$BS,BI$2,FALSE),"") -> 3.7891968 | ... CX25: =_xlfn.IFNA(VLOOKUP($BA25,HAVERD!$A:$BS,CX$2,FALSE),"") -> 3.8924818
A26: =A9 -> 45673 | B26: =VLOOKUP($A26,HAVERD!$A:$BS,B$2,FALSE) -> 4.7 | C26: =VLOOKUP($A26,HAVERD!$A:$BS,C$2,FALSE) -> 4.5365792 | D26: =VLOOKUP($A26,HAVERD!$A:$BS,D$2,FALSE) -> 4.4591431 | E26: =VLOOKUP($A26,HAVERD!$A:$BS,E$2,FALSE) -> 4.4049873 | F26: =VLOOKUP($A26,HAVERD!$A:$BS,F$2,FALSE) -> 4.3545297 | G26: =VLOOKUP($A26,HAVERD!$A:$BS,G$2,FALSE) -> 4.3030819 | H26: =VLOOKUP($A26,HAVERD!$A:$BS,H$2,FALSE) -> 4.2536483 | I26: =VLOOKUP($A26,HAVERD!$A:$BS,I$2,FALSE) -> 4.2099764 | ... AX26: =VLOOKUP($A26,HAVERD!$A:$BS,AX$2,FALSE) -> 3.9412115 | BA26: =BA9 -> 45761 | BB26: =_xlfn.IFNA(VLOOKUP($BA26,HAVERD!$A:$BS,BB$2,FALSE),"") -> 4.4582 | BC26: =_xlfn.IFNA(VLOOKUP($BA26,HAVERD!$A:$BS,BC$2,FALSE),"") -> 4.3126921 | BD26: =_xlfn.IFNA(VLOOKUP($BA26,HAVERD!$A:$BS,BD$2,FALSE),"") -> 4.1913674 | BE26: =_xlfn.IFNA(VLOOKUP($BA26,HAVERD!$A:$BS,BE$2,FALSE),"") -> 4.0990096 | BF26: =_xlfn.IFNA(VLOOKUP($BA26,HAVERD!$A:$BS,BF$2,FALSE),"") -> 4.0149637 | BG26: =_xlfn.IFNA(VLOOKUP($BA26,HAVERD!$A:$BS,BG$2,FALSE),"") -> 3.931502 | BH26: =_xlfn.IFNA(VLOOKUP($BA26,HAVERD!$A:$BS,BH$2,FALSE),"") -> 3.85251 | BI26: =_xlfn.IFNA(VLOOKUP($BA26,HAVERD!$A:$BS,BI$2,FALSE),"") -> 3.7838345 | ... CX26: =_xlfn.IFNA(VLOOKUP($BA26,HAVERD!$A:$BS,CX$2,FALSE),"") -> 3.8345921
A27: =A10 -> 45674 | B27: =VLOOKUP($A27,HAVERD!$A:$BS,B$2,FALSE) -> 4.7 | C27: =VLOOKUP($A27,HAVERD!$A:$BS,C$2,FALSE) -> 4.5219514 | D27: =VLOOKUP($A27,HAVERD!$A:$BS,D$2,FALSE) -> 4.4415724 | E27: =VLOOKUP($A27,HAVERD!$A:$BS,E$2,FALSE) -> 4.3810211 | F27: =VLOOKUP($A27,HAVERD!$A:$BS,F$2,FALSE) -> 4.3255362 | G27: =VLOOKUP($A27,HAVERD!$A:$BS,G$2,FALSE) -> 4.2715314 | H27: =VLOOKUP($A27,HAVERD!$A:$BS,H$2,FALSE) -> 4.2216815 | I27: =VLOOKUP($A27,HAVERD!$A:$BS,I$2,FALSE) -> 4.1788801 | ... AX27: =VLOOKUP($A27,HAVERD!$A:$BS,AX$2,FALSE) -> 3.9200765 | BA27: =BA10 -> 45762 | BB27: =_xlfn.IFNA(VLOOKUP($BA27,HAVERD!$A:$BS,BB$2,FALSE),"") -> 4.4585 | BC27: =_xlfn.IFNA(VLOOKUP($BA27,HAVERD!$A:$BS,BC$2,FALSE),"") -> 4.3003244 | BD27: =_xlfn.IFNA(VLOOKUP($BA27,HAVERD!$A:$BS,BD$2,FALSE),"") -> 4.1800162 | BE27: =_xlfn.IFNA(VLOOKUP($BA27,HAVERD!$A:$BS,BE$2,FALSE),"") -> 4.0813777 | BF27: =_xlfn.IFNA(VLOOKUP($BA27,HAVERD!$A:$BS,BF$2,FALSE),"") -> 3.9874367 | BG27: =_xlfn.IFNA(VLOOKUP($BA27,HAVERD!$A:$BS,BG$2,FALSE),"") -> 3.8945333 | BH27: =_xlfn.IFNA(VLOOKUP($BA27,HAVERD!$A:$BS,BH$2,FALSE),"") -> 3.807839 | BI27: =_xlfn.IFNA(VLOOKUP($BA27,HAVERD!$A:$BS,BI$2,FALSE),"") -> 3.7329429 | ... CX27: =_xlfn.IFNA(VLOOKUP($BA27,HAVERD!$A:$BS,CX$2,FALSE),"") -> 3.8253301
A28: =A11 -> 45677 | B28: =VLOOKUP($A28,HAVERD!$A:$BS,B$2,FALSE) -> 4.7 | C28: =VLOOKUP($A28,HAVERD!$A:$BS,C$2,FALSE) -> 4.5000267 | D28: =VLOOKUP($A28,HAVERD!$A:$BS,D$2,FALSE) -> 4.4463263 | E28: =VLOOKUP($A28,HAVERD!$A:$BS,E$2,FALSE) -> 4.3909734 | F28: =VLOOKUP($A28,HAVERD!$A:$BS,F$2,FALSE) -> 4.332188 | G28: =VLOOKUP($A28,HAVERD!$A:$BS,G$2,FALSE) -> 4.2745293 | H28: =VLOOKUP($A28,HAVERD!$A:$BS,H$2,FALSE) -> 4.2228441 | I28: =VLOOKUP($A28,HAVERD!$A:$BS,I$2,FALSE) -> 4.1799756 | ... AX28: =VLOOKUP($A28,HAVERD!$A:$BS,AX$2,FALSE) -> 3.9254038 | BA28: =BA11 -> 45763 | BB28: =_xlfn.IFNA(VLOOKUP($BA28,HAVERD!$A:$BS,BB$2,FALSE),"") -> 4.4585 | BC28: =_xlfn.IFNA(VLOOKUP($BA28,HAVERD!$A:$BS,BC$2,FALSE),"") -> 4.2759184 | BD28: =_xlfn.IFNA(VLOOKUP($BA28,HAVERD!$A:$BS,BD$2,FALSE),"") -> 4.1526541 | BE28: =_xlfn.IFNA(VLOOKUP($BA28,HAVERD!$A:$BS,BE$2,FALSE),"") -> 4.057955 | BF28: =_xlfn.IFNA(VLOOKUP($BA28,HAVERD!$A:$BS,BF$2,FALSE),"") -> 3.971095 | BG28: =_xlfn.IFNA(VLOOKUP($BA28,HAVERD!$A:$BS,BG$2,FALSE),"") -> 3.8852689 | BH28: =_xlfn.IFNA(VLOOKUP($BA28,HAVERD!$A:$BS,BH$2,FALSE),"") -> 3.8044936 | BI28: =_xlfn.IFNA(VLOOKUP($BA28,HAVERD!$A:$BS,BI$2,FALSE),"") -> 3.7344911 | ... CX28: =_xlfn.IFNA(VLOOKUP($BA28,HAVERD!$A:$BS,CX$2,FALSE),"") -> 3.8199038
A29: =A12 -> 45678 | B29: =VLOOKUP($A29,HAVERD!$A:$BS,B$2,FALSE) -> 4.7 | C29: =VLOOKUP($A29,HAVERD!$A:$BS,C$2,FALSE) -> 4.484872 | D29: =VLOOKUP($A29,HAVERD!$A:$BS,D$2,FALSE) -> 4.4384666 | E29: =VLOOKUP($A29,HAVERD!$A:$BS,E$2,FALSE) -> 4.3841836 | F29: =VLOOKUP($A29,HAVERD!$A:$BS,F$2,FALSE) -> 4.3240279 | G29: =VLOOKUP($A29,HAVERD!$A:$BS,G$2,FALSE) -> 4.2650434 | H29: =VLOOKUP($A29,HAVERD!$A:$BS,H$2,FALSE) -> 4.212658 | I29: =VLOOKUP($A29,HAVERD!$A:$BS,I$2,FALSE) -> 4.1700255 | ... AX29: =VLOOKUP($A29,HAVERD!$A:$BS,AX$2,FALSE) -> 3.8604511 | BA29: =BA12 -> 45764 | BB29: =_xlfn.IFNA(VLOOKUP($BA29,HAVERD!$A:$BS,BB$2,FALSE),"") -> 4.459 | BC29: =_xlfn.IFNA(VLOOKUP($BA29,HAVERD!$A:$BS,BC$2,FALSE),"") -> 4.2648654 | BD29: =_xlfn.IFNA(VLOOKUP($BA29,HAVERD!$A:$BS,BD$2,FALSE),"") -> 4.1419825 | BE29: =_xlfn.IFNA(VLOOKUP($BA29,HAVERD!$A:$BS,BE$2,FALSE),"") -> 4.0391454 | BF29: =_xlfn.IFNA(VLOOKUP($BA29,HAVERD!$A:$BS,BF$2,FALSE),"") -> 3.9411515 | BG29: =_xlfn.IFNA(VLOOKUP($BA29,HAVERD!$A:$BS,BG$2,FALSE),"") -> 3.8458918 | BH29: =_xlfn.IFNA(VLOOKUP($BA29,HAVERD!$A:$BS,BH$2,FALSE),"") -> 3.7584655 | BI29: =_xlfn.IFNA(VLOOKUP($BA29,HAVERD!$A:$BS,BI$2,FALSE),"") -> 3.683865 | ... CX29: =_xlfn.IFNA(VLOOKUP($BA29,HAVERD!$A:$BS,CX$2,FALSE),"") -> 3.7772999
A30: =A13 -> 45679 | B30: =VLOOKUP($A30,HAVERD!$A:$BS,B$2,FALSE) -> 4.7 | C30: =VLOOKUP($A30,HAVERD!$A:$BS,C$2,FALSE) -> 4.4757356 | D30: =VLOOKUP($A30,HAVERD!$A:$BS,D$2,FALSE) -> 4.4383779 | E30: =VLOOKUP($A30,HAVERD!$A:$BS,E$2,FALSE) -> 4.3856464 | F30: =VLOOKUP($A30,HAVERD!$A:$BS,F$2,FALSE) -> 4.3229666 | G30: =VLOOKUP($A30,HAVERD!$A:$BS,G$2,FALSE) -> 4.2598599 | H30: =VLOOKUP($A30,HAVERD!$A:$BS,H$2,FALSE) -> 4.2032262 | I30: =VLOOKUP($A30,HAVERD!$A:$BS,I$2,FALSE) -> 4.1570015 | ... AX30: =VLOOKUP($A30,HAVERD!$A:$BS,AX$2,FALSE) -> 3.8686946 | BA30: =BA13 -> 45765 | BB30: =_xlfn.IFNA(VLOOKUP($BA30,HAVERD!$A:$BS,BB$2,FALSE),"") | BC30: =_xlfn.IFNA(VLOOKUP($BA30,HAVERD!$A:$BS,BC$2,FALSE),"") | BD30: =_xlfn.IFNA(VLOOKUP($BA30,HAVERD!$A:$BS,BD$2,FALSE),"") | BE30: =_xlfn.IFNA(VLOOKUP($BA30,HAVERD!$A:$BS,BE$2,FALSE),"") | BF30: =_xlfn.IFNA(VLOOKUP($BA30,HAVERD!$A:$BS,BF$2,FALSE),"") | BG30: =_xlfn.IFNA(VLOOKUP($BA30,HAVERD!$A:$BS,BG$2,FALSE),"") | BH30: =_xlfn.IFNA(VLOOKUP($BA30,HAVERD!$A:$BS,BH$2,FALSE),"") | BI30: =_xlfn.IFNA(VLOOKUP($BA30,HAVERD!$A:$BS,BI$2,FALSE),"") | ... CX30: =_xlfn.IFNA(VLOOKUP($BA30,HAVERD!$A:$BS,CX$2,FALSE),"")
A31: =A14 -> 45680 | B31: =VLOOKUP($A31,HAVERD!$A:$BS,B$2,FALSE) -> 4.7001 | C31: =VLOOKUP($A31,HAVERD!$A:$BS,C$2,FALSE) -> 4.4650853 | D31: =VLOOKUP($A31,HAVERD!$A:$BS,D$2,FALSE) -> 4.4336144 | E31: =VLOOKUP($A31,HAVERD!$A:$BS,E$2,FALSE) -> 4.3790128 | F31: =VLOOKUP($A31,HAVERD!$A:$BS,F$2,FALSE) -> 4.3105457 | G31: =VLOOKUP($A31,HAVERD!$A:$BS,G$2,FALSE) -> 4.2407452 | H31: =VLOOKUP($A31,HAVERD!$A:$BS,H$2,FALSE) -> 4.178016 | I31: =VLOOKUP($A31,HAVERD!$A:$BS,I$2,FALSE) -> 4.1267057 | ... AX31: =VLOOKUP($A31,HAVERD!$A:$BS,AX$2,FALSE) -> 3.8872239 | BA31: =BA14 -> 45768 | BB31: =_xlfn.IFNA(VLOOKUP($BA31,HAVERD!$A:$BS,BB$2,FALSE),"") | BC31: =_xlfn.IFNA(VLOOKUP($BA31,HAVERD!$A:$BS,BC$2,FALSE),"") | BD31: =_xlfn.IFNA(VLOOKUP($BA31,HAVERD!$A:$BS,BD$2,FALSE),"") | BE31: =_xlfn.IFNA(VLOOKUP($BA31,HAVERD!$A:$BS,BE$2,FALSE),"") | BF31: =_xlfn.IFNA(VLOOKUP($BA31,HAVERD!$A:$BS,BF$2,FALSE),"") | BG31: =_xlfn.IFNA(VLOOKUP($BA31,HAVERD!$A:$BS,BG$2,FALSE),"") | BH31: =_xlfn.IFNA(VLOOKUP($BA31,HAVERD!$A:$BS,BH$2,FALSE),"") | BI31: =_xlfn.IFNA(VLOOKUP($BA31,HAVERD!$A:$BS,BI$2,FALSE),"") | ... CX31: =_xlfn.IFNA(VLOOKUP($BA31,HAVERD!$A:$BS,CX$2,FALSE),"")
A32: =A15 -> 45681 | B32: =VLOOKUP($A32,HAVERD!$A:$BS,B$2,FALSE) -> 4.7 | C32: =VLOOKUP($A32,HAVERD!$A:$BS,C$2,FALSE) -> 4.4660198 | D32: =VLOOKUP($A32,HAVERD!$A:$BS,D$2,FALSE) -> 4.4361991 | E32: =VLOOKUP($A32,HAVERD!$A:$BS,E$2,FALSE) -> 4.3843893 | F32: =VLOOKUP($A32,HAVERD!$A:$BS,F$2,FALSE) -> 4.319762 | G32: =VLOOKUP($A32,HAVERD!$A:$BS,G$2,FALSE) -> 4.2545703 | H32: =VLOOKUP($A32,HAVERD!$A:$BS,H$2,FALSE) -> 4.1964227 | I32: =VLOOKUP($A32,HAVERD!$A:$BS,I$2,FALSE) -> 4.1491561 | ... AX32: =VLOOKUP($A32,HAVERD!$A:$BS,AX$2,FALSE) -> 3.9040089 | BA32: =BA15 -> 45769 | BB32: =_xlfn.IFNA(VLOOKUP($BA32,HAVERD!$A:$BS,BB$2,FALSE),"") -> 4.4593 | BC32: =_xlfn.IFNA(VLOOKUP($BA32,HAVERD!$A:$BS,BC$2,FALSE),"") -> 4.213294 | BD32: =_xlfn.IFNA(VLOOKUP($BA32,HAVERD!$A:$BS,BD$2,FALSE),"") -> 4.1262615 | BE32: =_xlfn.IFNA(VLOOKUP($BA32,HAVERD!$A:$BS,BE$2,FALSE),"") -> 4.0235652 | BF32: =_xlfn.IFNA(VLOOKUP($BA32,HAVERD!$A:$BS,BF$2,FALSE),"") -> 3.9125732 | BG32: =_xlfn.IFNA(VLOOKUP($BA32,HAVERD!$A:$BS,BG$2,FALSE),"") -> 3.8043488 | BH32: =_xlfn.IFNA(VLOOKUP($BA32,HAVERD!$A:$BS,BH$2,FALSE),"") -> 3.7071044 | BI32: =_xlfn.IFNA(VLOOKUP($BA32,HAVERD!$A:$BS,BI$2,FALSE),"") -> 3.6256913 | ... CX32: =_xlfn.IFNA(VLOOKUP($BA32,HAVERD!$A:$BS,CX$2,FALSE),"") -> 3.7741399
A33: =A16 -> 45684 | B33: =VLOOKUP($A33,HAVERD!$A:$BS,B$2,FALSE) -> 4.7 | C33: =VLOOKUP($A33,HAVERD!$A:$BS,C$2,FALSE) -> 4.4608224 | D33: =VLOOKUP($A33,HAVERD!$A:$BS,D$2,FALSE) -> 4.4241921 | E33: =VLOOKUP($A33,HAVERD!$A:$BS,E$2,FALSE) -> 4.3661033 | F33: =VLOOKUP($A33,HAVERD!$A:$BS,F$2,FALSE) -> 4.2945824 | G33: =VLOOKUP($A33,HAVERD!$A:$BS,G$2,FALSE) -> 4.2222341 | H33: =VLOOKUP($A33,HAVERD!$A:$BS,H$2,FALSE) -> 4.1569599 | I33: =VLOOKUP($A33,HAVERD!$A:$BS,I$2,FALSE) -> 4.10271 | ... AX33: =VLOOKUP($A33,HAVERD!$A:$BS,AX$2,FALSE) -> 3.8439485 | BA33: =BA16 -> 45770 | BB33: =_xlfn.IFNA(VLOOKUP($BA33,HAVERD!$A:$BS,BB$2,FALSE),"") -> 4.459 | BC33: =_xlfn.IFNA(VLOOKUP($BA33,HAVERD!$A:$BS,BC$2,FALSE),"") -> 4.2000461 | BD33: =_xlfn.IFNA(VLOOKUP($BA33,HAVERD!$A:$BS,BD$2,FALSE),"") -> 4.1260767 | BE33: =_xlfn.IFNA(VLOOKUP($BA33,HAVERD!$A:$BS,BE$2,FALSE),"") -> 4.0314754 | BF33: =_xlfn.IFNA(VLOOKUP($BA33,HAVERD!$A:$BS,BF$2,FALSE),"") -> 3.9271294 | BG33: =_xlfn.IFNA(VLOOKUP($BA33,HAVERD!$A:$BS,BG$2,FALSE),"") -> 3.8258409 | BH33: =_xlfn.IFNA(VLOOKUP($BA33,HAVERD!$A:$BS,BH$2,FALSE),"") -> 3.7369131 | BI33: =_xlfn.IFNA(VLOOKUP($BA33,HAVERD!$A:$BS,BI$2,FALSE),"") -> 3.6661292 | ... CX33: =_xlfn.IFNA(VLOOKUP($BA33,HAVERD!$A:$BS,CX$2,FALSE),"") -> 3.8038986
A34: =A17 -> 45685 | B34: =VLOOKUP($A34,HAVERD!$A:$BS,B$2,FALSE) -> 4.7 | C34: =VLOOKUP($A34,HAVERD!$A:$BS,C$2,FALSE) -> 4.4598169 | D34: =VLOOKUP($A34,HAVERD!$A:$BS,D$2,FALSE) -> 4.4206843 | E34: =VLOOKUP($A34,HAVERD!$A:$BS,E$2,FALSE) -> 4.362708 | F34: =VLOOKUP($A34,HAVERD!$A:$BS,F$2,FALSE) -> 4.2944473 | G34: =VLOOKUP($A34,HAVERD!$A:$BS,G$2,FALSE) -> 4.2275019 | H34: =VLOOKUP($A34,HAVERD!$A:$BS,H$2,FALSE) -> 4.1682824 | I34: =VLOOKUP($A34,HAVERD!$A:$BS,I$2,FALSE) -> 4.1201531 | ... AX34: =VLOOKUP($A34,HAVERD!$A:$BS,AX$2,FALSE) -> 3.8577803 | BA34: =BA17 -> 45771 | BB34: =_xlfn.IFNA(VLOOKUP($BA34,HAVERD!$A:$BS,BB$2,FALSE),"") -> 4.4592 | BC34: =_xlfn.IFNA(VLOOKUP($BA34,HAVERD!$A:$BS,BC$2,FALSE),"") -> 4.1778004 | BD34: =_xlfn.IFNA(VLOOKUP($BA34,HAVERD!$A:$BS,BD$2,FALSE),"") -> 4.1039997 | BE34: =_xlfn.IFNA(VLOOKUP($BA34,HAVERD!$A:$BS,BE$2,FALSE),"") -> 4.0037581 | BF34: =_xlfn.IFNA(VLOOKUP($BA34,HAVERD!$A:$BS,BF$2,FALSE),"") -> 3.8936118 | BG34: =_xlfn.IFNA(VLOOKUP($BA34,HAVERD!$A:$BS,BG$2,FALSE),"") -> 3.7891444 | BH34: =_xlfn.IFNA(VLOOKUP($BA34,HAVERD!$A:$BS,BH$2,FALSE),"") -> 3.698212 | BI34: =_xlfn.IFNA(VLOOKUP($BA34,HAVERD!$A:$BS,BI$2,FALSE),"") -> 3.6246667 | ... CX34: =_xlfn.IFNA(VLOOKUP($BA34,HAVERD!$A:$BS,CX$2,FALSE),"") -> 3.7314689
... A37: =A20 -> 45688 | B37: =VLOOKUP($A37,HAVERD!$A:$BS,B$2,FALSE) -> 4.7037 | C37: =VLOOKUP($A37,HAVERD!$A:$BS,C$2,FALSE) -> 4.4560191 | D37: =VLOOKUP($A37,HAVERD!$A:$BS,D$2,FALSE) -> 4.4072557 | E37: =VLOOKUP($A37,HAVERD!$A:$BS,E$2,FALSE) -> 4.3383168 | F37: =VLOOKUP($A37,HAVERD!$A:$BS,F$2,FALSE) -> 4.2592031 | G37: =VLOOKUP($A37,HAVERD!$A:$BS,G$2,FALSE) -> 4.1834049 | H37: =VLOOKUP($A37,HAVERD!$A:$BS,H$2,FALSE) -> 4.1181155 | I37: =VLOOKUP($A37,HAVERD!$A:$BS,I$2,FALSE) -> 4.0656131 | ... AX37: =VLOOKUP($A37,HAVERD!$A:$BS,AX$2,FALSE) -> 3.7897023 | BA37: =BA20 -> 45776 | BB37: =_xlfn.IFNA(VLOOKUP($BA37,HAVERD!$A:$BS,BB$2,FALSE),"") -> 4.459 | BC37: =_xlfn.IFNA(VLOOKUP($BA37,HAVERD!$A:$BS,BC$2,FALSE),"") -> 4.1829059 | BD37: =_xlfn.IFNA(VLOOKUP($BA37,HAVERD!$A:$BS,BD$2,FALSE),"") -> 4.0985573 | BE37: =_xlfn.IFNA(VLOOKUP($BA37,HAVERD!$A:$BS,BE$2,FALSE),"") -> 3.992871 | BF37: =_xlfn.IFNA(VLOOKUP($BA37,HAVERD!$A:$BS,BF$2,FALSE),"") -> 3.8789074 | BG37: =_xlfn.IFNA(VLOOKUP($BA37,HAVERD!$A:$BS,BG$2,FALSE),"") -> 3.7713581 | BH37: =_xlfn.IFNA(VLOOKUP($BA37,HAVERD!$A:$BS,BH$2,FALSE),"") -> 3.6771273 | BI37: =_xlfn.IFNA(VLOOKUP($BA37,HAVERD!$A:$BS,BI$2,FALSE),"") -> 3.5993768 | ... CX37: =_xlfn.IFNA(VLOOKUP($BA37,HAVERD!$A:$BS,CX$2,FALSE),"") -> 3.6985572
A39: Average | BA39: Average
A40: Month | B40: =MONTH(B20) -> 1 | C40: =MONTH(C20) -> 3 | D40: =MONTH(D20) -> 4 | E40: =MONTH(E20) -> 5 | F40: =MONTH(F20) -> 6 | G40: =MONTH(G20) -> 7 | H40: =MONTH(H20) -> 8 | I40: =MONTH(I20) -> 8 | ... AX40: =MONTH(AX20) -> 1 | BA40: Month | BB40: =MONTH(BB18) -> 4 | BC40: =MONTH(BC18) -> 5 | BD40: =MONTH(BD18) -> 6 | BE40: =MONTH(BE18) -> 7 | BF40: =MONTH(BF18) -> 8 | BG40: =MONTH(BG18) -> 9 | BH40: =MONTH(BH18) -> 10 | BI40: =MONTH(BI18) -> 11 | ... CX40: =MONTH(CX18) -> 4
A41: Year | B41: =YEAR(B20) -> 2025 | C41: =YEAR(C20) -> 2025 | D41: =YEAR(D20) -> 2025 | E41: =YEAR(E20) -> 2025 | F41: =YEAR(F20) -> 2025 | G41: =YEAR(G20) -> 2025 | H41: =YEAR(H20) -> 2025 | I41: =YEAR(I20) -> 2025 | ... AX41: =YEAR(AX20) -> 2029 | BA41: Year | BB41: =YEAR(BB20) -> 2025 | BC41: =YEAR(BC20) -> 2025 | BD41: =YEAR(BD20) -> 2025 | BE41: =YEAR(BE20) -> 2025 | BF41: =YEAR(BF20) -> 2025 | BG41: =YEAR(BG20) -> 2025 | BH41: =YEAR(BH20) -> 2025 | BI41: =YEAR(BI20) -> 2025 | ... CX41: =YEAR(CX20) -> 2029
A42: YYYYMM | B42: =B41*100+B40 -> 202501 | C42: =C41*100+C40 -> 202503 | D42: =D41*100+D40 -> 202504 | E42: =E41*100+E40 -> 202505 | F42: =F41*100+F40 -> 202506 | G42: =G41*100+G40 -> 202507 | H42: =H41*100+H40 -> 202508 | I42: =I41*100+I40 -> 202508 | ... AX42: =AX41*100+AX40 -> 202901 | BA42: YYYYMM | BB42: =BB41*100+BB40 -> 202504 | BC42: =BC41*100+BC40 -> 202505 | BD42: =BD41*100+BD40 -> 202506 | BE42: =BE41*100+BE40 -> 202507 | BF42: =BF41*100+BF40 -> 202508 | BG42: =BG41*100+BG40 -> 202509 | BH42: =BH41*100+BH40 -> 202510 | BI42: =BI41*100+BI40 -> 202511 | ... CX42: =CX41*100+CX40 -> 202904
A43: Quarter | B43: =IF(B40<4,1,IF(B40<7,2,IF(B40<10,3,4))) -> 1 | C43: =IF(C40<4,1,IF(C40<7,2,IF(C40<10,3,4))) -> 1 | D43: =IF(D40<4,1,IF(D40<7,2,IF(D40<10,3,4))) -> 2 | E43: =IF(E40<4,1,IF(E40<7,2,IF(E40<10,3,4))) -> 2 | F43: =IF(F40<4,1,IF(F40<7,2,IF(F40<10,3,4))) -> 2 | G43: =IF(G40<4,1,IF(G40<7,2,IF(G40<10,3,4))) -> 3 | H43: =IF(H40<4,1,IF(H40<7,2,IF(H40<10,3,4))) -> 3 | I43: =IF(I40<4,1,IF(I40<7,2,IF(I40<10,3,4))) -> 3 | ... AX43: =IF(AX40<4,1,IF(AX40<7,2,IF(AX40<10,3,4))) -> 1 | BA43: Quarter | BB43: =IF(BB40<4,1,IF(BB40<7,2,IF(BB40<10,3,4))) -> 2 | BC43: =IF(BC40<4,1,IF(BC40<7,2,IF(BC40<10,3,4))) -> 2 | BD43: =IF(BD40<4,1,IF(BD40<7,2,IF(BD40<10,3,4))) -> 2 | BE43: =IF(BE40<4,1,IF(BE40<7,2,IF(BE40<10,3,4))) -> 3 | BF43: =IF(BF40<4,1,IF(BF40<7,2,IF(BF40<10,3,4))) -> 3 | BG43: =IF(BG40<4,1,IF(BG40<7,2,IF(BG40<10,3,4))) -> 3 | BH43: =IF(BH40<4,1,IF(BH40<7,2,IF(BH40<10,3,4))) -> 4 | BI43: =IF(BI40<4,1,IF(BI40<7,2,IF(BI40<10,3,4))) -> 4 | ... CX43: =IF(CX40<4,1,IF(CX40<7,2,IF(CX40<10,3,4))) -> 2
A44: YYYYQQ | B44: =B41*100+B43 -> 202501 | C44: =C41*100+C43 -> 202501 | D44: =D41*100+D43 -> 202502 | E44: =E41*100+E43 -> 202502 | F44: =F41*100+F43 -> 202502 | G44: =G41*100+G43 -> 202503 | H44: =H41*100+H43 -> 202503 | I44: =I41*100+I43 -> 202503 | ... AX44: =AX41*100+AX43 -> 202901 | BA44: YYYYQQ | BB44: =BB41*100+BB43 -> 202502 | BC44: =BC41*100+BC43 -> 202502 | BD44: =BD41*100+BD43 -> 202502 | BE44: =BE41*100+BE43 -> 202503 | BF44: =BF41*100+BF43 -> 202503 | BG44: =BG41*100+BG43 -> 202503 | BH44: =BH41*100+BH43 -> 202504 | BI44: =BI41*100+BI43 -> 202504 | ... CX44: =CX41*100+CX43 -> 202902
...

Sheet Market expectations - Gas
A1: ='Market pricing dates'!A2 -> February 2025 MPR | C1: ='Market pricing dates'!A12 -> 15 working days to 31 Jan 2025 | AZ1: ='Market pricing dates'!D2 -> May 2025 MPR | BB1: ='Market pricing dates'!D12 -> 15 working days to 29 Apr 2025
A2: Column # | B2: =HAVERD!BU$1 -> 73 | C2: =+B2+1 -> 74 | D2: =+C2+1 -> 75 | E2: =+D2+1 -> 76 | F2: =+E2+1 -> 77 | G2: =+F2+1 -> 78 | H2: =+G2+1 -> 79 | I2: =+H2+1 -> 80 | J2: =+I2+1 -> 81 | ... AW2: =+AV2+1 -> 120 | AZ2: Column # | BA2: =HAVERD!BU$1 -> 73 | BB2: =+BA2+1 -> 74 | BC2: =+BB2+1 -> 75 | BD2: =+BC2+1 -> 76 | BE2: =+BD2+1 -> 77 | BF2: =+BE2+1 -> 78 | BG2: =+BF2+1 -> 79 | BH2: =+BG2+1 -> 80 | BI2: =+BH2+1 -> 81 | ... CV2: =+CU2+1 -> 120
A3: Months | B3: =HAVERD!BU$2 -> Gas - 1 | C3: =HAVERD!BV$2 -> Gas - 2 | D3: =HAVERD!BW$2 -> Gas - 3 | E3: =HAVERD!BX$2 -> Gas - 4 | F3: =HAVERD!BY$2 -> Gas - 5 | G3: =HAVERD!BZ$2 -> Gas - 6 | H3: =HAVERD!CA$2 -> Gas - 7 | I3: =HAVERD!CB$2 -> Gas - 8 | ... AW3: =HAVERD!DP$2 -> Gas - 48 | AZ3: Months | BA3: =HAVERD!BU$2 -> Gas - 1 | BB3: =HAVERD!BV$2 -> Gas - 2 | BC3: =HAVERD!BW$2 -> Gas - 3 | BD3: =HAVERD!BX$2 -> Gas - 4 | BE3: =HAVERD!BY$2 -> Gas - 5 | BF3: =HAVERD!BZ$2 -> Gas - 6 | BG3: =HAVERD!CA$2 -> Gas - 7 | BH3: =HAVERD!CB$2 -> Gas - 8 | ... CV3: =HAVERD!DP$2 -> Gas - 48
A4: Days | C4: 30.416667 | D4: =+C4+30.4166667 -> 60.833333 | E4: =+D4+30.4166667 -> 91.25 | F4: =+E4+30.4166667 -> 121.66667 | G4: =+F4+30.4166667 -> 152.08333 | H4: =+G4+30.4166667 -> 182.5 | I4: =+H4+30.4166667 -> 212.91667 | J4: =+I4+30.4166667 -> 243.33333 | K4: =+J4+30.4166667 -> 273.75 | ... AW4: =+AV4+30.4166667 -> 1429.5833 | AZ4: Days | BB4: 30.416667 | BC4: =+BB4+30.4166667 -> 60.833333 | BD4: =+BC4+30.4166667 -> 91.25 | BE4: =+BD4+30.4166667 -> 121.66667 | BF4: =+BE4+30.4166667 -> 152.08333 | BG4: =+BF4+30.4166667 -> 182.5 | BH4: =+BG4+30.4166667 -> 212.91667 | BI4: =+BH4+30.4166667 -> 243.33333 | BJ4: =+BI4+30.4166667 -> 273.75 | ... CV4: =+CU4+30.4166667 -> 1429.5833
A5: Dates | AZ5: Dates
A6: =A11-7 -> 45670 | B6: =A6 -> 45670 | C6: =$B6+C$4 -> 45700.417 | D6: =$B6+D$4 -> 45730.833 | E6: =$B6+E$4 -> 45761.25 | F6: =$B6+F$4 -> 45791.667 | G6: =$B6+G$4 -> 45822.083 | H6: =$B6+H$4 -> 45852.5 | I6: =$B6+I$4 -> 45882.917 | J6: =$B6+J$4 -> 45913.333 | ... AW6: =$B6+AW$4 -> 47099.583 | AZ6: =AZ11-7 -> 45756 | BA6: =AZ6 -> 45756 | BB6: =$AZ6+BB$4 -> 45786.417 | BC6: =$AZ6+BC$4 -> 45816.833 | BD6: =$AZ6+BD$4 -> 45847.25 | BE6: =$AZ6+BE$4 -> 45877.667 | BF6: =$AZ6+BF$4 -> 45908.083 | BG6: =$AZ6+BG$4 -> 45938.5 | BH6: =$AZ6+BH$4 -> 45968.917 | BI6: =$AZ6+BI$4 -> 45999.333 | ... CV6: =$AZ6+CV$4 -> 47185.583
