Workbook
Name A: #REF!
Name Data: [1]sheet0!$C$2
Name S: {#N/A,#N/A,FALSE,"CGBR95C"}

Sheet >> CHARTS

Sheet >> DATA

Sheet Chart Data
A1: UK trade with US by sector | AX1: Mechanical power generators (consumer) | AY1: Specialised machinery | AZ1: Metal working machinery | BA1: General industrial machinery | BB1: Office machinery | BC1: Telecoms & sound equipment | BD1: Miscellaneous electrical goods | BE1: Road vehicles other than cars | BF1: Cars | BG1: Railway equipment | BH1: Aircraft | BI1: Ships | BJ1: Plumbing, heating & lighting fixtures | BK1: Furniture | BL1: Travel goods, handbags etc | BM1: Clothing | BN1: Footwear | BO1: Scientific instruments | BP1: Photographic & optical goods & clocks | BQ1: Works of art | BR1: Jewellery | BS1: Other manufactures | BT1: Unspecified goods | BV1: GDP growth | CC1: CPI inflation | CI1: Exports | CO1: RXD | CU1: Full blown Trump CPI calculation | CX1: Goods exports to US as % of total exports
B2: Total | C2: ='ONS - UK Exports by type'!E1 -> Live animals | D2: ='ONS - UK Exports by type'!F1 -> Meat & meat preparations | E2: ='ONS - UK Exports by type'!G1 -> Dairy products & eggs | F2: ='ONS - UK Exports by type'!H1 -> Fish and shellfish | G2: ='ONS - UK Exports by type'!I1 -> Cereals | H2: ='ONS - UK Exports by type'!J1 -> Vegetables & fruit | I2: ='ONS - UK Exports by type'!K1 -> Sugar | J2: ='ONS - UK Exports by type'!L1 -> Coffee, tea, cocoa etc | ... AV2: ='ONS - UK Exports by type'!AX1 -> Miscellaneous metal manufactures | AW2: Electric motors | AX2: Mechanical power generators | AY2: Specialised machinery | AZ2: Metal working machinery | BA2: General industrial machinery | BB2: Office machinery | BC2: ='ONS - UK Exports by type'!BO1 -> Telecoms & sound equipment (consumer) | BD2: Miscellaneous electrical goods | BE2: ='ONS - UK Exports by type'!BU1 -> Road vehicles other than cars (consumer) | BF2: ='ONS - UK Exports by type'!BX1 -> Cars | BG2: ='ONS - UK Exports by type'!BY1 -> Railway equipment (intermediate) | BH2: ='ONS - UK Exports by type'!CA1 -> Aircraft | BI2: ='ONS - UK Exports by type'!CB1 -> Ships | BJ2: ='ONS - UK Exports by type'!CC1 -> Plumbing, heating & lighting fixtures (consumer) | BK2: Furniture | BL2: ='ONS - UK Exports by type'!CI1 -> Travel goods, handbags etc | BM2: ='ONS - UK Exports by type'!CJ1 -> Clothing | BN2: ='ONS - UK Exports by type'!CK1 -> Footwear | BO2: ='ONS - UK Exports by type'!CL1 -> Scientific instruments (consumer) | BP2: Photographic & optical goods & clocks | BQ2: ='ONS - UK Exports by type'!CR1 -> Works of art | BR2: ='ONS - UK Exports by type'!CS1 -> Jewellery | BS2: Other manufactures | BT2: ='ONS - UK Exports by type'!CW1 -> Unspecified goods | BW2: Baseline | BX2: Full-blown Trump presidency | BY2: ZERO LINE | CA2: Difference | CD2: Baseline | CE2: Full-blown Trump presidency | CG2: Difference | CJ2: Baseline | CK2: Full-blown Trump presidency | CM2: Difference | CP2: Baseline | CQ2: Full-blown Trump presidency | CS2: Difference | CU2: Tariff increase | CV2: 0.062 | CY2: Share | CZ2: Level | DA2: Original deal | DB2: Pre steel increase | DC2: Pre-trade deal
A3: Exports | BV3: 2023 | BW3: =100*((DataQ!D207/DataQ!D203)-1) -> 0.86831577 | BX3: =100*((DataQ!K207/DataQ!K203)-1) -> 0.86831577 | BY3: 0 | CA3: =100*((DataQ!K207/DataQ!D207)-1) -> 0 | CC3: 2023 | CD3: =100*((DataQ!E207/DataQ!E203)-1) -> 10.178266 | CE3: =100*((DataQ!L207/DataQ!L203)-1) -> 10.178266 | CG3: =100*((DataQ!L207/DataQ!E207)-1) -> 0 | CI3: 2023 | CJ3: =100*((DataQ!F207/DataQ!F203)-1) -> 9.1534853 | CK3: =100*((DataQ!M207/DataQ!M203)-1) -> 9.1534853 | CM3: =100*((DataQ!M207/DataQ!F207)-1) -> 0 | CO3: 2023 | CP3: =DataQ!J207 -> 1.215133 | CQ3: =DataQ!Q207 -> 1.215133 | CS3: =100*((DataQ!Q207/DataQ!J207)-1) -> 0 | CU3: US share in UK goods imports | CV3: =B62/100 -> 0.099705261 | CX3: Exports to US - 10% tariff | CY3: =100*(CZ3/$CZ$8) -> 5.2227766 | CZ3: =DD4-CZ10-CZ4 -> 45084 | DA3: =DD4-DA10-DA4 -> 47201 | DB3: =DD4-CZ10-CZ4 -> 45084 | DC3: =DD4-DC10-DC4 -> 38781 | DE3: =CY3/SUM($CY$3:$CY$4) -> 0.74602859
A4: 2018 | B4: ='ONS - UK Exports by type'!D221 -> 52715 | C4: ='ONS - UK Exports by type'!E221 -> 22 | D4: ='ONS - UK Exports by type'!F221 -> 39 | E4: ='ONS - UK Exports by type'!G221 -> 65 | F4: ='ONS - UK Exports by type'!H221 -> 201 | G4: ='ONS - UK Exports by type'!I221 -> 109 | H4: ='ONS - UK Exports by type'!J221 -> 26 | I4: ='ONS - UK Exports by type'!K221 -> 26 | ... AV4: ='ONS - UK Exports by type'!AX221 -> 715 | AW4: ='ONS - UK Exports by type'!AY221+'ONS - UK Exports by type'!AZ221 -> 194 | AX4: ='ONS - UK Exports by type'!BA221+'ONS - UK Exports by type'!BB221+'ONS - UK Exports by type'!BC221 -> 4849 | AY4: ='ONS - UK Exports by type'!BD221+'ONS - UK Exports by type'!BE221+'ONS - UK Exports by type'!BF221 -> 1604 | AZ4: ='ONS - UK Exports by type'!BG221+'ONS - UK Exports by type'!BH221 -> 186 | BA4: ='ONS - UK Exports by type'!BI221+'ONS - UK Exports by type'!BJ221+'ONS - UK Exports by type'!BK221 -> 2232 | BB4: ='ONS - UK Exports by type'!BL221+'ONS - UK Exports by type'!BK221+'ONS - UK Exports by type'!BM221 -> 1217 | BC4: ='ONS - UK Exports by type'!BO221+'ONS - UK Exports by type'!BP221+'ONS - UK Exports by type'!BQ221 -> 748 | BD4: ='ONS - UK Exports by type'!BR221+'ONS - UK Exports by type'!BS221+'ONS - UK Exports by type'!BT221 -> 1951 | BE4: ='ONS - UK Exports by type'!BU221+'ONS - UK Exports by type'!BV221+'ONS - UK Exports by type'!BW221 -> 832 | BF4: ='ONS - UK Exports by type'!BX221 -> 7898 | BG4: ='ONS - UK Exports by type'!BY221+'ONS - UK Exports by type'!BZ221 -> 9 | BH4: ='ONS - UK Exports by type'!CA221 -> 2355 | BI4: ='ONS - UK Exports by type'!CB221 -> 375 | BJ4: ='ONS - UK Exports by type'!CC221+'ONS - UK Exports by type'!CD221+'ONS - UK Exports by type'!CE221 -> 60 | BK4: ='ONS - UK Exports by type'!CF221+'ONS - UK Exports by type'!CG221+'ONS - UK Exports by type'!CH221 -> 554 | BL4: ='ONS - UK Exports by type'!CI221 -> 39 | BM4: ='ONS - UK Exports by type'!CJ221 -> 316 | BN4: ='ONS - UK Exports by type'!CK221 -> 53 | BO4: ='ONS - UK Exports by type'!CL221+'ONS - UK Exports by type'!CK221+'ONS - UK Exports by type'!CM221 -> 353 | BP4: ='ONS - UK Exports by type'!CO221+'ONS - UK Exports by type'!CP221+'ONS - UK Exports by type'!CQ221 -> 416 | BQ4: ='ONS - UK Exports by type'!CR221 -> 3181 | BR4: ='ONS - UK Exports by type'!CS221 -> 231 | BS4: ='ONS - UK Exports by type'!CT221+'ONS - UK Exports by type'!CU221+'ONS - UK Exports by type'!CV221 -> 1321 | BT4: ='ONS - UK Exports by type'!CW221 -> 279 | BW4: =100*((DataQ!D208/DataQ!D204)-1) -> 0.53322097 | BX4: =100*((DataQ!K208/DataQ!K204)-1) -> 0.53322097 | BY4: 0 | CA4: =100*((DataQ!K208/DataQ!D208)-1) -> 0 | CD4: =100*((DataQ!E208/DataQ!E204)-1) -> 8.439049 | CE4: =100*((DataQ!L208/DataQ!L204)-1) -> 8.439049 | CG4: =100*((DataQ!L208/DataQ!E208)-1) -> 0 | CJ4: =100*((DataQ!F208/DataQ!F204)-1) -> 2.0102585 | CK4: =100*((DataQ!M208/DataQ!M204)-1) -> 2.0102585 | CM4: =100*((DataQ!M208/DataQ!F208)-1) -> 0 | CP4: =DataQ!J208 -> 1.251867 | CQ4: =DataQ!Q208 -> 1.251867 | CS4: =100*((DataQ!Q208/DataQ!J208)-1) -> 0 | CU4: Goods import share of UK CPI basket | CV4: 0.3 | CX4: Exports to US - goods currently exempt | CY4: =100*(CZ4/$CZ$8) -> 1.7779961 | CZ4: =((CY17+CY18+CY19+CY20+CY21)/$CZ$23)*$DD$4 -> 15348 | DA4: =((CY17+CY18+CY19+CY20)/$CZ$23)*$DD$4 -> 13231 | DB4: =((CY13+CY17+CY18+CY19+CY20)/$CZ$23)*$DD$4 -> 15216 | DC4: =((CY17+CY18+CY19+CY20)/$CZ$23)*$DD$4 -> 13231 | DD4: ='ONS Pink Book - 9.4'!AA58 -> 60432 | DE4: =CY4/SUM($CY$3:$CY$4) -> 0.25397141
A5: 2019 | B5: ='ONS - UK Exports by type'!D457 -> 58893 | C5: ='ONS - UK Exports by type'!E457 -> 29 | D5: ='ONS - UK Exports by type'!F457 -> 41 | E5: ='ONS - UK Exports by type'!G457 -> 75 | F5: ='ONS - UK Exports by type'!H457 -> 331 | G5: ='ONS - UK Exports by type'!I457 -> 115 | H5: ='ONS - UK Exports by type'!J457 -> 25 | I5: ='ONS - UK Exports by type'!K457 -> 20 | ... AV5: ='ONS - UK Exports by type'!AX457 -> 755 | AW5: ='ONS - UK Exports by type'!AY457+'ONS - UK Exports by type'!AZ457 -> 211 | AX5: ='ONS - UK Exports by type'!BA457+'ONS - UK Exports by type'!BB457+'ONS - UK Exports by type'!BC457 -> 5425 | AY5: ='ONS - UK Exports by type'!BD457+'ONS - UK Exports by type'!BE457+'ONS - UK Exports by type'!BF457 -> 1772 | AZ5: ='ONS - UK Exports by type'!BG457+'ONS - UK Exports by type'!BH457 -> 181 | BA5: ='ONS - UK Exports by type'!BI457+'ONS - UK Exports by type'!BJ457+'ONS - UK Exports by type'!BK457 -> 2561 | BB5: ='ONS - UK Exports by type'!BL457+'ONS - UK Exports by type'!BK457+'ONS - UK Exports by type'!BM457 -> 1359 | BC5: ='ONS - UK Exports by type'!BO457+'ONS - UK Exports by type'!BP457+'ONS - UK Exports by type'!BQ457 -> 855 | BD5: ='ONS - UK Exports by type'!BR457+'ONS - UK Exports by type'!BS457+'ONS - UK Exports by type'!BT457 -> 2170 | BE5: ='ONS - UK Exports by type'!BU457+'ONS - UK Exports by type'!BV457+'ONS - UK Exports by type'!BW457 -> 866 | BF5: ='ONS - UK Exports by type'!BX457 -> 8685 | BG5: ='ONS - UK Exports by type'!BY457+'ONS - UK Exports by type'!BZ457 -> 5 | BH5: ='ONS - UK Exports by type'!CA457 -> 2438 | BI5: ='ONS - UK Exports by type'!CB457 -> 253 | BJ5: ='ONS - UK Exports by type'!CC457+'ONS - UK Exports by type'!CD457+'ONS - UK Exports by type'!CE457 -> 77 | BK5: ='ONS - UK Exports by type'!CF457+'ONS - UK Exports by type'!CG457+'ONS - UK Exports by type'!CH457 -> 624 | BL5: ='ONS - UK Exports by type'!CI457 -> 41 | BM5: ='ONS - UK Exports by type'!CJ457 -> 399 | BN5: ='ONS - UK Exports by type'!CK457 -> 57 | BO5: ='ONS - UK Exports by type'!CL457+'ONS - UK Exports by type'!CK457+'ONS - UK Exports by type'!CM457 -> 368 | BP5: ='ONS - UK Exports by type'!CO457+'ONS - UK Exports by type'!CP457+'ONS - UK Exports by type'!CQ457 -> 418 | BQ5: ='ONS - UK Exports by type'!CR457 -> 2739 | BR5: ='ONS - UK Exports by type'!CS457 -> 286 | BS5: ='ONS - UK Exports by type'!CT457+'ONS - UK Exports by type'!CU457+'ONS - UK Exports by type'!CV457 -> 1545 | BT5: ='ONS - UK Exports by type'!CW457 -> 2964 | BW5: =100*((DataQ!D209/DataQ!D205)-1) -> 0.31314431 | BX5: =100*((DataQ!K209/DataQ!K205)-1) -> 0.31314431 | BY5: 0 | CA5: =100*((DataQ!K209/DataQ!D209)-1) -> 0 | CD5: =100*((DataQ!E209/DataQ!E205)-1) -> 6.7136185 | CE5: =100*((DataQ!L209/DataQ!L205)-1) -> 6.7136185 | CG5: =100*((DataQ!L209/DataQ!E209)-1) -> 0 | CJ5: =100*((DataQ!F209/DataQ!F205)-1) -> -8.5368404 | CK5: =100*((DataQ!M209/DataQ!M205)-1) -> -8.5368404 | CM5: =100*((DataQ!M209/DataQ!F209)-1) -> 0 | CP5: =DataQ!J209 -> 1.2659 | CQ5: =DataQ!Q209 -> 1.2659 | CS5: =100*((DataQ!Q209/DataQ!J209)-1) -> 0 | CV5: =CV2*CV3*CV4 -> 0.0018545179 | CX5: Exports to US - steel & aluminium | CY5: =100*(CZ5/$CZ$8) -> 0.22995323 | CZ5: =(CY13/$CZ$23)*$DD$4 -> 1985 | DA5: =(CY13/$CZ$23)*$DD$4 -> 1985
A6: 2020 | B6: ='ONS - UK Exports by type'!D693 -> 47423 | C6: ='ONS - UK Exports by type'!E693 -> 23 | D6: ='ONS - UK Exports by type'!F693 -> 31 | E6: ='ONS - UK Exports by type'!G693 -> 67 | F6: ='ONS - UK Exports by type'!H693 -> 204 | G6: ='ONS - UK Exports by type'!I693 -> 104 | H6: ='ONS - UK Exports by type'!J693 -> 29 | I6: ='ONS - UK Exports by type'!K693 -> 56 | ... AV6: ='ONS - UK Exports by type'!AX693 -> 721 | AW6: ='ONS - UK Exports by type'!AY693+'ONS - UK Exports by type'!AZ693 -> 205 | AX6: ='ONS - UK Exports by type'!BA693+'ONS - UK Exports by type'!BB693+'ONS - UK Exports by type'!BC693 -> 3775 | AY6: ='ONS - UK Exports by type'!BD693+'ONS - UK Exports by type'!BE693+'ONS - UK Exports by type'!BF693 -> 1315 | AZ6: ='ONS - UK Exports by type'!BG693+'ONS - UK Exports by type'!BH693 -> 208 | BA6: ='ONS - UK Exports by type'!BI693+'ONS - UK Exports by type'!BJ693+'ONS - UK Exports by type'!BK693 -> 2594 | BB6: ='ONS - UK Exports by type'!BL693+'ONS - UK Exports by type'!BK693+'ONS - UK Exports by type'!BM693 -> 1590 | BC6: ='ONS - UK Exports by type'!BO693+'ONS - UK Exports by type'!BP693+'ONS - UK Exports by type'!BQ693 -> 803 | BD6: ='ONS - UK Exports by type'!BR693+'ONS - UK Exports by type'!BS693+'ONS - UK Exports by type'!BT693 -> 2130 | BE6: ='ONS - UK Exports by type'!BU693+'ONS - UK Exports by type'!BV693+'ONS - UK Exports by type'!BW693 -> 698 | BF6: ='ONS - UK Exports by type'!BX693 -> 5850 | BG6: ='ONS - UK Exports by type'!BY693+'ONS - UK Exports by type'!BZ693 -> 11 | BH6: ='ONS - UK Exports by type'!CA693 -> 2205 | BI6: ='ONS - UK Exports by type'!CB693 -> 379 | BJ6: ='ONS - UK Exports by type'!CC693+'ONS - UK Exports by type'!CD693+'ONS - UK Exports by type'!CE693 -> 73 | BK6: ='ONS - UK Exports by type'!CF693+'ONS - UK Exports by type'!CG693+'ONS - UK Exports by type'!CH693 -> 492 | BL6: ='ONS - UK Exports by type'!CI693 -> 44 | BM6: ='ONS - UK Exports by type'!CJ693 -> 340 | BN6: ='ONS - UK Exports by type'!CK693 -> 43 | BO6: ='ONS - UK Exports by type'!CL693+'ONS - UK Exports by type'!CK693+'ONS - UK Exports by type'!CM693 -> 303 | BP6: ='ONS - UK Exports by type'!CO693+'ONS - UK Exports by type'!CP693+'ONS - UK Exports by type'!CQ693 -> 322 | BQ6: ='ONS - UK Exports by type'!CR693 -> 1626 | BR6: ='ONS - UK Exports by type'!CS693 -> 167 | BS6: ='ONS - UK Exports by type'!CT693+'ONS - UK Exports by type'!CU693+'ONS - UK Exports by type'!CV693 -> 1410 | BT6: ='ONS - UK Exports by type'!CW693 -> 983 | BW6: =100*((DataQ!D210/DataQ!D206)-1) -> -0.34997571 | BX6: =100*((DataQ!K210/DataQ!K206)-1) -> -0.34997571 | BY6: 0 | CA6: =100*((DataQ!K210/DataQ!D210)-1) -> 0 | CD6: =100*((DataQ!E210/DataQ!E206)-1) -> 4.1568272 | CE6: =100*((DataQ!L210/DataQ!L206)-1) -> 4.1568272 | CG6: =100*((DataQ!L210/DataQ!E210)-1) -> 0 | CJ6: =100*((DataQ!F210/DataQ!F206)-1) -> -9.1616093 | CK6: =100*((DataQ!M210/DataQ!M206)-1) -> -9.1616093 | CM6: =100*((DataQ!M210/DataQ!F210)-1) -> 0 | CP6: =DataQ!J210 -> 1.2417 | CQ6: =DataQ!Q210 -> 1.2417 | CS6: =100*((DataQ!Q210/DataQ!J210)-1) -> 0 | CX6: Goods exports to other countries | CY6: =100*(CZ6/$CZ$8) -> 38.586268 | CZ6: ='ONS Pink Book - 9.4'!AA94-'ONS Pink Book - 9.4'!AA58 -> 333084 | DA6: ='ONS Pink Book - 9.4'!AA94-'ONS Pink Book - 9.4'!AA58 -> 333084 | DB6: ='ONS Pink Book - 9.4'!AA94-'ONS Pink Book - 9.4'!AA58 -> 333084 | DC6: ='ONS Pink Book - 9.4'!AA94-'ONS Pink Book - 9.4'!AA58 -> 333084
A7: 2021 | B7: ='ONS - UK Exports by type'!D929 -> 49720 | C7: ='ONS - UK Exports by type'!E929 -> 44 | D7: ='ONS - UK Exports by type'!F929 -> 42 | E7: ='ONS - UK Exports by type'!G929 -> 78 | F7: ='ONS - UK Exports by type'!H929 -> 226 | G7: ='ONS - UK Exports by type'!I929 -> 124 | H7: ='ONS - UK Exports by type'!J929 -> 23 | I7: ='ONS - UK Exports by type'!K929 -> 23 | ... AV7: ='ONS - UK Exports by type'!AX929 -> 720 | AW7: ='ONS - UK Exports by type'!AY929+'ONS - UK Exports by type'!AZ929 -> 191 | AX7: ='ONS - UK Exports by type'!BA929+'ONS - UK Exports by type'!BB929+'ONS - UK Exports by type'!BC929 -> 3558 | AY7: ='ONS - UK Exports by type'!BD929+'ONS - UK Exports by type'!BE929+'ONS - UK Exports by type'!BF929 -> 1530 | AZ7: ='ONS - UK Exports by type'!BG929+'ONS - UK Exports by type'!BH929 -> 235 | BA7: ='ONS - UK Exports by type'!BI929+'ONS - UK Exports by type'!BJ929+'ONS - UK Exports by type'!BK929 -> 2639 | BB7: ='ONS - UK Exports by type'!BL929+'ONS - UK Exports by type'!BK929+'ONS - UK Exports by type'!BM929 -> 1689 | BC7: ='ONS - UK Exports by type'!BO929+'ONS - UK Exports by type'!BP929+'ONS - UK Exports by type'!BQ929 -> 777 | BD7: ='ONS - UK Exports by type'!BR929+'ONS - UK Exports by type'!BS929+'ONS - UK Exports by type'!BT929 -> 2153 | BE7: ='ONS - UK Exports by type'!BU929+'ONS - UK Exports by type'!BV929+'ONS - UK Exports by type'!BW929 -> 886 | BF7: ='ONS - UK Exports by type'!BX929 -> 6803 | BG7: ='ONS - UK Exports by type'!BY929+'ONS - UK Exports by type'!BZ929 -> 17 | BH7: ='ONS - UK Exports by type'!CA929 -> 1985 | BI7: ='ONS - UK Exports by type'!CB929 -> 411 | BJ7: ='ONS - UK Exports by type'!CC929+'ONS - UK Exports by type'!CD929+'ONS - UK Exports by type'!CE929 -> 88 | BK7: ='ONS - UK Exports by type'!CF929+'ONS - UK Exports by type'!CG929+'ONS - UK Exports by type'!CH929 -> 369 | BL7: ='ONS - UK Exports by type'!CI929 -> 47 | BM7: ='ONS - UK Exports by type'!CJ929 -> 603 | BN7: ='ONS - UK Exports by type'!CK929 -> 55 | BO7: ='ONS - UK Exports by type'!CL929+'ONS - UK Exports by type'!CK929+'ONS - UK Exports by type'!CM929 -> 321 | BP7: ='ONS - UK Exports by type'!CO929+'ONS - UK Exports by type'!CP929+'ONS - UK Exports by type'!CQ929 -> 275 | BQ7: ='ONS - UK Exports by type'!CR929 -> 1426 | BR7: ='ONS - UK Exports by type'!CS929 -> 240 | BS7: ='ONS - UK Exports by type'!CT929+'ONS - UK Exports by type'!CU929+'ONS - UK Exports by type'!CV929 -> 1666 | BT7: ='ONS - UK Exports by type'!CW929 -> 253 | BV7: 2024 | BW7: =100*((DataQ!D211/DataQ!D207)-1) -> 0.25369832 | BX7: =100*((DataQ!K211/DataQ!K207)-1) -> 0.25369832 | BY7: 0 | CA7: =100*((DataQ!K211/DataQ!D211)-1) -> 0 | CC7: 2024 | CD7: =100*((DataQ!E211/DataQ!E207)-1) -> 3.5491137 | CE7: =100*((DataQ!L211/DataQ!L207)-1) -> 3.5491137 | CG7: =100*((DataQ!L211/DataQ!E211)-1) -> 0 | CI7: 2024 | CJ7: =100*((DataQ!F211/DataQ!F207)-1) -> -2.5841338 | CK7: =100*((DataQ!M211/DataQ!M207)-1) -> -2.5841338 | CM7: =100*((DataQ!M211/DataQ!F211)-1) -> 0 | CO7: 2024 | CP7: =DataQ!J211 -> 1.267967 | CQ7: =DataQ!Q211 -> 1.267967 | CS7: =100*((DataQ!Q211/DataQ!J211)-1) -> 0 | CX7: Services exports | CY7: =100*(CZ7/$CZ$8) -> 54.183006 | CZ7: ='ONS Pink Book - 9.5'!AA94 -> 467718 | DA7: ='ONS Pink Book - 9.5'!AA94 -> 467718 | DB7: ='ONS Pink Book - 9.5'!AA94 -> 467718 | DC7: ='ONS Pink Book - 9.5'!AA94 -> 467718
A8: 2022 | B8: ='ONS - UK Exports by type'!D1165 -> 59940 | C8: ='ONS - UK Exports by type'!E1165 -> 69 | D8: ='ONS - UK Exports by type'!F1165 -> 41 | E8: ='ONS - UK Exports by type'!G1165 -> 127 | F8: ='ONS - UK Exports by type'!H1165 -> 257 | G8: ='ONS - UK Exports by type'!I1165 -> 166 | H8: ='ONS - UK Exports by type'!J1165 -> 27 | I8: ='ONS - UK Exports by type'!K1165 -> 22 | ... AV8: ='ONS - UK Exports by type'!AX1165 -> 882 | AW8: ='ONS - UK Exports by type'!AY1165+'ONS - UK Exports by type'!AZ1165 -> 244 | AX8: ='ONS - UK Exports by type'!BA1165+'ONS - UK Exports by type'!BB1165+'ONS - UK Exports by type'!BC1165 -> 4475 | AY8: ='ONS - UK Exports by type'!BD1165+'ONS - UK Exports by type'!BE1165+'ONS - UK Exports by type'!BF1165 -> 2004 | AZ8: ='ONS - UK Exports by type'!BG1165+'ONS - UK Exports by type'!BH1165 -> 240 | BA8: ='ONS - UK Exports by type'!BI1165+'ONS - UK Exports by type'!BJ1165+'ONS - UK Exports by type'!BK1165 -> 3380 | BB8: ='ONS - UK Exports by type'!BL1165+'ONS - UK Exports by type'!BK1165+'ONS - UK Exports by type'!BM1165 -> 2218 | BC8: ='ONS - UK Exports by type'!BO1165+'ONS - UK Exports by type'!BP1165+'ONS - UK Exports by type'!BQ1165 -> 952 | BD8: ='ONS - UK Exports by type'!BR1165+'ONS - UK Exports by type'!BS1165+'ONS - UK Exports by type'!BT1165 -> 2416 | BE8: ='ONS - UK Exports by type'!BU1165+'ONS - UK Exports by type'!BV1165+'ONS - UK Exports by type'!BW1165 -> 1268 | BF8: ='ONS - UK Exports by type'!BX1165 -> 7238 | BG8: ='ONS - UK Exports by type'!BY1165+'ONS - UK Exports by type'!BZ1165 -> 14 | BH8: ='ONS - UK Exports by type'!CA1165 -> 1925 | BI8: ='ONS - UK Exports by type'!CB1165 -> 242 | BJ8: ='ONS - UK Exports by type'!CC1165+'ONS - UK Exports by type'!CD1165+'ONS - UK Exports by type'!CE1165 -> 110 | BK8: ='ONS - UK Exports by type'!CF1165+'ONS - UK Exports by type'!CG1165+'ONS - UK Exports by type'!CH1165 -> 464 | BL8: ='ONS - UK Exports by type'!CI1165 -> 68 | BM8: ='ONS - UK Exports by type'!CJ1165 -> 501 | BN8: ='ONS - UK Exports by type'!CK1165 -> 55 | BO8: ='ONS - UK Exports by type'!CL1165+'ONS - UK Exports by type'!CK1165+'ONS - UK Exports by type'!CM1165 -> 350 | BP8: ='ONS - UK Exports by type'!CO1165+'ONS - UK Exports by type'!CP1165+'ONS - UK Exports by type'!CQ1165 -> 324 | BQ8: ='ONS - UK Exports by type'!CR1165 -> 1925 | BR8: ='ONS - UK Exports by type'!CS1165 -> 326 | BS8: ='ONS - UK Exports by type'!CT1165+'ONS - UK Exports by type'!CU1165+'ONS - UK Exports by type'!CV1165 -> 2021 | BT8: ='ONS - UK Exports by type'!CW1165 -> 295 | BW8: =100*((DataQ!D212/DataQ!D208)-1) -> 0.70451165 | BX8: =100*((DataQ!K212/DataQ!K208)-1) -> 0.70451165 | BY8: 0 | CA8: =100*((DataQ!K212/DataQ!D212)-1) -> 0 | CD8: =100*((DataQ!E212/DataQ!E208)-1) -> 2.1108336 | CE8: =100*((DataQ!L212/DataQ!L208)-1) -> 2.1108336 | CG8: =100*((DataQ!L212/DataQ!E212)-1) -> 0 | CJ8: =100*((DataQ!F212/DataQ!F208)-1) -> -2.8735165 | CK8: =100*((DataQ!M212/DataQ!M208)-1) -> -2.8735165 | CM8: =100*((DataQ!M212/DataQ!F212)-1) -> 0 | CP8: =DataQ!J212 -> 1.261867 | CQ8: =DataQ!Q212 -> 1.261867 | CS8: =100*((DataQ!Q212/DataQ!J212)-1) -> 0 | CZ8: =SUM(CZ3:CZ7) -> 863219 | DA8: =SUM(DA3:DA7) -> 863219 | DB8: =SUM(DB3:DB7) -> 861102 | DC8: =SUM(DC3:DC7) -> 852814 | DD8: ='ONS Pink Book - 9.3'!AA94 -> 861234
A9: 2023 | B9: ='ONS - UK Exports by type'!D1401 -> 60432 | C9: ='ONS - UK Exports by type'!E1401 -> 41 | D9: ='ONS - UK Exports by type'!F1401 -> 33 | E9: ='ONS - UK Exports by type'!G1401 -> 99 | F9: ='ONS - UK Exports by type'!H1401 -> 245 | G9: ='ONS - UK Exports by type'!I1401 -> 137 | H9: ='ONS - UK Exports by type'!J1401 -> 30 | I9: ='ONS - UK Exports by type'!K1401 -> 10 | ... AV9: ='ONS - UK Exports by type'!AX1401 -> 931 | AW9: ='ONS - UK Exports by type'!AY1401+'ONS - UK Exports by type'!AZ1401 -> 296 | AX9: ='ONS - UK Exports by type'!BA1401+'ONS - UK Exports by type'!BB1401+'ONS - UK Exports by type'!BC1401 -> 6077 | AY9: ='ONS - UK Exports by type'!BD1401+'ONS - UK Exports by type'!BE1401+'ONS - UK Exports by type'!BF1401 -> 2495 | AZ9: ='ONS - UK Exports by type'!BG1401+'ONS - UK Exports by type'!BH1401 -> 203 | BA9: ='ONS - UK Exports by type'!BI1401+'ONS - UK Exports by type'!BJ1401+'ONS - UK Exports by type'!BK1401 -> 3842 | BB9: ='ONS - UK Exports by type'!BL1401+'ONS - UK Exports by type'!BK1401+'ONS - UK Exports by type'!BM1401 -> 2481 | BC9: ='ONS - UK Exports by type'!BO1401+'ONS - UK Exports by type'!BP1401+'ONS - UK Exports by type'!BQ1401 -> 968 | BD9: ='ONS - UK Exports by type'!BR1401+'ONS - UK Exports by type'!BS1401+'ONS - UK Exports by type'!BT1401 -> 2558 | BE9: ='ONS - UK Exports by type'!BU1401+'ONS - UK Exports by type'!BV1401+'ONS - UK Exports by type'!BW1401 -> 1333 | BF9: ='ONS - UK Exports by type'!BX1401 -> 6435 | BG9: ='ONS - UK Exports by type'!BY1401+'ONS - UK Exports by type'!BZ1401 -> 7 | BH9: ='ONS - UK Exports by type'!CA1401 -> 2117 | BI9: ='ONS - UK Exports by type'!CB1401 -> 290 | BJ9: ='ONS - UK Exports by type'!CC1401+'ONS - UK Exports by type'!CD1401+'ONS - UK Exports by type'!CE1401 -> 109 | BK9: ='ONS - UK Exports by type'!CF1401+'ONS - UK Exports by type'!CG1401+'ONS - UK Exports by type'!CH1401 -> 531 | BL9: ='ONS - UK Exports by type'!CI1401 -> 56 | BM9: ='ONS - UK Exports by type'!CJ1401 -> 409 | BN9: ='ONS - UK Exports by type'!CK1401 -> 54 | BO9: ='ONS - UK Exports by type'!CL1401+'ONS - UK Exports by type'!CK1401+'ONS - UK Exports by type'!CM1401 -> 396 | BP9: ='ONS - UK Exports by type'!CO1401+'ONS - UK Exports by type'!CP1401+'ONS - UK Exports by type'!CQ1401 -> 336 | BQ9: ='ONS - UK Exports by type'!CR1401 -> 1482 | BR9: ='ONS - UK Exports by type'!CS1401 -> 277 | BS9: ='ONS - UK Exports by type'!CT1401+'ONS - UK Exports by type'!CU1401+'ONS - UK Exports by type'!CV1401 -> 2012 | BT9: ='ONS - UK Exports by type'!CW1401 -> 1206 | BW9: =100*((DataQ!D213/DataQ!D209)-1) -> 1.0703897 | BX9: =100*((DataQ!K213/DataQ!K209)-1) -> 1.0703897 | BY9: 0 | CA9: =100*((DataQ!K213/DataQ!D213)-1) -> 0 | CD9: =100*((DataQ!E213/DataQ!E209)-1) -> 2.0547945 | CE9: =100*((DataQ!L213/DataQ!L209)-1) -> 2.0547945 | CG9: =100*((DataQ!L213/DataQ!E213)-1) -> 0 | CJ9: =100*((DataQ!F213/DataQ!F209)-1) -> 0.73738076 | CK9: =100*((DataQ!M213/DataQ!M209)-1) -> 0.73738076 | CM9: =100*((DataQ!M213/DataQ!F213)-1) -> 0 | CP9: =DataQ!J213 -> 1.300467 | CQ9: =DataQ!Q213 -> 1.300467 | CS9: =100*((DataQ!Q213/DataQ!J213)-1) -> 0
BW10: =100*((DataQ!D214/DataQ!D210)-1) -> 1.9092154 | BX10: =100*((DataQ!K214/DataQ!K210)-1) -> 1.9101967 | BY10: 0 | CA10: =100*((DataQ!K214/DataQ!D214)-1) -> 0.00096290053 | CD10: =100*((DataQ!E214/DataQ!E210)-1) -> 2.4228082 | CE10: =100*((DataQ!L214/DataQ!L210)-1) -> 2.427279 | CG10: =100*((DataQ!L214/DataQ!E214)-1) -> 0.0043650676 | CJ10: =100*((DataQ!F214/DataQ!F210)-1) -> 1.7531388 | CK10: =100*((DataQ!M214/DataQ!M210)-1) -> 1.7640714 | CM10: =100*((DataQ!M214/DataQ!F214)-1) -> 0.01074416 | CP10: =DataQ!J214 -> 1.303542 | CQ10: =DataQ!Q214 -> 1.303544 | CS10: =100*((DataQ!Q214/DataQ!J214)-1) -> 0.00015342812 | CX10: Exports to US - sector-specific tariffs | CY10: =100*(CZ10/$CZ$8) -> 0 | CZ10: 0 | DC10: =((CY13+CY14)/$CZ$23)*$DD$4 -> 8420 | DE10: =CY10/SUM($CY$3:$CY$4) -> 0
A11: Imports | BV11: 2025 | BW11: =100*((DataQ!D215/DataQ!D211)-1) -> 1.5549918 | BX11: =100*((DataQ!K215/DataQ!K211)-1) -> 1.5514239 | BY11: 0 | CA11: =100*((DataQ!K215/DataQ!D215)-1) -> -0.0035133054 | CC11: 2025 | CD11: =100*((DataQ!E215/DataQ!E211)-1) -> 2.4920105 | CE11: =100*((DataQ!L215/DataQ!L211)-1) -> 2.5084923 | CG11: =100*((DataQ!L215/DataQ!E215)-1) -> 0.016081108 | CI11: 2025 | CJ11: =100*((DataQ!F215/DataQ!F211)-1) -> 3.2832407 | CK11: =100*((DataQ!M215/DataQ!M211)-1) -> 3.2933509 | CM11: =100*((DataQ!M215/DataQ!F215)-1) -> 0.0097887437 | CO11: 2025 | CP11: =DataQ!J215 -> 1.272145 | CQ11: =DataQ!Q215 -> 1.272144 | CS11: =100*((DataQ!Q215/DataQ!J215)-1) -> -7.8607391e-05
A12: 2018 | B12: ='ONS - UK Imports by type'!D221 -> 41613 | C12: ='ONS - UK Imports by type'!E221 -> 40 | D12: ='ONS - UK Imports by type'!F221 -> 7 | E12: ='ONS - UK Imports by type'!G221 -> 23 | F12: ='ONS - UK Imports by type'!H221 -> 67 | G12: ='ONS - UK Imports by type'!I221 -> 84 | H12: ='ONS - UK Imports by type'!J221 -> 345 | I12: ='ONS - UK Imports by type'!K221 -> 26 | ... AV12: ='ONS - UK Imports by type'!AX221 -> 1021 | AW12: ='ONS - UK Imports by type'!AY221+'ONS - UK Imports by type'!AZ221 -> 265 | AX12: ='ONS - UK Imports by type'!BA221+'ONS - UK Imports by type'!BB221+'ONS - UK Imports by type'!BC221 -> 6298 | AY12: ='ONS - UK Imports by type'!BD221+'ONS - UK Imports by type'!BE221+'ONS - UK Imports by type'!BF221 -> 746 | AZ12: ='ONS - UK Imports by type'!BG221+'ONS - UK Imports by type'!BH221 -> 120 | BA12: ='ONS - UK Imports by type'!BI221+'ONS - UK Imports by type'!BJ221+'ONS - UK Imports by type'!BK221 -> 2364 | BB12: ='ONS - UK Imports by type'!BL221+'ONS - UK Imports by type'!BK221+'ONS - UK Imports by type'!BM221 -> 1371 | BC12: ='ONS - UK Imports by type'!BO221+'ONS - UK Imports by type'!BP221+'ONS - UK Imports by type'!BQ221 -> 1280 | BD12: ='ONS - UK Imports by type'!BR221+'ONS - UK Imports by type'!BS221+'ONS - UK Imports by type'!BT221 -> 2456 | BE12: ='ONS - UK Imports by type'!BU221+'ONS - UK Imports by type'!BV221+'ONS - UK Imports by type'!BW221 -> 607 | BF12: ='ONS - UK Imports by type'!BX221 -> 109 | BG12: ='ONS - UK Imports by type'!BY221+'ONS - UK Imports by type'!BZ221 -> 7 | BH12: ='ONS - UK Imports by type'!CA221 -> 2614 | BI12: ='ONS - UK Imports by type'!CB221 -> 63 | BJ12: ='ONS - UK Imports by type'!CC221+'ONS - UK Imports by type'!CD221+'ONS - UK Imports by type'!CE221 -> 51 | BK12: ='ONS - UK Imports by type'!CF221+'ONS - UK Imports by type'!CG221+'ONS - UK Imports by type'!CH221 -> 362 | BL12: ='ONS - UK Imports by type'!CI221 -> 32 | BM12: ='ONS - UK Imports by type'!CJ221 -> 355 | BN12: ='ONS - UK Imports by type'!CK221 -> 28 | BO12: ='ONS - UK Imports by type'!CL221+'ONS - UK Imports by type'!CK221+'ONS - UK Imports by type'!CM221 -> 263 | BP12: ='ONS - UK Imports by type'!CO221+'ONS - UK Imports by type'!CP221+'ONS - UK Imports by type'!CQ221 -> 239 | BQ12: ='ONS - UK Imports by type'!CR221 -> 1321 | BR12: ='ONS - UK Imports by type'!CS221 -> 175 | BS12: ='ONS - UK Imports by type'!CT221+'ONS - UK Imports by type'!CU221+'ONS - UK Imports by type'!CV221 -> 1616 | BT12: ='ONS - UK Imports by type'!CW221 -> 1651 | BW12: =100*((DataQ!D216/DataQ!D212)-1) -> 1.4791854 | BX12: =100*((DataQ!K216/DataQ!K212)-1) -> 1.4683107 | BY12: 0 | CA12: =100*((DataQ!K216/DataQ!D216)-1) -> -0.01071624 | CD12: =100*((DataQ!E216/DataQ!E212)-1) -> 2.3163891 | CE12: =100*((DataQ!L216/DataQ!L212)-1) -> 2.3495647 | CG12: =100*((DataQ!L216/DataQ!E216)-1) -> 0.032424522 | CJ12: =100*((DataQ!F216/DataQ!F212)-1) -> 4.0953895 | CK12: =100*((DataQ!M216/DataQ!M212)-1) -> 4.1028695 | CM12: =100*((DataQ!M216/DataQ!F216)-1) -> 0.0071857012 | CP12: =DataQ!J216 -> 1.275929 | CQ12: =DataQ!Q216 -> 1.275929 | CS12: =100*((DataQ!Q216/DataQ!J216)-1) -> 0 | CX12: =CX10 -> Exports to US - sector-specific tariffs
A13: 2019 | B13: ='ONS - UK Imports by type'!D457 -> 46839 | C13: ='ONS - UK Imports by type'!E457 -> 26 | D13: ='ONS - UK Imports by type'!F457 -> 6 | E13: ='ONS - UK Imports by type'!G457 -> 20 | F13: ='ONS - UK Imports by type'!H457 -> 71 | G13: ='ONS - UK Imports by type'!I457 -> 64 | H13: ='ONS - UK Imports by type'!J457 -> 339 | I13: ='ONS - UK Imports by type'!K457 -> 28 | ... AV13: ='ONS - UK Imports by type'!AX457 -> 1079 | AW13: ='ONS - UK Imports by type'!AY457+'ONS - UK Imports by type'!AZ457 -> 289 | AX13: ='ONS - UK Imports by type'!BA457+'ONS - UK Imports by type'!BB457+'ONS - UK Imports by type'!BC457 -> 7067 | AY13: ='ONS - UK Imports by type'!BD457+'ONS - UK Imports by type'!BE457+'ONS - UK Imports by type'!BF457 -> 731 | AZ13: ='ONS - UK Imports by type'!BG457+'ONS - UK Imports by type'!BH457 -> 124 | BA13: ='ONS - UK Imports by type'!BI457+'ONS - UK Imports by type'!BJ457+'ONS - UK Imports by type'!BK457 -> 2621 | BB13: ='ONS - UK Imports by type'!BL457+'ONS - UK Imports by type'!BK457+'ONS - UK Imports by type'!BM457 -> 1466 | BC13: ='ONS - UK Imports by type'!BO457+'ONS - UK Imports by type'!BP457+'ONS - UK Imports by type'!BQ457 -> 1343 | BD13: ='ONS - UK Imports by type'!BR457+'ONS - UK Imports by type'!BS457+'ONS - UK Imports by type'!BT457 -> 2731 | BE13: ='ONS - UK Imports by type'!BU457+'ONS - UK Imports by type'!BV457+'ONS - UK Imports by type'!BW457 -> 643 | BF13: ='ONS - UK Imports by type'!BX457 -> 122 | BG13: ='ONS - UK Imports by type'!BY457+'ONS - UK Imports by type'!BZ457 -> 8 | BH13: ='ONS - UK Imports by type'!CA457 -> 2176 | BI13: ='ONS - UK Imports by type'!CB457 -> 41 | BJ13: ='ONS - UK Imports by type'!CC457+'ONS - UK Imports by type'!CD457+'ONS - UK Imports by type'!CE457 -> 64 | BK13: ='ONS - UK Imports by type'!CF457+'ONS - UK Imports by type'!CG457+'ONS - UK Imports by type'!CH457 -> 388 | BL13: ='ONS - UK Imports by type'!CI457 -> 31 | BM13: ='ONS - UK Imports by type'!CJ457 -> 340 | BN13: ='ONS - UK Imports by type'!CK457 -> 30 | BO13: ='ONS - UK Imports by type'!CL457+'ONS - UK Imports by type'!CK457+'ONS - UK Imports by type'!CM457 -> 277 | BP13: ='ONS - UK Imports by type'!CO457+'ONS - UK Imports by type'!CP457+'ONS - UK Imports by type'!CQ457 -> 251 | BQ13: ='ONS - UK Imports by type'!CR457 -> 1350 | BR13: ='ONS - UK Imports by type'!CS457 -> 208 | BS13: ='ONS - UK Imports by type'!CT457+'ONS - UK Imports by type'!CU457+'ONS - UK Imports by type'!CV457 -> 1699 | BT13: ='ONS - UK Imports by type'!CW457 -> 4210 | BW13: =100*((DataQ!D217/DataQ!D213)-1) -> 1.6055609 | BX13: =100*((DataQ!K217/DataQ!K213)-1) -> 1.5896575 | BY13: 0 | CA13: =100*((DataQ!K217/DataQ!D217)-1) -> -0.015652137 | CD13: =100*((DataQ!E217/DataQ!E213)-1) -> 2.7128262 | CE13: =100*((DataQ!L217/DataQ!L213)-1) -> 2.7604773 | CG13: =100*((DataQ!L217/DataQ!E217)-1) -> 0.04639246 | CJ13: =100*((DataQ!F217/DataQ!F213)-1) -> 2.6564633 | CK13: =100*((DataQ!M217/DataQ!M213)-1) -> 2.6645272 | CM13: =100*((DataQ!M217/DataQ!F217)-1) -> 0.0078552637 | CP13: =DataQ!J217 -> 1.279734 | CQ13: =DataQ!Q217 -> 1.279739 | CS13: =100*((DataQ!Q217/DataQ!J217)-1) -> 0.00039070619 | CX13: Steel/aluminium | CY13: ='ONS - UK Exports by type'!AV1401+'ONS - UK Exports by type'!AW1401 -> 1985
A14: 2020 | B14: ='ONS - UK Imports by type'!D693 -> 37577 | C14: ='ONS - UK Imports by type'!E693 -> 8 | D14: ='ONS - UK Imports by type'!F693 -> 6 | E14: ='ONS - UK Imports by type'!G693 -> 23 | F14: ='ONS - UK Imports by type'!H693 -> 74 | G14: ='ONS - UK Imports by type'!I693 -> 66 | H14: ='ONS - UK Imports by type'!J693 -> 326 | I14: ='ONS - UK Imports by type'!K693 -> 34 | ... AV14: ='ONS - UK Imports by type'!AX693 -> 864 | AW14: ='ONS - UK Imports by type'!AY693+'ONS - UK Imports by type'!AZ693 -> 238 | AX14: ='ONS - UK Imports by type'!BA693+'ONS - UK Imports by type'!BB693+'ONS - UK Imports by type'!BC693 -> 4931 | AY14: ='ONS - UK Imports by type'!BD693+'ONS - UK Imports by type'!BE693+'ONS - UK Imports by type'!BF693 -> 704 | AZ14: ='ONS - UK Imports by type'!BG693+'ONS - UK Imports by type'!BH693 -> 92 | BA14: ='ONS - UK Imports by type'!BI693+'ONS - UK Imports by type'!BJ693+'ONS - UK Imports by type'!BK693 -> 1998 | BB14: ='ONS - UK Imports by type'!BL693+'ONS - UK Imports by type'!BK693+'ONS - UK Imports by type'!BM693 -> 1181 | BC14: ='ONS - UK Imports by type'!BO693+'ONS - UK Imports by type'!BP693+'ONS - UK Imports by type'!BQ693 -> 1153 | BD14: ='ONS - UK Imports by type'!BR693+'ONS - UK Imports by type'!BS693+'ONS - UK Imports by type'!BT693 -> 2146 | BE14: ='ONS - UK Imports by type'!BU693+'ONS - UK Imports by type'!BV693+'ONS - UK Imports by type'!BW693 -> 430 | BF14: ='ONS - UK Imports by type'!BX693 -> 60 | BG14: ='ONS - UK Imports by type'!BY693+'ONS - UK Imports by type'!BZ693 -> 9 | BH14: ='ONS - UK Imports by type'!CA693 -> 1733 | BI14: ='ONS - UK Imports by type'!CB693 -> 107 | BJ14: ='ONS - UK Imports by type'!CC693+'ONS - UK Imports by type'!CD693+'ONS - UK Imports by type'!CE693 -> 48 | BK14: ='ONS - UK Imports by type'!CF693+'ONS - UK Imports by type'!CG693+'ONS - UK Imports by type'!CH693 -> 281 | BL14: ='ONS - UK Imports by type'!CI693 -> 22 | BM14: ='ONS - UK Imports by type'!CJ693 -> 292 | BN14: ='ONS - UK Imports by type'!CK693 -> 23 | BO14: ='ONS - UK Imports by type'!CL693+'ONS - UK Imports by type'!CK693+'ONS - UK Imports by type'!CM693 -> 207 | BP14: ='ONS - UK Imports by type'!CO693+'ONS - UK Imports by type'!CP693+'ONS - UK Imports by type'!CQ693 -> 248 | BQ14: ='ONS - UK Imports by type'!CR693 -> 824 | BR14: ='ONS - UK Imports by type'!CS693 -> 168 | BS14: ='ONS - UK Imports by type'!CT693+'ONS - UK Imports by type'!CU693+'ONS - UK Imports by type'!CV693 -> 1476 | BT14: ='ONS - UK Imports by type'!CW693 -> 1781 | BW14: =100*((DataQ!D218/DataQ!D214)-1) -> 1.5139437 | BX14: =100*((DataQ!K218/DataQ!K214)-1) -> 1.4992062 | BY14: 0 | CA14: =100*((DataQ!K218/DataQ!D218)-1) -> -0.013554945 | CD14: =100*((DataQ!E218/DataQ!E214)-1) -> 2.5821964 | CE14: =100*((DataQ!L218/DataQ!L214)-1) -> 2.6645725 | CG14: =100*((DataQ!L218/DataQ!E218)-1) -> 0.084671074 | CJ14: =100*((DataQ!F218/DataQ!F214)-1) -> 2.0264918 | CK14: =100*((DataQ!M218/DataQ!M214)-1) -> 2.0449908 | CM14: =100*((DataQ!M218/DataQ!F218)-1) -> 0.02887767 | CP14: =DataQ!J218 -> 1.283582 | CQ14: =DataQ!Q218 -> 1.276834 | CS14: =100*((DataQ!Q218/DataQ!J218)-1) -> -0.52571632 | CX14: Cars & car parts | CY14: ='ONS - UK Exports by type'!BX1401 -> 6435 | CZ14: =100*(((CY13+CY14)/'ONS - UK Exports by type'!D1423)*(1-CY7/100)) -> 0.98033903
A15: 2021 | B15: ='ONS - UK Imports by type'!D929 -> 39247 | C15: ='ONS - UK Imports by type'!E929 -> 11 | D15: ='ONS - UK Imports by type'!F929 -> 9 | E15: ='ONS - UK Imports by type'!G929 -> 23 | F15: ='ONS - UK Imports by type'!H929 -> 46 | G15: ='ONS - UK Imports by type'!I929 -> 50 | H15: ='ONS - UK Imports by type'!J929 -> 268 | I15: ='ONS - UK Imports by type'!K929 -> 39 | ... AV15: ='ONS - UK Imports by type'!AX929 -> 766 | AW15: ='ONS - UK Imports by type'!AY929+'ONS - UK Imports by type'!AZ929 -> 220 | AX15: ='ONS - UK Imports by type'!BA929+'ONS - UK Imports by type'!BB929+'ONS - UK Imports by type'!BC929 -> 3615 | AY15: ='ONS - UK Imports by type'!BD929+'ONS - UK Imports by type'!BE929+'ONS - UK Imports by type'!BF929 -> 618 | AZ15: ='ONS - UK Imports by type'!BG929+'ONS - UK Imports by type'!BH929 -> 129 | BA15: ='ONS - UK Imports by type'!BI929+'ONS - UK Imports by type'!BJ929+'ONS - UK Imports by type'!BK929 -> 1953 | BB15: ='ONS - UK Imports by type'!BL929+'ONS - UK Imports by type'!BK929+'ONS - UK Imports by type'!BM929 -> 1246 | BC15: ='ONS - UK Imports by type'!BO929+'ONS - UK Imports by type'!BP929+'ONS - UK Imports by type'!BQ929 -> 1145 | BD15: ='ONS - UK Imports by type'!BR929+'ONS - UK Imports by type'!BS929+'ONS - UK Imports by type'!BT929 -> 2070 | BE15: ='ONS - UK Imports by type'!BU929+'ONS - UK Imports by type'!BV929+'ONS - UK Imports by type'!BW929 -> 375 | BF15: ='ONS - UK Imports by type'!BX929 -> 138 | BG15: ='ONS - UK Imports by type'!BY929+'ONS - UK Imports by type'!BZ929 -> 8 | BH15: ='ONS - UK Imports by type'!CA929 -> 1663 | BI15: ='ONS - UK Imports by type'!CB929 -> 35 | BJ15: ='ONS - UK Imports by type'!CC929+'ONS - UK Imports by type'!CD929+'ONS - UK Imports by type'!CE929 -> 48 | BK15: ='ONS - UK Imports by type'!CF929+'ONS - UK Imports by type'!CG929+'ONS - UK Imports by type'!CH929 -> 260 | BL15: ='ONS - UK Imports by type'!CI929 -> 21 | BM15: ='ONS - UK Imports by type'!CJ929 -> 222 | BN15: ='ONS - UK Imports by type'!CK929 -> 20 | BO15: ='ONS - UK Imports by type'!CL929+'ONS - UK Imports by type'!CK929+'ONS - UK Imports by type'!CM929 -> 204 | BP15: ='ONS - UK Imports by type'!CO929+'ONS - UK Imports by type'!CP929+'ONS - UK Imports by type'!CQ929 -> 212 | BQ15: ='ONS - UK Imports by type'!CR929 -> 646 | BR15: ='ONS - UK Imports by type'!CS929 -> 198 | BS15: ='ONS - UK Imports by type'!CT929+'ONS - UK Imports by type'!CU929+'ONS - UK Imports by type'!CV929 -> 1668 | BT15: ='ONS - UK Imports by type'!CW929 -> 2492 | BV15: 2026 | BW15: =100*((DataQ!D219/DataQ!D215)-1) -> 1.5938953 | BX15: =100*((DataQ!K219/DataQ!K215)-1) -> 1.5591576 | BY15: 0 | CA15: =100*((DataQ!K219/DataQ!D219)-1) -> -0.037704886 | CC15: 2026 | CD15: =100*((DataQ!E219/DataQ!E215)-1) -> 2.5346924 | CE15: =100*((DataQ!L219/DataQ!L215)-1) -> 2.6753776 | CG15: =100*((DataQ!L219/DataQ!E219)-1) -> 0.15331057 | CI15: 2026 | CJ15: =100*((DataQ!F219/DataQ!F215)-1) -> 2.0454198 | CK15: =100*((DataQ!M219/DataQ!M215)-1) -> 2.0685487 | CM15: =100*((DataQ!M219/DataQ!F219)-1) -> 0.032456299 | CO15: 2026 | CP15: =DataQ!J219 -> 1.287893 | CQ15: =DataQ!Q219 -> 1.26948 | CS15: =100*((DataQ!Q219/DataQ!J219)-1) -> -1.4296995
A16: 2022 | B16: ='ONS - UK Imports by type'!D1165 -> 61892 | C16: ='ONS - UK Imports by type'!E1165 -> 39 | D16: ='ONS - UK Imports by type'!F1165 -> 5 | E16: ='ONS - UK Imports by type'!G1165 -> 14 | F16: ='ONS - UK Imports by type'!H1165 -> 40 | G16: ='ONS - UK Imports by type'!I1165 -> 78 | H16: ='ONS - UK Imports by type'!J1165 -> 279 | I16: ='ONS - UK Imports by type'!K1165 -> 41 | ... AV16: ='ONS - UK Imports by type'!AX1165 -> 919 | AW16: ='ONS - UK Imports by type'!AY1165+'ONS - UK Imports by type'!AZ1165 -> 252 | AX16: ='ONS - UK Imports by type'!BA1165+'ONS - UK Imports by type'!BB1165+'ONS - UK Imports by type'!BC1165 -> 4946 | AY16: ='ONS - UK Imports by type'!BD1165+'ONS - UK Imports by type'!BE1165+'ONS - UK Imports by type'!BF1165 -> 672 | AZ16: ='ONS - UK Imports by type'!BG1165+'ONS - UK Imports by type'!BH1165 -> 122 | BA16: ='ONS - UK Imports by type'!BI1165+'ONS - UK Imports by type'!BJ1165+'ONS - UK Imports by type'!BK1165 -> 2478 | BB16: ='ONS - UK Imports by type'!BL1165+'ONS - UK Imports by type'!BK1165+'ONS - UK Imports by type'!BM1165 -> 1456 | BC16: ='ONS - UK Imports by type'!BO1165+'ONS - UK Imports by type'!BP1165+'ONS - UK Imports by type'!BQ1165 -> 1470 | BD16: ='ONS - UK Imports by type'!BR1165+'ONS - UK Imports by type'!BS1165+'ONS - UK Imports by type'!BT1165 -> 2580 | BE16: ='ONS - UK Imports by type'!BU1165+'ONS - UK Imports by type'!BV1165+'ONS - UK Imports by type'!BW1165 -> 336 | BF16: ='ONS - UK Imports by type'!BX1165 -> 230 | BG16: ='ONS - UK Imports by type'!BY1165+'ONS - UK Imports by type'!BZ1165 -> 18 | BH16: ='ONS - UK Imports by type'!CA1165 -> 2703 | BI16: ='ONS - UK Imports by type'!CB1165 -> 43 | BJ16: ='ONS - UK Imports by type'!CC1165+'ONS - UK Imports by type'!CD1165+'ONS - UK Imports by type'!CE1165 -> 56 | BK16: ='ONS - UK Imports by type'!CF1165+'ONS - UK Imports by type'!CG1165+'ONS - UK Imports by type'!CH1165 -> 248 | BL16: ='ONS - UK Imports by type'!CI1165 -> 31 | BM16: ='ONS - UK Imports by type'!CJ1165 -> 245 | BN16: ='ONS - UK Imports by type'!CK1165 -> 27 | BO16: ='ONS - UK Imports by type'!CL1165+'ONS - UK Imports by type'!CK1165+'ONS - UK Imports by type'!CM1165 -> 279 | BP16: ='ONS - UK Imports by type'!CO1165+'ONS - UK Imports by type'!CP1165+'ONS - UK Imports by type'!CQ1165 -> 206 | BQ16: ='ONS - UK Imports by type'!CR1165 -> 866 | BR16: ='ONS - UK Imports by type'!CS1165 -> 272 | BS16: ='ONS - UK Imports by type'!CT1165+'ONS - UK Imports by type'!CU1165+'ONS - UK Imports by type'!CV1165 -> 1673 | BT16: ='ONS - UK Imports by type'!CW1165 -> 1825 | BW16: =100*((DataQ!D220/DataQ!D216)-1) -> 1.6329545 | BX16: =100*((DataQ!K220/DataQ!K216)-1) -> 1.5737906 | BY16: 0 | CA16: =100*((DataQ!K220/DataQ!D220)-1) -> -0.068923257 | CD16: =100*((DataQ!E220/DataQ!E216)-1) -> 2.4845655 | CE16: =100*((DataQ!L220/DataQ!L216)-1) -> 2.6578029 | CG16: =100*((DataQ!L220/DataQ!E220)-1) -> 0.20151694 | CJ16: =100*((DataQ!F220/DataQ!F216)-1) -> 2.0323243 | CK16: =100*((DataQ!M220/DataQ!M216)-1) -> 2.0537811 | CM16: =100*((DataQ!M220/DataQ!F220)-1) -> 0.028216626 | CP16: =DataQ!J220 -> 1.29213 | CQ16: =DataQ!Q220 -> 1.262606 | CS16: =100*((DataQ!Q220/DataQ!J220)-1) -> -2.2849094 | CX16: =CX4 -> Exports to US - goods currently exempt
A17: 2023 | B17: ='ONS - UK Imports by type'!D1401 -> 57948 | C17: ='ONS - UK Imports by type'!E1401 -> 10 | D17: ='ONS - UK Imports by type'!F1401 -> 4 | E17: ='ONS - UK Imports by type'!G1401 -> 18 | F17: ='ONS - UK Imports by type'!H1401 -> 31 | G17: ='ONS - UK Imports by type'!I1401 -> 67 | H17: ='ONS - UK Imports by type'!J1401 -> 245 | I17: ='ONS - UK Imports by type'!K1401 -> 46 | ... AV17: ='ONS - UK Imports by type'!AX1401 -> 1093 | AW17: ='ONS - UK Imports by type'!AY1401+'ONS - UK Imports by type'!AZ1401 -> 328 | AX17: ='ONS - UK Imports by type'!BA1401+'ONS - UK Imports by type'!BB1401+'ONS - UK Imports by type'!BC1401 -> 5729 | AY17: ='ONS - UK Imports by type'!BD1401+'ONS - UK Imports by type'!BE1401+'ONS - UK Imports by type'!BF1401 -> 676 | AZ17: ='ONS - UK Imports by type'!BG1401+'ONS - UK Imports by type'!BH1401 -> 147 | BA17: ='ONS - UK Imports by type'!BI1401+'ONS - UK Imports by type'!BJ1401+'ONS - UK Imports by type'!BK1401 -> 2629 | BB17: ='ONS - UK Imports by type'!BL1401+'ONS - UK Imports by type'!BK1401+'ONS - UK Imports by type'!BM1401 -> 1415 | BC17: ='ONS - UK Imports by type'!BO1401+'ONS - UK Imports by type'!BP1401+'ONS - UK Imports by type'!BQ1401 -> 1874 | BD17: ='ONS - UK Imports by type'!BR1401+'ONS - UK Imports by type'!BS1401+'ONS - UK Imports by type'!BT1401 -> 2973 | BE17: ='ONS - UK Imports by type'!BU1401+'ONS - UK Imports by type'!BV1401+'ONS - UK Imports by type'!BW1401 -> 307 | BF17: ='ONS - UK Imports by type'!BX1401 -> 821 | BG17: ='ONS - UK Imports by type'!BY1401+'ONS - UK Imports by type'!BZ1401 -> 34 | BH17: ='ONS - UK Imports by type'!CA1401 -> 3118 | BI17: ='ONS - UK Imports by type'!CB1401 -> 125 | BJ17: ='ONS - UK Imports by type'!CC1401+'ONS - UK Imports by type'!CD1401+'ONS - UK Imports by type'!CE1401 -> 57 | BK17: ='ONS - UK Imports by type'!CF1401+'ONS - UK Imports by type'!CG1401+'ONS - UK Imports by type'!CH1401 -> 249 | BL17: ='ONS - UK Imports by type'!CI1401 -> 38 | BM17: ='ONS - UK Imports by type'!CJ1401 -> 228 | BN17: ='ONS - UK Imports by type'!CK1401 -> 26 | BO17: ='ONS - UK Imports by type'!CL1401+'ONS - UK Imports by type'!CK1401+'ONS - UK Imports by type'!CM1401 -> 323 | BP17: ='ONS - UK Imports by type'!CO1401+'ONS - UK Imports by type'!CP1401+'ONS - UK Imports by type'!CQ1401 -> 183 | BQ17: ='ONS - UK Imports by type'!CR1401 -> 526 | BR17: ='ONS - UK Imports by type'!CS1401 -> 199 | BS17: ='ONS - UK Imports by type'!CT1401+'ONS - UK Imports by type'!CU1401+'ONS - UK Imports by type'!CV1401 -> 1426 | BT17: ='ONS - UK Imports by type'!CW1401 -> 244 | BW17: =100*((DataQ!D221/DataQ!D217)-1) -> 1.6810457 | BX17: =100*((DataQ!K221/DataQ!K217)-1) -> 1.588933 | BY17: 0 | CA17: =100*((DataQ!K221/DataQ!D221)-1) -> -0.10622783 | CD17: =100*((DataQ!E221/DataQ!E217)-1) -> 2.4281625 | CE17: =100*((DataQ!L221/DataQ!L217)-1) -> 2.5469914 | CG17: =100*((DataQ!L221/DataQ!E221)-1) -> 0.16245825 | CJ17: =100*((DataQ!F221/DataQ!F217)-1) -> 2.0035156 | CK17: =100*((DataQ!M221/DataQ!M217)-1) -> 1.987743 | CM17: =100*((DataQ!M221/DataQ!F221)-1) -> -0.0076087463 | CP17: =DataQ!J221 -> 1.296342 | CQ17: =DataQ!Q221 -> 1.267093 | CS17: =100*((DataQ!Q221/DataQ!J221)-1) -> -2.2562719 | CX17: Copper | CY17: ='ONS - UK Exports by type'!AW1401 -> 1570
BW18: =100*((DataQ!D222/DataQ!D218)-1) -> 1.7161233 | BX18: =100*((DataQ!K222/DataQ!K218)-1) -> 1.584185 | BY18: 0 | CA18: =100*((DataQ!K222/DataQ!D222)-1) -> -0.14324967 | CD18: =100*((DataQ!E222/DataQ!E218)-1) -> 2.3596112 | CE18: =100*((DataQ!L222/DataQ!L218)-1) -> 2.368352 | CG18: =100*((DataQ!L222/DataQ!E222)-1) -> 0.093217658 | CJ18: =100*((DataQ!F222/DataQ!F218)-1) -> 1.9487513 | CK18: =100*((DataQ!M222/DataQ!M218)-1) -> 1.8591008 | CM18: =100*((DataQ!M222/DataQ!F222)-1) -> -0.059084507 | CP18: =DataQ!J222 -> 1.301524 | CQ18: =DataQ!Q222 -> 1.275095 | CS18: =100*((DataQ!Q222/DataQ!J222)-1) -> -2.0306195 | CX18: Pharma | CY18: ='ONS - UK Exports by type'!AJ1401 -> 8783
BV19: 2027 | BW19: =100*((DataQ!D223/DataQ!D219)-1) -> 1.7314998 | BX19: =100*((DataQ!K223/DataQ!K219)-1) -> 1.5741898 | BY19: 0 | CA19: =100*((DataQ!K223/DataQ!D223)-1) -> -0.19227907 | CC19: 2027 | CD19: =100*((DataQ!E223/DataQ!E219)-1) -> 2.3175004 | CE19: =100*((DataQ!L223/DataQ!L219)-1) -> 2.204695 | CG19: =100*((DataQ!L223/DataQ!E223)-1) -> 0.042891235 | CI19: 2027 | CJ19: =100*((DataQ!F223/DataQ!F219)-1) -> 1.9084025 | CK19: =100*((DataQ!M223/DataQ!M219)-1) -> 1.7557024 | CM19: =100*((DataQ!M223/DataQ!F223)-1) -> -0.11743278 | CO19: 2027 | CP19: =DataQ!J223 -> 1.307673 | CQ19: =DataQ!Q223 -> 1.283775 | CS19: =100*((DataQ!Q223/DataQ!J223)-1) -> -1.8275211 | CX19: Semiconductors | CY19: ='ONS - UK Exports by type'!AY1401+'ONS - UK Exports by type'!AZ1401+'ONS - UK Exports by type'!BR1401+'ONS - UK Exports by type'!BS1401+'ONS - UK Exports by type'!BT1401 -> 2854
C20: =RANK(C22,$C$22:$BT$22) -> 50 | D20: =RANK(D22,$C$22:$BT$22) -> 53 | E20: =RANK(E22,$C$22:$BT$22) -> 44 | F20: =RANK(F22,$C$22:$BT$22) -> 36 | G20: =RANK(G22,$C$22:$BT$22) -> 42 | H20: =RANK(H22,$C$22:$BT$22) -> 54 | I20: =RANK(I22,$C$22:$BT$22) -> 62 | J20: =RANK(J22,$C$22:$BT$22) -> 46 | ... BT20: =RANK(BT22,$C$22:$BT$22) -> 16 | BW20: =100*((DataQ!D224/DataQ!D220)-1) -> 1.7667293 | BX20: =100*((DataQ!K224/DataQ!K220)-1) -> 1.6195156 | BY20: 0 | CA20: =100*((DataQ!K224/DataQ!D224)-1) -> -0.21348151 | CD20: =100*((DataQ!E224/DataQ!E220)-1) -> 2.2369235 | CE20: =100*((DataQ!L224/DataQ!L220)-1) -> 2.0658036 | CG20: =100*((DataQ!L224/DataQ!E224)-1) -> 0.033803846 | CJ20: =100*((DataQ!F224/DataQ!F220)-1) -> 1.8597027 | CK20: =100*((DataQ!M224/DataQ!M220)-1) -> 1.6662104 | CM20: =100*((DataQ!M224/DataQ!F224)-1) -> -0.16179655 | CP20: =DataQ!J224 -> 1.313792 | CQ20: =DataQ!Q224 -> 1.292182 | CS20: =100*((DataQ!Q224/DataQ!J224)-1) -> -1.644857 | CX20: Lumber | CY20: ='ONS - UK Exports by type'!S1401+'ONS - UK Exports by type'!AR1401 -> 24
C21: =C2 -> Live animals | D21: =D2 -> Meat & meat preparations | E21: =E2 -> Dairy products & eggs | F21: =F2 -> Fish and shellfish | G21: =G2 -> Cereals | H21: =H2 -> Vegetables & fruit | I21: =I2 -> Sugar | J21: =J2 -> Coffee, tea, cocoa etc | ... BT21: =BT2 -> Unspecified goods | BW21: =100*((DataQ!D225/DataQ!D221)-1) -> 1.7717328 | BX21: =100*((DataQ!K225/DataQ!K221)-1) -> 1.6590949 | BY21: 0 | CA21: =100*((DataQ!K225/DataQ!D225)-1) -> -0.21678731 | CD21: =100*((DataQ!E225/DataQ!E221)-1) -> 2.1843263 | CE21: =100*((DataQ!L225/DataQ!L221)-1) -> 2.0747058 | CG21: =100*((DataQ!L225/DataQ!E225)-1) -> 0.05500676 | CJ21: =100*((DataQ!F225/DataQ!F221)-1) -> 1.8303877 | CK21: =100*((DataQ!M225/DataQ!M221)-1) -> 1.6347136 | CM21: =100*((DataQ!M225/DataQ!F225)-1) -> -0.19975093 | CP21: =DataQ!J225 -> 1.319877 | CQ21: =DataQ!Q225 -> 1.300337 | CS21: =100*((DataQ!Q225/DataQ!J225)-1) -> -1.480441 | CX21: Aerospace | CY21: ='ONS - UK Exports by type'!CA1401 -> 2117
C22: =C9+C23 -> 41.001 | D22: =D9+D23 -> 33.002 | E22: =E9+E23 -> 99.003 | F22: =F9+F23 -> 245.004 | G22: =G9+G23 -> 137.005 | H22: =H9+H23 -> 30.006 | I22: =I9+I23 -> 10.007 | J22: =J9+J23 -> 56.008 | ... BT22: =BT9+BT23 -> 1206.07 | BW22: =100*((DataQ!D226/DataQ!D222)-1) -> 1.7665855 | BX22: =100*((DataQ!K226/DataQ!K222)-1) -> 1.696639 | BY22: 0 | CA22: =100*((DataQ!K226/DataQ!D226)-1) -> -0.21188345 | CD22: =100*((DataQ!E226/DataQ!E222)-1) -> 2.11392 | CE22: =100*((DataQ!L226/DataQ!L222)-1) -> 2.1155414 | CG22: =100*((DataQ!L226/DataQ!E226)-1) -> 0.09480694 | CJ22: =100*((DataQ!F226/DataQ!F222)-1) -> 1.7827728 | CK22: =100*((DataQ!M226/DataQ!M222)-1) -> 1.5963626 | CM22: =100*((DataQ!M226/DataQ!F226)-1) -> -0.24212147 | CP22: =DataQ!J226 -> 1.325938 | CQ22: =DataQ!Q226 -> 1.308271 | CS22: =100*((DataQ!Q226/DataQ!J226)-1) -> -1.3324152
C23: 0.001 | D23: =C23+0.001 -> 0.002 | E23: =D23+0.001 -> 0.003 | F23: =E23+0.001 -> 0.004 | G23: =F23+0.001 -> 0.005 | H23: =G23+0.001 -> 0.006 | I23: =H23+0.001 -> 0.007 | J23: =I23+0.001 -> 0.008 | K23: =J23+0.001 -> 0.009 | ... BT23: =BS23+0.001 -> 0.07 | BV23: 2028 | BW23: =100*((DataQ!D227/DataQ!D223)-1) -> 1.7461755 | BX23: =100*((DataQ!K227/DataQ!K223)-1) -> 1.7286691 | BY23: 0 | CA23: =100*((DataQ!K227/DataQ!D227)-1) -> -0.2094519 | CC23: 2028 | CD23: =100*((DataQ!E227/DataQ!E223)-1) -> 2.13071 | CE23: =100*((DataQ!L227/DataQ!L223)-1) -> 2.2128714 | CG23: =100*((DataQ!L227/DataQ!E227)-1) -> 0.12337307 | CI23: 2028 | CJ23: =100*((DataQ!F227/DataQ!F223)-1) -> 1.7096294 | CK23: =100*((DataQ!M227/DataQ!M223)-1) -> 1.5294275 | CM23: =100*((DataQ!M227/DataQ!F227)-1) -> -0.29439764 | CO23: 2028 | CP23: =DataQ!J227 -> 1.331969 | CQ23: =DataQ!Q227 -> 1.316001 | CS23: =100*((DataQ!Q227/DataQ!J227)-1) -> -1.1988267 | CX23: Total exports to US | CZ23: ='ONS - UK Exports by type'!D1401 -> 60432
BW24: =100*((DataQ!D228/DataQ!D224)-1) -> 1.7007559 | BX24: =100*((DataQ!K228/DataQ!K224)-1) -> 1.710968 | BY24: 0 | CA24: =100*((DataQ!K228/DataQ!D228)-1) -> -0.20346163 | CD24: =100*((DataQ!E228/DataQ!E224)-1) -> 2.1394698 | CE24: =100*((DataQ!L228/DataQ!L224)-1) -> 2.2644407 | CG24: =100*((DataQ!L228/DataQ!E228)-1) -> 0.15619839 | CJ24: =100*((DataQ!F228/DataQ!F224)-1) -> 1.6509434 | CK24: =100*((DataQ!M228/DataQ!M224)-1) -> 1.455294 | CM24: =100*((DataQ!M228/DataQ!F228)-1) -> -0.35395696 | CP24: =DataQ!J228 -> 1.337969 | CQ24: =DataQ!Q228 -> 1.323535 | CS24: =100*((DataQ!Q228/DataQ!J228)-1) -> -1.0787993
C25: 1 | D25: =+C25+1 -> 2 | E25: =+D25+1 -> 3 | F25: =+E25+1 -> 4 | G25: =+F25+1 -> 5 | H25: =+G25+1 -> 6 | I25: =+H25+1 -> 7 | J25: =+I25+1 -> 8 | K25: =+J25+1 -> 9 | ... BT25: =+BS25+1 -> 70 | BW25: =100*((DataQ!D229/DataQ!D225)-1) -> 1.6754148 | BX25: =100*((DataQ!K229/DataQ!K225)-1) -> 1.6894826 | BY25: 0 | CA25: =100*((DataQ!K229/DataQ!D229)-1) -> -0.20298133 | CD25: =100*((DataQ!E229/DataQ!E225)-1) -> 2.1573332 | CE25: =100*((DataQ!L229/DataQ!L225)-1) -> 2.2963962 | CG25: =100*((DataQ!L229/DataQ!E229)-1) -> 0.19120796 | CJ25: =100*((DataQ!F229/DataQ!F225)-1) -> 1.6013585 | CK25: =100*((DataQ!M229/DataQ!M225)-1) -> 1.3896206 | CM25: =100*((DataQ!M229/DataQ!F229)-1) -> -0.40773538 | CP25: =DataQ!J229 -> 1.343936 | CQ25: =DataQ!Q229 -> 1.330886 | CS25: =100*((DataQ!Q229/DataQ!J229)-1) -> -0.97102838
C26: =HLOOKUP(C$25,$C$20:$BT$22,2,FALSE) -> Medicinal & pharmaceutical products | D26: =HLOOKUP(D$25,$C$20:$BT$22,2,FALSE) -> Cars | E26: =HLOOKUP(E$25,$C$20:$BT$22,2,FALSE) -> Mechanical power generators | F26: =HLOOKUP(F$25,$C$20:$BT$22,2,FALSE) -> General industrial machinery | G26: =HLOOKUP(G$25,$C$20:$BT$22,2,FALSE) -> Organic chemicals | H26: =HLOOKUP(H$25,$C$20:$BT$22,2,FALSE) -> Miscellaneous electrical goods | I26: =HLOOKUP(I$25,$C$20:$BT$22,2,FALSE) -> Specialised machinery | J26: =HLOOKUP(J$25,$C$20:$BT$22,2,FALSE) -> Office machinery | ... BT26: =HLOOKUP(BT$25,$C$20:$BT$22,2,FALSE) -> Hides, skins & furskins | BW26: =100*((DataQ!D230/DataQ!D226)-1) -> 1.6450527 | BX26: =100*((DataQ!K230/DataQ!K226)-1) -> 1.6502045 | BY26: 0 | CA26: =100*((DataQ!K230/DataQ!D230)-1) -> -0.20682571 | CD26: =100*((DataQ!E230/DataQ!E226)-1) -> 2.1554434 | CE26: =100*((DataQ!L230/DataQ!L226)-1) -> 2.2780369 | CG26: =100*((DataQ!L230/DataQ!E230)-1) -> 0.21492753 | CJ26: =100*((DataQ!F230/DataQ!F226)-1) -> 1.5997698 | CK26: =100*((DataQ!M230/DataQ!M226)-1) -> 1.3828723 | CM26: =100*((DataQ!M230/DataQ!F230)-1) -> -0.45508686 | CP26: =DataQ!J230 -> 1.348955 | CQ26: =DataQ!Q230 -> 1.337163 | CS26: =100*((DataQ!Q230/DataQ!J230)-1) -> -0.87415814
B27: 2023 exports | C27: =HLOOKUP(C$25,$C$20:$BT$22,3,FALSE) -> 8783.032 | D27: =HLOOKUP(D$25,$C$20:$BT$22,3,FALSE) -> 6435.056 | E27: =HLOOKUP(E$25,$C$20:$BT$22,3,FALSE) -> 6077.048 | F27: =HLOOKUP(F$25,$C$20:$BT$22,3,FALSE) -> 3842.051 | G27: =HLOOKUP(G$25,$C$20:$BT$22,3,FALSE) -> 2816.029 | H27: =HLOOKUP(H$25,$C$20:$BT$22,3,FALSE) -> 2558.054 | I27: =HLOOKUP(I$25,$C$20:$BT$22,3,FALSE) -> 2495.049 | J27: =HLOOKUP(J$25,$C$20:$BT$22,3,FALSE) -> 2481.052 | ... BT27: =HLOOKUP(BT$25,$C$20:$BT$22,3,FALSE) -> 0.012 | BV27: 2029 | BW27: =100*((DataQ!D231/DataQ!D227)-1) -> 1.6147268 | BX27: =100*((DataQ!K231/DataQ!K227)-1) -> 1.6138388 | BY27: 0 | CA27: =100*((DataQ!K231/DataQ!D231)-1) -> -0.21032396 | CC27: 2029 | CD27: =100*((DataQ!E231/DataQ!E227)-1) -> 2.1118688 | CE27: =100*((DataQ!L231/DataQ!L227)-1) -> 2.2227234 | CG27: =100*((DataQ!L231/DataQ!E231)-1) -> 0.23206893 | CI27: 2029 | CJ27: =100*((DataQ!F231/DataQ!F227)-1) -> 1.5514616 | CK27: =100*((DataQ!M231/DataQ!M227)-1) -> 1.3469722 | CM27: =100*((DataQ!M231/DataQ!F231)-1) -> -0.49517018 | CO27: 2029 | CP27: =DataQ!J231 -> 1.35303 | CQ27: =DataQ!Q231 -> 1.342386 | CS27: =100*((DataQ!Q231/DataQ!J231)-1) -> -0.78667879
BW28: =100*((DataQ!D232/DataQ!D228)-1) -> 1.5892728 | BX28: =100*((DataQ!K232/DataQ!K228)-1) -> 1.5832445 | BY28: 0 | CA28: =100*((DataQ!K232/DataQ!D232)-1) -> -0.20938355 | CD28: =100*((DataQ!E232/DataQ!E228)-1) -> 2.0792333 | CE28: =100*((DataQ!L232/DataQ!L228)-1) -> 2.1685143 | CG28: =100*((DataQ!L232/DataQ!E232)-1) -> 0.24379744 | CJ28: =100*((DataQ!F232/DataQ!F228)-1) -> 1.509038 | CK28: =100*((DataQ!M232/DataQ!M228)-1) -> 1.3276751 | CM28: =100*((DataQ!M232/DataQ!F232)-1) -> -0.53199134 | CP28: =DataQ!J232 -> 1.357076 | CQ28: =DataQ!Q232 -> 1.347472 | CS28: =100*((DataQ!Q232/DataQ!J232)-1) -> -0.70769802
C29: 1 | D29: 2 | E29: 3 | F29: 4 | G29: 5 | H29: 6 | I29: 7 | BW29: =100*((DataQ!D233/DataQ!D229)-1) -> 1.5590613 | BX29: =100*((DataQ!K233/DataQ!K229)-1) -> 1.5526068 | BY29: 0 | CA29: =100*((DataQ!K233/DataQ!D233)-1) -> -0.20932384 | CD29: =100*((DataQ!E233/DataQ!E229)-1) -> 2.0588806 | CE29: =100*((DataQ!L233/DataQ!L229)-1) -> 2.1232646 | CG29: =100*((DataQ!L233/DataQ!E233)-1) -> 0.25441365 | CJ29: =100*((DataQ!F233/DataQ!F229)-1) -> 1.4939749 | CK29: =100*((DataQ!M233/DataQ!M229)-1) -> 1.3387551 | CM29: =100*((DataQ!M233/DataQ!F233)-1) -> -0.56004683 | CP29: =DataQ!J233 -> 1.3611 | CQ29: =DataQ!Q233 -> 1.352431 | CS29: =100*((DataQ!Q233/DataQ!J233)-1) -> -0.63691132
C30: =C26 -> Medicinal & pharmaceutical products | D30: =D26 -> Cars | E30: =E26 -> Mechanical power generators | F30: =F26 -> General industrial machinery | G30: =G26 -> Organic chemicals | H30: =H26 -> Miscellaneous electrical goods | I30: =I26 -> Specialised machinery | J30: Other | BW30: =100*((DataQ!D234/DataQ!D230)-1) -> 1.5388333 | BX30: =100*((DataQ!K234/DataQ!K230)-1) -> 1.5334259 | BY30: 0 | CA30: =100*((DataQ!K234/DataQ!D234)-1) -> -0.21214019 | CD30: =100*((DataQ!E234/DataQ!E230)-1) -> 2.0308018 | CE30: =100*((DataQ!L234/DataQ!L230)-1) -> 2.0833319 | CG30: =100*((DataQ!L234/DataQ!E234)-1) -> 0.26652279 | CJ30: =100*((DataQ!F234/DataQ!F230)-1) -> 1.5115401 | CK30: =100*((DataQ!M234/DataQ!M230)-1) -> 1.3818041 | CM30: =100*((DataQ!M234/DataQ!F234)-1) -> -0.58230943 | CP30: =DataQ!J234 -> 1.364191 | CQ30: =DataQ!Q234 -> 1.356369 | CS30: =100*((DataQ!Q234/DataQ!J234)-1) -> -0.57338012
B31: =B27 -> 2023 exports | C31: =C27 -> 8783.032 | D31: =D27 -> 6435.056 | E31: =E27 -> 6077.048 | F31: =F27 -> 3842.051 | G31: =G27 -> 2816.029 | H31: =H27 -> 2558.054 | I31: =I27 -> 2495.049 | J31: =B17-SUM(C31:I31) -> 24941.681
A34: US exports as share of total | BV34: =20%*30%*10% -> 0.006
A35: 2023 | B35: =B2 -> Total | C35: =C2 -> Live animals | D35: =D2 -> Meat & meat preparations | E35: =E2 -> Dairy products & eggs | F35: =F2 -> Fish and shellfish | G35: =G2 -> Cereals | H35: =H2 -> Vegetables & fruit | I35: =I2 -> Sugar | ... BT35: =BT2 -> Unspecified goods
A36: Exports to US | B36: ='ONS - UK Exports by type'!D1401 -> 60432 | C36: ='ONS - UK Exports by type'!E1401 -> 41 | D36: ='ONS - UK Exports by type'!F1401 -> 33 | E36: ='ONS - UK Exports by type'!G1401 -> 99 | F36: ='ONS - UK Exports by type'!H1401 -> 245 | G36: ='ONS - UK Exports by type'!I1401 -> 137 | H36: ='ONS - UK Exports by type'!J1401 -> 30 | I36: ='ONS - UK Exports by type'!K1401 -> 10 | ... AV36: ='ONS - UK Exports by type'!AX1401 -> 931 | AW36: ='ONS - UK Exports by type'!AY1401+'ONS - UK Exports by type'!AZ1401 -> 296 | AX36: ='ONS - UK Exports by type'!BA1401+'ONS - UK Exports by type'!BB1401+'ONS - UK Exports by type'!BC1401 -> 6077 | AY36: ='ONS - UK Exports by type'!BD1401+'ONS - UK Exports by type'!BE1401+'ONS - UK Exports by type'!BF1401 -> 2495 | AZ36: ='ONS - UK Exports by type'!BG1401+'ONS - UK Exports by type'!BH1401 -> 203 | BA36: ='ONS - UK Exports by type'!BI1401+'ONS - UK Exports by type'!BJ1401+'ONS - UK Exports by type'!BK1401 -> 3842 | BB36: ='ONS - UK Exports by type'!BL1401+'ONS - UK Exports by type'!BK1401+'ONS - UK Exports by type'!BM1401 -> 2481 | BC36: ='ONS - UK Exports by type'!BO1401+'ONS - UK Exports by type'!BP1401+'ONS - UK Exports by type'!BQ1401 -> 968 | BD36: ='ONS - UK Exports by type'!BR1401+'ONS - UK Exports by type'!BS1401+'ONS - UK Exports by type'!BT1401 -> 2558 | BE36: ='ONS - UK Exports by type'!BU1401+'ONS - UK Exports by type'!BV1401+'ONS - UK Exports by type'!BW1401 -> 1333 | BF36: ='ONS - UK Exports by type'!BX1401 -> 6435 | BG36: ='ONS - UK Exports by type'!BY1401+'ONS - UK Exports by type'!BZ1401 -> 7 | BH36: ='ONS - UK Exports by type'!CA1401 -> 2117 | BI36: ='ONS - UK Exports by type'!CB1401 -> 290 | BJ36: ='ONS - UK Exports by type'!CC1401+'ONS - UK Exports by type'!CD1401+'ONS - UK Exports by type'!CE1401 -> 109 | BK36: ='ONS - UK Exports by type'!CF1401+'ONS - UK Exports by type'!CG1401+'ONS - UK Exports by type'!CH1401 -> 531 | BL36: ='ONS - UK Exports by type'!CI1401 -> 56 | BM36: ='ONS - UK Exports by type'!CJ1401 -> 409 | BN36: ='ONS - UK Exports by type'!CK1401 -> 54 | BO36: ='ONS - UK Exports by type'!CL1401+'ONS - UK Exports by type'!CK1401+'ONS - UK Exports by type'!CM1401 -> 396 | BP36: ='ONS - UK Exports by type'!CO1401+'ONS - UK Exports by type'!CP1401+'ONS - UK Exports by type'!CQ1401 -> 336 | BQ36: ='ONS - UK Exports by type'!CR1401 -> 1482 | BR36: ='ONS - UK Exports by type'!CS1401 -> 277 | BS36: ='ONS - UK Exports by type'!CT1401+'ONS - UK Exports by type'!CU1401+'ONS - UK Exports by type'!CV1401 -> 2012 | BT36: ='ONS - UK Exports by type'!CW1401 -> 1206
