Workbook
Name _DLX1.INC: HAVERQ!$A$1:$E$6
Name _DLX2.INC: HAVERD!$B$1:$FZ$6
Name _DLX3.INC: HAVERW!$B$1:$F$6
Name _DLX4.INC: HAVERM!$A$1:$AF$6

Sheet Chart Data
A1: Inflation forecasts | H1: Oil and petrol prices | P1: FX pass through | U1: Food commodities | AZ1: Food and core goods contributions | BI1: OE vs BoE forecast >>> | BP1: CPI Services vs Pay growth >>>
B2: OE (February) | C2: OE (February) | D2: BoE (February) | E2: BoE (Nov) | F2: 2% LINE | I2: Unleaded pump price (LHS) | J2: Diesel pump price (LHS) | M2: Brent crude oil price (RHS) | O2: Period | P2: Date | Q2: Passthrough to annual inflation (LHS) | R2: Passthrough to price level (LHS) | U2: Date | V2: UN global food price inflation in £ terms (adv. 12m, LHS) | W2: ONS UK food price inflation (RHS) | X2: PPI food output | Y2: Zeroline | Z2: FX adj | AA2: Rebase | AD2: Date | AE2: MPC's measure of underlying CPI services inflation* (LHS) | AF2: BoE DMP measure of one-year inflation expectations (adv. 6m, RHS) | AJ2: Date | AL2: Pence per therm | AO2: Jul-23 cap | AP2: Oct-23 cap | AQ2: Jan-24 cap | AR2: Apr-24 cap | AS2: Jul-24 cap | AT2: Oct-24 cap | AU2: Jan-25 cap | AV2: Apr-25 cap | AW2: Jul-25 cap | AZ2: Date | BA2: Food | BB2: Core goods | BC2: Food avg | BD2: Core goods avg | BE2: 2010-2019 average | BF2: Zeroline | BJ2: OE (latest) | BK2: OE (Nov) | BL2: BoE* (Feb) | BM2: 2% LINE | BQ2: Date | BR2: CPI services | BS2: AWE total pay growth | BT2: Zeroline | BX2: Lower profit margins | BY2: Higher prices | BZ2: Lower number of employees | CA2: Lower employee wages | CB2: Other | CC2: None of the above
A3: 43831 | B3: ='[24]CPI Forecast'!D294 -> 1.7692706 | C3: =NA() -> #N/A | D3: =NA() -> #N/A | E3: =NA() -> #N/A | F3: 2 | H3: 43836 | I3: =HAVERW!C8 -> 126.09 | J3: =HAVERW!D8 -> 131.56 | L3: 43831 | M3: =HAVERD!BA7/HAVERD!BB7 -> #N/A | O3: 1 | P3: t | Q3: ='[25]Impulse responses'!DK9 -> 0.26727528 | R3: ='[25]Impulse responses'!EN9 -> 0.095902362 | U3: 40179 | V3: =NA() -> #N/A | W3: =((HAVERM!J139/HAVERM!J127)-1)*100 -> 1.8327606 | X3: =((HAVERM!K136/HAVERM!K124)-1)*100 -> 0 | Y3: 0 | Z3: =HAVERM!H139/HAVERM!I139 -> 62.987254 | AA3: =(Z3/AVERAGE($Z$63:$Z$74))*100 -> 103.42422 | AD3: 44197 | AE3: ='BoE MPR - Chart 2.21'!D7 -> 1.4 | AF3: =HAVERM!L265 -> 1.494 | AJ3: 43831 | AL3: =IF(HAVERD!H7="",HAVERD!D7,AVERAGE(HAVERD!H7:Q7)) -> #N/A | AZ3: 45292 | BA3: ='[26]CPI Forecast'!V342 -> 1.9632648 | BB3: ='[26]CPI Forecast'!AN342 -> 8.3186845 | BC3: 0.85340364 | BD3: 2.5013809 | BF3: 0 | BI3: 43831 | BJ3: ='[27]CPI Forecast'!D294 -> 1.7692706 | BK3: =NA() -> #N/A | BL3: =NA() -> #N/A | BM3: 2 | BP3: 20191 | BQ3: =LEFT(BP3,4) -> 2019 | BR3: ='[28]CPI Forecast'!AA581 -> 2.4880644 | BS3: 3.2552148 | BT3: 0 | BW3: 45597 | BX3: =HAVERM!M317 -> 59 | BY3: =HAVERM!N317 -> 54 | BZ3: =HAVERM!O317 -> 54 | CA3: =HAVERM!P317 -> 38 | CB3: =HAVERM!Q317 -> 8 | CC3: =HAVERM!R317 -> 3
A4: 43862 | B4: ='[24]CPI Forecast'!D295 -> 1.7095297 | C4: =NA() -> #N/A | D4: =NA() -> #N/A | E4: =NA() -> #N/A | F4: 2 | H4: =+H3+7 -> 43843 | I4: =HAVERW!C9 -> 127.17 | J4: =HAVERW!D9 -> 132.69 | L4: 43832 | M4: =HAVERD!BA8/HAVERD!BB8 -> 50.837819 | O4: 2 | Q4: ='[25]Impulse responses'!DK10 -> 0.42339588 | R4: ='[25]Impulse responses'!EN10 -> 0.20175133 | U4: 40210 | V4: =NA() -> #N/A | W4: =((HAVERM!J140/HAVERM!J128)-1)*100 -> 1.3528749 | X4: =((HAVERM!K137/HAVERM!K125)-1)*100 -> 0.56369786 | Y4: 0 | Z4: =HAVERM!H140/HAVERM!I140 -> 63.592699 | AA4: =(Z4/AVERAGE($Z$63:$Z$74))*100 -> 104.41835 | AD4: 44228 | AE4: ='BoE MPR - Chart 2.21'!D8 -> 1.2 | AF4: =HAVERM!L266 -> 1.751 | AJ4: 43832 | AL4: =IF(HAVERD!H8="",AL3,AVERAGE(HAVERD!H8:Q8)) -> 37.246 | AZ4: 45323 | BA4: ='[26]CPI Forecast'!V343 -> 1.2718872 | BB4: ='[26]CPI Forecast'!AN343 -> 6.7134168 | BC4: 0.85340364 | BD4: 2.5013809 | BF4: 0 | BI4: 43862 | BJ4: ='[27]CPI Forecast'!D295 -> 1.7095297 | BK4: =NA() -> #N/A | BL4: =NA() -> #N/A | BM4: 2 | BP4: 20192 | BQ4: =LEFT(BP4,4) -> 2019 | BR4: ='[28]CPI Forecast'!AA582 -> 2.6615757 | BS4: 3.9354772 | BT4: 0 | BW4: 45627 | BX4: =HAVERM!M318 -> 64 | BY4: =HAVERM!N318 -> 54 | BZ4: =HAVERM!O318 -> 53 | CA4: =HAVERM!P318 -> 41 | CB4: =HAVERM!Q318 -> 7 | CC4: =HAVERM!R318 -> 4
A5: 43891 | B5: ='[24]CPI Forecast'!D296 -> 1.5233075 | C5: =NA() -> #N/A | D5: =NA() -> #N/A | E5: =NA() -> #N/A | F5: 2 | H5: =+H4+7 -> 43850 | I5: =HAVERW!C10 -> 127.18 | J5: =HAVERW!D10 -> 132.74 | L5: 43833 | M5: =HAVERD!BA9/HAVERD!BB9 -> 52.845777 | O5: 3 | Q5: ='[25]Impulse responses'!DK11 -> 0.57439711 | R5: ='[25]Impulse responses'!EN11 -> 0.34535061 | U5: 40238 | V5: =NA() -> #N/A | W5: =((HAVERM!J141/HAVERM!J129)-1)*100 -> 2.0385051 | X5: =((HAVERM!K138/HAVERM!K126)-1)*100 -> 0.78651685 | Y5: 0 | Z5: =HAVERM!H141/HAVERM!I141 -> 64.106823 | AA5: =(Z5/AVERAGE($Z$63:$Z$74))*100 -> 105.26253 | AD5: 44256 | AE5: ='BoE MPR - Chart 2.21'!D9 -> 1.2 | AF5: =HAVERM!L267 -> 1.891 | AJ5: 43833 | AL5: =IF(HAVERD!H9="",AL4,AVERAGE(HAVERD!H9:Q9)) -> 39.732 | AZ5: 45352 | BA5: ='[26]CPI Forecast'!V344 -> 0.80433786 | BB5: ='[26]CPI Forecast'!AN344 -> 6.0383119 | BC5: 0.85340364 | BD5: 2.5013809 | BF5: 0 | BI5: 43891 | BJ5: ='[27]CPI Forecast'!D296 -> 1.5233075 | BK5: =NA() -> #N/A | BL5: =NA() -> #N/A | BM5: 2 | BP5: 20193 | BQ5: =LEFT(BP5,4) -> 2019 | BR5: ='[28]CPI Forecast'!AA583 -> 2.4026482 | BS5: 3.8289728 | BT5: 0 | BW5: 45658 | BX5: =HAVERM!M319 -> 63 | BY5: =HAVERM!N319 -> 61 | BZ5: =HAVERM!O319 -> 54 | CA5: =HAVERM!P319 -> 37 | CB5: =HAVERM!Q319 -> 12 | CC5: =HAVERM!R319 -> 3
A6: 43922 | B6: ='[24]CPI Forecast'!D297 -> 0.76742263 | C6: =NA() -> #N/A | D6: =NA() -> #N/A | E6: =NA() -> #N/A | F6: 2 | H6: =+H5+7 -> 43857 | I6: =HAVERW!C11 -> 127.33 | J6: =HAVERW!D11 -> 132.88 | L6: 43836 | M6: =HAVERD!BA10/HAVERD!BB10 -> 53.385516 | O6: 4 | Q6: ='[25]Impulse responses'!DK12 -> 0.60063748 | R6: ='[25]Impulse responses'!EN12 -> 0.49550998 | U6: 40269 | V6: =NA() -> #N/A | W6: =((HAVERM!J142/HAVERM!J130)-1)*100 -> 2.8441411 | X6: =((HAVERM!K139/HAVERM!K127)-1)*100 -> -0.22396417 | Y6: 0 | Z6: =HAVERM!H142/HAVERM!I142 -> 63.298566 | AA6: =(Z6/AVERAGE($Z$63:$Z$74))*100 -> 103.93539 | AD6: 44287 | AE6: ='BoE MPR - Chart 2.21'!D10 -> 1.3 | AF6: =HAVERM!L268 -> 2.122 | AJ6: 43836 | AL6: =IF(HAVERD!H10="",AL5,AVERAGE(HAVERD!H10:Q10)) -> 38.667 | AZ6: 45383 | BA6: ='[26]CPI Forecast'!V345 -> -0.11452749 | BB6: ='[26]CPI Forecast'!AN345 -> 4.2109142 | BC6: 0.85340364 | BD6: 2.5013809 | BF6: 0 | BI6: 43922 | BJ6: ='[27]CPI Forecast'!D297 -> 0.76742263 | BK6: =NA() -> #N/A | BL6: =NA() -> #N/A | BM6: 2 | BP6: 20194 | BQ6: =LEFT(BP6,4) -> 2019 | BR6: ='[28]CPI Forecast'!AA584 -> 2.3727847 | BS6: 2.7146402 | BT6: 0
A7: 43952 | B7: ='[24]CPI Forecast'!D298 -> 0.47986067 | C7: =NA() -> #N/A | D7: =NA() -> #N/A | E7: =NA() -> #N/A | F7: 2 | H7: =+H6+7 -> 43864 | I7: =HAVERW!C12 -> 125.85 | J7: =HAVERW!D12 -> 131.48 | L7: 43837 | M7: =HAVERD!BA11/HAVERD!BB11 -> 52.385307 | O7: 5 | P7: t+1 | Q7: ='[25]Impulse responses'!DK13 -> 0.58307829 | R7: ='[25]Impulse responses'!EN13 -> 0.64127955 | U7: 40299 | V7: =NA() -> #N/A | W7: =((HAVERM!J143/HAVERM!J131)-1)*100 -> 1.8038331 | X7: =((HAVERM!K140/HAVERM!K128)-1)*100 -> -0.77864294 | Y7: 0 | Z7: =HAVERM!H143/HAVERM!I143 -> 65.905517 | AA7: =(Z7/AVERAGE($Z$63:$Z$74))*100 -> 108.21597 | AD7: 44317 | AE7: ='BoE MPR - Chart 2.21'!D11 -> 1.8 | AF7: =HAVERM!L269 -> 2.099 | AJ7: 43837 | AL7: =IF(HAVERD!H11="",AL6,AVERAGE(HAVERD!H11:Q11)) -> 37.814 | AZ7: 45413 | BA7: ='[26]CPI Forecast'!V346 -> -0.81732485 | BB7: ='[26]CPI Forecast'!AN346 -> 3.2502555 | BC7: 0.85340364 | BD7: 2.5013809 | BF7: 0 | BI7: 43952 | BJ7: ='[27]CPI Forecast'!D298 -> 0.47986067 | BK7: =NA() -> #N/A | BL7: =NA() -> #N/A | BM7: 2 | BP7: 20201 | BQ7: =LEFT(BP7,4) -> 2020 | BR7: ='[28]CPI Forecast'!AA585 -> 2.4420383 | BS7: 2.2067968 | BT7: 0
A8: 43983 | B8: ='[24]CPI Forecast'!D299 -> 0.60315196 | C8: =NA() -> #N/A | D8: =NA() -> #N/A | E8: =NA() -> #N/A | F8: 2 | H8: =+H7+7 -> 43871 | I8: =HAVERW!C13 -> 124.73 | J8: =HAVERW!D13 -> 129.7 | L8: =+L3+7 -> 43838 | M8: =HAVERD!BA12/HAVERD!BB12 -> 51.385602 | O8: 6 | Q8: ='[25]Impulse responses'!DK14 -> 0.55128787 | R8: ='[25]Impulse responses'!EN14 -> 0.77910152 | U8: 40330 | V8: =NA() -> #N/A | W8: =((HAVERM!J144/HAVERM!J132)-1)*100 -> 1.920904 | X8: =((HAVERM!K141/HAVERM!K129)-1)*100 -> -0.78037904 | Y8: 0 | Z8: =HAVERM!H144/HAVERM!I144 -> 64.968498 | AA8: =(Z8/AVERAGE($Z$63:$Z$74))*100 -> 106.67739 | AD8: 44348 | AE8: ='BoE MPR - Chart 2.21'!D12 -> 2.3 | AF8: =HAVERM!L270 -> 2.383 | AJ8: =+AJ3+7 -> 43838 | AL8: =IF(HAVERD!H12="",AL7,AVERAGE(HAVERD!H12:Q12)) -> 37.963 | AZ8: 45444 | BA8: ='[26]CPI Forecast'!V347 -> -0.90777218 | BB8: ='[26]CPI Forecast'!AN347 -> 2.9929787 | BC8: 0.85340364 | BD8: 2.5013809 | BF8: 0 | BI8: 43983 | BJ8: ='[27]CPI Forecast'!D299 -> 0.60315196 | BK8: =NA() -> #N/A | BL8: =NA() -> #N/A | BM8: 2 | BP8: 20202 | BQ8: =LEFT(BP8,4) -> 2020 | BR8: ='[28]CPI Forecast'!AA586 -> 1.9124297 | BS8: -1.1173184 | BT8: 0
A9: 44013 | B9: ='[24]CPI Forecast'!D300 -> 1.0403061 | C9: =NA() -> #N/A | D9: =NA() -> #N/A | E9: =NA() -> #N/A | F9: 2 | H9: =+H8+7 -> 43878 | I9: =HAVERW!C14 -> 123.8 | J9: =HAVERW!D14 -> 128.2 | L9: =+L4+7 -> 43839 | M9: =HAVERD!BA13/HAVERD!BB13 -> 51.023067 | O9: 7 | Q9: ='[25]Impulse responses'!DK15 -> 0.5160122 | R9: ='[25]Impulse responses'!EN15 -> 0.90810457 | U9: 40360 | V9: =NA() -> #N/A | W9: =((HAVERM!J145/HAVERM!J133)-1)*100 -> 3.2879819 | X9: =((HAVERM!K142/HAVERM!K130)-1)*100 -> -0.44493882 | Y9: 0 | Z9: =HAVERM!H145/HAVERM!I145 -> 65.363749 | AA9: =(Z9/AVERAGE($Z$63:$Z$74))*100 -> 107.32639 | AD9: 44378 | AE9: ='BoE MPR - Chart 2.21'!D13 -> 1.9 | AF9: =HAVERM!L271 -> 2.438 | AJ9: =+AJ4+7 -> 43839 | AL9: =IF(HAVERD!H13="",AL8,AVERAGE(HAVERD!H13:Q13)) -> 38.255 | AZ9: 45474 | BA9: ='[26]CPI Forecast'!V348 -> -0.69584436 | BB9: ='[26]CPI Forecast'!AN348 -> 2.9391016 | BC9: 0.85340364 | BD9: 2.5013809 | BF9: 0 | BI9: 44013 | BJ9: ='[27]CPI Forecast'!D300 -> 1.0403061 | BK9: =NA() -> #N/A | BL9: =NA() -> #N/A | BM9: 2 | BP9: 20203 | BQ9: =LEFT(BP9,4) -> 2020 | BR9: ='[28]CPI Forecast'!AA587 -> 1.3977684 | BS9: 1.4751077 | BT9: 0
A10: 44044 | B10: ='[24]CPI Forecast'!D301 -> 0.21960784 | C10: =NA() -> #N/A | D10: =NA() -> #N/A | E10: =NA() -> #N/A | F10: 2 | H10: =+H9+7 -> 43885 | I10: =HAVERW!C15 -> 123.45 | J10: =HAVERW!D15 -> 127.67 | L10: =+L5+7 -> 43840 | M10: =HAVERD!BA14/HAVERD!BB14 -> 51.117746 | O10: 8 | Q10: ='[25]Impulse responses'!DK16 -> 0.48109182 | R10: ='[25]Impulse responses'!EN16 -> 1.0283775 | U10: 40391 | V10: =NA() -> #N/A | W10: =((HAVERM!J146/HAVERM!J134)-1)*100 -> 4.109589 | X10: =((HAVERM!K143/HAVERM!K131)-1)*100 -> 0.11148272 | Y10: 0 | Z10: =HAVERM!H146/HAVERM!I146 -> 68.837803 | AA10: =(Z10/AVERAGE($Z$63:$Z$74))*100 -> 113.03074 | AD10: 44409 | AE10: ='BoE MPR - Chart 2.21'!D14 -> 4.5 | AF10: =HAVERM!L272 -> 2.647 | AJ10: =+AJ5+7 -> 43840 | AL10: =IF(HAVERD!H14="",AL9,AVERAGE(HAVERD!H14:Q14)) -> 37.688 | AZ10: 45505 | BA10: ='[26]CPI Forecast'!V349 -> -0.52653144 | BB10: ='[26]CPI Forecast'!AN349 -> 2.4618949 | BC10: 0.85340364 | BD10: 2.5013809 | BF10: 0 | BI10: 44044 | BJ10: ='[27]CPI Forecast'!D301 -> 0.21960784 | BK10: =NA() -> #N/A | BL10: =NA() -> #N/A | BM10: 2 | BP10: 20204 | BQ10: =LEFT(BP10,4) -> 2020 | BR10: ='[28]CPI Forecast'!AA588 -> 1.4487676 | BS10: 4.5482547 | BT10: 0
A11: 44075 | B11: ='[24]CPI Forecast'!D302 -> 0.53190018 | C11: =NA() -> #N/A | D11: =NA() -> #N/A | E11: =NA() -> #N/A | F11: 2 | H11: =+H10+7 -> 43892 | I11: =HAVERW!C16 -> 122.43 | J11: =HAVERW!D16 -> 126.62 | L11: =+L6+7 -> 43843 | M11: =HAVERD!BA15/HAVERD!BB15 -> 49.418291 | O11: 9 | P11: t+2 | Q11: ='[25]Impulse responses'!DK17 -> 0.44783231 | R11: ='[25]Impulse responses'!EN17 -> 1.1403356 | U11: 40422 | V11: =NA() -> #N/A | W11: =((HAVERM!J147/HAVERM!J135)-1)*100 -> 5.1843318 | X11: =((HAVERM!K144/HAVERM!K132)-1)*100 -> -0.33444816 | Y11: 0 | Z11: =HAVERM!H147/HAVERM!I147 -> 73.244319 | AA11: =(Z11/AVERAGE($Z$63:$Z$74))*100 -> 120.26618 | AD11: 44440 | AE11: ='BoE MPR - Chart 2.21'!D15 -> 3 | AF11: =HAVERM!L273 -> 2.736 | AJ11: =+AJ6+7 -> 43843 | AL11: =IF(HAVERD!H15="",AL10,AVERAGE(HAVERD!H15:Q15)) -> 38.188 | AZ11: 45536 | BA11: ='[26]CPI Forecast'!V350 -> -0.56232676 | BB11: ='[26]CPI Forecast'!AN350 -> 2.623591 | BC11: 0.85340364 | BD11: 2.5013809 | BF11: 0 | BI11: 44075 | BJ11: ='[27]CPI Forecast'!D302 -> 0.53190018 | BK11: =NA() -> #N/A | BL11: =NA() -> #N/A | BM11: 2 | BP11: 20211 | BQ11: =LEFT(BP11,4) -> 2021 | BR11: ='[28]CPI Forecast'!AA589 -> 1.5594583 | BS11: 4.1949478 | BT11: 0
A12: 44105 | B12: ='[24]CPI Forecast'!D303 -> 0.69715046 | C12: =NA() -> #N/A | D12: =NA() -> #N/A | E12: =NA() -> #N/A | F12: 2 | H12: =+H11+7 -> 43899 | I12: =HAVERW!C17 -> 122.24 | J12: =HAVERW!D17 -> 126.25 | L12: =+L7+7 -> 43844 | M12: =HAVERD!BA16/HAVERD!BB16 -> 49.538816 | O12: 10 | Q12: ='[25]Impulse responses'!DK18 -> 0.41661096 | R12: ='[25]Impulse responses'!EN18 -> 1.2444883 | U12: 40452 | V12: =NA() -> #N/A | W12: =((HAVERM!J148/HAVERM!J136)-1)*100 -> 4.5610034 | X12: =((HAVERM!K145/HAVERM!K133)-1)*100 -> 0.44792833 | Y12: 0 | Z12: =HAVERM!H148/HAVERM!I148 -> 75.715547 | AA12: =(Z12/AVERAGE($Z$63:$Z$74))*100 -> 124.3239 | AD12: 44470 | AE12: ='BoE MPR - Chart 2.21'!D16 -> 3.3 | AF12: =HAVERM!L274 -> 2.944 | AJ12: =+AJ7+7 -> 43844 | AL12: =IF(HAVERD!H16="",AL11,AVERAGE(HAVERD!H16:Q16)) -> 36.646 | AZ12: 45566 | BA12: ='[26]CPI Forecast'!V351 -> -0.29943167 | BB12: ='[26]CPI Forecast'!AN351 -> 2.7310615 | BC12: 0.85340364 | BD12: 2.5013809 | BF12: 0 | BI12: 44105 | BJ12: ='[27]CPI Forecast'!D303 -> 0.69715046 | BK12: =NA() -> #N/A | BL12: =NA() -> #N/A | BM12: 2 | BP12: 20212 | BQ12: =LEFT(BP12,4) -> 2021 | BR12: ='[28]CPI Forecast'!AA590 -> 1.8670632 | BS12: 8.8512241 | BT12: 0
A13: 44136 | B13: ='[24]CPI Forecast'!D304 -> 0.31506509 | C13: =NA() -> #N/A | D13: =NA() -> #N/A | E13: =NA() -> #N/A | F13: 2 | H13: =+H12+7 -> 43906 | I13: =HAVERW!C18 -> 120.33 | J13: =HAVERW!D18 -> 124.36 | L13: =+L8+7 -> 43845 | M13: =HAVERD!BA17/HAVERD!BB17 -> 48.598633 | O13: 11 | Q13: ='[25]Impulse responses'!DK19 -> 0.38746865 | R13: ='[25]Impulse responses'!EN19 -> 1.3413555 | U13: 40483 | V13: =NA() -> #N/A | W13: =((HAVERM!J149/HAVERM!J137)-1)*100 -> 5.5555556 | X13: =((HAVERM!K146/HAVERM!K134)-1)*100 -> 1.3513514 | Y13: 0 | Z13: =HAVERM!H149/HAVERM!I149 -> 77.814673 | AA13: =(Z13/AVERAGE($Z$63:$Z$74))*100 -> 127.77064 | AD13: 44501 | AE13: ='BoE MPR - Chart 2.21'!D17 -> 3.7 | AF13: =HAVERM!L275 -> 3.185 | AJ13: =+AJ8+7 -> 43845 | AL13: =IF(HAVERD!H17="",AL12,AVERAGE(HAVERD!H17:Q17)) -> 36.35 | AZ13: 45597 | BA13: ='[26]CPI Forecast'!V352 -> 0.32758672 | BB13: ='[26]CPI Forecast'!AN352 -> 3.2433227 | BC13: 0.85340364 | BD13: 2.5013809 | BF13: 0 | BI13: 44136 | BJ13: ='[27]CPI Forecast'!D304 -> 0.31506509 | BK13: =NA() -> #N/A | BL13: =NA() -> #N/A | BM13: 2 | BP13: 20213 | BQ13: =LEFT(BP13,4) -> 2021 | BR13: ='[28]CPI Forecast'!AA591 -> 2.4101613 | BS13: 6.0569477 | BT13: 0
A14: 44166 | B14: ='[24]CPI Forecast'!D305 -> 0.58876645 | C14: =NA() -> #N/A | D14: =NA() -> #N/A | E14: =NA() -> #N/A | F14: 2 | H14: =+H13+7 -> 43913 | I14: =HAVERW!C19 -> 119.64 | J14: =HAVERW!D19 -> 123.41 | L14: =+L9+7 -> 43846 | M14: =HAVERD!BA18/HAVERD!BB18 -> 49.460473 | O14: 12 | Q14: ='[25]Impulse responses'!DK20 -> 0.36032826 | R14: ='[25]Impulse responses'!EN20 -> 1.4314376 | U14: 40513 | V14: =NA() -> #N/A | W14: =((HAVERM!J150/HAVERM!J138)-1)*100 -> 6.1728395 | X14: =((HAVERM!K147/HAVERM!K135)-1)*100 -> 0.8988764 | Y14: 0 | Z14: =HAVERM!H150/HAVERM!I150 -> 82.932769 | AA14: =(Z14/AVERAGE($Z$63:$Z$74))*100 -> 136.17448 | AD14: 44531 | AE14: ='BoE MPR - Chart 2.21'!D18 -> 3.4 | AF14: =HAVERM!L276 -> 3.28 | AJ14: =+AJ9+7 -> 43846 | AL14: =IF(HAVERD!H18="",AL13,AVERAGE(HAVERD!H18:Q18)) -> 35.639 | AZ14: 45627 | BA14: ='[26]CPI Forecast'!V353 -> 0.53109473 | BB14: ='[26]CPI Forecast'!AN353 -> 2.825646 | BC14: 0.85340364 | BD14: 2.5013809 | BF14: 0 | BI14: 44166 | BJ14: ='[27]CPI Forecast'!D305 -> 0.58876645 | BK14: =NA() -> #N/A | BL14: =NA() -> #N/A | BM14: 2 | BP14: 20214 | BQ14: =LEFT(BP14,4) -> 2021 | BR14: ='[28]CPI Forecast'!AA592 -> 3.3237203 | BS14: 4.5267549 | BT14: 0
A15: 44197 | B15: ='[24]CPI Forecast'!D306 -> 0.70058043 | C15: =NA() -> #N/A | D15: =NA() -> #N/A | E15: =NA() -> #N/A | F15: 2 | H15: =+H14+7 -> 43920 | I15: =HAVERW!C20 -> 112.45 | J15: =HAVERW!D20 -> 118.6 | L15: =+L10+7 -> 43847 | M15: =HAVERD!BA19/HAVERD!BB19 -> 49.159567 | O15: 13 | P15: t+3 | Q15: ='[25]Impulse responses'!DK21 -> 0.33507514 | R15: ='[25]Impulse responses'!EN21 -> 1.5152064 | U15: 40544 | V15: =NA() -> #N/A | W15: =((HAVERM!J151/HAVERM!J139)-1)*100 -> 6.2992126 | X15: =((HAVERM!K148/HAVERM!K136)-1)*100 -> 2.027027 | Y15: 0 | Z15: =HAVERM!H151/HAVERM!I151 -> 84.710351 | AA15: =(Z15/AVERAGE($Z$63:$Z$74))*100 -> 139.09325 | AD15: 44562 | AE15: ='BoE MPR - Chart 2.21'!D19 -> 3.5 | AF15: =HAVERM!L277 -> 3.21 | AJ15: =+AJ10+7 -> 43847 | AL15: =IF(HAVERD!H19="",AL14,AVERAGE(HAVERD!H19:Q19)) -> 34.806 | AZ15: 45658 | BA15: ='[26]CPI Forecast'!V354 -> 0.67591702 | BB15: ='[26]CPI Forecast'!AN354 -> 3.1140094 | BC15: 0.85340364 | BD15: 2.5013809 | BF15: 0 | BI15: 44197 | BJ15: ='[27]CPI Forecast'!D306 -> 0.70058043 | BK15: =NA() -> #N/A | BL15: =NA() -> #N/A | BM15: 2 | BP15: 20221 | BQ15: =LEFT(BP15,4) -> 2022 | BR15: ='[28]CPI Forecast'!AA593 -> 3.574043 | BS15: 6.9863766 | BT15: 0
A16: 44228 | B16: ='[24]CPI Forecast'!D307 -> 0.41421589 | C16: =NA() -> #N/A | D16: =NA() -> #N/A | E16: =NA() -> #N/A | F16: 2 | H16: =+H15+7 -> 43927 | I16: =HAVERW!C21 -> 110.23 | J16: =HAVERW!D21 -> 116.83 | L16: =+L11+7 -> 43850 | M16: =HAVERD!BA20/HAVERD!BB20 -> 49.723034 | O16: 14 | Q16: ='[25]Impulse responses'!DK22 -> 0.31158664 | R16: ='[25]Impulse responses'!EN22 -> 1.593103 | U16: 40575 | V16: =NA() -> #N/A | W16: =((HAVERM!J152/HAVERM!J140)-1)*100 -> 6.2291435 | X16: =((HAVERM!K149/HAVERM!K137)-1)*100 -> 2.4663677 | Y16: 0 | Z16: =HAVERM!H152/HAVERM!I152 -> 85.368878 | AA16: =(Z16/AVERAGE($Z$63:$Z$74))*100 -> 140.17454 | AD16: 44593 | AE16: ='BoE MPR - Chart 2.21'!D20 -> 3.7 | AF16: =HAVERM!L278 -> 3.14 | AJ16: =+AJ11+7 -> 43850 | AL16: =IF(HAVERD!H20="",AL15,AVERAGE(HAVERD!H20:Q20)) -> 33.852 | AZ16: 45689 | BA16: ='[26]CPI Forecast'!V355 -> 0.7313925 | BB16: ='[26]CPI Forecast'!AN355 -> 3.3016893 | BC16: 0.85340364 | BD16: 2.5013809 | BF16: 0 | BI16: 44228 | BJ16: ='[27]CPI Forecast'!D307 -> 0.41421589 | BK16: =NA() -> #N/A | BL16: =NA() -> #N/A | BM16: 2 | BP16: 20222 | BQ16: =LEFT(BP16,4) -> 2022 | BR16: ='[28]CPI Forecast'!AA594 -> 4.939923 | BS16: 5.1326471 | BT16: 0
A17: 44256 | B17: ='[24]CPI Forecast'!D308 -> 0.71432517 | C17: =NA() -> #N/A | D17: =NA() -> #N/A | E17: =NA() -> #N/A | F17: 2 | H17: =+H16+7 -> 43934 | I17: =HAVERW!C22 -> 109.27 | J17: =HAVERW!D22 -> 116.15 | L17: =+L12+7 -> 43851 | M17: =HAVERD!BA21/HAVERD!BB21 -> 48.751723 | O17: 15 | Q17: ='[25]Impulse responses'!DK23 -> 0.28974269 | R17: ='[25]Impulse responses'!EN23 -> 1.6655387 | U17: 40603 | V17: =NA() -> #N/A | W17: =((HAVERM!J153/HAVERM!J141)-1)*100 -> 4.5504994 | X17: =((HAVERM!K150/HAVERM!K138)-1)*100 -> 2.8985507 | Y17: 0 | Z17: =HAVERM!H153/HAVERM!I153 -> 83.111579 | AA17: =(Z17/AVERAGE($Z$63:$Z$74))*100 -> 136.46809 | AD17: 44621 | AE17: ='BoE MPR - Chart 2.21'!D21 -> 4.4 | AF17: =HAVERM!L279 -> 3.42 | AJ17: =+AJ12+7 -> 43851 | AL17: =IF(HAVERD!H21="",AL16,AVERAGE(HAVERD!H21:Q21)) -> 33.969 | AZ17: 45717 | BA17: ='[26]CPI Forecast'!V356 -> 0.74696704 | BB17: ='[26]CPI Forecast'!AN356 -> 2.8692497 | BC17: 0.85340364 | BD17: 2.5013809 | BF17: 0 | BI17: 44256 | BJ17: ='[27]CPI Forecast'!D308 -> 0.71432517 | BK17: =NA() -> #N/A | BL17: =NA() -> #N/A | BM17: 2 | BP17: 20223 | BQ17: =LEFT(BP17,4) -> 2022 | BR17: ='[28]CPI Forecast'!AA595 -> 5.9272668 | BS17: 5.8823469 | BT17: 0
A18: 44287 | B18: ='[24]CPI Forecast'!D309 -> 1.5259222 | C18: =NA() -> #N/A | D18: =NA() -> #N/A | E18: =NA() -> #N/A | F18: 2 | H18: =+H17+7 -> 43941 | I18: =HAVERW!C23 -> 108.63 | J18: =HAVERW!D23 -> 115.73 | L18: =+L13+7 -> 43852 | M18: =HAVERD!BA22/HAVERD!BB22 -> 47.264287 | O18: 16 | Q18: ='[25]Impulse responses'!DK24 -> 0.26942937 | R18: ='[25]Impulse responses'!EN24 -> 1.732896 | U18: 40634 | V18: =NA() -> #N/A | W18: =((HAVERM!J154/HAVERM!J142)-1)*100 -> 4.3141593 | X18: =((HAVERM!K151/HAVERM!K139)-1)*100 -> 5.0505051 | Y18: 0 | Z18: =HAVERM!H154/HAVERM!I154 -> 83.389416 | AA18: =(Z18/AVERAGE($Z$63:$Z$74))*100 -> 136.92429 | AD18: 44652 | AE18: ='BoE MPR - Chart 2.21'!D22 -> 5.3 | AF18: =HAVERM!L280 -> 4.017 | AJ18: =+AJ13+7 -> 43852 | AL18: =IF(HAVERD!H22="",AL17,AVERAGE(HAVERD!H22:Q22)) -> 33.108 | AZ18: 45748 | BA18: ='[26]CPI Forecast'!V357 -> 0.94314358 | BB18: ='[26]CPI Forecast'!AN357 -> 3.0382419 | BC18: 0.85340364 | BD18: 2.5013809 | BF18: 0 | BI18: 44287 | BJ18: ='[27]CPI Forecast'!D309 -> 1.5259222 | BK18: =NA() -> #N/A | BL18: =NA() -> #N/A | BM18: 2 | BP18: 20224 | BQ18: =LEFT(BP18,4) -> 2022 | BR18: ='[28]CPI Forecast'!AA596 -> 6.4758868 | BS18: 6.355444 | BT18: 0
A19: 44317 | B19: ='[24]CPI Forecast'!D310 -> 2.1149485 | C19: =NA() -> #N/A | D19: =NA() -> #N/A | E19: =NA() -> #N/A | F19: 2 | H19: =+H18+7 -> 43948 | I19: =HAVERW!C24 -> 107.88 | J19: =HAVERW!D24 -> 115.22 | L19: =+L14+7 -> 43853 | M19: =HAVERD!BA23/HAVERD!BB23 -> 46.699192 | O19: 17 | P19: t+4 | Q19: ='[25]Impulse responses'!DK25 -> 0.2505399 | R19: ='[25]Impulse responses'!EN25 -> 1.795531 | U19: 40664 | V19: =NA() -> #N/A | W19: =((HAVERM!J155/HAVERM!J143)-1)*100 -> 5.7585825 | X19: =((HAVERM!K152/HAVERM!K140)-1)*100 -> 5.8295964 | Y19: 0 | Z19: =HAVERM!H155/HAVERM!I155 -> 82.822462 | AA19: =(Z19/AVERAGE($Z$63:$Z$74))*100 -> 135.99336 | AD19: 44682 | AE19: ='BoE MPR - Chart 2.21'!D23 -> 5.4 | AF19: =HAVERM!L281 -> 4.411 | AJ19: =+AJ14+7 -> 43853 | AL19: =IF(HAVERD!H23="",AL18,AVERAGE(HAVERD!H23:Q23)) -> 32.613 | AZ19: 45778 | BA19: ='[26]CPI Forecast'!V358 -> 1.1539396 | BB19: ='[26]CPI Forecast'!AN358 -> 3.4199924 | BC19: 0.85340364 | BD19: 2.5013809 | BF19: 0 | BI19: 44317 | BJ19: ='[27]CPI Forecast'!D310 -> 2.1149485 | BK19: =NA() -> #N/A | BL19: =NA() -> #N/A | BM19: 2 | BP19: 20231 | BQ19: =LEFT(BP19,4) -> 2023 | BR19: ='[28]CPI Forecast'!AA597 -> 6.3958967 | BS19: 6.3087995 | BT19: 0
A20: 44348 | B20: ='[24]CPI Forecast'!D311 -> 2.5141826 | C20: =NA() -> #N/A | D20: =NA() -> #N/A | E20: =NA() -> #N/A | F20: 2 | H20: =+H19+7 -> 43955 | I20: =HAVERW!C25 -> 107.56 | J20: =HAVERW!D25 -> 114.94 | L20: =+L15+7 -> 43854 | M20: =HAVERD!BA24/HAVERD!BB24 -> 45.412107 | O20: 18 | Q20: ='[25]Impulse responses'!DK26 -> 0.23297464 | R20: ='[25]Impulse responses'!EN26 -> 1.8537747 | U20: 40695 | V20: =NA() -> #N/A | W20: =((HAVERM!J156/HAVERM!J144)-1)*100 -> 6.9844789 | X20: =((HAVERM!K153/HAVERM!K141)-1)*100 -> 6.741573 | Y20: 0 | Z20: =HAVERM!H156/HAVERM!I156 -> 83.138029 | AA20: =(Z20/AVERAGE($Z$63:$Z$74))*100 -> 136.51152 | AD20: 44713 | AE20: ='BoE MPR - Chart 2.21'!D24 -> 5.5 | AF20: =HAVERM!L282 -> 4.743 | AJ20: =+AJ15+7 -> 43854 | AL20: =IF(HAVERD!H24="",AL19,AVERAGE(HAVERD!H24:Q24)) -> 32.742 | AZ20: 45809 | BA20: ='[26]CPI Forecast'!V359 -> 1.5126528 | BB20: ='[26]CPI Forecast'!AN359 -> 3.4488504 | BC20: 0.85340364 | BD20: 2.5013809 | BF20: 0 | BI20: 44348 | BJ20: ='[27]CPI Forecast'!D311 -> 2.5141826 | BK20: =NA() -> #N/A | BL20: =NA() -> #N/A | BM20: 2 | BP20: 20232 | BQ20: =LEFT(BP20,4) -> 2023 | BR20: ='[28]CPI Forecast'!AA598 -> 7.1599978 | BS20: 8.1733292 | BT20: 0
A21: 44378 | B21: ='[24]CPI Forecast'!D312 -> 2.0399369 | C21: =NA() -> #N/A | D21: =NA() -> #N/A | E21: =NA() -> #N/A | F21: 2 | H21: =+H20+7 -> 43962 | I21: =HAVERW!C26 -> 107.45 | J21: =HAVERW!D26 -> 114.83 | L21: =+L16+7 -> 43857 | M21: =HAVERD!BA25/HAVERD!BB25 -> 44.837623 | O21: 19 | Q21: ='[25]Impulse responses'!DK27 -> 0.21664083 | R21: ='[25]Impulse responses'!EN27 -> 1.9079349 | U21: 40725 | V21: =NA() -> #N/A | W21: =((HAVERM!J157/HAVERM!J145)-1)*100 -> 6.1470911 | X21: =((HAVERM!K154/HAVERM!K142)-1)*100 -> 6.8156425 | Y21: 0 | Z21: =HAVERM!H157/HAVERM!I157 -> 82.378445 | AA21: =(Z21/AVERAGE($Z$63:$Z$74))*100 -> 135.26429 | AD21: 44743 | AE21: ='BoE MPR - Chart 2.21'!D25 -> 5.7 | AF21: =HAVERM!L283 -> 4.682 | AJ21: =+AJ16+7 -> 43857 | AL21: =IF(HAVERD!H25="",AL20,AVERAGE(HAVERD!H25:Q25)) -> 32.896 | AZ21: 45839 | BA21: ='[26]CPI Forecast'!V360 -> 1.1535605 | BB21: ='[26]CPI Forecast'!AN360 -> 3.4288316 | BC21: 0.85340364 | BD21: 2.5013809 | BF21: 0 | BI21: 44378 | BJ21: ='[27]CPI Forecast'!D312 -> 2.0399369 | BK21: =NA() -> #N/A | BL21: =NA() -> #N/A | BM21: 2 | BP21: 20233 | BQ21: =LEFT(BP21,4) -> 2023 | BR21: ='[28]CPI Forecast'!AA599 -> 7.0600784 | BS21: 7.7130583 | BT21: 0
A22: 44409 | B22: ='[24]CPI Forecast'!D313 -> 3.1966707 | C22: =NA() -> #N/A | D22: =NA() -> #N/A | E22: =NA() -> #N/A | F22: 2 | H22: =+H21+7 -> 43969 | I22: =HAVERW!C27 -> 105.09 | J22: =HAVERW!D27 -> 112.22 | L22: =+L17+7 -> 43858 | M22: =HAVERD!BA26/HAVERD!BB26 -> 45.72903 | O22: 20 | Q22: ='[25]Impulse responses'!DK28 -> 0.20145217 | R22: ='[25]Impulse responses'!EN28 -> 1.9582979 | U22: 40756 | V22: =NA() -> #N/A | W22: =((HAVERM!J158/HAVERM!J146)-1)*100 -> 6.25 | X22: =((HAVERM!K155/HAVERM!K143)-1)*100 -> 7.0155902 | Y22: 0 | Z22: =HAVERM!H158/HAVERM!I158 -> 81.172009 | AA22: =(Z22/AVERAGE($Z$63:$Z$74))*100 -> 133.28334 | AD22: 44774 | AE22: ='BoE MPR - Chart 2.21'!D26 -> 6 | AF22: =HAVERM!L284 -> 4.833 | AJ22: =+AJ17+7 -> 43858 | AL22: =IF(HAVERD!H26="",AL21,AVERAGE(HAVERD!H26:Q26)) -> 33.714 | AZ22: 45870 | BA22: ='[26]CPI Forecast'!V361 -> 1.2150545 | BB22: ='[26]CPI Forecast'!AN361 -> 3.5305889 | BC22: 0.85340364 | BD22: 2.5013809 | BF22: 0 | BI22: 44409 | BJ22: ='[27]CPI Forecast'!D313 -> 3.1966707 | BK22: =NA() -> #N/A | BL22: =NA() -> #N/A | BM22: 2 | BP22: 20234 | BQ22: =LEFT(BP22,4) -> 2023 | BR22: ='[28]CPI Forecast'!AA600 -> 6.4104318 | BS22: 5.9228031 | BT22: 0
A23: 44440 | B23: ='[24]CPI Forecast'!D314 -> 3.080069 | C23: =NA() -> #N/A | D23: =NA() -> #N/A | E23: =NA() -> #N/A | F23: 2 | H23: =+H22+7 -> 43976 | I23: =HAVERW!C28 -> 104.87 | J23: =HAVERW!D28 -> 111.7 | L23: =+L18+7 -> 43859 | M23: =HAVERD!BA27/HAVERD!BB27 -> 45.738462 | O23: 21 | P23: t+5 | Q23: ='[25]Impulse responses'!DK29 -> 0.18732838 | R23: ='[25]Impulse responses'!EN29 -> 2.00513 | U23: 40787 | V23: =NA() -> #N/A | W23: =((HAVERM!J159/HAVERM!J147)-1)*100 -> 6.3526835 | X23: =((HAVERM!K156/HAVERM!K144)-1)*100 -> 7.9418345 | Y23: 0 | Z23: =HAVERM!H159/HAVERM!I159 -> 82.430463 | AA23: =(Z23/AVERAGE($Z$63:$Z$74))*100 -> 135.3497 | AD23: 44805 | AE23: ='BoE MPR - Chart 2.21'!D27 -> 5.9 | AF23: =HAVERM!L285 -> 5.087 | AJ23: =+AJ18+7 -> 43859 | AL23: =IF(HAVERD!H27="",AL22,AVERAGE(HAVERD!H27:Q27)) -> 32.498 | AZ23: 45901 | BA23: ='[26]CPI Forecast'!V362 -> 1.3320921 | BB23: ='[26]CPI Forecast'!AN362 -> 3.3390454 | BC23: 0.85340364 | BD23: 2.5013809 | BF23: 0 | BI23: 44440 | BJ23: ='[27]CPI Forecast'!D314 -> 3.080069 | BK23: =NA() -> #N/A | BL23: =NA() -> #N/A | BM23: 2 | BP23: 20241 | BQ23: =LEFT(BP23,4) -> 2024 | BR23: ='[28]CPI Forecast'!AA601 -> 6.2048304 | BS23: 5.9344095 | BT23: 0
A24: 44470 | B24: ='[24]CPI Forecast'!D315 -> 4.2062117 | C24: =NA() -> #N/A | D24: =NA() -> #N/A | E24: =NA() -> #N/A | F24: 2 | H24: =+H23+7 -> 43983 | I24: =HAVERW!C29 -> 105.17 | J24: =HAVERW!D29 -> 111.76 | L24: =+L19+7 -> 43860 | M24: =HAVERD!BA28/HAVERD!BB28 -> 44.061069 | O24: 22 | Q24: ='[25]Impulse responses'!DK30 -> 0.1741948 | R24: ='[25]Impulse responses'!EN30 -> 2.0486787 | U24: 40817 | V24: =NA() -> #N/A | W24: =((HAVERM!J160/HAVERM!J148)-1)*100 -> 4.9073064 | X24: =((HAVERM!K157/HAVERM!K145)-1)*100 -> 8.0267559 | Y24: 0 | Z24: =HAVERM!H160/HAVERM!I160 -> 79.695431 | AA24: =(Z24/AVERAGE($Z$63:$Z$74))*100 -> 130.85882 | AD24: 44835 | AE24: ='BoE MPR - Chart 2.21'!D28 -> 6.2 | AF24: =HAVERM!L286 -> 5.573 | AJ24: =+AJ19+7 -> 43860 | AL24: =IF(HAVERD!H28="",AL23,AVERAGE(HAVERD!H28:Q28)) -> 31.61 | AZ24: 45931 | BA24: ='[26]CPI Forecast'!V363 -> 0.96235044 | BB24: ='[26]CPI Forecast'!AN363 -> 3.3689461 | BC24: 0.85340364 | BD24: 2.5013809 | BF24: 0 | BI24: 44470 | BJ24: ='[27]CPI Forecast'!D315 -> 4.2062117 | BK24: =NA() -> #N/A | BL24: =NA() -> #N/A | BM24: 2 | BP24: 20242 | BQ24: =LEFT(BP24,4) -> 2024 | BR24: ='[28]CPI Forecast'!AA602 -> 5.7581862 | BS24: 4.5638948 | BT24: 0
A25: 44501 | B25: ='[24]CPI Forecast'!D316 -> 5.1299005 | C25: =NA() -> #N/A | D25: =NA() -> #N/A | E25: =NA() -> #N/A | F25: 2 | H25: =+H24+7 -> 43990 | I25: =HAVERW!C30 -> 105.74 | J25: =HAVERW!D30 -> 111.98 | L25: =+L20+7 -> 43861 | M25: =HAVERD!BA29/HAVERD!BB29 -> 43.834889 | O25: 23 | Q25: ='[25]Impulse responses'!DK31 -> 0.16198201 | R25: ='[25]Impulse responses'!EN31 -> 2.0891742 | U25: 40848 | V25: =NA() -> #N/A | W25: =((HAVERM!J161/HAVERM!J149)-1)*100 -> 3.9742213 | X25: =((HAVERM!K158/HAVERM!K146)-1)*100 -> 7.5555556 | Y25: 0 | Z25: =HAVERM!H161/HAVERM!I161 -> 79.663376 | AA25: =(Z25/AVERAGE($Z$63:$Z$74))*100 -> 130.80618 | AD25: 44866 | AE25: ='BoE MPR - Chart 2.21'!D29 -> 6.7 | AF25: =HAVERM!L287 -> 5.899 | AJ25: =+AJ20+7 -> 43861 | AL25: =IF(HAVERD!H29="",AL24,AVERAGE(HAVERD!H29:Q29)) -> 32.048 | AZ25: 45962 | BA25: ='[26]CPI Forecast'!V364 -> 1.155022 | BB25: ='[26]CPI Forecast'!AN364 -> 3.0784852 | BC25: 0.85340364 | BD25: 2.5013809 | BF25: 0 | BI25: 44501 | BJ25: ='[27]CPI Forecast'!D316 -> 5.1299005 | BK25: =NA() -> #N/A | BL25: =NA() -> #N/A | BM25: 2 | BP25: 20243 | BQ25: =LEFT(BP25,4) -> 2024 | BR25: ='[28]CPI Forecast'!AA603 -> 5.2248195 | BS25: 4.4066047 | BT25: 0
A26: 44531 | B26: ='[24]CPI Forecast'!D317 -> 5.3860457 | C26: =NA() -> #N/A | D26: =NA() -> #N/A | E26: =NA() -> #N/A | F26: 2 | H26: =+H25+7 -> 43997 | I26: =HAVERW!C31 -> 106.37 | J26: =HAVERW!D31 -> 112.53 | L26: =+L21+7 -> 43864 | M26: =HAVERD!BA30/HAVERD!BB30 -> 41.496965 | O26: 24 | Q26: ='[25]Impulse responses'!DK32 -> 0.15062546 | R26: ='[25]Impulse responses'!EN32 -> 2.1268306 | U26: 40878 | V26: =NA() -> #N/A | W26: =((HAVERM!J162/HAVERM!J150)-1)*100 -> 3.6997886 | X26: =((HAVERM!K159/HAVERM!K147)-1)*100 -> 8.1291759 | Y26: 0 | Z26: =HAVERM!H162/HAVERM!I162 -> 78.216234 | AA26: =(Z26/AVERAGE($Z$63:$Z$74))*100 -> 128.43 | AD26: 44896 | AE26: ='BoE MPR - Chart 2.21'!D30 -> 6.8 | AF26: =HAVERM!L288 -> 6.046 | AJ26: =+AJ21+7 -> 43864 | AL26: =IF(HAVERD!H30="",AL25,AVERAGE(HAVERD!H30:Q30)) -> 31.264 | AZ26: 45992 | BA26: ='[26]CPI Forecast'!V365 -> 1.1539155 | BB26: ='[26]CPI Forecast'!AN365 -> 3.1671163 | BC26: 0.85340364 | BD26: 2.5013809 | BF26: 0 | BI26: 44531 | BJ26: ='[27]CPI Forecast'!D317 -> 5.3860457 | BK26: =NA() -> #N/A | BL26: =NA() -> #N/A | BM26: 2 | BP26: 20244 | BQ26: =LEFT(BP26,4) -> 2024 | BR26: ='[28]CPI Forecast'!AA604 -> 4.795296 | BS26: 5.9910132 | BT26: 0
A27: 44562 | B27: ='[24]CPI Forecast'!D318 -> 5.4555133 | C27: =NA() -> #N/A | D27: =NA() -> #N/A | E27: =NA() -> #N/A | F27: 2 | H27: =+H26+7 -> 44004 | I27: =HAVERW!C32 -> 107.13 | J27: =HAVERW!D32 -> 112.98 | L27: =+L22+7 -> 43865 | M27: =HAVERD!BA31/HAVERD!BB31 -> 41.381958 | O27: 25 | P27: 2031 | Q27: ='[25]Impulse responses'!DK33 -> 0.14006512 | R27: ='[25]Impulse responses'!EN33 -> 2.1618469 | U27: 40909 | V27: =((AA15/AA3)-1)*100 -> 34.488084 | W27: =((HAVERM!J163/HAVERM!J151)-1)*100 -> 3.4920635 | X27: =((HAVERM!K160/HAVERM!K148)-1)*100 -> 7.3951435 | Y27: 0 | Z27: =HAVERM!H163/HAVERM!I163 -> 78.787879 | AA27: =(Z27/AVERAGE($Z$63:$Z$74))*100 -> 129.36863 | AD27: 44927 | AE27: ='BoE MPR - Chart 2.21'!D31 -> 6.4 | AF27: =HAVERM!L289 -> 6.272 | AJ27: =+AJ22+7 -> 43865 | AL27: =IF(HAVERD!H31="",AL26,AVERAGE(HAVERD!H31:Q31)) -> 31.947 | AZ27: 46023 | BA27: ='[26]CPI Forecast'!V366 -> 1.1718623 | BB27: ='[26]CPI Forecast'!AN366 -> 3.2384129 | BC27: 0.85340364 | BD27: 2.5013809 | BF27: 0 | BI27: 44562 | BJ27: ='[27]CPI Forecast'!D318 -> 5.4555133 | BK27: =NA() -> #N/A | BL27: =NA() -> #N/A | BM27: 2 | BP27: 20251 | BQ27: =LEFT(BP27,4) -> 2025 | BR27: ='[28]CPI Forecast'!AA605 -> 4.7054626 | BS27: 5.6993959 | BT27: 0
A28: 44593 | B28: ='[24]CPI Forecast'!D319 -> 6.1766081 | C28: =NA() -> #N/A | D28: =NA() -> #N/A | E28: =NA() -> #N/A | F28: 2 | H28: =+H27+7 -> 44011 | I28: =HAVERW!C33 -> 108.31 | J28: =HAVERW!D33 -> 114.1 | L28: =+L23+7 -> 43866 | M28: =HAVERD!BA32/HAVERD!BB32 -> 42.637092 | O28: 26 | Q28: ='[25]Impulse responses'!DK34 -> 0.13024516 | R28: ='[25]Impulse responses'!EN34 -> 2.1944081 | U28: 40940 | V28: =((AA16/AA4)-1)*100 -> 34.243205 | W28: =((HAVERM!J164/HAVERM!J152)-1)*100 -> 3.6649215 | X28: =((HAVERM!K161/HAVERM!K149)-1)*100 -> 6.7833698 | Y28: 0 | Z28: =HAVERM!H164/HAVERM!I164 -> 79.29376 | AA28: =(Z28/AVERAGE($Z$63:$Z$74))*100 -> 130.19928 | AD28: 44958 | AE28: ='BoE MPR - Chart 2.21'!D32 -> 7.5 | AF28: =HAVERM!L290 -> 6.464 | AJ28: =+AJ23+7 -> 43866 | AL28: =IF(HAVERD!H32="",AL27,AVERAGE(HAVERD!H32:Q32)) -> 32.545 | AZ28: 46054 | BA28: ='[26]CPI Forecast'!V367 -> 1.1652859 | BB28: ='[26]CPI Forecast'!AN367 -> 3.246811 | BC28: 0.85340364 | BD28: 2.5013809 | BF28: 0 | BI28: 44593 | BJ28: ='[27]CPI Forecast'!D319 -> 6.1766081 | BK28: =NA() -> #N/A | BL28: =NA() -> #N/A | BM28: 2 | BP28: 20252 | BQ28: =LEFT(BP28,4) -> 2025 | BR28: ='[28]CPI Forecast'!AA606 -> 3.5468013 | BS28: 5.5549469 | BT28: 0
A29: 44621 | B29: ='[24]CPI Forecast'!D320 -> 7.023124 | C29: =NA() -> #N/A | D29: =NA() -> #N/A | E29: =NA() -> #N/A | F29: 2 | H29: =+H28+7 -> 44018 | I29: =HAVERW!C34 -> 109.43 | J29: =HAVERW!D34 -> 115.05 | L29: =+L24+7 -> 43867 | M29: =HAVERD!BA33/HAVERD!BB33 -> 42.679248 | O29: 27 | Q29: ='[25]Impulse responses'!DK35 -> 0.12111368 | R29: ='[25]Impulse responses'!EN35 -> 2.2246866 | U29: 40969 | V29: =((AA17/AA5)-1)*100 -> 29.64545 | W29: =((HAVERM!J165/HAVERM!J153)-1)*100 -> 4.5647558 | X29: =((HAVERM!K162/HAVERM!K150)-1)*100 -> 5.8504875 | Y29: 0 | Z29: =HAVERM!H165/HAVERM!I165 -> 79.44132 | AA29: =(Z29/AVERAGE($Z$63:$Z$74))*100 -> 130.44157 | AD29: 44986 | AE29: ='BoE MPR - Chart 2.21'!D33 -> 7.2 | AF29: =HAVERM!L291 -> 6.574 | AJ29: =+AJ24+7 -> 43867 | AL29: =IF(HAVERD!H33="",AL28,AVERAGE(HAVERD!H33:Q33)) -> 32.332 | AZ29: 46082 | BA29: ='[26]CPI Forecast'!V368 -> 1.1586351 | BB29: ='[26]CPI Forecast'!AN368 -> 3.2706631 | BC29: 0.85340364 | BD29: 2.5013809 | BF29: 0 | BI29: 44621 | BJ29: ='[27]CPI Forecast'!D320 -> 7.023124 | BK29: =NA() -> #N/A | BL29: =NA() -> #N/A | BM29: 2 | BP29: 20253 | BQ29: =LEFT(BP29,4) -> 2025 | BR29: ='[28]CPI Forecast'!AA607 -> 3.6082961 | BS29: 5.225741 | BT29: 0
A30: 44652 | B30: ='[24]CPI Forecast'!D321 -> 9.0106617 | C30: =NA() -> #N/A | D30: =NA() -> #N/A | E30: =NA() -> #N/A | F30: 2 | H30: =+H29+7 -> 44025 | I30: =HAVERW!C35 -> 111.24 | J30: =HAVERW!D35 -> 116.75 | L30: =+L25+7 -> 43868 | M30: =HAVERD!BA34/HAVERD!BB34 -> 42.143906 | O30: 28 | Q30: ='[25]Impulse responses'!DK36 -> 0.11262241 | R30: ='[25]Impulse responses'!EN36 -> 2.2528422 | U30: 41000 | V30: =((AA18/AA6)-1)*100 -> 31.739818 | W30: =((HAVERM!J166/HAVERM!J154)-1)*100 -> 4.3478261 | X30: =((HAVERM!K163/HAVERM!K151)-1)*100 -> 4.9145299 | Y30: 0 | Z30: =HAVERM!H166/HAVERM!I166 -> 77.682028 | AA30: =(Z30/AVERAGE($Z$63:$Z$74))*100 -> 127.55284 | AD30: 45017 | AE30: ='BoE MPR - Chart 2.21'!D34 -> 7.1 | AF30: =HAVERM!L292 -> 6.422 | AJ30: =+AJ25+7 -> 43868 | AL30: =IF(HAVERD!H34="",AL29,AVERAGE(HAVERD!H34:Q34)) -> 32.474 | AZ30: 46113 | BA30: ='[26]CPI Forecast'!V369 -> 1.1595054 | BB30: ='[26]CPI Forecast'!AN369 -> 3.1441456 | BC30: 0.85340364 | BD30: 2.5013809 | BF30: 0 | BI30: 44652 | BJ30: ='[27]CPI Forecast'!D321 -> 9.0106617 | BK30: =NA() -> #N/A | BL30: =NA() -> #N/A | BM30: 2 | BP30: 20254 | BQ30: =LEFT(BP30,4) -> 2025 | BR30: ='[28]CPI Forecast'!AA608 -> 3.8236673 | BS30: 4.0656286 | BT30: 0
A31: 44682 | B31: ='[24]CPI Forecast'!D322 -> 9.0827013 | C31: =NA() -> #N/A | D31: =NA() -> #N/A | E31: =NA() -> #N/A | F31: 2 | H31: =+H30+7 -> 44032 | I31: =HAVERW!C36 -> 112.23 | J31: =HAVERW!D36 -> 117.35 | L31: =+L26+7 -> 43871 | M31: =HAVERD!BA35/HAVERD!BB35 -> 41.313936 | O31: 29 | P31: 2032 | Q31: ='[25]Impulse responses'!DK37 -> 0.10472646 | R31: ='[25]Impulse responses'!EN37 -> 2.2790238 | U31: 41030 | V31: =((AA19/AA7)-1)*100 -> 25.66848 | W31: =((HAVERM!J167/HAVERM!J155)-1)*100 -> 3.3507853 | X31: =((HAVERM!K164/HAVERM!K152)-1)*100 -> 4.2372881 | Y31: 0 | Z31: =HAVERM!H167/HAVERM!I167 -> 74.819239 | AA31: =(Z31/AVERAGE($Z$63:$Z$74))*100 -> 122.85218 | AD31: 45047 | AE31: ='BoE MPR - Chart 2.21'!D35 -> 7.2 | AF31: =HAVERM!L293 -> 6.186 | AJ31: =+AJ26+7 -> 43871 | AL31: =IF(HAVERD!H35="",AL30,AVERAGE(HAVERD!H35:Q35)) -> 31.623 | AZ31: 46143 | BA31: ='[26]CPI Forecast'!V370 -> 1.1537379 | BB31: ='[26]CPI Forecast'!AN370 -> 2.9827404 | BC31: 0.85340364 | BD31: 2.5013809 | BF31: 0 | BI31: 44682 | BJ31: ='[27]CPI Forecast'!D322 -> 9.0827013 | BK31: =NA() -> #N/A | BL31: =NA() -> #N/A | BM31: 2 | BP31: 20261 | BQ31: =LEFT(BP31,4) -> 2026 | BR31: ='[28]CPI Forecast'!AA609 -> 4.1016154 | BS31: 3.4308593 | BT31: 0
A32: 44713 | B32: ='[24]CPI Forecast'!D323 -> 9.4121135 | C32: =NA() -> #N/A | D32: =NA() -> #N/A | E32: =NA() -> #N/A | F32: 2 | H32: =+H31+7 -> 44039 | I32: =HAVERW!C37 -> 112.66 | J32: =HAVERW!D37 -> 117.76 | L32: =+L27+7 -> 43872 | M32: =HAVERD!BA36/HAVERD!BB36 -> 41.714948 | O32: 30 | Q32: ='[25]Impulse responses'!DK38 -> 0.097384096 | R32: ='[25]Impulse responses'!EN38 -> 2.3033698 | U32: 41061 | V32: =((AA20/AA8)-1)*100 -> 27.966678 | W32: =((HAVERM!J168/HAVERM!J156)-1)*100 -> 2.1761658 | X32: =((HAVERM!K165/HAVERM!K153)-1)*100 -> 4.2105263 | Y32: 0 | Z32: =HAVERM!H168/HAVERM!I168 -> 74.369019 | AA32: =(Z32/AVERAGE($Z$63:$Z$74))*100 -> 122.11292 | AD32: 45078 | AE32: ='BoE MPR - Chart 2.21'!D36 -> 7.1 | AF32: =HAVERM!L294 -> 5.904 | AJ32: =+AJ27+7 -> 43872 | AL32: =IF(HAVERD!H36="",AL31,AVERAGE(HAVERD!H36:Q36)) -> 31.567 | AZ32: 46174 | BA32: ='[26]CPI Forecast'!V371 -> 1.1555319 | BB32: ='[26]CPI Forecast'!AN371 -> 2.8290204 | BC32: 0.85340364 | BD32: 2.5013809 | BF32: 0 | BI32: 44713 | BJ32: ='[27]CPI Forecast'!D323 -> 9.4121135 | BK32: =NA() -> #N/A | BL32: =NA() -> #N/A | BM32: 2 | BP32: 20262 | BQ32: =LEFT(BP32,4) -> 2026 | BR32: ='[28]CPI Forecast'!AA610 -> 3.9247882 | BS32: 2.911259 | BT32: 0
A33: 44743 | B33: ='[24]CPI Forecast'!D324 -> 10.100901 | C33: =NA() -> #N/A | D33: =NA() -> #N/A | E33: =NA() -> #N/A | F33: 2 | H33: =+H32+7 -> 44046 | I33: =HAVERW!C38 -> 112.91 | J33: =HAVERW!D38 -> 117.97 | L33: =+L28+7 -> 43873 | M33: =HAVERD!BA37/HAVERD!BB37 -> 42.805395 | O33: 31 | Q33: ='[25]Impulse responses'!DK39 -> 0.090556503 | R33: ='[25]Impulse responses'!EN39 -> 2.3260089 | U33: 41091 | V33: =((AA21/AA9)-1)*100 -> 26.030784 | W33: =((HAVERM!J169/HAVERM!J157)-1)*100 -> 2.1716649 | X33: =((HAVERM!K166/HAVERM!K154)-1)*100 -> 3.7656904 | Y33: 0 | Z33: =HAVERM!H169/HAVERM!I169 -> 78.260312 | AA33: =(Z33/AVERAGE($Z$63:$Z$74))*100 -> 128.50237 | AD33: 45108 | AE33: ='BoE MPR - Chart 2.21'!D37 -> 6.7 | AF33: =HAVERM!L295 -> 5.764 | AJ33: =+AJ28+7 -> 43873 | AL33: =IF(HAVERD!H37="",AL32,AVERAGE(HAVERD!H37:Q37)) -> 32.284 | AZ33: 46204 | BA33: ='[26]CPI Forecast'!V372 -> 1.1825363 | BB33: ='[26]CPI Forecast'!AN372 -> 2.6459875 | BC33: 0.85340364 | BD33: 2.5013809 | BF33: 0 | BI33: 44743 | BJ33: ='[27]CPI Forecast'!D324 -> 10.100901 | BK33: =NA() -> #N/A | BL33: =NA() -> #N/A | BM33: 2 | BP33: 20263 | BQ33: =LEFT(BP33,4) -> 2026 | BR33: ='[28]CPI Forecast'!AA611 -> 3.7535341 | BS33: 2.788756 | BT33: 0
A34: 44774 | B34: ='[24]CPI Forecast'!D325 -> 9.8701878 | C34: =NA() -> #N/A | D34: =NA() -> #N/A | E34: =NA() -> #N/A | F34: 2 | H34: =+H33+7 -> 44053 | I34: =HAVERW!C39 -> 113.02 | J34: =HAVERW!D39 -> 118.01 | L34: =+L29+7 -> 43874 | M34: =HAVERD!BA38/HAVERD!BB38 -> 43.155879 | O34: 32 | Q34: ='[25]Impulse responses'!DK40 -> 0.084207593 | R34: ='[25]Impulse responses'!EN40 -> 2.3470608 | U34: 41122 | V34: =((AA22/AA10)-1)*100 -> 17.917779 | W34: =((HAVERM!J170/HAVERM!J158)-1)*100 -> 2.1671827 | X34: =((HAVERM!K167/HAVERM!K155)-1)*100 -> 3.5379813 | Y34: 0 | Z34: =HAVERM!H170/HAVERM!I170 -> 78.376487 | AA34: =(Z34/AVERAGE($Z$63:$Z$74))*100 -> 128.69313 | AD34: 45139 | AE34: ='BoE MPR - Chart 2.21'!D38 -> 6.5 | AF34: =HAVERM!L296 -> 5.65 | AJ34: =+AJ29+7 -> 43874 | AL34: =IF(HAVERD!H38="",AL33,AVERAGE(HAVERD!H38:Q38)) -> 32.695 | AZ34: 46235 | BA34: ='[26]CPI Forecast'!V373 -> 1.1625584 | BB34: ='[26]CPI Forecast'!AN373 -> 2.5042719 | BC34: 0.85340364 | BD34: 2.5013809 | BF34: 0 | BI34: 44774 | BJ34: ='[27]CPI Forecast'!D325 -> 9.8701878 | BK34: =NA() -> #N/A | BL34: =NA() -> #N/A | BM34: 2 | BP34: 20264 | BQ34: =LEFT(BP34,4) -> 2026 | BR34: ='[28]CPI Forecast'!AA612 -> 3.677327 | BS34: 2.7377058 | BT34: 0
A35: 44805 | B35: ='[24]CPI Forecast'!D326 -> 10.095628 | C35: =NA() -> #N/A | D35: =NA() -> #N/A | E35: =NA() -> #N/A | F35: 2 | H35: =+H34+7 -> 44060 | I35: =HAVERW!C40 -> 113.04 | J35: =HAVERW!D40 -> 118 | L35: =+L30+7 -> 43875 | M35: =HAVERD!BA39/HAVERD!BB39 -> 44.076521 | O35: 33 | P35: 2033 | Q35: ='[25]Impulse responses'!DK41 -> 0.078303804 | R35: ='[25]Impulse responses'!EN41 -> 2.3666368 | U35: 41153 | V35: =((AA23/AA11)-1)*100 -> 12.541784 | W35: =((HAVERM!J171/HAVERM!J159)-1)*100 -> 1.9567456 | X35: =((HAVERM!K168/HAVERM!K156)-1)*100 -> 2.9015544 | Y35: 0 | Z35: =HAVERM!H171/HAVERM!I171 -> 77.624721 | AA35: =(Z35/AVERAGE($Z$63:$Z$74))*100 -> 127.45874 | AD35: 45170 | AE35: ='BoE MPR - Chart 2.21'!D39 -> 6.6 | AF35: =HAVERM!L297 -> 5.492 | AJ35: =+AJ30+7 -> 43875 | AL35: =IF(HAVERD!H39="",AL34,AVERAGE(HAVERD!H39:Q39)) -> 33.108 | AZ35: 46266 | BA35: ='[26]CPI Forecast'!V374 -> 1.1374184 | BB35: ='[26]CPI Forecast'!AN374 -> 2.3710297 | BC35: 0.85340364 | BD35: 2.5013809 | BF35: 0 | BI35: 44805 | BJ35: ='[27]CPI Forecast'!D326 -> 10.095628 | BK35: =NA() -> #N/A | BL35: =NA() -> #N/A | BM35: 2 | BP35: 20271 | BQ35: =LEFT(BP35,4) -> 2027 | BR35: ='[28]CPI Forecast'!AA613 -> 3.6428281 | BS35: 2.6525913 | BT35: 0
A36: 44835 | B36: ='[24]CPI Forecast'!D327 -> 11.051566 | C36: =NA() -> #N/A | D36: =NA() -> #N/A | E36: =NA() -> #N/A | F36: 2 | H36: =+H35+7 -> 44067 | I36: =HAVERW!C41 -> 113.22 | J36: =HAVERW!D41 -> 118.14 | L36: =+L31+7 -> 43878 | M36: =HAVERD!BA40/HAVERD!BB40 -> 44.464093 | O36: 34 | Q36: ='[25]Impulse responses'!DK42 -> 0.072813929 | R36: ='[25]Impulse responses'!EN42 -> 2.3848403 | U36: 41183 | V36: =((AA24/AA12)-1)*100 -> 5.2563642 | W36: =((HAVERM!J172/HAVERM!J160)-1)*100 -> 3.4303534 | X36: =((HAVERM!K169/HAVERM!K157)-1)*100 -> 2.6831785 | Y36: 0 | Z36: =HAVERM!H172/HAVERM!I172 -> 77.119224 | AA36: =(Z36/AVERAGE($Z$63:$Z$74))*100 -> 126.62872 | AD36: 45200 | AE36: ='BoE MPR - Chart 2.21'!D40 -> 6.4 | AF36: =HAVERM!L298 -> 5.545 | AJ36: =+AJ31+7 -> 43878 | AL36: =IF(HAVERD!H40="",AL35,AVERAGE(HAVERD!H40:Q40)) -> 34.343 | AZ36: 46296 | BA36: ='[26]CPI Forecast'!V375 -> 1.1367631 | BB36: ='[26]CPI Forecast'!AN375 -> 2.2152762 | BC36: 0.85340364 | BD36: 2.5013809 | BF36: 0 | BI36: 44835 | BJ36: ='[27]CPI Forecast'!D327 -> 11.051566 | BK36: =NA() -> #N/A | BL36: =NA() -> #N/A | BM36: 2 | BP36: 20272 | BQ36: =LEFT(BP36,4) -> 2027 | BR36: ='[28]CPI Forecast'!AA614 -> 3.5743155 | BS36: 2.5922215 | BT36: 0
A37: 44866 | B37: ='[24]CPI Forecast'!D328 -> 10.672013 | C37: =NA() -> #N/A | D37: =NA() -> #N/A | E37: =NA() -> #N/A | F37: 2 | H37: =+H36+7 -> 44074 | I37: =HAVERW!C42 -> 113.29 | J37: =HAVERW!D42 -> 118.18 | L37: =+L32+7 -> 43879 | M37: =HAVERD!BA41/HAVERD!BB41 -> 43.990182 | O37: 35 | Q37: ='[25]Impulse responses'!DK43 -> 0.067708949 | R37: ='[25]Impulse responses'!EN43 -> 2.4017675 | U37: 41214 | V37: =((AA25/AA13)-1)*100 -> 2.375777 | W37: =((HAVERM!J173/HAVERM!J161)-1)*100 -> 3.9256198 | X37: =((HAVERM!K170/HAVERM!K158)-1)*100 -> 3.0991736 | Y37: 0 | Z37: =HAVERM!H173/HAVERM!I173 -> 77.376104 | AA37: =(Z37/AVERAGE($Z$63:$Z$74))*100 -> 127.05051 | AD37: 45231 | AE37: ='BoE MPR - Chart 2.21'!D41 -> 5.7 | AF37: =HAVERM!L299 -> 5.444 | AJ37: =+AJ32+7 -> 43879 | AL37: =IF(HAVERD!H41="",AL36,AVERAGE(HAVERD!H41:Q41)) -> 33.835 | AZ37: 46327 | BA37: ='[26]CPI Forecast'!V376 -> 1.1225308 | BB37: ='[26]CPI Forecast'!AN376 -> 2.0715836 | BC37: 0.85340364 | BD37: 2.5013809 | BF37: 0 | BI37: 44866 | BJ37: ='[27]CPI Forecast'!D328 -> 10.672013 | BK37: =NA() -> #N/A | BL37: =NA() -> #N/A | BM37: 2 | BP37: 20273 | BQ37: =LEFT(BP37,4) -> 2027 | BR37: ='[28]CPI Forecast'!AA615 -> 3.52096 | BS37: 2.5478114 | BT37: 0
A38: 44896 | B38: ='[24]CPI Forecast'!D329 -> 10.528374 | C38: =NA() -> #N/A | D38: =NA() -> #N/A | E38: =NA() -> #N/A | F38: 2 | H38: =+H37+7 -> 44081 | I38: =HAVERW!C43 -> 113.37 | J38: =HAVERW!D43 -> 118.22 | L38: =+L33+7 -> 43880 | M38: =HAVERD!BA42/HAVERD!BB42 -> 46.112269 | O38: 36 | Q38: ='[25]Impulse responses'!DK44 -> 0.062961879 | R38: ='[25]Impulse responses'!EN44 -> 2.417508 | U38: 41244 | V38: =((AA26/AA14)-1)*100 -> -5.6871799 | W38: =((HAVERM!J174/HAVERM!J162)-1)*100 -> 3.7716616 | X38: =((HAVERM!K171/HAVERM!K159)-1)*100 -> 2.9866117 | Y38: 0 | Z38: =HAVERM!H174/HAVERM!I174 -> 76.065411 | AA38: =(Z38/AVERAGE($Z$63:$Z$74))*100 -> 124.89837 | AD38: 45261 | AE38: ='BoE MPR - Chart 2.21'!D42 -> 5.8 | AF38: =HAVERM!L300 -> 5.297 | AJ38: =+AJ33+7 -> 43880 | AL38: =IF(HAVERD!H42="",AL37,AVERAGE(HAVERD!H42:Q42)) -> 33.529 | AZ38: 46357 | BA38: ='[26]CPI Forecast'!V377 -> 1.1124769 | BB38: ='[26]CPI Forecast'!AN377 -> 1.9244644 | BC38: 0.85340364 | BD38: 2.5013809 | BF38: 0 | BI38: 44896 | BJ38: ='[27]CPI Forecast'!D329 -> 10.528374 | BK38: =NA() -> #N/A | BL38: =NA() -> #N/A | BM38: 2 | BP38: 20274 | BQ38: =LEFT(BP38,4) -> 2027 | BR38: ='[28]CPI Forecast'!AA616 -> 3.4518878 | BS38: 2.5453632 | BT38: 0
A39: 44927 | B39: ='[24]CPI Forecast'!D330 -> 10.051524 | C39: =NA() -> #N/A | D39: =NA() -> #N/A | E39: =NA() -> #N/A | F39: 2 | H39: =+H38+7 -> 44088 | I39: =HAVERW!C44 -> 113.32 | J39: =HAVERW!D44 -> 118.18 | L39: =+L34+7 -> 43881 | M39: =HAVERD!BA43/HAVERD!BB43 -> 46.36286 | O39: 37 | P39: 2034 | Q39: ='[25]Impulse responses'!DK45 -> 0.058547626 | R39: ='[25]Impulse responses'!EN45 -> 2.4321449 | U39: 41275 | V39: =((AA27/AA15)-1)*100 -> -6.9914391 | W39: =((HAVERM!J175/HAVERM!J163)-1)*100 -> 4.192229 | X39: =((HAVERM!K172/HAVERM!K160)-1)*100 -> 3.1860226 | Y39: 0 | Z39: =HAVERM!H175/HAVERM!I175 -> 77.332832 | AA39: =(Z39/AVERAGE($Z$63:$Z$74))*100 -> 126.97946 | AD39: 45292 | AE39: ='BoE MPR - Chart 2.21'!D43 -> 6.3 | AF39: =HAVERM!L301 -> 5.175 | AJ39: =+AJ34+7 -> 43881 | AL39: =IF(HAVERD!H43="",AL38,AVERAGE(HAVERD!H43:Q43)) -> 33.237 | BI39: 44927 | BJ39: ='[27]CPI Forecast'!D330 -> 10.051524 | BK39: =NA() -> #N/A | BL39: =NA() -> #N/A | BM39: 2
A40: 44958 | B40: ='[24]CPI Forecast'!D331 -> 10.416397 | C40: =NA() -> #N/A | D40: =NA() -> #N/A | E40: =NA() -> #N/A | F40: 2 | H40: =+H39+7 -> 44095 | I40: =HAVERW!C45 -> 113.31 | J40: =HAVERW!D45 -> 118.16 | L40: =+L35+7 -> 43882 | M40: =HAVERD!BA44/HAVERD!BB44 -> 45.209073 | O40: 38 | Q40: ='[25]Impulse responses'!DK46 -> 0.054442855 | R40: ='[25]Impulse responses'!EN46 -> 2.4457556 | U40: 41306 | V40: =((AA28/AA16)-1)*100 -> -7.1163142 | W40: =((HAVERM!J176/HAVERM!J164)-1)*100 -> 3.6363636 | X40: =((HAVERM!K173/HAVERM!K161)-1)*100 -> 3.2786885 | Y40: 0 | Z40: =HAVERM!H176/HAVERM!I176 -> 79.661455 | AA40: =(Z40/AVERAGE($Z$63:$Z$74))*100 -> 130.80303 | AD40: 45323 | AE40: ='BoE MPR - Chart 2.21'!D44 -> 5.2 | AF40: =HAVERM!L302 -> 4.977 | AJ40: =+AJ35+7 -> 43882 | AL40: =IF(HAVERD!H44="",AL39,AVERAGE(HAVERD!H44:Q44)) -> 32.786 | BI40: 44958 | BJ40: ='[27]CPI Forecast'!D331 -> 10.416397 | BK40: =NA() -> #N/A | BL40: =NA() -> #N/A | BM40: 2
...

Sheet Data >>>

Sheet HAVERW
B1: 20200101W !W | C1: P112GPU@INTWKLY | D1: P112GPD@INTWKLY
B2: .DESC | C2: United Kingdom: Pump Price: Ultra Low Sulfur Unleaded Petrol (Pence/Liter) | D2: United Kingdom: Pump Price: Ultra Low Sulfur Diesel (Pence/Liter)
B3: .T1 | C3: 09-Jun-2003W | D3: 09-Jun-2003W
B4: .TN | C4: 03-Mar-2025W | D4: 03-Mar-2025W
B5: .LSOURCE | C5: UK Department of Energy & Climate Change | D5: UK Department of Energy & Climate Change
B6: .DTLM | C6: Mar-04-2025 10:01 | D6: Mar-04-2025 10:01
A7: 43829 | B7: 20191230W | C7: 124.96 | D7: 130.54
A8: =+A7+7 -> 43836 | B8: 20200106W | C8: 126.09 | D8: 131.56
A9: =+A8+7 -> 43843 | B9: 20200113W | C9: 127.17 | D9: 132.69
A10: =+A9+7 -> 43850 | B10: 20200120W | C10: 127.18 | D10: 132.74
A11: =+A10+7 -> 43857 | B11: 20200127W | C11: 127.33 | D11: 132.88
A12: =+A11+7 -> 43864 | B12: 20200203W | C12: 125.85 | D12: 131.48
A13: =+A12+7 -> 43871 | B13: 20200210W | C13: 124.73 | D13: 129.7
A14: =+A13+7 -> 43878 | B14: 20200217W | C14: 123.8 | D14: 128.2
A15: =+A14+7 -> 43885 | B15: 20200224W | C15: 123.45 | D15: 127.67
A16: =+A15+7 -> 43892 | B16: 20200302W | C16: 122.43 | D16: 126.62
A17: =+A16+7 -> 43899 | B17: 20200309W | C17: 122.24 | D17: 126.25
A18: =+A17+7 -> 43906 | B18: 20200316W | C18: 120.33 | D18: 124.36
A19: =+A18+7 -> 43913 | B19: 20200323W | C19: 119.64 | D19: 123.41
... A277: =+A276+7 -> 45719 | B277: 20250303W | C277: 139.61 | D277: 146.88

Sheet HAVERD
B1: 20200101 !D | D1: IFNG01C@CMDTY | E1: IFNG02C@CMDTY | F1: IFNG03C@CMDTY | G1: IFNG04C@CMDTY | H1: IFNG05C@CMDTY | I1: IFNG06C@CMDTY | J1: IFNG07C@CMDTY | K1: IFNG08C@CMDTY | L1: IFNG09C@CMDTY | M1: IFNG10C@CMDTY | N1: IFNG11C@CMDTY | O1: IFNG12C@CMDTY | P1: IFNG13C@CMDTY | Q1: IFNG14C@CMDTY | R1: IFNG15C@CMDTY | S1: IFNG16C@CMDTY | T1: IFNG17C@CMDTY | U1: IFNG18C@CMDTY | V1: IFNG19C@CMDTY | W1: IFNG20C@CMDTY | X1: IFNG21C@CMDTY | Y1: IFNG22C@CMDTY | Z1: IFNG23C@CMDTY | AA1: IFNG24C@CMDTY | AB1: IFNG25C@CMDTY | AC1: IFNG26C@CMDTY | AD1: IFNG27C@CMDTY | AE1: IFNG28C@CMDTY | AF1: IFNG29C@CMDTY | AG1: IFNG30C@CMDTY | AH1: IFNG31C@CMDTY | AI1: IFNG32C@CMDTY | AJ1: IFNG33C@CMDTY | AK1: IFNG34C@CMDTY | AL1: IFNG35C@CMDTY | AM1: IFNG36C@CMDTY | AN1: IFNG37C@CMDTY | AO1: IFNG38C@CMDTY | AP1: IFNG39C@CMDTY | AQ1: IFNG40C@CMDTY | AR1: IFNG41C@CMDTY | AS1: IFNG42C@CMDTY | AT1: IFNG43C@CMDTY | AU1: IFNG44C@CMDTY | AV1: IFNG45C@CMDTY | AW1: IFNG46C@CMDTY | AX1: IFNG47C@CMDTY | AY1: IFNG48C@CMDTY | BA1: PEBRT@DAILY | BB1: X112USB@INTDAILY
B2: .DESC | D2: ICE UK Natural Gas Futures: 1st Position: Settlement Price (Sterling/Therm) | E2: ICE UK Natural Gas Futures: 2nd Position: Settlement Price (Sterling/Therm) | F2: ICE UK Natural Gas Futures: 3rd Position: Settlement Price (Sterling/Therm) | G2: ICE UK Natural Gas Futures: 4th Position: Settlement Price (Sterling/Therm) | H2: ICE UK Natural Gas Futures: 5th Position: Settlement Price (Sterling/Therm) | I2: ICE UK Natural Gas Futures: 6th Position: Settlement Price (Sterling/Therm) | J2: ICE UK Natural Gas Futures: 7th Position: Settlement Price (Sterling/Therm) | K2: ICE UK Natural Gas Futures: 8th Position: Settlement Price (Sterling/Therm) | L2: ICE UK Natural Gas Futures: 9th Position: Settlement Price (Sterling/Therm) | M2: ICE UK Natural Gas Futures: 10th Position: Settlement Price (Sterling/Therm) | N2: ICE UK Natural Gas Futures: 11th Position: Settlement Price (Sterling/Therm) | O2: ICE UK Natural Gas Futures: 12th Position: Settlement Price (Sterling/Therm) | P2: ICE UK Natural Gas Futures: 13th Position: Settlement Price (Sterling/Therm) | Q2: ICE UK Natural Gas Futures: 14th Position: Settlement Price (Sterling/Therm) | R2: ICE UK Natural Gas Futures: 15th Position: Settlement Price (Sterling/Therm) | S2: ICE UK Natural Gas Futures: 16th Position: Settlement Price (Sterling/Therm) | T2: ICE UK Natural Gas Futures: 17th Position: Settlement Price (Sterling/Therm) | U2: ICE UK Natural Gas Futures: 18th Position: Settlement Price (Sterling/Therm) | V2: ICE UK Natural Gas Future: 19th Position: Settlement Price (Sterling/Therm) | W2: ICE UK Natural Gas Future: 20th Position: Settlement Price (Sterling/Therm) | X2: ICE UK Natural Gas Future: 21st Position: Settlement Price (Sterling/Therm) | Y2: ICE UK Natural Gas Future: 22nd Position: Settlement Price (Sterling/Therm) | Z2: ICE UK Natural Gas Future: 23rd Position: Settlement Price (Sterling/Therm) | AA2: ICE UK Natural Gas Future: 24th Position: Settlement Price (Sterling/Therm) | AB2: ICE UK Natural Gas Future: 25th Position: Settlement Price (Sterling/Therm) | AC2: ICE UK Natural Gas Future: 26th Position: Settlement Price (Sterling/Therm) | AD2: ICE UK Natural Gas Future: 27th Position: Settlement Price (Sterling/Therm) | AE2: ICE UK Natural Gas Future: 28th Position: Settlement Price (Sterling/Therm) | AF2: ICE UK Natural Gas Future: 29th Position: Settlement Price (Sterling/Therm) | AG2: ICE UK Natural Gas Future: 30th Position: Settlement Price (Sterling/Therm) | AH2: ICE UK Natural Gas Future: 31st Position: Settlement Price (Sterling/Therm) | AI2: ICE UK Natural Gas Future: 32nd Position: Settlement Price (Sterling/Therm) | AJ2: ICE UK Natural Gas Future: 33rd Position: Settlement Price (Sterling/Therm) | AK2: ICE UK Natural Gas Future: 34th Position: Settlement Price (Sterling/Therm) | AL2: ICE UK Natural Gas Future: 35th Position: Settlement Price (Sterling/Therm) | AM2: ICE UK Natural Gas Future: 36th Position: Settlement Price (Sterling/Therm) | AN2: ICE UK Natural Gas Future: 37th Position: Settlement Price (Sterling/Therm) | AO2: ICE UK Natural Gas Future: 38th Position: Settlement Price (Sterling/Therm) | AP2: ICE UK Natural Gas Future: 39th Position: Settlement Price (Sterling/Therm) | AQ2: ICE UK Natural Gas Future: 40th Position: Settlement Price (Sterling/Therm) | AR2: ICE UK Natural Gas Future: 41st Position: Settlement Price (Sterling/Therm) | AS2: ICE UK Natural Gas Future: 42nd Position: Settlement Price (Sterling/Therm) | AT2: ICE UK Natural Gas Future: 43rd Position: Settlement Price (Sterling/Therm) | AU2: ICE UK Natural Gas Future: 44th Position: Settlement Price (Sterling/Therm) | AV2: ICE UK Natural Gas Future: 45th Position: Settlement Price (Sterling/Therm) | AW2: ICE UK Natural Gas Future: 46th Position: Settlement Price (Sterling/Therm) | AX2: ICE UK Natural Gas Future: 47th Position: Settlement Price (Sterling/Therm) | AY2: ICE UK Natural Gas Future: 48th Position: Settlement Price (Sterling/Therm) | BA2: Europe Brent Spot Price FOB (US$ per Barrel) | BB2: UK: Spot Exchange Rate: US Dollar (US$/GBP)
B3: .T1 | D3: 31-Jan-1997 | E3: 31-Jan-1997 | F3: 31-Jan-1997 | G3: 31-Jan-1997 | H3: 31-Jan-1997 | I3: 31-Jan-1997 | J3: 31-Jan-1997 | K3: 31-Jan-1997 | L3: 31-Jan-1997 | M3: 31-Jan-1997 | N3: 31-Jan-1997 | O3: 29-Jun-2004 | P3: 28-Feb-2007 | Q3: 11-Apr-2008 | R3: 11-Apr-2008 | S3: 11-Apr-2008 | T3: 11-Apr-2008 | U3: 30-May-2008 | V3: 16-Aug-2010 | W3: 16-Aug-2010 | X3: 16-Aug-2010 | Y3: 16-Aug-2010 | Z3: 16-Aug-2010 | AA3: 16-Aug-2010 | AB3: 16-Aug-2010 | AC3: 16-Aug-2010 | AD3: 16-Aug-2010 | AE3: 16-Aug-2010 | AF3: 16-Aug-2010 | AG3: 16-Aug-2010 | AH3: 16-Aug-2010 | AI3: 16-Aug-2010 | AJ3: 16-Aug-2010 | AK3: 16-Aug-2010 | AL3: 16-Aug-2010 | AM3: 16-Aug-2010 | AN3: 16-Aug-2010 | AO3: 16-Aug-2010 | AP3: 16-Aug-2010 | AQ3: 16-Aug-2010 | AR3: 16-Aug-2010 | AS3: 16-Aug-2010 | AT3: 16-Aug-2010 | AU3: 16-Aug-2010 | AV3: 16-Aug-2010 | AW3: 16-Aug-2010 | AX3: 16-Aug-2010 | AY3: 16-Aug-2010 | BA3: 21-May-1986 | BB3: 02-Jan-1975
B4: .TN | D4: 06-Mar-2025 | E4: 06-Mar-2025 | F4: 06-Mar-2025 | G4: 06-Mar-2025 | H4: 06-Mar-2025 | I4: 06-Mar-2025 | J4: 06-Mar-2025 | K4: 06-Mar-2025 | L4: 06-Mar-2025 | M4: 06-Mar-2025 | N4: 06-Mar-2025 | O4: 06-Mar-2025 | P4: 06-Mar-2025 | Q4: 06-Mar-2025 | R4: 06-Mar-2025 | S4: 06-Mar-2025 | T4: 06-Mar-2025 | U4: 06-Mar-2025 | V4: 06-Mar-2025 | W4: 06-Mar-2025 | X4: 06-Mar-2025 | Y4: 06-Mar-2025 | Z4: 06-Mar-2025 | AA4: 06-Mar-2025 | AB4: 06-Mar-2025 | AC4: 06-Mar-2025 | AD4: 06-Mar-2025 | AE4: 06-Mar-2025 | AF4: 06-Mar-2025 | AG4: 06-Mar-2025 | AH4: 06-Mar-2025 | AI4: 06-Mar-2025 | AJ4: 06-Mar-2025 | AK4: 06-Mar-2025 | AL4: 06-Mar-2025 | AM4: 06-Mar-2025 | AN4: 06-Mar-2025 | AO4: 06-Mar-2025 | AP4: 06-Mar-2025 | AQ4: 06-Mar-2025 | AR4: 06-Mar-2025 | AS4: 06-Mar-2025 | AT4: 06-Mar-2025 | AU4: 06-Mar-2025 | AV4: 06-Mar-2025 | AW4: 06-Mar-2025 | AX4: 06-Mar-2025 | AY4: 06-Mar-2025 | BA4: 05-Mar-2025 | BB4: 06-Mar-2025
B5: .LSOURCE | D5: IntercontinentalExchange | E5: IntercontinentalExchange | F5: IntercontinentalExchange | G5: IntercontinentalExchange | H5: IntercontinentalExchange | I5: IntercontinentalExchange | J5: IntercontinentalExchange | K5: IntercontinentalExchange | L5: IntercontinentalExchange | M5: IntercontinentalExchange | N5: IntercontinentalExchange | O5: IntercontinentalExchange | P5: IntercontinentalExchange | Q5: IntercontinentalExchange | R5: IntercontinentalExchange | S5: IntercontinentalExchange | T5: IntercontinentalExchange | U5: IntercontinentalExchange | V5: IntercontinentalExchange | W5: IntercontinentalExchange | X5: IntercontinentalExchange | Y5: IntercontinentalExchange | Z5: IntercontinentalExchange | AA5: IntercontinentalExchange | AB5: IntercontinentalExchange | AC5: IntercontinentalExchange | AD5: IntercontinentalExchange | AE5: IntercontinentalExchange | AF5: IntercontinentalExchange | AG5: IntercontinentalExchange | AH5: IntercontinentalExchange | AI5: IntercontinentalExchange | AJ5: IntercontinentalExchange | AK5: IntercontinentalExchange | AL5: IntercontinentalExchange | AM5: IntercontinentalExchange | AN5: IntercontinentalExchange | AO5: IntercontinentalExchange | AP5: IntercontinentalExchange | AQ5: IntercontinentalExchange | AR5: IntercontinentalExchange | AS5: IntercontinentalExchange | AT5: IntercontinentalExchange | AU5: IntercontinentalExchange | AV5: IntercontinentalExchange | AW5: IntercontinentalExchange | AX5: IntercontinentalExchange | AY5: IntercontinentalExchange | BA5: Energy Information Administration | BB5: Bank of England
B6: .DTLM | D6: Mar-07-2025 03:19 | E6: Mar-07-2025 03:19 | F6: Mar-07-2025 03:19 | G6: Mar-07-2025 03:19 | H6: Mar-07-2025 03:19 | I6: Mar-07-2025 03:19 | J6: Mar-07-2025 03:19 | K6: Mar-07-2025 03:19 | L6: Mar-07-2025 03:19 | M6: Mar-07-2025 03:19 | N6: Mar-07-2025 03:19 | O6: Mar-07-2025 03:19 | P6: Mar-07-2025 03:19 | Q6: Mar-07-2025 03:19 | R6: Mar-07-2025 03:19 | S6: Mar-07-2025 03:19 | T6: Mar-07-2025 03:19 | U6: Mar-07-2025 03:19 | V6: Mar-07-2025 03:19 | W6: Mar-07-2025 03:19 | X6: Mar-07-2025 03:19 | Y6: Mar-07-2025 03:19 | Z6: Mar-07-2025 03:19 | AA6: Mar-07-2025 03:19 | AB6: Mar-07-2025 03:19 | AC6: Mar-07-2025 03:19 | AD6: Mar-07-2025 03:19 | AE6: Mar-07-2025 03:19 | AF6: Mar-07-2025 03:19 | AG6: Mar-07-2025 03:19 | AH6: Mar-07-2025 03:19 | AI6: Mar-07-2025 03:19 | AJ6: Mar-07-2025 03:19 | AK6: Mar-07-2025 03:19 | AL6: Mar-07-2025 03:19 | AM6: Mar-07-2025 03:19 | AN6: Mar-07-2025 03:19 | AO6: Mar-07-2025 03:19 | AP6: Mar-07-2025 03:19 | AQ6: Mar-07-2025 03:19 | AR6: Mar-07-2025 03:19 | AS6: Mar-07-2025 03:19 | AT6: Mar-07-2025 03:19 | AU6: Mar-07-2025 03:19 | AV6: Mar-07-2025 03:19 | AW6: Mar-07-2025 03:19 | AX6: Mar-07-2025 03:19 | AY6: Mar-07-2025 03:19 | BA6: Mar-06-2025 13:02 | BB6: Mar-07-2025 09:31
A7: 43831 | B7: 20200101 | C7: 43831 | D7: #N/A | E7: #N/A | F7: #N/A | G7: #N/A | H7: #N/A | I7: #N/A | J7: #N/A | K7: #N/A | L7: #N/A | M7: #N/A | N7: #N/A | O7: #N/A | P7: #N/A | Q7: #N/A | R7: #N/A | S7: #N/A | T7: #N/A | U7: #N/A | V7: #N/A | W7: #N/A | X7: #N/A | Y7: #N/A | Z7: #N/A | AA7: #N/A | AB7: #N/A | AC7: #N/A | AD7: #N/A | AE7: #N/A | AF7: #N/A | AG7: #N/A | AH7: #N/A | AI7: #N/A | AJ7: #N/A | AK7: #N/A | AL7: #N/A | AM7: #N/A | AN7: #N/A | AO7: #N/A | AP7: #N/A | AQ7: #N/A | AR7: #N/A | AS7: #N/A | AT7: #N/A | AU7: #N/A | AV7: #N/A | AW7: #N/A | AX7: #N/A | AY7: #N/A | BA7: #N/A | BB7: #N/A
A8: 43832 | B8: 20200102 | C8: 43832 | D8: 31.03 | E8: 30.63 | F8: 29.5 | G8: 28.72 | H8: 27.58 | I8: 28.3 | J8: 29.31 | K8: 30.22 | L8: 33.15 | M8: 40.85 | N8: 45.48 | O8: 46.39 | P8: 47 | Q8: 44.18 | R8: 40.47 | S8: 37.83 | T8: 37 | U8: 36.06 | V8: 36.51 | W8: 38.13 | X8: 42.19 | Y8: 45.31 | Z8: 47.77 | AA8: 51.39 | AB8: 50.66 | AC8: 46.76 | AD8: 40.78 | AE8: 39 | AF8: 38.6 | AG8: 39.19 | AH8: 40.2 | AI8: 41.96 | AJ8: 46.51 | AK8: 48.99 | AL8: 50.33 | AM8: 50.87 | AN8: 49.48 | AO8: 46.4 | AP8: 40.95 | AQ8: 39.43 | AR8: 38.9 | AS8: 39.14 | AT8: 40.21 | AU8: 43.18 | AV8: 47.78 | AW8: 50.08 | AX8: 50.61 | AY8: 50.66 | BA8: 67.05 | BB8: 1.3189
