Workbook
Name _1_: #REF!
Name _2ecm: #REF!
Name _3ecw: #REF!
Name _bot1: #REF!
Name _bot1: #REF!
Name _bot2: #REF!
Name _bot2: #REF!
Name _bot3: #REF!
Name _bot3: #REF!
Name _bot4: #REF!
Name _bot4: #REF!
Name _bot5: #REF!
Name _bot5: #REF!
Name _bot6: #REF!
Name _bot6: #REF!
Name _DLX1.INC: HAVERM!$B$2:$AH$7
Name _DLX2.INC: #REF!
Name _DLX2.INC: HAVERD!$G$3:$GV$8
Name _DLX3.INC: #REF!
Name _DLX3.INC: HAVERQ!$B$2:$H$7
Name _DLX6.INC: #REF!
Name _DLX7.INC: #REF!
Name _MYE4: #REF!
Name _MYE5: #REF!
Name _MYE6: #REF!
Name _OEP.MPCScenarios: 'Table - MPC scenarios'!$B$3:$E$12
Name _top1: #REF!
Name _top1: #REF!
Name _top2: #REF!
Name _top2: #REF!
Name _top3: #REF!
Name _top3: #REF!
Name _top4: #REF!
Name _top4: #REF!
Name _top5: #REF!
Name _top5: #REF!
Name _top6: #REF!
Name _top6: #REF!
Name a: SERIES1s:SERIES1e
Name About_these_data: #REF!
Name AllNSAData: #REF!
Name AllSAData: #REF!
Name AME: OFFSET(#REF!,0,0,MAX(#REF!),1)
Name Amytest: #REF!
Name Ann: #REF!
Name Ann_chg: #REF!
Name appended: OFFSET(#REF!,0,0,MAX(#REF!)+MAX(#REF!),#REF!)
Name approx2: #REF!
Name approx3: #REF!
Name approx4: #REF!
Name approx5: #REF!
Name approx6: #REF!
Name approx7: #REF!
Name Apr_50: #REF!
Name Apr_51: #REF!
Name Apr_52: #REF!
Name Apr_53: #REF!
Name Apr_54: #REF!
Name Apr_55: #REF!
Name Apr_56: #REF!

Sheet >> MARKET PRICING CHARTS

Sheet >> DATA

Sheet Chart Data
A1: Services inflation | H1: Private sector pay growth | L1: Inflation forecasts | S1: BoE DMP | Y1: BoE DMP
B2: Outturn | C2: BoE staff forecast (May) | D2: BoE staff forecast (Aug) | E2: BoE staff forecast (Nov) | F2: BoE staff forecast (Feb)
B3: Outturn | F3: BoE forecast | I3: Outturn | J3: BoE forecast | M3: CPI inflation | N3: BoE forecast, market interest rate expectations (Feb) | O3: OE (Mar) | P3: HMT consensus (Feb) | Q3: 2% LINE | T3: Prices - past year | U3: Prices - next year | V3: Wages - past year | W3: Wages - next year | Z3: Prices - past year | AA3: Prices - next year | AB3: Wages - past year | AC3: Wages - next year
A4: 44562 | B4: =100*((HAVERM!D152/HAVERM!D140)-1) -> 3.2685512 | H4: 44562 | I4: =HAVERM!E152 -> 4.2 | L4: 44927 | M4: =100*((HAVERQ!F40/HAVERQ!F36)-1) -> 10.178263 | Q4: 2 | S4: 43466 | T4: =HAVERM!F116 -> 2.79 | U4: =HAVERM!G116 -> 2.531 | V4: =HAVERM!H116 -> #N/A | W4: =HAVERM!I116 -> #N/A | Y4: 43466 | Z4: =HAVERM!J116 -> 2.525 | AA4: =HAVERM!K116 -> 2.471 | AB4: =HAVERM!L116 -> #N/A | AC4: =HAVERM!M116 -> #N/A
A5: 44593 | B5: =100*((HAVERM!D153/HAVERM!D141)-1) -> 3.4391534 | H5: 44593 | I5: =HAVERM!E153 -> 4.6 | L5: 45017 | M5: =100*((HAVERQ!F41/HAVERQ!F37)-1) -> 8.4390513 | Q5: 2 | S5: 43497 | T5: =HAVERM!F117 -> 2.23 | U5: =HAVERM!G117 -> 2.56 | V5: =HAVERM!H117 -> #N/A | W5: =HAVERM!I117 -> #N/A | Y5: 43497 | Z5: =HAVERM!J117 -> 2.415 | AA5: =HAVERM!K117 -> 2.424 | AB5: =HAVERM!L117 -> #N/A | AC5: =HAVERM!M117 -> #N/A
A6: 44621 | B6: =100*((HAVERM!D154/HAVERM!D142)-1) -> 3.9612676 | H6: 44621 | I6: =HAVERM!E154 -> 4.9 | L6: 45108 | M6: =100*((HAVERQ!F42/HAVERQ!F38)-1) -> 6.7135896 | Q6: 2 | S6: 43525 | T6: =HAVERM!F118 -> 2.4 | U6: =HAVERM!G118 -> 2.066 | V6: =HAVERM!H118 -> #N/A | W6: =HAVERM!I118 -> #N/A | Y6: 43525 | Z6: =HAVERM!J118 -> 2.474 | AA6: =HAVERM!K118 -> 2.386 | AB6: =HAVERM!L118 -> #N/A | AC6: =HAVERM!M118 -> #N/A
A7: 44652 | B7: =100*((HAVERM!D155/HAVERM!D143)-1) -> 4.7244094 | H7: 44652 | I7: =HAVERM!E155 -> 4.8 | L7: 45200 | M7: =100*((HAVERQ!F43/HAVERQ!F39)-1) -> 4.1568008 | Q7: 2 | S7: 43556 | T7: =HAVERM!F119 -> 2.87 | U7: =HAVERM!G119 -> 2.705 | V7: =HAVERM!H119 -> #N/A | W7: =HAVERM!I119 -> #N/A | Y7: 43556 | Z7: =HAVERM!J119 -> 2.501 | AA7: =HAVERM!K119 -> 2.444 | AB7: =HAVERM!L119 -> #N/A | AC7: =HAVERM!M119 -> #N/A
A8: 44682 | B8: =100*((HAVERM!D156/HAVERM!D144)-1) -> 4.886562 | H8: 44682 | I8: =HAVERM!E156 -> 5.1 | L8: 45292 | M8: =100*((HAVERQ!F44/HAVERQ!F40)-1) -> 3.5490605 | O8: =100*((GMW!B211/GMW!B207)-1) -> 3.5491137 | Q8: 2 | S8: 43586 | T8: =HAVERM!F120 -> 1.78 | U8: =HAVERM!G120 -> 2.318 | V8: =HAVERM!H120 -> #N/A | W8: =HAVERM!I120 -> #N/A | Y8: 43586 | Z8: =HAVERM!J120 -> 2.348 | AA8: =HAVERM!K120 -> 2.363 | AB8: =HAVERM!L120 -> #N/A | AC8: =HAVERM!M120 -> #N/A
A9: 44713 | B9: =100*((HAVERM!D157/HAVERM!D145)-1) -> 5.2173913 | H9: 44713 | I9: =HAVERM!E157 -> 5.4 | L9: 45383 | M9: =100*((HAVERQ!F45/HAVERQ!F41)-1) -> 2.110885 | O9: =100*((GMW!B212/GMW!B208)-1) -> 2.1108336 | Q9: 2 | S9: 43617 | T9: =HAVERM!F121 -> 2.7 | U9: =HAVERM!G121 -> 2.158 | V9: =HAVERM!H121 -> #N/A | W9: =HAVERM!I121 -> #N/A | Y9: 43617 | Z9: =HAVERM!J121 -> 2.449 | AA9: =HAVERM!K121 -> 2.394 | AB9: =HAVERM!L121 -> #N/A | AC9: =HAVERM!M121 -> #N/A
A10: 44743 | B10: =100*((HAVERM!D158/HAVERM!D146)-1) -> 5.7241977 | H10: 44743 | I10: =HAVERM!E158 -> 6 | L10: 45474 | M10: =100*((HAVERQ!F46/HAVERQ!F42)-1) -> 2.0547945 | O10: =100*((GMW!B213/GMW!B209)-1) -> 2.0547945 | Q10: 2 | S10: 43647 | T10: =HAVERM!F122 -> 2.26 | U10: =HAVERM!G122 -> 2.099 | V10: =HAVERM!H122 -> #N/A | W10: =HAVERM!I122 -> #N/A | Y10: 43647 | Z10: =HAVERM!J122 -> 2.246 | AA10: =HAVERM!K122 -> 2.192 | AB10: =HAVERM!L122 -> #N/A | AC10: =HAVERM!M122 -> #N/A
A11: 44774 | B11: =100*((HAVERM!D159/HAVERM!D147)-1) -> 5.9585492 | H11: 44774 | I11: =HAVERM!E159 -> 6.2 | L11: 45566 | M11: =100*((HAVERQ!F47/HAVERQ!F43)-1) -> 2.4753726 | O11: =100*((GMW!B214/GMW!B210)-1) -> 2.4753214 | Q11: 2 | S11: 43678 | T11: =HAVERM!F123 -> 1.91 | U11: =HAVERM!G123 -> 2.281 | V11: =HAVERM!H123 -> #N/A | W11: =HAVERM!I123 -> #N/A | Y11: 43678 | Z11: =HAVERM!J123 -> 2.291 | AA11: =HAVERM!K123 -> 2.179 | AB11: =HAVERM!L123 -> #N/A | AC11: =HAVERM!M123 -> #N/A
A12: 44805 | B12: =100*((HAVERM!D160/HAVERM!D148)-1) -> 6.1312608 | H12: 44805 | I12: =HAVERM!E160 -> 6.6 | L12: 45658 | N12: =HAVERQ!C48 -> 2.8 | O12: =100*((GMW!B215/GMW!B211)-1) -> 2.7942785 | Q12: 2 | S12: 43709 | T12: =HAVERM!F124 -> 2.26 | U12: =HAVERM!G124 -> 2.345 | V12: =HAVERM!H124 -> #N/A | W12: =HAVERM!I124 -> #N/A | Y12: 43709 | Z12: =HAVERM!J124 -> 2.142 | AA12: =HAVERM!K124 -> 2.241 | AB12: =HAVERM!L124 -> #N/A | AC12: =HAVERM!M124 -> #N/A
A13: 44835 | B13: =100*((HAVERM!D161/HAVERM!D149)-1) -> 6.2660944 | H13: 44835 | I13: =HAVERM!E161 -> 6.9 | L13: 45748 | N13: =HAVERQ!C49 -> 3.5 | O13: =100*((GMW!B216/GMW!B212)-1) -> 3.1688675 | Q13: 2 | S13: 43739 | T13: =HAVERM!F125 -> 1.99 | U13: =HAVERM!G125 -> 2.214 | V13: =HAVERM!H125 -> #N/A | W13: =HAVERM!I125 -> #N/A | Y13: 43739 | Z13: =HAVERM!J125 -> 2.053 | AA13: =HAVERM!K125 -> 2.28 | AB13: =HAVERM!L125 -> #N/A | AC13: =HAVERM!M125 -> #N/A
A14: 44866 | B14: =100*((HAVERM!D162/HAVERM!D150)-1) -> 6.3464837 | H14: 44866 | I14: =HAVERM!E162 -> 7.3 | L14: 45839 | N14: =HAVERQ!C50 -> 3.7 | O14: =100*((GMW!B217/GMW!B213)-1) -> 3.4616704 | Q14: 2 | S14: 43770 | T14: =HAVERM!F126 -> 1.86 | U14: =HAVERM!G126 -> 2.152 | V14: =HAVERM!H126 -> #N/A | W14: =HAVERM!I126 -> #N/A | Y14: 43770 | Z14: =HAVERM!J126 -> 2.037 | AA14: =HAVERM!K126 -> 2.237 | AB14: =HAVERM!L126 -> #N/A | AC14: =HAVERM!M126 -> #N/A
A15: 44896 | B15: =100*((HAVERM!D163/HAVERM!D151)-1) -> 6.8376068 | H15: 44896 | I15: =HAVERM!E163 -> 7.3 | L15: 45931 | N15: =HAVERQ!C51 -> 3.5 | O15: =100*((GMW!B218/GMW!B214)-1) -> 3.1802078 | P15: 2.8 | Q15: 2 | S15: 43800 | T15: =HAVERM!F127 -> 1.99 | U15: =HAVERM!G127 -> 2.372 | V15: =HAVERM!H127 -> #N/A | W15: =HAVERM!I127 -> #N/A | Y15: 43800 | Z15: =HAVERM!J127 -> 1.948 | AA15: =HAVERM!K127 -> 2.246 | AB15: =HAVERM!L127 -> #N/A | AC15: =HAVERM!M127 -> #N/A
A16: 44927 | B16: =100*((HAVERM!D164/HAVERM!D152)-1) -> 5.9024808 | H16: 44927 | I16: =HAVERM!E164 -> 7.1 | L16: 46023 | N16: =HAVERQ!C52 -> 3 | O16: =100*((GMW!B219/GMW!B215)-1) -> 3.1185782 | Q16: 2 | S16: 43831 | T16: =HAVERM!F128 -> 2.06 | U16: =HAVERM!G128 -> 2.117 | V16: =HAVERM!H128 -> #N/A | W16: =HAVERM!I128 -> #N/A | Y16: 43831 | Z16: =HAVERM!J128 -> 1.971 | AA16: =HAVERM!K128 -> 2.214 | AB16: =HAVERM!L128 -> #N/A | AC16: =HAVERM!M128 -> #N/A
A17: 44958 | B17: =100*((HAVERM!D165/HAVERM!D153)-1) -> 6.6496164 | H17: 44958 | I17: =HAVERM!E165 -> 7.1 | L17: 46113 | N17: =HAVERQ!C53 -> 2.6 | O17: =100*((GMW!B220/GMW!B216)-1) -> 2.5062593 | Q17: 2 | S17: 43862 | T17: =HAVERM!F129 -> 1.74 | U17: =HAVERM!G129 -> 2.094 | V17: =HAVERM!H129 -> #N/A | W17: =HAVERM!I129 -> #N/A | Y17: 43862 | Z17: =HAVERM!J129 -> 1.931 | AA17: =HAVERM!K129 -> 2.195 | AB17: =HAVERM!L129 -> #N/A | AC17: =HAVERM!M129 -> #N/A
A18: 44986 | B18: =100*((HAVERM!D166/HAVERM!D154)-1) -> 6.6892464 | H18: 44986 | I18: =HAVERM!E166 -> 7.2 | L18: 46204 | N18: =HAVERQ!C54 -> 2.6 | O18: =100*((GMW!B221/GMW!B217)-1) -> 2.4448239 | Q18: 2 | S18: 43891 | T18: =HAVERM!F130 -> 1.69 | U18: =HAVERM!G130 -> 1.598 | V18: =HAVERM!H130 -> #N/A | W18: =HAVERM!I130 -> #N/A | Y18: 43891 | Z18: =HAVERM!J130 -> 1.83 | AA18: =HAVERM!K130 -> 1.937 | AB18: =HAVERM!L130 -> #N/A | AC18: =HAVERM!M130 -> #N/A
A19: 45017 | B19: =100*((HAVERM!D167/HAVERM!D155)-1) -> 6.9340017 | H19: 45017 | I19: =HAVERM!E167 -> 7.7 | L19: 46296 | N19: =HAVERQ!C55 -> 2.4 | O19: =100*((GMW!B222/GMW!B218)-1) -> 2.374475 | P19: 2.3 | Q19: 2 | S19: 43922 | T19: =HAVERM!F131 -> 1.87 | U19: =HAVERM!G131 -> 1.213 | V19: =HAVERM!H131 -> #N/A | W19: =HAVERM!I131 -> #N/A | Y19: 43922 | Z19: =HAVERM!J131 -> 1.765 | AA19: =HAVERM!K131 -> 1.635 | AB19: =HAVERM!L131 -> #N/A | AC19: =HAVERM!M131 -> #N/A
A20: 45047 | B20: =100*((HAVERM!D168/HAVERM!D156)-1) -> 7.3211314 | H20: 45047 | I20: =HAVERM!E168 -> 7.9 | L20: 46388 | N20: =HAVERQ!C56 -> 2.3 | O20: =100*((GMW!B223/GMW!B219)-1) -> 2.1515991 | Q20: 2 | S20: 43952 | T20: =HAVERM!F132 -> 1.72 | U20: =HAVERM!G132 -> 1.389 | V20: =HAVERM!H132 -> #N/A | W20: =HAVERM!I132 -> #N/A | Y20: 43952 | Z20: =HAVERM!J132 -> 1.759 | AA20: =HAVERM!K132 -> 1.4 | AB20: =HAVERM!L132 -> #N/A | AC20: =HAVERM!M132 -> #N/A
A21: 45078 | B21: =100*((HAVERM!D169/HAVERM!D157)-1) -> 7.1900826 | H21: 45078 | I21: =HAVERM!E169 -> 8.1 | L21: 46478 | N21: =HAVERQ!C57 -> 2.2 | O21: =100*((GMW!B224/GMW!B220)-1) -> 2.1662517 | Q21: 2 | S21: 43983 | T21: =HAVERM!F133 -> 1.18 | U21: =HAVERM!G133 -> 1.431 | V21: =HAVERM!H133 -> #N/A | W21: =HAVERM!I133 -> #N/A | Y21: 43983 | Z21: =HAVERM!J133 -> 1.59 | AA21: =HAVERM!K133 -> 1.344 | AB21: =HAVERM!L133 -> #N/A | AC21: =HAVERM!M133 -> #N/A
A22: 45108 | B22: =100*((HAVERM!D170/HAVERM!D158)-1) -> 7.4651354 | H22: 45108 | I22: =HAVERM!E170 -> 8.1 | L22: 46569 | N22: =HAVERQ!C58 -> 2.1 | O22: =100*((GMW!B225/GMW!B221)-1) -> 2.2200162 | Q22: 2 | S22: 44013 | T22: =HAVERM!F134 -> 1.34 | U22: =HAVERM!G134 -> 1.661 | V22: =HAVERM!H134 -> #N/A | W22: =HAVERM!I134 -> #N/A | Y22: 44013 | Z22: =HAVERM!J134 -> 1.414 | AA22: =HAVERM!K134 -> 1.494 | AB22: =HAVERM!L134 -> #N/A | AC22: =HAVERM!M134 -> #N/A
A23: 45139 | B23: =100*((HAVERM!D171/HAVERM!D159)-1) -> 6.7644662 | H23: 45139 | I23: =HAVERM!E171 -> 8.1 | L23: 46661 | N23: =HAVERQ!C59 -> 2 | O23: =100*((GMW!B226/GMW!B222)-1) -> 2.2619974 | Q23: 2 | S23: 44044 | T23: =HAVERM!F135 -> 1.04 | U23: =HAVERM!G135 -> 2.16 | V23: =HAVERM!H135 -> #N/A | W23: =HAVERM!I135 -> #N/A | Y23: 44044 | Z23: =HAVERM!J135 -> 1.187 | AA23: =HAVERM!K135 -> 1.751 | AB23: =HAVERM!L135 -> #N/A | AC23: =HAVERM!M135 -> #N/A
A24: 45170 | B24: =100*((HAVERM!D172/HAVERM!D160)-1) -> 6.916192 | H24: 45170 | I24: =HAVERM!E172 -> 7.9 | L24: 46753 | N24: =HAVERQ!C60 -> 1.9 | O24: =100*((GMW!B227/GMW!B223)-1) -> 2.2554921 | Q24: 2 | S24: 44075 | T24: =HAVERM!F136 -> 1.57 | U24: =HAVERM!G136 -> 1.853 | V24: =HAVERM!H136 -> #N/A | W24: =HAVERM!I136 -> #N/A | Y24: 44075 | Z24: =HAVERM!J136 -> 1.317 | AA24: =HAVERM!K136 -> 1.891 | AB24: =HAVERM!L136 -> #N/A | AC24: =HAVERM!M136 -> #N/A
A25: 45200 | B25: =100*((HAVERM!D173/HAVERM!D161)-1) -> 6.542811 | H25: 45200 | I25: =HAVERM!E173 -> 7.3 | S25: 44105 | T25: =HAVERM!F137 -> 2.21 | U25: =HAVERM!G137 -> 2.354 | V25: =HAVERM!H137 -> #N/A | W25: =HAVERM!I137 -> #N/A | Y25: 44105 | Z25: =HAVERM!J137 -> 1.606 | AA25: =HAVERM!K137 -> 2.122 | AB25: =HAVERM!L137 -> #N/A | AC25: =HAVERM!M137 -> #N/A
A26: 45231 | B26: =100*((HAVERM!D174/HAVERM!D162)-1) -> 6.2096774 | H26: 45231 | I26: =HAVERM!E174 -> 6.7 | S26: 44136 | T26: =HAVERM!F138 -> 1.69 | U26: =HAVERM!G138 -> 2.092 | V26: =HAVERM!H138 -> #N/A | W26: =HAVERM!I138 -> #N/A | Y26: 44136 | Z26: =HAVERM!J138 -> 1.823 | AA26: =HAVERM!K138 -> 2.099 | AB26: =HAVERM!L138 -> #N/A | AC26: =HAVERM!M138 -> #N/A
A27: 45261 | B27: =100*((HAVERM!D175/HAVERM!D163)-1) -> 6.4 | H27: 45261 | I27: =HAVERM!E175 -> 6.2 | S27: 44166 | T27: =HAVERM!F139 -> 0.88 | U27: =HAVERM!G139 -> 2.705 | V27: =HAVERM!H139 -> #N/A | W27: =HAVERM!I139 -> #N/A | Y27: 44166 | Z27: =HAVERM!J139 -> 1.591 | AA27: =HAVERM!K139 -> 2.383 | AB27: =HAVERM!L139 -> #N/A | AC27: =HAVERM!M139 -> #N/A
A28: 45292 | B28: =100*((HAVERM!D176/HAVERM!D164)-1) -> 6.542811 | H28: 45292 | I28: =HAVERM!E176 -> 6.1 | S28: 44197 | T28: =HAVERM!F140 -> 1.83 | U28: =HAVERM!G140 -> 2.517 | V28: =HAVERM!H140 -> #N/A | W28: =HAVERM!I140 -> #N/A | Y28: 44197 | Z28: =HAVERM!J140 -> 1.467 | AA28: =HAVERM!K140 -> 2.438 | AB28: =HAVERM!L140 -> #N/A | AC28: =HAVERM!M140 -> #N/A
A29: 45323 | B29: =100*((HAVERM!D177/HAVERM!D165)-1) -> 6.0751399 | H29: 45323 | I29: =HAVERM!E177 -> 6 | S29: 44228 | T29: =HAVERM!F141 -> 2.05 | U29: =HAVERM!G141 -> 2.719 | V29: =HAVERM!H141 -> #N/A | W29: =HAVERM!I141 -> #N/A | Y29: 44228 | Z29: =HAVERM!J141 -> 1.589 | AA29: =HAVERM!K141 -> 2.647 | AB29: =HAVERM!L141 -> #N/A | AC29: =HAVERM!M141 -> #N/A
A30: 45352 | B30: =100*((HAVERM!D178/HAVERM!D166)-1) -> 5.952381 | H30: 45352 | I30: =HAVERM!E178 -> 5.9 | S30: 44256 | T30: =HAVERM!F142 -> 1.65 | U30: =HAVERM!G142 -> 2.973 | V30: =HAVERM!H142 -> #N/A | W30: =HAVERM!I142 -> #N/A | Y30: 44256 | Z30: =HAVERM!J142 -> 1.847 | AA30: =HAVERM!K142 -> 2.736 | AB30: =HAVERM!L142 -> #N/A | AC30: =HAVERM!M142 -> #N/A
A31: 45383 | B31: =100*((HAVERM!D179/HAVERM!D167)-1) -> 5.859375 | C31: ='MPR Chart 2.16 (May)'!L70 -> 5.52 | H31: 45383 | I31: =HAVERM!E179 -> 5.9 | S31: 44287 | T31: =HAVERM!F143 -> 2.79 | U31: =HAVERM!G143 -> 3.139 | V31: =HAVERM!H143 -> #N/A | W31: =HAVERM!I143 -> #N/A | Y31: 44287 | Z31: =HAVERM!J143 -> 2.165 | AA31: =HAVERM!K143 -> 2.944 | AB31: =HAVERM!L143 -> #N/A | AC31: =HAVERM!M143 -> #N/A
A32: 45413 | B32: =100*((HAVERM!D180/HAVERM!D168)-1) -> 5.7364341 | C32: ='MPR Chart 2.16 (May)'!L71 -> 5.258 | H32: 45413 | I32: =HAVERM!E180 -> 5.6 | S32: 44317 | T32: =HAVERM!F144 -> 2.83 | U32: =HAVERM!G144 -> 3.442 | V32: =HAVERM!H144 -> #N/A | W32: =HAVERM!I144 -> #N/A | Y32: 44317 | Z32: =HAVERM!J144 -> 2.424 | AA32: =HAVERM!K144 -> 3.185 | AB32: =HAVERM!L144 -> #N/A | AC32: =HAVERM!M144 -> #N/A
A33: 45444 | B33: =100*((HAVERM!D181/HAVERM!D169)-1) -> 5.7054742 | C33: ='MPR Chart 2.16 (May)'!L72 -> 5.134 | H33: 45444 | I33: =HAVERM!E181 -> 5.3 | S33: 44348 | T33: =HAVERM!F145 -> 3.13 | U33: =HAVERM!G145 -> 3.258 | V33: =HAVERM!H145 -> #N/A | W33: =HAVERM!I145 -> #N/A | Y33: 44348 | Z33: =HAVERM!J145 -> 2.915 | AA33: =HAVERM!K145 -> 3.28 | AB33: =HAVERM!L145 -> #N/A | AC33: =HAVERM!M145 -> #N/A
A34: 45474 | B34: =100*((HAVERM!D182/HAVERM!D170)-1) -> 5.1908397 | C34: ='MPR Chart 2.16 (May)'!L73 -> 4.949 | D34: ='MPR Chart 2.16 (Aug)'!L49 -> 5.563 | H34: 45474 | I34: =HAVERM!E182 -> 5 | S34: 44378 | T34: =HAVERM!F146 -> 3.77 | U34: =HAVERM!G146 -> 2.931 | V34: =HAVERM!H146 -> #N/A | W34: =HAVERM!I146 -> #N/A | Y34: 44378 | Z34: =HAVERM!J146 -> 3.24 | AA34: =HAVERM!K146 -> 3.21 | AB34: =HAVERM!L146 -> #N/A | AC34: =HAVERM!M146 -> #N/A
A35: 45505 | B35: =100*((HAVERM!D183/HAVERM!D171)-1) -> 5.5725191 | C35: ='MPR Chart 2.16 (May)'!L74 -> 5.001 | D35: ='MPR Chart 2.16 (Aug)'!L50 -> 5.84 | H35: 45505 | I35: =HAVERM!E183 -> 4.8 | S35: 44409 | T35: =HAVERM!F147 -> 3.45 | U35: =HAVERM!G147 -> 3.23 | V35: =HAVERM!H147 -> #N/A | W35: =HAVERM!I147 -> #N/A | Y35: 44409 | Z35: =HAVERM!J147 -> 3.445 | AA35: =HAVERM!K147 -> 3.14 | AB35: =HAVERM!L147 -> #N/A | AC35: =HAVERM!M147 -> #N/A
A36: 45536 | B36: =100*((HAVERM!D184/HAVERM!D172)-1) -> 4.9467275 | C36: ='MPR Chart 2.16 (May)'!L75 -> 4.728 | D36: ='MPR Chart 2.16 (Aug)'!L51 -> 5.52 | H36: 45536 | I36: =HAVERM!E184 -> 4.9 | S36: 44440 | T36: =HAVERM!F148 -> 4.53 | U36: =HAVERM!G148 -> 4.098 | V36: =HAVERM!H148 -> #N/A | W36: =HAVERM!I148 -> #N/A | Y36: 44440 | Z36: =HAVERM!J148 -> 3.913 | AA36: =HAVERM!K148 -> 3.42 | AB36: =HAVERM!L148 -> #N/A | AC36: =HAVERM!M148 -> #N/A
A37: 45566 | B37: =100*((HAVERM!D185/HAVERM!D173)-1) -> 5.0037908 | D37: ='MPR Chart 2.16 (Aug)'!L52 -> 5.502 | E37: ='MPR Chart 2.22 (Nov)'!L52 -> 4.972 | H37: 45566 | I37: =HAVERM!E185 -> 5.5 | S37: 44470 | T37: =HAVERM!F149 -> 5.41 | U37: =HAVERM!G149 -> 4.724 | V37: =HAVERM!H149 -> #N/A | W37: =HAVERM!I149 -> #N/A | Y37: 44470 | Z37: =HAVERM!J149 -> 4.461 | AA37: =HAVERM!K149 -> 4.017 | AB37: =HAVERM!L149 -> #N/A | AC37: =HAVERM!M149 -> #N/A
A38: 45597 | B38: =100*((HAVERM!D186/HAVERM!D174)-1) -> 5.0113895 | D38: ='MPR Chart 2.16 (Aug)'!L53 -> 5.395 | E38: ='MPR Chart 2.22 (Nov)'!L53 -> 4.913 | H38: 45597 | I38: =HAVERM!E186 -> 5.9 | S38: 44501 | T38: =HAVERM!F150 -> 4.81 | U38: =HAVERM!G150 -> 4.411 | V38: =HAVERM!H150 -> #N/A | W38: =HAVERM!I150 -> #N/A | Y38: 44501 | Z38: =HAVERM!J150 -> 4.916 | AA38: =HAVERM!K150 -> 4.411 | AB38: =HAVERM!L150 -> #N/A | AC38: =HAVERM!M150 -> #N/A
A39: 45627 | B39: =100*((HAVERM!D187/HAVERM!D175)-1) -> 4.3609023 | D39: ='MPR Chart 2.16 (Aug)'!L54 -> 5.286 | E39: ='MPR Chart 2.22 (Nov)'!L54 -> 4.739 | H39: 45627 | I39: =HAVERM!E187 -> 6.2 | J39: ='MPR Chart 2.22 (Feb)'!C34 -> 6.292 | S39: 44531 | T39: =HAVERM!F151 -> 5.48 | U39: =HAVERM!G151 -> 5.094 | V39: =HAVERM!H151 -> #N/A | W39: =HAVERM!I151 -> #N/A | Y39: 44531 | Z39: =HAVERM!J151 -> 5.233 | AA39: =HAVERM!K151 -> 4.743 | AB39: =HAVERM!L151 -> #N/A | AC39: =HAVERM!M151 -> #N/A
A40: 45658 | B40: =100*((HAVERM!D188/HAVERM!D176)-1) -> 5.0037908 | E40: ='MPR Chart 2.22 (Nov)'!L55 -> 5.112 | F40: ='MPR Chart 2.20 (Feb)'!B69 -> 5.161 | H40: 45658 | S40: 44562 | T40: =HAVERM!F152 -> 5.41 | U40: =HAVERM!G152 -> 4.542 | V40: =HAVERM!H152 -> #N/A | W40: =HAVERM!I152 -> #N/A | Y40: 44562 | Z40: =HAVERM!J152 -> 5.235 | AA40: =HAVERM!K152 -> 4.682 | AB40: =HAVERM!L152 -> #N/A | AC40: =HAVERM!M152 -> #N/A
...

Sheet Market pricing dates
A2: February 2025 MPR | B2: 45685 | D2: March 2025 | E2: 45727
A4: Last 5 working days | D4: Last 5 working days
A5: =TEXT(B5,"dddd") -> Wednesday | B5: =IF(A6="Monday",B6-3,B6-1) -> 45679 | D5: =TEXT(E5,"dddd") -> Wednesday | E5: =IF(D6="Monday",E6-3,E6-1) -> 45721
A6: =TEXT(B6,"dddd") -> Thursday | B6: =IF(A7="Monday",B7-3,B7-1) -> 45680 | D6: =TEXT(E6,"dddd") -> Thursday | E6: =IF(D7="Monday",E7-3,E7-1) -> 45722
A7: =TEXT(B7,"dddd") -> Friday | B7: =IF(A8="Monday",B8-3,B8-1) -> 45681 | D7: =TEXT(E7,"dddd") -> Friday | E7: =IF(D8="Monday",E8-3,E8-1) -> 45723
A8: =TEXT(B8,"dddd") -> Monday | B8: =IF(A9="Monday",B9-3,B9-1) -> 45684 | D8: =TEXT(E8,"dddd") -> Monday | E8: =IF(D9="Monday",E9-3,E9-1) -> 45726
A9: =TEXT(B9,"dddd") -> Tuesday | B9: =B2 -> 45685 | D9: =TEXT(E9,"dddd") -> Tuesday | E9: =E2 -> 45727
B11: =TEXT(B9,"dd mmm yyyy") -> 28 Jan 2025 | E11: =TEXT(E9,"dd mmm yyyy") -> 11 Mar 2025
A12: ="15 working days to "&B11 -> 15 working days to 28 Jan 2025 | D12: ="15 working days to "&E11 -> 15 working days to 11 Mar 2025

Sheet Market expectations - RCB
A1: ='Market pricing dates'!A2 -> February 2025 MPR | C1: ='Market pricing dates'!A12 -> 15 working days to 28 Jan 2025 | BA1: ='Market pricing dates'!D2 -> March 2025 | BC1: ='Market pricing dates'!D12 -> 15 working days to 11 Mar 2025
A2: Column # | B2: =HAVERD!I$1 -> 9 | C2: =+B2+1 -> 10 | D2: =+C2+1 -> 11 | E2: =+D2+1 -> 12 | F2: =+E2+1 -> 13 | G2: =+F2+1 -> 14 | H2: =+G2+1 -> 15 | I2: =+H2+1 -> 16 | J2: =+I2+1 -> 17 | ... AX2: =+AW2+1 -> 57 | BA2: Column # | BB2: =HAVERD!I$1 -> 9 | BC2: =+BB2+1 -> 10 | BD2: =+BC2+1 -> 11 | BE2: =+BD2+1 -> 12 | BF2: =+BE2+1 -> 13 | BG2: =+BF2+1 -> 14 | BH2: =+BG2+1 -> 15 | BI2: =+BH2+1 -> 16 | BJ2: =+BI2+1 -> 17 | ... CX2: =+CW2+1 -> 57
A3: Months | B3: =HAVERD!I$2 -> Overnight | C3: =HAVERD!J$2 -> 1 | D3: =HAVERD!K$2 -> 2 | E3: =HAVERD!L$2 -> 3 | F3: =HAVERD!M$2 -> 4 | G3: =HAVERD!N$2 -> 5 | H3: =HAVERD!O$2 -> 6 | I3: =HAVERD!P$2 -> 7 | ... AX3: =HAVERD!BE$2 -> 48 | BA3: Months | BB3: =HAVERD!I$2 -> Overnight | BC3: =HAVERD!J$2 -> 1 | BD3: =HAVERD!K$2 -> 2 | BE3: =HAVERD!L$2 -> 3 | BF3: =HAVERD!M$2 -> 4 | BG3: =HAVERD!N$2 -> 5 | BH3: =HAVERD!O$2 -> 6 | BI3: =HAVERD!P$2 -> 7 | ... CX3: =HAVERD!BE$2 -> 48
A4: Days | C4: 30.416667 | D4: =+C4+30.4166667 -> 60.833333 | E4: =+D4+30.4166667 -> 91.25 | F4: =+E4+30.4166667 -> 121.66667 | G4: =+F4+30.4166667 -> 152.08333 | H4: =+G4+30.4166667 -> 182.5 | I4: =+H4+30.4166667 -> 212.91667 | J4: =+I4+30.4166667 -> 243.33333 | K4: =+J4+30.4166667 -> 273.75 | ... AX4: =+AW4+30.4166667 -> 1460 | BA4: Days | BC4: 30.416667 | BD4: =+BC4+30.4166667 -> 60.833333 | BE4: =+BD4+30.4166667 -> 91.25 | BF4: =+BE4+30.4166667 -> 121.66667 | BG4: =+BF4+30.4166667 -> 152.08333 | BH4: =+BG4+30.4166667 -> 182.5 | BI4: =+BH4+30.4166667 -> 212.91667 | BJ4: =+BI4+30.4166667 -> 243.33333 | BK4: =+BJ4+30.4166667 -> 273.75 | ... CX4: =+CW4+30.4166667 -> 1460
A5: Dates | BA5: Dates
A6: =A11-7 -> 45665 | B6: =A6 -> 45665 | C6: =$B6+C$4 -> 45695.417 | D6: =$B6+D$4 -> 45725.833 | E6: =$B6+E$4 -> 45756.25 | F6: =$B6+F$4 -> 45786.667 | G6: =$B6+G$4 -> 45817.083 | H6: =$B6+H$4 -> 45847.5 | I6: =$B6+I$4 -> 45877.917 | J6: =$B6+J$4 -> 45908.333 | ... AX6: =$B6+AX$4 -> 47125 | BA6: =BA11-7 -> 45707 | BB6: =BA6 -> 45707 | BC6: =$BA6+BC$4 -> 45737.417 | BD6: =$BA6+BD$4 -> 45767.833 | BE6: =$BA6+BE$4 -> 45798.25 | BF6: =$BA6+BF$4 -> 45828.667 | BG6: =$BA6+BG$4 -> 45859.083 | BH6: =$BA6+BH$4 -> 45889.5 | BI6: =$BA6+BI$4 -> 45919.917 | BJ6: =$BA6+BJ$4 -> 45950.333 | ... CX6: =$BA6+CX$4 -> 47167
A7: =A12-7 -> 45666 | B7: =A7 -> 45666 | C7: =$B7+C$4 -> 45696.417 | D7: =$B7+D$4 -> 45726.833 | E7: =$B7+E$4 -> 45757.25 | F7: =$B7+F$4 -> 45787.667 | G7: =$B7+G$4 -> 45818.083 | H7: =$B7+H$4 -> 45848.5 | I7: =$B7+I$4 -> 45878.917 | J7: =$B7+J$4 -> 45909.333 | ... AX7: =$B7+AX$4 -> 47126 | BA7: =BA12-7 -> 45708 | BB7: =BA7 -> 45708 | BC7: =$BA7+BC$4 -> 45738.417 | BD7: =$BA7+BD$4 -> 45768.833 | BE7: =$BA7+BE$4 -> 45799.25 | BF7: =$BA7+BF$4 -> 45829.667 | BG7: =$BA7+BG$4 -> 45860.083 | BH7: =$BA7+BH$4 -> 45890.5 | BI7: =$BA7+BI$4 -> 45920.917 | BJ7: =$BA7+BJ$4 -> 45951.333 | ... CX7: =$BA7+CX$4 -> 47168
A8: =A13-7 -> 45667 | B8: =A8 -> 45667 | C8: =$B8+C$4 -> 45697.417 | D8: =$B8+D$4 -> 45727.833 | E8: =$B8+E$4 -> 45758.25 | F8: =$B8+F$4 -> 45788.667 | G8: =$B8+G$4 -> 45819.083 | H8: =$B8+H$4 -> 45849.5 | I8: =$B8+I$4 -> 45879.917 | J8: =$B8+J$4 -> 45910.333 | ... AX8: =$B8+AX$4 -> 47127 | BA8: =BA13-7 -> 45709 | BB8: =BA8 -> 45709 | BC8: =$BA8+BC$4 -> 45739.417 | BD8: =$BA8+BD$4 -> 45769.833 | BE8: =$BA8+BE$4 -> 45800.25 | BF8: =$BA8+BF$4 -> 45830.667 | BG8: =$BA8+BG$4 -> 45861.083 | BH8: =$BA8+BH$4 -> 45891.5 | BI8: =$BA8+BI$4 -> 45921.917 | BJ8: =$BA8+BJ$4 -> 45952.333 | ... CX8: =$BA8+CX$4 -> 47169
A9: =A14-7 -> 45670 | B9: =A9 -> 45670 | C9: =$B9+C$4 -> 45700.417 | D9: =$B9+D$4 -> 45730.833 | E9: =$B9+E$4 -> 45761.25 | F9: =$B9+F$4 -> 45791.667 | G9: =$B9+G$4 -> 45822.083 | H9: =$B9+H$4 -> 45852.5 | I9: =$B9+I$4 -> 45882.917 | J9: =$B9+J$4 -> 45913.333 | ... AX9: =$B9+AX$4 -> 47130 | BA9: =BA14-7 -> 45712 | BB9: =BA9 -> 45712 | BC9: =$BA9+BC$4 -> 45742.417 | BD9: =$BA9+BD$4 -> 45772.833 | BE9: =$BA9+BE$4 -> 45803.25 | BF9: =$BA9+BF$4 -> 45833.667 | BG9: =$BA9+BG$4 -> 45864.083 | BH9: =$BA9+BH$4 -> 45894.5 | BI9: =$BA9+BI$4 -> 45924.917 | BJ9: =$BA9+BJ$4 -> 45955.333 | ... CX9: =$BA9+CX$4 -> 47172
A10: =A15-7 -> 45671 | B10: =A10 -> 45671 | C10: =$B10+C$4 -> 45701.417 | D10: =$B10+D$4 -> 45731.833 | E10: =$B10+E$4 -> 45762.25 | F10: =$B10+F$4 -> 45792.667 | G10: =$B10+G$4 -> 45823.083 | H10: =$B10+H$4 -> 45853.5 | I10: =$B10+I$4 -> 45883.917 | J10: =$B10+J$4 -> 45914.333 | ... AX10: =$B10+AX$4 -> 47131 | BA10: =BA15-7 -> 45713 | BB10: =BA10 -> 45713 | BC10: =$BA10+BC$4 -> 45743.417 | BD10: =$BA10+BD$4 -> 45773.833 | BE10: =$BA10+BE$4 -> 45804.25 | BF10: =$BA10+BF$4 -> 45834.667 | BG10: =$BA10+BG$4 -> 45865.083 | BH10: =$BA10+BH$4 -> 45895.5 | BI10: =$BA10+BI$4 -> 45925.917 | BJ10: =$BA10+BJ$4 -> 45956.333 | ... CX10: =$BA10+CX$4 -> 47173
A11: =A16-7 -> 45672 | B11: =A11 -> 45672 | C11: =$B11+C$4 -> 45702.417 | D11: =$B11+D$4 -> 45732.833 | E11: =$B11+E$4 -> 45763.25 | F11: =$B11+F$4 -> 45793.667 | G11: =$B11+G$4 -> 45824.083 | H11: =$B11+H$4 -> 45854.5 | I11: =$B11+I$4 -> 45884.917 | J11: =$B11+J$4 -> 45915.333 | ... AX11: =$B11+AX$4 -> 47132 | BA11: =BA16-7 -> 45714 | BB11: =BA11 -> 45714 | BC11: =$BA11+BC$4 -> 45744.417 | BD11: =$BA11+BD$4 -> 45774.833 | BE11: =$BA11+BE$4 -> 45805.25 | BF11: =$BA11+BF$4 -> 45835.667 | BG11: =$BA11+BG$4 -> 45866.083 | BH11: =$BA11+BH$4 -> 45896.5 | BI11: =$BA11+BI$4 -> 45926.917 | BJ11: =$BA11+BJ$4 -> 45957.333 | ... CX11: =$BA11+CX$4 -> 47174
A12: =A17-7 -> 45673 | B12: =A12 -> 45673 | C12: =$B12+C$4 -> 45703.417 | D12: =$B12+D$4 -> 45733.833 | E12: =$B12+E$4 -> 45764.25 | F12: =$B12+F$4 -> 45794.667 | G12: =$B12+G$4 -> 45825.083 | H12: =$B12+H$4 -> 45855.5 | I12: =$B12+I$4 -> 45885.917 | J12: =$B12+J$4 -> 45916.333 | ... AX12: =$B12+AX$4 -> 47133 | BA12: =BA17-7 -> 45715 | BB12: =BA12 -> 45715 | BC12: =$BA12+BC$4 -> 45745.417 | BD12: =$BA12+BD$4 -> 45775.833 | BE12: =$BA12+BE$4 -> 45806.25 | BF12: =$BA12+BF$4 -> 45836.667 | BG12: =$BA12+BG$4 -> 45867.083 | BH12: =$BA12+BH$4 -> 45897.5 | BI12: =$BA12+BI$4 -> 45927.917 | BJ12: =$BA12+BJ$4 -> 45958.333 | ... CX12: =$BA12+CX$4 -> 47175
A13: =A18-7 -> 45674 | B13: =A13 -> 45674 | C13: =$B13+C$4 -> 45704.417 | D13: =$B13+D$4 -> 45734.833 | E13: =$B13+E$4 -> 45765.25 | F13: =$B13+F$4 -> 45795.667 | G13: =$B13+G$4 -> 45826.083 | H13: =$B13+H$4 -> 45856.5 | I13: =$B13+I$4 -> 45886.917 | J13: =$B13+J$4 -> 45917.333 | ... AX13: =$B13+AX$4 -> 47134 | BA13: =BA18-7 -> 45716 | BB13: =BA13 -> 45716 | BC13: =$BA13+BC$4 -> 45746.417 | BD13: =$BA13+BD$4 -> 45776.833 | BE13: =$BA13+BE$4 -> 45807.25 | BF13: =$BA13+BF$4 -> 45837.667 | BG13: =$BA13+BG$4 -> 45868.083 | BH13: =$BA13+BH$4 -> 45898.5 | BI13: =$BA13+BI$4 -> 45928.917 | BJ13: =$BA13+BJ$4 -> 45959.333 | ... CX13: =$BA13+CX$4 -> 47176
A14: =A19-7 -> 45677 | B14: =A14 -> 45677 | C14: =$B14+C$4 -> 45707.417 | D14: =$B14+D$4 -> 45737.833 | E14: =$B14+E$4 -> 45768.25 | F14: =$B14+F$4 -> 45798.667 | G14: =$B14+G$4 -> 45829.083 | H14: =$B14+H$4 -> 45859.5 | I14: =$B14+I$4 -> 45889.917 | J14: =$B14+J$4 -> 45920.333 | ... AX14: =$B14+AX$4 -> 47137 | BA14: =BA19-7 -> 45719 | BB14: =BA14 -> 45719 | BC14: =$BA14+BC$4 -> 45749.417 | BD14: =$BA14+BD$4 -> 45779.833 | BE14: =$BA14+BE$4 -> 45810.25 | BF14: =$BA14+BF$4 -> 45840.667 | BG14: =$BA14+BG$4 -> 45871.083 | BH14: =$BA14+BH$4 -> 45901.5 | BI14: =$BA14+BI$4 -> 45931.917 | BJ14: =$BA14+BJ$4 -> 45962.333 | ... CX14: =$BA14+CX$4 -> 47179
A15: =A20-7 -> 45678 | B15: =A15 -> 45678 | C15: =$B15+C$4 -> 45708.417 | D15: =$B15+D$4 -> 45738.833 | E15: =$B15+E$4 -> 45769.25 | F15: =$B15+F$4 -> 45799.667 | G15: =$B15+G$4 -> 45830.083 | H15: =$B15+H$4 -> 45860.5 | I15: =$B15+I$4 -> 45890.917 | J15: =$B15+J$4 -> 45921.333 | ... AX15: =$B15+AX$4 -> 47138 | BA15: =BA20-7 -> 45720 | BB15: =BA15 -> 45720 | BC15: =$BA15+BC$4 -> 45750.417 | BD15: =$BA15+BD$4 -> 45780.833 | BE15: =$BA15+BE$4 -> 45811.25 | BF15: =$BA15+BF$4 -> 45841.667 | BG15: =$BA15+BG$4 -> 45872.083 | BH15: =$BA15+BH$4 -> 45902.5 | BI15: =$BA15+BI$4 -> 45932.917 | BJ15: =$BA15+BJ$4 -> 45963.333 | ... CX15: =$BA15+CX$4 -> 47180
A16: ='Market pricing dates'!B5 -> 45679 | B16: =A16 -> 45679 | C16: =$B16+C$4 -> 45709.417 | D16: =$B16+D$4 -> 45739.833 | E16: =$B16+E$4 -> 45770.25 | F16: =$B16+F$4 -> 45800.667 | G16: =$B16+G$4 -> 45831.083 | H16: =$B16+H$4 -> 45861.5 | I16: =$B16+I$4 -> 45891.917 | J16: =$B16+J$4 -> 45922.333 | ... AX16: =$B16+AX$4 -> 47139 | BA16: ='Market pricing dates'!E5 -> 45721 | BB16: =BA16 -> 45721 | BC16: =$BA16+BC$4 -> 45751.417 | BD16: =$BA16+BD$4 -> 45781.833 | BE16: =$BA16+BE$4 -> 45812.25 | BF16: =$BA16+BF$4 -> 45842.667 | BG16: =$BA16+BG$4 -> 45873.083 | BH16: =$BA16+BH$4 -> 45903.5 | BI16: =$BA16+BI$4 -> 45933.917 | BJ16: =$BA16+BJ$4 -> 45964.333 | ... CX16: =$BA16+CX$4 -> 47181
A17: ='Market pricing dates'!B6 -> 45680 | B17: =A17 -> 45680 | C17: =$B17+C$4 -> 45710.417 | D17: =$B17+D$4 -> 45740.833 | E17: =$B17+E$4 -> 45771.25 | F17: =$B17+F$4 -> 45801.667 | G17: =$B17+G$4 -> 45832.083 | H17: =$B17+H$4 -> 45862.5 | I17: =$B17+I$4 -> 45892.917 | J17: =$B17+J$4 -> 45923.333 | ... AX17: =$B17+AX$4 -> 47140 | BA17: ='Market pricing dates'!E6 -> 45722 | BB17: =BA17 -> 45722 | BC17: =$BA17+BC$4 -> 45752.417 | BD17: =$BA17+BD$4 -> 45782.833 | BE17: =$BA17+BE$4 -> 45813.25 | BF17: =$BA17+BF$4 -> 45843.667 | BG17: =$BA17+BG$4 -> 45874.083 | BH17: =$BA17+BH$4 -> 45904.5 | BI17: =$BA17+BI$4 -> 45934.917 | BJ17: =$BA17+BJ$4 -> 45965.333 | ... CX17: =$BA17+CX$4 -> 47182
A18: ='Market pricing dates'!B7 -> 45681 | B18: =A18 -> 45681 | C18: =$B18+C$4 -> 45711.417 | D18: =$B18+D$4 -> 45741.833 | E18: =$B18+E$4 -> 45772.25 | F18: =$B18+F$4 -> 45802.667 | G18: =$B18+G$4 -> 45833.083 | H18: =$B18+H$4 -> 45863.5 | I18: =$B18+I$4 -> 45893.917 | J18: =$B18+J$4 -> 45924.333 | ... AX18: =$B18+AX$4 -> 47141 | BA18: ='Market pricing dates'!E7 -> 45723 | BB18: =BA18 -> 45723 | BC18: =$BA18+BC$4 -> 45753.417 | BD18: =$BA18+BD$4 -> 45783.833 | BE18: =$BA18+BE$4 -> 45814.25 | BF18: =$BA18+BF$4 -> 45844.667 | BG18: =$BA18+BG$4 -> 45875.083 | BH18: =$BA18+BH$4 -> 45905.5 | BI18: =$BA18+BI$4 -> 45935.917 | BJ18: =$BA18+BJ$4 -> 45966.333 | ... CX18: =$BA18+CX$4 -> 47183
A19: ='Market pricing dates'!B8 -> 45684 | B19: =A19 -> 45684 | C19: =$B19+C$4 -> 45714.417 | D19: =$B19+D$4 -> 45744.833 | E19: =$B19+E$4 -> 45775.25 | F19: =$B19+F$4 -> 45805.667 | G19: =$B19+G$4 -> 45836.083 | H19: =$B19+H$4 -> 45866.5 | I19: =$B19+I$4 -> 45896.917 | J19: =$B19+J$4 -> 45927.333 | ... AX19: =$B19+AX$4 -> 47144 | BA19: ='Market pricing dates'!E8 -> 45726 | BB19: =BA19 -> 45726 | BC19: =$BA19+BC$4 -> 45756.417 | BD19: =$BA19+BD$4 -> 45786.833 | BE19: =$BA19+BE$4 -> 45817.25 | BF19: =$BA19+BF$4 -> 45847.667 | BG19: =$BA19+BG$4 -> 45878.083 | BH19: =$BA19+BH$4 -> 45908.5 | BI19: =$BA19+BI$4 -> 45938.917 | BJ19: =$BA19+BJ$4 -> 45969.333 | ... CX19: =$BA19+CX$4 -> 47186
A20: ='Market pricing dates'!B9 -> 45685 | B20: =A20 -> 45685 | C20: =$B20+C$4 -> 45715.417 | D20: =$B20+D$4 -> 45745.833 | E20: =$B20+E$4 -> 45776.25 | F20: =$B20+F$4 -> 45806.667 | G20: =$B20+G$4 -> 45837.083 | H20: =$B20+H$4 -> 45867.5 | I20: =$B20+I$4 -> 45897.917 | J20: =$B20+J$4 -> 45928.333 | ... AX20: =$B20+AX$4 -> 47145 | BA20: ='Market pricing dates'!E9 -> 45727 | BB20: =BA20 -> 45727 | BC20: =$BA20+BC$4 -> 45757.417 | BD20: =$BA20+BD$4 -> 45787.833 | BE20: =$BA20+BE$4 -> 45818.25 | BF20: =$BA20+BF$4 -> 45848.667 | BG20: =$BA20+BG$4 -> 45879.083 | BH20: =$BA20+BH$4 -> 45909.5 | BI20: =$BA20+BI$4 -> 45939.917 | BJ20: =$BA20+BJ$4 -> 45970.333 | ... CX20: =$BA20+CX$4 -> 47187
A22: Market expectations | BA22: Market expectations
A23: =A6 -> 45665 | B23: =VLOOKUP($A23,HAVERD!$A:$BS,B$2,FALSE) -> 4.7 | C23: =VLOOKUP($A23,HAVERD!$A:$BS,C$2,FALSE) -> 4.6151373 | D23: =VLOOKUP($A23,HAVERD!$A:$BS,D$2,FALSE) -> 4.5287964 | E23: =VLOOKUP($A23,HAVERD!$A:$BS,E$2,FALSE) -> 4.4759515 | F23: =VLOOKUP($A23,HAVERD!$A:$BS,F$2,FALSE) -> 4.4368204 | G23: =VLOOKUP($A23,HAVERD!$A:$BS,G$2,FALSE) -> 4.4010511 | H23: =VLOOKUP($A23,HAVERD!$A:$BS,H$2,FALSE) -> 4.3672281 | I23: =VLOOKUP($A23,HAVERD!$A:$BS,I$2,FALSE) -> 4.3364382 | ... AX23: =VLOOKUP($A23,HAVERD!$A:$BS,AX$2,FALSE) -> 4.0454322 | BA23: =BA6 -> 45707 | BB23: =_xlfn.IFNA(VLOOKUP($BA23,HAVERD!$A:$BS,BB$2,FALSE),"") -> 4.4543 | BC23: =_xlfn.IFNA(VLOOKUP($BA23,HAVERD!$A:$BS,BC$2,FALSE),"") -> 4.4582888 | BD23: =_xlfn.IFNA(VLOOKUP($BA23,HAVERD!$A:$BS,BD$2,FALSE),"") -> 4.3867693 | BE23: =_xlfn.IFNA(VLOOKUP($BA23,HAVERD!$A:$BS,BE$2,FALSE),"") -> 4.3006902 | BF23: =_xlfn.IFNA(VLOOKUP($BA23,HAVERD!$A:$BS,BF$2,FALSE),"") -> 4.2136923 | BG23: =_xlfn.IFNA(VLOOKUP($BA23,HAVERD!$A:$BS,BG$2,FALSE),"") -> 4.136256 | BH23: =_xlfn.IFNA(VLOOKUP($BA23,HAVERD!$A:$BS,BH$2,FALSE),"") -> 4.0726368 | BI23: =_xlfn.IFNA(VLOOKUP($BA23,HAVERD!$A:$BS,BI$2,FALSE),"") -> 4.0244765 | ... CX23: =_xlfn.IFNA(VLOOKUP($BA23,HAVERD!$A:$BS,CX$2,FALSE),"") -> 3.9044401
A24: =A7 -> 45666 | B24: =VLOOKUP($A24,HAVERD!$A:$BS,B$2,FALSE) -> 4.7 | C24: =VLOOKUP($A24,HAVERD!$A:$BS,C$2,FALSE) -> 4.604997 | D24: =VLOOKUP($A24,HAVERD!$A:$BS,D$2,FALSE) -> 4.5109165 | E24: =VLOOKUP($A24,HAVERD!$A:$BS,E$2,FALSE) -> 4.454254 | F24: =VLOOKUP($A24,HAVERD!$A:$BS,F$2,FALSE) -> 4.4128636 | G24: =VLOOKUP($A24,HAVERD!$A:$BS,G$2,FALSE) -> 4.3754509 | H24: =VLOOKUP($A24,HAVERD!$A:$BS,H$2,FALSE) -> 4.3405305 | I24: =VLOOKUP($A24,HAVERD!$A:$BS,I$2,FALSE) -> 4.3092492 | ... AX24: =VLOOKUP($A24,HAVERD!$A:$BS,AX$2,FALSE) -> 4.0525498 | BA24: =BA7 -> 45708 | BB24: =_xlfn.IFNA(VLOOKUP($BA24,HAVERD!$A:$BS,BB$2,FALSE),"") -> 4.4543 | BC24: =_xlfn.IFNA(VLOOKUP($BA24,HAVERD!$A:$BS,BC$2,FALSE),"") -> 4.4549439 | BD24: =_xlfn.IFNA(VLOOKUP($BA24,HAVERD!$A:$BS,BD$2,FALSE),"") -> 4.3888295 | BE24: =_xlfn.IFNA(VLOOKUP($BA24,HAVERD!$A:$BS,BE$2,FALSE),"") -> 4.3059671 | BF24: =_xlfn.IFNA(VLOOKUP($BA24,HAVERD!$A:$BS,BF$2,FALSE),"") -> 4.220164 | BG24: =_xlfn.IFNA(VLOOKUP($BA24,HAVERD!$A:$BS,BG$2,FALSE),"") -> 4.1421522 | BH24: =_xlfn.IFNA(VLOOKUP($BA24,HAVERD!$A:$BS,BH$2,FALSE),"") -> 4.0768151 | BI24: =_xlfn.IFNA(VLOOKUP($BA24,HAVERD!$A:$BS,BI$2,FALSE),"") -> 4.0261351 | ... CX24: =_xlfn.IFNA(VLOOKUP($BA24,HAVERD!$A:$BS,CX$2,FALSE),"") -> 3.9258982
A25: =A8 -> 45667 | B25: =VLOOKUP($A25,HAVERD!$A:$BS,B$2,FALSE) -> 4.7 | C25: =VLOOKUP($A25,HAVERD!$A:$BS,C$2,FALSE) -> 4.6000014 | D25: =VLOOKUP($A25,HAVERD!$A:$BS,D$2,FALSE) -> 4.5105074 | E25: =VLOOKUP($A25,HAVERD!$A:$BS,E$2,FALSE) -> 4.456478 | F25: =VLOOKUP($A25,HAVERD!$A:$BS,F$2,FALSE) -> 4.4178169 | G25: =VLOOKUP($A25,HAVERD!$A:$BS,G$2,FALSE) -> 4.3838371 | H25: =VLOOKUP($A25,HAVERD!$A:$BS,H$2,FALSE) -> 4.352702 | I25: =VLOOKUP($A25,HAVERD!$A:$BS,I$2,FALSE) -> 4.3253638 | ... AX25: =VLOOKUP($A25,HAVERD!$A:$BS,AX$2,FALSE) -> 4.0711338 | BA25: =BA8 -> 45709 | BB25: =_xlfn.IFNA(VLOOKUP($BA25,HAVERD!$A:$BS,BB$2,FALSE),"") -> 4.4549 | BC25: =_xlfn.IFNA(VLOOKUP($BA25,HAVERD!$A:$BS,BC$2,FALSE),"") -> 4.4505201 | BD25: =_xlfn.IFNA(VLOOKUP($BA25,HAVERD!$A:$BS,BD$2,FALSE),"") -> 4.3800096 | BE25: =_xlfn.IFNA(VLOOKUP($BA25,HAVERD!$A:$BS,BE$2,FALSE),"") -> 4.2952907 | BF25: =_xlfn.IFNA(VLOOKUP($BA25,HAVERD!$A:$BS,BF$2,FALSE),"") -> 4.2094131 | BG25: =_xlfn.IFNA(VLOOKUP($BA25,HAVERD!$A:$BS,BG$2,FALSE),"") -> 4.1322403 | BH25: =_xlfn.IFNA(VLOOKUP($BA25,HAVERD!$A:$BS,BH$2,FALSE),"") -> 4.0680501 | BI25: =_xlfn.IFNA(VLOOKUP($BA25,HAVERD!$A:$BS,BI$2,FALSE),"") -> 4.0181879 | ... CX25: =_xlfn.IFNA(VLOOKUP($BA25,HAVERD!$A:$BS,CX$2,FALSE),"") -> 3.8754043
A26: =A9 -> 45670 | B26: =VLOOKUP($A26,HAVERD!$A:$BS,B$2,FALSE) -> 4.7 | C26: =VLOOKUP($A26,HAVERD!$A:$BS,C$2,FALSE) -> 4.583527 | D26: =VLOOKUP($A26,HAVERD!$A:$BS,D$2,FALSE) -> 4.5112586 | E26: =VLOOKUP($A26,HAVERD!$A:$BS,E$2,FALSE) -> 4.4690879 | F26: =VLOOKUP($A26,HAVERD!$A:$BS,F$2,FALSE) -> 4.438039 | G26: =VLOOKUP($A26,HAVERD!$A:$BS,G$2,FALSE) -> 4.4093316 | H26: =VLOOKUP($A26,HAVERD!$A:$BS,H$2,FALSE) -> 4.3818388 | I26: =VLOOKUP($A26,HAVERD!$A:$BS,I$2,FALSE) -> 4.3565668 | ... AX26: =VLOOKUP($A26,HAVERD!$A:$BS,AX$2,FALSE) -> 4.0874707 | BA26: =BA9 -> 45712 | BB26: =_xlfn.IFNA(VLOOKUP($BA26,HAVERD!$A:$BS,BB$2,FALSE),"") -> 4.4545 | BC26: =_xlfn.IFNA(VLOOKUP($BA26,HAVERD!$A:$BS,BC$2,FALSE),"") -> 4.4488754 | BD26: =_xlfn.IFNA(VLOOKUP($BA26,HAVERD!$A:$BS,BD$2,FALSE),"") -> 4.3767178 | BE26: =_xlfn.IFNA(VLOOKUP($BA26,HAVERD!$A:$BS,BE$2,FALSE),"") -> 4.2936555 | BF26: =_xlfn.IFNA(VLOOKUP($BA26,HAVERD!$A:$BS,BF$2,FALSE),"") -> 4.2122104 | BG26: =_xlfn.IFNA(VLOOKUP($BA26,HAVERD!$A:$BS,BG$2,FALSE),"") -> 4.1388356 | BH26: =_xlfn.IFNA(VLOOKUP($BA26,HAVERD!$A:$BS,BH$2,FALSE),"") -> 4.0762553 | BI26: =_xlfn.IFNA(VLOOKUP($BA26,HAVERD!$A:$BS,BI$2,FALSE),"") -> 4.0252535 | ... CX26: =_xlfn.IFNA(VLOOKUP($BA26,HAVERD!$A:$BS,CX$2,FALSE),"") -> 3.8839484
A27: =A10 -> 45671 | B27: =VLOOKUP($A27,HAVERD!$A:$BS,B$2,FALSE) -> 4.7 | C27: =VLOOKUP($A27,HAVERD!$A:$BS,C$2,FALSE) -> 4.5928108 | D27: =VLOOKUP($A27,HAVERD!$A:$BS,D$2,FALSE) -> 4.5365359 | E27: =VLOOKUP($A27,HAVERD!$A:$BS,E$2,FALSE) -> 4.5032957 | F27: =VLOOKUP($A27,HAVERD!$A:$BS,F$2,FALSE) -> 4.4752949 | G27: =VLOOKUP($A27,HAVERD!$A:$BS,G$2,FALSE) -> 4.446087 | H27: =VLOOKUP($A27,HAVERD!$A:$BS,H$2,FALSE) -> 4.4172097 | I27: =VLOOKUP($A27,HAVERD!$A:$BS,I$2,FALSE) -> 4.3922553 | ... AX27: =VLOOKUP($A27,HAVERD!$A:$BS,AX$2,FALSE) -> 4.1407446 | BA27: =BA10 -> 45713 | BB27: =_xlfn.IFNA(VLOOKUP($BA27,HAVERD!$A:$BS,BB$2,FALSE),"") -> 4.4547 | BC27: =_xlfn.IFNA(VLOOKUP($BA27,HAVERD!$A:$BS,BC$2,FALSE),"") -> 4.4468471 | BD27: =_xlfn.IFNA(VLOOKUP($BA27,HAVERD!$A:$BS,BD$2,FALSE),"") -> 4.3716378 | BE27: =_xlfn.IFNA(VLOOKUP($BA27,HAVERD!$A:$BS,BE$2,FALSE),"") -> 4.2849921 | BF27: =_xlfn.IFNA(VLOOKUP($BA27,HAVERD!$A:$BS,BF$2,FALSE),"") -> 4.1996561 | BG27: =_xlfn.IFNA(VLOOKUP($BA27,HAVERD!$A:$BS,BG$2,FALSE),"") -> 4.1218341 | BH27: =_xlfn.IFNA(VLOOKUP($BA27,HAVERD!$A:$BS,BH$2,FALSE),"") -> 4.0542254 | BI27: =_xlfn.IFNA(VLOOKUP($BA27,HAVERD!$A:$BS,BI$2,FALSE),"") -> 3.9980307 | ... CX27: =_xlfn.IFNA(VLOOKUP($BA27,HAVERD!$A:$BS,CX$2,FALSE),"") -> 3.7948826
A28: =A11 -> 45672 | B28: =VLOOKUP($A28,HAVERD!$A:$BS,B$2,FALSE) -> 4.7001 | C28: =VLOOKUP($A28,HAVERD!$A:$BS,C$2,FALSE) -> 4.5407893 | D28: =VLOOKUP($A28,HAVERD!$A:$BS,D$2,FALSE) -> 4.4591869 | E28: =VLOOKUP($A28,HAVERD!$A:$BS,E$2,FALSE) -> 4.406464 | F28: =VLOOKUP($A28,HAVERD!$A:$BS,F$2,FALSE) -> 4.3616584 | G28: =VLOOKUP($A28,HAVERD!$A:$BS,G$2,FALSE) -> 4.3170663 | H28: =VLOOKUP($A28,HAVERD!$A:$BS,H$2,FALSE) -> 4.2738664 | I28: =VLOOKUP($A28,HAVERD!$A:$BS,I$2,FALSE) -> 4.2354391 | ... AX28: =VLOOKUP($A28,HAVERD!$A:$BS,AX$2,FALSE) -> 3.9786814 | BA28: =BA11 -> 45714 | BB28: =_xlfn.IFNA(VLOOKUP($BA28,HAVERD!$A:$BS,BB$2,FALSE),"") -> 4.4547 | BC28: =_xlfn.IFNA(VLOOKUP($BA28,HAVERD!$A:$BS,BC$2,FALSE),"") -> 4.4461588 | BD28: =_xlfn.IFNA(VLOOKUP($BA28,HAVERD!$A:$BS,BD$2,FALSE),"") -> 4.368999 | BE28: =_xlfn.IFNA(VLOOKUP($BA28,HAVERD!$A:$BS,BE$2,FALSE),"") -> 4.2811278 | BF28: =_xlfn.IFNA(VLOOKUP($BA28,HAVERD!$A:$BS,BF$2,FALSE),"") -> 4.1959818 | BG28: =_xlfn.IFNA(VLOOKUP($BA28,HAVERD!$A:$BS,BG$2,FALSE),"") -> 4.118973 | BH28: =_xlfn.IFNA(VLOOKUP($BA28,HAVERD!$A:$BS,BH$2,FALSE),"") -> 4.0520088 | BI28: =_xlfn.IFNA(VLOOKUP($BA28,HAVERD!$A:$BS,BI$2,FALSE),"") -> 3.9965994 | ... CX28: =_xlfn.IFNA(VLOOKUP($BA28,HAVERD!$A:$BS,CX$2,FALSE),"") -> 3.7896401
A29: =A12 -> 45673 | B29: =VLOOKUP($A29,HAVERD!$A:$BS,B$2,FALSE) -> 4.7 | C29: =VLOOKUP($A29,HAVERD!$A:$BS,C$2,FALSE) -> 4.5365792 | D29: =VLOOKUP($A29,HAVERD!$A:$BS,D$2,FALSE) -> 4.4591431 | E29: =VLOOKUP($A29,HAVERD!$A:$BS,E$2,FALSE) -> 4.4049873 | F29: =VLOOKUP($A29,HAVERD!$A:$BS,F$2,FALSE) -> 4.3545297 | G29: =VLOOKUP($A29,HAVERD!$A:$BS,G$2,FALSE) -> 4.3030819 | H29: =VLOOKUP($A29,HAVERD!$A:$BS,H$2,FALSE) -> 4.2536483 | I29: =VLOOKUP($A29,HAVERD!$A:$BS,I$2,FALSE) -> 4.2099764 | ... AX29: =VLOOKUP($A29,HAVERD!$A:$BS,AX$2,FALSE) -> 3.9412115 | BA29: =BA12 -> 45715 | BB29: =_xlfn.IFNA(VLOOKUP($BA29,HAVERD!$A:$BS,BB$2,FALSE),"") -> 4.4547 | BC29: =_xlfn.IFNA(VLOOKUP($BA29,HAVERD!$A:$BS,BC$2,FALSE),"") -> 4.444503 | BD29: =_xlfn.IFNA(VLOOKUP($BA29,HAVERD!$A:$BS,BD$2,FALSE),"") -> 4.3663735 | BE29: =_xlfn.IFNA(VLOOKUP($BA29,HAVERD!$A:$BS,BE$2,FALSE),"") -> 4.2781586 | BF29: =_xlfn.IFNA(VLOOKUP($BA29,HAVERD!$A:$BS,BF$2,FALSE),"") -> 4.1934058 | BG29: =_xlfn.IFNA(VLOOKUP($BA29,HAVERD!$A:$BS,BG$2,FALSE),"") -> 4.1170166 | BH29: =_xlfn.IFNA(VLOOKUP($BA29,HAVERD!$A:$BS,BH$2,FALSE),"") -> 4.0505527 | BI29: =_xlfn.IFNA(VLOOKUP($BA29,HAVERD!$A:$BS,BI$2,FALSE),"") -> 3.9952263 | ... CX29: =_xlfn.IFNA(VLOOKUP($BA29,HAVERD!$A:$BS,CX$2,FALSE),"") -> 3.820733
A30: =A13 -> 45674 | B30: =VLOOKUP($A30,HAVERD!$A:$BS,B$2,FALSE) -> 4.7 | C30: =VLOOKUP($A30,HAVERD!$A:$BS,C$2,FALSE) -> 4.5219514 | D30: =VLOOKUP($A30,HAVERD!$A:$BS,D$2,FALSE) -> 4.4415724 | E30: =VLOOKUP($A30,HAVERD!$A:$BS,E$2,FALSE) -> 4.3810211 | F30: =VLOOKUP($A30,HAVERD!$A:$BS,F$2,FALSE) -> 4.3255362 | G30: =VLOOKUP($A30,HAVERD!$A:$BS,G$2,FALSE) -> 4.2715314 | H30: =VLOOKUP($A30,HAVERD!$A:$BS,H$2,FALSE) -> 4.2216815 | I30: =VLOOKUP($A30,HAVERD!$A:$BS,I$2,FALSE) -> 4.1788801 | ... AX30: =VLOOKUP($A30,HAVERD!$A:$BS,AX$2,FALSE) -> 3.9200765 | BA30: =BA13 -> 45716 | BB30: =_xlfn.IFNA(VLOOKUP($BA30,HAVERD!$A:$BS,BB$2,FALSE),"") -> 4.4552 | BC30: =_xlfn.IFNA(VLOOKUP($BA30,HAVERD!$A:$BS,BC$2,FALSE),"") -> 4.4457987 | BD30: =_xlfn.IFNA(VLOOKUP($BA30,HAVERD!$A:$BS,BD$2,FALSE),"") -> 4.3680602 | BE30: =_xlfn.IFNA(VLOOKUP($BA30,HAVERD!$A:$BS,BE$2,FALSE),"") -> 4.2781697 | BF30: =_xlfn.IFNA(VLOOKUP($BA30,HAVERD!$A:$BS,BF$2,FALSE),"") -> 4.191606 | BG30: =_xlfn.IFNA(VLOOKUP($BA30,HAVERD!$A:$BS,BG$2,FALSE),"") -> 4.1142582 | BH30: =_xlfn.IFNA(VLOOKUP($BA30,HAVERD!$A:$BS,BH$2,FALSE),"") -> 4.046947 | BI30: =_xlfn.IFNA(VLOOKUP($BA30,HAVERD!$A:$BS,BI$2,FALSE),"") -> 3.9904155 | ... CX30: =_xlfn.IFNA(VLOOKUP($BA30,HAVERD!$A:$BS,CX$2,FALSE),"") -> 3.7762567
A31: =A14 -> 45677 | B31: =VLOOKUP($A31,HAVERD!$A:$BS,B$2,FALSE) -> 4.7 | C31: =VLOOKUP($A31,HAVERD!$A:$BS,C$2,FALSE) -> 4.5000267 | D31: =VLOOKUP($A31,HAVERD!$A:$BS,D$2,FALSE) -> 4.4463263 | E31: =VLOOKUP($A31,HAVERD!$A:$BS,E$2,FALSE) -> 4.3909734 | F31: =VLOOKUP($A31,HAVERD!$A:$BS,F$2,FALSE) -> 4.332188 | G31: =VLOOKUP($A31,HAVERD!$A:$BS,G$2,FALSE) -> 4.2745293 | H31: =VLOOKUP($A31,HAVERD!$A:$BS,H$2,FALSE) -> 4.2228441 | I31: =VLOOKUP($A31,HAVERD!$A:$BS,I$2,FALSE) -> 4.1799756 | ... AX31: =VLOOKUP($A31,HAVERD!$A:$BS,AX$2,FALSE) -> 3.9254038 | BA31: =BA14 -> 45719 | BB31: =_xlfn.IFNA(VLOOKUP($BA31,HAVERD!$A:$BS,BB$2,FALSE),"") -> 4.455 | BC31: =_xlfn.IFNA(VLOOKUP($BA31,HAVERD!$A:$BS,BC$2,FALSE),"") -> 4.4462565 | BD31: =_xlfn.IFNA(VLOOKUP($BA31,HAVERD!$A:$BS,BD$2,FALSE),"") -> 4.3679877 | BE31: =_xlfn.IFNA(VLOOKUP($BA31,HAVERD!$A:$BS,BE$2,FALSE),"") -> 4.2797481 | BF31: =_xlfn.IFNA(VLOOKUP($BA31,HAVERD!$A:$BS,BF$2,FALSE),"") -> 4.1987048 | BG31: =_xlfn.IFNA(VLOOKUP($BA31,HAVERD!$A:$BS,BG$2,FALSE),"") -> 4.1278003 | BH31: =_xlfn.IFNA(VLOOKUP($BA31,HAVERD!$A:$BS,BH$2,FALSE),"") -> 4.0667299 | BI31: =_xlfn.IFNA(VLOOKUP($BA31,HAVERD!$A:$BS,BI$2,FALSE),"") -> 4.0163036 | ... CX31: =_xlfn.IFNA(VLOOKUP($BA31,HAVERD!$A:$BS,CX$2,FALSE),"") -> 3.8042811
A32: =A15 -> 45678 | B32: =VLOOKUP($A32,HAVERD!$A:$BS,B$2,FALSE) -> 4.7 | C32: =VLOOKUP($A32,HAVERD!$A:$BS,C$2,FALSE) -> 4.484872 | D32: =VLOOKUP($A32,HAVERD!$A:$BS,D$2,FALSE) -> 4.4384666 | E32: =VLOOKUP($A32,HAVERD!$A:$BS,E$2,FALSE) -> 4.3841836 | F32: =VLOOKUP($A32,HAVERD!$A:$BS,F$2,FALSE) -> 4.3240279 | G32: =VLOOKUP($A32,HAVERD!$A:$BS,G$2,FALSE) -> 4.2650434 | H32: =VLOOKUP($A32,HAVERD!$A:$BS,H$2,FALSE) -> 4.212658 | I32: =VLOOKUP($A32,HAVERD!$A:$BS,I$2,FALSE) -> 4.1700255 | ... AX32: =VLOOKUP($A32,HAVERD!$A:$BS,AX$2,FALSE) -> 3.8604511 | BA32: =BA15 -> 45720 | BB32: =_xlfn.IFNA(VLOOKUP($BA32,HAVERD!$A:$BS,BB$2,FALSE),"") -> 4.4551 | BC32: =_xlfn.IFNA(VLOOKUP($BA32,HAVERD!$A:$BS,BC$2,FALSE),"") -> 4.4415946 | BD32: =_xlfn.IFNA(VLOOKUP($BA32,HAVERD!$A:$BS,BD$2,FALSE),"") -> 4.3611957 | BE32: =_xlfn.IFNA(VLOOKUP($BA32,HAVERD!$A:$BS,BE$2,FALSE),"") -> 4.2711778 | BF32: =_xlfn.IFNA(VLOOKUP($BA32,HAVERD!$A:$BS,BF$2,FALSE),"") -> 4.1885673 | BG32: =_xlfn.IFNA(VLOOKUP($BA32,HAVERD!$A:$BS,BG$2,FALSE),"") -> 4.1154542 | BH32: =_xlfn.IFNA(VLOOKUP($BA32,HAVERD!$A:$BS,BH$2,FALSE),"") -> 4.0511841 | BI32: =_xlfn.IFNA(VLOOKUP($BA32,HAVERD!$A:$BS,BI$2,FALSE),"") -> 3.9966813 | ... CX32: =_xlfn.IFNA(VLOOKUP($BA32,HAVERD!$A:$BS,CX$2,FALSE),"") -> 3.782176
A33: =A16 -> 45679 | B33: =VLOOKUP($A33,HAVERD!$A:$BS,B$2,FALSE) -> 4.7 | C33: =VLOOKUP($A33,HAVERD!$A:$BS,C$2,FALSE) -> 4.4757356 | D33: =VLOOKUP($A33,HAVERD!$A:$BS,D$2,FALSE) -> 4.4383779 | E33: =VLOOKUP($A33,HAVERD!$A:$BS,E$2,FALSE) -> 4.3856464 | F33: =VLOOKUP($A33,HAVERD!$A:$BS,F$2,FALSE) -> 4.3229666 | G33: =VLOOKUP($A33,HAVERD!$A:$BS,G$2,FALSE) -> 4.2598599 | H33: =VLOOKUP($A33,HAVERD!$A:$BS,H$2,FALSE) -> 4.2032262 | I33: =VLOOKUP($A33,HAVERD!$A:$BS,I$2,FALSE) -> 4.1570015 | ... AX33: =VLOOKUP($A33,HAVERD!$A:$BS,AX$2,FALSE) -> 3.8686946 | BA33: =BA16 -> 45721 | BB33: =_xlfn.IFNA(VLOOKUP($BA33,HAVERD!$A:$BS,BB$2,FALSE),"") -> 4.455 | BC33: =_xlfn.IFNA(VLOOKUP($BA33,HAVERD!$A:$BS,BC$2,FALSE),"") -> 4.4465266 | BD33: =_xlfn.IFNA(VLOOKUP($BA33,HAVERD!$A:$BS,BD$2,FALSE),"") -> 4.3696171 | BE33: =_xlfn.IFNA(VLOOKUP($BA33,HAVERD!$A:$BS,BE$2,FALSE),"") -> 4.2858851 | BF33: =_xlfn.IFNA(VLOOKUP($BA33,HAVERD!$A:$BS,BF$2,FALSE),"") -> 4.2090963 | BG33: =_xlfn.IFNA(VLOOKUP($BA33,HAVERD!$A:$BS,BG$2,FALSE),"") -> 4.1413667 | BH33: =_xlfn.IFNA(VLOOKUP($BA33,HAVERD!$A:$BS,BH$2,FALSE),"") -> 4.0831071 | BI33: =_xlfn.IFNA(VLOOKUP($BA33,HAVERD!$A:$BS,BI$2,FALSE),"") -> 4.0356271 | ... CX33: =_xlfn.IFNA(VLOOKUP($BA33,HAVERD!$A:$BS,CX$2,FALSE),"") -> 3.9511751
A34: =A17 -> 45680 | B34: =VLOOKUP($A34,HAVERD!$A:$BS,B$2,FALSE) -> 4.7001 | C34: =VLOOKUP($A34,HAVERD!$A:$BS,C$2,FALSE) -> 4.4650853 | D34: =VLOOKUP($A34,HAVERD!$A:$BS,D$2,FALSE) -> 4.4336144 | E34: =VLOOKUP($A34,HAVERD!$A:$BS,E$2,FALSE) -> 4.3790128 | F34: =VLOOKUP($A34,HAVERD!$A:$BS,F$2,FALSE) -> 4.3105457 | G34: =VLOOKUP($A34,HAVERD!$A:$BS,G$2,FALSE) -> 4.2407452 | H34: =VLOOKUP($A34,HAVERD!$A:$BS,H$2,FALSE) -> 4.178016 | I34: =VLOOKUP($A34,HAVERD!$A:$BS,I$2,FALSE) -> 4.1267057 | ... AX34: =VLOOKUP($A34,HAVERD!$A:$BS,AX$2,FALSE) -> 3.8872239 | BA34: =BA17 -> 45722 | BB34: =_xlfn.IFNA(VLOOKUP($BA34,HAVERD!$A:$BS,BB$2,FALSE),"") -> 4.4557 | BC34: =_xlfn.IFNA(VLOOKUP($BA34,HAVERD!$A:$BS,BC$2,FALSE),"") -> 4.4467328 | BD34: =_xlfn.IFNA(VLOOKUP($BA34,HAVERD!$A:$BS,BD$2,FALSE),"") -> 4.3658811 | BE34: =_xlfn.IFNA(VLOOKUP($BA34,HAVERD!$A:$BS,BE$2,FALSE),"") -> 4.2788619 | BF34: =_xlfn.IFNA(VLOOKUP($BA34,HAVERD!$A:$BS,BF$2,FALSE),"") -> 4.2024214 | BG34: =_xlfn.IFNA(VLOOKUP($BA34,HAVERD!$A:$BS,BG$2,FALSE),"") -> 4.1370563 | BH34: =_xlfn.IFNA(VLOOKUP($BA34,HAVERD!$A:$BS,BH$2,FALSE),"") -> 4.0809187 | BI34: =_xlfn.IFNA(VLOOKUP($BA34,HAVERD!$A:$BS,BI$2,FALSE),"") -> 4.0336996 | ... CX34: =_xlfn.IFNA(VLOOKUP($BA34,HAVERD!$A:$BS,CX$2,FALSE),"") -> 3.937386
... A37: =A20 -> 45685 | B37: =VLOOKUP($A37,HAVERD!$A:$BS,B$2,FALSE) -> 4.7 | C37: =VLOOKUP($A37,HAVERD!$A:$BS,C$2,FALSE) -> 4.4598169 | D37: =VLOOKUP($A37,HAVERD!$A:$BS,D$2,FALSE) -> 4.4206843 | E37: =VLOOKUP($A37,HAVERD!$A:$BS,E$2,FALSE) -> 4.362708 | F37: =VLOOKUP($A37,HAVERD!$A:$BS,F$2,FALSE) -> 4.2944473 | G37: =VLOOKUP($A37,HAVERD!$A:$BS,G$2,FALSE) -> 4.2275019 | H37: =VLOOKUP($A37,HAVERD!$A:$BS,H$2,FALSE) -> 4.1682824 | I37: =VLOOKUP($A37,HAVERD!$A:$BS,I$2,FALSE) -> 4.1201531 | ... AX37: =VLOOKUP($A37,HAVERD!$A:$BS,AX$2,FALSE) -> 3.8577803 | BA37: =BA20 -> 45727 | BB37: =_xlfn.IFNA(VLOOKUP($BA37,HAVERD!$A:$BS,BB$2,FALSE),"") | BC37: =_xlfn.IFNA(VLOOKUP($BA37,HAVERD!$A:$BS,BC$2,FALSE),"") | BD37: =_xlfn.IFNA(VLOOKUP($BA37,HAVERD!$A:$BS,BD$2,FALSE),"") | BE37: =_xlfn.IFNA(VLOOKUP($BA37,HAVERD!$A:$BS,BE$2,FALSE),"") | BF37: =_xlfn.IFNA(VLOOKUP($BA37,HAVERD!$A:$BS,BF$2,FALSE),"") | BG37: =_xlfn.IFNA(VLOOKUP($BA37,HAVERD!$A:$BS,BG$2,FALSE),"") | BH37: =_xlfn.IFNA(VLOOKUP($BA37,HAVERD!$A:$BS,BH$2,FALSE),"") | BI37: =_xlfn.IFNA(VLOOKUP($BA37,HAVERD!$A:$BS,BI$2,FALSE),"") | ... CX37: =_xlfn.IFNA(VLOOKUP($BA37,HAVERD!$A:$BS,CX$2,FALSE),"")
A39: Average | BA39: Average
A40: Month | B40: =MONTH(B20) -> 1 | C40: =MONTH(C20) -> 2 | D40: =MONTH(D20) -> 3 | E40: =MONTH(E20) -> 4 | F40: =MONTH(F20) -> 5 | G40: =MONTH(G20) -> 6 | H40: =MONTH(H20) -> 7 | I40: =MONTH(I20) -> 8 | ... AX40: =MONTH(AX20) -> 1 | BA40: Month | BB40: =MONTH(BB18) -> 3 | BC40: =MONTH(BC18) -> 4 | BD40: =MONTH(BD18) -> 5 | BE40: =MONTH(BE18) -> 6 | BF40: =MONTH(BF18) -> 7 | BG40: =MONTH(BG18) -> 8 | BH40: =MONTH(BH18) -> 9 | BI40: =MONTH(BI18) -> 10 | ... CX40: =MONTH(CX18) -> 3
A41: Year | B41: =YEAR(B20) -> 2025 | C41: =YEAR(C20) -> 2025 | D41: =YEAR(D20) -> 2025 | E41: =YEAR(E20) -> 2025 | F41: =YEAR(F20) -> 2025 | G41: =YEAR(G20) -> 2025 | H41: =YEAR(H20) -> 2025 | I41: =YEAR(I20) -> 2025 | ... AX41: =YEAR(AX20) -> 2029 | BA41: Year | BB41: =YEAR(BB20) -> 2025 | BC41: =YEAR(BC20) -> 2025 | BD41: =YEAR(BD20) -> 2025 | BE41: =YEAR(BE20) -> 2025 | BF41: =YEAR(BF20) -> 2025 | BG41: =YEAR(BG20) -> 2025 | BH41: =YEAR(BH20) -> 2025 | BI41: =YEAR(BI20) -> 2025 | ... CX41: =YEAR(CX20) -> 2029
A42: YYYYMM | B42: =B41*100+B40 -> 202501 | C42: =C41*100+C40 -> 202502 | D42: =D41*100+D40 -> 202503 | E42: =E41*100+E40 -> 202504 | F42: =F41*100+F40 -> 202505 | G42: =G41*100+G40 -> 202506 | H42: =H41*100+H40 -> 202507 | I42: =I41*100+I40 -> 202508 | ... AX42: =AX41*100+AX40 -> 202901 | BA42: YYYYMM | BB42: =BB41*100+BB40 -> 202503 | BC42: =BC41*100+BC40 -> 202504 | BD42: =BD41*100+BD40 -> 202505 | BE42: =BE41*100+BE40 -> 202506 | BF42: =BF41*100+BF40 -> 202507 | BG42: =BG41*100+BG40 -> 202508 | BH42: =BH41*100+BH40 -> 202509 | BI42: =BI41*100+BI40 -> 202510 | ... CX42: =CX41*100+CX40 -> 202903
A43: Quarter | B43: =IF(B40<4,1,IF(B40<7,2,IF(B40<10,3,4))) -> 1 | C43: =IF(C40<4,1,IF(C40<7,2,IF(C40<10,3,4))) -> 1 | D43: =IF(D40<4,1,IF(D40<7,2,IF(D40<10,3,4))) -> 1 | E43: =IF(E40<4,1,IF(E40<7,2,IF(E40<10,3,4))) -> 2 | F43: =IF(F40<4,1,IF(F40<7,2,IF(F40<10,3,4))) -> 2 | G43: =IF(G40<4,1,IF(G40<7,2,IF(G40<10,3,4))) -> 2 | H43: =IF(H40<4,1,IF(H40<7,2,IF(H40<10,3,4))) -> 3 | I43: =IF(I40<4,1,IF(I40<7,2,IF(I40<10,3,4))) -> 3 | ... AX43: =IF(AX40<4,1,IF(AX40<7,2,IF(AX40<10,3,4))) -> 1 | BA43: Quarter | BB43: =IF(BB40<4,1,IF(BB40<7,2,IF(BB40<10,3,4))) -> 1 | BC43: =IF(BC40<4,1,IF(BC40<7,2,IF(BC40<10,3,4))) -> 2 | BD43: =IF(BD40<4,1,IF(BD40<7,2,IF(BD40<10,3,4))) -> 2 | BE43: =IF(BE40<4,1,IF(BE40<7,2,IF(BE40<10,3,4))) -> 2 | BF43: =IF(BF40<4,1,IF(BF40<7,2,IF(BF40<10,3,4))) -> 3 | BG43: =IF(BG40<4,1,IF(BG40<7,2,IF(BG40<10,3,4))) -> 3 | BH43: =IF(BH40<4,1,IF(BH40<7,2,IF(BH40<10,3,4))) -> 3 | BI43: =IF(BI40<4,1,IF(BI40<7,2,IF(BI40<10,3,4))) -> 4 | ... CX43: =IF(CX40<4,1,IF(CX40<7,2,IF(CX40<10,3,4))) -> 1
A44: YYYYQQ | B44: =B41*100+B43 -> 202501 | C44: =C41*100+C43 -> 202501 | D44: =D41*100+D43 -> 202501 | E44: =E41*100+E43 -> 202502 | F44: =F41*100+F43 -> 202502 | G44: =G41*100+G43 -> 202502 | H44: =H41*100+H43 -> 202503 | I44: =I41*100+I43 -> 202503 | ... AX44: =AX41*100+AX43 -> 202901 | BA44: YYYYQQ | BB44: =BB41*100+BB43 -> 202501 | BC44: =BC41*100+BC43 -> 202502 | BD44: =BD41*100+BD43 -> 202502 | BE44: =BE41*100+BE43 -> 202502 | BF44: =BF41*100+BF43 -> 202503 | BG44: =BG41*100+BG43 -> 202503 | BH44: =BH41*100+BH43 -> 202503 | BI44: =BI41*100+BI43 -> 202504 | ... CX44: =CX41*100+CX43 -> 202901
...

Sheet Market expectations - Gas
A1: ='Market pricing dates'!A2 -> February 2025 MPR | C1: ='Market pricing dates'!A12 -> 15 working days to 28 Jan 2025 | AZ1: ='Market pricing dates'!D2 -> March 2025 | BB1: ='Market pricing dates'!D12 -> 15 working days to 11 Mar 2025
A2: Column # | B2: =HAVERD!BU$1 -> 73 | C2: =+B2+1 -> 74 | D2: =+C2+1 -> 75 | E2: =+D2+1 -> 76 | F2: =+E2+1 -> 77 | G2: =+F2+1 -> 78 | H2: =+G2+1 -> 79 | I2: =+H2+1 -> 80 | J2: =+I2+1 -> 81 | ... AW2: =+AV2+1 -> 120 | AZ2: Column # | BA2: =HAVERD!BU$1 -> 73 | BB2: =+BA2+1 -> 74 | BC2: =+BB2+1 -> 75 | BD2: =+BC2+1 -> 76 | BE2: =+BD2+1 -> 77 | BF2: =+BE2+1 -> 78 | BG2: =+BF2+1 -> 79 | BH2: =+BG2+1 -> 80 | BI2: =+BH2+1 -> 81 | ... CV2: =+CU2+1 -> 120
A3: Months | B3: =HAVERD!BU$2 -> Gas - 1 | C3: =HAVERD!BV$2 -> Gas - 2 | D3: =HAVERD!BW$2 -> Gas - 3 | E3: =HAVERD!BX$2 -> Gas - 4 | F3: =HAVERD!BY$2 -> Gas - 5 | G3: =HAVERD!BZ$2 -> Gas - 6 | H3: =HAVERD!CA$2 -> Gas - 7 | I3: =HAVERD!CB$2 -> Gas - 8 | ... AW3: =HAVERD!DP$2 -> Gas - 48 | AZ3: Months | BA3: =HAVERD!BU$2 -> Gas - 1 | BB3: =HAVERD!BV$2 -> Gas - 2 | BC3: =HAVERD!BW$2 -> Gas - 3 | BD3: =HAVERD!BX$2 -> Gas - 4 | BE3: =HAVERD!BY$2 -> Gas - 5 | BF3: =HAVERD!BZ$2 -> Gas - 6 | BG3: =HAVERD!CA$2 -> Gas - 7 | BH3: =HAVERD!CB$2 -> Gas - 8 | ... CV3: =HAVERD!DP$2 -> Gas - 48
A4: Days | C4: 30.416667 | D4: =+C4+30.4166667 -> 60.833333 | E4: =+D4+30.4166667 -> 91.25 | F4: =+E4+30.4166667 -> 121.66667 | G4: =+F4+30.4166667 -> 152.08333 | H4: =+G4+30.4166667 -> 182.5 | I4: =+H4+30.4166667 -> 212.91667 | J4: =+I4+30.4166667 -> 243.33333 | K4: =+J4+30.4166667 -> 273.75 | ... AW4: =+AV4+30.4166667 -> 1429.5833 | AZ4: Days | BB4: 30.416667 | BC4: =+BB4+30.4166667 -> 60.833333 | BD4: =+BC4+30.4166667 -> 91.25 | BE4: =+BD4+30.4166667 -> 121.66667 | BF4: =+BE4+30.4166667 -> 152.08333 | BG4: =+BF4+30.4166667 -> 182.5 | BH4: =+BG4+30.4166667 -> 212.91667 | BI4: =+BH4+30.4166667 -> 243.33333 | BJ4: =+BI4+30.4166667 -> 273.75 | ... CV4: =+CU4+30.4166667 -> 1429.5833
A5: Dates | AZ5: Dates
A6: =A11-7 -> 45665 | B6: =A6 -> 45665 | C6: =$B6+C$4 -> 45695.417 | D6: =$B6+D$4 -> 45725.833 | E6: =$B6+E$4 -> 45756.25 | F6: =$B6+F$4 -> 45786.667 | G6: =$B6+G$4 -> 45817.083 | H6: =$B6+H$4 -> 45847.5 | I6: =$B6+I$4 -> 45877.917 | J6: =$B6+J$4 -> 45908.333 | ... AW6: =$B6+AW$4 -> 47094.583 | AZ6: =AZ11-7 -> 45707 | BA6: =AZ6 -> 45707 | BB6: =$AZ6+BB$4 -> 45737.417 | BC6: =$AZ6+BC$4 -> 45767.833 | BD6: =$AZ6+BD$4 -> 45798.25 | BE6: =$AZ6+BE$4 -> 45828.667 | BF6: =$AZ6+BF$4 -> 45859.083 | BG6: =$AZ6+BG$4 -> 45889.5 | BH6: =$AZ6+BH$4 -> 45919.917 | BI6: =$AZ6+BI$4 -> 45950.333 | ... CV6: =$AZ6+CV$4 -> 47136.583
A7: =A12-7 -> 45666 | B7: =A7 -> 45666 | C7: =$B7+C$4 -> 45696.417 | D7: =$B7+D$4 -> 45726.833 | E7: =$B7+E$4 -> 45757.25 | F7: =$B7+F$4 -> 45787.667 | G7: =$B7+G$4 -> 45818.083 | H7: =$B7+H$4 -> 45848.5 | I7: =$B7+I$4 -> 45878.917 | J7: =$B7+J$4 -> 45909.333 | ... AW7: =$B7+AW$4 -> 47095.583 | AZ7: =AZ12-7 -> 45708 | BA7: =AZ7 -> 45708 | BB7: =$AZ7+BB$4 -> 45738.417 | BC7: =$AZ7+BC$4 -> 45768.833 | BD7: =$AZ7+BD$4 -> 45799.25 | BE7: =$AZ7+BE$4 -> 45829.667 | BF7: =$AZ7+BF$4 -> 45860.083 | BG7: =$AZ7+BG$4 -> 45890.5 | BH7: =$AZ7+BH$4 -> 45920.917 | BI7: =$AZ7+BI$4 -> 45951.333 | ... CV7: =$AZ7+CV$4 -> 47137.583
A8: =A13-7 -> 45667 | B8: =A8 -> 45667 | C8: =$B8+C$4 -> 45697.417 | D8: =$B8+D$4 -> 45727.833 | E8: =$B8+E$4 -> 45758.25 | F8: =$B8+F$4 -> 45788.667 | G8: =$B8+G$4 -> 45819.083 | H8: =$B8+H$4 -> 45849.5 | I8: =$B8+I$4 -> 45879.917 | J8: =$B8+J$4 -> 45910.333 | ... AW8: =$B8+AW$4 -> 47096.583 | AZ8: =AZ13-7 -> 45709 | BA8: =AZ8 -> 45709 | BB8: =$AZ8+BB$4 -> 45739.417 | BC8: =$AZ8+BC$4 -> 45769.833 | BD8: =$AZ8+BD$4 -> 45800.25 | BE8: =$AZ8+BE$4 -> 45830.667 | BF8: =$AZ8+BF$4 -> 45861.083 | BG8: =$AZ8+BG$4 -> 45891.5 | BH8: =$AZ8+BH$4 -> 45921.917 | BI8: =$AZ8+BI$4 -> 45952.333 | ... CV8: =$AZ8+CV$4 -> 47138.583
A9: =A14-7 -> 45670 | B9: =A9 -> 45670 | C9: =$B9+C$4 -> 45700.417 | D9: =$B9+D$4 -> 45730.833 | E9: =$B9+E$4 -> 45761.25 | F9: =$B9+F$4 -> 45791.667 | G9: =$B9+G$4 -> 45822.083 | H9: =$B9+H$4 -> 45852.5 | I9: =$B9+I$4 -> 45882.917 | J9: =$B9+J$4 -> 45913.333 | ... AW9: =$B9+AW$4 -> 47099.583 | AZ9: =AZ14-7 -> 45712 | BA9: =AZ9 -> 45712 | BB9: =$AZ9+BB$4 -> 45742.417 | BC9: =$AZ9+BC$4 -> 45772.833 | BD9: =$AZ9+BD$4 -> 45803.25 | BE9: =$AZ9+BE$4 -> 45833.667 | BF9: =$AZ9+BF$4 -> 45864.083 | BG9: =$AZ9+BG$4 -> 45894.5 | BH9: =$AZ9+BH$4 -> 45924.917 | BI9: =$AZ9+BI$4 -> 45955.333 | ... CV9: =$AZ9+CV$4 -> 47141.583
A10: =A15-7 -> 45671 | B10: =A10 -> 45671 | C10: =$B10+C$4 -> 45701.417 | D10: =$B10+D$4 -> 45731.833 | E10: =$B10+E$4 -> 45762.25 | F10: =$B10+F$4 -> 45792.667 | G10: =$B10+G$4 -> 45823.083 | H10: =$B10+H$4 -> 45853.5 | I10: =$B10+I$4 -> 45883.917 | J10: =$B10+J$4 -> 45914.333 | ... AW10: =$B10+AW$4 -> 47100.583 | AZ10: =AZ15-7 -> 45713 | BA10: =AZ10 -> 45713 | BB10: =$AZ10+BB$4 -> 45743.417 | BC10: =$AZ10+BC$4 -> 45773.833 | BD10: =$AZ10+BD$4 -> 45804.25 | BE10: =$AZ10+BE$4 -> 45834.667 | BF10: =$AZ10+BF$4 -> 45865.083 | BG10: =$AZ10+BG$4 -> 45895.5 | BH10: =$AZ10+BH$4 -> 45925.917 | BI10: =$AZ10+BI$4 -> 45956.333 | ... CV10: =$AZ10+CV$4 -> 47142.583
A11: =A16-7 -> 45672 | B11: =A11 -> 45672 | C11: =$B11+C$4 -> 45702.417 | D11: =$B11+D$4 -> 45732.833 | E11: =$B11+E$4 -> 45763.25 | F11: =$B11+F$4 -> 45793.667 | G11: =$B11+G$4 -> 45824.083 | H11: =$B11+H$4 -> 45854.5 | I11: =$B11+I$4 -> 45884.917 | J11: =$B11+J$4 -> 45915.333 | ... AW11: =$B11+AW$4 -> 47101.583 | AZ11: =AZ16-7 -> 45714 | BA11: =AZ11 -> 45714 | BB11: =$AZ11+BB$4 -> 45744.417 | BC11: =$AZ11+BC$4 -> 45774.833 | BD11: =$AZ11+BD$4 -> 45805.25 | BE11: =$AZ11+BE$4 -> 45835.667 | BF11: =$AZ11+BF$4 -> 45866.083 | BG11: =$AZ11+BG$4 -> 45896.5 | BH11: =$AZ11+BH$4 -> 45926.917 | BI11: =$AZ11+BI$4 -> 45957.333 | ... CV11: =$AZ11+CV$4 -> 47143.583
A12: =A17-7 -> 45673 | B12: =A12 -> 45673 | C12: =$B12+C$4 -> 45703.417 | D12: =$B12+D$4 -> 45733.833 | E12: =$B12+E$4 -> 45764.25 | F12: =$B12+F$4 -> 45794.667 | G12: =$B12+G$4 -> 45825.083 | H12: =$B12+H$4 -> 45855.5 | I12: =$B12+I$4 -> 45885.917 | J12: =$B12+J$4 -> 45916.333 | ... AW12: =$B12+AW$4 -> 47102.583 | AZ12: =AZ17-7 -> 45715 | BA12: =AZ12 -> 45715 | BB12: =$AZ12+BB$4 -> 45745.417 | BC12: =$AZ12+BC$4 -> 45775.833 | BD12: =$AZ12+BD$4 -> 45806.25 | BE12: =$AZ12+BE$4 -> 45836.667 | BF12: =$AZ12+BF$4 -> 45867.083 | BG12: =$AZ12+BG$4 -> 45897.5 | BH12: =$AZ12+BH$4 -> 45927.917 | BI12: =$AZ12+BI$4 -> 45958.333 | ... CV12: =$AZ12+CV$4 -> 47144.583
A13: =A18-7 -> 45674 | B13: =A13 -> 45674 | C13: =$B13+C$4 -> 45704.417 | D13: =$B13+D$4 -> 45734.833 | E13: =$B13+E$4 -> 45765.25 | F13: =$B13+F$4 -> 45795.667 | G13: =$B13+G$4 -> 45826.083 | H13: =$B13+H$4 -> 45856.5 | I13: =$B13+I$4 -> 45886.917 | J13: =$B13+J$4 -> 45917.333 | ... AW13: =$B13+AW$4 -> 47103.583 | AZ13: =AZ18-7 -> 45716 | BA13: =AZ13 -> 45716 | BB13: =$AZ13+BB$4 -> 45746.417 | BC13: =$AZ13+BC$4 -> 45776.833 | BD13: =$AZ13+BD$4 -> 45807.25 | BE13: =$AZ13+BE$4 -> 45837.667 | BF13: =$AZ13+BF$4 -> 45868.083 | BG13: =$AZ13+BG$4 -> 45898.5 | BH13: =$AZ13+BH$4 -> 45928.917 | BI13: =$AZ13+BI$4 -> 45959.333 | ... CV13: =$AZ13+CV$4 -> 47145.583
A14: =A19-7 -> 45677 | B14: =A14 -> 45677 | C14: =$B14+C$4 -> 45707.417 | D14: =$B14+D$4 -> 45737.833 | E14: =$B14+E$4 -> 45768.25 | F14: =$B14+F$4 -> 45798.667 | G14: =$B14+G$4 -> 45829.083 | H14: =$B14+H$4 -> 45859.5 | I14: =$B14+I$4 -> 45889.917 | J14: =$B14+J$4 -> 45920.333 | ... AW14: =$B14+AW$4 -> 47106.583 | AZ14: =AZ19-7 -> 45719 | BA14: =AZ14 -> 45719 | BB14: =$AZ14+BB$4 -> 45749.417 | BC14: =$AZ14+BC$4 -> 45779.833 | BD14: =$AZ14+BD$4 -> 45810.25 | BE14: =$AZ14+BE$4 -> 45840.667 | BF14: =$AZ14+BF$4 -> 45871.083 | BG14: =$AZ14+BG$4 -> 45901.5 | BH14: =$AZ14+BH$4 -> 45931.917 | BI14: =$AZ14+BI$4 -> 45962.333 | ... CV14: =$AZ14+CV$4 -> 47148.583
A15: =A20-7 -> 45678 | B15: =A15 -> 45678 | C15: =$B15+C$4 -> 45708.417 | D15: =$B15+D$4 -> 45738.833 | E15: =$B15+E$4 -> 45769.25 | F15: =$B15+F$4 -> 45799.667 | G15: =$B15+G$4 -> 45830.083 | H15: =$B15+H$4 -> 45860.5 | I15: =$B15+I$4 -> 45890.917 | J15: =$B15+J$4 -> 45921.333 | ... AW15: =$B15+AW$4 -> 47107.583 | AZ15: =AZ20-7 -> 45720 | BA15: =AZ15 -> 45720 | BB15: =$AZ15+BB$4 -> 45750.417 | BC15: =$AZ15+BC$4 -> 45780.833 | BD15: =$AZ15+BD$4 -> 45811.25 | BE15: =$AZ15+BE$4 -> 45841.667 | BF15: =$AZ15+BF$4 -> 45872.083 | BG15: =$AZ15+BG$4 -> 45902.5 | BH15: =$AZ15+BH$4 -> 45932.917 | BI15: =$AZ15+BI$4 -> 45963.333 | ... CV15: =$AZ15+CV$4 -> 47149.583
A16: ='Market pricing dates'!B5 -> 45679 | B16: =A16 -> 45679 | C16: =$B16+C$4 -> 45709.417 | D16: =$B16+D$4 -> 45739.833 | E16: =$B16+E$4 -> 45770.25 | F16: =$B16+F$4 -> 45800.667 | G16: =$B16+G$4 -> 45831.083 | H16: =$B16+H$4 -> 45861.5 | I16: =$B16+I$4 -> 45891.917 | J16: =$B16+J$4 -> 45922.333 | ... AW16: =$B16+AW$4 -> 47108.583 | AZ16: ='Market pricing dates'!E5 -> 45721 | BA16: =AZ16 -> 45721 | BB16: =$AZ16+BB$4 -> 45751.417 | BC16: =$AZ16+BC$4 -> 45781.833 | BD16: =$AZ16+BD$4 -> 45812.25 | BE16: =$AZ16+BE$4 -> 45842.667 | BF16: =$AZ16+BF$4 -> 45873.083 | BG16: =$AZ16+BG$4 -> 45903.5 | BH16: =$AZ16+BH$4 -> 45933.917 | BI16: =$AZ16+BI$4 -> 45964.333 | ... CV16: =$AZ16+CV$4 -> 47150.583
