Workbook
Name A: #REF!
Name Data: [1]sheet0!$C$2
Name S: {#N/A,#N/A,FALSE,"CGBR95C"}

Sheet >> CHARTS

Sheet >> DATA

Sheet Chart Data
A1: GDP | G1: GDP | L1: Non-fuel goods exports | Q1: Non-fuel goods exports | V1: Business investment | AC1: Business investment | AH1: Investment | AM1: CPI inflation | AR1: Potential output | AW1: Potential output - April forecast | BH1: Potential output - March forecast
AX2: ESTAR * AVHR | AY2: EDUC / POP15_64 | AZ2: K | BA2: TREND | BB2: YHAT | BC2: GDP | BE2: Potential output | BF2: GDP | BI2: ESTAR * AVHR | BJ2: EDUC / POP15_64 | BK2: K | BL2: TREND | BM2: YHAT | BN2: GDP | BP2: Potential output | BQ2: GDP
B3: April 2025 | C3: March 2025 | D3: January 2025 | H3: April 2025 | I3: March 2025 | M3: April 2025 | N3: March 2025 | R3: April 2025 | S3: March 2025 | W3: April 2025 | X3: March 2025 | Y3: January 2025 | AD3: April 2025 | AE3: March 2025 | AI3: April 2025 | AJ3: March 2025 | AN3: April 2025 | AO3: March 2025 | AP3: 2% target | AS3: April 2025 | AT3: March 2025 | AW3: 1980 | AX3: ='Annual Data'!K14*'Annual Data'!L14 -> 24.76553 | AY3: ='Annual Data'!M14/'Annual Data'!N14 -> 8.4961678 | AZ3: ='Annual Data'!O14 -> 1265800.5 | BA3: ='Annual Data'!P14 -> -7.645228 | BB3: ='Annual Data'!J14 -> 1080987.1 | BC3: ='Annual Data'!B14 -> 1059660 | BH3: 1980 | BI3: ='Annual Data'!Z14*'Annual Data'!AA14 -> 24.76553 | BJ3: ='Annual Data'!AB14/'Annual Data'!AC14 -> 8.4961678 | BK3: ='Annual Data'!AD14 -> 1265800.5 | BL3: ='Annual Data'!AE14 -> -7.645228 | BM3: ='Annual Data'!Y14 -> 1080987.1 | BN3: ='Annual Data'!Q14 -> 1059660
A4: 44927 | B4: ='Quarterly Data'!D207 -> 634428 | C4: ='Quarterly Data'!S207 -> 634807 | D4: ='Quarterly Data'!AH207 -> 634807 | E4: =100*((B4/C4)-1) -> -0.059703185 | G4: 44927 | H4: =100*('Quarterly Data'!D207/'Quarterly Data'!$D$215) -> 98.22544 | I4: =100*('Quarterly Data'!S207/'Quarterly Data'!$S$215) -> 98.723744 | J4: =100*((H4/I4)-1) -> -0.50474555 | L4: 44927 | M4: ='Quarterly Data'!G207 -> 87398 | N4: ='Quarterly Data'!V207 -> 87198 | O4: =100*((M4/N4)-1) -> 0.22936306 | Q4: 44927 | R4: =100*('Quarterly Data'!G207/'Quarterly Data'!$G$215) -> 110.82122 | S4: =100*('Quarterly Data'!V207/'Quarterly Data'!$V$215) -> 114.53659 | T4: =100*((R4/S4)-1) -> -3.2438307 | V4: 44927 | W4: ='Quarterly Data'!K207 -> 62765 | X4: ='Quarterly Data'!Z207 -> 62590 | Y4: ='Quarterly Data'!AO207 -> 62590 | Z4: =100*((W4/X4)-1) -> 0.27959738 | AA4: =100*((W4/Y4)-1) -> 0.27959738 | AC4: 44927 | AD4: =100*('Quarterly Data'!K207/'Quarterly Data'!$K$215) -> 98.297764 | AE4: =100*('Quarterly Data'!Z207/'Quarterly Data'!$Z$215) -> 98.445183 | AF4: =100*((AD4/AE4)-1) -> -0.14974665 | AH4: 44927 | AI4: =100*('Quarterly Data'!J207/'Quarterly Data'!$J$215) -> 99.433535 | AJ4: =100*('Quarterly Data'!Y207/'Quarterly Data'!$Y$215) -> 101.25094 | AK4: =100*((AI4/AJ4)-1) -> -1.7949539 | AM4: 44927 | AN4: =100*(('Quarterly Data'!E207/'Quarterly Data'!E203)-1) -> 10.178266 | AO4: =100*(('Quarterly Data'!T207/'Quarterly Data'!T203)-1) -> 10.178266 | AP4: 2 | AR4: 44927 | AS4: ='Quarterly Data'!L207 -> 628265.6 | AT4: ='Quarterly Data'!AA207 -> 628224.8 | AU4: =100*((AS4/AT4)-1) -> 0.0064944905 | AW4: 1981 | AX4: ='Annual Data'!K15*'Annual Data'!L15 -> 24.65965 | AY4: ='Annual Data'!M15/'Annual Data'!N15 -> 8.5228977 | AZ4: ='Annual Data'!O15 -> 1278218.5 | BA4: ='Annual Data'!P15 -> -7.595809 | BB4: ='Annual Data'!J15 -> 1096885.7 | BC4: ='Annual Data'!B15 -> 1052374 | BE4: =100*((BB4/BB3)-1) -> 1.4707484 | BF4: =100*((BC4/BC3)-1) -> -0.68757903 | BH4: 1981 | BI4: ='Annual Data'!Z15*'Annual Data'!AA15 -> 24.65965 | BJ4: ='Annual Data'!AB15/'Annual Data'!AC15 -> 8.5228977 | BK4: ='Annual Data'!AD15 -> 1278218.5 | BL4: ='Annual Data'!AE15 -> -7.595809 | BM4: ='Annual Data'!Y15 -> 1096885.7 | BN4: ='Annual Data'!Q15 -> 1052374 | BP4: =100*((BM4/BM3)-1) -> 1.4707484 | BQ4: =100*((BN4/BN3)-1) -> -0.68757903
A5: 45017 | B5: ='Quarterly Data'!D208 -> 634694 | C5: ='Quarterly Data'!S208 -> 634866 | D5: ='Quarterly Data'!AH208 -> 634866 | E5: =100*((B5/C5)-1) -> -0.027092331 | G5: 45017 | H5: =100*('Quarterly Data'!D208/'Quarterly Data'!$D$215) -> 98.266624 | I5: =100*('Quarterly Data'!S208/'Quarterly Data'!$S$215) -> 98.732919 | J5: =100*((H5/I5)-1) -> -0.47227992 | L5: 45017 | M5: ='Quarterly Data'!G208 -> 87193 | N5: ='Quarterly Data'!V208 -> 87228 | O5: =100*((M5/N5)-1) -> -0.040124731 | Q5: 45017 | R5: =100*('Quarterly Data'!G208/'Quarterly Data'!$G$215) -> 110.56128 | S5: =100*('Quarterly Data'!V208/'Quarterly Data'!$V$215) -> 114.576 | T5: =100*((R5/S5)-1) -> -3.50398 | V5: 45017 | W5: ='Quarterly Data'!K208 -> 63006 | X5: ='Quarterly Data'!Z208 -> 63199 | Y5: ='Quarterly Data'!AO208 -> 63199 | Z5: =100*((W5/X5)-1) -> -0.30538458 | AA5: =100*((W5/Y5)-1) -> -0.30538458 | AC5: 45017 | AD5: =100*('Quarterly Data'!K208/'Quarterly Data'!$K$215) -> 98.6752 | AE5: =100*('Quarterly Data'!Z208/'Quarterly Data'!$Z$215) -> 99.403053 | AF5: =100*((AD5/AE5)-1) -> -0.73222403 | AH5: 45017 | AI5: =100*('Quarterly Data'!J208/'Quarterly Data'!$J$215) -> 97.968315 | AJ5: =100*('Quarterly Data'!Y208/'Quarterly Data'!$Y$215) -> 100.05864 | AK5: =100*((AI5/AJ5)-1) -> -2.0891047 | AM5: 45017 | AN5: =100*(('Quarterly Data'!E208/'Quarterly Data'!E204)-1) -> 8.439049 | AO5: =100*(('Quarterly Data'!T208/'Quarterly Data'!T204)-1) -> 8.439049 | AP5: 2 | AR5: 45017 | AS5: ='Quarterly Data'!L208 -> 629361.4 | AT5: ='Quarterly Data'!AA208 -> 630809.5 | AU5: =100*((AS5/AT5)-1) -> -0.22956217 | AW5: 1982 | AX5: ='Annual Data'!K16*'Annual Data'!L16 -> 24.297707 | AY5: ='Annual Data'!M16/'Annual Data'!N16 -> 8.5398115 | AZ5: ='Annual Data'!O16 -> 1288706.5 | BA5: ='Annual Data'!P16 -> -7.546708 | BB5: ='Annual Data'!J16 -> 1103412.6 | BC5: ='Annual Data'!B16 -> 1073055 | BE5: =100*((BB5/BB4)-1) -> 0.59503921 | BF5: =100*((BC5/BC4)-1) -> 1.9651759 | BH5: 1982 | BI5: ='Annual Data'!Z16*'Annual Data'!AA16 -> 24.297707 | BJ5: ='Annual Data'!AB16/'Annual Data'!AC16 -> 8.5398115 | BK5: ='Annual Data'!AD16 -> 1288706.5 | BL5: ='Annual Data'!AE16 -> -7.546708 | BM5: ='Annual Data'!Y16 -> 1103412.6 | BN5: ='Annual Data'!Q16 -> 1073055 | BP5: =100*((BM5/BM4)-1) -> 0.59503921 | BQ5: =100*((BN5/BN4)-1) -> 1.9651759
A6: 45108 | B6: ='Quarterly Data'!D209 -> 634327 | C6: ='Quarterly Data'!S209 -> 634052 | D6: ='Quarterly Data'!AH209 -> 634052 | E6: =100*((B6/C6)-1) -> 0.043371837 | G6: 45108 | H6: =100*('Quarterly Data'!D209/'Quarterly Data'!$D$215) -> 98.209803 | I6: =100*('Quarterly Data'!S209/'Quarterly Data'!$S$215) -> 98.606328 | J6: =100*((H6/I6)-1) -> -0.40212953 | L6: 45108 | M6: ='Quarterly Data'!G209 -> 83160 | N6: ='Quarterly Data'!V209 -> 83531 | O6: =100*((M6/N6)-1) -> -0.44414648 | Q6: 45108 | R6: =100*('Quarterly Data'!G209/'Quarterly Data'!$G$215) -> 105.44741 | S6: =100*('Quarterly Data'!V209/'Quarterly Data'!$V$215) -> 109.7199 | T6: =100*((R6/S6)-1) -> -3.8940014 | V6: 45108 | W6: ='Quarterly Data'!K209 -> 61551 | X6: ='Quarterly Data'!Z209 -> 61724 | Y6: ='Quarterly Data'!AO209 -> 61724 | Z6: =100*((W6/X6)-1) -> -0.28027996 | AA6: =100*((W6/Y6)-1) -> -0.28027996 | AC6: 45108 | AD6: =100*('Quarterly Data'!K209/'Quarterly Data'!$K$215) -> 96.39649 | AE6: =100*('Quarterly Data'!Z209/'Quarterly Data'!$Z$215) -> 97.083088 | AF6: =100*((AD6/AE6)-1) -> -0.70722689 | AH6: 45108 | AI6: =100*('Quarterly Data'!J209/'Quarterly Data'!$J$215) -> 96.436534 | AJ6: =100*('Quarterly Data'!Y209/'Quarterly Data'!$Y$215) -> 98.459802 | AK6: =100*((AI6/AJ6)-1) -> -2.0549181 | AM6: 45108 | AN6: =100*(('Quarterly Data'!E209/'Quarterly Data'!E205)-1) -> 6.7136185 | AO6: =100*(('Quarterly Data'!T209/'Quarterly Data'!T205)-1) -> 6.7136185 | AP6: 2 | AR6: 45108 | AS6: ='Quarterly Data'!L209 -> 628663.1 | AT6: ='Quarterly Data'!AA209 -> 628564.2 | AU6: =100*((AS6/AT6)-1) -> 0.015734272 | AW6: 1983 | AX6: ='Annual Data'!K17*'Annual Data'!L17 -> 24.304682 | AY6: ='Annual Data'!M17/'Annual Data'!N17 -> 8.5563187 | AZ6: ='Annual Data'!O17 -> 1301611.5 | BA6: ='Annual Data'!P17 -> -7.497925 | BB6: ='Annual Data'!J17 -> 1121588.5 | BC6: ='Annual Data'!B17 -> 1117759 | BE6: =100*((BB6/BB5)-1) -> 1.6472442 | BF6: =100*((BC6/BC5)-1) -> 4.1660493 | BH6: 1983 | BI6: ='Annual Data'!Z17*'Annual Data'!AA17 -> 24.304682 | BJ6: ='Annual Data'!AB17/'Annual Data'!AC17 -> 8.5563187 | BK6: ='Annual Data'!AD17 -> 1301611.5 | BL6: ='Annual Data'!AE17 -> -7.497925 | BM6: ='Annual Data'!Y17 -> 1121588.5 | BN6: ='Annual Data'!Q17 -> 1117759 | BP6: =100*((BM6/BM5)-1) -> 1.6472442 | BQ6: =100*((BN6/BN5)-1) -> 4.1660493
A7: 45200 | B7: ='Quarterly Data'!D210 -> 633011 | C7: ='Quarterly Data'!S210 -> 632365 | D7: ='Quarterly Data'!AH210 -> 632365 | E7: =100*((B7/C7)-1) -> 0.10215619 | G7: 45200 | H7: =100*('Quarterly Data'!D210/'Quarterly Data'!$D$215) -> 98.006053 | I7: =100*('Quarterly Data'!S210/'Quarterly Data'!$S$215) -> 98.343969 | J7: =100*((H7/I7)-1) -> -0.34360695 | L7: 45200 | M7: ='Quarterly Data'!G210 -> 86003 | N7: ='Quarterly Data'!V210 -> 85834 | O7: =100*((M7/N7)-1) -> 0.19689167 | Q7: 45200 | R7: =100*('Quarterly Data'!G210/'Quarterly Data'!$G$215) -> 109.05235 | S7: =100*('Quarterly Data'!V210/'Quarterly Data'!$V$215) -> 112.74494 | T7: =100*((R7/S7)-1) -> -3.2751768 | V7: 45200 | W7: ='Quarterly Data'!K210 -> 62681 | X7: ='Quarterly Data'!Z210 -> 62795 | Y7: ='Quarterly Data'!AO210 -> 62795 | Z7: =100*((W7/X7)-1) -> -0.18154312 | AA7: =100*((W7/Y7)-1) -> -0.18154312 | AC7: 45200 | AD7: =100*('Quarterly Data'!K210/'Quarterly Data'!$K$215) -> 98.16621 | AE7: =100*('Quarterly Data'!Z210/'Quarterly Data'!$Z$215) -> 98.767619 | AF7: =100*((AD7/AE7)-1) -> -0.60891279 | AH7: 45200 | AI7: =100*('Quarterly Data'!J210/'Quarterly Data'!$J$215) -> 97.33209 | AJ7: =100*('Quarterly Data'!Y210/'Quarterly Data'!$Y$215) -> 99.31875 | AK7: =100*((AI7/AJ7)-1) -> -2.0002873 | AM7: 45200 | AN7: =100*(('Quarterly Data'!E210/'Quarterly Data'!E206)-1) -> 4.1568272 | AO7: =100*(('Quarterly Data'!T210/'Quarterly Data'!T206)-1) -> 4.1568272 | AP7: 2 | AR7: 45200 | AS7: ='Quarterly Data'!L210 -> 631659.5 | AT7: ='Quarterly Data'!AA210 -> 630612.8 | AU7: =100*((AS7/AT7)-1) -> 0.16598141 | AW7: 1984 | AX7: ='Annual Data'!K18*'Annual Data'!L18 -> 24.910802 | AY7: ='Annual Data'!M18/'Annual Data'!N18 -> 8.5981632 | AZ7: ='Annual Data'!O18 -> 1322354.2 | BA7: ='Annual Data'!P18 -> -7.449458 | BB7: ='Annual Data'!J18 -> 1160834.9 | BC7: ='Annual Data'!B18 -> 1142579 | BE7: =100*((BB7/BB6)-1) -> 3.49918 | BF7: =100*((BC7/BC6)-1) -> 2.2205144 | BH7: 1984 | BI7: ='Annual Data'!Z18*'Annual Data'!AA18 -> 24.910802 | BJ7: ='Annual Data'!AB18/'Annual Data'!AC18 -> 8.5981632 | BK7: ='Annual Data'!AD18 -> 1322354.2 | BL7: ='Annual Data'!AE18 -> -7.449458 | BM7: ='Annual Data'!Y18 -> 1160834.9 | BN7: ='Annual Data'!Q18 -> 1142579 | BP7: =100*((BM7/BM6)-1) -> 3.49918 | BQ7: =100*((BN7/BN6)-1) -> 2.2205144
A8: 45292 | B8: ='Quarterly Data'!D211 -> 638746 | C8: ='Quarterly Data'!S211 -> 637729 | D8: ='Quarterly Data'!AH211 -> 637023 | E8: =100*((B8/C8)-1) -> 0.15947213 | G8: 45292 | H8: =100*('Quarterly Data'!D211/'Quarterly Data'!$D$215) -> 98.893975 | I8: =100*('Quarterly Data'!S211/'Quarterly Data'!$S$215) -> 99.178167 | J8: =100*((H8/I8)-1) -> -0.28654625 | L8: 45292 | M8: ='Quarterly Data'!G211 -> 82999 | N8: ='Quarterly Data'!V211 -> 82683 | O8: =100*((M8/N8)-1) -> 0.38218255 | Q8: 45292 | R8: =100*('Quarterly Data'!G211/'Quarterly Data'!$G$215) -> 105.24326 | S8: =100*('Quarterly Data'!V211/'Quarterly Data'!$V$215) -> 108.60603 | T8: =100*((R8/S8)-1) -> -3.0963067 | V8: 45292 | W8: ='Quarterly Data'!K211 -> 62527 | X8: ='Quarterly Data'!Z211 -> 62349 | Y8: ='Quarterly Data'!AO211 -> 62978 | Z8: =100*((W8/X8)-1) -> 0.28548974 | AA8: =100*((W8/Y8)-1) -> -0.71612309 | AC8: 45292 | AD8: =100*('Quarterly Data'!K211/'Quarterly Data'!$K$215) -> 97.925027 | AE8: =100*('Quarterly Data'!Z211/'Quarterly Data'!$Z$215) -> 98.066124 | AF8: =100*((AD8/AE8)-1) -> -0.14387951 | AH8: 45292 | AI8: =100*('Quarterly Data'!J211/'Quarterly Data'!$J$215) -> 98.072912 | AJ8: =100*('Quarterly Data'!Y211/'Quarterly Data'!$Y$215) -> 100.2553 | AK8: =100*((AI8/AJ8)-1) -> -2.1768341 | AM8: 45292 | AN8: =100*(('Quarterly Data'!E211/'Quarterly Data'!E207)-1) -> 3.5491137 | AO8: =100*(('Quarterly Data'!T211/'Quarterly Data'!T207)-1) -> 3.5491137 | AP8: 2 | AR8: 45292 | AS8: ='Quarterly Data'!L211 -> 638150.9 | AT8: ='Quarterly Data'!AA211 -> 638391.4 | AU8: =100*((AS8/AT8)-1) -> -0.037672813 | AW8: 1985 | AX8: ='Annual Data'!K19*'Annual Data'!L19 -> 25.107865 | AY8: ='Annual Data'!M19/'Annual Data'!N19 -> 8.6987735 | AZ8: ='Annual Data'!O19 -> 1348477 | BA8: ='Annual Data'!P19 -> -7.401305 | BB8: ='Annual Data'!J19 -> 1193082.3 | BC8: ='Annual Data'!B19 -> 1189278 | BE8: =100*((BB8/BB7)-1) -> 2.7779489 | BF8: =100*((BC8/BC7)-1) -> 4.0871572 | BH8: 1985 | BI8: ='Annual Data'!Z19*'Annual Data'!AA19 -> 25.107865 | BJ8: ='Annual Data'!AB19/'Annual Data'!AC19 -> 8.6987735 | BK8: ='Annual Data'!AD19 -> 1348477 | BL8: ='Annual Data'!AE19 -> -7.401305 | BM8: ='Annual Data'!Y19 -> 1193082.3 | BN8: ='Annual Data'!Q19 -> 1189278 | BP8: =100*((BM8/BM7)-1) -> 2.7779489 | BQ8: =100*((BN8/BN7)-1) -> 4.0871572
A9: 45383 | B9: ='Quarterly Data'!D212 -> 641670 | C9: ='Quarterly Data'!S212 -> 640592 | D9: ='Quarterly Data'!AH212 -> 639269 | E9: =100*((B9/C9)-1) -> 0.16828184 | G9: 45383 | H9: =100*('Quarterly Data'!D212/'Quarterly Data'!$D$215) -> 99.346684 | I9: =100*('Quarterly Data'!S212/'Quarterly Data'!$S$215) -> 99.623414 | J9: =100*((H9/I9)-1) -> -0.27777577 | L9: 45383 | M9: ='Quarterly Data'!G212 -> 79136 | N9: ='Quarterly Data'!V212 -> 78994 | O9: =100*((M9/N9)-1) -> 0.17976049 | Q9: 45383 | R9: =100*('Quarterly Data'!G212/'Quarterly Data'!$G$215) -> 100.34495 | S9: =100*('Quarterly Data'!V212/'Quarterly Data'!$V$215) -> 103.76045 | T9: =100*((R9/S9)-1) -> -3.2917144 | V9: 45383 | W9: ='Quarterly Data'!K212 -> 63634 | X9: ='Quarterly Data'!Z212 -> 63236 | Y9: ='Quarterly Data'!AO212 -> 64099 | Z9: =100*((W9/X9)-1) -> 0.62938832 | AA9: =100*((W9/Y9)-1) -> -0.72544033 | AC9: 45383 | AD9: =100*('Quarterly Data'!K212/'Quarterly Data'!$K$215) -> 99.658726 | AE9: =100*('Quarterly Data'!Z212/'Quarterly Data'!$Z$215) -> 99.461249 | AF9: =100*((AD9/AE9)-1) -> 0.19854667 | AH9: 45383 | AI9: =100*('Quarterly Data'!J212/'Quarterly Data'!$J$215) -> 99.141355 | AJ9: =100*('Quarterly Data'!Y212/'Quarterly Data'!$Y$215) -> 100.93964 | AK9: =100*((AI9/AJ9)-1) -> -1.7815446 | AM9: 45383 | AN9: =100*(('Quarterly Data'!E212/'Quarterly Data'!E208)-1) -> 2.1108336 | AO9: =100*(('Quarterly Data'!T212/'Quarterly Data'!T208)-1) -> 2.1108336 | AP9: 2 | AR9: 45383 | AS9: ='Quarterly Data'!L212 -> 640407.3 | AT9: ='Quarterly Data'!AA212 -> 640919.3 | AU9: =100*((AS9/AT9)-1) -> -0.079885252 | AW9: 1986 | AX9: ='Annual Data'!K20*'Annual Data'!L20 -> 846672.54 | AY9: ='Annual Data'!M20/'Annual Data'!N20 -> 8.811239 | AZ9: ='Annual Data'!O20 -> 1372084.8 | BA9: ='Annual Data'!P20 -> -7.353953 | BB9: ='Annual Data'!J20 -> 1223572.5 | BC9: ='Annual Data'!B20 -> 1226237 | BE9: =100*((BB9/BB8)-1) -> 2.5555823 | BF9: =100*((BC9/BC8)-1) -> 3.1076838 | BH9: 1986 | BI9: ='Annual Data'!Z20*'Annual Data'!AA20 -> 846672.54 | BJ9: ='Annual Data'!AB20/'Annual Data'!AC20 -> 8.811239 | BK9: ='Annual Data'!AD20 -> 1372084.8 | BL9: ='Annual Data'!AE20 -> -7.353953 | BM9: ='Annual Data'!Y20 -> 1223572.5 | BN9: ='Annual Data'!Q20 -> 1226237 | BP9: =100*((BM9/BM8)-1) -> 2.5555823 | BQ9: =100*((BN9/BN8)-1) -> 3.1076838
A10: 45474 | B10: ='Quarterly Data'!D213 -> 641675 | C10: ='Quarterly Data'!S213 -> 640417 | D10: ='Quarterly Data'!AH213 -> 639452 | E10: =100*((B10/C10)-1) -> 0.19643451 | G10: 45474 | H10: =100*('Quarterly Data'!D213/'Quarterly Data'!$D$215) -> 99.347458 | I10: =100*('Quarterly Data'!S213/'Quarterly Data'!$S$215) -> 99.596198 | J10: =100*((H10/I10)-1) -> -0.24974846 | L10: 45474 | M10: ='Quarterly Data'!G213 -> 79947 | N10: ='Quarterly Data'!V213 -> 79804 | O10: =100*((M10/N10)-1) -> 0.17918901 | Q10: 45474 | R10: =100*('Quarterly Data'!G213/'Quarterly Data'!$G$215) -> 101.3733 | S10: =100*('Quarterly Data'!V213/'Quarterly Data'!$V$215) -> 104.8244 | T10: =100*((R10/S10)-1) -> -3.292266 | V10: 45474 | W10: ='Quarterly Data'!K213 -> 65023 | X10: ='Quarterly Data'!Z213 -> 64412 | Y10: ='Quarterly Data'!AO213 -> 65327 | Z10: =100*((W10/X10)-1) -> 0.94858101 | AA10: =100*((W10/Y10)-1) -> -0.46535123 | AC10: 45474 | AD10: =100*('Quarterly Data'!K213/'Quarterly Data'!$K$215) -> 101.83407 | AE10: =100*('Quarterly Data'!Z213/'Quarterly Data'!$Z$215) -> 101.31093 | AF10: =100*((AD10/AE10)-1) -> 0.51637275 | AH10: 45474 | AI10: =100*('Quarterly Data'!J213/'Quarterly Data'!$J$215) -> 100.12941 | AJ10: =100*('Quarterly Data'!Y213/'Quarterly Data'!$Y$215) -> 101.91941 | AK10: =100*((AI10/AJ10)-1) -> -1.7562888 | AM10: 45474 | AN10: =100*(('Quarterly Data'!E213/'Quarterly Data'!E209)-1) -> 2.0547945 | AO10: =100*(('Quarterly Data'!T213/'Quarterly Data'!T209)-1) -> 2.0547945 | AP10: 2 | AR10: 45474 | AS10: ='Quarterly Data'!L213 -> 646654.9 | AT10: ='Quarterly Data'!AA213 -> 646929.4 | AU10: =100*((AS10/AT10)-1) -> -0.042431214 | AW10: 1987 | AX10: ='Annual Data'!K21*'Annual Data'!L21 -> 854924.76 | AY10: ='Annual Data'!M21/'Annual Data'!N21 -> 8.9162746 | AZ10: ='Annual Data'!O21 -> 1399611 | BA10: ='Annual Data'!P21 -> -7.308859 | BB10: ='Annual Data'!J21 -> 1257734.5 | BC10: ='Annual Data'!B21 -> 1292703 | BE10: =100*((BB10/BB9)-1) -> 2.7919882 | BF10: =100*((BC10/BC9)-1) -> 5.4203225 | BH10: 1987 | BI10: ='Annual Data'!Z21*'Annual Data'!AA21 -> 854924.76 | BJ10: ='Annual Data'!AB21/'Annual Data'!AC21 -> 8.9162746 | BK10: ='Annual Data'!AD21 -> 1399611 | BL10: ='Annual Data'!AE21 -> -7.308859 | BM10: ='Annual Data'!Y21 -> 1257734.5 | BN10: ='Annual Data'!Q21 -> 1292703 | BP10: =100*((BM10/BM9)-1) -> 2.7919882 | BQ10: =100*((BN10/BN9)-1) -> 5.4203225
A11: 45566 | B11: ='Quarterly Data'!D214 -> 642287 | C11: ='Quarterly Data'!S214 -> 641065 | D11: ='Quarterly Data'!AH214 -> 640033.9 | E11: =100*((B11/C11)-1) -> 0.1906203 | G11: 45566 | H11: =100*('Quarterly Data'!D214/'Quarterly Data'!$D$215) -> 99.442211 | I11: =100*('Quarterly Data'!S214/'Quarterly Data'!$S$215) -> 99.696974 | J11: =100*((H11/I11)-1) -> -0.25553678 | L11: 45566 | M11: ='Quarterly Data'!G214 -> 75593 | N11: ='Quarterly Data'!V214 -> 75407 | O11: =100*((M11/N11)-1) -> 0.24666145 | Q11: 45566 | R11: =100*('Quarterly Data'!G214/'Quarterly Data'!$G$215) -> 95.852402 | S11: =100*('Quarterly Data'!V214/'Quarterly Data'!$V$215) -> 99.048838 | T11: =100*((R11/S11)-1) -> -3.2271317 | V11: 45566 | W11: ='Quarterly Data'!K214 -> 63820 | X11: ='Quarterly Data'!Z214 -> 62338 | Y11: ='Quarterly Data'!AO214 -> 64366.69 | Z11: =100*((W11/X11)-1) -> 2.3773621 | AA11: =100*((W11/Y11)-1) -> -0.84933682 | AC11: 45566 | AD11: =100*('Quarterly Data'!K214/'Quarterly Data'!$K$215) -> 99.950025 | AE11: =100*('Quarterly Data'!Z214/'Quarterly Data'!$Z$215) -> 98.048822 | AF11: =100*((AD11/AE11)-1) -> 1.9390366 | AH11: 45566 | AI11: =100*('Quarterly Data'!J214/'Quarterly Data'!$J$215) -> 99.509605 | AJ11: =100*('Quarterly Data'!Y214/'Quarterly Data'!$Y$215) -> 101.00843 | AK11: =100*((AI11/AJ11)-1) -> -1.4838575 | AM11: 45566 | AN11: =100*(('Quarterly Data'!E214/'Quarterly Data'!E210)-1) -> 2.4753214 | AO11: =100*(('Quarterly Data'!T214/'Quarterly Data'!T210)-1) -> 2.4753214 | AP11: 2 | AR11: 45566 | AS11: ='Quarterly Data'!L214 -> 645443.6 | AT11: ='Quarterly Data'!AA214 -> 646080.4 | AU11: =100*((AS11/AT11)-1) -> -0.098563584 | AW11: 1988 | AX11: ='Annual Data'!K22*'Annual Data'!L22 -> 869416.89 | AY11: ='Annual Data'!M22/'Annual Data'!N22 -> 9.0335851 | AZ11: ='Annual Data'!O22 -> 1439126.5 | BA11: ='Annual Data'!P22 -> -7.264205 | BB11: ='Annual Data'!J22 -> 1302509.7 | BC11: ='Annual Data'!B22 -> 1362204 | BE11: =100*((BB11/BB10)-1) -> 3.5599882 | BF11: =100*((BC11/BC10)-1) -> 5.376409 | BH11: 1988 | BI11: ='Annual Data'!Z22*'Annual Data'!AA22 -> 869416.89 | BJ11: ='Annual Data'!AB22/'Annual Data'!AC22 -> 9.0335851 | BK11: ='Annual Data'!AD22 -> 1439126.5 | BL11: ='Annual Data'!AE22 -> -7.264205 | BM11: ='Annual Data'!Y22 -> 1302509.7 | BN11: ='Annual Data'!Q22 -> 1362204 | BP11: =100*((BM11/BM10)-1) -> 3.5599882 | BQ11: =100*((BN11/BN10)-1) -> 5.376409
A12: 45658 | B12: ='Quarterly Data'!D215 -> 645889.7 | C12: ='Quarterly Data'!S215 -> 643013.5 | D12: ='Quarterly Data'!AH215 -> 642502.8 | E12: =100*((B12/C12)-1) -> 0.4473001 | G12: 45658 | H12: =100*('Quarterly Data'!D215/'Quarterly Data'!$D$215) -> 100 | I12: =100*('Quarterly Data'!S215/'Quarterly Data'!$S$215) -> 100 | J12: =100*((H12/I12)-1) -> 0 | L12: 45658 | M12: ='Quarterly Data'!G215 -> 78863.96 | N12: ='Quarterly Data'!V215 -> 76131.13 | O12: =100*((M12/N12)-1) -> 3.5896354 | Q12: 45658 | R12: =100*('Quarterly Data'!G215/'Quarterly Data'!$G$215) -> 100 | S12: =100*('Quarterly Data'!V215/'Quarterly Data'!$V$215) -> 100 | T12: =100*((R12/S12)-1) -> 0 | V12: 45658 | W12: ='Quarterly Data'!K215 -> 63851.91 | X12: ='Quarterly Data'!Z215 -> 63578.53 | Y12: ='Quarterly Data'!AO215 -> 64431.09 | Z12: =100*((W12/X12)-1) -> 0.42998792 | AA12: =100*((W12/Y12)-1) -> -0.89891386 | AC12: 45658 | AD12: =100*('Quarterly Data'!K215/'Quarterly Data'!$K$215) -> 100 | AE12: =100*('Quarterly Data'!Z215/'Quarterly Data'!$Z$215) -> 100 | AF12: =100*((AD12/AE12)-1) -> 0 | AH12: 45658 | AI12: =100*('Quarterly Data'!J215/'Quarterly Data'!$J$215) -> 100 | AJ12: =100*('Quarterly Data'!Y215/'Quarterly Data'!$Y$215) -> 100 | AK12: =100*((AI12/AJ12)-1) -> 0 | AM12: 45658 | AN12: =100*(('Quarterly Data'!E215/'Quarterly Data'!E211)-1) -> 2.7868693 | AO12: =100*(('Quarterly Data'!T215/'Quarterly Data'!T211)-1) -> 2.7942785 | AP12: 2 | AR12: 45658 | AS12: ='Quarterly Data'!L215 -> 649760.7 | AT12: ='Quarterly Data'!AA215 -> 649314.1 | AU12: =100*((AS12/AT12)-1) -> 0.068780271 | AW12: 1989 | AX12: ='Annual Data'!K23*'Annual Data'!L23 -> 881201.46 | AY12: ='Annual Data'!M23/'Annual Data'!N23 -> 9.1558676 | AZ12: ='Annual Data'!O23 -> 1489091 | BA12: ='Annual Data'!P23 -> -7.219823 | BB12: ='Annual Data'!J23 -> 1349436.2 | BC12: ='Annual Data'!B23 -> 1394928 | BE12: =100*((BB12/BB11)-1) -> 3.6027755 | BF12: =100*((BC12/BC11)-1) -> 2.4022834 | BH12: 1989 | BI12: ='Annual Data'!Z23*'Annual Data'!AA23 -> 881201.46 | BJ12: ='Annual Data'!AB23/'Annual Data'!AC23 -> 9.1558676 | BK12: ='Annual Data'!AD23 -> 1489091 | BL12: ='Annual Data'!AE23 -> -7.219823 | BM12: ='Annual Data'!Y23 -> 1349436.2 | BN12: ='Annual Data'!Q23 -> 1394928 | BP12: =100*((BM12/BM11)-1) -> 3.6027755 | BQ12: =100*((BN12/BN11)-1) -> 2.4022834
A13: 45748 | B13: ='Quarterly Data'!D216 -> 647140.2 | C13: ='Quarterly Data'!S216 -> 645036.8 | D13: ='Quarterly Data'!AH216 -> 644937.6 | E13: =100*((B13/C13)-1) -> 0.32608992 | G13: 45748 | H13: =100*('Quarterly Data'!D216/'Quarterly Data'!$D$215) -> 100.19361 | I13: =100*('Quarterly Data'!S216/'Quarterly Data'!$S$215) -> 100.31466 | J13: =100*((H13/I13)-1) -> -0.12067041 | L13: 45748 | M13: ='Quarterly Data'!G216 -> 76532.99 | N13: ='Quarterly Data'!V216 -> 76218.15 | O13: =100*((M13/N13)-1) -> 0.41307746 | Q13: 45748 | R13: =100*('Quarterly Data'!G216/'Quarterly Data'!$G$215) -> 97.044315 | S13: =100*('Quarterly Data'!V216/'Quarterly Data'!$V$215) -> 100.1143 | T13: =100*((R13/S13)-1) -> -3.0664824 | V13: 45748 | W13: ='Quarterly Data'!K216 -> 63839.13 | X13: ='Quarterly Data'!Z216 -> 63756.54 | Y13: ='Quarterly Data'!AO216 -> 64650.15 | Z13: =100*((W13/X13)-1) -> 0.12953965 | AA13: =100*((W13/Y13)-1) -> -1.254475 | AC13: 45748 | AD13: =100*('Quarterly Data'!K216/'Quarterly Data'!$K$215) -> 99.979985 | AE13: =100*('Quarterly Data'!Z216/'Quarterly Data'!$Z$215) -> 100.27998 | AF13: =100*((AD13/AE13)-1) -> -0.29916191 | AH13: 45748 | AI13: =100*('Quarterly Data'!J216/'Quarterly Data'!$J$215) -> 100.07261 | AJ13: =100*('Quarterly Data'!Y216/'Quarterly Data'!$Y$215) -> 100.5913 | AK13: =100*((AI13/AJ13)-1) -> -0.5156369 | AM13: 45748 | AN13: =100*(('Quarterly Data'!E216/'Quarterly Data'!E212)-1) -> 3.0628401 | AO13: =100*(('Quarterly Data'!T216/'Quarterly Data'!T212)-1) -> 3.1688675 | AP13: 2 | AR13: 45748 | AS13: ='Quarterly Data'!L216 -> 651663.3 | AT13: ='Quarterly Data'!AA216 -> 651120.4 | AU13: =100*((AS13/AT13)-1) -> 0.083379357 | AW13: 1990 | AX13: ='Annual Data'!K24*'Annual Data'!L24 -> 879722.64 | AY13: ='Annual Data'!M24/'Annual Data'!N24 -> 9.2673131 | AZ13: ='Annual Data'!O24 -> 1546268.5 | BA13: ='Annual Data'!P24 -> -7.175712 | BB13: ='Annual Data'!J24 -> 1385653.3 | BC13: ='Annual Data'!B24 -> 1402748 | BE13: =100*((BB13/BB12)-1) -> 2.683869 | BF13: =100*((BC13/BC12)-1) -> 0.56060241 | BH13: 1990 | BI13: ='Annual Data'!Z24*'Annual Data'!AA24 -> 879722.64 | BJ13: ='Annual Data'!AB24/'Annual Data'!AC24 -> 9.2673131 | BK13: ='Annual Data'!AD24 -> 1546268.5 | BL13: ='Annual Data'!AE24 -> -7.175712 | BM13: ='Annual Data'!Y24 -> 1385653.3 | BN13: ='Annual Data'!Q24 -> 1402748 | BP13: =100*((BM13/BM12)-1) -> 2.683869 | BQ13: =100*((BN13/BN12)-1) -> 0.56060241
A14: 45839 | B14: ='Quarterly Data'!D217 -> 648105.8 | C14: ='Quarterly Data'!S217 -> 647093.9 | D14: ='Quarterly Data'!AH217 -> 647364.9 | E14: =100*((B14/C14)-1) -> 0.15637607 | G14: 45839 | H14: =100*('Quarterly Data'!D217/'Quarterly Data'!$D$215) -> 100.34311 | I14: =100*('Quarterly Data'!S217/'Quarterly Data'!$S$215) -> 100.63457 | J14: =100*((H14/I14)-1) -> -0.28962852 | L14: 45839 | M14: ='Quarterly Data'!G217 -> 75001.37 | N14: ='Quarterly Data'!V217 -> 76140.98 | O14: =100*((M14/N14)-1) -> -1.4967104 | Q14: 45839 | R14: =100*('Quarterly Data'!G217/'Quarterly Data'!$G$215) -> 95.102211 | S14: =100*('Quarterly Data'!V217/'Quarterly Data'!$V$215) -> 100.01294 | T14: =100*((R14/S14)-1) -> -4.9100915 | V14: 45839 | W14: ='Quarterly Data'!K217 -> 63871.05 | X14: ='Quarterly Data'!Z217 -> 63966.93 | Y14: ='Quarterly Data'!AO217 -> 64934.61 | Z14: =100*((W14/X14)-1) -> -0.14988995 | AA14: =100*((W14/Y14)-1) -> -1.6378939 | AC14: 45839 | AD14: =100*('Quarterly Data'!K217/'Quarterly Data'!$K$215) -> 100.02998 | AE14: =100*('Quarterly Data'!Z217/'Quarterly Data'!$Z$215) -> 100.6109 | AF14: =100*((AD14/AE14)-1) -> -0.57739514 | AH14: 45839 | AI14: =100*('Quarterly Data'!J217/'Quarterly Data'!$J$215) -> 100.25233 | AJ14: =100*('Quarterly Data'!Y217/'Quarterly Data'!$Y$215) -> 101.46541 | AK14: =100*((AI14/AJ14)-1) -> -1.195566 | AM14: 45839 | AN14: =100*(('Quarterly Data'!E217/'Quarterly Data'!E213)-1) -> 3.2803132 | AO14: =100*(('Quarterly Data'!T217/'Quarterly Data'!T213)-1) -> 3.4616704 | AP14: 2 | AR14: 45839 | AS14: ='Quarterly Data'!L217 -> 653590.9 | AT14: ='Quarterly Data'!AA217 -> 653146.6 | AU14: =100*((AS14/AT14)-1) -> 0.068024545 | AW14: 1991 | AX14: ='Annual Data'!K25*'Annual Data'!L25 -> 861885.22 | AY14: ='Annual Data'!M25/'Annual Data'!N25 -> 9.375413 | AZ14: ='Annual Data'!O25 -> 1600385.2 | BA14: ='Annual Data'!P25 -> -7.13187 | BB14: ='Annual Data'!J25 -> 1404835.5 | BC14: ='Annual Data'!B25 -> 1383043 | BE14: =100*((BB14/BB13)-1) -> 1.3843434 | BF14: =100*((BC14/BC13)-1) -> -1.4047427 | BH14: 1991 | BI14: ='Annual Data'!Z25*'Annual Data'!AA25 -> 861885.22 | BJ14: ='Annual Data'!AB25/'Annual Data'!AC25 -> 9.375413 | BK14: ='Annual Data'!AD25 -> 1600385.2 | BL14: ='Annual Data'!AE25 -> -7.13187 | BM14: ='Annual Data'!Y25 -> 1404835.5 | BN14: ='Annual Data'!Q25 -> 1383043 | BP14: =100*((BM14/BM13)-1) -> 1.3843434 | BQ14: =100*((BN14/BN13)-1) -> -1.4047427
A15: 45931 | B15: ='Quarterly Data'!D218 -> 649184.3 | C15: ='Quarterly Data'!S218 -> 649337.3 | D15: ='Quarterly Data'!AH218 -> 649965.9 | E15: =100*((B15/C15)-1) -> -0.023562484 | G15: 45931 | H15: =100*('Quarterly Data'!D218/'Quarterly Data'!$D$215) -> 100.51009 | I15: =100*('Quarterly Data'!S218/'Quarterly Data'!$S$215) -> 100.98346 | J15: =100*((H15/I15)-1) -> -0.46876579 | L15: 45931 | M15: ='Quarterly Data'!G218 -> 73106.27 | N15: ='Quarterly Data'!V218 -> 76067.3 | O15: =100*((M15/N15)-1) -> -3.8926451 | Q15: 45931 | R15: =100*('Quarterly Data'!G218/'Quarterly Data'!$G$215) -> 92.699213 | S15: =100*('Quarterly Data'!V218/'Quarterly Data'!$V$215) -> 99.916158 | T15: =100*((R15/S15)-1) -> -7.2230011 | V15: 45931 | W15: ='Quarterly Data'!K218 -> 63826.35 | X15: ='Quarterly Data'!Z218 -> 64171.65 | Y15: ='Quarterly Data'!AO218 -> 65226.83 | Z15: =100*((W15/X15)-1) -> -0.53808808 | AA15: =100*((W15/Y15)-1) -> -2.1470919 | AC15: 45931 | AD15: =100*('Quarterly Data'!K218/'Quarterly Data'!$K$215) -> 99.95997 | AE15: =100*('Quarterly Data'!Z218/'Quarterly Data'!$Z$215) -> 100.93289 | AF15: =100*((AD15/AE15)-1) -> -0.96393122 | AH15: 45931 | AI15: =100*('Quarterly Data'!J218/'Quarterly Data'!$J$215) -> 100.43913 | AJ15: =100*('Quarterly Data'!Y218/'Quarterly Data'!$Y$215) -> 102.28221 | AK15: =100*((AI15/AJ15)-1) -> -1.8019514 | AM15: 45931 | AN15: =100*(('Quarterly Data'!E218/'Quarterly Data'!E214)-1) -> 2.9612529 | AO15: =100*(('Quarterly Data'!T218/'Quarterly Data'!T214)-1) -> 3.1802078 | AP15: 2 | AR15: 45931 | AS15: ='Quarterly Data'!L218 -> 655545.4 | AT15: ='Quarterly Data'!AA218 -> 655401.6 | AU15: =100*((AS15/AT15)-1) -> 0.021940746 | AW15: 1992 | AX15: ='Annual Data'!K26*'Annual Data'!L26 -> 848974.47 | AY15: ='Annual Data'!M26/'Annual Data'!N26 -> 9.4785341 | AZ15: ='Annual Data'!O26 -> 1638555.8 | BA15: ='Annual Data'!P26 -> -7.088298 | BB15: ='Annual Data'!J26 -> 1424319.6 | BC15: ='Annual Data'!B26 -> 1386437 | BE15: =100*((BB15/BB14)-1) -> 1.3869311 | BF15: =100*((BC15/BC14)-1) -> 0.2454009 | BH15: 1992 | BI15: ='Annual Data'!Z26*'Annual Data'!AA26 -> 848974.47 | BJ15: ='Annual Data'!AB26/'Annual Data'!AC26 -> 9.4785341 | BK15: ='Annual Data'!AD26 -> 1638555.8 | BL15: ='Annual Data'!AE26 -> -7.088298 | BM15: ='Annual Data'!Y26 -> 1424319.6 | BN15: ='Annual Data'!Q26 -> 1386437 | BP15: =100*((BM15/BM14)-1) -> 1.3869311 | BQ15: =100*((BN15/BN14)-1) -> 0.2454009
... A19: 46296 | B19: ='Quarterly Data'!D222 -> 655799.6 | C19: ='Quarterly Data'!S222 -> 659363.1 | D19: ='Quarterly Data'!AH222 -> 661119.8 | E19: =100*((B19/C19)-1) -> -0.54044577 | G19: 46296 | H19: =100*('Quarterly Data'!D222/'Quarterly Data'!$D$215) -> 101.5343 | I19: =100*('Quarterly Data'!S222/'Quarterly Data'!$S$215) -> 102.54265 | J19: =100*((H19/I19)-1) -> -0.98334735 | L19: 46296 | M19: ='Quarterly Data'!G222 -> 72199.7 | N19: ='Quarterly Data'!V222 -> 76212.55 | O19: =100*((M19/N19)-1) -> -5.2653402 | Q19: 46296 | R19: =100*('Quarterly Data'!G222/'Quarterly Data'!$G$215) -> 91.549676 | S19: =100*('Quarterly Data'!V222/'Quarterly Data'!$V$215) -> 100.10695 | T19: =100*((R19/S19)-1) -> -8.5481289 | V19: 46296 | W19: ='Quarterly Data'!K222 -> 63992.46 | X19: ='Quarterly Data'!Z222 -> 65686.47 | Y19: ='Quarterly Data'!AO222 -> 67079.09 | Z19: =100*((W19/X19)-1) -> -2.5789329 | AA19: =100*((W19/Y19)-1) -> -4.6014786 | AC19: 46296 | AD19: =100*('Quarterly Data'!K222/'Quarterly Data'!$K$215) -> 100.22012 | AE19: =100*('Quarterly Data'!Z222/'Quarterly Data'!$Z$215) -> 103.31549 | AF19: =100*((AD19/AE19)-1) -> -2.9960382 | AH19: 46296 | AI19: =100*('Quarterly Data'!J222/'Quarterly Data'!$J$215) -> 101.77486 | AJ19: =100*('Quarterly Data'!Y222/'Quarterly Data'!$Y$215) -> 105.30334 | AK19: =100*((AI19/AJ19)-1) -> -3.3507793 | AM19: 46296 | AN19: =100*(('Quarterly Data'!E222/'Quarterly Data'!E218)-1) -> 2.3620006 | AO19: =100*(('Quarterly Data'!T222/'Quarterly Data'!T218)-1) -> 2.374475 | AP19: 2 | AR19: 46296 | AS19: ='Quarterly Data'!L222 -> 664151.9 | AT19: ='Quarterly Data'!AA222 -> 665473.2 | AU19: =100*((AS19/AT19)-1) -> -0.19855045 | AW19: 1996 | AX19: ='Annual Data'!K30*'Annual Data'!L30 -> 866753.37 | AY19: ='Annual Data'!M30/'Annual Data'!N30 -> 9.720396 | AZ19: ='Annual Data'!O30 -> 1787124 | BA19: ='Annual Data'!P30 -> -6.916649 | BB19: ='Annual Data'!J30 -> 1564487.6 | BC19: ='Annual Data'!B30 -> 1539846 | BE19: =100*((BB19/BB18)-1) -> 2.6900477 | BF19: =100*((BC19/BC18)-1) -> 2.5819939 | BH19: 1996 | BI19: ='Annual Data'!Z30*'Annual Data'!AA30 -> 866753.37 | BJ19: ='Annual Data'!AB30/'Annual Data'!AC30 -> 9.720396 | BK19: ='Annual Data'!AD30 -> 1787124 | BL19: ='Annual Data'!AE30 -> -6.916649 | BM19: ='Annual Data'!Y30 -> 1564487.6 | BN19: ='Annual Data'!Q30 -> 1539846 | BP19: =100*((BM19/BM18)-1) -> 2.6900477 | BQ19: =100*((BN19/BN18)-1) -> 2.5819939
AR20: 46388 | AS20: ='Quarterly Data'!L223 -> 666314.6 | AT20: ='Quarterly Data'!AA223 -> 667995 | AU20: =100*((AS20/AT20)-1) -> -0.25155877 | AW20: 1997 | AX20: ='Annual Data'!K31*'Annual Data'!L31 -> 877828.58 | AY20: ='Annual Data'!M31/'Annual Data'!N31 -> 9.7395739 | AZ20: ='Annual Data'!O31 -> 1838121.5 | BA20: ='Annual Data'!P31 -> -6.87919 | BB20: ='Annual Data'!J31 -> 1608111.9 | BC20: ='Annual Data'!B31 -> 1615678 | BE20: =100*((BB20/BB19)-1) -> 2.7884082 | BF20: =100*((BC20/BC19)-1) -> 4.9246483 | BH20: 1997 | BI20: ='Annual Data'!Z31*'Annual Data'!AA31 -> 877828.58 | BJ20: ='Annual Data'!AB31/'Annual Data'!AC31 -> 9.7395739 | BK20: ='Annual Data'!AD31 -> 1838121.5 | BL20: ='Annual Data'!AE31 -> -6.87919 | BM20: ='Annual Data'!Y31 -> 1608111.9 | BN20: ='Annual Data'!Q31 -> 1615678 | BP20: =100*((BM20/BM19)-1) -> 2.7884082 | BQ20: =100*((BN20/BN19)-1) -> 4.9246483
AR21: 46478 | AS21: ='Quarterly Data'!L224 -> 668574.9 | AT21: ='Quarterly Data'!AA224 -> 670454.7 | AU21: =100*((AS21/AT21)-1) -> -0.28037688 | AW21: 1998 | AX21: ='Annual Data'!K32*'Annual Data'!L32 -> 884900.37 | AY21: ='Annual Data'!M32/'Annual Data'!N32 -> 9.7651542 | AZ21: ='Annual Data'!O32 -> 1907750 | BA21: ='Annual Data'!P32 -> -6.861095 | BB21: ='Annual Data'!J32 -> 1644834.7 | BC21: ='Annual Data'!B32 -> 1670654 | BE21: =100*((BB21/BB20)-1) -> 2.2835973 | BF21: =100*((BC21/BC20)-1) -> 3.4026582 | BH21: 1998 | BI21: ='Annual Data'!Z32*'Annual Data'!AA32 -> 884900.37 | BJ21: ='Annual Data'!AB32/'Annual Data'!AC32 -> 9.7651542 | BK21: ='Annual Data'!AD32 -> 1907750 | BL21: ='Annual Data'!AE32 -> -6.861095 | BM21: ='Annual Data'!Y32 -> 1644834.7 | BN21: ='Annual Data'!Q32 -> 1670654 | BP21: =100*((BM21/BM20)-1) -> 2.2835973 | BQ21: =100*((BN21/BN20)-1) -> 3.4026582
AR22: 46569 | AS22: ='Quarterly Data'!L225 -> 670903.7 | AT22: ='Quarterly Data'!AA225 -> 672935 | AU22: =100*((AS22/AT22)-1) -> -0.30185679 | AW22: 1999 | AX22: ='Annual Data'!K33*'Annual Data'!L33 -> 895986.1 | AY22: ='Annual Data'!M33/'Annual Data'!N33 -> 9.8328067 | AZ22: ='Annual Data'!O33 -> 1982625 | BA22: ='Annual Data'!P33 -> -6.844647 | BB22: ='Annual Data'!J33 -> 1691774 | BC22: ='Annual Data'!B33 -> 1721748 | BE22: =100*((BB22/BB21)-1) -> 2.8537396 | BF22: =100*((BC22/BC21)-1) -> 3.0583233 | BH22: 1999 | BI22: ='Annual Data'!Z33*'Annual Data'!AA33 -> 895986.1 | BJ22: ='Annual Data'!AB33/'Annual Data'!AC33 -> 9.8328067 | BK22: ='Annual Data'!AD33 -> 1982625 | BL22: ='Annual Data'!AE33 -> -6.844647 | BM22: ='Annual Data'!Y33 -> 1691774 | BN22: ='Annual Data'!Q33 -> 1721748 | BP22: =100*((BM22/BM21)-1) -> 2.8537396 | BQ22: =100*((BN22/BN21)-1) -> 3.0583233
AR23: 46661 | AS23: ='Quarterly Data'!L226 -> 673270.1 | AT23: ='Quarterly Data'!AA226 -> 675409.1 | AU23: =100*((AS23/AT23)-1) -> -0.31669695 | AW23: 2000 | AX23: ='Annual Data'!K34*'Annual Data'!L34 -> 897004.57 | AY23: ='Annual Data'!M34/'Annual Data'!N34 -> 9.9743923 | AZ23: ='Annual Data'!O34 -> 2062500 | BA23: ='Annual Data'!P34 -> -6.828236 | BB23: ='Annual Data'!J34 -> 1730478.3 | BC23: ='Annual Data'!B34 -> 1796500 | BE23: =100*((BB23/BB22)-1) -> 2.2877938 | BF23: =100*((BC23/BC22)-1) -> 4.3416342 | BH23: 2000 | BI23: ='Annual Data'!Z34*'Annual Data'!AA34 -> 897004.57 | BJ23: ='Annual Data'!AB34/'Annual Data'!AC34 -> 9.9743923 | BK23: ='Annual Data'!AD34 -> 2062500 | BL23: ='Annual Data'!AE34 -> -6.828236 | BM23: ='Annual Data'!Y34 -> 1730478.3 | BN23: ='Annual Data'!Q34 -> 1796500 | BP23: =100*((BM23/BM22)-1) -> 2.2877938 | BQ23: =100*((BN23/BN22)-1) -> 4.3416342
AR24: 46753 | AS24: ='Quarterly Data'!L227 -> 675708.6 | AT24: ='Quarterly Data'!AA227 -> 677887.6 | AU24: =100*((AS24/AT24)-1) -> -0.32143972 | AW24: 2001 | AX24: ='Annual Data'!K35*'Annual Data'!L35 -> 906197.83 | AY24: ='Annual Data'!M35/'Annual Data'!N35 -> 10.222142 | AZ24: ='Annual Data'!O35 -> 2140250 | BA24: ='Annual Data'!P35 -> -6.811865 | BB24: ='Annual Data'!J35 -> 1785942.4 | BC24: ='Annual Data'!B35 -> 1842720 | BE24: =100*((BB24/BB23)-1) -> 3.2051312 | BF24: =100*((BC24/BC23)-1) -> 2.5727804 | BH24: 2001 | BI24: ='Annual Data'!Z35*'Annual Data'!AA35 -> 906197.83 | BJ24: ='Annual Data'!AB35/'Annual Data'!AC35 -> 10.222142 | BK24: ='Annual Data'!AD35 -> 2140250 | BL24: ='Annual Data'!AE35 -> -6.811865 | BM24: ='Annual Data'!Y35 -> 1785942.4 | BN24: ='Annual Data'!Q35 -> 1842720 | BP24: =100*((BM24/BM23)-1) -> 3.2051312 | BQ24: =100*((BN24/BN23)-1) -> 2.5727804
AR25: 46844 | AS25: ='Quarterly Data'!L228 -> 678119.8 | AT25: ='Quarterly Data'!AA228 -> 680403.3 | AU25: =100*((AS25/AT25)-1) -> -0.33560978 | AW25: 2002 | AX25: ='Annual Data'!K36*'Annual Data'!L36 -> 905078.99 | AY25: ='Annual Data'!M36/'Annual Data'!N36 -> 10.55383 | AZ25: ='Annual Data'!O36 -> 2206750 | BA25: ='Annual Data'!P36 -> -6.795533 | BB25: ='Annual Data'!J36 -> 1829581.9 | BC25: ='Annual Data'!B36 -> 1875809 | BE25: =100*((BB25/BB24)-1) -> 2.4434999 | BF25: =100*((BC25/BC24)-1) -> 1.7956608 | BH25: 2002 | BI25: ='Annual Data'!Z36*'Annual Data'!AA36 -> 905078.99 | BJ25: ='Annual Data'!AB36/'Annual Data'!AC36 -> 10.55383 | BK25: ='Annual Data'!AD36 -> 2206750 | BL25: ='Annual Data'!AE36 -> -6.795533 | BM25: ='Annual Data'!Y36 -> 1829581.9 | BN25: ='Annual Data'!Q36 -> 1875809 | BP25: =100*((BM25/BM24)-1) -> 2.4434999 | BQ25: =100*((BN25/BN24)-1) -> 1.7956608
AR26: 46935 | AS26: ='Quarterly Data'!L229 -> 680510.3 | AT26: ='Quarterly Data'!AA229 -> 682909.3 | AU26: =100*((AS26/AT26)-1) -> -0.35129116 | AW26: 2003 | AX26: ='Annual Data'!K37*'Annual Data'!L37 -> 907432.95 | AY26: ='Annual Data'!M37/'Annual Data'!N37 -> 10.921333 | AZ26: ='Annual Data'!O37 -> 2263125 | BA26: ='Annual Data'!P37 -> -6.77924 | BB26: ='Annual Data'!J37 -> 1876404.4 | BC26: ='Annual Data'!B37 -> 1934941 | BE26: =100*((BB26/BB25)-1) -> 2.5591913 | BF26: =100*((BC26/BC25)-1) -> 3.1523465 | BH26: 2003 | BI26: ='Annual Data'!Z37*'Annual Data'!AA37 -> 907432.95 | BJ26: ='Annual Data'!AB37/'Annual Data'!AC37 -> 10.921333 | BK26: ='Annual Data'!AD37 -> 2263125 | BL26: ='Annual Data'!AE37 -> -6.77924 | BM26: ='Annual Data'!Y37 -> 1876404.4 | BN26: ='Annual Data'!Q37 -> 1934941 | BP26: =100*((BM26/BM25)-1) -> 2.5591913 | BQ26: =100*((BN26/BN25)-1) -> 3.1523465
AR27: 47027 | AS27: ='Quarterly Data'!L230 -> 682872.2 | AT27: ='Quarterly Data'!AA230 -> 685382.8 | AU27: =100*((AS27/AT27)-1) -> -0.36630625 | AW27: 2004 | AX27: ='Annual Data'!K38*'Annual Data'!L38 -> 912728.2 | AY27: ='Annual Data'!M38/'Annual Data'!N38 -> 11.276552 | AZ27: ='Annual Data'!O38 -> 2318000 | BA27: ='Annual Data'!P38 -> -6.762987 | BB27: ='Annual Data'!J38 -> 1925416.5 | BC27: ='Annual Data'!B38 -> 1982500 | BE27: =100*((BB27/BB26)-1) -> 2.6120222 | BF27: =100*((BC27/BC26)-1) -> 2.4579044 | BH27: 2004 | BI27: ='Annual Data'!Z38*'Annual Data'!AA38 -> 912728.2 | BJ27: ='Annual Data'!AB38/'Annual Data'!AC38 -> 11.276552 | BK27: ='Annual Data'!AD38 -> 2318000 | BL27: ='Annual Data'!AE38 -> -6.762987 | BM27: ='Annual Data'!Y38 -> 1925416.5 | BN27: ='Annual Data'!Q38 -> 1982500 | BP27: =100*((BM27/BM26)-1) -> 2.6120222 | BQ27: =100*((BN27/BN26)-1) -> 2.4579044
AR28: 47119 | AS28: ='Quarterly Data'!L231 -> 685260.5 | AT28: ='Quarterly Data'!AA231 -> 687829.1 | AU28: =100*((AS28/AT28)-1) -> -0.37343579 | AW28: 2005 | AX28: ='Annual Data'!K39*'Annual Data'!L39 -> 926585.3 | AY28: ='Annual Data'!M39/'Annual Data'!N39 -> 11.571259 | AZ28: ='Annual Data'!O39 -> 2377750 | BA28: ='Annual Data'!P39 -> -6.746771 | BB28: ='Annual Data'!J39 -> 1984701.9 | BC28: ='Annual Data'!B39 -> 2036675 | BE28: =100*((BB28/BB27)-1) -> 3.0790948 | BF28: =100*((BC28/BC27)-1) -> 2.7326608 | BH28: 2005 | BI28: ='Annual Data'!Z39*'Annual Data'!AA39 -> 926585.3 | BJ28: ='Annual Data'!AB39/'Annual Data'!AC39 -> 11.571259 | BK28: ='Annual Data'!AD39 -> 2377750 | BL28: ='Annual Data'!AE39 -> -6.746771 | BM28: ='Annual Data'!Y39 -> 1984701.9 | BN28: ='Annual Data'!Q39 -> 2036675 | BP28: =100*((BM28/BM27)-1) -> 3.0790948 | BQ28: =100*((BN28/BN27)-1) -> 2.7326608
AR29: 47209 | AS29: ='Quarterly Data'!L232 -> 687617.9 | AT29: ='Quarterly Data'!AA232 -> 690238.7 | AU29: =100*((AS29/AT29)-1) -> -0.37969473 | AW29: 2006 | AX29: ='Annual Data'!K40*'Annual Data'!L40 -> 938041.8 | AY29: ='Annual Data'!M40/'Annual Data'!N40 -> 11.80839 | AZ29: ='Annual Data'!O40 -> 2443500 | BA29: ='Annual Data'!P40 -> -6.730595 | BB29: ='Annual Data'!J40 -> 2040054.2 | BC29: ='Annual Data'!B40 -> 2085162 | BE29: =100*((BB29/BB28)-1) -> 2.7889478 | BF29: =100*((BC29/BC28)-1) -> 2.380694 | BH29: 2006 | BI29: ='Annual Data'!Z40*'Annual Data'!AA40 -> 938041.8 | BJ29: ='Annual Data'!AB40/'Annual Data'!AC40 -> 11.80839 | BK29: ='Annual Data'!AD40 -> 2443500 | BL29: ='Annual Data'!AE40 -> -6.730595 | BM29: ='Annual Data'!Y40 -> 2040054.2 | BN29: ='Annual Data'!Q40 -> 2085162 | BP29: =100*((BM29/BM28)-1) -> 2.7889478 | BQ29: =100*((BN29/BN28)-1) -> 2.380694
AR30: 47300 | AS30: ='Quarterly Data'!L233 -> 690014.9 | AT30: ='Quarterly Data'!AA233 -> 692664.1 | AU30: =100*((AS30/AT30)-1) -> -0.38246532 | AW30: 2007 | AX30: ='Annual Data'!K41*'Annual Data'!L41 -> 945614.3 | AY30: ='Annual Data'!M41/'Annual Data'!N41 -> 12.020052 | AZ30: ='Annual Data'!O41 -> 2521500 | BA30: ='Annual Data'!P41 -> -6.722856 | BB30: ='Annual Data'!J41 -> 2087491.9 | BC30: ='Annual Data'!B41 -> 2139895 | BE30: =100*((BB30/BB29)-1) -> 2.3253157 | BF30: =100*((BC30/BC29)-1) -> 2.62488 | BH30: 2007 | BI30: ='Annual Data'!Z41*'Annual Data'!AA41 -> 945614.3 | BJ30: ='Annual Data'!AB41/'Annual Data'!AC41 -> 12.020052 | BK30: ='Annual Data'!AD41 -> 2521500 | BL30: ='Annual Data'!AE41 -> -6.722856 | BM30: ='Annual Data'!Y41 -> 2087491.9 | BN30: ='Annual Data'!Q41 -> 2139895 | BP30: =100*((BM30/BM29)-1) -> 2.3253157 | BQ30: =100*((BN30/BN29)-1) -> 2.62488
AR31: 47392 | AS31: ='Quarterly Data'!L234 -> 692387.9 | AT31: ='Quarterly Data'!AA234 -> 695095.9 | AU31: =100*((AS31/AT31)-1) -> -0.38958653 | AW31: 2008 | AX31: ='Annual Data'!K42*'Annual Data'!L42 -> 954262.3 | AY31: ='Annual Data'!M42/'Annual Data'!N42 -> 12.201912 | AZ31: ='Annual Data'!O42 -> 2595500 | BA31: ='Annual Data'!P42 -> -6.72336 | BB31: ='Annual Data'!J42 -> 2131891.2 | BC31: ='Annual Data'!B42 -> 2134571 | BE31: =100*((BB31/BB30)-1) -> 2.1269208 | BF31: =100*((BC31/BC30)-1) -> -0.24879725 | BH31: 2008 | BI31: ='Annual Data'!Z42*'Annual Data'!AA42 -> 954262.3 | BJ31: ='Annual Data'!AB42/'Annual Data'!AC42 -> 12.201912 | BK31: ='Annual Data'!AD42 -> 2595500 | BL31: ='Annual Data'!AE42 -> -6.72336 | BM31: ='Annual Data'!Y42 -> 2131891.2 | BN31: ='Annual Data'!Q42 -> 2134571 | BP31: =100*((BM31/BM30)-1) -> 2.1269208 | BQ31: =100*((BN31/BN30)-1) -> -0.24879725
... AR51: 49218 | AS51: ='Quarterly Data'!L254 -> 745421.2 | AT51: ='Quarterly Data'!AA254 -> 750348.9 | AU51: =100*((AS51/AT51)-1) -> -0.65672116 | AW51: 2028 | AX51: ='Annual Data'!K62*'Annual Data'!L62 -> 1125837.6 | AY51: ='Annual Data'!M62/'Annual Data'!N62 -> 14.148503 | AZ51: ='Annual Data'!O62 -> 3506825.5 | BA51: ='Annual Data'!P62 -> -6.786471 | BB51: ='Annual Data'!J62 -> 2717210.9 | BC51: ='Annual Data'!B62 -> 2696080.6 | BE51: =100*((BB51/BB50)-1) -> 1.4239156 | BF51: =100*((BC51/BC50)-1) -> 1.839685 | BH51: 2028 | BI51: ='Annual Data'!Z62*'Annual Data'!AA62 -> 1124608.3 | BJ51: ='Annual Data'!AB62/'Annual Data'!AC62 -> 14.148503 | BK51: ='Annual Data'!AD62 -> 3518260.2 | BL51: ='Annual Data'!AE62 -> -6.773676 | BM51: ='Annual Data'!Y62 -> 2726583 | BN51: ='Annual Data'!Q62 -> 2714647.4 | BP51: =100*((BM51/BM50)-1) -> 1.4809175 | BQ51: =100*((BN51/BN50)-1) -> 1.8343594
AW52: 2029 | AX52: ='Annual Data'!K63*'Annual Data'!L63 -> 1136256.8 | AY52: ='Annual Data'!M63/'Annual Data'!N63 -> 14.226979 | AZ52: ='Annual Data'!O63 -> 3554214.8 | BA52: ='Annual Data'!P63 -> -6.780026 | BB52: ='Annual Data'!J63 -> 2755281.2 | BC52: ='Annual Data'!B63 -> 2743598.4 | BE52: =100*((BB52/BB51)-1) -> 1.4010801 | BF52: =100*((BC52/BC51)-1) -> 1.762477 | BH52: 2029 | BI52: ='Annual Data'!Z63*'Annual Data'!AA63 -> 1134648.4 | BJ52: ='Annual Data'!AB63/'Annual Data'!AC63 -> 14.226979 | BK52: ='Annual Data'!AD63 -> 3572777.8 | BL52: ='Annual Data'!AE63 -> -6.767708 | BM52: ='Annual Data'!Y63 -> 2765827.8 | BN52: ='Annual Data'!Q63 -> 2760086 | BP52: =100*((BM52/BM51)-1) -> 1.43934 | BQ52: =100*((BN52/BN51)-1) -> 1.6738306
AW53: 2030 | AX53: ='Annual Data'!K64*'Annual Data'!L64 -> 1145515.5 | AY53: ='Annual Data'!M64/'Annual Data'!N64 -> 14.302916 | AZ53: ='Annual Data'!O64 -> 3603829.8 | BA53: ='Annual Data'!P64 -> -6.770878 | BB53: ='Annual Data'!J64 -> 2794047.7 | BC53: ='Annual Data'!B64 -> 2787932 | BE53: =100*((BB53/BB52)-1) -> 1.4069889 | BF53: =100*((BC53/BC52)-1) -> 1.6158925 | BH53: 2030 | BI53: ='Annual Data'!Z64*'Annual Data'!AA64 -> 1144251.4 | BJ53: ='Annual Data'!AB64/'Annual Data'!AC64 -> 14.302916 | BK53: ='Annual Data'!AD64 -> 3628879 | BL53: ='Annual Data'!AE64 -> -6.759888 | BM53: ='Annual Data'!Y64 -> 2806111 | BN53: ='Annual Data'!Q64 -> 2804164.9 | BP53: =100*((BM53/BM52)-1) -> 1.4564609 | BQ53: =100*((BN53/BN52)-1) -> 1.5970118
AW54: 2031 | AX54: ='Annual Data'!K65*'Annual Data'!L65 -> 1154388.8 | AY54: ='Annual Data'!M65/'Annual Data'!N65 -> 14.375743 | AZ54: ='Annual Data'!O65 -> 3656608.5 | BA54: ='Annual Data'!P65 -> -6.759206 | BB54: ='Annual Data'!J65 -> 2834792.3 | BC54: ='Annual Data'!B65 -> 2832594.8 | BE54: =100*((BB54/BB53)-1) -> 1.4582643 | BF54: =100*((BC54/BC53)-1) -> 1.6020046 | BH54: 2031 | BI54: ='Annual Data'!Z65*'Annual Data'!AA65 -> 1153862.9 | BJ54: ='Annual Data'!AB65/'Annual Data'!AC65 -> 14.375743 | BK54: ='Annual Data'!AD65 -> 3687931.5 | BL54: ='Annual Data'!AE65 -> -6.749416 | BM54: ='Annual Data'!Y65 -> 2849000.3 | BN54: ='Annual Data'!Q65 -> 2848839.6 | BP54: =100*((BM54/BM53)-1) -> 1.5284249 | BQ54: =100*((BN54/BN53)-1) -> 1.5931552
AW55: 2032 | AX55: ='Annual Data'!K66*'Annual Data'!L66 -> 1162996.9 | AY55: ='Annual Data'!M66/'Annual Data'!N66 -> 14.444172 | AZ55: ='Annual Data'!O66 -> 3713127.5 | BA55: ='Annual Data'!P66 -> -6.745538 | BB55: ='Annual Data'!J66 -> 2877552.9 | BC55: ='Annual Data'!B66 -> 2877149.6 | BE55: =100*((BB55/BB54)-1) -> 1.5084209 | BF55: =100*((BC55/BC54)-1) -> 1.5729324 | BH55: 2032 | BI55: ='Annual Data'!Z66*'Annual Data'!AA66 -> 1163032.8 | BJ55: ='Annual Data'!AB66/'Annual Data'!AC66 -> 14.444172 | BK55: ='Annual Data'!AD66 -> 3750560.8 | BL55: ='Annual Data'!AE66 -> -6.736639 | BM55: ='Annual Data'!Y66 -> 2893790.1 | BN55: ='Annual Data'!Q66 -> 2893722.4 | BP55: =100*((BM55/BM54)-1) -> 1.5721234 | BQ55: =100*((BN55/BN54)-1) -> 1.5754766
AW56: 2033 | AX56: ='Annual Data'!K67*'Annual Data'!L67 -> 1171104 | AY56: ='Annual Data'!M67/'Annual Data'!N67 -> 14.507863 | AZ56: ='Annual Data'!O67 -> 3773137.5 | BA56: ='Annual Data'!P67 -> -6.729813 | BB56: ='Annual Data'!J67 -> 2921984.8 | BC56: ='Annual Data'!B67 -> 2921985.5 | BE56: =100*((BB56/BB55)-1) -> 1.5440863 | BF56: =100*((BC56/BC55)-1) -> 1.5583444 | BH56: 2033 | BI56: ='Annual Data'!Z67*'Annual Data'!AA67 -> 1171186.6 | BJ56: ='Annual Data'!AB67/'Annual Data'!AC67 -> 14.507863 | BK56: ='Annual Data'!AD67 -> 3816466.8 | BL56: ='Annual Data'!AE67 -> -6.721356 | BM56: ='Annual Data'!Y67 -> 2939683.8 | BN56: ='Annual Data'!Q67 -> 2939685.7 | BP56: =100*((BM56/BM55)-1) -> 1.5859374 | BQ56: =100*((BN56/BN55)-1) -> 1.5883797
AW57: 2034 | AX57: ='Annual Data'!K68*'Annual Data'!L68 -> 1177582.8 | AY57: ='Annual Data'!M68/'Annual Data'!N68 -> 14.566618 | AZ57: ='Annual Data'!O68 -> 3836108.2 | BA57: ='Annual Data'!P68 -> -6.712835 | BB57: ='Annual Data'!J68 -> 2965535.8 | BC57: ='Annual Data'!B68 -> 2965535.9 | BE57: =100*((BB57/BB56)-1) -> 1.4904595 | BF57: =100*((BC57/BC56)-1) -> 1.4904386 | BH57: 2034 | BI57: ='Annual Data'!Z68*'Annual Data'!AA68 -> 1177591.6 | BJ57: ='Annual Data'!AB68/'Annual Data'!AC68 -> 14.566618 | BK57: ='Annual Data'!AD68 -> 3884986 | BL57: ='Annual Data'!AE68 -> -6.704401 | BM57: ='Annual Data'!Y68 -> 2984695.2 | BN57: ='Annual Data'!Q68 -> 2984697.2 | BP57: =100*((BM57/BM56)-1) -> 1.5311647 | BQ57: =100*((BN57/BN56)-1) -> 1.5311671
AW58: 2035 | AX58: ='Annual Data'!K69*'Annual Data'!L69 -> 1183325.2 | AY58: ='Annual Data'!M69/'Annual Data'!N69 -> 14.6204 | AZ58: ='Annual Data'!O69 -> 3901801.5 | BA58: ='Annual Data'!P69 -> -6.694562 | BB58: ='Annual Data'!J69 -> 3009580.5 | BC58: ='Annual Data'!B69 -> 3009581 | BE58: =100*((BB58/BB57)-1) -> 1.485219 | BF58: =100*((BC58/BC57)-1) -> 1.4852324 | BH58: 2035 | BI58: ='Annual Data'!Z69*'Annual Data'!AA69 -> 1183325.2 | BJ58: ='Annual Data'!AB69/'Annual Data'!AC69 -> 14.6204 | BK58: ='Annual Data'!AD69 -> 3955891.2 | BL58: ='Annual Data'!AE69 -> -6.68615 | BM58: ='Annual Data'!Y69 -> 3030201.1 | BN58: ='Annual Data'!Q69 -> 3030203.2 | BP58: =100*((BM58/BM57)-1) -> 1.5246414 | BQ58: =100*((BN58/BN57)-1) -> 1.5246438
AW59: 2036 | AX59: ='Annual Data'!K70*'Annual Data'!L70 -> 1189094.3 | AY59: ='Annual Data'!M70/'Annual Data'!N70 -> 14.66993 | AZ59: ='Annual Data'!O70 -> 3970259.5 | BA59: ='Annual Data'!P70 -> -6.675002 | BB59: ='Annual Data'!J70 -> 3055423.2 | BC59: ='Annual Data'!B70 -> 3055424.1 | BE59: =100*((BB59/BB58)-1) -> 1.5232256 | BF59: =100*((BC59/BC58)-1) -> 1.5232386 | BH59: 2036 | BI59: ='Annual Data'!Z70*'Annual Data'!AA70 -> 1189094.3 | BJ59: ='Annual Data'!AB70/'Annual Data'!AC70 -> 14.66993 | BK59: ='Annual Data'!AD70 -> 4029250 | BL59: ='Annual Data'!AE70 -> -6.666616 | BM59: ='Annual Data'!Y70 -> 3077430.1 | BN59: ='Annual Data'!Q70 -> 3077431 | BP59: =100*((BM59/BM58)-1) -> 1.5586094 | BQ59: =100*((BN59/BN58)-1) -> 1.5585687
AW60: 2037 | AX60: ='Annual Data'!K71*'Annual Data'!L71 -> 1194862.7 | AY60: ='Annual Data'!M71/'Annual Data'!N71 -> 14.716929 | AZ60: ='Annual Data'!O71 -> 4041537 | BA60: ='Annual Data'!P71 -> -6.655 | BB60: ='Annual Data'!J71 -> 3102526.6 | BC60: ='Annual Data'!B71 -> 3102529.7 | BE60: =100*((BB60/BB59)-1) -> 1.5416326 | BF60: =100*((BC60/BC59)-1) -> 1.5417041 | BH60: 2037 | BI60: ='Annual Data'!Z71*'Annual Data'!AA71 -> 1194862.7 | BJ60: ='Annual Data'!AB71/'Annual Data'!AC71 -> 14.716929 | BK60: ='Annual Data'!AD71 -> 4105132.5 | BL60: ='Annual Data'!AE71 -> -6.646638 | BM60: ='Annual Data'!Y71 -> 3125831 | BN60: ='Annual Data'!Q71 -> 3125832.8 | BP60: =100*((BM60/BM59)-1) -> 1.5727701 | BQ60: =100*((BN60/BN59)-1) -> 1.5727989
AW61: 2038 | AX61: ='Annual Data'!K72*'Annual Data'!L72 -> 1200630.3 | AY61: ='Annual Data'!M72/'Annual Data'!N72 -> 14.761935 | AZ61: ='Annual Data'!O72 -> 4115651 | BA61: ='Annual Data'!P72 -> -6.634227 | BB61: ='Annual Data'!J72 -> 3151203.9 | BC61: ='Annual Data'!B72 -> 3151203.3 | BE61: =100*((BB61/BB60)-1) -> 1.5689567 | BF61: =100*((BC61/BC60)-1) -> 1.5688359 | BH61: 2038 | BI61: ='Annual Data'!Z72*'Annual Data'!AA72 -> 1200630.3 | BJ61: ='Annual Data'!AB72/'Annual Data'!AC72 -> 14.761935 | BK61: ='Annual Data'!AD72 -> 4183569.5 | BL61: ='Annual Data'!AE72 -> -6.625892 | BM61: ='Annual Data'!Y72 -> 3175720.1 | BN61: ='Annual Data'!Q72 -> 3175719.7 | BP61: =100*((BM61/BM60)-1) -> 1.5960268 | BQ61: =100*((BN61/BN60)-1) -> 1.5959555
AW62: 2039 | AX62: ='Annual Data'!K73*'Annual Data'!L73 -> 1206396.9 | AY62: ='Annual Data'!M73/'Annual Data'!N73 -> 14.805608 | AZ62: ='Annual Data'!O73 -> 4192666.2 | BA62: ='Annual Data'!P73 -> -6.613024 | BB62: ='Annual Data'!J73 -> 3201256.6 | BC62: ='Annual Data'!B73 -> 3201256.9 | BE62: =100*((BB62/BB61)-1) -> 1.5883675 | BF62: =100*((BC62/BC61)-1) -> 1.5883964 | BH62: 2039 | BI62: ='Annual Data'!Z73*'Annual Data'!AA73 -> 1206396.9 | BJ62: ='Annual Data'!AB73/'Annual Data'!AC73 -> 14.805608 | BK62: ='Annual Data'!AD73 -> 4264640.5 | BL62: ='Annual Data'!AE73 -> -6.604714 | BM62: ='Annual Data'!Y73 -> 3226906.7 | BN62: ='Annual Data'!Q73 -> 3226906.8 | BP62: =100*((BM62/BM61)-1) -> 1.6118108 | BQ62: =100*((BN62/BN61)-1) -> 1.6118268
...

Sheet Annual Data
B1: ='Quarterly Data'!D1 -> APR014A.db | C1: ='Quarterly Data'!E1 -> APR014A.db | D1: ='Quarterly Data'!F1 -> APR014A.db | E1: ='Quarterly Data'!G1 -> APR014A.db | F1: ='Quarterly Data'!H1 -> APR014A.db | G1: ='Quarterly Data'!I1 -> APR014A.db | H1: ='Quarterly Data'!J1 -> APR014A.db | I1: ='Quarterly Data'!K1 -> APR014A.db | ... AE1: ='Quarterly Data'!AG1 -> MAR010I.db
B2: ='Quarterly Data'!D2 -> UK | C2: ='Quarterly Data'!E2 -> UK | D2: ='Quarterly Data'!F2 -> UK | E2: ='Quarterly Data'!G2 -> UK | F2: ='Quarterly Data'!H2 -> UK | G2: ='Quarterly Data'!I2 -> UK | H2: ='Quarterly Data'!J2 -> UK | I2: ='Quarterly Data'!K2 -> UK | ... AE2: ='Quarterly Data'!AG2 -> UK
B3: ='Quarterly Data'!D3 -> GDP | C3: ='Quarterly Data'!E3 -> CPI | D3: ='Quarterly Data'!F3 -> X | E3: ='Quarterly Data'!G3 -> XGNF | F3: ='Quarterly Data'!H3 -> M | G3: ='Quarterly Data'!I3 -> MGNF | H3: ='Quarterly Data'!J3 -> IF | I3: ='Quarterly Data'!K3 -> IPNR | ... AE3: ='Quarterly Data'!AG3 -> TREND
B4: ='Quarterly Data'!D4 -> GBR | C4: ='Quarterly Data'!E4 -> GBR | D4: ='Quarterly Data'!F4 -> GBR | E4: ='Quarterly Data'!G4 -> GBR | F4: ='Quarterly Data'!H4 -> GBR | G4: ='Quarterly Data'!I4 -> GBR | H4: ='Quarterly Data'!J4 -> GBR | I4: ='Quarterly Data'!K4 -> GBR | ... AE4: ='Quarterly Data'!AG4 -> GBR
B5: ='Quarterly Data'!D5 -> L | C5: ='Quarterly Data'!E5 -> L | D5: ='Quarterly Data'!F5 -> L | E5: ='Quarterly Data'!G5 -> L | F5: ='Quarterly Data'!H5 -> L | G5: ='Quarterly Data'!I5 -> L | H5: ='Quarterly Data'!J5 -> L | I5: ='Quarterly Data'!K5 -> L | ... AE5: ='Quarterly Data'!AG5 -> L
B6: ='Quarterly Data'!D6 -> 202404 | C6: ='Quarterly Data'!E6 -> 202404 | D6: ='Quarterly Data'!F6 -> 202404 | E6: ='Quarterly Data'!G6 -> 202404 | F6: ='Quarterly Data'!H6 -> 202404 | G6: ='Quarterly Data'!I6 -> 202404 | H6: ='Quarterly Data'!J6 -> 202404 | I6: ='Quarterly Data'!K6 -> 202404 | ... AE6: ='Quarterly Data'!AG6 -> 202302
A7: 1973 | B7: =SUMIF('Quarterly Data'!$B:$B,'Annual Data'!$A7,'Quarterly Data'!D:D) -> 987527 | C7: =AVERAGEIF('Quarterly Data'!$B:$B,'Annual Data'!$A7,'Quarterly Data'!E:E) -> 12.428425 | D7: =SUMIF('Quarterly Data'!$B:$B,'Annual Data'!$A7,'Quarterly Data'!F:F) -> 148219 | E7: =SUMIF('Quarterly Data'!$B:$B,'Annual Data'!$A7,'Quarterly Data'!G:G) -> 57084.06 | F7: =SUMIF('Quarterly Data'!$B:$B,'Annual Data'!$A7,'Quarterly Data'!H:H) -> 141214 | G7: =SUMIF('Quarterly Data'!$B:$B,'Annual Data'!$A7,'Quarterly Data'!I:I) -> -16816.35 | H7: =SUMIF('Quarterly Data'!$B:$B,'Annual Data'!$A7,'Quarterly Data'!J:J) -> 193673 | I7: =SUMIF('Quarterly Data'!$B:$B,'Annual Data'!$A7,'Quarterly Data'!K:K) -> 64130.86 | J7: =SUMIF('Quarterly Data'!$B:$B,'Annual Data'!$A7,'Quarterly Data'!L:L) -> 995761.2 | K7: =AVERAGEIF('Quarterly Data'!$B:$B,'Annual Data'!$A7,'Quarterly Data'!M:M) -> 24874.8 | L7: =AVERAGEIF('Quarterly Data'!$B:$B,'Annual Data'!$A7,'Quarterly Data'!N:N) -> 0.001 | M7: =AVERAGEIF('Quarterly Data'!$B:$B,'Annual Data'!$A7,'Quarterly Data'!O:O) -> 286021.4 | N7: =AVERAGEIF('Quarterly Data'!$B:$B,'Annual Data'!$A7,'Quarterly Data'!P:P) -> 35322.815 | O7: =AVERAGEIF('Quarterly Data'!$B:$B,'Annual Data'!$A7,'Quarterly Data'!Q:Q) -> 1074461.5 | P7: =SUMIF('Quarterly Data'!$B:$B,'Annual Data'!$A7,'Quarterly Data'!R:R) -> -7.690755 | Q7: =SUMIF('Quarterly Data'!$B:$B,'Annual Data'!$A7,'Quarterly Data'!S:S) -> 987527 | R7: =AVERAGEIF('Quarterly Data'!$B:$B,'Annual Data'!$A7,'Quarterly Data'!T:T) -> 12.428425 | S7: =SUMIF('Quarterly Data'!$B:$B,'Annual Data'!$A7,'Quarterly Data'!U:U) -> 148219 | T7: =SUMIF('Quarterly Data'!$B:$B,'Annual Data'!$A7,'Quarterly Data'!V:V) -> 57084.06 | U7: =SUMIF('Quarterly Data'!$B:$B,'Annual Data'!$A7,'Quarterly Data'!W:W) -> 141214 | V7: =SUMIF('Quarterly Data'!$B:$B,'Annual Data'!$A7,'Quarterly Data'!X:X) -> -16816.35 | W7: =SUMIF('Quarterly Data'!$B:$B,'Annual Data'!$A7,'Quarterly Data'!Y:Y) -> 193673 | X7: =SUMIF('Quarterly Data'!$B:$B,'Annual Data'!$A7,'Quarterly Data'!Z:Z) -> 64130.86 | Y7: =SUMIF('Quarterly Data'!$B:$B,'Annual Data'!$A7,'Quarterly Data'!AA:AA) -> 995761.2 | Z7: =AVERAGEIF('Quarterly Data'!$B:$B,'Annual Data'!$A7,'Quarterly Data'!AB:AB) -> 24874.8 | AA7: =AVERAGEIF('Quarterly Data'!$B:$B,'Annual Data'!$A7,'Quarterly Data'!AC:AC) -> 0.001 | AB7: =AVERAGEIF('Quarterly Data'!$B:$B,'Annual Data'!$A7,'Quarterly Data'!AD:AD) -> 286021.4 | AC7: =AVERAGEIF('Quarterly Data'!$B:$B,'Annual Data'!$A7,'Quarterly Data'!AE:AE) -> 35322.815 | AD7: =AVERAGEIF('Quarterly Data'!$B:$B,'Annual Data'!$A7,'Quarterly Data'!AF:AF) -> 1074461.5 | AE7: =SUMIF('Quarterly Data'!$B:$B,'Annual Data'!$A7,'Quarterly Data'!AG:AG) -> -7.690755
A8: 1974 | B8: =SUMIF('Quarterly Data'!$B:$B,'Annual Data'!$A8,'Quarterly Data'!D:D) -> 962880 | C8: =AVERAGEIF('Quarterly Data'!$B:$B,'Annual Data'!$A8,'Quarterly Data'!E:E) -> 14.383608 | D8: =SUMIF('Quarterly Data'!$B:$B,'Annual Data'!$A8,'Quarterly Data'!F:F) -> 158966 | E8: =SUMIF('Quarterly Data'!$B:$B,'Annual Data'!$A8,'Quarterly Data'!G:G) -> 63320.36 | F8: =SUMIF('Quarterly Data'!$B:$B,'Annual Data'!$A8,'Quarterly Data'!H:H) -> 142566 | G8: =SUMIF('Quarterly Data'!$B:$B,'Annual Data'!$A8,'Quarterly Data'!I:I) -> -9135.5 | H8: =SUMIF('Quarterly Data'!$B:$B,'Annual Data'!$A8,'Quarterly Data'!J:J) -> 179218 | I8: =SUMIF('Quarterly Data'!$B:$B,'Annual Data'!$A8,'Quarterly Data'!K:K) -> 67920.03 | J8: =SUMIF('Quarterly Data'!$B:$B,'Annual Data'!$A8,'Quarterly Data'!L:L) -> 1007843.7 | K8: =AVERAGEIF('Quarterly Data'!$B:$B,'Annual Data'!$A8,'Quarterly Data'!M:M) -> 24938.64 | L8: =AVERAGEIF('Quarterly Data'!$B:$B,'Annual Data'!$A8,'Quarterly Data'!N:N) -> 0.001 | M8: =AVERAGEIF('Quarterly Data'!$B:$B,'Annual Data'!$A8,'Quarterly Data'!O:O) -> 288869 | N8: =AVERAGEIF('Quarterly Data'!$B:$B,'Annual Data'!$A8,'Quarterly Data'!P:P) -> 35332.713 | O8: =AVERAGEIF('Quarterly Data'!$B:$B,'Annual Data'!$A8,'Quarterly Data'!Q:Q) -> 1107914 | P8: =SUMIF('Quarterly Data'!$B:$B,'Annual Data'!$A8,'Quarterly Data'!R:R) -> -7.706507 | Q8: =SUMIF('Quarterly Data'!$B:$B,'Annual Data'!$A8,'Quarterly Data'!S:S) -> 962880 | R8: =AVERAGEIF('Quarterly Data'!$B:$B,'Annual Data'!$A8,'Quarterly Data'!T:T) -> 14.383608 | S8: =SUMIF('Quarterly Data'!$B:$B,'Annual Data'!$A8,'Quarterly Data'!U:U) -> 158966 | T8: =SUMIF('Quarterly Data'!$B:$B,'Annual Data'!$A8,'Quarterly Data'!V:V) -> 63320.36 | U8: =SUMIF('Quarterly Data'!$B:$B,'Annual Data'!$A8,'Quarterly Data'!W:W) -> 142566 | V8: =SUMIF('Quarterly Data'!$B:$B,'Annual Data'!$A8,'Quarterly Data'!X:X) -> -9135.5 | W8: =SUMIF('Quarterly Data'!$B:$B,'Annual Data'!$A8,'Quarterly Data'!Y:Y) -> 179218 | X8: =SUMIF('Quarterly Data'!$B:$B,'Annual Data'!$A8,'Quarterly Data'!Z:Z) -> 67920.03 | Y8: =SUMIF('Quarterly Data'!$B:$B,'Annual Data'!$A8,'Quarterly Data'!AA:AA) -> 1007843.7 | Z8: =AVERAGEIF('Quarterly Data'!$B:$B,'Annual Data'!$A8,'Quarterly Data'!AB:AB) -> 24938.64 | AA8: =AVERAGEIF('Quarterly Data'!$B:$B,'Annual Data'!$A8,'Quarterly Data'!AC:AC) -> 0.001 | AB8: =AVERAGEIF('Quarterly Data'!$B:$B,'Annual Data'!$A8,'Quarterly Data'!AD:AD) -> 288869 | AC8: =AVERAGEIF('Quarterly Data'!$B:$B,'Annual Data'!$A8,'Quarterly Data'!AE:AE) -> 35332.713 | AD8: =AVERAGEIF('Quarterly Data'!$B:$B,'Annual Data'!$A8,'Quarterly Data'!AF:AF) -> 1107914 | AE8: =SUMIF('Quarterly Data'!$B:$B,'Annual Data'!$A8,'Quarterly Data'!AG:AG) -> -7.706507
