Workbook
Name _DLX1.INC: HAVERM!$A$1:$G$6
Name _DLX2.INC: HAVERQ!$A$2:$BN$7
Name Data: [1]sheet0!$C$2

Sheet CHARTS>>

Sheet DATA>>

Sheet Chart Data
A1: LFS unemployment - single-month & three-month rates | E1: LFS unemployment - single-month range & 3-month rate | L1: Employees - LFS, HMRC, WFJ | Q1: LFS revisions | Y1: Long-term net inward migration
B3: Single month rate | C3: Three-month rate | F3: Single month range - min | G3: Range of single-month estimates | H3: Three-month rate | J3: Single month range - max | M3: Labour Force Survey | N3: HMRC | O3: Workforce jobs | R3: 45200 | S3: 45323 | T3: Current | V3: Diff 000s | W3: Diff % | Z3: Current estimate | AA3: Previous estimate | AB3: January 2024 population projections | AD3: Diff (history) | AE3: Diff vs pproj
A4: 42370 | B4: =HAVERM!C439 -> 4.928 | C4: =HAVERM!B439 -> 5.1 | E4: 42370 | F4: =MIN(HAVERM!C438:C440) -> 4.928 | G4: =J4-F4 -> 0.324 | H4: =HAVERM!B439 -> 5.1 | J4: =MAX(HAVERM!C438:C440) -> 5.252 | L4: 43466 | M4: =HAVERQ!BC164-AVERAGE(HAVERQ!$BC$164:$BC$167) -> -88.25 | N4: =(HAVERQ!BD164-AVERAGE(HAVERQ!$BD$164:$BD$167))/1000 -> -77.403167 | O4: =HAVERQ!BE164-AVERAGE(HAVERQ!$BE$164:$BE$167) -> -111 | Q4: 43466 | R4: =DataQ!Q191 -> 32697 | S4: =DataQ!P191 -> 32721 | T4: =DataQ!O191 -> 32773 | V4: =T4-R4 -> 76 | W4: =100*((T4/R4)-1) -> 0.23243723 | Y4: 41061 | Z4: ='LTIM ye Jun24 - Table 1'!C105 -> 162000 | AA4: ='LTIM ye Dec23 - Table 1'!C100 -> 162000
A5: 42401 | B5: =HAVERM!C440 -> 5.116 | C5: =HAVERM!B440 -> 5.1 | E5: 42401 | F5: =MIN(HAVERM!C439:C441) -> 4.928 | G5: =J5-F5 -> 0.237 | H5: =HAVERM!B440 -> 5.1 | J5: =MAX(HAVERM!C439:C441) -> 5.165 | L5: 43556 | M5: =HAVERQ!BC165-AVERAGE(HAVERQ!$BC$164:$BC$167) -> 31.75 | N5: =(HAVERQ!BD165-AVERAGE(HAVERQ!$BD$164:$BD$167))/1000 -> -12.3305 | O5: =HAVERQ!BE165-AVERAGE(HAVERQ!$BE$164:$BE$167) -> -38 | Q5: 43556 | R5: =DataQ!Q192 -> 32811 | S5: =DataQ!P192 -> 32839 | T5: =DataQ!O192 -> 32965 | V5: =T5-R5 -> 154 | W5: =100*((T5/R5)-1) -> 0.46935479 | Y5: 41153 | Z5: ='LTIM ye Jun24 - Table 1'!C106 -> 157000 | AA5: ='LTIM ye Dec23 - Table 1'!C101 -> 157000
A6: 42430 | B6: =HAVERM!C441 -> 5.165 | C6: =HAVERM!B441 -> 5 | E6: 42430 | F6: =MIN(HAVERM!C440:C442) -> 4.73 | G6: =J6-F6 -> 0.435 | H6: =HAVERM!B441 -> 5 | J6: =MAX(HAVERM!C440:C442) -> 5.165 | L6: 43647 | M6: =HAVERQ!BC166-AVERAGE(HAVERQ!$BC$164:$BC$167) -> -18.25 | N6: =(HAVERQ!BD166-AVERAGE(HAVERQ!$BD$164:$BD$167))/1000 -> 20.369833 | O6: =HAVERQ!BE166-AVERAGE(HAVERQ!$BE$164:$BE$167) -> 94 | Q6: 43647 | R6: =DataQ!Q193 -> 32753 | S6: =DataQ!P193 -> 32779 | T6: =DataQ!O193 -> 32894 | V6: =T6-R6 -> 141 | W6: =100*((T6/R6)-1) -> 0.43049492 | Y6: 41244 | Z6: ='LTIM ye Jun24 - Table 1'!C107 -> 195000 | AA6: ='LTIM ye Dec23 - Table 1'!C102 -> 195000
A7: 42461 | B7: =HAVERM!C442 -> 4.73 | C7: =HAVERM!B442 -> 4.9 | E7: 42461 | F7: =MIN(HAVERM!C441:C443) -> 4.73 | G7: =J7-F7 -> 0.435 | H7: =HAVERM!B442 -> 4.9 | J7: =MAX(HAVERM!C441:C443) -> 5.165 | L7: 43739 | M7: =HAVERQ!BC167-AVERAGE(HAVERQ!$BC$164:$BC$167) -> 74.75 | N7: =(HAVERQ!BD167-AVERAGE(HAVERQ!$BD$164:$BD$167))/1000 -> 69.363833 | O7: =HAVERQ!BE167-AVERAGE(HAVERQ!$BE$164:$BE$167) -> 55 | Q7: 43739 | R7: =DataQ!Q194 -> 32934 | S7: =DataQ!P194 -> 32954 | T7: =DataQ!O194 -> 33055 | V7: =T7-R7 -> 121 | W7: =100*((T7/R7)-1) -> 0.36740147 | Y7: 41334 | Z7: ='LTIM ye Jun24 - Table 1'!C108 -> 204000 | AA7: ='LTIM ye Dec23 - Table 1'!C103 -> 204000
A8: 42491 | B8: =HAVERM!C443 -> 4.88 | C8: =HAVERM!B443 -> 4.9 | E8: 42491 | F8: =MIN(HAVERM!C442:C444) -> 4.73 | G8: =J8-F8 -> 0.415 | H8: =HAVERM!B443 -> 4.9 | J8: =MAX(HAVERM!C442:C444) -> 5.145 | L8: 43831 | M8: =HAVERQ!BC168-AVERAGE(HAVERQ!$BC$164:$BC$167) -> 98.75 | N8: =(HAVERQ!BD168-AVERAGE(HAVERQ!$BD$164:$BD$167))/1000 -> 123.16417 | O8: =HAVERQ!BE168-AVERAGE(HAVERQ!$BE$164:$BE$167) -> 201 | Q8: 43831 | R8: =DataQ!Q195 -> 32984 | S8: =DataQ!P195 -> 33000 | T8: =DataQ!O195 -> 32972 | V8: =T8-R8 -> -12 | W8: =100*((T8/R8)-1) -> -0.036381276 | Y8: 41426 | Z8: ='LTIM ye Jun24 - Table 1'!C109 -> 215000 | AA8: ='LTIM ye Dec23 - Table 1'!C104 -> 215000
A9: 42522 | B9: =HAVERM!C444 -> 5.145 | C9: =HAVERM!B444 -> 4.9 | E9: 42522 | F9: =MIN(HAVERM!C443:C445) -> 4.659 | G9: =J9-F9 -> 0.486 | H9: =HAVERM!B444 -> 4.9 | J9: =MAX(HAVERM!C443:C445) -> 5.145 | L9: 43922 | M9: =HAVERQ!BC169-AVERAGE(HAVERQ!$BC$164:$BC$167) -> 52.75 | N9: =(HAVERQ!BD169-AVERAGE(HAVERQ!$BD$164:$BD$167))/1000 -> -470.3985 | O9: =HAVERQ!BE169-AVERAGE(HAVERQ!$BE$164:$BE$167) -> -96 | Q9: 43922 | R9: =DataQ!Q196 -> 32560 | S9: =DataQ!P196 -> 32571 | T9: =DataQ!O196 -> 32636 | V9: =T9-R9 -> 76 | W9: =100*((T9/R9)-1) -> 0.23341523 | Y9: 41518 | Z9: ='LTIM ye Jun24 - Table 1'!C110 -> 259000 | AA9: ='LTIM ye Dec23 - Table 1'!C105 -> 259000
A10: 42552 | B10: =HAVERM!C445 -> 4.659 | C10: =HAVERM!B445 -> 5 | E10: 42552 | F10: =MIN(HAVERM!C444:C446) -> 4.659 | G10: =J10-F10 -> 0.486 | H10: =HAVERM!B445 -> 5 | J10: =MAX(HAVERM!C444:C446) -> 5.145 | L10: 44013 | M10: =HAVERQ!BC170-AVERAGE(HAVERQ!$BC$164:$BC$167) -> 18.75 | N10: =(HAVERQ!BD170-AVERAGE(HAVERQ!$BD$164:$BD$167))/1000 -> -654.1075 | O10: =HAVERQ!BE170-AVERAGE(HAVERQ!$BE$164:$BE$167) -> -502 | Q10: 44013 | R10: =DataQ!Q197 -> 32333 | S10: =DataQ!P197 -> 32354 | T10: =DataQ!O197 -> 32352 | V10: =T10-R10 -> 19 | W10: =100*((T10/R10)-1) -> 0.058763492 | Y10: 41609 | Z10: ='LTIM ye Jun24 - Table 1'!C111 -> 244000 | AA10: ='LTIM ye Dec23 - Table 1'!C106 -> 244000
A11: 42583 | B11: =HAVERM!C446 -> 5.104 | C11: =HAVERM!B446 -> 4.8 | E11: 42583 | F11: =MIN(HAVERM!C445:C447) -> 4.659 | G11: =J11-F11 -> 0.445 | H11: =HAVERM!B446 -> 4.8 | J11: =MAX(HAVERM!C445:C447) -> 5.104 | L11: 44105 | M11: =HAVERQ!BC171-AVERAGE(HAVERQ!$BC$164:$BC$167) -> 64.75 | N11: =(HAVERQ!BD171-AVERAGE(HAVERQ!$BD$164:$BD$167))/1000 -> -786.03883 | O11: =HAVERQ!BE171-AVERAGE(HAVERQ!$BE$164:$BE$167) -> -507 | Q11: 44105 | R11: =DataQ!Q198 -> 32159 | S11: =DataQ!P198 -> 32198 | T11: =DataQ!O198 -> 32266 | V11: =T11-R11 -> 107 | W11: =100*((T11/R11)-1) -> 0.33272179 | Y11: 41699 | Z11: ='LTIM ye Jun24 - Table 1'!C112 -> 256000 | AA11: ='LTIM ye Dec23 - Table 1'!C107 -> 256000
A12: 42614 | B12: =HAVERM!C447 -> 4.736 | C12: =HAVERM!B447 -> 4.8 | E12: 42614 | F12: =MIN(HAVERM!C446:C448) -> 4.66 | G12: =J12-F12 -> 0.444 | H12: =HAVERM!B447 -> 4.8 | J12: =MAX(HAVERM!C446:C448) -> 5.104 | L12: 44197 | M12: =HAVERQ!BC172-AVERAGE(HAVERQ!$BC$164:$BC$167) -> 164.75 | N12: =(HAVERQ!BD172-AVERAGE(HAVERQ!$BD$164:$BD$167))/1000 -> -736.78817 | O12: =HAVERQ!BE172-AVERAGE(HAVERQ!$BE$164:$BE$167) -> -318 | Q12: 44197 | R12: =DataQ!Q199 -> 32165 | S12: =DataQ!P199 -> 32221 | T12: =DataQ!O199 -> 32308 | V12: =T12-R12 -> 143 | W12: =100*((T12/R12)-1) -> 0.44458262 | Y12: 41791 | Z12: ='LTIM ye Jun24 - Table 1'!C113 -> 248000 | AA12: ='LTIM ye Dec23 - Table 1'!C108 -> 248000
A13: 42644 | B13: =HAVERM!C448 -> 4.66 | C13: =HAVERM!B448 -> 4.8 | E13: 42644 | F13: =MIN(HAVERM!C447:C449) -> 4.66 | G13: =J13-F13 -> 0.291 | H13: =HAVERM!B448 -> 4.8 | J13: =MAX(HAVERM!C447:C449) -> 4.951 | L13: 44287 | M13: =HAVERQ!BC173-AVERAGE(HAVERQ!$BC$164:$BC$167) -> 299.75 | N13: =(HAVERQ!BD173-AVERAGE(HAVERQ!$BD$164:$BD$167))/1000 -> -405.6285 | O13: =HAVERQ!BE173-AVERAGE(HAVERQ!$BE$164:$BE$167) -> -54 | Q13: 44287 | R13: =DataQ!Q200 -> 32303 | S13: =DataQ!P200 -> 32377 | T13: =DataQ!O200 -> 32454 | V13: =T13-R13 -> 151 | W13: =100*((T13/R13)-1) -> 0.46744884 | Y13: 41883 | Z13: ='LTIM ye Jun24 - Table 1'!C114 -> 264000 | AA13: ='LTIM ye Dec23 - Table 1'!C109 -> 264000
A14: 42675 | B14: =HAVERM!C449 -> 4.951 | C14: =HAVERM!B449 -> 4.7 | E14: 42675 | F14: =MIN(HAVERM!C448:C450) -> 4.594 | G14: =J14-F14 -> 0.357 | H14: =HAVERM!B449 -> 4.7 | J14: =MAX(HAVERM!C448:C450) -> 4.951 | L14: 44378 | M14: =HAVERQ!BC174-AVERAGE(HAVERQ!$BC$164:$BC$167) -> 547.75 | N14: =(HAVERQ!BD174-AVERAGE(HAVERQ!$BD$164:$BD$167))/1000 -> 18.3385 | O14: =HAVERQ!BE174-AVERAGE(HAVERQ!$BE$164:$BE$167) -> 279 | Q14: 44378 | R14: =DataQ!Q201 -> 32592 | S14: =DataQ!P201 -> 32687 | T14: =DataQ!O201 -> 32712 | V14: =T14-R14 -> 120 | W14: =100*((T14/R14)-1) -> 0.36818851 | Y14: 41974 | Z14: ='LTIM ye Jun24 - Table 1'!C115 -> 284000 | AA14: ='LTIM ye Dec23 - Table 1'!C110 -> 284000
A15: 42705 | B15: =HAVERM!C450 -> 4.594 | C15: =HAVERM!B450 -> 4.7 | E15: 42705 | F15: =MIN(HAVERM!C449:C451) -> 4.594 | G15: =J15-F15 -> 0.357 | H15: =HAVERM!B450 -> 4.7 | J15: =MAX(HAVERM!C449:C451) -> 4.951 | L15: 44470 | M15: =HAVERQ!BC175-AVERAGE(HAVERQ!$BC$164:$BC$167) -> 638.75 | N15: =(HAVERQ!BD175-AVERAGE(HAVERQ!$BD$164:$BD$167))/1000 -> 252.3115 | O15: =HAVERQ!BE175-AVERAGE(HAVERQ!$BE$164:$BE$167) -> 424 | Q15: 44470 | R15: =DataQ!Q202 -> 32567 | S15: =DataQ!P202 -> 32686 | T15: =DataQ!O202 -> 32729 | V15: =T15-R15 -> 162 | W15: =100*((T15/R15)-1) -> 0.49743605 | Y15: 42064 | Z15: ='LTIM ye Jun24 - Table 1'!C116 -> 296000 | AA15: ='LTIM ye Dec23 - Table 1'!C111 -> 296000
... A21: 42887 | B21: =HAVERM!C456 -> 4.311 | C21: =HAVERM!B456 -> 4.3 | E21: 42887 | F21: =MIN(HAVERM!C455:C457) -> 4.311 | G21: =J21-F21 -> 0.079 | H21: =HAVERM!B456 -> 4.3 | J21: =MAX(HAVERM!C455:C457) -> 4.39 | L21: 45017 | M21: =HAVERQ!BC181-AVERAGE(HAVERQ!$BC$164:$BC$167) -> 1071.75 | N21: =(HAVERQ!BD181-AVERAGE(HAVERQ!$BD$164:$BD$167))/1000 -> 1227.6148 | O21: =HAVERQ!BE181-AVERAGE(HAVERQ!$BE$164:$BE$167) -> 1280 | Q21: 45017 | R21: =DataQ!Q208 -> 32929 | S21: =DataQ!P208 -> 33163 | T21: =DataQ!O208 -> 33356 | V21: =T21-R21 -> 427 | W21: =100*((T21/R21)-1) -> 1.2967293 | Y21: 42614 | Z21: ='LTIM ye Jun24 - Table 1'!C122 -> 290000 | AA21: ='LTIM ye Dec23 - Table 1'!C117 -> 290000
A22: 42917 | B22: =HAVERM!C457 -> 4.332 | C22: =HAVERM!B457 -> 4.3 | E22: 42917 | F22: =MIN(HAVERM!C456:C458) -> 4.311 | G22: =J22-F22 -> 0.021 | H22: =HAVERM!B457 -> 4.3 | J22: =MAX(HAVERM!C456:C458) -> 4.332 | L22: 45108 | M22: =HAVERQ!BC182-AVERAGE(HAVERQ!$BC$164:$BC$167) -> 1048.75 | N22: =(HAVERQ!BD182-AVERAGE(HAVERQ!$BD$164:$BD$167))/1000 -> 1290.1655 | O22: =HAVERQ!BE182-AVERAGE(HAVERQ!$BE$164:$BE$167) -> 1412 | Q22: 45108 | S22: =DataQ!P209 -> 33102 | T22: =DataQ!O209 -> 33326 | Y22: 42705 | Z22: ='LTIM ye Jun24 - Table 1'!C123 -> 249000 | AA22: ='LTIM ye Dec23 - Table 1'!C118 -> 249000
A23: 42948 | B23: =HAVERM!C458 -> 4.33 | C23: =HAVERM!B458 -> 4.3 | E23: 42948 | F23: =MIN(HAVERM!C457:C459) -> 4.134 | G23: =J23-F23 -> 0.198 | H23: =HAVERM!B458 -> 4.3 | J23: =MAX(HAVERM!C457:C459) -> 4.332 | L23: 45200 | M23: =HAVERQ!BC183-AVERAGE(HAVERQ!$BC$164:$BC$167) -> 1038.75 | N23: =(HAVERQ!BD183-AVERAGE(HAVERQ!$BD$164:$BD$167))/1000 -> 1389.6362 | O23: =HAVERQ!BE183-AVERAGE(HAVERQ!$BE$164:$BE$167) -> 1460 | Q23: 45200 | S23: =DataQ!P210 -> 33174 | T23: =DataQ!O210 -> 33377 | Y23: 42795 | Z23: ='LTIM ye Jun24 - Table 1'!C124 -> 240000 | AA23: ='LTIM ye Dec23 - Table 1'!C119 -> 240000
A24: 42979 | B24: =HAVERM!C459 -> 4.134 | C24: =HAVERM!B459 -> 4.2 | E24: 42979 | F24: =MIN(HAVERM!C458:C460) -> 4.134 | G24: =J24-F24 -> 0.196 | H24: =HAVERM!B459 -> 4.2 | J24: =MAX(HAVERM!C458:C460) -> 4.33 | L24: 45292 | M24: =HAVERQ!BC184-AVERAGE(HAVERQ!$BC$164:$BC$167) -> 1146.75 | N24: =(HAVERQ!BD184-AVERAGE(HAVERQ!$BD$164:$BD$167))/1000 -> 1457.8648 | O24: =HAVERQ!BE184-AVERAGE(HAVERQ!$BE$164:$BE$167) -> 1552 | Q24: 45292 | T24: =DataQ!O211 -> 33331 | Y24: 42887 | Z24: ='LTIM ye Jun24 - Table 1'!C125 -> 200000 | AA24: ='LTIM ye Dec23 - Table 1'!C120 -> 200000
A25: 43009 | B25: =HAVERM!C460 -> 4.289 | C25: =HAVERM!B460 -> 4.3 | E25: 43009 | F25: =MIN(HAVERM!C459:C461) -> 4.134 | G25: =J25-F25 -> 0.245 | H25: =HAVERM!B460 -> 4.3 | J25: =MAX(HAVERM!C459:C461) -> 4.379 | L25: 45383 | M25: =HAVERQ!BC185-AVERAGE(HAVERQ!$BC$164:$BC$167) -> 1242.75 | N25: =(HAVERQ!BD185-AVERAGE(HAVERQ!$BD$164:$BD$167))/1000 -> 1491.8655 | O25: =HAVERQ!BE185-AVERAGE(HAVERQ!$BE$164:$BE$167) -> 1576 | Q25: 45383 | T25: =DataQ!O212 -> 33496 | Y25: 42979 | Z25: ='LTIM ye Jun24 - Table 1'!C126 -> 205000 | AA25: ='LTIM ye Dec23 - Table 1'!C121 -> 205000
A26: 43040 | B26: =HAVERM!C461 -> 4.379 | C26: =HAVERM!B461 -> 4.4 | E26: 43040 | F26: =MIN(HAVERM!C460:C462) -> 4.289 | G26: =J26-F26 -> 0.106 | H26: =HAVERM!B461 -> 4.4 | J26: =MAX(HAVERM!C460:C462) -> 4.395 | L26: 45474 | M26: =HAVERQ!BC186-AVERAGE(HAVERQ!$BC$164:$BC$167) -> 1458.75 | N26: =(HAVERQ!BD186-AVERAGE(HAVERQ!$BD$164:$BD$167))/1000 -> 1487.0645 | O26: =HAVERQ!BE186-AVERAGE(HAVERQ!$BE$164:$BE$167) -> 1617 | Q26: 45474 | T26: =DataQ!O213 -> 33749 | Y26: 43070 | Z26: ='LTIM ye Jun24 - Table 1'!C127 -> 208000 | AA26: ='LTIM ye Dec23 - Table 1'!C122 -> 208000
A27: 43070 | B27: =HAVERM!C462 -> 4.395 | C27: =HAVERM!B462 -> 4.3 | E27: 43070 | F27: =MIN(HAVERM!C461:C463) -> 4.173 | G27: =J27-F27 -> 0.222 | H27: =HAVERM!B462 -> 4.3 | J27: =MAX(HAVERM!C461:C463) -> 4.395 | L27: 45566 | N27: =(HAVERQ!BD187-AVERAGE(HAVERQ!$BD$164:$BD$167))/1000 -> 1469.1912 | Q27: 45566 | Y27: 43160 | Z27: ='LTIM ye Jun24 - Table 1'!C128 -> 193000 | AA27: ='LTIM ye Dec23 - Table 1'!C123 -> 193000
A28: 43101 | B28: =HAVERM!C463 -> 4.173 | C28: =HAVERM!B463 -> 4.2 | E28: 43101 | F28: =MIN(HAVERM!C462:C464) -> 4.056 | G28: =J28-F28 -> 0.339 | H28: =HAVERM!B463 -> 4.2 | J28: =MAX(HAVERM!C462:C464) -> 4.395 | Y28: 43252 | Z28: ='LTIM ye Jun24 - Table 1'!C129 -> 216000 | AA28: ='LTIM ye Dec23 - Table 1'!C124 -> 216000
A29: 43132 | B29: =HAVERM!C464 -> 4.056 | C29: =HAVERM!B464 -> 4.2 | E29: 43132 | F29: =MIN(HAVERM!C463:C465) -> 4.056 | G29: =J29-F29 -> 0.329 | H29: =HAVERM!B464 -> 4.2 | J29: =MAX(HAVERM!C463:C465) -> 4.385 | R29: =DataQ!Q6 -> 202302 | S29: =DataQ!P6 -> 202304 | T29: =DataQ!O6 -> 202403 | Y29: 43344 | Z29: ='LTIM ye Jun24 - Table 1'!C130 -> 226000 | AA29: ='LTIM ye Dec23 - Table 1'!C125 -> 226000
A30: 43160 | B30: =HAVERM!C465 -> 4.385 | C30: =HAVERM!B465 -> 4.2 | E30: 43160 | F30: =MIN(HAVERM!C464:C466) -> 4.056 | G30: =J30-F30 -> 0.329 | H30: =HAVERM!B465 -> 4.2 | J30: =MAX(HAVERM!C464:C466) -> 4.385 | Y30: 43435 | Z30: ='LTIM ye Jun24 - Table 1'!C131 -> 276000 | AA30: ='LTIM ye Dec23 - Table 1'!C126 -> 276000
A31: 43191 | B31: =HAVERM!C466 -> 4.16 | C31: =HAVERM!B466 -> 4.2 | E31: 43191 | F31: =MIN(HAVERM!C465:C467) -> 3.936 | G31: =J31-F31 -> 0.449 | H31: =HAVERM!B466 -> 4.2 | J31: =MAX(HAVERM!C465:C467) -> 4.385 | Y31: 43525 | Z31: ='LTIM ye Jun24 - Table 1'!C132 -> 274000 | AA31: ='LTIM ye Dec23 - Table 1'!C127 -> 274000
A32: 43221 | B32: =HAVERM!C467 -> 3.936 | C32: =HAVERM!B467 -> 4 | E32: 43221 | F32: =MIN(HAVERM!C466:C468) -> 3.936 | G32: =J32-F32 -> 0.224 | H32: =HAVERM!B467 -> 4 | J32: =MAX(HAVERM!C466:C468) -> 4.16 | Y32: 43617 | Z32: ='LTIM ye Jun24 - Table 1'!C133 -> 224000 | AA32: ='LTIM ye Dec23 - Table 1'!C128 -> 224000
A33: 43252 | B33: =HAVERM!C468 -> 4.037 | C33: =HAVERM!B468 -> 4 | E33: 43252 | F33: =MIN(HAVERM!C467:C469) -> 3.936 | G33: =J33-F33 -> 0.197 | H33: =HAVERM!B468 -> 4 | J33: =MAX(HAVERM!C467:C469) -> 4.133 | Y33: 43709 | Z33: ='LTIM ye Jun24 - Table 1'!C134 -> 202000 | AA33: ='LTIM ye Dec23 - Table 1'!C129 -> 202000
A34: 43282 | B34: =HAVERM!C469 -> 4.133 | C34: =HAVERM!B469 -> 4 | E34: 43282 | F34: =MIN(HAVERM!C468:C470) -> 3.925 | G34: =J34-F34 -> 0.208 | H34: =HAVERM!B469 -> 4 | J34: =MAX(HAVERM!C468:C470) -> 4.133 | Y34: 43800 | Z34: ='LTIM ye Jun24 - Table 1'!C135 -> 184000 | AA34: ='LTIM ye Dec23 - Table 1'!C130 -> 184000
A35: 43313 | B35: =HAVERM!C470 -> 3.925 | C35: =HAVERM!B470 -> 4.1 | E35: 43313 | F35: =MIN(HAVERM!C469:C471) -> 3.925 | G35: =J35-F35 -> 0.262 | H35: =HAVERM!B470 -> 4.1 | J35: =MAX(HAVERM!C469:C471) -> 4.187 | Y35: 43891 | Z35: ='LTIM ye Jun24 - Table 1'!C136 -> 170000 | AA35: ='LTIM ye Dec23 - Table 1'!C131 -> 170000
A36: 43344 | B36: =HAVERM!C471 -> 4.187 | C36: =HAVERM!B471 -> 4.1 | E36: 43344 | F36: =MIN(HAVERM!C470:C472) -> 3.925 | G36: =J36-F36 -> 0.262 | H36: =HAVERM!B471 -> 4.1 | J36: =MAX(HAVERM!C470:C472) -> 4.187 | Y36: 43983 | Z36: ='LTIM ye Jun24 - Table 1'!C137 -> 111000 | AA36: ='LTIM ye Dec23 - Table 1'!C132 -> 111000
A37: 43374 | B37: =HAVERM!C472 -> 4.101 | C37: =HAVERM!B472 -> 4 | E37: 43374 | F37: =MIN(HAVERM!C471:C473) -> 3.827 | G37: =J37-F37 -> 0.36 | H37: =HAVERM!B472 -> 4 | J37: =MAX(HAVERM!C471:C473) -> 4.187 | Y37: 44075 | Z37: ='LTIM ye Jun24 - Table 1'!C138 -> 35000 | AA37: ='LTIM ye Dec23 - Table 1'!C133 -> 35000
A38: 43405 | B38: =HAVERM!C473 -> 3.827 | C38: =HAVERM!B473 -> 4 | E38: 43405 | F38: =MIN(HAVERM!C472:C474) -> 3.827 | G38: =J38-F38 -> 0.318 | H38: =HAVERM!B473 -> 4 | J38: =MAX(HAVERM!C472:C474) -> 4.145 | Y38: 44166 | Z38: ='LTIM ye Jun24 - Table 1'!C139 -> 93000 | AA38: ='LTIM ye Dec23 - Table 1'!C134 -> 93000
A39: 43435 | B39: =HAVERM!C474 -> 4.145 | C39: =HAVERM!B474 -> 3.9 | E39: 43435 | F39: =MIN(HAVERM!C473:C475) -> 3.827 | G39: =J39-F39 -> 0.318 | H39: =HAVERM!B474 -> 3.9 | J39: =MAX(HAVERM!C473:C475) -> 4.145 | Y39: 44256 | Z39: ='LTIM ye Jun24 - Table 1'!C140 -> 132000 | AA39: ='LTIM ye Dec23 - Table 1'!C135 -> 132000
A40: 43466 | B40: =HAVERM!C475 -> 3.864 | C40: =HAVERM!B475 -> 4 | E40: 43466 | F40: =MIN(HAVERM!C474:C476) -> 3.819 | G40: =J40-F40 -> 0.326 | H40: =HAVERM!B475 -> 4 | J40: =MAX(HAVERM!C474:C476) -> 4.145 | Y40: 44348 | Z40: ='LTIM ye Jun24 - Table 1'!C141 -> 254000 | AA40: ='LTIM ye Dec23 - Table 1'!C136 -> 221000 | AB40: ='Pproj - Jan24'!D12*1000 -> 221500 | AE40: =Z40-AB40 -> 32500
A41: 43497 | B41: =HAVERM!C476 -> 3.819 | C41: =HAVERM!B476 -> 3.8 | E41: 43497 | F41: =MIN(HAVERM!C475:C477) -> 3.816 | G41: =J41-F41 -> 0.048 | H41: =HAVERM!B476 -> 3.8 | J41: =MAX(HAVERM!C475:C477) -> 3.864 | Y41: 44440 | Z41: ='LTIM ye Jun24 - Table 1'!C142 -> 467000 | AA41: ='LTIM ye Dec23 - Table 1'!C137 -> 443000
A42: 43525 | B42: =HAVERM!C477 -> 3.816 | C42: =HAVERM!B477 -> 3.8 | E42: 43525 | F42: =MIN(HAVERM!C476:C478) -> 3.816 | G42: =J42-F42 -> 0.073 | H42: =HAVERM!B477 -> 3.8 | J42: =MAX(HAVERM!C476:C478) -> 3.889 | Y42: 44531 | Z42: ='LTIM ye Jun24 - Table 1'!C143 -> 484000 | AA42: ='LTIM ye Dec23 - Table 1'!C138 -> 466000
A43: 43556 | B43: =HAVERM!C478 -> 3.889 | C43: =HAVERM!B478 -> 3.8 | E43: 43556 | F43: =MIN(HAVERM!C477:C479) -> 3.685 | G43: =J43-F43 -> 0.204 | H43: =HAVERM!B478 -> 3.8 | J43: =MAX(HAVERM!C477:C479) -> 3.889 | Y43: 44621 | Z43: ='LTIM ye Jun24 - Table 1'!C144 -> 548000 | AA43: ='LTIM ye Dec23 - Table 1'!C139 -> 526000
A44: 43586 | B44: =HAVERM!C479 -> 3.685 | C44: =HAVERM!B479 -> 3.9 | E44: 43586 | F44: =MIN(HAVERM!C478:C480) -> 3.685 | G44: =J44-F44 -> 0.401 | H44: =HAVERM!B479 -> 3.9 | J44: =MAX(HAVERM!C478:C480) -> 4.086 | Y44: 44713 | Z44: ='LTIM ye Jun24 - Table 1'!C145 -> 634000 | AA44: ='LTIM ye Dec23 - Table 1'!C140 -> 607000 | AB44: ='Pproj - Jan24'!D13*1000 -> 595900 | AD44: =Z44-AA44 -> 27000 | AE44: =Z44-AB44 -> 38100
A45: 43617 | B45: =HAVERM!C480 -> 4.086 | C45: =HAVERM!B480 -> 3.9 | E45: 43617 | F45: =MIN(HAVERM!C479:C481) -> 3.685 | G45: =J45-F45 -> 0.401 | H45: =HAVERM!B480 -> 3.9 | J45: =MAX(HAVERM!C479:C481) -> 4.086 | Y45: 44805 | Z45: ='LTIM ye Jun24 - Table 1'!C146 -> 789000 | AA45: ='LTIM ye Dec23 - Table 1'!C141 -> 718000
A46: 43647 | B46: =HAVERM!C481 -> 3.783 | C46: =HAVERM!B481 -> 3.9 | E46: 43647 | F46: =MIN(HAVERM!C480:C482) -> 3.771 | G46: =J46-F46 -> 0.315 | H46: =HAVERM!B481 -> 3.9 | J46: =MAX(HAVERM!C480:C482) -> 4.086 | Y46: 44896 | Z46: ='LTIM ye Jun24 - Table 1'!C147 -> 872000 | AA46: ='LTIM ye Dec23 - Table 1'!C142 -> 764000
...

Sheet HAVERM
A1: 198001 !M | B1: MGSX@UK | C1: UKSEURA@UK | D1: UKNEMW@UK
A2: .DESC | B2: UK: LFS: Unemployment Rate: Aged 16 and Over (SA, %) | C2: UK: LFS: Unemployment Rate: Aged 16 and Over (SA, %) | D2: UK: National Minimum Wage/National Living Wage (NSA, GBP/hr)
A3: .T1 | B3: Feb-1971 | C3: Jun-1992 | D3: Apr-1999
A4: .TN | B4: Oct-2024 | C4: Nov-2024 | D4: Mar-2026
A5: .LSOURCE | B5: Office for National Statistics | C5: Office for National Statistics | D5: Low Pay Commission
A6: .DTLM | B6: Jan-21-2025 07:06 | C6: Jan-21-2025 07:05 | D6: Oct-30-2024 11:52
A7: 198001 | B7: 5.7 | C7: #N/A | D7: #N/A
A8: 198002 | B8: 5.8 | C8: #N/A | D8: #N/A
A9: 198003 | B9: 6 | C9: #N/A | D9: #N/A
A10: 198004 | B10: 6.1 | C10: #N/A | D10: #N/A
A11: 198005 | B11: 6.3 | C11: #N/A | D11: #N/A
A12: 198006 | B12: 6.5 | C12: #N/A | D12: #N/A
A13: 198007 | B13: 6.8 | C13: #N/A | D13: #N/A
A14: 198008 | B14: 7.1 | C14: #N/A | D14: #N/A
A15: 198009 | B15: 7.4 | C15: #N/A | D15: #N/A
A16: 198010 | B16: 7.7 | C16: #N/A | D16: #N/A
A17: 198011 | B17: 8 | C17: #N/A | D17: #N/A
A18: 198012 | B18: 8.3 | C18: #N/A | D18: #N/A
... A155: 199205 | B155: 9.8 | C155: #N/A | D155: #N/A
A156: 199206 | B156: 9.9 | C156: 9.977 | D156: #N/A
A157: 199207 | B157: 9.9 | C157: 9.865 | D157: #N/A
A158: 199208 | B158: 9.9 | C158: 9.947 | D158: #N/A
A159: 199209 | B159: 10.1 | C159: 10.027 | D159: #N/A
A160: 199210 | B160: 10.2 | C160: 10.227 | D160: #N/A
A161: 199211 | B161: 10.4 | C161: 10.439 | D161: #N/A
A162: 199212 | B162: 10.5 | C162: 10.489 | D162: #N/A
A163: 199301 | B163: 10.7 | C163: 10.696 | D163: #N/A
A164: 199302 | B164: 10.6 | C164: 10.837 | D164: #N/A
A165: 199303 | B165: 10.6 | C165: 10.363 | D165: #N/A
A166: 199304 | B166: 10.5 | C166: 10.519 | D166: #N/A
A167: 199305 | B167: 10.4 | C167: 10.457 | D167: #N/A
... A237: 199903 | B237: 6.2 | C237: 6.115 | D237: #N/A
A238: 199904 | B238: 6.1 | C238: 6.139 | D238: 3.6
A239: 199905 | B239: 6 | C239: 6.079 | D239: 3.6
A240: 199906 | B240: 6 | C240: 5.915 | D240: 3.6
A241: 199907 | B241: 5.9 | C241: 5.922 | D241: 3.6
A242: 199908 | B242: 5.9 | C242: 5.887 | D242: 3.6
A243: 199909 | B243: 5.8 | C243: 5.845 | D243: 3.6
A244: 199910 | B244: 5.8 | C244: 5.773 | D244: 3.6
A245: 199911 | B245: 5.8 | C245: 5.937 | D245: 3.6
...

Sheet HAVERQ
V1: =AVERAGE(V$180:V$183) -> 2596.75 | AN1: =AVERAGE(AN$180:AN$183) -> 30807.75 | AT1: =V1/(V1+AN1) -> 0.077736533 | AU1: =1-AT1 -> 0.92226347
A2: 19801 !Q | B2: G7AUQ@UK | C2: G7K5Q@UK | D2: G7GOQ@UK | E2: MFY7Q@UK | F2: MFZ2Q@UK | G2: G9BZQ@UK | H2: G9C2Q@UK | I2: MFY9Q@UK | J2: MFY5Q@UK | K2: G7ERQ@UK | L2: G7EUQ@UK | M2: G7EXQ@UK | N2: G7F2Q@UK | O2: G7F5Q@UK | P2: G7FGQ@UK | Q2: G7FJQ@UK | R2: G7FMQ@UK | S2: DYDCQ@UK | T2: JWR5Q@UK | U2: JWR6Q@UK | V2: JWR7Q@UK | W2: JWR8Q@UK | X2: JWR9Q@UK | Y2: JWS2Q@UK | Z2: JWS3Q@UK | AA2: JWS4Q@UK | AB2: JWS5Q@UK | AC2: JWS6Q@UK | AD2: JWS7Q@UK | AE2: JWS8Q@UK | AF2: JWS9Q@UK | AG2: JWT2Q@UK | AH2: JWT3Q@UK | AI2: JWT4Q@UK | AJ2: JWT5Q@UK | AK2: JWT6Q@UK | AL2: JWT7Q@UK | AM2: KW78Q@UK | AN2: JWT8Q@UK | AO2: UKNEJ@UK | AP2: MGSCQ@UK | AQ2: MGSXQ@UK | AR2: BEIRQ@UK | AS2: UNVAL1@UK | AT2: UBCMERD@UK | AU2: UBCSERD@UK | AV2: YBWHQ@UK | AW2: MGSLQ@UK | AX2: MGWGQ@UK | AY2: LF24Q@UK | AZ2: YBUVQ@UK | BA2: KAC4@UK | BB2: MGRZQ@UK | BC2: MGRNQ@UK | BD2: UKSEPEP@UK | BE2: BCAJQ@UK | BF2: YCCXQ@UK | BG2: LFM2Q@UK | BH2: MGSCQ@UK
A3: .DESC | B3: UK: Total Public Sector Employment (SA, Thous) | C3: UK: Total Private Sector Employment (SA, Thous) | D3: UK: Total Employment [Labor Force Survey] (SA, Thous) | E3: UK: Public Sector Employment ex Major Reclassifications (SA. Thous) | F3: UK: Private Sector Employment ex Major Reclassifications (SA. Thous) | G3: UK: Public Sector Employment as % of Total Employment (SA, %) | H3: UK: Private Sector Employment as % of Total Employment (SA, %) | I3: UK: Public Sector Employment ex Major Reclassifications (SA. % of Employed) | J3: UK: Private Sector Employment ex Major Reclassifications (SA. % of Employed) | K3: UK: Public Sector Employment: Construction (SA, Thous) | L3: UK: Public Sector Employment: HM Forces (SA, Thous) | M3: UK: Public Sector Employment: Police [including Civilians] (SA, Thous) | N3: UK: Public Sector Employment: Public Administration (SA, Thous) | O3: UK: Public Sector Employment: Education (SA, Thous) | P3: UK: Public Sector Employment: National Health Service (SA, Thous) | Q3: UK: Public Sector Employment: Other Health and Social Work (SA, Thous) | R3: UK: Public Sector Employment: Other Public Sector (SA, Thous) | S3: UK: Total Workforce Jobs [Count of Jobs, Not People] (SA, Thous) | T3: UK: Workforce Jobs: Agriculture, Forestry & Fishing(SA, Thous) | U3: UK: Workforce Jobs: Mining & Quarrying(SA, Thous) | V3: UK: Workforce Jobs: Manufacturing(SA, Thous) | W3: UK: Workforce Jobs: Electricity, Gas, Steam & Air-Conditioning Supply(SA, Thous) | X3: UK: Workforce Jobs: Water Supply, Waste Management & Remediation(SA, Thous) | Y3: UK: Workforce Jobs: Construction(SA, Thous) | Z3: UK: Workforce Jobs: Wholesale/Retail Trade, Motor Vehicle Repair(SA, Thous) | AA3: UK: Workforce Jobs: Transportation & Storage(SA, Thous) | AB3: UK: Workforce Jobs: Accommodation & Food Services(SA, Thous) | AC3: UK: Workforce Jobs: Information & Communication(SA, Thous) | AD3: UK: Workforce Jobs: Financial & Insurance Activities(SA, Thous) | AE3: UK: Workforce Jobs: Real Estate Activities(SA, Thous) | AF3: UK: Workforce Jobs: Professional Scientific & Technical Activities(SA, Thous) | AG3: UK: Workforce Jobs: Administrative & Support Services(SA, Thous) | AH3: UK: Workforce Jobs: Public Administration, Defense, Social Security(SA, Thous) | AI3: UK: Workforce Jobs: Education(SA, Thous) | AJ3: UK: Workforce Jobs: Human Health & Social Work Activities(SA, Thous) | AK3: UK: Workforce Jobs: Arts, Entertainment & Recreation(SA, Thous) | AL3: UK: Workforce Jobs: Other Service Activities(SA, Thous) | AM3: UK: Workforce Jobs: People Employed by Households, etc. (SA, Thous) | AN3: UK: Workforce Jobs: Total Services(SA, Thous) | AO3: UK: Job Vacancies Excluding Agriculture, Forestry & Fishing (NSA, Thous) | AP3: UK: LFS: Unemployed: Aged 16 & Over (SA, Thous) | AQ3: UK: LFS: Unemployment Rate: Aged 16 and Over (SA, %) | AR3: UK: LFS: ILO Redundancy Rate (SA, Per 1000 Employees) | AS3: UK: BoE Agents' Survey: Labor Market: Recruitment Difficulties (NSA, % Bal) | AT3: UK: BCC Survey: Manufacturing: Recruitment Difficulties (% of Cos) | AU3: UK: BCC Survey: Service: Recruitment Difficulties (% of Cos) | AV3: UK: LFS: Unemployed: Aged 16 & Over: Over 12 Months (SA, Thous) | AW3: UK: LFS: Working Age Population: Age 16 & Over (NSA, Thous) | AX3: UK: LFS: Economic Activity Rate: Aged 16 and Over (SA, %) | AY3: UK: LFS: Employment Rate: Aged 16 to 64 (SA, %) | AZ3: UK: LFS: Average Actual Weekly Hours Worked: All Workers (SA, Hours) | BA3: Great Britain: AWE, Total Pay: Private Sector (SA, GBP) | BB3: UK: LFS: Employment: Aged 16 and Over (SA, Thous) | BC3: UK: LFS: Employees (SA, Thous) | BD3: UK: Paid Employees: PAYE Real Time Information [RTI] (SA, Number) | BE3: UK: Workforce Jobs: Employees (SA, Thous) | BF3: UK: LFS: Part-Time Workers: Couldn't Find Full-Time Job (SA, Thous) | BG3: UK: LFS: Economically Inactive: Wants a Job (SA, Thous) | BH3: UK: LFS: Unemployed: Aged 16 & Over (SA, Thous)
A4: .T1 | B4: Q2-1991 | C4: Q1-1999 | D4: Q1-1999 | E4: Q1-1999 | F4: Q1-1999 | G4: Q1-1999 | H4: Q1-1999 | I4: Q1-1999 | J4: Q1-1999 | K4: Q1-1999 | L4: Q1-1999 | M4: Q1-1999 | N4: Q1-1999 | O4: Q1-1999 | P4: Q1-1999 | Q4: Q1-1999 | R4: Q1-1999 | S4: Q2-1959 | T4: Q2-1978 | U4: Q2-1978 | V4: Q2-1978 | W4: Q2-1978 | X4: Q2-1978 | Y4: Q2-1978 | Z4: Q2-1978 | AA4: Q2-1978 | AB4: Q2-1978 | AC4: Q2-1978 | AD4: Q2-1978 | AE4: Q2-1978 | AF4: Q2-1978 | AG4: Q2-1978 | AH4: Q2-1978 | AI4: Q2-1978 | AJ4: Q2-1978 | AK4: Q2-1978 | AL4: Q2-1978 | AM4: Q2-1978 | AN4: Q2-1978 | AO4: Q2-2001 <- Apr-2001 | AP4: Q1-1971 | AQ4: Q1-1971 | AR4: Q2-1995 | AS4: Q1-2005 <- Jan-2005 | AT4: Q1-1989 | AU4: Q1-1989 | AV4: Q2-1992 | AW4: Q1-1971 | AX4: Q1-1971 | AY4: Q1-1971 | AZ4: Q2-1992 | BA4: Q1-2000 <- Jan-2000 | BB4: Q1-1971 | BC4: Q2-1992 | BD4: Q3-2014 <- Jul-2014 | BE4: Q2-1959 | BF4: Q2-1992 | BG4: Q2-1992 | BH4: Q1-1971
A5: .TN | B5: Q3-2024 | C5: Q3-2024 | D5: Q3-2024 | E5: Q3-2024 | F5: Q3-2024 | G5: Q3-2024 | H5: Q3-2024 | I5: Q3-2024 | J5: Q3-2024 | K5: Q3-2024 | L5: Q3-2024 | M5: Q3-2024 | N5: Q3-2024 | O5: Q3-2024 | P5: Q3-2024 | Q5: Q3-2024 | R5: Q3-2024 | S5: Q3-2024 | T5: Q3-2024 | U5: Q3-2024 | V5: Q3-2024 | W5: Q3-2024 | X5: Q3-2024 | Y5: Q3-2024 | Z5: Q3-2024 | AA5: Q3-2024 | AB5: Q3-2024 | AC5: Q3-2024 | AD5: Q3-2024 | AE5: Q3-2024 | AF5: Q3-2024 | AG5: Q3-2024 | AH5: Q3-2024 | AI5: Q3-2024 | AJ5: Q3-2024 | AK5: Q3-2024 | AL5: Q3-2024 | AM5: Q3-2024 | AN5: Q3-2024 | AO5: Q4-2024 <- Dec-2024 | AP5: Q3-2024 | AQ5: Q3-2024 | AR5: Q3-2024 | AS5: Q3-2024 <- Nov-2024 | AT5: Q4-2024 | AU5: Q4-2024 | AV5: Q3-2024 | AW5: Q3-2024 | AX5: Q3-2024 | AY5: Q3-2024 | AZ5: Q3-2024 | BA5: Q3-2024 <- Nov-2024 | BB5: Q3-2024 | BC5: Q3-2024 | BD5: Q4-2024 <- Dec-2024 | BE5: Q3-2024 | BF5: Q3-2024 | BG5: Q3-2024 | BH5: Q3-2024
A6: .LSOURCE | B6: Office for National Statistics | C6: Office for National Statistics | D6: Office for National Statistics | E6: Office for National Statistics | F6: Office for National Statistics | G6: Office for National Statistics | H6: Office for National Statistics | I6: Office for National Statistics | J6: Office for National Statistics | K6: Office for National Statistics | L6: Office for National Statistics | M6: Office for National Statistics | N6: Office for National Statistics | O6: Office for National Statistics | P6: Office for National Statistics | Q6: Office for National Statistics | R6: Office for National Statistics | S6: Office for National Statistics | T6: Office for National Statistics | U6: Office for National Statistics | V6: Office for National Statistics | W6: Office for National Statistics | X6: Office for National Statistics | Y6: Office for National Statistics | Z6: Office for National Statistics | AA6: Office for National Statistics | AB6: Office for National Statistics | AC6: Office for National Statistics | AD6: Office for National Statistics | AE6: Office for National Statistics | AF6: Office for National Statistics | AG6: Office for National Statistics | AH6: Office for National Statistics | AI6: Office for National Statistics | AJ6: Office for National Statistics | AK6: Office for National Statistics | AL6: Office for National Statistics | AM6: Office for National Statistics | AN6: Office for National Statistics | AO6: Office for National Statistics | AP6: Office for National Statistics | AQ6: Office for National Statistics | AR6: Office for National Statistics | AS6: Bank of England | AT6: The British Chambers of Commerce | AU6: The British Chambers of Commerce | AV6: Office for National Statistics | AW6: Office for National Statistics | AX6: Office for National Statistics | AY6: Office for National Statistics | AZ6: Office for National Statistics | BA6: Office for National Statistics | BB6: Office for National Statistics | BC6: Office for National Statistics | BD6: Office for National Statistics | BE6: Office for National Statistics | BF6: Office for National Statistics | BG6: Office for National Statistics | BH6: Office for National Statistics
A7: .DTLM | B7: Dec-17-2024 07:20 | C7: Dec-17-2024 07:20 | D7: Dec-17-2024 07:20 | E7: Dec-17-2024 07:20 | F7: Dec-17-2024 07:20 | G7: Dec-17-2024 07:20 | H7: Dec-17-2024 07:20 | I7: Dec-17-2024 07:20 | J7: Dec-17-2024 07:20 | K7: Dec-17-2024 07:20 | L7: Dec-17-2024 07:20 | M7: Dec-17-2024 07:04 | N7: Dec-17-2024 07:20 | O7: Dec-17-2024 07:20 | P7: Dec-17-2024 07:20 | Q7: Dec-17-2024 07:20 | R7: Dec-17-2024 07:20 | S7: Dec-17-2024 07:20 | T7: Dec-17-2024 07:20 | U7: Dec-17-2024 07:20 | V7: Dec-17-2024 07:20 | W7: Dec-17-2024 07:20 | X7: Dec-17-2024 07:20 | Y7: Dec-17-2024 07:20 | Z7: Dec-17-2024 07:20 | AA7: Dec-17-2024 07:20 | AB7: Dec-17-2024 07:20 | AC7: Dec-17-2024 07:20 | AD7: Dec-17-2024 07:20 | AE7: Dec-17-2024 07:20 | AF7: Dec-17-2024 07:20 | AG7: Dec-17-2024 07:20 | AH7: Dec-17-2024 07:20 | AI7: Dec-17-2024 07:20 | AJ7: Dec-17-2024 07:20 | AK7: Dec-17-2024 07:20 | AL7: Dec-17-2024 07:20 | AM7: Dec-17-2024 07:20 | AN7: Dec-17-2024 07:20 | AO7: Jan-21-2025 07:04 | AP7: Dec-17-2024 07:18 | AQ7: Dec-17-2024 07:20 | AR7: Dec-17-2024 07:20 | AS7: Dec-19-2024 12:02 | AT7: Jan-06-2025 00:01 | AU7: Jan-06-2025 00:01 | AV7: Dec-17-2024 07:20 | AW7: Dec-17-2024 07:20 | AX7: Dec-17-2024 07:20 | AY7: Dec-17-2024 07:20 | AZ7: Dec-17-2024 07:20 | BA7: Jan-21-2025 07:03 | BB7: Dec-17-2024 07:20 | BC7: Dec-17-2024 07:20 | BD7: Jan-21-2025 07:04 | BE7: Dec-17-2024 07:20 | BF7: Dec-17-2024 07:20 | BG7: Dec-17-2024 07:20 | BH7: Dec-17-2024 07:18
A8: 19801 | B8: #N/A | C8: #N/A | D8: #N/A | E8: #N/A | F8: #N/A | G8: #N/A | H8: #N/A | I8: #N/A | J8: #N/A | K8: #N/A | L8: #N/A | M8: #N/A | N8: #N/A | O8: #N/A | P8: #N/A | Q8: #N/A | R8: #N/A | S8: 27465 | T8: 509 | U8: 373 | V8: 6541 | W8: 259 | X8: 156 | Y8: 1962 | Z8: 4153 | AA8: 1408 | AB8: 1257 | AC8: 791 | AD8: 853 | AE8: 176 | AF8: 1023 | AG8: 1120 | AH8: 1992 | AI8: 1747 | AJ8: 2025 | AK8: 510 | AL8: 610 | AM8: 0 | AN8: 17664 | AO8: #N/A | AP8: 1558 | AQ8: 5.8 | AR8: #N/A | AS8: #N/A | AT8: #N/A | AU8: #N/A | AV8: #N/A | AW8: 42610 | AX8: 62.9 | AY8: 71.5 | AZ8: #N/A | BA8: #N/A | BB8: 25250 | BC8: #N/A | BD8: #N/A | BE8: 25010 | BF8: #N/A | BG8: #N/A | BH8: 1558
A9: 19802 | B9: #N/A | C9: #N/A | D9: #N/A | E9: #N/A | F9: #N/A | G9: #N/A | H9: #N/A | I9: #N/A | J9: #N/A | K9: #N/A | L9: #N/A | M9: #N/A | N9: #N/A | O9: #N/A | P9: #N/A | Q9: #N/A | R9: #N/A | S9: 27369 | T9: 510 | U9: 368 | V9: 6423 | W9: 260 | X9: 155 | Y9: 1962 | Z9: 4151 | AA9: 1406 | AB9: 1265 | AC9: 787 | AD9: 860 | AE9: 177 | AF9: 1031 | AG9: 1126 | AH9: 1983 | AI9: 1740 | AJ9: 2044 | AK9: 510 | AL9: 611 | AM9: 0 | AN9: 17691 | AO9: #N/A | AP9: 1700 | AQ9: 6.3 | AR9: #N/A | AS9: #N/A | AT9: #N/A | AU9: #N/A | AV9: #N/A | AW9: 42699 | AX9: 63 | AY9: 71.2 | AZ9: #N/A | BA9: #N/A | BB9: 25190 | BC9: #N/A | BD9: #N/A | BE9: 24879 | BF9: #N/A | BG9: #N/A | BH9: 1700
A10: 19803 | B10: #N/A | C10: #N/A | D10: #N/A | E10: #N/A | F10: #N/A | G10: #N/A | H10: #N/A | I10: #N/A | J10: #N/A | K10: #N/A | L10: #N/A | M10: #N/A | N10: #N/A | O10: #N/A | P10: #N/A | Q10: #N/A | R10: #N/A | S10: 27108 | T10: 513 | U10: 365 | V10: 6228 | W10: 262 | X10: 155 | Y10: 1951 | Z10: 4096 | AA10: 1398 | AB10: 1258 | AC10: 777 | AD10: 874 | AE10: 177 | AF10: 1029 | AG10: 1122 | AH10: 1984 | AI10: 1740 | AJ10: 2058 | AK10: 510 | AL10: 611 | AM10: 0 | AN10: 17634 | AO10: #N/A | AP10: 1905 | AQ10: 7.1 | AR10: #N/A | AS10: #N/A | AT10: #N/A | AU10: #N/A | AV10: #N/A | AW10: 42784 | AX10: 63 | AY10: 70.7 | AZ10: #N/A | BA10: #N/A | BB10: 25050 | BC10: #N/A | BD10: #N/A | BE10: 24581 | BF10: #N/A | BG10: #N/A | BH10: 1905
A11: 19804 | B11: #N/A | C11: #N/A | D11: #N/A | E11: #N/A | F11: #N/A | G11: #N/A | H11: #N/A | I11: #N/A | J11: #N/A | K11: #N/A | L11: #N/A | M11: #N/A | N11: #N/A | O11: #N/A | P11: #N/A | Q11: #N/A | R11: #N/A | S11: 26813 | T11: 503 | U11: 359 | V11: 6045 | W11: 261 | X11: 154 | Y11: 1921 | Z11: 4055 | AA11: 1384 | AB11: 1261 | AC11: 767 | AD11: 876 | AE11: 177 | AF11: 1027 | AG11: 1114 | AH11: 1979 | AI11: 1723 | AJ11: 2077 | AK11: 514 | AL11: 615 | AM11: 0 | AN11: 17570 | AO11: #N/A | AP11: 2169 | AQ11: 8 | AR11: #N/A | AS11: #N/A | AT11: #N/A | AU11: #N/A | AV11: #N/A | AW11: 42862 | AX11: 63.1 | AY11: 69.9 | AZ11: #N/A | BA11: #N/A | BB11: 24855 | BC11: #N/A | BD11: #N/A | BE11: 24254 | BF11: #N/A | BG11: #N/A | BH11: 2169
A12: 19811 | B12: #N/A | C12: #N/A | D12: #N/A | E12: #N/A | F12: #N/A | G12: #N/A | H12: #N/A | I12: #N/A | J12: #N/A | K12: #N/A | L12: #N/A | M12: #N/A | N12: #N/A | O12: #N/A | P12: #N/A | Q12: #N/A | R12: #N/A | S12: 26551 | T12: 503 | U12: 349 | V12: 5901 | W12: 259 | X12: 152 | Y12: 1893 | Z12: 4038 | AA12: 1369 | AB12: 1250 | AC12: 757 | AD12: 879 | AE12: 177 | AF12: 1024 | AG12: 1107 | AH12: 1968 | AI12: 1712 | AJ12: 2090 | AK12: 511 | AL12: 613 | AM12: 0 | AN12: 17494 | AO12: #N/A | AP12: 2403 | AQ12: 8.9 | AR12: #N/A | AS12: #N/A | AT12: #N/A | AU12: #N/A | AV12: #N/A | AW12: 42940 | AX12: 63 | AY12: 69.3 | AZ12: #N/A | BA12: #N/A | BB12: 24661 | BC12: #N/A | BD12: #N/A | BE12: 23962 | BF12: #N/A | BG12: #N/A | BH12: 2403
A13: 19812 | B13: #N/A | C13: #N/A | D13: #N/A | E13: #N/A | F13: #N/A | G13: #N/A | H13: #N/A | I13: #N/A | J13: #N/A | K13: #N/A | L13: #N/A | M13: #N/A | N13: #N/A | O13: #N/A | P13: #N/A | Q13: #N/A | R13: #N/A | S13: 26348 | T13: 492 | U13: 347 | V13: 5789 | W13: 257 | X13: 150 | Y13: 1863 | Z13: 4035 | AA13: 1359 | AB13: 1234 | AC13: 751 | AD13: 878 | AE13: 177 | AF13: 1025 | AG13: 1101 | AH13: 1958 | AI13: 1715 | AJ13: 2098 | AK13: 508 | AL13: 611 | AM13: 0 | AN13: 17450 | AO13: #N/A | AP13: 2588 | AQ13: 9.6 | AR13: #N/A | AS13: #N/A | AT13: #N/A | AU13: #N/A | AV13: #N/A | AW13: 43017 | AX13: 63 | AY13: 68.7 | AZ13: #N/A | BA13: #N/A | BB13: 24495 | BC13: #N/A | BD13: #N/A | BE13: 23728 | BF13: #N/A | BG13: #N/A | BH13: 2588
A14: 19813 | B14: #N/A | C14: #N/A | D14: #N/A | E14: #N/A | F14: #N/A | G14: #N/A | H14: #N/A | I14: #N/A | J14: #N/A | K14: #N/A | L14: #N/A | M14: #N/A | N14: #N/A | O14: #N/A | P14: #N/A | Q14: #N/A | R14: #N/A | S14: 26240 | T14: 485 | U14: 343 | V14: 5714 | W14: 257 | X14: 149 | Y14: 1829 | Z14: 4040 | AA14: 1352 | AB14: 1244 | AC14: 745 | AD14: 874 | AE14: 178 | AF14: 1033 | AG14: 1106 | AH14: 1947 | AI14: 1715 | AJ14: 2111 | AK14: 508 | AL14: 610 | AM14: 0 | AN14: 17463 | AO14: #N/A | AP14: 2684 | AQ14: 9.9 | AR14: #N/A | AS14: #N/A | AT14: #N/A | AU14: #N/A | AV14: #N/A | AW14: 43084 | AX14: 62.8 | AY14: 68.2 | AZ14: #N/A | BA14: #N/A | BB14: 24355 | BC14: #N/A | BD14: #N/A | BE14: 23605 | BF14: #N/A | BG14: #N/A | BH14: 2684
A15: 19814 | B15: #N/A | C15: #N/A | D15: #N/A | E15: #N/A | F15: #N/A | G15: #N/A | H15: #N/A | I15: #N/A | J15: #N/A | K15: #N/A | L15: #N/A | M15: #N/A | N15: #N/A | O15: #N/A | P15: #N/A | Q15: #N/A | R15: #N/A | S15: 26046 | T15: 484 | U15: 338 | V15: 5628 | W15: 254 | X15: 148 | Y15: 1801 | Z15: 3993 | AA15: 1339 | AB15: 1260 | AC15: 742 | AD15: 875 | AE15: 178 | AF15: 1031 | AG15: 1106 | AH15: 1938 | AI15: 1708 | AJ15: 2103 | AK15: 510 | AL15: 612 | AM15: 0 | AN15: 17394 | AO15: #N/A | AP15: 2761 | AQ15: 10.2 | AR15: #N/A | AS15: #N/A | AT15: #N/A | AU15: #N/A | AV15: #N/A | AW15: 43130 | AX15: 62.5 | AY15: 67.7 | AZ15: #N/A | BA15: #N/A | BB15: 24209 | BC15: #N/A | BD15: #N/A | BE15: 23402 | BF15: #N/A | BG15: #N/A | BH15: 2761
A16: 19821 | B16: #N/A | C16: #N/A | D16: #N/A | E16: #N/A | F16: #N/A | G16: #N/A | H16: #N/A | I16: #N/A | J16: #N/A | K16: #N/A | L16: #N/A | M16: #N/A | N16: #N/A | O16: #N/A | P16: #N/A | Q16: #N/A | R16: #N/A | S16: 25997 | T16: 484 | U16: 334 | V16: 5570 | W16: 250 | X16: 148 | Y16: 1800 | Z16: 3989 | AA16: 1333 | AB16: 1271 | AC16: 740 | AD16: 874 | AE16: 179 | AF16: 1034 | AG16: 1111 | AH16: 1921 | AI16: 1707 | AJ16: 2122 | AK16: 514 | AL16: 616 | AM16: 0 | AN16: 17411 | AO16: #N/A | AP16: 2803 | AQ16: 10.4 | AR16: #N/A | AS16: #N/A | AT16: #N/A | AU16: #N/A | AV16: #N/A | AW16: 43176 | AX16: 62.4 | AY16: 67.4 | AZ16: #N/A | BA16: #N/A | BB16: 24120 | BC16: #N/A | BD16: #N/A | BE16: 23343 | BF16: #N/A | BG16: #N/A | BH16: 2803
A17: 19822 | B17: #N/A | C17: #N/A | D17: #N/A | E17: #N/A | F17: #N/A | G17: #N/A | H17: #N/A | I17: #N/A | J17: #N/A | K17: #N/A | L17: #N/A | M17: #N/A | N17: #N/A | O17: #N/A | P17: #N/A | Q17: #N/A | R17: #N/A | S17: 25900 | T17: 488 | U17: 329 | V17: 5472 | W17: 248 | X17: 146 | Y17: 1809 | Z17: 3975 | AA17: 1325 | AB17: 1268 | AC17: 739 | AD17: 873 | AE17: 181 | AF17: 1048 | AG17: 1119 | AH17: 1916 | AI17: 1706 | AJ17: 2129 | AK17: 514 | AL17: 617 | AM17: 0 | AN17: 17409 | AO17: #N/A | AP17: 2841 | AQ17: 10.6 | AR17: #N/A | AS17: #N/A | AT17: #N/A | AU17: #N/A | AV17: #N/A | AW17: 43222 | AX17: 62.2 | AY17: 67.1 | AZ17: #N/A | BA17: #N/A | BB17: 24027 | BC17: #N/A | BD17: #N/A | BE17: 23237 | BF17: #N/A | BG17: #N/A | BH17: 2841
A18: 19823 | B18: #N/A | C18: #N/A | D18: #N/A | E18: #N/A | F18: #N/A | G18: #N/A | H18: #N/A | I18: #N/A | J18: #N/A | K18: #N/A | L18: #N/A | M18: #N/A | N18: #N/A | O18: #N/A | P18: #N/A | Q18: #N/A | R18: #N/A | S18: 25779 | T18: 485 | U18: 325 | V18: 5381 | W18: 246 | X18: 145 | Y18: 1803 | Z18: 3952 | AA18: 1312 | AB18: 1256 | AC18: 730 | AD18: 884 | AE18: 181 | AF18: 1049 | AG18: 1116 | AH18: 1910 | AI18: 1710 | AJ18: 2168 | AK18: 513 | AL18: 614 | AM18: 0 | AN18: 17394 | AO18: #N/A | AP18: 2897 | AQ18: 10.8 | AR18: #N/A | AS18: #N/A | AT18: #N/A | AU18: #N/A | AV18: #N/A | AW18: 43274 | AX18: 61.9 | AY18: 66.6 | AZ18: #N/A | BA18: #N/A | BB18: 23901 | BC18: #N/A | BD18: #N/A | BE18: 23105 | BF18: #N/A | BG18: #N/A | BH18: 2897
A19: 19824 | B19: #N/A | C19: #N/A | D19: #N/A | E19: #N/A | F19: #N/A | G19: #N/A | H19: #N/A | I19: #N/A | J19: #N/A | K19: #N/A | L19: #N/A | M19: #N/A | N19: #N/A | O19: #N/A | P19: #N/A | Q19: #N/A | R19: #N/A | S19: 25588 | T19: 493 | U19: 320 | V19: 5287 | W19: 243 | X19: 144 | Y19: 1800 | Z19: 3914 | AA19: 1307 | AB19: 1231 | AC19: 729 | AD19: 888 | AE19: 181 | AF19: 1049 | AG19: 1122 | AH19: 1907 | AI19: 1706 | AJ19: 2136 | AK19: 515 | AL19: 617 | AM19: 0 | AN19: 17301 | AO19: #N/A | AP19: 2960 | AQ19: 11.1 | AR19: #N/A | AS19: #N/A | AT19: #N/A | AU19: #N/A | AV19: #N/A | AW19: 43337 | AX19: 61.6 | AY19: 66.1 | AZ19: #N/A | BA19: #N/A | BB19: 23755 | BC19: #N/A | BD19: #N/A | BE19: 22903 | BF19: #N/A | BG19: #N/A | BH19: 2960
... A43: 19884 | B43: #N/A | C43: #N/A | D43: #N/A | E43: #N/A | F43: #N/A | G43: #N/A | H43: #N/A | I43: #N/A | J43: #N/A | K43: #N/A | L43: #N/A | M43: #N/A | N43: #N/A | O43: #N/A | P43: #N/A | Q43: #N/A | R43: #N/A | S43: 28644 | T43: 518 | U43: 176 | V43: 5033 | W43: 211 | X43: 145 | Y43: 2114 | Z43: 4484 | AA43: 1331 | AB43: 1558 | AC43: 822 | AD43: 1145 | AE43: 252 | AF43: 1445 | AG43: 1462 | AH43: 1802 | AI43: 2007 | AJ43: 2717 | AK43: 633 | AL43: 789 | AM43: 0 | AN43: 20447 | AO43: #N/A | AP43: 2293 | AQ43: 8 | AR43: #N/A | AS43: #N/A | AT43: #N/A | AU43: #N/A | AV43: #N/A | AW43: 44676 | AX43: 64.1 | AY43: 71.5 | AZ43: #N/A | BA43: #N/A | BB43: 26355 | BC43: #N/A | BD43: #N/A | BE43: 24547 | BF43: #N/A | BG43: #N/A | BH43: 2293
A44: 19891 | B44: #N/A | C44: #N/A | D44: #N/A | E44: #N/A | F44: #N/A | G44: #N/A | H44: #N/A | I44: #N/A | J44: #N/A | K44: #N/A | L44: #N/A | M44: #N/A | N44: #N/A | O44: #N/A | P44: #N/A | Q44: #N/A | R44: #N/A | S44: 28955 | T44: 521 | U44: 172 | V44: 5037 | W44: 210 | X44: 145 | Y44: 2152 | Z44: 4556 | AA44: 1339 | AB44: 1603 | AC44: 831 | AD44: 1158 | AE44: 256 | AF44: 1467 | AG44: 1485 | AH44: 1789 | AI44: 2029 | AJ44: 2754 | AK44: 643 | AL44: 805 | AM44: 0 | AN44: 20717 | AO44: #N/A | AP44: 2179 | AQ44: 7.6 | AR44: #N/A | AS44: #N/A | AT44: 64 | AU44: 58 | AV44: #N/A | AW44: 44713 | AX44: 64.3 | AY44: 72.1 | AZ44: #N/A | BA44: #N/A | BB44: 26590 | BC44: #N/A | BD44: #N/A | BE44: 24729 | BF44: #N/A | BG44: #N/A | BH44: 2179
A45: 19892 | B45: #N/A | C45: #N/A | D45: #N/A | E45: #N/A | F45: #N/A | G45: #N/A | H45: #N/A | I45: #N/A | J45: #N/A | K45: #N/A | L45: #N/A | M45: #N/A | N45: #N/A | O45: #N/A | P45: #N/A | Q45: #N/A | R45: #N/A | S45: 29046 | T45: 517 | U45: 169 | V45: 5031 | W45: 206 | X45: 146 | Y45: 2195 | Z45: 4572 | AA45: 1360 | AB45: 1614 | AC45: 836 | AD45: 1160 | AE45: 260 | AF45: 1487 | AG45: 1499 | AH45: 1792 | AI45: 2037 | AJ45: 2715 | AK45: 643 | AL45: 808 | AM45: 0 | AN45: 20782 | AO45: #N/A | AP45: 2083 | AQ45: 7.2 | AR45: #N/A | AS45: #N/A | AT45: 63 | AU45: 56 | AV45: #N/A | AW45: 44750 | AX45: 64.4 | AY45: 72.4 | AZ45: #N/A | BA45: #N/A | BB45: 26730 | BC45: #N/A | BD45: #N/A | BE45: 24747 | BF45: #N/A | BG45: #N/A | BH45: 2083
A46: 19893 | B46: #N/A | C46: #N/A | D46: #N/A | E46: #N/A | F46: #N/A | G46: #N/A | H46: #N/A | I46: #N/A | J46: #N/A | K46: #N/A | L46: #N/A | M46: #N/A | N46: #N/A | O46: #N/A | P46: #N/A | Q46: #N/A | R46: #N/A | S46: 29152 | T46: 517 | U46: 164 | V46: 5043 | W46: 203 | X46: 147 | Y46: 2207 | Z46: 4585 | AA46: 1370 | AB46: 1635 | AC46: 836 | AD46: 1164 | AE46: 264 | AF46: 1509 | AG46: 1525 | AH46: 1797 | AI46: 2057 | AJ46: 2677 | AK46: 643 | AL46: 810 | AM46: 0 | AN46: 20870 | AO46: #N/A | AP46: 2045 | AQ46: 7.1 | AR46: #N/A | AS46: #N/A | AT46: 66 | AU46: 62 | AV46: #N/A | AW46: 44782 | AX46: 64.4 | AY46: 72.6 | AZ46: #N/A | BA46: #N/A | BB46: 26795 | BC46: #N/A | BD46: #N/A | BE46: 24855 | BF46: #N/A | BG46: #N/A | BH46: 2045
A47: 19894 | B47: #N/A | C47: #N/A | D47: #N/A | E47: #N/A | F47: #N/A | G47: #N/A | H47: #N/A | I47: #N/A | J47: #N/A | K47: #N/A | L47: #N/A | M47: #N/A | N47: #N/A | O47: #N/A | P47: #N/A | Q47: #N/A | R47: #N/A | S47: 29267 | T47: 516 | U47: 163 | V47: 5011 | W47: 200 | X47: 147 | Y47: 2202 | Z47: 4613 | AA47: 1382 | AB47: 1663 | AC47: 842 | AD47: 1165 | AE47: 266 | AF47: 1522 | AG47: 1544 | AH47: 1815 | AI47: 2064 | AJ47: 2718 | AK47: 634 | AL47: 801 | AM47: 0 | AN47: 21028 | AO47: #N/A | AP47: 2021 | AQ47: 7 | AR47: #N/A | AS47: #N/A | AT47: 60 | AU47: 53 | AV47: #N/A | AW47: 44805 | AX47: 64.5 | AY47: 72.8 | AZ47: #N/A | BA47: #N/A | BB47: 26880 | BC47: #N/A | BD47: #N/A | BE47: 24969 | BF47: #N/A | BG47: #N/A | BH47: 2021
A48: 19901 | B48: #N/A | C48: #N/A | D48: #N/A | E48: #N/A | F48: #N/A | G48: #N/A | H48: #N/A | I48: #N/A | J48: #N/A | K48: #N/A | L48: #N/A | M48: #N/A | N48: #N/A | O48: #N/A | P48: #N/A | Q48: #N/A | R48: #N/A | S48: 29291 | T48: 516 | U48: 161 | V48: 4963 | W48: 197 | X48: 146 | Y48: 2212 | Z48: 4618 | AA48: 1388 | AB48: 1669 | AC48: 844 | AD48: 1170 | AE48: 267 | AF48: 1533 | AG48: 1556 | AH48: 1821 | AI48: 2060 | AJ48: 2736 | AK48: 633 | AL48: 800 | AM48: 0 | AN48: 21095 | AO48: #N/A | AP48: 2004 | AQ48: 6.9 | AR48: #N/A | AS48: #N/A | AT48: 67 | AU48: 60 | AV48: #N/A | AW48: 44829 | AX48: 64.5 | AY48: 72.8 | AZ48: #N/A | BA48: #N/A | BB48: 26900 | BC48: #N/A | BD48: #N/A | BE48: 25002 | BF48: #N/A | BG48: #N/A | BH48: 2004
A49: 19902 | B49: #N/A | C49: #N/A | D49: #N/A | E49: #N/A | F49: #N/A | G49: #N/A | H49: #N/A | I49: #N/A | J49: #N/A | K49: #N/A | L49: #N/A | M49: #N/A | N49: #N/A | O49: #N/A | P49: #N/A | Q49: #N/A | R49: #N/A | S49: 29370 | T49: 516 | U49: 159 | V49: 4925 | W49: 197 | X49: 145 | Y49: 2221 | Z49: 4645 | AA49: 1386 | AB49: 1675 | AC49: 847 | AD49: 1172 | AE49: 270 | AF49: 1549 | AG49: 1577 | AH49: 1827 | AI49: 2060 | AJ49: 2752 | AK49: 642 | AL49: 806 | AM49: 0 | AN49: 21208 | AO49: #N/A | AP49: 2002 | AQ49: 6.9 | AR49: #N/A | AS49: #N/A | AT49: 73 | AU49: 60 | AV49: #N/A | AW49: 44852 | AX49: 64.5 | AY49: 72.8 | AZ49: #N/A | BA49: #N/A | BB49: 26935 | BC49: #N/A | BD49: #N/A | BE49: 25061 | BF49: #N/A | BG49: #N/A | BH49: 2002
A50: 19903 | B50: #N/A | C50: #N/A | D50: #N/A | E50: #N/A | F50: #N/A | G50: #N/A | H50: #N/A | I50: #N/A | J50: #N/A | K50: #N/A | L50: #N/A | M50: #N/A | N50: #N/A | O50: #N/A | P50: #N/A | Q50: #N/A | R50: #N/A | S50: 29254 | T50: 509 | U50: 156 | V50: 4875 | W50: 196 | X50: 143 | Y50: 2199 | Z50: 4639 | AA50: 1388 | AB50: 1689 | AC50: 840 | AD50: 1180 | AE50: 269 | AF50: 1545 | AG50: 1571 | AH50: 1830 | AI50: 2034 | AJ50: 2750 | AK50: 640 | AL50: 801 | AM50: 0 | AN50: 21176 | AO50: #N/A | AP50: 2049 | AQ50: 7.1 | AR50: #N/A | AS50: #N/A | AT50: 62 | AU50: 55 | AV50: #N/A | AW50: 44875 | AX50: 64.5 | AY50: 72.7 | AZ50: #N/A | BA50: #N/A | BB50: 26900 | BC50: #N/A | BD50: #N/A | BE50: 25006 | BF50: #N/A | BG50: #N/A | BH50: 2049
A51: 19904 | B51: #N/A | C51: #N/A | D51: #N/A | E51: #N/A | F51: #N/A | G51: #N/A | H51: #N/A | I51: #N/A | J51: #N/A | K51: #N/A | L51: #N/A | M51: #N/A | N51: #N/A | O51: #N/A | P51: #N/A | Q51: #N/A | R51: #N/A | S51: 29046 | T51: 502 | U51: 152 | V51: 4768 | W51: 195 | X51: 140 | Y51: 2168 | Z51: 4608 | AA51: 1381 | AB51: 1694 | AC51: 833 | AD51: 1166 | AE51: 266 | AF51: 1531 | AG51: 1565 | AH51: 1829 | AI51: 2049 | AJ51: 2771 | AK51: 634 | AL51: 793 | AM51: 0 | AN51: 21121 | AO51: #N/A | AP51: 2158 | AQ51: 7.5 | AR51: #N/A | AS51: #N/A | AT51: 57 | AU51: 47 | AV51: #N/A | AW51: 44898 | AX51: 64.4 | AY51: 72.3 | AZ51: #N/A | BA51: #N/A | BB51: 26750 | BC51: #N/A | BD51: #N/A | BE51: 24847 | BF51: #N/A | BG51: #N/A | BH51: 2158
A52: 19911 | B52: #N/A | C52: #N/A | D52: #N/A | E52: #N/A | F52: #N/A | G52: #N/A | H52: #N/A | I52: #N/A | J52: #N/A | K52: #N/A | L52: #N/A | M52: #N/A | N52: #N/A | O52: #N/A | P52: #N/A | Q52: #N/A | R52: #N/A | S52: 28742 | T52: 501 | U52: 148 | V52: 4631 | W52: 193 | X52: 138 | Y52: 2120 | Z52: 4579 | AA52: 1367 | AB52: 1667 | AC52: 821 | AD52: 1160 | AE52: 264 | AF52: 1523 | AG52: 1565 | AH52: 1839 | AI52: 2042 | AJ52: 2783 | AK52: 623 | AL52: 778 | AM52: 0 | AN52: 21012 | AO52: #N/A | AP52: 2306 | AQ52: 8 | AR52: #N/A | AS52: #N/A | AT52: 32 | AU52: 36 | AV52: #N/A | AW52: 44920 | AX52: 64.2 | AY52: 71.7 | AZ52: #N/A | BA52: #N/A | BB52: 26530 | BC52: #N/A | BD52: #N/A | BE52: 24588 | BF52: #N/A | BG52: #N/A | BH52: 2306
A53: 19912 | B53: 5994 | C53: #N/A | D53: #N/A | E53: #N/A | F53: #N/A | G53: #N/A | H53: #N/A | I53: #N/A | J53: #N/A | K53: #N/A | L53: #N/A | M53: #N/A | N53: #N/A | O53: #N/A | P53: #N/A | Q53: #N/A | R53: #N/A | S53: 28445 | T53: 496 | U53: 145 | V53: 4509 | W53: 189 | X53: 138 | Y53: 2078 | Z53: 4553 | AA53: 1356 | AB53: 1636 | AC53: 811 | AD53: 1145 | AE53: 262 | AF53: 1509 | AG53: 1552 | AH53: 1837 | AI53: 2038 | AJ53: 2796 | AK53: 624 | AL53: 773 | AM53: 0 | AN53: 20891 | AO53: #N/A | AP53: 2492 | AQ53: 8.7 | AR53: #N/A | AS53: #N/A | AT53: 34 | AU53: 29 | AV53: #N/A | AW53: 44941 | AX53: 64 | AY53: 71 | AZ53: #N/A | BA53: #N/A | BB53: 26275 | BC53: #N/A | BD53: #N/A | BE53: 24362 | BF53: #N/A | BG53: #N/A | BH53: 2492
A54: 19913 | B54: #N/A | C54: #N/A | D54: #N/A | E54: #N/A | F54: #N/A | G54: #N/A | H54: #N/A | I54: #N/A | J54: #N/A | K54: #N/A | L54: #N/A | M54: #N/A | N54: #N/A | O54: #N/A | P54: #N/A | Q54: #N/A | R54: #N/A | S54: 28265 | T54: 491 | U54: 142 | V54: 4432 | W54: 185 | X54: 137 | Y54: 2039 | Z54: 4556 | AA54: 1349 | AB54: 1619 | AC54: 804 | AD54: 1138 | AE54: 261 | AF54: 1507 | AG54: 1546 | AH54: 1842 | AI54: 2015 | AJ54: 2805 | AK54: 625 | AL54: 771 | AM54: 0 | AN54: 20840 | AO54: #N/A | AP54: 2624 | AQ54: 9.2 | AR54: #N/A | AS54: #N/A | AT54: 27 | AU54: 20 | AV54: #N/A | AW54: 44958 | AX54: 63.7 | AY54: 70.3 | AZ54: #N/A | BA54: #N/A | BB54: 26025 | BC54: #N/A | BD54: #N/A | BE54: 24226 | BF54: #N/A | BG54: #N/A | BH54: 2624
A55: 19914 | B55: #N/A | C55: #N/A | D55: #N/A | E55: #N/A | F55: #N/A | G55: #N/A | H55: #N/A | I55: #N/A | J55: #N/A | K55: #N/A | L55: #N/A | M55: #N/A | N55: #N/A | O55: #N/A | P55: #N/A | Q55: #N/A | R55: #N/A | S55: 28129 | T55: 494 | U55: 133 | V55: 4379 | W55: 179 | X55: 140 | Y55: 2011 | Z55: 4541 | AA55: 1345 | AB55: 1581 | AC55: 802 | AD55: 1126 | AE55: 260 | AF55: 1501 | AG55: 1547 | AH55: 1848 | AI55: 2017 | AJ55: 2821 | AK55: 629 | AL55: 774 | AM55: 0 | AN55: 20793 | AO55: #N/A | AP55: 2697 | AQ55: 9.5 | AR55: #N/A | AS55: #N/A | AT55: 33 | AU55: 33 | AV55: #N/A | AW55: 44975 | AX55: 63.4 | AY55: 69.8 | AZ55: #N/A | BA55: #N/A | BB55: 25820 | BC55: #N/A | BD55: #N/A | BE55: 24101 | BF55: #N/A | BG55: #N/A | BH55: 2697
A56: 19921 | B56: #N/A | C56: #N/A | D56: #N/A | E56: #N/A | F56: #N/A | G56: #N/A | H56: #N/A | I56: #N/A | J56: #N/A | K56: #N/A | L56: #N/A | M56: #N/A | N56: #N/A | O56: #N/A | P56: #N/A | Q56: #N/A | R56: #N/A | S56: 28124 | T56: 496 | U56: 125 | V56: 4327 | W56: 174 | X56: 144 | Y56: 1983 | Z56: 4561 | AA56: 1343 | AB56: 1596 | AC56: 800 | AD56: 1113 | AE56: 261 | AF56: 1505 | AG56: 1551 | AH56: 1848 | AI56: 2030 | AJ56: 2853 | AK56: 636 | AL56: 779 | AM56: 0 | AN56: 20874 | AO56: #N/A | AP56: 2762 | AQ56: 9.7 | AR56: #N/A | AS56: #N/A | AT56: 24 | AU56: 22 | AV56: #N/A | AW56: 44992 | AX56: 63.3 | AY56: 69.4 | AZ56: #N/A | BA56: #N/A | BB56: 25710 | BC56: #N/A | BD56: #N/A | BE56: 24099 | BF56: #N/A | BG56: #N/A | BH56: 2762
A57: 19922 | B57: 5919 | C57: #N/A | D57: #N/A | E57: #N/A | F57: #N/A | G57: #N/A | H57: #N/A | I57: #N/A | J57: #N/A | K57: #N/A | L57: #N/A | M57: #N/A | N57: #N/A | O57: #N/A | P57: #N/A | Q57: #N/A | R57: #N/A | S57: 27966 | T57: 493 | U57: 121 | V57: 4286 | W57: 168 | X57: 146 | Y57: 1953 | Z57: 4524 | AA57: 1326 | AB57: 1607 | AC57: 796 | AD57: 1111 | AE57: 261 | AF57: 1506 | AG57: 1549 | AH57: 1839 | AI57: 2009 | AJ57: 2861 | AK57: 635 | AL57: 775 | AM57: 0 | AN57: 20800 | AO57: #N/A | AP57: 2777 | AQ57: 9.8 | AR57: #N/A | AS57: #N/A | AT57: 23 | AU57: 23 | AV57: 1005 | AW57: 44996 | AX57: 63.1 | AY57: 69.1 | AZ57: 33.2 | BA57: #N/A | BB57: 25605 | BC57: 21576 | BD57: #N/A | BE57: 23970 | BF57: 663 | BG57: 1985 | BH57: 2777
A58: 19923 | B58: #N/A | C58: #N/A | D58: #N/A | E58: #N/A | F58: #N/A | G58: #N/A | H58: #N/A | I58: #N/A | J58: #N/A | K58: #N/A | L58: #N/A | M58: #N/A | N58: #N/A | O58: #N/A | P58: #N/A | Q58: #N/A | R58: #N/A | S58: 27542 | T58: 491 | U58: 117 | V58: 4192 | W58: 166 | X58: 147 | Y58: 1915 | Z58: 4438 | AA58: 1291 | AB58: 1576 | AC58: 782 | AD58: 1089 | AE58: 259 | AF58: 1500 | AG58: 1534 | AH58: 1826 | AI58: 1990 | AJ58: 2839 | AK58: 628 | AL58: 764 | AM58: 0 | AN58: 20515 | AO58: #N/A | AP58: 2815 | AQ58: 9.9 | AR58: #N/A | AS58: #N/A | AT58: 28 | AU58: 28 | AV58: 1088 | AW58: 45003 | AX58: 62.9 | AY58: 68.9 | AZ58: 33 | BA58: #N/A | BB58: 25509 | BC58: 21551 | BD58: #N/A | BE58: 23599 | BF58: 709 | BG58: 1996 | BH58: 2815
A59: 19924 | B59: #N/A | C59: #N/A | D59: #N/A | E59: #N/A | F59: #N/A | G59: #N/A | H59: #N/A | I59: #N/A | J59: #N/A | K59: #N/A | L59: #N/A | M59: #N/A | N59: #N/A | O59: #N/A | P59: #N/A | Q59: #N/A | R59: #N/A | S59: 27417 | T59: 487 | U59: 108 | V59: 4104 | W59: 160 | X59: 149 | Y59: 1883 | Z59: 4439 | AA59: 1290 | AB59: 1583 | AC59: 780 | AD59: 1077 | AE59: 259 | AF59: 1500 | AG59: 1543 | AH59: 1815 | AI59: 1990 | AJ59: 2855 | AK59: 632 | AL59: 765 | AM59: 0 | AN59: 20526 | AO59: #N/A | AP59: 2932 | AQ59: 10.4 | AR59: #N/A | AS59: #N/A | AT59: 34 | AU59: 26 | AV59: 1176 | AW59: 45010 | AX59: 62.8 | AY59: 68.5 | AZ59: 32.9 | BA59: #N/A | BB59: 25336 | BC59: 21429 | BD59: #N/A | BE59: 23532 | BF59: 732 | BG59: 2013 | BH59: 2932
A60: 19931 | B60: #N/A | C60: #N/A | D60: #N/A | E60: #N/A | F60: #N/A | G60: #N/A | H60: #N/A | I60: #N/A | J60: #N/A | K60: #N/A | L60: #N/A | M60: #N/A | N60: #N/A | O60: #N/A | P60: #N/A | Q60: #N/A | R60: #N/A | S60: 27533 | T60: 503 | U60: 102 | V60: 4105 | W60: 156 | X60: 151 | Y60: 1872 | Z60: 4473 | AA60: 1291 | AB60: 1580 | AC60: 787 | AD60: 1076 | AE60: 263 | AF60: 1523 | AG60: 1567 | AH60: 1802 | AI60: 1994 | AJ60: 2866 | AK60: 645 | AL60: 779 | AM60: 0 | AN60: 20644 | AO60: #N/A | AP60: 3004 | AQ60: 10.6 | AR60: #N/A | AS60: #N/A | AT60: 32 | AU60: 28 | AV60: 1243 | AW60: 45016 | AX60: 62.8 | AY60: 68.4 | AZ60: 33 | BA60: #N/A | BB60: 25282 | BC60: 21388 | BD60: #N/A | BE60: 23549 | BF60: 782 | BG60: 2050 | BH60: 3004
A61: 19932 | B61: 5820 | C61: #N/A | D61: #N/A | E61: #N/A | F61: #N/A | G61: #N/A | H61: #N/A | I61: #N/A | J61: #N/A | K61: #N/A | L61: #N/A | M61: #N/A | N61: #N/A | O61: #N/A | P61: #N/A | Q61: #N/A | R61: #N/A | S61: 27519 | T61: 506 | U61: 88 | V61: 4098 | W61: 151 | X61: 154 | Y61: 1851 | Z61: 4495 | AA61: 1283 | AB61: 1564 | AC61: 790 | AD61: 1078 | AE61: 265 | AF61: 1538 | AG61: 1588 | AH61: 1787 | AI61: 1988 | AJ61: 2868 | AK61: 646 | AL61: 781 | AM61: 0 | AN61: 20671 | AO61: #N/A | AP61: 2931 | AQ61: 10.4 | AR61: #N/A | AS61: #N/A | AT61: 32 | AU61: 28 | AV61: 1244 | AW61: 45022 | AX61: 62.7 | AY61: 68.4 | AZ61: 33 | BA61: #N/A | BB61: 25293 | BC61: 21389 | BD61: #N/A | BE61: 23584 | BF61: 812 | BG61: 2177 | BH61: 2931
A62: 19933 | B62: #N/A | C62: #N/A | D62: #N/A | E62: #N/A | F62: #N/A | G62: #N/A | H62: #N/A | I62: #N/A | J62: #N/A | K62: #N/A | L62: #N/A | M62: #N/A | N62: #N/A | O62: #N/A | P62: #N/A | Q62: #N/A | R62: #N/A | S62: 27576 | T62: 505 | U62: 83 | V62: 4086 | W62: 147 | X62: 157 | Y62: 1846 | Z62: 4531 | AA62: 1280 | AB62: 1585 | AC62: 790 | AD62: 1070 | AE62: 269 | AF62: 1556 | AG62: 1601 | AH62: 1774 | AI62: 1992 | AJ62: 2864 | AK62: 653 | AL62: 786 | AM62: 0 | AN62: 20752 | AO62: #N/A | AP62: 2890 | AQ62: 10.2 | AR62: #N/A | AS62: #N/A | AT62: 38 | AU62: 35 | AV62: 1253 | AW62: 45033 | AX62: 62.6 | AY62: 68.5 | AZ62: 33 | BA62: #N/A | BB62: 25316 | BC62: 21431 | BD62: #N/A | BE62: 23655 | BF62: 816 | BG62: 2282 | BH62: 2890
A63: 19934 | B63: #N/A | C63: #N/A | D63: #N/A | E63: #N/A | F63: #N/A | G63: #N/A | H63: #N/A | I63: #N/A | J63: #N/A | K63: #N/A | L63: #N/A | M63: #N/A | N63: #N/A | O63: #N/A | P63: #N/A | Q63: #N/A | R63: #N/A | S63: 27649 | T63: 493 | U63: 78 | V63: 4092 | W63: 146 | X63: 154 | Y63: 1860 | Z63: 4561 | AA63: 1278 | AB63: 1597 | AC63: 794 | AD63: 1085 | AE63: 269 | AF63: 1558 | AG63: 1595 | AH63: 1756 | AI63: 2002 | AJ63: 2887 | AK63: 656 | AL63: 789 | AM63: 0 | AN63: 20826 | AO63: #N/A | AP63: 2892 | AQ63: 10.3 | AR63: #N/A | AS63: #N/A | AT63: 42 | AU63: 38 | AV63: 1274 | AW63: 45046 | AX63: 62.6 | AY63: 68.5 | AZ63: 33 | BA63: #N/A | BB63: 25320 | BC63: 21403 | BD63: #N/A | BE63: 23668 | BF63: 825 | BG63: 2328 | BH63: 2892
...

Sheet DataA
B1: =DataQ!F1 -> JAN010B.db | C1: =DataQ!G1 -> JAN010B.db | D1: =DataQ!H1 -> JAN010B.db | E1: =DataQ!I1 -> JAN010B.db | F1: =DataQ!J1 -> JAN010B.db | G1: =DataQ!K1 -> JAN010B.db | H1: =DataQ!L1 -> JAN010B.db | I1: =DataQ!M1 -> JAN010B.db | J1: =DataQ!N1 -> JAN010B.db
B2: =DataQ!F2 -> UK | C2: =DataQ!G2 -> UK | D2: =DataQ!H2 -> UK | E2: =DataQ!I2 -> UK | F2: =DataQ!J2 -> UK | G2: =DataQ!K2 -> UK | H2: =DataQ!L2 -> UK | I2: =DataQ!M2 -> UK | J2: =DataQ!N2 -> UK
B3: =DataQ!F3 -> WC | C3: =DataQ!G3 -> TP | D3: =DataQ!H3 -> WAGEWKLY | E3: =DataQ!I3 -> COGTP | F3: =DataQ!J3 -> GDP! | G3: =DataQ!K3 -> PEWFP | H3: =DataQ!L3 -> PEDY! | I3: =DataQ!M3 -> PEDY | J3: =DataQ!N3 -> PC
B4: =DataQ!F4 -> GBR | C4: =DataQ!G4 -> GBR | D4: =DataQ!H4 -> GBR | E4: =DataQ!I4 -> GBR | F4: =DataQ!J4 -> GBR | G4: =DataQ!K4 -> GBR | H4: =DataQ!L4 -> GBR | I4: =DataQ!M4 -> GBR | J4: =DataQ!N4 -> GBR
B5: =DataQ!F5 -> L | C5: =DataQ!G5 -> L | D5: =DataQ!H5 -> L | E5: =DataQ!I5 -> L | F5: =DataQ!J5 -> L | G5: =DataQ!K5 -> L | H5: =DataQ!L5 -> L | I5: =DataQ!M5 -> L | J5: =DataQ!N5 -> L
B6: =DataQ!F6 -> 202403 | C6: =DataQ!G6 -> 202403 | D6: =DataQ!H6 -> 202403 | E6: =DataQ!I6 -> 202403 | F6: =DataQ!J6 -> 202403 | G6: =DataQ!K6 -> 202403 | H6: =DataQ!L6 -> 202403 | I6: =DataQ!M6 -> 202403 | J6: =DataQ!N6 -> 202403
A7: 1973 | B7: =AVERAGEIF(DataQ!$B:$B,DataA!$A7,DataQ!F:F) -> 11.970672 | C7: =SUMIF(DataQ!$B:$B,DataA!$A7,DataQ!G:G) -> 2309.3419 | D7: =AVERAGEIF(DataQ!$B:$B,DataA!$A7,DataQ!H:H) -> 15.940815 | E7: =SUMIF(DataQ!$B:$B,DataA!$A7,DataQ!I:I) -> 17908 | F7: =SUMIF(DataQ!$B:$B,DataA!$A7,DataQ!J:J) -> 81793 | G7: =SUMIF(DataQ!$B:$B,DataA!$A7,DataQ!K:K) -> 39478 | H7: =SUMIF(DataQ!$B:$B,DataA!$A7,DataQ!L:L) -> 52432 | I7: =SUMIF(DataQ!$B:$B,DataA!$A7,DataQ!M:M) -> 560418 | J7: =AVERAGEIF(DataQ!$B:$B,DataA!$A7,DataQ!N:N) -> 9.5139817
A8: 1974 | B8: =AVERAGEIF(DataQ!$B:$B,DataA!$A8,DataQ!F:F) -> 14.668508 | C8: =SUMIF(DataQ!$B:$B,DataA!$A8,DataQ!G:G) -> 3137.9616 | D8: =AVERAGEIF(DataQ!$B:$B,DataA!$A8,DataQ!H:H) -> 19.300352 | E8: =SUMIF(DataQ!$B:$B,DataA!$A8,DataQ!I:I) -> 16624 | F8: =SUMIF(DataQ!$B:$B,DataA!$A8,DataQ!J:J) -> 92673 | G8: =SUMIF(DataQ!$B:$B,DataA!$A8,DataQ!K:K) -> 46712 | H8: =SUMIF(DataQ!$B:$B,DataA!$A8,DataQ!L:L) -> 61570 | I8: =SUMIF(DataQ!$B:$B,DataA!$A8,DataQ!M:M) -> 555668 | J8: =AVERAGEIF(DataQ!$B:$B,DataA!$A8,DataQ!N:N) -> 11.254465
A9: 1975 | B9: =AVERAGEIF(DataQ!$B:$B,DataA!$A9,DataQ!F:F) -> 19.486995 | C9: =SUMIF(DataQ!$B:$B,DataA!$A9,DataQ!G:G) -> 4573.711 | D9: =AVERAGEIF(DataQ!$B:$B,DataA!$A9,DataQ!H:H) -> 25.941457 | E9: =SUMIF(DataQ!$B:$B,DataA!$A9,DataQ!I:I) -> 17697 | F9: =SUMIF(DataQ!$B:$B,DataA!$A9,DataQ!J:J) -> 115093 | G9: =SUMIF(DataQ!$B:$B,DataA!$A9,DataQ!K:K) -> 60461 | H9: =SUMIF(DataQ!$B:$B,DataA!$A9,DataQ!L:L) -> 76602 | I9: =SUMIF(DataQ!$B:$B,DataA!$A9,DataQ!M:M) -> 560371 | J9: =AVERAGEIF(DataQ!$B:$B,DataA!$A9,DataQ!N:N) -> 13.886603
A10: 1976 | B10: =AVERAGEIF(DataQ!$B:$B,DataA!$A10,DataQ!F:F) -> 21.511143 | C10: =SUMIF(DataQ!$B:$B,DataA!$A10,DataQ!G:G) -> 5695.777 | D10: =AVERAGEIF(DataQ!$B:$B,DataA!$A10,DataQ!H:H) -> 31.409385 | E10: =SUMIF(DataQ!$B:$B,DataA!$A10,DataQ!I:I) -> 22080 | F10: =SUMIF(DataQ!$B:$B,DataA!$A10,DataQ!J:J) -> 136999 | G10: =SUMIF(DataQ!$B:$B,DataA!$A10,DataQ!K:K) -> 67888 | H10: =SUMIF(DataQ!$B:$B,DataA!$A10,DataQ!L:L) -> 89189 | I10: =SUMIF(DataQ!$B:$B,DataA!$A10,DataQ!M:M) -> 559606 | J10: =AVERAGEIF(DataQ!$B:$B,DataA!$A10,DataQ!N:N) -> 16.170227
