Workbook
Name _DLX1.INC: HAVERM!$A$2:$CG$7
Name _DLX2.INC: HAVERQ!$A$2:$CY$7
Name Data: [1]sheet0!$C$2

Sheet CHARTS>>

Sheet DATA>>

Sheet Chart Data
A1: Change in jobs since 2019 - private vs public | E1: Composition of public sector employment | M1: Composition of public sector employment (shares) | U1: Composition of public sector employment (change since 2000) | AD1: Change in WFJ since 2019 | AE1: =HAVERQ!T186 -> 360 | AF1: =HAVERQ!U186 -> 47 | AG1: =HAVERQ!V186 -> 2589 | AH1: =HAVERQ!W186 -> 139 | AI1: =HAVERQ!X186 -> 245 | AJ1: =HAVERQ!Y186 -> 2220 | AK1: =HAVERQ!Z186 -> 4704 | AL1: =HAVERQ!AA186 -> 1879 | ... AV1: =HAVERQ!AK186 -> 1103 | AW1: =HAVERQ!AL186+HAVERQ!AK186 -> 2027 | BA1: Change in WFJ since 2019 | BU1: Change in WFJ since 2019 | CF1: Vacancies per 100 jobs | DB1: Productivity (output per job) | DW1: WFJ forecast | FD1: WFJ forecast - public sector, private sector by pay level | FJ1: WFJ forecast - public sector, private sector by pay level | FP1: HMRC RTI by sector (3m/3m) | GL1: HMRC RTI by sector (3m/3m) | GW1: HMRC RTI by sector (level) | HH1: Pay vs HMRC RTI | HL1: Pay vs vacancies | HP1: Government spending (% of GDP) | HU1: Government spending (per head) | HZ1: Public & private sector employment | IE1: Change in jobs since 2019 - private vs public | II1: Change in jobs since 2019 - private vs public | IM1: WFJ - public emlpoyment vs other | IQ1: Change in jobs since 2019 - private vs public
B3: Public sector | C3: Private sector | F3: NHS | G3: Education | H3: Public administration | I3: Police | J3: HM forces | K3: Other | N3: NHS | O3: Education | P3: Public administration | Q3: Police | R3: HM forces | S3: Other | V3: NHS | W3: Education | X3: Public administration | Y3: Police | Z3: HM forces | AA3: Other | AB3: Total | AE3: Agriculture | AF3: Extraction | AG3: Manufacturing | AH3: Utilities | AI3: Water | AJ3: Construction | AK3: Wholesale & retail | AL3: Transport | AM3: Accommodation & food | AN3: Communications | AO3: Financial services | AP3: Real estate | AQ3: Professional services | AR3: Administrative services | AS3: Public admin | AT3: Education | AU3: Health | AV3: Art & recreation | AW3: Other services | AY3: Other services | BB3: Agriculture | BC3: Extraction & utilities | BD3: Manufacturing | BE3: Construction | BF3: Distribution, accommodation & food | BG3: Transport, storage & comms | BH3: Business services & finance | BI3: Government & other services | BK3: Agriculture | BL3: Extraction & utilities | BM3: Manufacturing | BN3: Construction | BO3: Distribution, accommodation & food | BP3: Transport, storage & comms | BQ3: Business services & finance | BR3: Government & other services | BS3: Check | BV3: Agriculture | BW3: Extraction & utilities | BX3: Manufacturing | BY3: Construction | BZ3: Distribution, accommodation & food | CA3: Transport, storage & comms | CB3: Business services & finance | CC3: Government & other services | CD3: Check | CG3: Total | CI3: Extraction | CJ3: Manufacturing | CK3: Utilities | CL3: Water | CM3: Construction | CN3: Wholesale & retail | CO3: Transport | CP3: Accommodation & food | CQ3: Communications | CR3: Financial services | CS3: Real estate | CT3: Professional services | CU3: Administrative services | CV3: Public admin | CW3: Education | CX3: Health | CY3: Art & recreation | CZ3: Other services | DC3: Agriculture | DD3: Extraction | DE3: Manufacturing | DF3: Utilities | DG3: Water | DH3: Construction | DI3: Wholesale & retail | DJ3: Transport | DK3: Accommodation & food | DL3: Communications | DM3: Financial services | DN3: Real estate | DO3: Professional services | DP3: Administrative services | DQ3: Public admin | DR3: Education | DS3: Health | DT3: Art & recreation | DU3: Other services | DX3: Total | DY3: Agriculture | DZ3: Extraction | EA3: Manufacturing | EB3: Utilities | EC3: Water | ED3: Construction | EE3: Wholesale & retail | EF3: Transport | EG3: Accommodation & food | EH3: Communications | EI3: Financial services | EJ3: Real estate | EK3: Professional services | EL3: Administrative services | EM3: Public admin | EN3: Education | EO3: Health | EP3: Art & recreation | EQ3: Other services | ET3: Agriculture | EU3: Extraction & utilities | EV3: Manufacturing | EW3: Construction | EX3: Distribution, accommodation & food | EY3: Transport, storage & comms | EZ3: Business services & finance | FA3: Government & other services | FB3: Check | FE3: Government & other services | FF3: Private sector - higher paid* | FG3: Private sector - lower paid* | FH3: Check | FK3: Government & other services | FL3: Private sector - higher paid* | FM3: Private sector - lower paid* | FN3: Total | FQ3: Total | FR3: Agriculture | FS3: Extraction | FT3: Manufacturing | FU3: Utilities | FV3: Water | FW3: Construction | FX3: Wholesale & retail | FY3: Transport | FZ3: Accommodation & food | GA3: Communications | GB3: Financial services | GC3: Real estate | GD3: Professional services | GE3: Administrative services | GF3: Public admin | GG3: Education | GH3: Health | GI3: Art & recreation | GJ3: Other services | GM3: Agriculture | GN3: Extraction & utilities | GO3: Manufacturing | GP3: Construction | GQ3: Distribution, accommodation & food | GR3: Transport & comms | GS3: Financial services | GT3: Business services | GU3: Public services | GX3: Agriculture | GY3: Extraction & utilities | GZ3: Manufacturing | HA3: Construction | HB3: Distribution, accommodation & food | HC3: Transport & comms | HD3: Financial services | HE3: Business services | HF3: Public services | HH3: Sector | HI3: Median pay | HJ3: Employee growth | HL3: Sector | HM3: Median pay | HN3: Vacancies per 100 jobs | HQ3: Current spending | HR3: Capital spending | HS3: Total | HV3: Current spending | HW3: Capital spending | HX3: Total | IA3: Public sector | IB3: Private sector | IC3: Check | IF3: Public sector | IG3: Private sector | IJ3: Public sector | IK3: Private sector | IN3: Government & other services | IO3: Mainly private sector | IR3: Government & other services | IS3: Mainly private sector
A4: 43466 | B4: =HAVERQ!E164-AVERAGE(HAVERQ!E$164:E$167) -> -30.75 | C4: =HAVERQ!F164-AVERAGE(HAVERQ!F$164:F$167) -> -66 | E4: 36526 | F4: =HAVERQ!P88 -> 1197 | G4: =HAVERQ!O88 -> 1406 | H4: =HAVERQ!N88 -> 1184 | I4: =HAVERQ!M88 -> 225 | J4: =HAVERQ!L88 -> 217 | K4: =HAVERQ!E88-F4-G4-H4-I4-J4 -> 800 | M4: 36526 | N4: =100*(F4/SUM($F4:$K4)) -> 23.801949 | O4: =100*(G4/SUM($F4:$K4)) -> 27.957845 | P4: =100*(H4/SUM($F4:$K4)) -> 23.543448 | Q4: =100*(I4/SUM($F4:$K4)) -> 4.4740505 | R4: =100*(J4/SUM($F4:$K4)) -> 4.3149732 | S4: =100*(K4/SUM($F4:$K4)) -> 15.907735 | U4: 36526 | V4: =F4-AVERAGE(F$4:F$7) -> -12.25 | W4: =G4-AVERAGE(G$4:G$7) -> -33.75 | X4: =H4-AVERAGE(H$4:H$7) -> 5 | Y4: =I4-AVERAGE(I$4:I$7) -> -0.75 | Z4: =J4-AVERAGE(J$4:J$7) -> 0.75 | AA4: =K4-AVERAGE(K$4:K$7) -> 12.25 | AB4: =SUM(V4:AA4) -> -28.75 | AD4: 43466 | AE4: =HAVERQ!T164-AVERAGE(HAVERQ!T$164:T$167) -> -11.25 | AF4: =HAVERQ!U164-AVERAGE(HAVERQ!U$164:U$167) -> 0.75 | AG4: =HAVERQ!V164-AVERAGE(HAVERQ!V$164:V$167) -> 14.25 | AH4: =HAVERQ!W164-AVERAGE(HAVERQ!W$164:W$167) -> -0.75 | AI4: =HAVERQ!X164-AVERAGE(HAVERQ!X$164:X$167) -> 5.5 | AJ4: =HAVERQ!Y164-AVERAGE(HAVERQ!Y$164:Y$167) -> 27.75 | AK4: =HAVERQ!Z164-AVERAGE(HAVERQ!Z$164:Z$167) -> 27.5 | AL4: =HAVERQ!AA164-AVERAGE(HAVERQ!AA$164:AA$167) -> -20 | ... AV4: =HAVERQ!AK164-AVERAGE(HAVERQ!AK$164:AK$167) -> -5.75 | AW4: =AY4-AVERAGE(AY$4:AY$7) -> -9.5 | AY4: =HAVERQ!AL164+HAVERQ!AM164 -> 1008 | BA4: 43466 | BB4: =BK4-AVERAGE(BK$4:BK$7) -> -11.25 | BC4: =BL4-AVERAGE(BL$4:BL$7) -> 5.5 | BD4: =BM4-AVERAGE(BM$4:BM$7) -> 14.25 | BE4: =BN4-AVERAGE(BN$4:BN$7) -> 27.75 | BF4: =BO4-AVERAGE(BO$4:BO$7) -> -5.5 | BG4: =BP4-AVERAGE(BP$4:BP$7) -> -36.25 | BH4: =BQ4-AVERAGE(BQ$4:BQ$7) -> -60.5 | BI4: =BR4-AVERAGE(BR$4:BR$7) -> -59.25 | BK4: =HAVERQ!T164 -> 387 | BL4: =HAVERQ!U164+HAVERQ!W164+HAVERQ!X164 -> 431 | BM4: =HAVERQ!V164 -> 2705 | BN4: =HAVERQ!Y164 -> 2361 | BO4: =HAVERQ!Z164+HAVERQ!AB164 -> 7499 | BP4: =HAVERQ!AA164+HAVERQ!AC164 -> 3270 | BQ4: =HAVERQ!AD164+HAVERQ!AE164+HAVERQ!AF164+HAVERQ!AG164 -> 7906 | BR4: =HAVERQ!AH164+HAVERQ!AI164+HAVERQ!AJ164+HAVERQ!AK164+HAVERQ!AL164+HAVERQ!AM164 -> 10881 | BS4: =HAVERQ!S164-SUM('Chart Data'!BK4:BR4) -> -2 | BU4: 34335 | BV4: =HAVERQ!T64 -> 492 | BW4: =HAVERQ!U64+HAVERQ!W64+HAVERQ!X64 -> 369 | BX4: =HAVERQ!V64 -> 4096 | BY4: =HAVERQ!Y64 -> 1867 | BZ4: =HAVERQ!Z64+HAVERQ!AB64 -> 6146 | CA4: =HAVERQ!AA64+HAVERQ!AC64 -> 2072 | CB4: =HAVERQ!AD64+HAVERQ!AE64+HAVERQ!AF64+HAVERQ!AG64 -> 4497 | CC4: =HAVERQ!AH64+HAVERQ!AI64+HAVERQ!AJ64+HAVERQ!AK64+HAVERQ!AL64+HAVERQ!AM64 -> 8091 | CD4: =HAVERQ!S64-SUM('Chart Data'!BV4:CC4) -> 0 | CF4: Q1 2025 | CG4: =AVERAGE(HAVERM!X548:X550) -> 2.4333333 | CI4: =AVERAGE(HAVERM!Y548:Y550) -> 3.2666667 | CJ4: =AVERAGE(HAVERM!Z548:Z550) -> 2.1666667 | CK4: =AVERAGE(HAVERM!AA548:AA550) -> 3 | CL4: =AVERAGE(HAVERM!AB548:AB550) -> 2.6666667 | CM4: =AVERAGE(HAVERM!AC548:AC550) -> 2.6 | CN4: =AVERAGE(HAVERM!AD548:AD550) -> 2.2666667 | CO4: =AVERAGE(HAVERM!AE548:AE550) -> 2.1 | CP4: =AVERAGE(HAVERM!AF548:AF550) -> 3.2333333 | ... CZ4: =AVERAGE(HAVERM!AP548:AP550) -> 2.1666667 | DB4: 36161 | DC4: =HAVERQ!BI84/HAVERQ!T84 -> 6.7752294 | DD4: =HAVERQ!BJ84/HAVERQ!U84 -> 601.54545 | DE4: =HAVERQ!BK84/HAVERQ!V84 -> 8.9590026 | DF4: =HAVERQ!BL84/HAVERQ!W84 -> 84.490196 | DG4: =HAVERQ!BM84/HAVERQ!X84 -> 41.506098 | DH4: =HAVERQ!BN84/HAVERQ!Y84 -> 17.63482 | DI4: =HAVERQ!BO84/HAVERQ!Z84 -> 9.5327448 | DJ4: =HAVERQ!BP84/HAVERQ!AA84 -> 13.231055 | ... DT4: =HAVERQ!BZ84/HAVERQ!AK84 -> 9.4086957 | DU4: =(HAVERQ!CA84+HAVERQ!CB84)/HAVERQ!AL84 -> 11.871099 | DW4: 2019 | DX4: =DataA!B53 -> 35565 | DY4: =DataA!C53 -> 398.25 | DZ4: =DataA!D53 -> 61.25 | EA4: =DataA!E53 -> 2690.75 | EB4: =DataA!F53 -> 141.75 | EC4: =DataA!G53 -> 222.5 | ED4: =DataA!H53 -> 2333.25 | EE4: =DataA!I53 -> 5005.5 | ... EQ4: =DataA!U53 -> 1017.5 | ES4: 2019 | ET4: =DY4 -> 398.25 | EU4: =DZ4+EB4+EC4 -> 425.5 | EV4: =EA4 -> 2690.75 | EW4: =ED4 -> 2333.25 | EX4: =EE4+EG4 -> 7504.5 | EY4: =EF4+EH4 -> 3306.25 | EZ4: =EI4+EJ4+EK4+EL4 -> 7966.5 | FA4: =EM4+EN4+EO4+EP4+EQ4 -> 10940.25 | FB4: =DX4-(SUM(ET4:FA4)) -> -0.25 | FD4: 43831 | FE4: =DataQ!U195+DataQ!V195+DataQ!W195+DataQ!X195+DataQ!Y195 -> 10975 | FF4: =DataQ!J195+DataQ!Q195+DataQ!H195+DataQ!P195+DataQ!S195+DataQ!K195+DataQ!L195 -> 8638 | FG4: =DataQ!N195+DataQ!I195+DataQ!R195+DataQ!G195+DataQ!T195+DataQ!M195+DataQ!O195 -> 15997 | FH4: =DataQ!F195-'Chart Data'!FE4-'Chart Data'!FF4-'Chart Data'!FG4 -> -1 | FJ4: 43831 | FK4: =FE4-(AVERAGE(FE$20:FE$23)) -> -955.75 | FL4: =FF4-(AVERAGE(FF$20:FF$23)) -> -307.25 | FM4: =FG4-(AVERAGE(FG$20:FG$23)) -> 78.75 | FN4: =SUM(FK4:FM4) -> -1184.25 | FP4: 42005 | FQ4: =100*((AVERAGE(HAVERM!AS426:AS428)/AVERAGE(HAVERM!AS423:AS425))-1) -> 0.64681 | FR4: =100*((AVERAGE(HAVERM!AT426:AT428)/AVERAGE(HAVERM!AT423:AT425))-1) -> 0.56278373 | FS4: =100*((AVERAGE(HAVERM!AU426:AU428)/AVERAGE(HAVERM!AU423:AU425))-1) -> -0.047955747 | FT4: =100*((AVERAGE(HAVERM!AV426:AV428)/AVERAGE(HAVERM!AV423:AV425))-1) -> -0.0031208153 | FU4: =100*((AVERAGE(HAVERM!AW426:AW428)/AVERAGE(HAVERM!AW423:AW425))-1) -> 0.46099291 | FV4: =100*((AVERAGE(HAVERM!AX426:AX428)/AVERAGE(HAVERM!AX423:AX425))-1) -> 0.63793926 | FW4: =100*((AVERAGE(HAVERM!AY426:AY428)/AVERAGE(HAVERM!AY423:AY425))-1) -> 0.89082514 | FX4: =100*((AVERAGE(HAVERM!AZ426:AZ428)/AVERAGE(HAVERM!AZ423:AZ425))-1) -> 0.93050514 | ... GI4: =100*((AVERAGE(HAVERM!BK426:BK428)/AVERAGE(HAVERM!BK423:BK425))-1) -> 1.1622119 | GJ4: =100*(((AVERAGE(HAVERM!BL426:BL428)+(AVERAGE(HAVERM!BM426:BM428)))/(AVERAGE(HAVERM!BL423:BL425)+AVERAGE(HAVERM!BM423:BM425))-1)) -> 0.99844185 | GL4: 42005 | GW4: 42005 | GX4: =HAVERM!AT428 -> 178218 | GY4: =HAVERM!AU428+HAVERM!AW428+HAVERM!AX428 -> 308670 | GZ4: =HAVERM!AV428 -> 2365273 | HA4: =HAVERM!AY428 -> 1114777 | HB4: =HAVERM!AZ428+HAVERM!BB428 -> 6149563 | HC4: =HAVERM!BA428+HAVERM!BC428 -> 2256758 | HD4: =HAVERM!BD428 -> 1068174 | HE4: =HAVERM!BE428+HAVERM!BF428+HAVERM!BG428 -> 4641583 | HF4: =HAVERM!BH428+HAVERM!BI428+HAVERM!BJ428+HAVERM!BK428+HAVERM!BL428+HAVERM!BM428 -> 9075119 | HH4: Agriculture | HI4: ='ASHE Annual pay All SIC'!D26 -> 27288 | HJ4: {=TRANSPOSE(FR128:GJ128)} -> -0.89380511 | HP4: 2007 | HQ4: {=TRANSPOSE('OBR MAR25 EDT 4.3'!E10:AA10)} -> 16.34162 | HR4: {=TRANSPOSE('OBR MAR25 EDT 4.3'!E16:AA16)} -> 3.0882622 | HS4: =HQ4+HR4 -> 19.429882 | HU4: 2007 | HV4: {=TRANSPOSE('OBR MAR25 EDT 4.3'!E11:AA11)} -> 6431.6118 | HW4: {=TRANSPOSE('OBR MAR25 EDT 4.3'!E17:AA17)} -> 1215.455 | HX4: =HV4+HW4 -> 7647.0668 | HZ4: 43466 | IA4: =HAVERQ!E164 -> 5285 | IB4: =HAVERQ!F164 -> 27558 | IC4: =DataQ!Z191-('Chart Data'!IA4+'Chart Data'!IB4) -> -67 | IE4: 43466 | IF4: =IA4-AVERAGE(IA$4:IA$7) -> -30.75 | IG4: =IB4-AVERAGE(IB$4:IB$7) -> -66 | II4: 43466 | IJ4: =100*(IA4/AVERAGE(IA$4:IA$7)) -> 99.42153 | IK4: =100*(IB4/AVERAGE(IB$4:IB$7)) -> 99.761077 | IM4: 43466 | IN4: =SUM(DataQ!U191:Y191) -> 10881 | IO4: =DataQ!F191-'Chart Data'!IN4 -> 24557 | IQ4: 43466 | IR4: =100*(IN4/AVERAGE(IN$4:IN$7)) -> 99.458422 | IS4: =100*(IO4/AVERAGE(IO$4:IO$7)) -> 99.72487
A5: 43556 | B5: =HAVERQ!E165-AVERAGE(HAVERQ!E$164:E$167) -> -10.75 | C5: =HAVERQ!F165-AVERAGE(HAVERQ!F$164:F$167) -> -23 | E5: 36617 | F5: =HAVERQ!P89 -> 1204 | G5: =HAVERQ!O89 -> 1441 | H5: =HAVERQ!N89 -> 1178 | I5: =HAVERQ!M89 -> 225 | J5: =HAVERQ!L89 -> 217 | K5: =HAVERQ!E89-F5-G5-H5-I5-J5 -> 784 | M5: 36617 | N5: =100*(F5/SUM($F5:$K5)) -> 23.846306 | O5: =100*(G5/SUM($F5:$K5)) -> 28.540305 | P5: =100*(H5/SUM($F5:$K5)) -> 23.331353 | Q5: =100*(I5/SUM($F5:$K5)) -> 4.456328 | R5: =100*(J5/SUM($F5:$K5)) -> 4.2978808 | S5: =100*(K5/SUM($F5:$K5)) -> 15.527827 | U5: 36617 | V5: =F5-AVERAGE(F$4:F$7) -> -5.25 | W5: =G5-AVERAGE(G$4:G$7) -> 1.25 | X5: =H5-AVERAGE(H$4:H$7) -> -1 | Y5: =I5-AVERAGE(I$4:I$7) -> -0.75 | Z5: =J5-AVERAGE(J$4:J$7) -> 0.75 | AA5: =K5-AVERAGE(K$4:K$7) -> -3.75 | AB5: =SUM(V5:AA5) -> -8.75 | AD5: 43556 | AE5: =HAVERQ!T165-AVERAGE(HAVERQ!T$164:T$167) -> -0.25 | AF5: =HAVERQ!U165-AVERAGE(HAVERQ!U$164:U$167) -> -1.25 | AG5: =HAVERQ!V165-AVERAGE(HAVERQ!V$164:V$167) -> -1.75 | AH5: =HAVERQ!W165-AVERAGE(HAVERQ!W$164:W$167) -> -0.75 | AI5: =HAVERQ!X165-AVERAGE(HAVERQ!X$164:X$167) -> 0.5 | AJ5: =HAVERQ!Y165-AVERAGE(HAVERQ!Y$164:Y$167) -> 5.75 | AK5: =HAVERQ!Z165-AVERAGE(HAVERQ!Z$164:Z$167) -> 11.5 | AL5: =HAVERQ!AA165-AVERAGE(HAVERQ!AA$164:AA$167) -> 13 | ... AV5: =HAVERQ!AK165-AVERAGE(HAVERQ!AK$164:AK$167) -> -9.75 | AW5: =AY5-AVERAGE(AY$4:AY$7) -> -8.5 | AY5: =HAVERQ!AL165+HAVERQ!AM165 -> 1009 | BA5: 43556 | BB5: =BK5-AVERAGE(BK$4:BK$7) -> -0.25 | BC5: =BL5-AVERAGE(BL$4:BL$7) -> -1.5 | BD5: =BM5-AVERAGE(BM$4:BM$7) -> -1.75 | BE5: =BN5-AVERAGE(BN$4:BN$7) -> 5.75 | BF5: =BO5-AVERAGE(BO$4:BO$7) -> 24.5 | BG5: =BP5-AVERAGE(BP$4:BP$7) -> 1.75 | BH5: =BQ5-AVERAGE(BQ$4:BQ$7) -> -8.5 | BI5: =BR5-AVERAGE(BR$4:BR$7) -> -40.25 | BK5: =HAVERQ!T165 -> 398 | BL5: =HAVERQ!U165+HAVERQ!W165+HAVERQ!X165 -> 424 | BM5: =HAVERQ!V165 -> 2689 | BN5: =HAVERQ!Y165 -> 2339 | BO5: =HAVERQ!Z165+HAVERQ!AB165 -> 7529 | BP5: =HAVERQ!AA165+HAVERQ!AC165 -> 3308 | BQ5: =HAVERQ!AD165+HAVERQ!AE165+HAVERQ!AF165+HAVERQ!AG165 -> 7958 | BR5: =HAVERQ!AH165+HAVERQ!AI165+HAVERQ!AJ165+HAVERQ!AK165+HAVERQ!AL165+HAVERQ!AM165 -> 10900 | BS5: =HAVERQ!S165-SUM('Chart Data'!BK5:BR5) -> 1 | BU5: 34425 | BV5: =HAVERQ!T65 -> 487 | BW5: =HAVERQ!U65+HAVERQ!W65+HAVERQ!X65 -> 359 | BX5: =HAVERQ!V65 -> 4121 | BY5: =HAVERQ!Y65 -> 1874 | BZ5: =HAVERQ!Z65+HAVERQ!AB65 -> 6185 | CA5: =HAVERQ!AA65+HAVERQ!AC65 -> 2084 | CB5: =HAVERQ!AD65+HAVERQ!AE65+HAVERQ!AF65+HAVERQ!AG65 -> 4507 | CC5: =HAVERQ!AH65+HAVERQ!AI65+HAVERQ!AJ65+HAVERQ!AK65+HAVERQ!AL65+HAVERQ!AM65 -> 8062 | CD5: =HAVERQ!S65-SUM('Chart Data'!BV5:CC5) -> -1 | CF5: 2024 average | CG5: =AVERAGE(HAVERM!X536:X547) -> 2.6583333 | CI5: =AVERAGE(HAVERM!Y536:Y547) -> 3.6583333 | CJ5: =AVERAGE(HAVERM!Z536:Z547) -> 2.5333333 | CK5: =AVERAGE(HAVERM!AA536:AA547) -> 3.425 | CL5: =AVERAGE(HAVERM!AB536:AB547) -> 2.6916667 | CM5: =AVERAGE(HAVERM!AC536:AC547) -> 2.4333333 | CN5: =AVERAGE(HAVERM!AD536:AD547) -> 2.3833333 | CO5: =AVERAGE(HAVERM!AE536:AE547) -> 2.1833333 | CP5: =AVERAGE(HAVERM!AF536:AF547) -> 3.7666667 | ... CZ5: =AVERAGE(HAVERM!AP536:AP547) -> 2.625 | DB5: 36251 | DC5: =HAVERQ!BI85/HAVERQ!T85 -> 7.1132075 | DD5: =HAVERQ!BJ85/HAVERQ!U85 -> 603.77632 | DE5: =HAVERQ!BK85/HAVERQ!V85 -> 9.1518895 | DF5: =HAVERQ!BL85/HAVERQ!W85 -> 88.156863 | DG5: =HAVERQ!BM85/HAVERQ!X85 -> 41.793939 | DH5: =HAVERQ!BN85/HAVERQ!Y85 -> 17.60241 | DI5: =HAVERQ!BO85/HAVERQ!Z85 -> 9.3493432 | DJ5: =HAVERQ!BP85/HAVERQ!AA85 -> 13.476969 | ... DT5: =HAVERQ!BZ85/HAVERQ!AK85 -> 9.2092697 | DU5: =(HAVERQ!CA85+HAVERQ!CB85)/HAVERQ!AL85 -> 11.891247 | DW5: 2024 | DX5: =DataA!B58 -> 36792.75 | DY5: =DataA!C58 -> 360.25 | DZ5: =DataA!D58 -> 48.25 | EA5: =DataA!E58 -> 2588 | EB5: =DataA!F58 -> 135.75 | EC5: =DataA!G58 -> 246 | ED5: =DataA!H58 -> 2209 | EE5: =DataA!I58 -> 4722.5 | ... EQ5: =DataA!U58 -> 997.5 | ES5: 2024 | ET5: =DY5 -> 360.25 | EU5: =DZ5+EB5+EC5 -> 430 | EV5: =EA5 -> 2588 | EW5: =ED5 -> 2209 | EX5: =EE5+EG5 -> 7388.75 | EY5: =EF5+EH5 -> 3516.25 | EZ5: =EI5+EJ5+EK5+EL5 -> 8371.25 | FA5: =EM5+EN5+EO5+EP5+EQ5 -> 11930.75 | FB5: =DX5-(SUM(ET5:FA5)) -> -1.5 | FD5: 43922 | FE5: =DataQ!U196+DataQ!V196+DataQ!W196+DataQ!X196+DataQ!Y196 -> 10977 | FF5: =DataQ!J196+DataQ!Q196+DataQ!H196+DataQ!P196+DataQ!S196+DataQ!K196+DataQ!L196 -> 8483 | FG5: =DataQ!N196+DataQ!I196+DataQ!R196+DataQ!G196+DataQ!T196+DataQ!M196+DataQ!O196 -> 15674 | FH5: =DataQ!F196-'Chart Data'!FE5-'Chart Data'!FF5-'Chart Data'!FG5 -> 1 | FJ5: 43922 | FK5: =FE5-(AVERAGE(FE$20:FE$23)) -> -953.75 | FL5: =FF5-(AVERAGE(FF$20:FF$23)) -> -462.25 | FM5: =FG5-(AVERAGE(FG$20:FG$23)) -> -244.25 | FN5: =SUM(FK5:FM5) -> -1660.25 | FP5: 42036 | FQ5: =100*((AVERAGE(HAVERM!AS427:AS429)/AVERAGE(HAVERM!AS424:AS426))-1) -> 0.70473908 | FR5: =100*((AVERAGE(HAVERM!AT427:AT429)/AVERAGE(HAVERM!AT424:AT426))-1) -> 1.0495907 | FS5: =100*((AVERAGE(HAVERM!AU427:AU429)/AVERAGE(HAVERM!AU424:AU426))-1) -> -0.81304885 | FT5: =100*((AVERAGE(HAVERM!AV427:AV429)/AVERAGE(HAVERM!AV424:AV426))-1) -> -0.06784322 | FU5: =100*((AVERAGE(HAVERM!AW427:AW429)/AVERAGE(HAVERM!AW424:AW426))-1) -> 0.71990879 | FV5: =100*((AVERAGE(HAVERM!AX427:AX429)/AVERAGE(HAVERM!AX424:AX426))-1) -> 0.80109771 | FW5: =100*((AVERAGE(HAVERM!AY427:AY429)/AVERAGE(HAVERM!AY424:AY426))-1) -> 0.85794421 | FX5: =100*((AVERAGE(HAVERM!AZ427:AZ429)/AVERAGE(HAVERM!AZ424:AZ426))-1) -> 1.0578494 | ... GI5: =100*((AVERAGE(HAVERM!BK427:BK429)/AVERAGE(HAVERM!BK424:BK426))-1) -> 1.2562187 | GJ5: =100*(((AVERAGE(HAVERM!BL427:BL429)+(AVERAGE(HAVERM!BM427:BM429)))/(AVERAGE(HAVERM!BL424:BL426)+AVERAGE(HAVERM!BM424:BM426))-1)) -> 0.95573114 | GL5: 42036 | GW5: 42036 | GX5: =HAVERM!AT429 -> 178345 | GY5: =HAVERM!AU429+HAVERM!AW429+HAVERM!AX429 -> 308696 | GZ5: =HAVERM!AV429 -> 2371584 | HA5: =HAVERM!AY429 -> 1118179 | HB5: =HAVERM!AZ429+HAVERM!BB429 -> 6155052 | HC5: =HAVERM!BA429+HAVERM!BC429 -> 2266463 | HD5: =HAVERM!BD429 -> 1069126 | HE5: =HAVERM!BE429+HAVERM!BF429+HAVERM!BG429 -> 4662777 | HF5: =HAVERM!BH429+HAVERM!BI429+HAVERM!BJ429+HAVERM!BK429+HAVERM!BL429+HAVERM!BM429 -> 9084632 | HH5: Extraction | HI5: ='ASHE Annual pay All SIC'!D30 -> 47022 | HJ5: -0.92967819 | HL5: Extraction | HM5: ='ASHE Annual pay All SIC'!D30 -> 47022 | HN5: {=TRANSPOSE(CI11:CZ11)} -> 0.77916667 | HP5: 2008 | HQ5: 16.925615 | HR5: 3.2968634 | HS5: =HQ5+HR5 -> 20.222479 | HU5: 2008 | HV5: 6446.2125 | HW5: 1255.6283 | HX5: =HV5+HW5 -> 7701.8408 | HZ5: 43556 | IA5: =HAVERQ!E165 -> 5305 | IB5: =HAVERQ!F165 -> 27601 | IC5: =DataQ!Z192-('Chart Data'!IA5+'Chart Data'!IB5) -> 57 | IE5: 43556 | IF5: =IA5-AVERAGE(IA$4:IA$7) -> -10.75 | IG5: =IB5-AVERAGE(IB$4:IB$7) -> -23 | II5: 43556 | IJ5: =100*(IA5/AVERAGE(IA$4:IA$7)) -> 99.797771 | IK5: =100*(IB5/AVERAGE(IB$4:IB$7)) -> 99.916739 | IM5: 43556 | IN5: =SUM(DataQ!U192:Y192) -> 10900 | IO5: =DataQ!F192-'Chart Data'!IN5 -> 24646 | IQ5: 43556 | IR5: =100*(IN5/AVERAGE(IN$4:IN$7)) -> 99.632093 | IS5: =100*(IO5/AVERAGE(IO$4:IO$7)) -> 100.0863
A6: 43647 | B6: =HAVERQ!E166-AVERAGE(HAVERQ!E$164:E$167) -> 13.25 | C6: =HAVERQ!F166-AVERAGE(HAVERQ!F$164:F$167) -> -46 | E6: 36708 | F6: =HAVERQ!P90 -> 1213 | G6: =HAVERQ!O90 -> 1455 | H6: =HAVERQ!N90 -> 1177 | I6: =HAVERQ!M90 -> 226 | J6: =HAVERQ!L90 -> 216 | K6: =HAVERQ!E90-F6-G6-H6-I6-J6 -> 785 | M6: 36708 | N6: =100*(F6/SUM($F6:$K6)) -> 23.915615 | O6: =100*(G6/SUM($F6:$K6)) -> 28.686909 | P6: =100*(H6/SUM($F6:$K6)) -> 23.205836 | Q6: =100*(I6/SUM($F6:$K6)) -> 4.455836 | R6: =100*(J6/SUM($F6:$K6)) -> 4.2586751 | S6: =100*(K6/SUM($F6:$K6)) -> 15.477129 | U6: 36708 | V6: =F6-AVERAGE(F$4:F$7) -> 3.75 | W6: =G6-AVERAGE(G$4:G$7) -> 15.25 | X6: =H6-AVERAGE(H$4:H$7) -> -2 | Y6: =I6-AVERAGE(I$4:I$7) -> 0.25 | Z6: =J6-AVERAGE(J$4:J$7) -> -0.25 | AA6: =K6-AVERAGE(K$4:K$7) -> -2.75 | AB6: =SUM(V6:AA6) -> 14.25 | AD6: 43647 | AE6: =HAVERQ!T166-AVERAGE(HAVERQ!T$164:T$167) -> 4.75 | AF6: =HAVERQ!U166-AVERAGE(HAVERQ!U$164:U$167) -> -0.25 | AG6: =HAVERQ!V166-AVERAGE(HAVERQ!V$164:V$167) -> 3.25 | AH6: =HAVERQ!W166-AVERAGE(HAVERQ!W$164:W$167) -> -2.75 | AI6: =HAVERQ!X166-AVERAGE(HAVERQ!X$164:X$167) -> -2.5 | AJ6: =HAVERQ!Y166-AVERAGE(HAVERQ!Y$164:Y$167) -> -25.25 | AK6: =HAVERQ!Z166-AVERAGE(HAVERQ!Z$164:Z$167) -> -4.5 | AL6: =HAVERQ!AA166-AVERAGE(HAVERQ!AA$164:AA$167) -> 2 | ... AV6: =HAVERQ!AK166-AVERAGE(HAVERQ!AK$164:AK$167) -> 2.25 | AW6: =AY6-AVERAGE(AY$4:AY$7) -> 1.5 | AY6: =HAVERQ!AL166+HAVERQ!AM166 -> 1019 | BA6: 43647 | BB6: =BK6-AVERAGE(BK$4:BK$7) -> 4.75 | BC6: =BL6-AVERAGE(BL$4:BL$7) -> -5.5 | BD6: =BM6-AVERAGE(BM$4:BM$7) -> 3.25 | BE6: =BN6-AVERAGE(BN$4:BN$7) -> -25.25 | BF6: =BO6-AVERAGE(BO$4:BO$7) -> 2.5 | BG6: =BP6-AVERAGE(BP$4:BP$7) -> 1.75 | BH6: =BQ6-AVERAGE(BQ$4:BQ$7) -> 47.5 | BI6: =BR6-AVERAGE(BR$4:BR$7) -> 21.75 | BK6: =HAVERQ!T166 -> 403 | BL6: =HAVERQ!U166+HAVERQ!W166+HAVERQ!X166 -> 420 | BM6: =HAVERQ!V166 -> 2694 | BN6: =HAVERQ!Y166 -> 2308 | BO6: =HAVERQ!Z166+HAVERQ!AB166 -> 7507 | BP6: =HAVERQ!AA166+HAVERQ!AC166 -> 3308 | BQ6: =HAVERQ!AD166+HAVERQ!AE166+HAVERQ!AF166+HAVERQ!AG166 -> 8014 | BR6: =HAVERQ!AH166+HAVERQ!AI166+HAVERQ!AJ166+HAVERQ!AK166+HAVERQ!AL166+HAVERQ!AM166 -> 10962 | BS6: =HAVERQ!S166-SUM('Chart Data'!BK6:BR6) -> -1 | BU6: 34516 | BV6: =HAVERQ!T66 -> 484 | BW6: =HAVERQ!U66+HAVERQ!W66+HAVERQ!X66 -> 352 | BX6: =HAVERQ!V66 -> 4151 | BY6: =HAVERQ!Y66 -> 1888 | BZ6: =HAVERQ!Z66+HAVERQ!AB66 -> 6243 | CA6: =HAVERQ!AA66+HAVERQ!AC66 -> 2094 | CB6: =HAVERQ!AD66+HAVERQ!AE66+HAVERQ!AF66+HAVERQ!AG66 -> 4617 | CC6: =HAVERQ!AH66+HAVERQ!AI66+HAVERQ!AJ66+HAVERQ!AK66+HAVERQ!AL66+HAVERQ!AM66 -> 8044 | CD6: =HAVERQ!S66-SUM('Chart Data'!BV6:CC6) -> 1 | CF6: 2010-2019 average | CG6: =AVERAGE(HAVERM!X368:X487) -> 2.2725 | CI6: =AVERAGE(HAVERM!Y368:Y487) -> 2.435 | CJ6: =AVERAGE(HAVERM!Z368:Z487) -> 1.8916667 | CK6: =AVERAGE(HAVERM!AA368:AA487) -> 2.8666667 | CL6: =AVERAGE(HAVERM!AB368:AB487) -> 1.3358333 | CM6: =AVERAGE(HAVERM!AC368:AC487) -> 1.4525 | CN6: =AVERAGE(HAVERM!AD368:AD487) -> 2.5666667 | CO6: =AVERAGE(HAVERM!AE368:AE487) -> 2.0358333 | CP6: =AVERAGE(HAVERM!AF368:AF487) -> 3.37 | ... CZ6: =AVERAGE(HAVERM!AP368:AP487) -> 2.8533333 | DB6: 36342 | DC6: =HAVERQ!BI86/HAVERQ!T86 -> 7.3333333 | DD6: =HAVERQ!BJ86/HAVERQ!U86 -> 612.98684 | DE6: =HAVERQ!BK86/HAVERQ!V86 -> 9.3891734 | DF6: =HAVERQ!BL86/HAVERQ!W86 -> 91.919192 | DG6: =HAVERQ!BM86/HAVERQ!X86 -> 42.453988 | DH6: =HAVERQ!BN86/HAVERQ!Y86 -> 17.804167 | DI6: =HAVERQ!BO86/HAVERQ!Z86 -> 9.4105866 | DJ6: =HAVERQ!BP86/HAVERQ!AA86 -> 13.401026 | ... DT6: =HAVERQ!BZ86/HAVERQ!AK86 -> 8.8510929 | DU6: =(HAVERQ!CA86+HAVERQ!CB86)/HAVERQ!AL86 -> 11.178893 | DW6: 2029 | DX6: =DataA!B63 -> 38728.525 | DY6: =DataA!C63 -> 362.614 | DZ6: =DataA!D63 -> 43.125685 | EA6: =DataA!E63 -> 2436.3983 | EB6: =DataA!F63 -> 134.91768 | EC6: =DataA!G63 -> 252.23687 | ED6: =DataA!H63 -> 2413.8517 | EE6: =DataA!I63 -> 4946.7212 | ... EQ6: =DataA!U63 -> 1072.053 | ES6: 2029 | ET6: =DY6 -> 362.614 | EU6: =DZ6+EB6+EC6 -> 430.28024 | EV6: =EA6 -> 2436.3983 | EW6: =ED6 -> 2413.8517 | EX6: =EE6+EG6 -> 7715.6932 | EY6: =EF6+EH6 -> 3800.511 | EZ6: =EI6+EJ6+EK6+EL6 -> 8929.9667 | FA6: =EM6+EN6+EO6+EP6+EQ6 -> 12638.21 | FB6: =DX6-(SUM(ET6:FA6)) -> 0.999365 | FD6: 44013 | FE6: =DataQ!U197+DataQ!V197+DataQ!W197+DataQ!X197+DataQ!Y197 -> 10843 | FF6: =DataQ!J197+DataQ!Q197+DataQ!H197+DataQ!P197+DataQ!S197+DataQ!K197+DataQ!L197 -> 8311 | FG6: =DataQ!N197+DataQ!I197+DataQ!R197+DataQ!G197+DataQ!T197+DataQ!M197+DataQ!O197 -> 15440 | FH6: =DataQ!F197-'Chart Data'!FE6-'Chart Data'!FF6-'Chart Data'!FG6 -> 0 | FJ6: 44013 | FK6: =FE6-(AVERAGE(FE$20:FE$23)) -> -1087.75 | FL6: =FF6-(AVERAGE(FF$20:FF$23)) -> -634.25 | FM6: =FG6-(AVERAGE(FG$20:FG$23)) -> -478.25 | FN6: =SUM(FK6:FM6) -> -2200.25 | FP6: 42064 | FQ6: =100*((AVERAGE(HAVERM!AS428:AS430)/AVERAGE(HAVERM!AS425:AS427))-1) -> 0.93672645 | FR6: =100*((AVERAGE(HAVERM!AT428:AT430)/AVERAGE(HAVERM!AT425:AT427))-1) -> 1.0161343 | FS6: =100*((AVERAGE(HAVERM!AU428:AU430)/AVERAGE(HAVERM!AU425:AU427))-1) -> -0.9793484 | FT6: =100*((AVERAGE(HAVERM!AV428:AV430)/AVERAGE(HAVERM!AV425:AV427))-1) -> 1.0623043 | FU6: =100*((AVERAGE(HAVERM!AW428:AW430)/AVERAGE(HAVERM!AW425:AW427))-1) -> 0.78776846 | FV6: =100*((AVERAGE(HAVERM!AX428:AX430)/AVERAGE(HAVERM!AX425:AX427))-1) -> 1.1945727 | FW6: =100*((AVERAGE(HAVERM!AY428:AY430)/AVERAGE(HAVERM!AY425:AY427))-1) -> 2.3760033 | FX6: =100*((AVERAGE(HAVERM!AZ428:AZ430)/AVERAGE(HAVERM!AZ425:AZ427))-1) -> 1.0585566 | ... GI6: =100*((AVERAGE(HAVERM!BK428:BK430)/AVERAGE(HAVERM!BK425:BK427))-1) -> 1.1866166 | GJ6: =100*(((AVERAGE(HAVERM!BL428:BL430)+(AVERAGE(HAVERM!BM428:BM430)))/(AVERAGE(HAVERM!BL425:BL427)+AVERAGE(HAVERM!BM425:BM427))-1)) -> 0.99081627 | GL6: 42064 | GW6: 42064 | GX6: =HAVERM!AT430 -> 178374 | GY6: =HAVERM!AU430+HAVERM!AW430+HAVERM!AX430 -> 309557 | GZ6: =HAVERM!AV430 -> 2374578 | HA6: =HAVERM!AY430 -> 1124033 | HB6: =HAVERM!AZ430+HAVERM!BB430 -> 6178886 | HC6: =HAVERM!BA430+HAVERM!BC430 -> 2274102 | HD6: =HAVERM!BD430 -> 1070374 | HE6: =HAVERM!BE430+HAVERM!BF430+HAVERM!BG430 -> 4690460 | HF6: =HAVERM!BH430+HAVERM!BI430+HAVERM!BJ430+HAVERM!BK430+HAVERM!BL430+HAVERM!BM430 -> 9094299 | HH6: Manufacturing | HI6: ='ASHE Annual pay All SIC'!D36 -> 35518 | HJ6: -0.42959079 | HL6: Manufacturing | HM6: ='ASHE Annual pay All SIC'!D36 -> 35518 | HN6: -0.30583333 | HP6: 2009 | HQ6: 18.265633 | HR6: 3.8046863 | HS6: =HQ6+HR6 -> 22.07032 | HU6: 2009 | HV6: 6720.9846 | HW6: 1399.9645 | HX6: =HV6+HW6 -> 8120.9491 | HZ6: 43647 | IA6: =HAVERQ!E166 -> 5329 | IB6: =HAVERQ!F166 -> 27578 | IC6: =DataQ!Z193-('Chart Data'!IA6+'Chart Data'!IB6) -> -11 | IE6: 43647 | IF6: =IA6-AVERAGE(IA$4:IA$7) -> 13.25 | IG6: =IB6-AVERAGE(IB$4:IB$7) -> -46 | II6: 43647 | IJ6: =100*(IA6/AVERAGE(IA$4:IA$7)) -> 100.24926 | IK6: =100*(IB6/AVERAGE(IB$4:IB$7)) -> 99.833478 | IM6: 43647 | IN6: =SUM(DataQ!U193:Y193) -> 10962 | IO6: =DataQ!F193-'Chart Data'!IN6 -> 24653 | IQ6: 43647 | IR6: =100*(IN6/AVERAGE(IN$4:IN$7)) -> 100.19881 | IS6: =100*(IO6/AVERAGE(IO$4:IO$7)) -> 100.11472
A7: 43739 | B7: =HAVERQ!E167-AVERAGE(HAVERQ!E$164:E$167) -> 28.25 | C7: =HAVERQ!F167-AVERAGE(HAVERQ!F$164:F$167) -> 135 | E7: 36800 | F7: =HAVERQ!P91 -> 1223 | G7: =HAVERQ!O91 -> 1457 | H7: =HAVERQ!N91 -> 1177 | I7: =HAVERQ!M91 -> 227 | J7: =HAVERQ!L91 -> 215 | K7: =HAVERQ!E91-F7-G7-H7-I7-J7 -> 782 | M7: 36800 | N7: =100*(F7/SUM($F7:$K7)) -> 24.070065 | O7: =100*(G7/SUM($F7:$K7)) -> 28.675458 | P7: =100*(H7/SUM($F7:$K7)) -> 23.164731 | Q7: =100*(I7/SUM($F7:$K7)) -> 4.4676245 | R7: =100*(J7/SUM($F7:$K7)) -> 4.2314505 | S7: =100*(K7/SUM($F7:$K7)) -> 15.390671 | U7: 36800 | V7: =F7-AVERAGE(F$4:F$7) -> 13.75 | W7: =G7-AVERAGE(G$4:G$7) -> 17.25 | X7: =H7-AVERAGE(H$4:H$7) -> -2 | Y7: =I7-AVERAGE(I$4:I$7) -> 1.25 | Z7: =J7-AVERAGE(J$4:J$7) -> -1.25 | AA7: =K7-AVERAGE(K$4:K$7) -> -5.75 | AB7: =SUM(V7:AA7) -> 23.25 | AD7: 43739 | AE7: =HAVERQ!T167-AVERAGE(HAVERQ!T$164:T$167) -> 6.75 | AF7: =HAVERQ!U167-AVERAGE(HAVERQ!U$164:U$167) -> 0.75 | AG7: =HAVERQ!V167-AVERAGE(HAVERQ!V$164:V$167) -> -15.75 | AH7: =HAVERQ!W167-AVERAGE(HAVERQ!W$164:W$167) -> 4.25 | AI7: =HAVERQ!X167-AVERAGE(HAVERQ!X$164:X$167) -> -3.5 | AJ7: =HAVERQ!Y167-AVERAGE(HAVERQ!Y$164:Y$167) -> -8.25 | AK7: =HAVERQ!Z167-AVERAGE(HAVERQ!Z$164:Z$167) -> -34.5 | AL7: =HAVERQ!AA167-AVERAGE(HAVERQ!AA$164:AA$167) -> 5 | ... AV7: =HAVERQ!AK167-AVERAGE(HAVERQ!AK$164:AK$167) -> 13.25 | AW7: =AY7-AVERAGE(AY$4:AY$7) -> 16.5 | AY7: =HAVERQ!AL167+HAVERQ!AM167 -> 1034 | BA7: 43739 | BB7: =BK7-AVERAGE(BK$4:BK$7) -> 6.75 | BC7: =BL7-AVERAGE(BL$4:BL$7) -> 1.5 | BD7: =BM7-AVERAGE(BM$4:BM$7) -> -15.75 | BE7: =BN7-AVERAGE(BN$4:BN$7) -> -8.25 | BF7: =BO7-AVERAGE(BO$4:BO$7) -> -21.5 | BG7: =BP7-AVERAGE(BP$4:BP$7) -> 32.75 | BH7: =BQ7-AVERAGE(BQ$4:BQ$7) -> 21.5 | BI7: =BR7-AVERAGE(BR$4:BR$7) -> 77.75 | BK7: =HAVERQ!T167 -> 405 | BL7: =HAVERQ!U167+HAVERQ!W167+HAVERQ!X167 -> 427 | BM7: =HAVERQ!V167 -> 2675 | BN7: =HAVERQ!Y167 -> 2325 | BO7: =HAVERQ!Z167+HAVERQ!AB167 -> 7483 | BP7: =HAVERQ!AA167+HAVERQ!AC167 -> 3339 | BQ7: =HAVERQ!AD167+HAVERQ!AE167+HAVERQ!AF167+HAVERQ!AG167 -> 7988 | BR7: =HAVERQ!AH167+HAVERQ!AI167+HAVERQ!AJ167+HAVERQ!AK167+HAVERQ!AL167+HAVERQ!AM167 -> 11018 | BS7: =HAVERQ!S167-SUM('Chart Data'!BK7:BR7) -> 1 | BU7: 34608 | BV7: =HAVERQ!T67 -> 470 | BW7: =HAVERQ!U67+HAVERQ!W67+HAVERQ!X67 -> 346 | BX7: =HAVERQ!V67 -> 4176 | BY7: =HAVERQ!Y67 -> 1879 | BZ7: =HAVERQ!Z67+HAVERQ!AB67 -> 6269 | CA7: =HAVERQ!AA67+HAVERQ!AC67 -> 2095 | CB7: =HAVERQ!AD67+HAVERQ!AE67+HAVERQ!AF67+HAVERQ!AG67 -> 4650 | CC7: =HAVERQ!AH67+HAVERQ!AI67+HAVERQ!AJ67+HAVERQ!AK67+HAVERQ!AL67+HAVERQ!AM67 -> 8056 | CD7: =HAVERQ!S67-SUM('Chart Data'!BV7:CC7) -> 0 | DB7: 36434 | DC7: =HAVERQ!BI87/HAVERQ!T87 -> 7.8059701 | DD7: =HAVERQ!BJ87/HAVERQ!U87 -> 604.47368 | DE7: =HAVERQ!BK87/HAVERQ!V87 -> 9.4796668 | DF7: =HAVERQ!BL87/HAVERQ!W87 -> 91.947917 | DG7: =HAVERQ!BM87/HAVERQ!X87 -> 46.025974 | DH7: =HAVERQ!BN87/HAVERQ!Y87 -> 17.802301 | DI7: =HAVERQ!BO87/HAVERQ!Z87 -> 9.8149663 | DJ7: =HAVERQ!BP87/HAVERQ!AA87 -> 12.945284 | ... DT7: =HAVERQ!BZ87/HAVERQ!AK87 -> 8.9661705 | DU7: =(HAVERQ!CA87+HAVERQ!CB87)/HAVERQ!AL87 -> 10.438202 | FD7: 44105 | FE7: =DataQ!U198+DataQ!V198+DataQ!W198+DataQ!X198+DataQ!Y198 -> 10874 | FF7: =DataQ!J198+DataQ!Q198+DataQ!H198+DataQ!P198+DataQ!S198+DataQ!K198+DataQ!L198 -> 8369 | FG7: =DataQ!N198+DataQ!I198+DataQ!R198+DataQ!G198+DataQ!T198+DataQ!M198+DataQ!O198 -> 15281 | FH7: =DataQ!F198-'Chart Data'!FE7-'Chart Data'!FF7-'Chart Data'!FG7 -> -2 | FJ7: 44105 | FK7: =FE7-(AVERAGE(FE$20:FE$23)) -> -1056.75 | FL7: =FF7-(AVERAGE(FF$20:FF$23)) -> -576.25 | FM7: =FG7-(AVERAGE(FG$20:FG$23)) -> -637.25 | FN7: =SUM(FK7:FM7) -> -2270.25 | FP7: 42095 | FQ7: =100*((AVERAGE(HAVERM!AS429:AS431)/AVERAGE(HAVERM!AS426:AS428))-1) -> 0.85010909 | FR7: =100*((AVERAGE(HAVERM!AT429:AT431)/AVERAGE(HAVERM!AT426:AT428))-1) -> 0.67591939 | FS7: =100*((AVERAGE(HAVERM!AU429:AU431)/AVERAGE(HAVERM!AU426:AU428))-1) -> -2.0363076 | FT7: =100*((AVERAGE(HAVERM!AV429:AV431)/AVERAGE(HAVERM!AV426:AV428))-1) -> 1.0286386 | FU7: =100*((AVERAGE(HAVERM!AW429:AW431)/AVERAGE(HAVERM!AW426:AW428))-1) -> 0.22187484 | FV7: =100*((AVERAGE(HAVERM!AX429:AX431)/AVERAGE(HAVERM!AX426:AX428))-1) -> 1.1093169 | FW7: =100*((AVERAGE(HAVERM!AY429:AY431)/AVERAGE(HAVERM!AY426:AY428))-1) -> 2.2008213 | FX7: =100*((AVERAGE(HAVERM!AZ429:AZ431)/AVERAGE(HAVERM!AZ426:AZ428))-1) -> 0.69672764 | ... GI7: =100*((AVERAGE(HAVERM!BK429:BK431)/AVERAGE(HAVERM!BK426:BK428))-1) -> 1.122939 | GJ7: =100*(((AVERAGE(HAVERM!BL429:BL431)+(AVERAGE(HAVERM!BM429:BM431)))/(AVERAGE(HAVERM!BL426:BL428)+AVERAGE(HAVERM!BM426:BM428))-1)) -> 0.87699487 | GL7: 42095 | GW7: 42095 | GX7: =HAVERM!AT431 -> 179191 | GY7: =HAVERM!AU431+HAVERM!AW431+HAVERM!AX431 -> 307089 | GZ7: =HAVERM!AV431 -> 2375569 | HA7: =HAVERM!AY431 -> 1129528 | HB7: =HAVERM!AZ431+HAVERM!BB431 -> 6187420 | HC7: =HAVERM!BA431+HAVERM!BC431 -> 2272257 | HD7: =HAVERM!BD431 -> 1079581 | HE7: =HAVERM!BE431+HAVERM!BF431+HAVERM!BG431 -> 4704084 | HF7: =HAVERM!BH431+HAVERM!BI431+HAVERM!BJ431+HAVERM!BK431+HAVERM!BL431+HAVERM!BM431 -> 9106124 | HH7: Utilities | HI7: ='ASHE Annual pay All SIC'!D61 -> 51886 | HJ7: 0.94272776 | HL7: Utilities | HM7: ='ASHE Annual pay All SIC'!D61 -> 51886 | HN7: -0.30333333 | HP7: 2010 | HQ7: 17.883927 | HR7: 3.1295946 | HS7: =HQ7+HR7 -> 21.013521 | HU7: 2010 | HV7: 6680.62 | HW7: 1169.0739 | HX7: =HV7+HW7 -> 7849.6939 | HZ7: 43739 | IA7: =HAVERQ!E167 -> 5344 | IB7: =HAVERQ!F167 -> 27759 | IC7: =DataQ!Z194-('Chart Data'!IA7+'Chart Data'!IB7) -> -46 | IE7: 43739 | IF7: =IA7-AVERAGE(IA$4:IA$7) -> 28.25 | IG7: =IB7-AVERAGE(IB$4:IB$7) -> 135 | II7: 43739 | IJ7: =100*(IA7/AVERAGE(IA$4:IA$7)) -> 100.53144 | IK7: =100*(IB7/AVERAGE(IB$4:IB$7)) -> 100.48871 | IM7: 43739 | IN7: =SUM(DataQ!U194:Y194) -> 11018 | IO7: =DataQ!F194-'Chart Data'!IN7 -> 24643 | IQ7: 43739 | IR7: =100*(IN7/AVERAGE(IN$4:IN$7)) -> 100.71068 | IS7: =100*(IO7/AVERAGE(IO$4:IO$7)) -> 100.07411
A8: 43831 | B8: =HAVERQ!E168-AVERAGE(HAVERQ!E$164:E$167) -> 53.25 | C8: =HAVERQ!F168-AVERAGE(HAVERQ!F$164:F$167) -> -174 | E8: 36892 | F8: =HAVERQ!P92 -> 1235 | G8: =HAVERQ!O92 -> 1463 | H8: =HAVERQ!N92 -> 1181 | I8: =HAVERQ!M92 -> 228 | J8: =HAVERQ!L92 -> 215 | K8: =HAVERQ!E92-F8-G8-H8-I8-J8 -> 785 | M8: 36892 | N8: =100*(F8/SUM($F8:$K8)) -> 24.182495 | O8: =100*(G8/SUM($F8:$K8)) -> 28.646955 | P8: =100*(H8/SUM($F8:$K8)) -> 23.125122 | Q8: =100*(I8/SUM($F8:$K8)) -> 4.4644605 | R8: =100*(J8/SUM($F8:$K8)) -> 4.209908 | S8: =100*(K8/SUM($F8:$K8)) -> 15.371059 | U8: 36892 | V8: =F8-AVERAGE(F$4:F$7) -> 25.75 | W8: =G8-AVERAGE(G$4:G$7) -> 23.25 | X8: =H8-AVERAGE(H$4:H$7) -> 2 | Y8: =I8-AVERAGE(I$4:I$7) -> 2.25 | Z8: =J8-AVERAGE(J$4:J$7) -> -1.25 | AA8: =K8-AVERAGE(K$4:K$7) -> -2.75 | AB8: =SUM(V8:AA8) -> 49.25 | AD8: 43831 | AE8: =HAVERQ!T168-AVERAGE(HAVERQ!T$164:T$167) -> -14.25 | AF8: =HAVERQ!U168-AVERAGE(HAVERQ!U$164:U$167) -> 6.75 | AG8: =HAVERQ!V168-AVERAGE(HAVERQ!V$164:V$167) -> -14.75 | AH8: =HAVERQ!W168-AVERAGE(HAVERQ!W$164:W$167) -> 5.25 | AI8: =HAVERQ!X168-AVERAGE(HAVERQ!X$164:X$167) -> -3.5 | AJ8: =HAVERQ!Y168-AVERAGE(HAVERQ!Y$164:Y$167) -> -40.25 | AK8: =HAVERQ!Z168-AVERAGE(HAVERQ!Z$164:Z$167) -> -67.5 | AL8: =HAVERQ!AA168-AVERAGE(HAVERQ!AA$164:AA$167) -> 1 | ... AV8: =HAVERQ!AK168-AVERAGE(HAVERQ!AK$164:AK$167) -> -4.75 | AW8: =AY8-AVERAGE(AY$4:AY$7) -> -28.5 | AY8: =HAVERQ!AL168+HAVERQ!AM168 -> 989 | BA8: 43831 | BB8: =BK8-AVERAGE(BK$4:BK$7) -> -14.25 | BC8: =BL8-AVERAGE(BL$4:BL$7) -> 8.5 | BD8: =BM8-AVERAGE(BM$4:BM$7) -> -14.75 | BE8: =BN8-AVERAGE(BN$4:BN$7) -> -40.25 | BF8: =BO8-AVERAGE(BO$4:BO$7) -> -47.5 | BG8: =BP8-AVERAGE(BP$4:BP$7) -> 49.75 | BH8: =BQ8-AVERAGE(BQ$4:BQ$7) -> 68.5 | BI8: =BR8-AVERAGE(BR$4:BR$7) -> 34.75 | BK8: =HAVERQ!T168 -> 384 | BL8: =HAVERQ!U168+HAVERQ!W168+HAVERQ!X168 -> 434 | BM8: =HAVERQ!V168 -> 2676 | BN8: =HAVERQ!Y168 -> 2293 | BO8: =HAVERQ!Z168+HAVERQ!AB168 -> 7457 | BP8: =HAVERQ!AA168+HAVERQ!AC168 -> 3356 | BQ8: =HAVERQ!AD168+HAVERQ!AE168+HAVERQ!AF168+HAVERQ!AG168 -> 8035 | BR8: =HAVERQ!AH168+HAVERQ!AI168+HAVERQ!AJ168+HAVERQ!AK168+HAVERQ!AL168+HAVERQ!AM168 -> 10975 | BS8: =HAVERQ!S168-SUM('Chart Data'!BK8:BR8) -> -1 | BU8: 34700 | BV8: =HAVERQ!T68 -> 469 | BW8: =HAVERQ!U68+HAVERQ!W68+HAVERQ!X68 -> 340 | BX8: =HAVERQ!V68 -> 4199 | BY8: =HAVERQ!Y68 -> 1844 | BZ8: =HAVERQ!Z68+HAVERQ!AB68 -> 6287 | CA8: =HAVERQ!AA68+HAVERQ!AC68 -> 2097 | CB8: =HAVERQ!AD68+HAVERQ!AE68+HAVERQ!AF68+HAVERQ!AG68 -> 4659 | CC8: =HAVERQ!AH68+HAVERQ!AI68+HAVERQ!AJ68+HAVERQ!AK68+HAVERQ!AL68+HAVERQ!AM68 -> 8034 | CD8: =HAVERQ!S68-SUM('Chart Data'!BV8:CC8) -> 1 | CF8: Height | CG8: 0.5 | CH8: =+CG8+1 -> 1.5 | CI8: =+CH8+1 -> 2.5 | CJ8: =+CI8+1 -> 3.5 | CK8: =+CJ8+1 -> 4.5 | CL8: =+CK8+1 -> 5.5 | CM8: =+CL8+1 -> 6.5 | CN8: =+CM8+1 -> 7.5 | CO8: =+CN8+1 -> 8.5 | ... CZ8: =+CY8+1 -> 19.5 | DB8: 36526 | DC8: =HAVERQ!BI88/HAVERQ!T88 -> 8.1234257 | DD8: =HAVERQ!BJ88/HAVERQ!U88 -> 593.73684 | DE8: =HAVERQ!BK88/HAVERQ!V88 -> 9.6789331 | DF8: =HAVERQ!BL88/HAVERQ!W88 -> 81.489583 | DG8: =HAVERQ!BM88/HAVERQ!X88 -> 45.165605 | DH8: =HAVERQ!BN88/HAVERQ!Y88 -> 18.102148 | DI8: =HAVERQ!BO88/HAVERQ!Z88 -> 10.235186 | DJ8: =HAVERQ!BP88/HAVERQ!AA88 -> 13.541728 | ... DT8: =HAVERQ!BZ88/HAVERQ!AK88 -> 9.1008065 | DU8: =(HAVERQ!CA88+HAVERQ!CB88)/HAVERQ!AL88 -> 11.153465 | DW8: 2019-2024 | DX8: =DX5-DX4 -> 1227.75 | DY8: =DY5-DY4 -> -38 | DZ8: =DZ5-DZ4 -> -13 | EA8: =EA5-EA4 -> -102.75 | EB8: =EB5-EB4 -> -6 | EC8: =EC5-EC4 -> 23.5 | ED8: =ED5-ED4 -> -124.25 | EE8: =EE5-EE4 -> -283 | ... EQ8: =EQ5-EQ4 -> -20 | ES8: 2019-2024 | ET8: =ET5-ET4 -> -38 | EU8: =EU5-EU4 -> 4.5 | EV8: =EV5-EV4 -> -102.75 | EW8: =EW5-EW4 -> -124.25 | EX8: =EX5-EX4 -> -115.75 | EY8: =EY5-EY4 -> 210 | EZ8: =EZ5-EZ4 -> 404.75 | FA8: =FA5-FA4 -> 990.5 | FD8: 44197 | FE8: =DataQ!U199+DataQ!V199+DataQ!W199+DataQ!X199+DataQ!Y199 -> 10964 | FF8: =DataQ!J199+DataQ!Q199+DataQ!H199+DataQ!P199+DataQ!S199+DataQ!K199+DataQ!L199 -> 8418 | FG8: =DataQ!N199+DataQ!I199+DataQ!R199+DataQ!G199+DataQ!T199+DataQ!M199+DataQ!O199 -> 15353 | FH8: =DataQ!F199-'Chart Data'!FE8-'Chart Data'!FF8-'Chart Data'!FG8 -> -1 | FJ8: 44197 | FK8: =FE8-(AVERAGE(FE$20:FE$23)) -> -966.75 | FL8: =FF8-(AVERAGE(FF$20:FF$23)) -> -527.25 | FM8: =FG8-(AVERAGE(FG$20:FG$23)) -> -565.25 | FN8: =SUM(FK8:FM8) -> -2059.25 | FP8: 42125 | FQ8: =100*((AVERAGE(HAVERM!AS430:AS432)/AVERAGE(HAVERM!AS427:AS429))-1) -> 0.81416259 | FR8: =100*((AVERAGE(HAVERM!AT430:AT432)/AVERAGE(HAVERM!AT427:AT429))-1) -> 0.61407697 | FS8: =100*((AVERAGE(HAVERM!AU430:AU432)/AVERAGE(HAVERM!AU427:AU429))-1) -> -2.5842577 | FT8: =100*((AVERAGE(HAVERM!AV430:AV432)/AVERAGE(HAVERM!AV427:AV429))-1) -> 0.9353508 | FU8: =100*((AVERAGE(HAVERM!AW430:AW432)/AVERAGE(HAVERM!AW427:AW429))-1) -> -0.20842766 | FV8: =100*((AVERAGE(HAVERM!AX430:AX432)/AVERAGE(HAVERM!AX427:AX429))-1) -> 0.97402112 | FW8: =100*((AVERAGE(HAVERM!AY430:AY432)/AVERAGE(HAVERM!AY427:AY429))-1) -> 2.2063106 | FX8: =100*((AVERAGE(HAVERM!AZ430:AZ432)/AVERAGE(HAVERM!AZ427:AZ429))-1) -> 0.48713175 | ... GI8: =100*((AVERAGE(HAVERM!BK430:BK432)/AVERAGE(HAVERM!BK427:BK429))-1) -> 1.0562295 | GJ8: =100*(((AVERAGE(HAVERM!BL430:BL432)+(AVERAGE(HAVERM!BM430:BM432)))/(AVERAGE(HAVERM!BL427:BL429)+AVERAGE(HAVERM!BM427:BM429))-1)) -> 0.80609794 | GL8: 42125 | GW8: 42125 | GX8: =HAVERM!AT432 -> 179850 | GY8: =HAVERM!AU432+HAVERM!AW432+HAVERM!AX432 -> 307190 | GZ8: =HAVERM!AV432 -> 2375914 | HA8: =HAVERM!AY432 -> 1134708 | HB8: =HAVERM!AZ432+HAVERM!BB432 -> 6205823 | HC8: =HAVERM!BA432+HAVERM!BC432 -> 2279115 | HD8: =HAVERM!BD432 -> 1080051 | HE8: =HAVERM!BE432+HAVERM!BF432+HAVERM!BG432 -> 4714370 | HF8: =HAVERM!BH432+HAVERM!BI432+HAVERM!BJ432+HAVERM!BK432+HAVERM!BL432+HAVERM!BM432 -> 9122668 | HH8: Water | HI8: ='ASHE Annual pay All SIC'!D63 -> 38435 | HJ8: 0.59868603 | HL8: Water | HM8: ='ASHE Annual pay All SIC'!D63 -> 38435 | HN8: 0.45916667 | HP8: 2011 | HQ8: 17.154498 | HR8: 2.6298741 | HS8: =HQ8+HR8 -> 19.784372 | HU8: 2011 | HV8: 6418.6721 | HW8: 984.01593 | HX8: =HV8+HW8 -> 7402.688 | HZ8: 43831 | IA8: =HAVERQ!E168 -> 5369 | IB8: =HAVERQ!F168 -> 27450 | IC8: =DataQ!Z195-('Chart Data'!IA8+'Chart Data'!IB8) -> 157 | IE8: 43831 | IF8: =IA8-AVERAGE(IA$4:IA$7) -> 53.25 | IG8: =IB8-AVERAGE(IB$4:IB$7) -> -174 | II8: 43831 | IJ8: =100*(IA8/AVERAGE(IA$4:IA$7)) -> 101.00174 | IK8: =100*(IB8/AVERAGE(IB$4:IB$7)) -> 99.370113 | IM8: 43831 | IN8: =SUM(DataQ!U195:Y195) -> 10975 | IO8: =DataQ!F195-'Chart Data'!IN8 -> 24634 | IQ8: 43831 | IR8: =100*(IN8/AVERAGE(IN$4:IN$7)) -> 100.31763 | IS8: =100*(IO8/AVERAGE(IO$4:IO$7)) -> 100.03756
A9: 43922 | B9: =HAVERQ!E169-AVERAGE(HAVERQ!E$164:E$167) -> 97.25 | C9: =HAVERQ!F169-AVERAGE(HAVERQ!F$164:F$167) -> -461 | E9: 36982 | F9: =HAVERQ!P93 -> 1249 | G9: =HAVERQ!O93 -> 1468 | H9: =HAVERQ!N93 -> 1185 | I9: =HAVERQ!M93 -> 229 | J9: =HAVERQ!L93 -> 214 | K9: =HAVERQ!E93-F9-G9-H9-I9-J9 -> 792 | M9: 36982 | N9: =100*(F9/SUM($F9:$K9)) -> 24.313802 | O9: =100*(G9/SUM($F9:$K9)) -> 28.57699 | P9: =100*(H9/SUM($F9:$K9)) -> 23.067938 | Q9: =100*(I9/SUM($F9:$K9)) -> 4.4578548 | R9: =100*(J9/SUM($F9:$K9)) -> 4.1658556 | S9: =100*(K9/SUM($F9:$K9)) -> 15.417559 | U9: 36982 | V9: =F9-AVERAGE(F$4:F$7) -> 39.75 | W9: =G9-AVERAGE(G$4:G$7) -> 28.25 | X9: =H9-AVERAGE(H$4:H$7) -> 6 | Y9: =I9-AVERAGE(I$4:I$7) -> 3.25 | Z9: =J9-AVERAGE(J$4:J$7) -> -2.25 | AA9: =K9-AVERAGE(K$4:K$7) -> 4.25 | AB9: =SUM(V9:AA9) -> 79.25 | AD9: 43922 | AE9: =HAVERQ!T169-AVERAGE(HAVERQ!T$164:T$167) -> -21.25 | AF9: =HAVERQ!U169-AVERAGE(HAVERQ!U$164:U$167) -> -0.25 | AG9: =HAVERQ!V169-AVERAGE(HAVERQ!V$164:V$167) -> -72.75 | AH9: =HAVERQ!W169-AVERAGE(HAVERQ!W$164:W$167) -> 4.25 | AI9: =HAVERQ!X169-AVERAGE(HAVERQ!X$164:X$167) -> -4.5 | AJ9: =HAVERQ!Y169-AVERAGE(HAVERQ!Y$164:Y$167) -> -57.25 | AK9: =HAVERQ!Z169-AVERAGE(HAVERQ!Z$164:Z$167) -> -29.5 | AL9: =HAVERQ!AA169-AVERAGE(HAVERQ!AA$164:AA$167) -> 1 | ... AV9: =HAVERQ!AK169-AVERAGE(HAVERQ!AK$164:AK$167) -> -51.75 | AW9: =AY9-AVERAGE(AY$4:AY$7) -> -40.5 | AY9: =HAVERQ!AL169+HAVERQ!AM169 -> 977 | BA9: 43922 | BB9: =BK9-AVERAGE(BK$4:BK$7) -> -21.25 | BC9: =BL9-AVERAGE(BL$4:BL$7) -> -0.5 | BD9: =BM9-AVERAGE(BM$4:BM$7) -> -72.75 | BE9: =BN9-AVERAGE(BN$4:BN$7) -> -57.25 | BF9: =BO9-AVERAGE(BO$4:BO$7) -> -181.5 | BG9: =BP9-AVERAGE(BP$4:BP$7) -> 21.75 | BH9: =BQ9-AVERAGE(BQ$4:BQ$7) -> -156.5 | BI9: =BR9-AVERAGE(BR$4:BR$7) -> 36.75 | BK9: =HAVERQ!T169 -> 377 | BL9: =HAVERQ!U169+HAVERQ!W169+HAVERQ!X169 -> 425 | BM9: =HAVERQ!V169 -> 2618 | BN9: =HAVERQ!Y169 -> 2276 | BO9: =HAVERQ!Z169+HAVERQ!AB169 -> 7323 | BP9: =HAVERQ!AA169+HAVERQ!AC169 -> 3328 | BQ9: =HAVERQ!AD169+HAVERQ!AE169+HAVERQ!AF169+HAVERQ!AG169 -> 7810 | BR9: =HAVERQ!AH169+HAVERQ!AI169+HAVERQ!AJ169+HAVERQ!AK169+HAVERQ!AL169+HAVERQ!AM169 -> 10977 | BS9: =HAVERQ!S169-SUM('Chart Data'!BK9:BR9) -> 1 | BU9: 34790 | BV9: =HAVERQ!T69 -> 465 | BW9: =HAVERQ!U69+HAVERQ!W69+HAVERQ!X69 -> 337 | BX9: =HAVERQ!V69 -> 4214 | BY9: =HAVERQ!Y69 -> 1856 | BZ9: =HAVERQ!Z69+HAVERQ!AB69 -> 6312 | CA9: =HAVERQ!AA69+HAVERQ!AC69 -> 2109 | CB9: =HAVERQ!AD69+HAVERQ!AE69+HAVERQ!AF69+HAVERQ!AG69 -> 4693 | CC9: =HAVERQ!AH69+HAVERQ!AI69+HAVERQ!AJ69+HAVERQ!AK69+HAVERQ!AL69+HAVERQ!AM69 -> 8061 | CD9: =HAVERQ!S69-SUM('Chart Data'!BV9:CC9) -> 0 | DB9: 36617 | DC9: =HAVERQ!BI89/HAVERQ!T89 -> 8.2481203 | DD9: =HAVERQ!BJ89/HAVERQ!U89 -> 542.57692 | DE9: =HAVERQ!BK89/HAVERQ!V89 -> 9.9065467 | DF9: =HAVERQ!BL89/HAVERQ!W89 -> 77.8 | DG9: =HAVERQ!BM89/HAVERQ!X89 -> 44.962733 | DH9: =HAVERQ!BN89/HAVERQ!Y89 -> 17.232261 | DI9: =HAVERQ!BO89/HAVERQ!Z89 -> 10.494168 | DJ9: =HAVERQ!BP89/HAVERQ!AA89 -> 13.292127 | ... DT9: =HAVERQ!BZ89/HAVERQ!AK89 -> 8.8544474 | DU9: =(HAVERQ!CA89+HAVERQ!CB89)/HAVERQ!AL89 -> 11.009816 | DW9: 2024-2029 | DX9: =DX6-DX5 -> 1935.775 | DY9: =DY6-DY5 -> 2.364 | DZ9: =DZ6-DZ5 -> -5.124315 | EA9: =EA6-EA5 -> -151.60175 | EB9: =EB6-EB5 -> -0.832325 | EC9: =EC6-EC5 -> 6.236875 | ED9: =ED6-ED5 -> 204.85175 | EE9: =EE6-EE5 -> 224.22125 | ... EQ9: =EQ6-EQ5 -> 74.553 | ES9: 2025-2029 | ET9: =ET6-ET5 -> 2.364 | EU9: =EU6-EU5 -> 0.280235 | EV9: =EV6-EV5 -> -151.60175 | EW9: =EW6-EW5 -> 204.85175 | EX9: =EX6-EX5 -> 326.94325 | EY9: =EY6-EY5 -> 284.261 | EZ9: =EZ6-EZ5 -> 558.71665 | FA9: =FA6-FA5 -> 707.4605 | FD9: 44287 | FE9: =DataQ!U200+DataQ!V200+DataQ!W200+DataQ!X200+DataQ!Y200 -> 11078 | FF9: =DataQ!J200+DataQ!Q200+DataQ!H200+DataQ!P200+DataQ!S200+DataQ!K200+DataQ!L200 -> 8495 | FG9: =DataQ!N200+DataQ!I200+DataQ!R200+DataQ!G200+DataQ!T200+DataQ!M200+DataQ!O200 -> 15499 | FH9: =DataQ!F200-'Chart Data'!FE9-'Chart Data'!FF9-'Chart Data'!FG9 -> 0 | FJ9: 44287 | FK9: =FE9-(AVERAGE(FE$20:FE$23)) -> -852.75 | FL9: =FF9-(AVERAGE(FF$20:FF$23)) -> -450.25 | FM9: =FG9-(AVERAGE(FG$20:FG$23)) -> -419.25 | FN9: =SUM(FK9:FM9) -> -1722.25 | FP9: 42156 | FQ9: =100*((AVERAGE(HAVERM!AS431:AS433)/AVERAGE(HAVERM!AS428:AS430))-1) -> 0.65543456 | FR9: =100*((AVERAGE(HAVERM!AT431:AT433)/AVERAGE(HAVERM!AT428:AT430))-1) -> 0.99806145 | FS9: =100*((AVERAGE(HAVERM!AU431:AU433)/AVERAGE(HAVERM!AU428:AU430))-1) -> -3.7028281 | FT9: =100*((AVERAGE(HAVERM!AV431:AV433)/AVERAGE(HAVERM!AV428:AV430))-1) -> 0.3002207 | FU9: =100*((AVERAGE(HAVERM!AW431:AW433)/AVERAGE(HAVERM!AW428:AW430))-1) -> -0.59203194 | FV9: =100*((AVERAGE(HAVERM!AX431:AX433)/AVERAGE(HAVERM!AX428:AX430))-1) -> 0.71836269 | FW9: =100*((AVERAGE(HAVERM!AY431:AY433)/AVERAGE(HAVERM!AY428:AY430))-1) -> 1.4416788 | FX9: =100*((AVERAGE(HAVERM!AZ431:AZ433)/AVERAGE(HAVERM!AZ428:AZ430))-1) -> 0.36596838 | ... GI9: =100*((AVERAGE(HAVERM!BK431:BK433)/AVERAGE(HAVERM!BK428:BK430))-1) -> 1.1236907 | GJ9: =100*(((AVERAGE(HAVERM!BL431:BL433)+(AVERAGE(HAVERM!BM431:BM433)))/(AVERAGE(HAVERM!BL428:BL430)+AVERAGE(HAVERM!BM428:BM430))-1)) -> 0.51072785 | GL9: 42156 | GW9: 42156 | GX9: =HAVERM!AT433 -> 181235 | GY9: =HAVERM!AU433+HAVERM!AW433+HAVERM!AX433 -> 307792 | GZ9: =HAVERM!AV433 -> 2381302 | HA9: =HAVERM!AY433 -> 1141150 | HB9: =HAVERM!AZ433+HAVERM!BB433 -> 6232523 | HC9: =HAVERM!BA433+HAVERM!BC433 -> 2291343 | HD9: =HAVERM!BD433 -> 1085127 | HE9: =HAVERM!BE433+HAVERM!BF433+HAVERM!BG433 -> 4724364 | HF9: =HAVERM!BH433+HAVERM!BI433+HAVERM!BJ433+HAVERM!BK433+HAVERM!BL433+HAVERM!BM433 -> 9117559 | HH9: Construction | HI9: ='ASHE Annual pay All SIC'!D68 -> 38209 | HJ9: -1.3505204 | HL9: Construction | HM9: ='ASHE Annual pay All SIC'!D68 -> 38209 | HN9: 0.53333333 | HP9: 2012 | HQ9: 16.411266 | HR9: 2.4708379 | HS9: =HQ9+HR9 -> 18.882104 | HU9: 2012 | HV9: 6178.2958 | HW9: 930.18829 | HX9: =HV9+HW9 -> 7108.4841 | HZ9: 43922 | IA9: =HAVERQ!E169 -> 5413 | IB9: =HAVERQ!F169 -> 27163 | IC9: =DataQ!Z196-('Chart Data'!IA9+'Chart Data'!IB9) -> 58 | IE9: 43922 | IF9: =IA9-AVERAGE(IA$4:IA$7) -> 97.25 | IG9: =IB9-AVERAGE(IB$4:IB$7) -> -461 | II9: 43922 | IJ9: =100*(IA9/AVERAGE(IA$4:IA$7)) -> 101.82947 | IK9: =100*(IB9/AVERAGE(IB$4:IB$7)) -> 98.331161 | IM9: 43922 | IN9: =SUM(DataQ!U196:Y196) -> 10977 | IO9: =DataQ!F196-'Chart Data'!IN9 -> 24158 | IQ9: 43922 | IR9: =100*(IN9/AVERAGE(IN$4:IN$7)) -> 100.33592 | IS9: =100*(IO9/AVERAGE(IO$4:IO$7)) -> 98.104549
A10: 44013 | B10: =HAVERQ!E170-AVERAGE(HAVERQ!E$164:E$167) -> 104.25 | C10: =HAVERQ!F170-AVERAGE(HAVERQ!F$164:F$167) -> -721 | E10: 37073 | F10: =HAVERQ!P94 -> 1263 | G10: =HAVERQ!O94 -> 1465 | H10: =HAVERQ!N94 -> 1188 | I10: =HAVERQ!M94 -> 231 | J10: =HAVERQ!L94 -> 214 | K10: =HAVERQ!E94-F10-G10-H10-I10-J10 -> 795 | M10: 37073 | N10: =100*(F10/SUM($F10:$K10)) -> 24.495733 | O10: =100*(G10/SUM($F10:$K10)) -> 28.413499 | P10: =100*(H10/SUM($F10:$K10)) -> 23.041117 | Q10: =100*(I10/SUM($F10:$K10)) -> 4.4802172 | R10: =100*(J10/SUM($F10:$K10)) -> 4.1505043 | S10: =100*(K10/SUM($F10:$K10)) -> 15.418929 | U10: 37073 | V10: =F10-AVERAGE(F$4:F$7) -> 53.75 | W10: =G10-AVERAGE(G$4:G$7) -> 25.25 | X10: =H10-AVERAGE(H$4:H$7) -> 9 | Y10: =I10-AVERAGE(I$4:I$7) -> 5.25 | Z10: =J10-AVERAGE(J$4:J$7) -> -2.25 | AA10: =K10-AVERAGE(K$4:K$7) -> 7.25 | AB10: =SUM(V10:AA10) -> 98.25 | AD10: 44013 | AE10: =HAVERQ!T170-AVERAGE(HAVERQ!T$164:T$167) -> 18.75 | AF10: =HAVERQ!U170-AVERAGE(HAVERQ!U$164:U$167) -> -7.25 | AG10: =HAVERQ!V170-AVERAGE(HAVERQ!V$164:V$167) -> -120.75 | AH10: =HAVERQ!W170-AVERAGE(HAVERQ!W$164:W$167) -> 1.25 | AI10: =HAVERQ!X170-AVERAGE(HAVERQ!X$164:X$167) -> 0.5 | AJ10: =HAVERQ!Y170-AVERAGE(HAVERQ!Y$164:Y$167) -> -190.25 | AK10: =HAVERQ!Z170-AVERAGE(HAVERQ!Z$164:Z$167) -> -163.5 | AL10: =HAVERQ!AA170-AVERAGE(HAVERQ!AA$164:AA$167) -> -16 | ... AV10: =HAVERQ!AK170-AVERAGE(HAVERQ!AK$164:AK$167) -> -105.75 | AW10: =AY10-AVERAGE(AY$4:AY$7) -> -78.5 | AY10: =HAVERQ!AL170+HAVERQ!AM170 -> 939 | BA10: 44013 | BB10: =BK10-AVERAGE(BK$4:BK$7) -> 18.75 | BC10: =BL10-AVERAGE(BL$4:BL$7) -> -5.5 | BD10: =BM10-AVERAGE(BM$4:BM$7) -> -120.75 | BE10: =BN10-AVERAGE(BN$4:BN$7) -> -190.25 | BF10: =BO10-AVERAGE(BO$4:BO$7) -> -377.5 | BG10: =BP10-AVERAGE(BP$4:BP$7) -> -4.25 | BH10: =BQ10-AVERAGE(BQ$4:BQ$7) -> -194.5 | BI10: =BR10-AVERAGE(BR$4:BR$7) -> -97.25 | BK10: =HAVERQ!T170 -> 417 | BL10: =HAVERQ!U170+HAVERQ!W170+HAVERQ!X170 -> 420 | BM10: =HAVERQ!V170 -> 2570 | BN10: =HAVERQ!Y170 -> 2143 | BO10: =HAVERQ!Z170+HAVERQ!AB170 -> 7127 | BP10: =HAVERQ!AA170+HAVERQ!AC170 -> 3302 | BQ10: =HAVERQ!AD170+HAVERQ!AE170+HAVERQ!AF170+HAVERQ!AG170 -> 7772 | BR10: =HAVERQ!AH170+HAVERQ!AI170+HAVERQ!AJ170+HAVERQ!AK170+HAVERQ!AL170+HAVERQ!AM170 -> 10843 | BS10: =HAVERQ!S170-SUM('Chart Data'!BK10:BR10) -> 0 | BU10: 34881 | BV10: =HAVERQ!T70 -> 469 | BW10: =HAVERQ!U70+HAVERQ!W70+HAVERQ!X70 -> 333 | BX10: =HAVERQ!V70 -> 4219 | BY10: =HAVERQ!Y70 -> 1843 | BZ10: =HAVERQ!Z70+HAVERQ!AB70 -> 6294 | CA10: =HAVERQ!AA70+HAVERQ!AC70 -> 2109 | CB10: =HAVERQ!AD70+HAVERQ!AE70+HAVERQ!AF70+HAVERQ!AG70 -> 4754 | CC10: =HAVERQ!AH70+HAVERQ!AI70+HAVERQ!AJ70+HAVERQ!AK70+HAVERQ!AL70+HAVERQ!AM70 -> 8024 | CD10: =HAVERQ!S70-SUM('Chart Data'!BV10:CC10) -> 1 | CF10: 2014-2024 average | CI10: =AVERAGE(HAVERM!Y428:Y547) -> 2.4875 | CJ10: =AVERAGE(HAVERM!Z428:Z547) -> 2.4725 | CK10: =AVERAGE(HAVERM!AA428:AA547) -> 3.3033333 | CL10: =AVERAGE(HAVERM!AB428:AB547) -> 2.2075 | CM10: =AVERAGE(HAVERM!AC428:AC547) -> 2.0666667 | CN10: =AVERAGE(HAVERM!AD428:AD547) -> 2.8 | CO10: =AVERAGE(HAVERM!AE428:AE547) -> 2.4191667 | CP10: =AVERAGE(HAVERM!AF428:AF547) -> 4.145 | ... CZ10: =AVERAGE(HAVERM!AP428:AP547) -> 3.2266667 | DB10: 36708 | DC10: =HAVERQ!BI90/HAVERQ!T90 -> 8.5575448 | DD10: =HAVERQ!BJ90/HAVERQ!U90 -> 537.97368 | DE10: =HAVERQ!BK90/HAVERQ!V90 -> 10.103535 | DF10: =HAVERQ!BL90/HAVERQ!W90 -> 77.6 | DG10: =HAVERQ!BM90/HAVERQ!X90 -> 45.378049 | DH10: =HAVERQ!BN90/HAVERQ!Y90 -> 16.968557 | DI10: =HAVERQ!BO90/HAVERQ!Z90 -> 10.304304 | DJ10: =HAVERQ!BP90/HAVERQ!AA90 -> 13.564493 | ... DT10: =HAVERQ!BZ90/HAVERQ!AK90 -> 8.9796472 | DU10: =(HAVERQ!CA90+HAVERQ!CB90)/HAVERQ!AL90 -> 11.081181 | FD10: 44378 | FE10: =DataQ!U201+DataQ!V201+DataQ!W201+DataQ!X201+DataQ!Y201 -> 11116 | FF10: =DataQ!J201+DataQ!Q201+DataQ!H201+DataQ!P201+DataQ!S201+DataQ!K201+DataQ!L201 -> 8537 | FG10: =DataQ!N201+DataQ!I201+DataQ!R201+DataQ!G201+DataQ!T201+DataQ!M201+DataQ!O201 -> 15632 | FH10: =DataQ!F201-'Chart Data'!FE10-'Chart Data'!FF10-'Chart Data'!FG10 -> 1 | FJ10: 44378 | FK10: =FE10-(AVERAGE(FE$20:FE$23)) -> -814.75 | FL10: =FF10-(AVERAGE(FF$20:FF$23)) -> -408.25 | FM10: =FG10-(AVERAGE(FG$20:FG$23)) -> -286.25 | FN10: =SUM(FK10:FM10) -> -1509.25 | FP10: 42186 | FQ10: =100*((AVERAGE(HAVERM!AS432:AS434)/AVERAGE(HAVERM!AS429:AS431))-1) -> 0.65023295 | FR10: =100*((AVERAGE(HAVERM!AT432:AT434)/AVERAGE(HAVERM!AT429:AT431))-1) -> 1.2809987 | FS10: =100*((AVERAGE(HAVERM!AU432:AU434)/AVERAGE(HAVERM!AU429:AU431))-1) -> -3.6868721 | FT10: =100*((AVERAGE(HAVERM!AV432:AV434)/AVERAGE(HAVERM!AV429:AV431))-1) -> 0.24089649 | FU10: =100*((AVERAGE(HAVERM!AW432:AW434)/AVERAGE(HAVERM!AW429:AW431))-1) -> 0.27026056 | FV10: =100*((AVERAGE(HAVERM!AX432:AX434)/AVERAGE(HAVERM!AX429:AX431))-1) -> 0.74316643 | FW10: =100*((AVERAGE(HAVERM!AY432:AY434)/AVERAGE(HAVERM!AY429:AY431))-1) -> 1.4286985 | FX10: =100*((AVERAGE(HAVERM!AZ432:AZ434)/AVERAGE(HAVERM!AZ429:AZ431))-1) -> 0.53111343 | ... GI10: =100*((AVERAGE(HAVERM!BK432:BK434)/AVERAGE(HAVERM!BK429:BK431))-1) -> 1.2911406 | GJ10: =100*(((AVERAGE(HAVERM!BL432:BL434)+(AVERAGE(HAVERM!BM432:BM434)))/(AVERAGE(HAVERM!BL429:BL431)+AVERAGE(HAVERM!BM429:BM431))-1)) -> 0.56328082 | GL10: 42186 | GW10: 42186 | GX10: =HAVERM!AT434 -> 181690 | GY10: =HAVERM!AU434+HAVERM!AW434+HAVERM!AX434 -> 308142 | GZ10: =HAVERM!AV434 -> 2381671 | HA10: =HAVERM!AY434 -> 1144054 | HB10: =HAVERM!AZ434+HAVERM!BB434 -> 6249550 | HC10: =HAVERM!BA434+HAVERM!BC434 -> 2298406 | HD10: =HAVERM!BD434 -> 1086447 | HE10: =HAVERM!BE434+HAVERM!BF434+HAVERM!BG434 -> 4744180 | HF10: =HAVERM!BH434+HAVERM!BI434+HAVERM!BJ434+HAVERM!BK434+HAVERM!BL434+HAVERM!BM434 -> 9126353 | HH10: Wholesale & retail | HI10: ='ASHE Annual pay All SIC'!D72 -> 25560 | HJ10: -0.61715835 | HL10: Wholesale & retail | HM10: ='ASHE Annual pay All SIC'!D72 -> 25560 | HN10: -0.53333333 | HP10: 2013 | HQ10: 15.944478 | HR10: 2.5544611 | HS10: =HQ10+HR10 -> 18.498939 | HU10: 2013 | HV10: 6114.5109 | HW10: 979.60436 | HX10: =HV10+HW10 -> 7094.1152 | HZ10: 44013 | IA10: =HAVERQ!E170 -> 5420 | IB10: =HAVERQ!F170 -> 26903 | IC10: =DataQ!Z197-('Chart Data'!IA10+'Chart Data'!IB10) -> 34 | IE10: 44013 | IF10: =IA10-AVERAGE(IA$4:IA$7) -> 104.25 | IG10: =IB10-AVERAGE(IB$4:IB$7) -> -721 | II10: 44013 | IJ10: =100*(IA10/AVERAGE(IA$4:IA$7)) -> 101.96115 | IK10: =100*(IB10/AVERAGE(IB$4:IB$7)) -> 97.389951 | IM10: 44013 | IN10: =SUM(DataQ!U197:Y197) -> 10843 | IO10: =DataQ!F197-'Chart Data'!IN10 -> 23751 | IQ10: 44013 | IR10: =100*(IN10/AVERAGE(IN$4:IN$7)) -> 99.111081 | IS10: =100*(IO10/AVERAGE(IO$4:IO$7)) -> 96.451741
A11: 44105 | B11: =HAVERQ!E171-AVERAGE(HAVERQ!E$164:E$167) -> 134.25 | C11: =HAVERQ!F171-AVERAGE(HAVERQ!F$164:F$167) -> -804 | E11: 37165 | F11: =HAVERQ!P95 -> 1278 | G11: =HAVERQ!O95 -> 1467 | H11: =HAVERQ!N95 -> 1197 | I11: =HAVERQ!M95 -> 234 | J11: =HAVERQ!L95 -> 214 | K11: =HAVERQ!E95-F11-G11-H11-I11-J11 -> 769 | M11: 37165 | N11: =100*(F11/SUM($F11:$K11)) -> 24.772243 | O11: =100*(G11/SUM($F11:$K11)) -> 28.435743 | P11: =100*(H11/SUM($F11:$K11)) -> 23.202171 | Q11: =100*(I11/SUM($F11:$K11)) -> 4.5357627 | R11: =100*(J11/SUM($F11:$K11)) -> 4.1480907 | S11: =100*(K11/SUM($F11:$K11)) -> 14.90599 | U11: 37165 | V11: =F11-AVERAGE(F$4:F$7) -> 68.75 | W11: =G11-AVERAGE(G$4:G$7) -> 27.25 | X11: =H11-AVERAGE(H$4:H$7) -> 18 | Y11: =I11-AVERAGE(I$4:I$7) -> 8.25 | Z11: =J11-AVERAGE(J$4:J$7) -> -2.25 | AA11: =K11-AVERAGE(K$4:K$7) -> -18.75 | AB11: =SUM(V11:AA11) -> 101.25 | AD11: 44105 | AE11: =HAVERQ!T171-AVERAGE(HAVERQ!T$164:T$167) -> -18.25 | AF11: =HAVERQ!U171-AVERAGE(HAVERQ!U$164:U$167) -> -8.25 | AG11: =HAVERQ!V171-AVERAGE(HAVERQ!V$164:V$167) -> -134.75 | AH11: =HAVERQ!W171-AVERAGE(HAVERQ!W$164:W$167) -> 4.25 | AI11: =HAVERQ!X171-AVERAGE(HAVERQ!X$164:X$167) -> 0.5 | AJ11: =HAVERQ!Y171-AVERAGE(HAVERQ!Y$164:Y$167) -> -179.25 | AK11: =HAVERQ!Z171-AVERAGE(HAVERQ!Z$164:Z$167) -> -174.5 | AL11: =HAVERQ!AA171-AVERAGE(HAVERQ!AA$164:AA$167) -> -47 | ... AV11: =HAVERQ!AK171-AVERAGE(HAVERQ!AK$164:AK$167) -> -119.75 | AW11: =AY11-AVERAGE(AY$4:AY$7) -> -88.5 | AY11: =HAVERQ!AL171+HAVERQ!AM171 -> 929 | BA11: 44105 | BB11: =BK11-AVERAGE(BK$4:BK$7) -> -18.25 | BC11: =BL11-AVERAGE(BL$4:BL$7) -> -3.5 | BD11: =BM11-AVERAGE(BM$4:BM$7) -> -134.75 | BE11: =BN11-AVERAGE(BN$4:BN$7) -> -179.25 | BF11: =BO11-AVERAGE(BO$4:BO$7) -> -478.5 | BG11: =BP11-AVERAGE(BP$4:BP$7) -> -42.25 | BH11: =BQ11-AVERAGE(BQ$4:BQ$7) -> -118.5 | BI11: =BR11-AVERAGE(BR$4:BR$7) -> -66.25 | BK11: =HAVERQ!T171 -> 380 | BL11: =HAVERQ!U171+HAVERQ!W171+HAVERQ!X171 -> 422 | BM11: =HAVERQ!V171 -> 2556 | BN11: =HAVERQ!Y171 -> 2154 | BO11: =HAVERQ!Z171+HAVERQ!AB171 -> 7026 | BP11: =HAVERQ!AA171+HAVERQ!AC171 -> 3264 | BQ11: =HAVERQ!AD171+HAVERQ!AE171+HAVERQ!AF171+HAVERQ!AG171 -> 7848 | BR11: =HAVERQ!AH171+HAVERQ!AI171+HAVERQ!AJ171+HAVERQ!AK171+HAVERQ!AL171+HAVERQ!AM171 -> 10874 | BS11: =HAVERQ!S171-SUM('Chart Data'!BK11:BR11) -> -2 | BU11: 34973 | BV11: =HAVERQ!T71 -> 471 | BW11: =HAVERQ!U71+HAVERQ!W71+HAVERQ!X71 -> 337 | BX11: =HAVERQ!V71 -> 4273 | BY11: =HAVERQ!Y71 -> 1837 | BZ11: =HAVERQ!Z71+HAVERQ!AB71 -> 6334 | CA11: =HAVERQ!AA71+HAVERQ!AC71 -> 2100 | CB11: =HAVERQ!AD71+HAVERQ!AE71+HAVERQ!AF71+HAVERQ!AG71 -> 4798 | CC11: =HAVERQ!AH71+HAVERQ!AI71+HAVERQ!AJ71+HAVERQ!AK71+HAVERQ!AL71+HAVERQ!AM71 -> 8042 | CD11: =HAVERQ!S71-SUM('Chart Data'!BV11:CC11) -> 0 | CF11: Diff vs average of past 10 years | CI11: =CI4-CI10 -> 0.77916667 | CJ11: =CJ4-CJ10 -> -0.30583333 | CK11: =CK4-CK10 -> -0.30333333 | CL11: =CL4-CL10 -> 0.45916667 | CM11: =CM4-CM10 -> 0.53333333 | CN11: =CN4-CN10 -> -0.53333333 | CO11: =CO4-CO10 -> -0.31916667 | CP11: =CP4-CP10 -> -0.91166667 | ... CZ11: =CZ4-CZ10 -> -1.06 | DB11: 36800 | DC11: =HAVERQ!BI91/HAVERQ!T91 -> 8.9177719 | DD11: =HAVERQ!BJ91/HAVERQ!U91 -> 519.67105 | DE11: =HAVERQ!BK91/HAVERQ!V91 -> 10.453893 | DF11: =HAVERQ!BL91/HAVERQ!W91 -> 80.737374 | DG11: =HAVERQ!BM91/HAVERQ!X91 -> 44.939394 | DH11: =HAVERQ!BN91/HAVERQ!Y91 -> 17.304236 | DI11: =HAVERQ!BO91/HAVERQ!Z91 -> 10.183711 | DJ11: =HAVERQ!BP91/HAVERQ!AA91 -> 13.234832 | ... DT11: =HAVERQ!BZ91/HAVERQ!AK91 -> 9.0147651 | DU11: =(HAVERQ!CA91+HAVERQ!CB91)/HAVERQ!AL91 -> 10.566998 | DW11: 2019-2024 | DX11: =100*((DX5/DX4)^(1/5)-1) -> 0.68108504 | DY11: =100*((DY5/DY4)^(1/5)-1) -> -1.9856552 | DZ11: =100*((DZ5/DZ4)^(1/5)-1) -> -4.65932 | EA11: =100*((EA5/EA4)^(1/5)-1) -> -0.77566782 | EB11: =100*((EB5/EB4)^(1/5)-1) -> -0.86126932 | EC11: =100*((EC5/EC4)^(1/5)-1) -> 2.0283864 | ED11: =100*((ED5/ED4)^(1/5)-1) -> -1.0884772 | EE11: =100*((EE5/EE4)^(1/5)-1) -> -1.1572317 | ... EQ11: =100*((EQ5/EQ4)^(1/5)-1) -> -0.39624823 | ES11: 2019-2024 | ET11: =100*((ET5/ET4)^(1/5)-1) -> -1.9856552 | EU11: =100*((EU5/EU4)^(1/5)-1) -> 0.21062672 | EV11: =100*((EV5/EV4)^(1/5)-1) -> -0.77566782 | EW11: =100*((EW5/EW4)^(1/5)-1) -> -1.0884772 | EX11: =100*((EX5/EX4)^(1/5)-1) -> -0.3104026 | EY11: =100*((EY5/EY4)^(1/5)-1) -> 1.2392248 | EZ11: =100*((EZ5/EZ4)^(1/5)-1) -> 0.99608759 | FA11: =100*((FA5/FA4)^(1/5)-1) -> 1.7485198 | FD11: 44470 | FE11: =DataQ!U202+DataQ!V202+DataQ!W202+DataQ!X202+DataQ!Y202 -> 11143 | FF11: =DataQ!J202+DataQ!Q202+DataQ!H202+DataQ!P202+DataQ!S202+DataQ!K202+DataQ!L202 -> 8560 | FG11: =DataQ!N202+DataQ!I202+DataQ!R202+DataQ!G202+DataQ!T202+DataQ!M202+DataQ!O202 -> 15625 | FH11: =DataQ!F202-'Chart Data'!FE11-'Chart Data'!FF11-'Chart Data'!FG11 -> 0 | FJ11: 44470 | FK11: =FE11-(AVERAGE(FE$20:FE$23)) -> -787.75 | FL11: =FF11-(AVERAGE(FF$20:FF$23)) -> -385.25 | FM11: =FG11-(AVERAGE(FG$20:FG$23)) -> -293.25 | FN11: =SUM(FK11:FM11) -> -1466.25 | FP11: 42217 | FQ11: =100*((AVERAGE(HAVERM!AS433:AS435)/AVERAGE(HAVERM!AS430:AS432))-1) -> 0.61887583 | FR11: =100*((AVERAGE(HAVERM!AT433:AT435)/AVERAGE(HAVERM!AT430:AT432))-1) -> 1.3148126 | FS11: =100*((AVERAGE(HAVERM!AU433:AU435)/AVERAGE(HAVERM!AU430:AU432))-1) -> -3.7137081 | FT11: =100*((AVERAGE(HAVERM!AV433:AV435)/AVERAGE(HAVERM!AV430:AV432))-1) -> 0.26612177 | FU11: =100*((AVERAGE(HAVERM!AW433:AW435)/AVERAGE(HAVERM!AW430:AW432))-1) -> 1.0183871 | FV11: =100*((AVERAGE(HAVERM!AX433:AX435)/AVERAGE(HAVERM!AX430:AX432))-1) -> 0.82981493 | FW11: =100*((AVERAGE(HAVERM!AY433:AY435)/AVERAGE(HAVERM!AY430:AY432))-1) -> 1.3114366 | FX11: =100*((AVERAGE(HAVERM!AZ433:AZ435)/AVERAGE(HAVERM!AZ430:AZ432))-1) -> 0.62974745 | ... GI11: =100*((AVERAGE(HAVERM!BK433:BK435)/AVERAGE(HAVERM!BK430:BK432))-1) -> 1.456907 | GJ11: =100*(((AVERAGE(HAVERM!BL433:BL435)+(AVERAGE(HAVERM!BM433:BM435)))/(AVERAGE(HAVERM!BL430:BL432)+AVERAGE(HAVERM!BM430:BM432))-1)) -> 0.60773993 | GL11: 42217 | GW11: 42217 | GX11: =HAVERM!AT435 -> 181556 | GY11: =HAVERM!AU435+HAVERM!AW435+HAVERM!AX435 -> 308203 | GZ11: =HAVERM!AV435 -> 2382052 | HA11: =HAVERM!AY435 -> 1147500 | HB11: =HAVERM!AZ435+HAVERM!BB435 -> 6262436 | HC11: =HAVERM!BA435+HAVERM!BC435 -> 2304318 | HD11: =HAVERM!BD435 -> 1084526 | HE11: =HAVERM!BE435+HAVERM!BF435+HAVERM!BG435 -> 4756642 | HF11: =HAVERM!BH435+HAVERM!BI435+HAVERM!BJ435+HAVERM!BK435+HAVERM!BL435+HAVERM!BM435 -> 9132772 | HH11: Transport | HI11: ='ASHE Annual pay All SIC'!D76 -> 35868 | HJ11: 0.17328294 | HL11: Transport | HM11: ='ASHE Annual pay All SIC'!D76 -> 35868 | HN11: -0.31916667 | HP11: 2014 | HQ11: 15.434557 | HR11: 2.6648364 | HS11: =HQ11+HR11 -> 18.099394 | HU11: 2014 | HV11: 6035.0367 | HW11: 1041.9726 | HX11: =HV11+HW11 -> 7077.0093 | HZ11: 44105 | IA11: =HAVERQ!E171 -> 5450 | IB11: =HAVERQ!F171 -> 26820 | IC11: =DataQ!Z198-('Chart Data'!IA11+'Chart Data'!IB11) -> -2 | IE11: 44105 | IF11: =IA11-AVERAGE(IA$4:IA$7) -> 134.25 | IG11: =IB11-AVERAGE(IB$4:IB$7) -> -804 | II11: 44105 | IJ11: =100*(IA11/AVERAGE(IA$4:IA$7)) -> 102.52551 | IK11: =100*(IB11/AVERAGE(IB$4:IB$7)) -> 97.089487 | IM11: 44105 | IN11: =SUM(DataQ!U198:Y198) -> 10874 | IO11: =DataQ!F198-'Chart Data'!IN11 -> 23648 | IQ11: 44105 | IR11: =100*(IN11/AVERAGE(IN$4:IN$7)) -> 99.394438 | IS11: =100*(IO11/AVERAGE(IO$4:IO$7)) -> 96.033462
