Workbook

Sheet CHARTS>>

Sheet DATA>>

Sheet Chart Data
A1: Budget policy decisions | I1: OBR fiscal impulse | M1: Headroom | P1: Revenues & spending | T1: Inflation forecasts | Z1: Real government spending across fiscal events | CF1: Real government spending across fiscal events | FB1: GDP forecasts compared
Z2: Real PSCE in RDEL per head (2024-2025=100) | AI2: Real PSGI in RDEL per head (2025-2026=100) | AR2: Real PSCE in RDEL per head (2024-2025 prices) | BA2: Real PSGI in RDEL per head (2024-2025 prices) | BJ2: PSCE in RDEL per head | BS2: PSGI in RDEL per head | CF2: Real PSCE in RDEL (2025-2026=100) | CP2: Real PSGI in RDEL (2025-2026=100) | CZ2: Real PSCE in RDEL (2024-2025 prices) | DI2: Real PSGI in RDEL (2024-2025 prices) | DR2: PSCE in RDEL | EA2: PSGI in RDEL | EJ2: GDP deflator (2025-2026 = 100) | ES2: GDP deflator (raw)
Z3: 44621 | AA3: 44866 | AB3: 44986 | AC3: 45231 | AD3: 45352 | AE3: 45566 | AF3: 45717 | AG3: 45962 | AI3: =Z3 -> 44621 | AJ3: =AA3 -> 44866 | AK3: =AB3 -> 44986 | AL3: =AC3 -> 45231 | AM3: =AD3 -> 45352 | AN3: =AE3 -> 45566 | AO3: =AF3 -> 45717 | AP3: 45962 | AR3: =Z3 -> 44621 | AS3: =AA3 -> 44866 | AT3: =AB3 -> 44986 | AU3: =AC3 -> 45231 | AV3: =AD3 -> 45352 | AW3: =AE3 -> 45566 | AX3: =AF3 -> 45717 | AY3: 45962 | BA3: =Z3 -> 44621 | BB3: =AA3 -> 44866 | BC3: =AB3 -> 44986 | BD3: =AC3 -> 45231 | BE3: =AD3 -> 45352 | BF3: =AE3 -> 45566 | BG3: =AF3 -> 45717 | BH3: 45962 | BJ3: =Z3 -> 44621 | BK3: =AA3 -> 44866 | BL3: =AB3 -> 44986 | BM3: =AC3 -> 45231 | BN3: =AD3 -> 45352 | BO3: =AE3 -> 45566 | BP3: =AF3 -> 45717 | BQ3: 45962 | BS3: =Z3 -> 44621 | BT3: =AA3 -> 44866 | BU3: =AB3 -> 44986 | BV3: =AC3 -> 45231 | BW3: =AD3 -> 45352 | BX3: =AE3 -> 45566 | BY3: =AF3 -> 45717 | BZ3: 45962 | CF3: =Z3 -> 44621 | CG3: =AA3 -> 44866 | CH3: =AB3 -> 44986 | CI3: =AC3 -> 45231 | CJ3: =AD3 -> 45352 | CK3: =AE3 -> 45566 | CL3: =AF3 -> 45717 | CM3: 45962 | CP3: =Z3 -> 44621 | CQ3: =AA3 -> 44866 | CR3: =AB3 -> 44986 | CS3: =AC3 -> 45231 | CT3: =AD3 -> 45352 | CU3: =AE3 -> 45566 | CV3: =AF3 -> 45717 | CW3: 45962 | CZ3: =Z3 -> 44621 | DA3: =AA3 -> 44866 | DB3: =AB3 -> 44986 | DC3: =AC3 -> 45231 | DD3: =AD3 -> 45352 | DE3: =AE3 -> 45566 | DF3: =AF3 -> 45717 | DG3: 45962 | DI3: =Z3 -> 44621 | DJ3: =AA3 -> 44866 | DK3: =AB3 -> 44986 | DL3: =AC3 -> 45231 | DM3: =AD3 -> 45352 | DN3: =AE3 -> 45566 | DO3: =AF3 -> 45717 | DP3: 45962 | DR3: =Z3 -> 44621 | DS3: =AA3 -> 44866 | DT3: =AB3 -> 44986 | DU3: =AC3 -> 45231 | DV3: =AD3 -> 45352 | DW3: =AE3 -> 45566 | DX3: =AF3 -> 45717 | DY3: 45962 | EA3: =Z3 -> 44621 | EB3: =AA3 -> 44866 | EC3: =AB3 -> 44986 | ED3: =AC3 -> 45231 | EE3: =AD3 -> 45352 | EF3: =AE3 -> 45566 | EG3: =AF3 -> 45717 | EH3: 45962 | EJ3: =Z3 -> 44621 | EK3: =AA3 -> 44866 | EL3: =AB3 -> 44986 | EM3: =AC3 -> 45231 | EN3: =AD3 -> 45352 | EO3: =AE3 -> 45566 | EP3: =AF3 -> 45717 | EQ3: 45962 | ES3: =Z3 -> 44621 | ET3: =AA3 -> 44866 | EU3: =AB3 -> 44986 | EV3: =AC3 -> 45231 | EW3: =AD3 -> 45352 | EX3: =AE3 -> 45566 | EY3: =AF3 -> 45717 | EZ3: 45962
B4: 2025-2026 | C4: 2026-2027 | D4: 2027-2028 | E4: 2028-2029 | F4: 2029-2030 | G4: 2030-2031 | K4: Fiscal impulse | N4: Headroom | Q4: Revenues | R4: Spending | U4: OE November forecast | V4: OE post-Budget forecast | W4: 2% LINE | Z4: Spring Statement (Mar22) | AA4: AS22 | AB4: Budget (Mar23) | AC4: AS23 | AD4: Budget (Mar24) | AE4: Budget (Oct24) | AF4: Spring forecast (Mar25) | AG4: Budget (Nov25) | AI4: =Z4 -> Spring Statement (Mar22) | AJ4: =AA4 -> AS22 | AK4: =AB4 -> Budget (Mar23) | AL4: =AC4 -> AS23 | AM4: =AD4 -> Budget (Mar24) | AN4: =AE4 -> Budget (Oct24) | AO4: =AF4 -> Spring forecast (Mar25) | AP4: Budget (Nov25) | AR4: =Z4 -> Spring Statement (Mar22) | AS4: =AA4 -> AS22 | AT4: =AB4 -> Budget (Mar23) | AU4: =AC4 -> AS23 | AV4: =AD4 -> Budget (Mar24) | AW4: =AE4 -> Budget (Oct24) | AX4: =AF4 -> Spring forecast (Mar25) | AY4: Budget (Nov25) | BA4: =Z4 -> Spring Statement (Mar22) | BB4: =AA4 -> AS22 | BC4: =AB4 -> Budget (Mar23) | BD4: =AC4 -> AS23 | BE4: =AD4 -> Budget (Mar24) | BF4: =AE4 -> Budget (Oct24) | BG4: =AF4 -> Spring forecast (Mar25) | BH4: Budget (Nov25) | BJ4: =Z4 -> Spring Statement (Mar22) | BK4: =AA4 -> AS22 | BL4: =AB4 -> Budget (Mar23) | BM4: =AC4 -> AS23 | BN4: =AD4 -> Budget (Mar24) | BO4: =AE4 -> Budget (Oct24) | BP4: =AF4 -> Spring forecast (Mar25) | BQ4: Budget (Nov25) | BS4: =Z4 -> Spring Statement (Mar22) | BT4: =AA4 -> AS22 | BU4: =AB4 -> Budget (Mar23) | BV4: =AC4 -> AS23 | BW4: =AD4 -> Budget (Mar24) | BX4: =AE4 -> Budget (Oct24) | BY4: =AF4 -> Spring forecast (Mar25) | BZ4: Budget (Nov25) | CC4: Population | CF4: =Z4 -> Spring Statement (Mar22) | CG4: =AA4 -> AS22 | CH4: =AB4 -> Budget (Mar23) | CI4: =AC4 -> AS23 | CJ4: =AD4 -> Budget (Mar24) | CK4: =AE4 -> Budget (Oct24) | CL4: =AF4 -> Spring forecast (Mar25) | CM4: Budget (Nov25) | CN4: 100 LINE | CP4: =Z4 -> Spring Statement (Mar22) | CQ4: =AA4 -> AS22 | CR4: =AB4 -> Budget (Mar23) | CS4: =AC4 -> AS23 | CT4: =AD4 -> Budget (Mar24) | CU4: =AE4 -> Budget (Oct24) | CV4: =AF4 -> Spring forecast (Mar25) | CW4: Budget (Nov25) | CX4: 100 LINE | CZ4: =Z4 -> Spring Statement (Mar22) | DA4: =AA4 -> AS22 | DB4: =AB4 -> Budget (Mar23) | DC4: =AC4 -> AS23 | DD4: =AD4 -> Budget (Mar24) | DE4: =AE4 -> Budget (Oct24) | DF4: =AF4 -> Spring forecast (Mar25) | DG4: Budget (Nov25) | DI4: =Z4 -> Spring Statement (Mar22) | DJ4: =AA4 -> AS22 | DK4: =AB4 -> Budget (Mar23) | DL4: =AC4 -> AS23 | DM4: =AD4 -> Budget (Mar24) | DN4: =AE4 -> Budget (Oct24) | DO4: =AF4 -> Spring forecast (Mar25) | DP4: Budget (Nov25) | DR4: =Z4 -> Spring Statement (Mar22) | DS4: =AA4 -> AS22 | DT4: =AB4 -> Budget (Mar23) | DU4: =AC4 -> AS23 | DV4: =AD4 -> Budget (Mar24) | DW4: =AE4 -> Budget (Oct24) | DX4: =AF4 -> Spring forecast (Mar25) | DY4: Budget (Nov25) | EA4: =Z4 -> Spring Statement (Mar22) | EB4: =AA4 -> AS22 | EC4: =AB4 -> Budget (Mar23) | ED4: =AC4 -> AS23 | EE4: =AD4 -> Budget (Mar24) | EF4: =AE4 -> Budget (Oct24) | EG4: =AF4 -> Spring forecast (Mar25) | EH4: Budget (Nov25) | EJ4: =Z4 -> Spring Statement (Mar22) | EK4: =AA4 -> AS22 | EL4: =AB4 -> Budget (Mar23) | EM4: =AC4 -> AS23 | EN4: =AD4 -> Budget (Mar24) | EO4: =AE4 -> Budget (Oct24) | EP4: =AF4 -> Spring forecast (Mar25) | EQ4: Budget (Nov25) | ES4: =Z4 -> Spring Statement (Mar22) | ET4: =AA4 -> AS22 | EU4: =AB4 -> Budget (Mar23) | EV4: =AC4 -> AS23 | EW4: =AD4 -> Budget (Mar24) | EX4: =AE4 -> Budget (Oct24) | EY4: =AF4 -> Spring forecast (Mar25) | EZ4: Budget (Nov25) | FC4: OBR (Nov25) | FD4: OBR (Mar25) | FE4: OE (Nov25)
A5: Tax | B5: =PresentationalScorecardRounded!I108 -> 70 | C5: =PresentationalScorecardRounded!J108 -> -1905 | D5: =PresentationalScorecardRounded!K108 -> 2890 | E5: =PresentationalScorecardRounded!L108 -> 10730 | F5: =PresentationalScorecardRounded!M108 -> 23150 | G5: =PresentationalScorecardRounded!N108 -> 26645 | I5: ='Aggregates (per cent of GDP)'!B57 -> 2000-01 | J5: =LEFT(I5,4) -> 2000 | K5: =-('Aggregates (per cent of GDP)'!M57-'Aggregates (per cent of GDP)'!M56) -> -0.014043284 | M5: 2010-2019 | N5: =AVERAGE(OBR_NOV25_C7.3!C27:C45) -> 33.984636 | P5: ='Aggregates (per cent of GDP)'!B5 -> 1948-49 | Q5: ='Aggregates (per cent of GDP)'!C5 -> 42.940919 | R5: ='Aggregates (per cent of GDP)'!D5 -> 38.599562 | T5: ='[1]CPI Forecast'!A342 -> 45292 | U5: ='[3]CPI Forecast'!F342 -> 3.9811146 | V5: ='[3]CPI Forecast'!D342 -> 3.9811146 | W5: 2 | Y5: 19-20 | Z5: =100*(AR5/AR$10) -> 90.99234 | AI5: =100*(BA5/BA$11) -> 70.963367 | AR5: =100*(BJ5/EJ5) -> 5.5851589 | BA5: =100*(BS5/EJ5) -> 1.0059249 | BJ5: =DR5/($CC5/1000) -> 4.8181184 | BS5: =EA5/($CC5/1000) -> 0.86777571 | CB5: 202001 | CC5: =VLOOKUP(CB5,DataQ!$C$7:$E$358,3,FALSE) -> 66712 | CE5: =Y5 -> 19-20 | CF5: =100*(CZ5/CZ$11) -> 85.577018 | CN5: 100 | CP5: =100*(DI5/DI$11) -> 67.606994 | CX5: 100 | CZ5: =100*(DR5/EJ5) -> 372.59712 | DI5: =100*(EA5/EJ5) -> 67.107261 | DR5: ='[2]Chart Data'!CJ5 -> 321.42632 | EA5: ='[2]Chart Data'!CR5 -> 57.891053 | EJ5: =100*(ES5/ES$11) -> 86.266451 | EK5: =100*(ET5/ET$11) -> 85.633753 | EL5: =100*(EU5/EU$11) -> 85.312398 | EM5: =100*(EV5/EV$11) -> 81.67592 | EN5: =100*(EW5/EW$11) -> 82.241835 | EO5: =100*(EX5/EX$11) -> 80.45333 | EP5: =100*(EY5/EY$11) -> 78.844029 | EQ5: =100*(EZ5/EZ$11) -> #DIV/0! | ES5: ='[2]Chart Data'!DH5 -> 100.74871 | ET5: ='[2]Chart Data'!DI5 -> 100.88484 | EU5: ='[2]Chart Data'!DJ5 -> 100.88484 | EV5: ='[2]Chart Data'!DK5 -> 100.73409 | EW5: ='[2]Chart Data'!DL5 -> 100.73409 | EX5: ='[2]Chart Data'!DM5 -> 100.73409 | EY5: ='[2]Chart Data'!DN5 -> 90.938577 | FB5: 2024 | FC5: =100*(OBR_NOV25_ST1.1!R114/OBR_NOV25_ST1.1!$R$114) -> 100 | FD5: =100*(OBR_MAR25_ST1.1!R110/OBR_MAR25_ST1.1!$R$110) -> 100 | FE5: =100*(FG5/$FG$5) -> 100 | FG5: =SUMIF(DataQ!A:A,'Chart Data'!FB5,DataQ!F:F) -> 2783075
A6: Spending | B6: =PresentationalScorecardRounded!I107 -> -4200 | C6: =PresentationalScorecardRounded!J107 -> -7410 | D6: =PresentationalScorecardRounded!K107 -> -10330 | E6: =PresentationalScorecardRounded!L107 -> -7305 | F6: =PresentationalScorecardRounded!M107 -> -2615 | G6: =PresentationalScorecardRounded!N107 -> -2535 | I6: ='Aggregates (per cent of GDP)'!B58 -> 2001-02 | J6: =LEFT(I6,4) -> 2001 | K6: =-('Aggregates (per cent of GDP)'!M58-'Aggregates (per cent of GDP)'!M57) -> 1.9511056 | M6: Sunak | N6: =AVERAGE(OBR_NOV25_C7.3!C46:C48) -> 26.014549 | P6: =OBR_NOV25_C4.1!B30 -> 1949-50 | Q6: ='Aggregates (per cent of GDP)'!C6 -> 43.298545 | R6: ='Aggregates (per cent of GDP)'!D6 -> 38.474813 | T6: ='[1]CPI Forecast'!A343 -> 45323 | U6: ='[3]CPI Forecast'!F343 -> 3.4114722 | V6: ='[3]CPI Forecast'!D343 -> 3.4114722 | W6: 2 | Y6: 20-21 | Z6: =100*(AR6/AR$10) -> 116.01458 | AI6: =100*(BA6/BA$11) -> 83.964623 | AR6: =100*(BJ6/EJ6) -> 7.1210373 | BA6: =100*(BS6/EJ6) -> 1.1902212 | BJ6: =DR6/($CC6/1000) -> 6.4932374 | BS6: =EA6/($CC6/1000) -> 1.0852897 | CB6: =+CB5+100 -> 202101 | CC6: =VLOOKUP(CB6,DataQ!$C$7:$E$358,3,FALSE) -> 66918.5 | CE6: =Y6 -> 20-21 | CF6: =100*(CZ6/CZ$11) -> 109.44782 | CN6: 100 | CP6: =100*(DI6/DI$11) -> 80.240938 | CX6: 100 | CZ6: =100*(DR6/EJ6) -> 476.52914 | DI6: =100*(EA6/EJ6) -> 79.647818 | DR6: ='[2]Chart Data'!CJ6 -> 434.5177 | EA6: ='[2]Chart Data'!CR6 -> 72.625962 | EJ6: =100*(ES6/ES$11) -> 91.183869 | EK6: =100*(ET6/ET$11) -> 91.036341 | EL6: =100*(EU6/EU$11) -> 90.569204 | EM6: =100*(EV6/EV$11) -> 86.027982 | EN6: =100*(EW6/EW$11) -> 86.624052 | EO6: =100*(EX6/EX$11) -> 84.740247 | EP6: =100*(EY6/EY$11) -> 82.977176 | EQ6: =100*(EZ6/EZ$11) -> #DIV/0! | ES6: ='[2]Chart Data'!DH6 -> 106.49166 | ET6: ='[2]Chart Data'!DI6 -> 107.24961 | EU6: ='[2]Chart Data'!DJ6 -> 107.10119 | EV6: ='[2]Chart Data'!DK6 -> 106.10166 | EW6: ='[2]Chart Data'!DL6 -> 106.10166 | EX6: ='[2]Chart Data'!DM6 -> 106.10166 | EY6: ='[2]Chart Data'!DN6 -> 95.705742 | FB6: 2025 | FC6: =100*(OBR_NOV25_ST1.1!R115/OBR_NOV25_ST1.1!$R$114) -> 101.48334 | FD6: =100*(OBR_MAR25_ST1.1!R111/OBR_MAR25_ST1.1!$R$110) -> 100.97159 | FE6: =100*(FG6/$FG$5) -> 101.41727 | FG6: =SUMIF(DataQ!A:A,'Chart Data'!FB6,DataQ!F:F) -> 2822518.8
A7: Total | B7: =SUM(B5:B6) -> -4130 | C7: =SUM(C5:C6) -> -9315 | D7: =SUM(D5:D6) -> -7440 | E7: =SUM(E5:E6) -> 3425 | F7: =SUM(F5:F6) -> 20535 | G7: =SUM(G5:G6) -> 24110 | I7: ='Aggregates (per cent of GDP)'!B59 -> 2002-03 | J7: =LEFT(I7,4) -> 2002 | K7: =-('Aggregates (per cent of GDP)'!M59-'Aggregates (per cent of GDP)'!M58) -> 2.0209111 | M7: Hunt | N7: =AVERAGE(OBR_NOV25_C7.3!C50:C52) -> 9.9622058 | P7: =OBR_NOV25_C4.1!B31 -> 1950-51 | Q7: ='Aggregates (per cent of GDP)'!C7 -> 42.841444 | R7: ='Aggregates (per cent of GDP)'!D7 -> 39.183673 | T7: ='[1]CPI Forecast'!A344 -> 45352 | U7: ='[3]CPI Forecast'!F344 -> 3.2280593 | V7: ='[3]CPI Forecast'!D344 -> 3.2280593 | W7: 2 | Y7: 21-22 | Z7: =100*(AR7/AR$10) -> 108.21144 | AA7: =100*(AS7/AS$10) -> 110.92075 | AB7: =100*(AT7/AT$10) -> 110.06915 | AI7: =100*(BA7/BA$11) -> 80.06318 | AJ7: =100*(BB7/BB$11) -> 92.126901 | AK7: =100*(BC7/BC$11) -> 91.416586 | AR7: =100*(BJ7/EJ7) -> 6.6420763 | AS7: =100*(BK7/EK7) -> 6.7598794 | AT7: =100*(BL7/EL7) -> 6.8111688 | BA7: =100*(BS7/EJ7) -> 1.1349172 | BB7: =100*(BT7/EK7) -> 1.2578242 | BC7: =100*(BU7/EL7) -> 1.2673677 | BJ7: =DR7/($CC7/1000) -> 6.0029462 | BK7: =DS7/($CC7/1000) -> 6.1323736 | BL7: =DT7/($CC7/1000) -> 6.1323736 | BS7: =EA7/($CC7/1000) -> 1.0257104 | BT7: =EB7/($CC7/1000) -> 1.141063 | BU7: =EC7/($CC7/1000) -> 1.141063 | CB7: =+CB6+100 -> 202201 | CC7: =VLOOKUP(CB7,DataQ!$C$7:$E$358,3,FALSE) -> 67471.5 | CE7: =Y7 -> 21-22 | CF7: =100*(CZ7/CZ$11) -> 102.92998 | CG7: =100*(DA7/DA$11) -> 105.98934 | CH7: =100*(DB7/DB$11) -> 105.44094 | CN7: 100 | CP7: =100*(DI7/DI$11) -> 77.1448 | CQ7: =100*(DJ7/DJ$11) -> 88.768787 | CR7: =100*(DK7/DK$11) -> 88.084363 | CX7: 100 | CZ7: =100*(DR7/EJ7) -> 448.15085 | DA7: =100*(DS7/EK7) -> 456.0992 | DB7: =100*(DT7/EL7) -> 459.55977 | DI7: =100*(EA7/EJ7) -> 76.574566 | DJ7: =100*(EB7/EK7) -> 84.867286 | DK7: =100*(EC7/EL7) -> 85.511201 | DR7: ='[2]Chart Data'!CJ7 -> 405.02778 | DS7: ='[2]Chart Data'!CK7 -> 413.76045 | DT7: ='[2]Chart Data'!CL7 -> 413.76045 | EA7: ='[2]Chart Data'!CR7 -> 69.20622 | EB7: ='[2]Chart Data'!CS7 -> 76.989229 | EC7: ='[2]Chart Data'!CT7 -> 76.989229 | EJ7: =100*(ES7/ES$11) -> 90.377554 | EK7: =100*(ET7/ET$11) -> 90.717204 | EL7: =100*(EU7/EU$11) -> 90.034087 | EM7: =100*(EV7/EV$11) -> 85.45606 | EN7: =100*(EW7/EW$11) -> 86.029411 | EO7: =100*(EX7/EX$11) -> 84.158538 | EP7: =100*(EY7/EY$11) -> 82.608053 | EQ7: =100*(EZ7/EZ$11) -> #DIV/0! | ES7: ='[2]Chart Data'!DH7 -> 105.54998 | ET7: ='[2]Chart Data'!DI7 -> 106.87364 | EU7: ='[2]Chart Data'!DJ7 -> 106.4684 | EV7: ='[2]Chart Data'!DK7 -> 105.39629 | EW7: ='[2]Chart Data'!DL7 -> 105.37331 | EX7: ='[2]Chart Data'!DM7 -> 105.37331 | EY7: ='[2]Chart Data'!DN7 -> 95.279996 | FB7: 2026 | FC7: =100*(OBR_NOV25_ST1.1!R116/OBR_NOV25_ST1.1!$R$114) -> 102.87515 | FD7: =100*(OBR_MAR25_ST1.1!R112/OBR_MAR25_ST1.1!$R$110) -> 102.8514 | FE7: =100*(FG7/$FG$5) -> 102.33453 | FG7: =SUMIF(DataQ!A:A,'Chart Data'!FB7,DataQ!F:F) -> 2848046.6
I8: ='Aggregates (per cent of GDP)'!B60 -> 2003-04 | J8: =LEFT(I8,4) -> 2003 | K8: =-('Aggregates (per cent of GDP)'!M60-'Aggregates (per cent of GDP)'!M59) -> 0.43914094 | P8: =OBR_NOV25_C4.1!B32 -> 1951-52 | Q8: ='Aggregates (per cent of GDP)'!C8 -> 41.131231 | R8: ='Aggregates (per cent of GDP)'!D8 -> 40.648815 | T8: ='[1]CPI Forecast'!A345 -> 45383 | U8: ='[3]CPI Forecast'!F345 -> 2.3330701 | V8: ='[3]CPI Forecast'!D345 -> 2.3330701 | W8: 2 | Y8: 22-23 | Z8: =100*(AR8/AR$10) -> 103.23134 | AA8: =100*(AS8/AS$10) -> 104.94869 | AB8: =100*(AT8/AT$10) -> 103.37416 | AC8: =100*(AU8/AU$10) -> 103.89247 | AD8: =100*(AV8/AV$10) -> 103.67212 | AI8: =100*(BA8/BA$11) -> 94.449425 | AJ8: =100*(BB8/BB$11) -> 100.13982 | AK8: =100*(BC8/BC$11) -> 95.858372 | AL8: =100*(BD8/BD$11) -> 103.87881 | AM8: =100*(BE8/BE$11) -> 102.1785 | AR8: =100*(BJ8/EJ8) -> 6.3363951 | AS8: =100*(BK8/EK8) -> 6.3959221 | AT8: =100*(BL8/EL8) -> 6.3968773 | AU8: =100*(BM8/EM8) -> 6.610211 | AV8: =100*(BN8/EN8) -> 6.4932717 | BA8: =100*(BS8/EJ8) -> 1.3388461 | BB8: =100*(BT8/EK8) -> 1.367226 | BC8: =100*(BU8/EL8) -> 1.3289471 | BD8: =100*(BV8/EM8) -> 1.4422606 | BE8: =100*(BW8/EN8) -> 1.4309267 | BJ8: =DR8/($CC8/1000) -> 5.9583347 | BK8: =DS8/($CC8/1000) -> 6.0827772 | BL8: =DT8/($CC8/1000) -> 6.082774 | BM8: =DU8/($CC8/1000) -> 6.02511 | BN8: =DV8/($CC8/1000) -> 5.9654001 | BS8: =EA8/($CC8/1000) -> 1.258964 | BT8: =EB8/($CC8/1000) -> 1.3002865 | BU8: =EC8/($CC8/1000) -> 1.2636923 | BV8: =ED8/($CC8/1000) -> 1.3145993 | BW8: =EE8/($CC8/1000) -> 1.3145993 | CB8: =+CB7+100 -> 202301 | CC8: =VLOOKUP(CB8,DataQ!$C$7:$E$358,3,FALSE) -> 68303.5 | CE8: =Y8 -> 22-23 | CF8: =100*(CZ8/CZ$11) -> 99.403771 | CG8: =100*(DA8/DA$11) -> 101.51939 | CH8: =100*(DB8/DB$11) -> 100.24858 | CI8: =100*(DC8/DC$11) -> 101.40112 | CJ8: =100*(DD8/DD$11) -> 100.79035 | CN8: 100 | CP8: =100*(DI8/DI$11) -> 92.128867 | CQ8: =100*(DJ8/DJ$11) -> 97.679454 | CR8: =100*(DK8/DK$11) -> 93.503197 | CS8: =100*(DL8/DL$11) -> 101.32658 | CT8: =100*(DM8/DM$11) -> 99.668046 | CX8: 100 | CZ8: =100*(DR8/EJ8) -> 432.79796 | DA8: =100*(DS8/EK8) -> 436.86387 | DB8: =100*(DT8/EL8) -> 436.92911 | DC8: =100*(DU8/EM8) -> 451.50055 | DD8: =100*(DV8/EN8) -> 443.51319 | DI8: =100*(EA8/EJ8) -> 91.447875 | DJ8: =100*(EB8/EK8) -> 93.386318 | DK8: =100*(EC8/EL8) -> 90.771738 | DL8: =100*(ED8/EM8) -> 98.511446 | DM8: =100*(EE8/EN8) -> 97.737304 | DR8: ='[2]Chart Data'!CJ8 -> 406.97511 | DS8: ='[2]Chart Data'!CK8 -> 415.47497 | DT8: ='[2]Chart Data'!CL8 -> 415.47476 | DU8: ='[2]Chart Data'!CM8 -> 411.5361 | DV8: ='[2]Chart Data'!CN8 -> 407.4577 | EA8: ='[2]Chart Data'!CR8 -> 85.991647 | EB8: ='[2]Chart Data'!CS8 -> 88.814116 | EC8: ='[2]Chart Data'!CT8 -> 86.31461 | ED8: ='[2]Chart Data'!CU8 -> 89.791733 | EE8: ='[2]Chart Data'!CV8 -> 89.791733 | EJ8: =100*(ES8/ES$11) -> 94.03351 | EK8: =100*(ET8/ET$11) -> 95.103991 | EL8: =100*(EU8/EU$11) -> 95.089741 | EM8: =100*(EV8/EV$11) -> 91.148528 | EN8: =100*(EW8/EW$11) -> 91.870482 | EO8: =100*(EX8/EX$11) -> 89.815286 | EP8: =100*(EY8/EY$11) -> 88.449975 | EQ8: =100*(EZ8/EZ$11) -> #DIV/0! | ES8: ='[2]Chart Data'!DH8 -> 109.81969 | ET8: ='[2]Chart Data'!DI8 -> 112.0417 | EU8: ='[2]Chart Data'!DJ8 -> 112.44689 | EV8: ='[2]Chart Data'!DK8 -> 112.41703 | EW8: ='[2]Chart Data'!DL8 -> 112.52776 | EX8: ='[2]Chart Data'!DM8 -> 112.45602 | EY8: ='[2]Chart Data'!DN8 -> 102.01806 | FB8: 2027 | FC8: =100*(OBR_NOV25_ST1.1!R117/OBR_NOV25_ST1.1!$R$114) -> 104.46214 | FD8: =100*(OBR_MAR25_ST1.1!R113/OBR_MAR25_ST1.1!$R$110) -> 104.69281 | FE8: =100*(FG8/$FG$5) -> 103.6345 | FG8: =SUMIF(DataQ!A:A,'Chart Data'!FB8,DataQ!F:F) -> 2884225.9
A9: check | B9: =PresentationalScorecardRounded!I106 -> -4125 | C9: =PresentationalScorecardRounded!J106 -> -9315 | D9: =PresentationalScorecardRounded!K106 -> -7445 | E9: =PresentationalScorecardRounded!L106 -> 3425 | F9: =PresentationalScorecardRounded!M106 -> 20535 | G9: =PresentationalScorecardRounded!N106 -> 24110 | I9: ='Aggregates (per cent of GDP)'!B61 -> 2004-05 | J9: =LEFT(I9,4) -> 2004 | K9: =-('Aggregates (per cent of GDP)'!M61-'Aggregates (per cent of GDP)'!M60) -> 0.49799101 | M9: Budget (Oct24) | N9: =OBR_NOV25_C7.3!C53 -> 9.9293595 | P9: =OBR_NOV25_C4.1!B33 -> 1952-53 | Q9: ='Aggregates (per cent of GDP)'!C9 -> 39.926622 | R9: ='Aggregates (per cent of GDP)'!D9 -> 41.271885 | T9: ='[1]CPI Forecast'!A346 -> 45413 | U9: ='[3]CPI Forecast'!F346 -> 1.9899778 | V9: ='[3]CPI Forecast'!D346 -> 1.9899778 | W9: 2 | Y9: 23-24 | Z9: =100*(AR9/AR$10) -> 99.906763 | AA9: =100*(AS9/AS$10) -> 101.51973 | AB9: =100*(AT9/AT$10) -> 101.14166 | AC9: =100*(AU9/AU$10) -> 100.33612 | AD9: =100*(AV9/AV$10) -> 99.838846 | AI9: =100*(BA9/BA$11) -> 100.35011 | AJ9: =100*(BB9/BB$11) -> 101.97794 | AK9: =100*(BC9/BC$11) -> 102.89491 | AL9: =100*(BD9/BD$11) -> 103.49245 | AM9: =100*(BE9/BE$11) -> 100.91231 | AN9: =100*(BF9/BF$11) -> 92.20828 | AO9: =100*(BG9/BG$11) -> 93.686949 | AR9: =100*(BJ9/EJ9) -> 6.132331 | AS9: =100*(BK9/EK9) -> 6.1869498 | AT9: =100*(BL9/EL9) -> 6.2587288 | AU9: =100*(BM9/EM9) -> 6.3839363 | AV9: =100*(BN9/EN9) -> 6.2531833 | AW9: =100*(BO9/EO9) -> 6.4125332 | AX9: =100*(BP9/EP9) -> 6.5177315 | BA9: =100*(BS9/EJ9) -> 1.42249 | BB9: =100*(BT9/EK9) -> 1.3923221 | BC9: =100*(BU9/EL9) -> 1.4264992 | BD9: =100*(BV9/EM9) -> 1.4368964 | BE9: =100*(BW9/EN9) -> 1.4131948 | BF9: =100*(BX9/EO9) -> 1.4651178 | BG9: =100*(BY9/EP9) -> 1.4891532 | BJ9: =DR9/($CC9/1000) -> 5.9054235 | BK9: =DS9/($CC9/1000) -> 6.0742993 | BL9: =DT9/($CC9/1000) -> 6.1032518 | BM9: =DU9/($CC9/1000) -> 6.1731424 | BN9: =DV9/($CC9/1000) -> 6.1214461 | BO9: =DW9/($CC9/1000) -> 6.1182863 | BP9: =DX9/($CC9/1000) -> 6.1182863 | BS9: =EA9/($CC9/1000) -> 1.3698552 | BT9: =EB9/($CC9/1000) -> 1.366971 | BU9: =EC9/($CC9/1000) -> 1.3910627 | BV9: =ED9/($CC9/1000) -> 1.3894509 | BW9: =EE9/($CC9/1000) -> 1.3834227 | BX9: =EF9/($CC9/1000) -> 1.3978891 | BY9: =EG9/($CC9/1000) -> 1.3978891 | CB9: =+CB8+100 -> 202401 | CC9: =VLOOKUP(CB9,DataQ!$C$7:$E$358,3,FALSE) -> 69092.25 | CE9: =Y9 -> 23-24 | CF9: =100*(CZ9/CZ$11) -> 97.313385 | CG9: =100*(DA9/DA$11) -> 99.336486 | CH9: =100*(DB9/DB$11) -> 99.216234 | CI9: =100*(DC9/DC$11) -> 99.060918 | CJ9: =100*(DD9/DD$11) -> 98.184498 | CN9: 100 | CP9: =100*(DI9/DI$11) -> 99.014923 | CQ9: =100*(DJ9/DJ$11) -> 100.62109 | CR9: =100*(DK9/DK$11) -> 101.52586 | CS9: =100*(DL9/DL$11) -> 102.11545 | CT9: =100*(DM9/DM$11) -> 99.569641 | CU9: =100*(DN9/DN$11) -> 90.981421 | CV9: =100*(DO9/DO$11) -> 92.440416 | CX9: 100 | CZ9: =100*(DR9/EJ9) -> 423.69655 | DA9: =100*(DS9/EK9) -> 427.47028 | DB9: =100*(DT9/EL9) -> 432.42965 | DC9: =100*(DU9/EM9) -> 441.08053 | DD9: =100*(DV9/EN9) -> 432.0465 | DE9: =100*(DW9/EO9) -> 443.05635 | DF9: =100*(DX9/EP9) -> 450.32474 | DI9: =100*(EA9/EJ9) -> 98.283031 | DJ9: =100*(EB9/EK9) -> 96.198666 | DK9: =100*(EC9/EL9) -> 98.560042 | DL9: =100*(ED9/EM9) -> 99.278405 | DM9: =100*(EE9/EN9) -> 97.640805 | DN9: =100*(EF9/EO9) -> 101.22829 | DO9: =100*(EG9/EP9) -> 102.88895 | DR9: ='[2]Chart Data'!CJ9 -> 408.019 | DS9: ='[2]Chart Data'!CK9 -> 419.68701 | DT9: ='[2]Chart Data'!CL9 -> 421.6874 | DU9: ='[2]Chart Data'!CM9 -> 426.51629 | DV9: ='[2]Chart Data'!CN9 -> 422.94449 | DW9: ='[2]Chart Data'!CO9 -> 422.72616 | DX9: ='[2]Chart Data'!CP9 -> 422.72616 | EA9: ='[2]Chart Data'!CR9 -> 94.646379 | EB9: ='[2]Chart Data'!CS9 -> 94.447103 | EC9: ='[2]Chart Data'!CT9 -> 96.111651 | ED9: ='[2]Chart Data'!CU9 -> 96.000288 | EE9: ='[2]Chart Data'!CV9 -> 95.583786 | EF9: ='[2]Chart Data'!CW9 -> 96.583303 | EG9: ='[2]Chart Data'!CX9 -> 96.583303 | EJ9: =100*(ES9/ES$11) -> 96.299816 | EK9: =100*(ET9/ET$11) -> 98.179224 | EL9: =100*(EU9/EU$11) -> 97.515837 | EM9: =100*(EV9/EV$11) -> 96.698056 | EN9: =100*(EW9/EW$11) -> 97.893279 | EO9: =100*(EX9/EX$11) -> 95.411377 | EP9: =100*(EY9/EY$11) -> 93.871407 | EQ9: =100*(EZ9/EZ$11) -> #DIV/0! | ES9: ='[2]Chart Data'!DH9 -> 112.46646 | ET9: ='[2]Chart Data'!DI9 -> 115.66462 | EU9: ='[2]Chart Data'!DJ9 -> 115.31583 | EV9: ='[2]Chart Data'!DK9 -> 119.26148 | EW9: ='[2]Chart Data'!DL9 -> 119.9048 | EX9: ='[2]Chart Data'!DM9 -> 119.46278 | EY9: ='[2]Chart Data'!DN9 -> 108.27113 | FB9: 2028 | FC9: =100*(OBR_NOV25_ST1.1!R118/OBR_NOV25_ST1.1!$R$114) -> 105.99506 | FD9: =100*(OBR_MAR25_ST1.1!R114/OBR_MAR25_ST1.1!$R$110) -> 106.49628 | FE9: =100*(FG9/$FG$5) -> 105.32973 | FG9: =SUMIF(DataQ!A:A,'Chart Data'!FB9,DataQ!F:F) -> 2931405.4
I10: ='Aggregates (per cent of GDP)'!B62 -> 2005-06 | J10: =LEFT(I10,4) -> 2005 | K10: =-('Aggregates (per cent of GDP)'!M62-'Aggregates (per cent of GDP)'!M61) -> -0.69891444 | M10: Spring forecast (Mar25) | N10: =OBR_NOV25_C7.3!C54 -> 9.9316225 | P10: =OBR_NOV25_C4.1!B34 -> 1953-54 | Q10: ='Aggregates (per cent of GDP)'!C10 -> 37.998202 | R10: ='Aggregates (per cent of GDP)'!D10 -> 40.503446 | T10: ='[1]CPI Forecast'!A347 -> 45444 | U10: ='[3]CPI Forecast'!F347 -> 1.9753105 | V10: ='[3]CPI Forecast'!D347 -> 1.9753105 | W10: 2 | Y10: 24-25 | Z10: =100*(AR10/AR$10) -> 100 | AA10: =100*(AS10/AS$10) -> 100 | AB10: =100*(AT10/AT$10) -> 100 | AC10: =100*(AU10/AU$10) -> 100 | AD10: =100*(AV10/AV$10) -> 100 | AE10: =100*(AW10/AW$10) -> 100 | AF10: =100*(AX10/AX$10) -> 100 | AI10: =100*(BA10/BA$11) -> 98.011095 | AJ10: =100*(BB10/BB$11) -> 100.19157 | AK10: =100*(BC10/BC$11) -> 101.36185 | AL10: =100*(BD10/BD$11) -> 104.39257 | AM10: =100*(BE10/BE$11) -> 103.13113 | AN10: =100*(BF10/BF$11) -> 91.655284 | AO10: =100*(BG10/BG$11) -> 95.455059 | AP10: =100*(BH10/BH$11) -> #DIV/0! | AR10: =100*(BJ10/EJ10) -> 6.1380539 | AS10: =100*(BK10/EK10) -> 6.0943325 | AT10: =100*(BL10/EL10) -> 6.1880818 | AU10: =100*(BM10/EM10) -> 6.3625508 | AV10: =100*(BN10/EN10) -> 6.2632768 | AW10: =100*(BO10/EO10) -> 6.6682366 | AX10: =100*(BP10/EP10) -> 6.6467268 | AY10: =100*(BQ10/EQ10) -> #DIV/0! | BA10: =100*(BS10/EJ10) -> 1.3893337 | BB10: =100*(BT10/EK10) -> 1.3679324 | BC10: =100*(BU10/EL10) -> 1.4052454 | BD10: =100*(BV10/EM10) -> 1.4493936 | BE10: =100*(BW10/EN10) -> 1.4442676 | BF10: =100*(BX10/EO10) -> 1.4563311 | BG10: =100*(BY10/EP10) -> 1.5172573 | BH10: =100*(BZ10/EQ10) -> #DIV/0! | BJ10: =DR10/($CC10/1000) -> 6.0204819 | BK10: =DS10/($CC10/1000) -> 6.0621868 | BL10: =DT10/($CC10/1000) -> 6.1290571 | BM10: =DU10/($CC10/1000) -> 6.2554091 | BN10: =DV10/($CC10/1000) -> 6.1798964 | BO10: =DW10/($CC10/1000) -> 6.5125227 | BP10: =DX10/($CC10/1000) -> 6.4747094 | BQ10: =DY10/($CC10/1000) -> 0 | BS10: =EA10/($CC10/1000) -> 1.3627216 | BT10: =EB10/($CC10/1000) -> 1.360717 | BU10: =EC10/($CC10/1000) -> 1.3918416 | BV10: =ED10/($CC10/1000) -> 1.4249867 | BW10: =EE10/($CC10/1000) -> 1.4250407 | BX10: =EF10/($CC10/1000) -> 1.4223235 | BY10: =EG10/($CC10/1000) -> 1.4779907 | BZ10: =EH10/($CC10/1000) -> 0 | CB10: =+CB9+100 -> 202501 | CC10: =VLOOKUP(CB10,DataQ!$C$7:$E$358,3,FALSE) -> 69612.07 | CE10: =Y10 -> 24-25 | CF10: =100*(CZ10/CZ$11) -> 98.137028 | CG10: =100*(DA10/DA$11) -> 98.585616 | CH10: =100*(DB10/DB$11) -> 98.83434 | CI10: =100*(DC10/DC$11) -> 99.471869 | CJ10: =100*(DD10/DD$11) -> 99.082872 | CK10: =100*(DE10/DE$11) -> 96.992273 | CL10: =100*(DF10/DF$11) -> 96.199486 | CN10: 100 | CP10: =100*(DI10/DI$11) -> 97.434609 | CQ10: =100*(DJ10/DJ$11) -> 99.602254 | CR10: =100*(DK10/DK$11) -> 100.76566 | CS10: =100*(DL10/DL$11) -> 103.77854 | CT10: =100*(DM10/DM$11) -> 102.52453 | CU10: =100*(DN10/DN$11) -> 91.116182 | CV10: =100*(DO10/DO$11) -> 94.893607 | CW10: =100*(DP10/DP$11) -> #DIV/0! | CX10: 100 | CZ10: =100*(DR10/EJ10) -> 427.28264 | DA10: =100*(DS10/EK10) -> 424.2391 | DB10: =100*(DT10/EL10) -> 430.76518 | DC10: =100*(DU10/EM10) -> 442.91033 | DD10: =100*(DV10/EN10) -> 435.99966 | DE10: =100*(DW10/EO10) -> 464.18975 | DF10: =100*(DX10/EP10) -> 462.69241 | DI10: =100*(EA10/EJ10) -> 96.714398 | DJ10: =100*(EB10/EK10) -> 95.224609 | DK10: =100*(EC10/EL10) -> 97.822043 | DL10: =100*(ED10/EM10) -> 100.89529 | DM10: =100*(EE10/EN10) -> 100.53846 | DN10: =100*(EF10/EO10) -> 101.37823 | DO10: =100*(EG10/EP10) -> 105.61942 | DP10: =100*(EH10/EQ10) -> #DIV/0! | DR10: ='[2]Chart Data'!CJ10 -> 419.09821 | DS10: ='[2]Chart Data'!CK10 -> 422.00137 | DT10: ='[2]Chart Data'!CL10 -> 426.65635 | DU10: ='[2]Chart Data'!CM10 -> 435.45198 | DV10: ='[2]Chart Data'!CN10 -> 430.19538 | DW10: ='[2]Chart Data'!CO10 -> 453.35019 | DX10: ='[2]Chart Data'!CP10 -> 450.71792 | EA10: ='[2]Chart Data'!CR10 -> 94.861872 | EB10: ='[2]Chart Data'!CS10 -> 94.722329 | EC10: ='[2]Chart Data'!CT10 -> 96.888973 | ED10: ='[2]Chart Data'!CU10 -> 99.196273 | EE10: ='[2]Chart Data'!CV10 -> 99.20003 | EF10: ='[2]Chart Data'!CW10 -> 99.010883 | EG10: ='[2]Chart Data'!CX10 -> 102.88599 | EJ10: =100*(ES10/ES$11) -> 98.084539 | EK10: =100*(ET10/ET$11) -> 99.472532 | EL10: =100*(EU10/EU$11) -> 99.046155 | EM10: =100*(EV10/EV$11) -> 98.316057 | EN10: =100*(EW10/EW$11) -> 98.668741 | EO10: =100*(EX10/EX$11) -> 97.664841 | EP10: =100*(EY10/EY$11) -> 97.411998 | EQ10: =100*(EZ10/EZ$11) -> #DIV/0! | ES10: ='[2]Chart Data'!DH10 -> 114.5508 | ET10: ='[2]Chart Data'!DI10 -> 117.18826 | EU10: ='[2]Chart Data'!DJ10 -> 117.12548 | EV10: ='[2]Chart Data'!DK10 -> 121.25702 | EW10: ='[2]Chart Data'!DL10 -> 120.85462 | EX10: ='[2]Chart Data'!DM10 -> 122.2843 | EY10: ='[2]Chart Data'!DN10 -> 112.35484 | FB10: 2029 | FC10: =100*(OBR_NOV25_ST1.1!R119/OBR_NOV25_ST1.1!$R$114) -> 107.60945 | FD10: =100*(OBR_MAR25_ST1.1!R115/OBR_MAR25_ST1.1!$R$110) -> 108.41408 | FE10: =100*(FG10/$FG$5) -> 107.07962 | FG10: =SUMIF(DataQ!A:A,'Chart Data'!FB10,DataQ!F:F) -> 2980106
A11: GDP! | B11: 3051.124 | C11: 3165.0453 | D11: 3277.5845 | E11: 3388.4929 | F11: 3504.0992 | G11: 3627.9775 | I11: ='Aggregates (per cent of GDP)'!B63 -> 2006-07 | J11: =LEFT(I11,4) -> 2006 | K11: =-('Aggregates (per cent of GDP)'!M63-'Aggregates (per cent of GDP)'!M62) -> -0.72216082 | M11: Budget (Nov25) | N11: =OBR_NOV25_C7.3!C55 -> 21.699459 | P11: =OBR_NOV25_C4.1!B35 -> 1954-55 | Q11: ='Aggregates (per cent of GDP)'!C11 -> 37.46378 | R11: ='Aggregates (per cent of GDP)'!D11 -> 38.923925 | T11: ='[1]CPI Forecast'!A348 -> 45474 | U11: ='[3]CPI Forecast'!F348 -> 2.2344448 | V11: ='[3]CPI Forecast'!D348 -> 2.2344448 | W11: 2 | Y11: 25-26 | Z11: =100*(AR11/AR$10) -> 101.29899 | AA11: =100*(AS11/AS$10) -> 100.83805 | AB11: =100*(AT11/AT$10) -> 100.58429 | AC11: =100*(AU11/AU$10) -> 99.939628 | AD11: =100*(AV11/AV$10) -> 100.33199 | AE11: =100*(AW11/AW$10) -> 102.49457 | AF11: =100*(AX11/AX$10) -> 103.33924 | AG11: =100*(AY11/AY$11) -> #DIV/0! | AI11: =100*(BA11/BA$11) -> 100 | AJ11: =100*(BB11/BB$11) -> 100 | AK11: =100*(BC11/BC$11) -> 100 | AL11: =100*(BD11/BD$11) -> 100 | AM11: =100*(BE11/BE$11) -> 100 | AN11: =100*(BF11/BF$11) -> 100 | AO11: =100*(BG11/BG$11) -> 100 | AP11: =100*(BH11/BH$11) -> #DIV/0! | AR11: =100*(BJ11/EJ11) -> 6.2177865 | AS11: =100*(BK11/EK11) -> 6.1454062 | AT11: =100*(BL11/EL11) -> 6.2242379 | AU11: =100*(BM11/EM11) -> 6.3587096 | AV11: =100*(BN11/EN11) -> 6.2840702 | AW11: =100*(BO11/EO11) -> 6.8345806 | AX11: =100*(BP11/EP11) -> 6.8686768 | AY11: =100*(BQ11/EQ11) -> #DIV/0! | BA11: =100*(BS11/EJ11) -> 1.417527 | BB11: =100*(BT11/EK11) -> 1.365317 | BC11: =100*(BU11/EL11) -> 1.3863652 | BD11: =100*(BV11/EM11) -> 1.388407 | BE11: =100*(BW11/EN11) -> 1.4004186 | BF11: =100*(BX11/EO11) -> 1.5889222 | BG11: =100*(BY11/EP11) -> 1.5894991 | BH11: =100*(BZ11/EQ11) -> #DIV/0! | BJ11: =DR11/($CC11/1000) -> 6.2177865 | BK11: =DS11/($CC11/1000) -> 6.1454062 | BL11: =DT11/($CC11/1000) -> 6.2242379 | BM11: =DU11/($CC11/1000) -> 6.3587096 | BN11: =DV11/($CC11/1000) -> 6.2840702 | BO11: =DW11/($CC11/1000) -> 6.8345806 | BP11: =DX11/($CC11/1000) -> 6.8686768 | BQ11: =DY11/($CC11/1000) -> 0 | BS11: =EA11/($CC11/1000) -> 1.417527 | BT11: =EB11/($CC11/1000) -> 1.365317 | BU11: =EC11/($CC11/1000) -> 1.3863652 | BV11: =ED11/($CC11/1000) -> 1.388407 | BW11: =EE11/($CC11/1000) -> 1.4004186 | BX11: =EF11/($CC11/1000) -> 1.5889222 | BY11: =EG11/($CC11/1000) -> 1.5894991 | BZ11: =EH11/($CC11/1000) -> 0 | CB11: =+CB10+100 -> 202601 | CC11: =VLOOKUP(CB11,DataQ!$C$7:$E$358,3,FALSE) -> 70023.94 | CE11: =Y11 -> 25-26 | CF11: =100*(CZ11/CZ$11) -> 100 | CG11: =100*(DA11/DA$11) -> 100 | CH11: =100*(DB11/DB$11) -> 100 | CI11: =100*(DC11/DC$11) -> 100 | CJ11: =100*(DD11/DD$11) -> 100 | CK11: =100*(DE11/DE$11) -> 100 | CL11: =100*(DF11/DF$11) -> 100 | CM11: =100*(DG11/DG$11) -> #DIV/0! | CN11: 100 | CP11: =100*(DI11/DI$11) -> 100 | CQ11: =100*(DJ11/DJ$11) -> 100 | CR11: =100*(DK11/DK$11) -> 100 | CS11: =100*(DL11/DL$11) -> 100 | CT11: =100*(DM11/DM$11) -> 100 | CU11: =100*(DN11/DN$11) -> 100 | CV11: =100*(DO11/DO$11) -> 100 | CW11: =100*(DP11/DP$11) -> #DIV/0! | CX11: 100 | CZ11: =100*(DR11/EJ11) -> 435.39391 | DA11: =100*(DS11/EK11) -> 430.32556 | DB11: =100*(DT11/EL11) -> 435.84566 | DC11: =100*(DU11/EM11) -> 445.2619 | DD11: =100*(DV11/EN11) -> 440.03535 | DE11: =100*(DW11/EO11) -> 478.58426 | DF11: =100*(DX11/EP11) -> 480.97181 | DI11: =100*(EA11/EJ11) -> 99.260827 | DJ11: =100*(EB11/EK11) -> 95.604873 | DK11: =100*(EC11/EL11) -> 97.078752 | DL11: =100*(ED11/EM11) -> 97.221725 | DM11: =100*(EE11/EN11) -> 98.062828 | DN11: =100*(EF11/EO11) -> 111.26259 | DO11: =100*(EG11/EP11) -> 111.30299 | DP11: =100*(EH11/EQ11) -> #DIV/0! | DR11: ='[2]Chart Data'!CJ11 -> 435.39391 | DS11: ='[2]Chart Data'!CK11 -> 430.32556 | DT11: ='[2]Chart Data'!CL11 -> 435.84566 | DU11: ='[2]Chart Data'!CM11 -> 445.2619 | DV11: ='[2]Chart Data'!CN11 -> 440.03535 | DW11: ='[2]Chart Data'!CO11 -> 478.58426 | DX11: ='[2]Chart Data'!CP11 -> 480.97181 | EA11: ='[2]Chart Data'!CR11 -> 99.260827 | EB11: ='[2]Chart Data'!CS11 -> 95.604873 | EC11: ='[2]Chart Data'!CT11 -> 97.078752 | ED11: ='[2]Chart Data'!CU11 -> 97.221725 | EE11: ='[2]Chart Data'!CV11 -> 98.062828 | EF11: ='[2]Chart Data'!CW11 -> 111.26259 | EG11: ='[2]Chart Data'!CX11 -> 111.30299 | EJ11: =100*(ES11/ES$11) -> 100 | EK11: =100*(ET11/ET$11) -> 100 | EL11: =100*(EU11/EU$11) -> 100 | EM11: =100*(EV11/EV$11) -> 100 | EN11: =100*(EW11/EW$11) -> 100 | EO11: =100*(EX11/EX$11) -> 100 | EP11: =100*(EY11/EY$11) -> 100 | EQ11: =100*(EZ11/EZ$11) -> #DIV/0! | ES11: ='[2]Chart Data'!DH11 -> 116.78782 | ET11: ='[2]Chart Data'!DI11 -> 117.80967 | EU11: ='[2]Chart Data'!DJ11 -> 118.25344 | EV11: ='[2]Chart Data'!DK11 -> 123.33389 | EW11: ='[2]Chart Data'!DL11 -> 122.48522 | EX11: ='[2]Chart Data'!DM11 -> 125.20811 | EY11: ='[2]Chart Data'!DN11 -> 115.33984 | FB11: 2030 | FC11: =100*(OBR_NOV25_ST1.1!R120/OBR_NOV25_ST1.1!$R$114) -> 109.27672 | FE11: =100*(FG11/$FG$5) -> 108.77203 | FG11: =SUMIF(DataQ!A:A,'Chart Data'!FB11,DataQ!F:F) -> 3027207.1
I12: ='Aggregates (per cent of GDP)'!B64 -> 2007-08 | J12: =LEFT(I12,4) -> 2007 | K12: =-('Aggregates (per cent of GDP)'!M64-'Aggregates (per cent of GDP)'!M63) -> 0.4997265 | P12: =OBR_NOV25_C4.1!B36 -> 1955-56 | Q12: ='Aggregates (per cent of GDP)'!C12 -> 35.96424 | R12: ='Aggregates (per cent of GDP)'!D12 -> 35.770115 | T12: ='[1]CPI Forecast'!A349 -> 45505 | U12: ='[3]CPI Forecast'!F349 -> 2.2162837 | V12: ='[3]CPI Forecast'!D349 -> 2.2162837 | W12: 2 | Y12: 26-27 | Z12: =100*(AR12/AR$10) -> 102.46105 | AA12: =100*(AS12/AS$10) -> 101.3154 | AB12: =100*(AT12/AT$10) -> 101.20752 | AC12: =100*(AU12/AU$10) -> 100.38453 | AD12: =100*(AV12/AV$10) -> 100.82299 | AE12: =100*(AW12/AW$10) -> 103.35738 | AF12: =100*(AX12/AX$10) -> 104.70414 | AG12: =100*(AY12/AY$11) -> #DIV/0! | AI12: =100*(BA12/BA$11) -> 101.13994 | AJ12: =100*(BB12/BB$11) -> 98.700442 | AK12: =100*(BC12/BC$11) -> 98.701289 | AL12: =100*(BD12/BD$11) -> 98.172123 | AM12: =100*(BE12/BE$11) -> 98.053064 | AN12: =100*(BF12/BF$11) -> 102.75911 | AO12: =100*(BG12/BG$11) -> 103.71948 | AP12: =100*(BH12/BH$11) -> #DIV/0! | AR12: =100*(BJ12/EJ12) -> 6.2891148 | AS12: =100*(BK12/EK12) -> 6.1744972 | AT12: =100*(BL12/EL12) -> 6.2628038 | AU12: =100*(BM12/EM12) -> 6.387017 | AV12: =100*(BN12/EN12) -> 6.3148232 | AW12: =100*(BO12/EO12) -> 6.8921145 | AX12: =100*(BP12/EP12) -> 6.9593979 | AY12: =100*(BQ12/EQ12) -> #DIV/0! | BA12: =100*(BS12/EJ12) -> 1.433686 | BB12: =100*(BT12/EK12) -> 1.3475739 | BC12: =100*(BU12/EL12) -> 1.3683603 | BD12: =100*(BV12/EM12) -> 1.3630286 | BE12: =100*(BW12/EN12) -> 1.3731533 | BF12: =100*(BX12/EO12) -> 1.6327623 | BG12: =100*(BY12/EP12) -> 1.6486202 | BH12: =100*(BZ12/EQ12) -> #DIV/0! | BJ12: =DR12/($CC12/1000) -> 6.4149476 | BK12: =DS12/($CC12/1000) -> 6.2497144 | BL12: =DT12/($CC12/1000) -> 6.3378433 | BM12: =DU12/($CC12/1000) -> 6.4907966 | BN12: =DV12/($CC12/1000) -> 6.4249291 | BO12: =DW12/($CC12/1000) -> 7.0278983 | BP12: =DX12/($CC12/1000) -> 7.0746904 | BQ12: =DY12/($CC12/1000) -> 0 | BS12: =EA12/($CC12/1000) -> 1.4623713 | BT12: =EB12/($CC12/1000) -> 1.3639899 | BU12: =EC12/($CC12/1000) -> 1.3847557 | BV12: =ED12/($CC12/1000) -> 1.3851758 | BW12: =EE12/($CC12/1000) -> 1.3970958 | BX12: =EF12/($CC12/1000) -> 1.6649299 | BY12: =EG12/($CC12/1000) -> 1.675932 | BZ12: =EH12/($CC12/1000) -> 0 | CB12: =+CB11+100 -> 202701 | CC12: =VLOOKUP(CB12,DataQ!$C$7:$E$358,3,FALSE) -> 70394.69 | CE12: =Y12 -> 26-27 | CF12: =100*(CZ12/CZ$11) -> 101.6827 | CG12: =100*(DA12/DA$11) -> 101.00535 | CH12: =100*(DB12/DB$11) -> 101.15235 | CI12: =100*(DC12/DC$11) -> 100.97699 | CJ12: =100*(DD12/DD$11) -> 101.02143 | CK12: =100*(DE12/DE$11) -> 101.37572 | CL12: =100*(DF12/DF$11) -> 101.85725 | CM12: =100*(DG12/DG$11) -> #DIV/0! | CN12: 100 | CP12: =100*(DI12/DI$11) -> 101.67544 | CQ12: =100*(DJ12/DJ$11) -> 99.223023 | CR12: =100*(DK12/DK$11) -> 99.223875 | CS12: =100*(DL12/DL$11) -> 98.691906 | CT12: =100*(DM12/DM$11) -> 98.572217 | CU12: =100*(DN12/DN$11) -> 103.30318 | CV12: =100*(DO12/DO$11) -> 104.26863 | CW12: =100*(DP12/DP$11) -> #DIV/0! | CX12: 100 | CZ12: =100*(DR12/EJ12) -> 442.72029 | DA12: =100*(DS12/EK12) -> 434.65182 | DB12: =100*(DT12/EL12) -> 440.86813 | DC12: =100*(DU12/EM12) -> 449.61208 | DD12: =100*(DV12/EN12) -> 444.53002 | DE12: =100*(DW12/EO12) -> 485.16826 | DF12: =100*(DX12/EP12) -> 489.90465 | DI12: =100*(EA12/EJ12) -> 100.92388 | DJ12: =100*(EB12/EK12) -> 94.862045 | DK12: =100*(EC12/EL12) -> 96.3253 | DL12: =100*(ED12/EM12) -> 95.949974 | DM12: =100*(EE12/EN12) -> 96.662704 | DN12: =100*(EF12/EO12) -> 114.9378 | DO12: =100*(EG12/EP12) -> 116.05411 | DP12: =100*(EH12/EQ12) -> #DIV/0! | DR12: ='[2]Chart Data'!CJ12 -> 451.57825 | DS12: ='[2]Chart Data'!CK12 -> 439.94671 | DT12: ='[2]Chart Data'!CL12 -> 446.15051 | DU12: ='[2]Chart Data'!CM12 -> 456.91761 | DV12: ='[2]Chart Data'!CN12 -> 452.28089 | DW12: ='[2]Chart Data'!CO12 -> 494.72672 | DX12: ='[2]Chart Data'!CP12 -> 498.02064 | EA12: ='[2]Chart Data'!CR12 -> 102.94317 | EB12: ='[2]Chart Data'!CS12 -> 96.017646 | EC12: ='[2]Chart Data'!CT12 -> 97.479447 | ED12: ='[2]Chart Data'!CU12 -> 97.50902 | EE12: ='[2]Chart Data'!CV12 -> 98.348124 | EF12: ='[2]Chart Data'!CW12 -> 117.20222 | EG12: ='[2]Chart Data'!CX12 -> 117.97671 | EJ12: =100*(ES12/ES$11) -> 102.0008 | EK12: =100*(ET12/ET$11) -> 101.21819 | EL12: =100*(EU12/EU$11) -> 101.19818 | EM12: =100*(EV12/EV$11) -> 101.62485 | EN12: =100*(EW12/EW$11) -> 101.74361 | EO12: =100*(EX12/EX$11) -> 101.97013 | EP12: =100*(EY12/EY$11) -> 101.65665 | EQ12: =100*(EZ12/EZ$11) -> #DIV/0! | ES12: ='[2]Chart Data'!DH12 -> 119.12452 | ET12: ='[2]Chart Data'!DI12 -> 119.24482 | EU12: ='[2]Chart Data'!DJ12 -> 119.67032 | EV12: ='[2]Chart Data'!DK12 -> 125.33789 | EW12: ='[2]Chart Data'!DL12 -> 124.62088 | EX12: ='[2]Chart Data'!DM12 -> 127.67488 | EY12: ='[2]Chart Data'!DN12 -> 117.25061
A13: % of GDP | B13: =B4 -> 2025-2026 | C13: =C4 -> 2026-2027 | D13: =D4 -> 2027-2028 | E13: =E4 -> 2028-2029 | F13: =F4 -> 2029-2030 | G13: =G4 -> 2030-2031 | I13: ='Aggregates (per cent of GDP)'!B65 -> 2008-09 | J13: =LEFT(I13,4) -> 2008 | K13: =-('Aggregates (per cent of GDP)'!M65-'Aggregates (per cent of GDP)'!M64) -> 3.595098 | P13: =OBR_NOV25_C4.1!B37 -> 1956-57 | Q13: ='Aggregates (per cent of GDP)'!C13 -> 35.569836 | R13: ='Aggregates (per cent of GDP)'!D13 -> 35.957286 | T13: ='[1]CPI Forecast'!A350 -> 45536 | U13: ='[3]CPI Forecast'!F350 -> 1.6803412 | V13: ='[3]CPI Forecast'!D350 -> 1.6803412 | W13: 2 | Y13: 27-28 | AA13: =100*(AS13/AS$10) -> 101.97263 | AB13: =100*(AT13/AT$10) -> 101.97889 | AC13: =100*(AU13/AU$10) -> 101.01745 | AD13: =100*(AV13/AV$10) -> 101.44433 | AE13: =100*(AW13/AW$10) -> 104.27074 | AF13: =100*(AX13/AX$10) -> 105.31285 | AG13: =100*(AY13/AY$11) -> #DIV/0! | AJ13: =100*(BB13/BB$11) -> 96.730307 | AK13: =100*(BC13/BC$11) -> 96.833521 | AL13: =100*(BD13/BD$11) -> 96.140004 | AM13: =100*(BE13/BE$11) -> 95.835608 | AN13: =100*(BF13/BF$11) -> 103.32073 | AO13: =100*(BG13/BG$11) -> 106.44075 | AP13: =100*(BH13/BH$11) -> #DIV/0! | AS13: =100*(BK13/EK13) -> 6.2145509 | AT13: =100*(BL13/EL13) -> 6.3105369 | AU13: =100*(BM13/EM13) -> 6.4272865 | AV13: =100*(BN13/EN13) -> 6.3537395 | AW13: =100*(BO13/EO13) -> 6.9530199 | AX13: =100*(BP13/EP13) -> 6.9998576 | AY13: =100*(BQ13/EQ13) -> #DIV/0! | BB13: =100*(BT13/EK13) -> 1.3206753 | BC13: =100*(BU13/EL13) -> 1.3424662 | BD13: =100*(BV13/EM13) -> 1.3348145 | BE13: =100*(BW13/EN13) -> 1.3420997 | BF13: =100*(BX13/EO13) -> 1.641686 | BG13: =100*(BY13/EP13) -> 1.6918748 | BH13: =100*(BZ13/EQ13) -> #DIV/0! | BK13: =DS13/($CC13/1000) -> 6.4032493 | BL13: =DT13/($CC13/1000) -> 6.491662 | BM13: =DU13/($CC13/1000) -> 6.6476064 | BN13: =DV13/($CC13/1000) -> 6.5855903 | BO13: =DW13/($CC13/1000) -> 7.2287978 | BP13: =DX13/($CC13/1000) -> 7.2607503 | BQ13: =DY13/($CC13/1000) -> 0 | BT13: =EB13/($CC13/1000) -> 1.3607762 | BU13: =EC13/($CC13/1000) -> 1.3809977 | BV13: =ED13/($CC13/1000) -> 1.3805704 | BW13: =EE13/($CC13/1000) -> 1.3910735 | BX13: =EF13/($CC13/1000) -> 1.7068003 | BY13: =EG13/($CC13/1000) -> 1.754933 | BZ13: =EH13/($CC13/1000) -> 0 | CB13: =+CB12+100 -> 202801 | CC13: =VLOOKUP(CB13,DataQ!$C$7:$E$358,3,FALSE) -> 70693.4 | CE13: =Y13 -> 27-28 | CG13: =100*(DA13/DA$11) -> 102.09195 | CH13: =100*(DB13/DB$11) -> 102.3558 | CI13: =100*(DC13/DC$11) -> 102.04483 | CJ13: =100*(DD13/DD$11) -> 102.07531 | CK13: =100*(DE13/DE$11) -> 102.70555 | CL13: =100*(DF13/DF$11) -> 102.88414 | CM13: =100*(DG13/DG$11) -> #DIV/0! | CN13: 100 | CQ13: =100*(DJ13/DJ$11) -> 97.655092 | CR13: =100*(DK13/DK$11) -> 97.759292 | CS13: =100*(DL13/DL$11) -> 97.059146 | CT13: =100*(DM13/DM$11) -> 96.751839 | CU13: =100*(DN13/DN$11) -> 104.30852 | CV13: =100*(DO13/DO$11) -> 107.45837 | CW13: =100*(DP13/DP$11) -> #DIV/0! | CX13: 100 | DA13: =100*(DS13/EK13) -> 439.32773 | DB13: =100*(DT13/EL13) -> 446.11331 | DC13: =100*(DU13/EM13) -> 454.36674 | DD13: =100*(DV13/EN13) -> 449.16745 | DE13: =100*(DW13/EO13) -> 491.53262 | DF13: =100*(DX13/EP13) -> 494.84373 | DJ13: =100*(EB13/EK13) -> 93.363026 | DK13: =100*(EC13/EL13) -> 94.903502 | DL13: =100*(ED13/EM13) -> 94.362576 | DM13: =100*(EE13/EN13) -> 94.87759 | DN13: =100*(EF13/EO13) -> 116.05637 | DO13: =100*(EG13/EP13) -> 119.60439 | DP13: =100*(EH13/EQ13) -> #DIV/0! | DS13: ='[2]Chart Data'!CK13 -> 452.66747 | DT13: ='[2]Chart Data'!CL13 -> 458.91766 | DU13: ='[2]Chart Data'!CM13 -> 469.9419 | DV13: ='[2]Chart Data'!CN13 -> 465.55777 | DW13: ='[2]Chart Data'!CO13 -> 511.0283 | DX13: ='[2]Chart Data'!CP13 -> 513.28713 | EB13: ='[2]Chart Data'!CS13 -> 96.197899 | EC13: ='[2]Chart Data'!CT13 -> 97.627423 | ED13: ='[2]Chart Data'!CU13 -> 97.597216 | EE13: ='[2]Chart Data'!CV13 -> 98.339717 | EF13: ='[2]Chart Data'!CW13 -> 120.65952 | EG13: ='[2]Chart Data'!CX13 -> 124.06218 | EK13: =100*(ET13/ET$11) -> 103.0364 | EL13: =100*(EU13/EU$11) -> 102.8702 | EM13: =100*(EV13/EV$11) -> 103.42788 | EN13: =100*(EW13/EW$11) -> 103.64905 | EO13: =100*(EX13/EX$11) -> 103.9663 | EP13: =100*(EY13/EY$11) -> 103.72711 | EQ13: =100*(EZ13/EZ$11) -> #DIV/0! | ET13: ='[2]Chart Data'!DI13 -> 121.38684 | EU13: ='[2]Chart Data'!DJ13 -> 121.64755 | EV13: ='[2]Chart Data'!DK13 -> 127.56164 | EW13: ='[2]Chart Data'!DL13 -> 126.95476 | EX13: ='[2]Chart Data'!DM13 -> 130.17424 | EY13: ='[2]Chart Data'!DN13 -> 119.63869
A14: Tax | B14: =-100*((B5/1000)/B$11) -> -0.0022942365 | C14: =-100*((C5/1000)/C$11) -> 0.060188711 | D14: =-100*((D5/1000)/D$11) -> -0.088174691 | E14: =-100*((E5/1000)/E$11) -> -0.31665995 | F14: =-100*((F5/1000)/F$11) -> -0.66065481 | G14: =-100*((G5/1000)/G$11) -> -0.73443124 | I14: ='Aggregates (per cent of GDP)'!B66 -> 2009-10 | J14: =LEFT(I14,4) -> 2009 | K14: =-('Aggregates (per cent of GDP)'!M66-'Aggregates (per cent of GDP)'!M65) -> 1.40712 | P14: =OBR_NOV25_C4.1!B38 -> 1957-58 | Q14: ='Aggregates (per cent of GDP)'!C14 -> 35.163468 | R14: ='Aggregates (per cent of GDP)'!D14 -> 35.190121 | T14: ='[1]CPI Forecast'!A351 -> 45566 | U14: ='[3]CPI Forecast'!F351 -> 2.2809915 | V14: ='[3]CPI Forecast'!D351 -> 2.2809915 | W14: 2 | Y14: 28-29 | AC14: =100*(AU14/AU$10) -> 101.65135 | AD14: =100*(AV14/AV$10) -> 102.03401 | AE14: =100*(AW14/AW$10) -> 105.20128 | AF14: =100*(AX14/AX$10) -> 105.9112 | AG14: =100*(AY14/AY$11) -> #DIV/0! | AL14: =100*(BD14/BD$11) -> 93.771106 | AM14: =100*(BE14/BE$11) -> 92.721614 | AN14: =100*(BF14/BF$11) -> 101.58432 | AO14: =100*(BG14/BG$11) -> 105.07532 | AP14: =100*(BH14/BH$11) -> #DIV/0! | AU14: =100*(BM14/EM14) -> 6.467619 | AV14: =100*(BN14/EN14) -> 6.3906724 | AW14: =100*(BO14/EO14) -> 7.0150702 | AX14: =100*(BP14/EP14) -> 7.0396282 | AY14: =100*(BQ14/EQ14) -> #DIV/0! | BD14: =100*(BV14/EM14) -> 1.3019246 | BE14: =100*(BW14/EN14) -> 1.2984907 | BF14: =100*(BX14/EO14) -> 1.6140958 | BG14: =100*(BY14/EP14) -> 1.6701712 | BH14: =100*(BZ14/EQ14) -> #DIV/0! | BM14: =DU14/($CC14/1000) -> 6.8151302 | BN14: =DV14/($CC14/1000) -> 6.7518911 | BO14: =DW14/($CC14/1000) -> 7.4370465 | BP14: =DX14/($CC14/1000) -> 7.4441901 | BQ14: =DY14/($CC14/1000) -> 0 | BV14: =ED14/($CC14/1000) -> 1.3718782 | BW14: =EE14/($CC14/1000) -> 1.3718851 | BX14: =EF14/($CC14/1000) -> 1.7111883 | BY14: =EG14/($CC14/1000) -> 1.7661547 | BZ14: =EH14/($CC14/1000) -> 0 | CB14: =+CB13+100 -> 202901 | CC14: =VLOOKUP(CB14,DataQ!$C$7:$E$358,3,FALSE) -> 70966.62 | CE14: =Y14 -> 28-29 | CI14: =100*(DC14/DC$11) -> 103.08204 | CJ14: =100*(DD14/DD$11) -> 103.06545 | CK14: =100*(DE14/DE$11) -> 104.0226 | CL14: =100*(DF14/DF$11) -> 103.86859 | CM14: =100*(DG14/DG$11) -> #DIV/0! | CN14: 100 | CS14: =100*(DL14/DL$11) -> 95.033476 | CT14: =100*(DM14/DM$11) -> 93.969856 | CU14: =100*(DN14/DN$11) -> 102.95188 | CV14: =100*(DO14/DO$11) -> 106.48987 | CW14: =100*(DP14/DP$11) -> #DIV/0! | CX14: 100 | DC14: =100*(DU14/EM14) -> 458.98506 | DD14: =100*(DV14/EN14) -> 453.52442 | DE14: =100*(DW14/EO14) -> 497.83582 | DF14: =100*(DX14/EP14) -> 499.57862 | DL14: =100*(ED14/EM14) -> 92.393186 | DM14: =100*(EE14/EN14) -> 92.149498 | DN14: =100*(EF14/EO14) -> 114.54693 | DO14: =100*(EG14/EP14) -> 118.52641 | DP14: =100*(EH14/EQ14) -> #DIV/0! | DU14: ='[2]Chart Data'!CM14 -> 483.64675 | DV14: ='[2]Chart Data'!CN14 -> 479.15889 | DW14: ='[2]Chart Data'!CO14 -> 527.78205 | DX14: ='[2]Chart Data'!CP14 -> 528.28901 | ED14: ='[2]Chart Data'!CU14 -> 97.357557 | EE14: ='[2]Chart Data'!CV14 -> 97.358047 | EF14: ='[2]Chart Data'!CW14 -> 121.43725 | EG14: ='[2]Chart Data'!CX14 -> 125.33803 | EM14: =100*(EV14/EV$11) -> 105.37309 | EN14: =100*(EW14/EW$11) -> 105.65228 | EO14: =100*(EX14/EX$11) -> 106.01528 | EP14: =100*(EY14/EY$11) -> 105.74692 | EQ14: =100*(EZ14/EZ$11) -> #DIV/0! | EV14: ='[2]Chart Data'!DK14 -> 129.96074 | EW14: ='[2]Chart Data'!DL14 -> 129.40843 | EX14: ='[2]Chart Data'!DM14 -> 132.73973 | EY14: ='[2]Chart Data'!DN14 -> 121.96833
A15: Current spending | B15: =-100*((B6/1000)/B$11) -> 0.13765419 | C15: =-100*((C6/1000)/C$11) -> 0.23411987 | D15: =-100*((D6/1000)/D$11) -> 0.31517113 | E15: =-100*((E6/1000)/E$11) -> 0.21558256 | F15: =-100*((F6/1000)/F$11) -> 0.074626882 | G15: =-100*((G6/1000)/G$11) -> 0.069873642 | I15: ='Aggregates (per cent of GDP)'!B67 -> 2010-11 | J15: =LEFT(I15,4) -> 2010 | K15: =-('Aggregates (per cent of GDP)'!M67-'Aggregates (per cent of GDP)'!M66) -> -2.1274984 | P15: =OBR_NOV25_C4.1!B39 -> 1958-59 | Q15: ='Aggregates (per cent of GDP)'!C15 -> 35.644201 | R15: ='Aggregates (per cent of GDP)'!D15 -> 35.948413 | T15: ='[1]CPI Forecast'!A352 -> 45597 | U15: ='[3]CPI Forecast'!F352 -> 2.6221267 | V15: ='[3]CPI Forecast'!D352 -> 2.6221267 | W15: 2 | Y15: 29-30 | AE15: =100*(AW15/AW$10) -> 106.25128 | AF15: =100*(AX15/AX$10) -> 106.59255 | AG15: =100*(AY15/AY$11) -> #DIV/0! | AN15: =100*(BF15/BF$11) -> 100.1593 | AO15: =100*(BG15/BG$11) -> 104.05386 | AP15: =100*(BH15/BH$11) -> #DIV/0! | AW15: =100*(BO15/EO15) -> 7.0850871 | AX15: =100*(BP15/EP15) -> 7.0849154 | AY15: =100*(BQ15/EQ15) -> #DIV/0! | BF15: =100*(BX15/EO15) -> 1.5914533 | BG15: =100*(BY15/EP15) -> 1.6539352 | BH15: =100*(BZ15/EQ15) -> #DIV/0! | BO15: =DW15/($CC15/1000) -> 7.6594427 | BP15: =DX15/($CC15/1000) -> 7.6330148 | BQ15: =DY15/($CC15/1000) -> 0 | BX15: =EF15/($CC15/1000) -> 1.7204651 | BY15: =EG15/($CC15/1000) -> 1.781886 | BZ15: =EH15/($CC15/1000) -> 0 | CB15: =+CB14+100 -> 203001 | CC15: =VLOOKUP(CB15,DataQ!$C$7:$E$358,3,FALSE) -> 71232.75 | CE15: =Y15 -> 29-30 | CK15: =100*(DE15/DE$11) -> 105.45483 | CL15: =100*(DF15/DF$11) -> 104.92881 | CM15: =100*(DG15/DG$11) -> #DIV/0! | CN15: 100 | CU15: =100*(DN15/DN$11) -> 101.88833 | CV15: =100*(DO15/DO$11) -> 105.85012 | CW15: =100*(DP15/DP$11) -> #DIV/0! | CX15: 100 | DE15: =100*(DW15/EO15) -> 504.69023 | DF15: =100*(DX15/EP15) -> 504.67801 | DN15: =100*(EF15/EO15) -> 113.36359 | DO15: =100*(EG15/EP15) -> 117.81435 | DP15: =100*(EH15/EQ15) -> #DIV/0! | DW15: ='[2]Chart Data'!CO15 -> 545.60317 | DX15: ='[2]Chart Data'!CP15 -> 543.72063 | EF15: ='[2]Chart Data'!CW15 -> 122.55346 | EG15: ='[2]Chart Data'!CX15 -> 126.92864 | EO15: =100*(EX15/EX$11) -> 108.10654 | EP15: =100*(EY15/EY$11) -> 107.73615 | EQ15: =100*(EZ15/EZ$11) -> #DIV/0! | EX15: ='[2]Chart Data'!DM15 -> 135.35816 | EY15: ='[2]Chart Data'!DN15 -> 124.2627
A16: Total | B16: =-100*((B7/1000)/B$11) -> 0.13535995 | C16: =-100*((C7/1000)/C$11) -> 0.29430858 | D16: =-100*((D7/1000)/D$11) -> 0.22699644 | E16: =-100*((E7/1000)/E$11) -> -0.10107738 | F16: =-100*((F7/1000)/F$11) -> -0.58602793 | G16: =-100*((G7/1000)/G$11) -> -0.6645576 | I16: ='Aggregates (per cent of GDP)'!B68 -> 2011-12 | J16: =LEFT(I16,4) -> 2011 | K16: =-('Aggregates (per cent of GDP)'!M68-'Aggregates (per cent of GDP)'!M67) -> -1.3607901 | P16: =OBR_NOV25_C4.1!B40 -> 1959-60 | Q16: ='Aggregates (per cent of GDP)'!C16 -> 33.652223 | R16: ='Aggregates (per cent of GDP)'!D16 -> 35.939384 | T16: ='[1]CPI Forecast'!A353 -> 45627 | U16: ='[3]CPI Forecast'!F353 -> 2.5029869 | V16: ='[3]CPI Forecast'!D353 -> 2.5029869 | W16: 2 | Y16: 30-31 | AG16: =100*(AY16/AY$11) -> #DIV/0! | AP16: =100*(BH16/BH$11) -> #DIV/0! | AY16: =100*(BQ16/EQ16) -> #DIV/0! | BH16: =100*(BZ16/EQ16) -> #DIV/0! | BQ16: =DY16/($CC16/1000) -> 0 | BZ16: =EH16/($CC16/1000) -> 0 | CB16: =+CB15+100 -> 203101 | CC16: =VLOOKUP(CB16,DataQ!$C$7:$E$358,3,FALSE) -> 71491.27 | CE16: =Y16 -> 30-31 | CM16: =100*(DG16/DG$11) -> #DIV/0! | CN16: 100 | CW16: =100*(DP16/DP$11) -> #DIV/0! | CX16: 100 | DP16: =100*(EH16/EQ16) -> #DIV/0! | EQ16: =100*(EZ16/EZ$11) -> #DIV/0!
I17: ='Aggregates (per cent of GDP)'!B69 -> 2012-13 | J17: =LEFT(I17,4) -> 2012 | K17: =-('Aggregates (per cent of GDP)'!M69-'Aggregates (per cent of GDP)'!M68) -> 0.35827152 | P17: =OBR_NOV25_C4.1!B41 -> 1960-61 | Q17: ='Aggregates (per cent of GDP)'!C17 -> 33.452184 | R17: ='Aggregates (per cent of GDP)'!D17 -> 35.936796 | T17: ='[1]CPI Forecast'!A354 -> 45658 | U17: ='[3]CPI Forecast'!F354 -> 2.9829405 | V17: ='[3]CPI Forecast'!D354 -> 2.9829405 | W17: 2
I18: ='Aggregates (per cent of GDP)'!B70 -> 2013-14 | J18: =LEFT(I18,4) -> 2013 | K18: =-('Aggregates (per cent of GDP)'!M70-'Aggregates (per cent of GDP)'!M69) -> -0.959001 | P18: =OBR_NOV25_C4.1!B42 -> 1961-62 | Q18: ='Aggregates (per cent of GDP)'!C18 -> 35.456709 | R18: ='Aggregates (per cent of GDP)'!D18 -> 37.623903 | T18: ='[1]CPI Forecast'!A355 -> 45689 | U18: ='[3]CPI Forecast'!F355 -> 2.8361877 | V18: ='[3]CPI Forecast'!D355 -> 2.8361877 | W18: 2
I19: ='Aggregates (per cent of GDP)'!B71 -> 2014-15 | J19: =LEFT(I19,4) -> 2014 | K19: =-('Aggregates (per cent of GDP)'!M71-'Aggregates (per cent of GDP)'!M70) -> 0.36972494 | P19: =OBR_NOV25_C4.1!B43 -> 1962-63 | Q19: ='Aggregates (per cent of GDP)'!C19 -> 35.472044 | R19: ='Aggregates (per cent of GDP)'!D19 -> 37.298435 | T19: ='[1]CPI Forecast'!A356 -> 45717 | U19: ='[3]CPI Forecast'!F356 -> 2.5941517 | V19: ='[3]CPI Forecast'!D356 -> 2.5941517 | W19: 2
I20: ='Aggregates (per cent of GDP)'!B72 -> 2015-16 | J20: =LEFT(I20,4) -> 2015 | K20: =-('Aggregates (per cent of GDP)'!M72-'Aggregates (per cent of GDP)'!M71) -> -0.4917689 | P20: =OBR_NOV25_C4.1!B44 -> 1963-64 | Q20: ='Aggregates (per cent of GDP)'!C20 -> 34.626828 | R20: ='Aggregates (per cent of GDP)'!D20 -> 37.3297 | T20: ='[1]CPI Forecast'!A357 -> 45748 | U20: ='[3]CPI Forecast'!F357 -> 3.5273316 | V20: ='[3]CPI Forecast'!D357 -> 3.5273316 | W20: 2
I21: ='Aggregates (per cent of GDP)'!B73 -> 2016-17 | J21: =LEFT(I21,4) -> 2016 | K21: =-('Aggregates (per cent of GDP)'!M73-'Aggregates (per cent of GDP)'!M72) -> -1.4453522 | P21: =OBR_NOV25_C4.1!B45 -> 1964-65 | Q21: ='Aggregates (per cent of GDP)'!C21 -> 35.156609 | R21: ='Aggregates (per cent of GDP)'!D21 -> 37.023864 | T21: ='[1]CPI Forecast'!A358 -> 45778 | U21: ='[3]CPI Forecast'!F358 -> 3.3579498 | V21: ='[3]CPI Forecast'!D358 -> 3.3579498 | W21: 2
I22: ='Aggregates (per cent of GDP)'!B74 -> 2017-18 | J22: =LEFT(I22,4) -> 2017 | K22: =-('Aggregates (per cent of GDP)'!M74-'Aggregates (per cent of GDP)'!M73) -> 0.086068042 | P22: =OBR_NOV25_C4.1!B46 -> 1965-66 | Q22: ='Aggregates (per cent of GDP)'!C22 -> 36.94927 | R22: ='Aggregates (per cent of GDP)'!D22 -> 38.473034 | T22: ='[1]CPI Forecast'!A359 -> 45809 | U22: ='[3]CPI Forecast'!F359 -> 3.5764899 | V22: ='[3]CPI Forecast'!D359 -> 3.5764899 | W22: 2
I23: ='Aggregates (per cent of GDP)'!B75 -> 2018-19 | J23: =LEFT(I23,4) -> 2018 | K23: =-('Aggregates (per cent of GDP)'!M75-'Aggregates (per cent of GDP)'!M74) -> -0.2307328 | P23: =OBR_NOV25_C4.1!B47 -> 1966-67 | Q23: ='Aggregates (per cent of GDP)'!C23 -> 37.628247 | R23: ='Aggregates (per cent of GDP)'!D23 -> 40.023022 | T23: ='[1]CPI Forecast'!A360 -> 45839 | U23: ='[3]CPI Forecast'!F360 -> 3.8294852 | V23: ='[3]CPI Forecast'!D360 -> 3.8294852 | W23: 2
I24: ='Aggregates (per cent of GDP)'!B76 -> 2019-20 | J24: =LEFT(I24,4) -> 2019 | K24: =-('Aggregates (per cent of GDP)'!M76-'Aggregates (per cent of GDP)'!M75) -> 0.92709237 | P24: =OBR_NOV25_C4.1!B48 -> 1967-68 | Q24: ='Aggregates (per cent of GDP)'!C24 -> 39.075729 | R24: ='Aggregates (per cent of GDP)'!D24 -> 42.925682 | T24: ='[1]CPI Forecast'!A361 -> 45870 | U24: ='[3]CPI Forecast'!F361 -> 3.7882569 | V24: ='[3]CPI Forecast'!D361 -> 3.7882569 | W24: 2
I25: ='Aggregates (per cent of GDP)'!B77 -> 2020-21 | J25: =LEFT(I25,4) -> 2020 | K25: =-('Aggregates (per cent of GDP)'!M77-'Aggregates (per cent of GDP)'!M76) -> 12.139105 | P25: =OBR_NOV25_C4.1!B49 -> 1968-69 | Q25: ='Aggregates (per cent of GDP)'!C25 -> 40.793946 | R25: ='Aggregates (per cent of GDP)'!D25 -> 41.371128 | T25: ='[1]CPI Forecast'!A362 -> 45901 | U25: ='[3]CPI Forecast'!F362 -> 3.7827367 | V25: ='[3]CPI Forecast'!D362 -> 3.7827367 | W25: 2
I26: ='Aggregates (per cent of GDP)'!B78 -> 2021-22 | J26: =LEFT(I26,4) -> 2021 | K26: =-('Aggregates (per cent of GDP)'!M78-'Aggregates (per cent of GDP)'!M77) -> -9.8878906 | P26: =OBR_NOV25_C4.1!B50 -> 1969-70 | Q26: ='Aggregates (per cent of GDP)'!C26 -> 41.841671 | R26: ='Aggregates (per cent of GDP)'!D26 -> 40.127025 | T26: ='[1]CPI Forecast'!A363 -> 45931 | U26: ='[3]CPI Forecast'!F363 -> 3.5588638 | V26: ='[3]CPI Forecast'!D363 -> 3.5588638 | W26: 2
I27: ='Aggregates (per cent of GDP)'!B79 -> 2022-23 | J27: =LEFT(I27,4) -> 2022 | K27: =-('Aggregates (per cent of GDP)'!M79-'Aggregates (per cent of GDP)'!M78) -> -1.7832895 | P27: =OBR_NOV25_C4.1!B51 -> 1970-71 | Q27: ='Aggregates (per cent of GDP)'!C27 -> 40.037063 | R27: ='Aggregates (per cent of GDP)'!D27 -> 39.477649 | T27: ='[1]CPI Forecast'!A364 -> 45962 | U27: ='[3]CPI Forecast'!F364 -> 3.6037818 | V27: ='[3]CPI Forecast'!D364 -> 3.6111748 | W27: 2
I28: ='Aggregates (per cent of GDP)'!B80 -> 2023-24 | J28: =LEFT(I28,4) -> 2023 | K28: =-('Aggregates (per cent of GDP)'!M80-'Aggregates (per cent of GDP)'!M79) -> 0.023723999 | P28: =OBR_NOV25_C4.1!B52 -> 1971-72 | Q28: ='Aggregates (per cent of GDP)'!C28 -> 38.364478 | R28: ='Aggregates (per cent of GDP)'!D28 -> 39.346039 | T28: ='[1]CPI Forecast'!A365 -> 45992 | U28: ='[3]CPI Forecast'!F365 -> 3.7805448 | V28: ='[3]CPI Forecast'!D365 -> 3.767209 | W28: 2
... I35: ='Aggregates (per cent of GDP)'!B87 -> 2030-31 | J35: =LEFT(I35,4) -> 2030 | K35: =-('Aggregates (per cent of GDP)'!M87-'Aggregates (per cent of GDP)'!M86) -> -0.044477868 | P35: =OBR_NOV25_C4.1!B59 -> 1978-79 | Q35: ='Aggregates (per cent of GDP)'!C35 -> 36.905288 | R35: ='Aggregates (per cent of GDP)'!D35 -> 41.420706 | T35: ='[1]CPI Forecast'!A372 -> 46204 | U35: ='[3]CPI Forecast'!F372 -> 2.533463 | V35: ='[3]CPI Forecast'!D372 -> 2.4565987 | W35: 2
P36: =OBR_NOV25_C4.1!B60 -> 1979-80 | Q36: ='Aggregates (per cent of GDP)'!C36 -> 37.271293 | R36: ='Aggregates (per cent of GDP)'!D36 -> 40.946091 | T36: ='[1]CPI Forecast'!A373 -> 46235 | U36: ='[3]CPI Forecast'!F373 -> 2.6664216 | V36: ='[3]CPI Forecast'!D373 -> 2.5889284 | W36: 2
P37: =OBR_NOV25_C4.1!B61 -> 1980-81 | Q37: ='Aggregates (per cent of GDP)'!C37 -> 38.491785 | R37: ='Aggregates (per cent of GDP)'!D37 -> 42.803908 | T37: ='[1]CPI Forecast'!A374 -> 46266 | U37: ='[3]CPI Forecast'!F374 -> 2.7912075 | V37: ='[3]CPI Forecast'!D374 -> 2.7384588 | W37: 2
P38: =OBR_NOV25_C4.1!B62 -> 1981-82 | Q38: ='Aggregates (per cent of GDP)'!C38 -> 40.812214 | R38: ='Aggregates (per cent of GDP)'!D38 -> 42.820321 | T38: ='[1]CPI Forecast'!A375 -> 46296 | U38: ='[3]CPI Forecast'!F375 -> 2.6235579 | V38: ='[3]CPI Forecast'!D375 -> 2.5612302 | W38: 2
P39: =OBR_NOV25_C4.1!B63 -> 1982-83 | Q39: ='Aggregates (per cent of GDP)'!C39 -> 40.523009 | R39: ='Aggregates (per cent of GDP)'!D39 -> 43.127992 | T39: ='[1]CPI Forecast'!A376 -> 46327 | U39: ='[3]CPI Forecast'!F376 -> 2.603508 | V39: ='[3]CPI Forecast'!D376 -> 2.5329938 | W39: 2
P40: =OBR_NOV25_C4.1!B64 -> 1983-84 | Q40: ='Aggregates (per cent of GDP)'!C40 -> 39.415409 | R40: ='Aggregates (per cent of GDP)'!D40 -> 42.706138 | T40: ='[1]CPI Forecast'!A377 -> 46357 | U40: ='[3]CPI Forecast'!F377 -> 2.584902 | V40: ='[3]CPI Forecast'!D377 -> 2.5341351 | W40: 2
P41: =OBR_NOV25_C4.1!B65 -> 1984-85 | Q41: ='Aggregates (per cent of GDP)'!C41 -> 39.140924 | R41: ='Aggregates (per cent of GDP)'!D41 -> 42.382304 | T41: ='[1]CPI Forecast'!A378 -> 46388 | U41: ='[3]CPI Forecast'!F378 -> 2.628996 | V41: ='[3]CPI Forecast'!D378 -> 2.497903 | W41: 2
P42: =OBR_NOV25_C4.1!B66 -> 1985-86 | Q42: ='Aggregates (per cent of GDP)'!C42 -> 38.214948 | R42: ='Aggregates (per cent of GDP)'!D42 -> 40.342803 | T42: ='[1]CPI Forecast'!A379 -> 46419 | U42: ='[3]CPI Forecast'!F379 -> 2.631464 | V42: ='[3]CPI Forecast'!D379 -> 2.5012822 | W42: 2
P43: =OBR_NOV25_C4.1!B67 -> 1986-87 | Q43: ='Aggregates (per cent of GDP)'!C43 -> 37.312392 | R43: ='Aggregates (per cent of GDP)'!D43 -> 39.228198 | T43: ='[1]CPI Forecast'!A380 -> 46447 | U43: ='[3]CPI Forecast'!F380 -> 2.6234877 | V43: ='[3]CPI Forecast'!D380 -> 2.4941755 | W43: 2
P44: =OBR_NOV25_C4.1!B68 -> 1987-88 | Q44: ='Aggregates (per cent of GDP)'!C44 -> 36.058787 | R44: ='Aggregates (per cent of GDP)'!D44 -> 37.048195 | T44: ='[1]CPI Forecast'!A381 -> 46478 | U44: ='[3]CPI Forecast'!F381 -> 2.5896898 | V44: ='[3]CPI Forecast'!D381 -> 2.6381523 | W44: 2
P45: =OBR_NOV25_C4.1!B69 -> 1988-89 | Q45: ='Aggregates (per cent of GDP)'!C45 -> 35.4042 | R45: ='Aggregates (per cent of GDP)'!D45 -> 34.437469 | T45: ='[1]CPI Forecast'!A382 -> 46508 | U45: ='[3]CPI Forecast'!F382 -> 2.5814426 | V45: ='[3]CPI Forecast'!D382 -> 2.6302195 | W45: 2
P46: =OBR_NOV25_C4.1!B70 -> 1989-90 | Q46: ='Aggregates (per cent of GDP)'!C46 -> 34.584797 | R46: ='Aggregates (per cent of GDP)'!D46 -> 34.60443 | T46: ='[1]CPI Forecast'!A383 -> 46539 | U46: ='[3]CPI Forecast'!F383 -> 2.5781021 | V46: ='[3]CPI Forecast'!D383 -> 2.6272637 | W46: 2
...

Sheet DataQ
E1: =GMW!NF2 -> NOV021L.db | F1: =$E$1 -> NOV021L.db | G1: =$E$1 -> NOV021L.db | H1: =$E$1 -> NOV021L.db
E2: UK | F2: UK | G2: UK | H2: UK
E3: POP | F3: GDP | G3: CPI | H3: WAGEWKLY
E4: GBR | F4: GBR | G4: GBR | H4: GBR
E5: L | F5: L | G5: L | H5: L
A6: CYs | B6: FYs | D6: =D358+5 -> 2329 | E6: {=_xlfn.CONCAT(INDEX(GMW!$A$2:$NF$60,MATCH(1,(GMW!$NE$2:$NE$60=E$3)*(GMW!$ND$2:$ND$60=E$4),0),$D6-1966),"0",(INDEX(GMW!$A$2:$NF$60,MATCH(1,(GMW!$NE$2:$NE$60=E$3)*(GMW!$ND$2:$ND$60=E$4),0),$D6-1965)))} -> 202402 | F6: {=_xlfn.CONCAT(INDEX(GMW!$A$2:$NF$60,MATCH(1,(GMW!$NE$2:$NE$60=F$3)*(GMW!$ND$2:$ND$60=F$4),0),$D6-1966),"0",(INDEX(GMW!$A$2:$NF$60,MATCH(1,(GMW!$NE$2:$NE$60=F$3)*(GMW!$ND$2:$ND$60=F$4),0),$D6-1965)))} -> 202503 | G6: {=_xlfn.CONCAT(INDEX(GMW!$A$2:$NF$60,MATCH(1,(GMW!$NE$2:$NE$60=G$3)*(GMW!$ND$2:$ND$60=G$4),0),$D6-1966),"0",(INDEX(GMW!$A$2:$NF$60,MATCH(1,(GMW!$NE$2:$NE$60=G$3)*(GMW!$ND$2:$ND$60=G$4),0),$D6-1965)))} -> 202503 | H6: {=_xlfn.CONCAT(INDEX(GMW!$A$2:$NF$60,MATCH(1,(GMW!$NE$2:$NE$60=H$3)*(GMW!$ND$2:$ND$60=H$4),0),$D6-1966),"0",(INDEX(GMW!$A$2:$NF$60,MATCH(1,(GMW!$NE$2:$NE$60=H$3)*(GMW!$ND$2:$ND$60=H$4),0),$D6-1965)))} -> 202503
A7: 1973 | C7: 197301 | D7: 1973 | E7: {=INDEX(GMW!$A$2:$NF$60,MATCH(1,(GMW!$NE$2:$NE$60=E$3)*(GMW!$ND$2:$ND$60=E$4),0),$D7-1966)} -> 56191.5 | F7: {=INDEX(GMW!$A$2:$NF$60,MATCH(1,(GMW!$NE$2:$NE$60=F$3)*(GMW!$ND$2:$ND$60=F$4),0),$D7-1966)} -> 267015 | G7: {=INDEX(GMW!$A$2:$NF$60,MATCH(1,(GMW!$NE$2:$NE$60=G$3)*(GMW!$ND$2:$ND$60=G$4),0),$D7-1966)} -> 11.88749 | H7: {=INDEX(GMW!$A$2:$NF$60,MATCH(1,(GMW!$NE$2:$NE$60=H$3)*(GMW!$ND$2:$ND$60=H$4),0),$D7-1966)} -> 14.85115
