Workbook
Name \A: #REF!
Name \B: #REF!
Name \e: #REF!
Name \I: #REF!
Name \l: #REF!
Name \P: #REF!
Name \Q: #REF!
Name \S: #REF!
Name \T: #REF!
Name \UPDATE: #REF!
Name \Z: #REF!
Name ________tab6: !#REF!
Name ________tab8: !#REF!
Name _______tab3: !#REF!
Name _______tab6: !#REF!
Name _______tab8: !#REF!
Name ______tab3: !#REF!
Name ______tab6: !#REF!
Name ______tab8: !#REF!
Name _____PC1: #REF!
Name _____tab3: !#REF!
Name _____tab6: !#REF!
Name _____tab8: !#REF!
Name ____tab3: !#REF!
Name ____tab6: !#REF!
Name ____tab8: !#REF!
Name ___05MAY11: #REF!
Name ___20MAY11: #REF!
Name ___21MAY11: #REF!
Name ___PC1: #REF!
Name ___tab3: !#REF!
Name ___tab6: !#REF!
Name ___tab8: !#REF!
Name __05MAY11: #REF!
Name __20MAY11: #REF!
Name __21MAY11: #REF!
Name __PBR1: #REF!
Name __PBR2: #REF!
Name __PBR3: #REF!
Name __PBR4: #REF!
Name __PBR5: #REF!
Name __PBR6: #REF!
Name __PBR7: #REF!
Name __PBR8: #REF!
Name __PC1: #REF!
Name __pop: #REF!
Name __tab3: !#REF!
Name __tab6: !#REF!
Name __tab8: !#REF!
Name __Territ: #REF!
Name _05MAY11: #REF!
Name _1_: #REF!
Name _1_0: #REF!
Name _1_05MAY11: #REF!
Name _1377_0: #REF!
Name _1395_0: #REF!
Name _1396_0: #REF!
Name _2_: #REF!
Name _2_0: #REF!
Name _2_20MAY11: #REF!

Sheet Chart 1 data
A1: Section 1: Current economic conditions
A3: Chart 1.1 - Contributions to CPI inflation
B5: Contributions to CPI inflation, percentage points | H5: Inflation rate, per cent
A6: Date | B6: Food | C6: Electricity and gas | D6: Fuels and lubricants | E6: Other goods | F6: Services | H6: CPI | K6: Bank of England | L6: Oxford Economics
A7: 44227 | B7: -0.058 | C7: -0.275 | D7: -0.257 | E7: 0.447 | F7: 0.844 | H7: 0.701
A8: 44255 | B8: -0.047 | C8: -0.257 | D8: -0.113 | E8: 0.126 | F8: 0.705 | H8: 0.414
A9: 44286 | B9: -0.135 | C9: -0.238 | D9: 0.09 | E9: 0.291 | F9: 0.706 | H9: 0.714
A10: 44316 | B10: -0.028 | C10: 0.104 | D10: 0.352 | E10: 0.387 | F10: 0.712 | H10: 1.526
A11: 44347 | B11: -0.115 | C11: 0.112 | D11: 0.454 | E11: 0.796 | F11: 0.868 | H11: 2.115
A12: 44377 | B12: -0.041 | C12: 0.107 | D12: 0.512 | E12: 0.989 | F12: 0.947 | H12: 2.514
A13: 44408 | B13: -0.054 | C13: 0.111 | D13: 0.46 | E13: 0.848 | F13: 0.675 | H13: 2.04
A14: 44439 | B14: 0.056 | C14: 0.111 | D14: 0.467 | E14: 1.207 | F14: 1.357 | H14: 3.197
A15: 44469 | B15: 0.1 | C15: 0.118 | D15: 0.468 | E15: 1.257 | F15: 1.138 | H15: 3.08
A16: 44500 | B16: 0.152 | C16: 0.752 | D16: 0.565 | E16: 1.326 | F16: 1.412 | H16: 4.206
A17: 44530 | B17: 0.293 | C17: 0.761 | D17: 0.744 | E17: 1.87 | F17: 1.461 | H17: 5.13
A18: 44561 | B18: 0.473 | C18: 0.747 | D18: 0.707 | E18: 1.983 | F18: 1.476 | H18: 5.386
... A54: 45657 | B54: 0.226 | C54: -0.265 | D54: -0.156 | E54: 0.555 | F54: 2.144 | H54: 2.503
A55: 45688 | B55: 0.371 | C55: -0.409 | D55: -0.07 | E55: 0.633 | F55: 2.457 | H55: 2.983 | J55: 45658 | K55: =H55 -> 2.983
A56: 45716 | B56: 0.369 | C56: -0.411 | D56: -0.082 | E56: 0.524 | F56: 2.437 | H56: 2.836 | J56: 45689 | K56: =H56 -> 2.836
A57: 45747 | B57: 0.341 | C57: -0.411 | D57: -0.17 | E57: 0.522 | F57: 2.312 | H57: 2.594 | J57: 45717 | K57: =H57 -> 2.594
A58: 45777 | B58: 0.383 | C58: 0.224 | D58: -0.296 | E58: 0.525 | F58: 2.692 | H58: 3.527 | J58: 45748 | K58: =H58 -> 3.527
A59: 45808 | B59: 0.491 | C59: 0.226 | D59: -0.345 | E59: 0.657 | F59: 2.329 | H59: 3.358 | J59: 45778 | K59: =H59 -> 3.358
A60: 45838 | B60: 0.506 | C60: 0.228 | D60: -0.278 | E60: 0.757 | F60: 2.364 | H60: 3.576 | J60: 45809 | K60: =H60 -> 3.576
A61: 45869 | B61: 0.551 | C61: 0.299 | D61: -0.206 | E61: 0.676 | F61: 2.509 | H61: 3.829 | J61: 45839 | K61: =H61 -> 3.829
A62: 45900 | B62: 0.57 | C62: 0.304 | D62: -0.147 | E62: 0.682 | F62: 2.38 | H62: 3.788 | J62: 45870 | K62: =H62 -> 3.788
A63: 45930 | B63: 0.506 | C63: 0.305 | D63: -0.034 | E63: 0.65 | F63: 2.356 | H63: 3.783 | J63: 45901 | K63: =H63 -> 3.783
A64: October 2025 (Bank staff projections) | B64: 0.556 | C64: 0.062 | D64: 0.041 | E64: 0.624 | F64: 2.312 | H64: 3.595 | J64: 45931 | K64: =H64 -> 3.595 | L64: 3.6
A65: November 2025 (Bank staff projections) | B65: 0.557 | C65: 0.065 | D65: 0.011 | E65: 0.506 | F65: 2.267 | H65: 3.407 | J65: 45962 | K65: =H65 -> 3.407 | L65: ='[1]CPI Forecast'!D364 -> 3.6111763
A66: December 2025 (Bank staff projections) | B66: 0.585 | C66: 0.061 | D66: -0.029 | E66: 0.522 | F66: 2.323 | H66: 3.463 | J66: 45992 | K66: =H66 -> 3.463 | L66: ='[1]CPI Forecast'!D365 -> 3.7659882
A67: January 2026 (Bank staff projections) | B67: 0.497 | C67: 0.004 | D67: -0.056 | E67: 0.424 | F67: 2.129 | H67: 2.998 | J67: 46023 | K67: =H67 -> 2.998 | L67: ='[1]CPI Forecast'!D366 -> 3.5007391
A68: February 2026 (Bank staff projections) | B68: 0.502 | C68: 0.002 | D68: -0.101 | E68: 0.572 | F68: 2.113 | H68: 3.088 | J68: 46054 | K68: =H68 -> 3.088 | L68: ='[1]CPI Forecast'!D367 -> 3.4287604
A69: March 2026 (Bank staff projections) | B69: 0.509 | C69: 0.008 | D69: -0.044 | E69: 0.619 | F69: 2.134 | H69: 3.226 | J69: 46082 | K69: =H69 -> 3.226 | L69: ='[1]CPI Forecast'!D368 -> 3.3353312

Sheet Chart Data
A1: Implied probability of rate cut by meeting | F1: Change compared with today
B2: December | C2: February | D2: 0.5 | F2: December | G2: February
A3: 45915 | B3: =IF(F3<0,-F3/0.25,F3/0.25) -> 0.3344 | C3: =IF(G3<0,-G3/0.25,G3/0.25) -> 0.7704 | D3: 0.5 | F3: =HAVERD!E104-HAVERD!$B104 -> -0.0836 | G3: =HAVERD!F104-HAVERD!$B104 -> -0.1926
A4: 45916 | B4: =IF(F4<0,-F4/0.25,F4/0.25) -> 0.3132 | C4: =IF(G4<0,-G4/0.25,G4/0.25) -> 0.7332 | D4: 0.5 | F4: =HAVERD!E105-HAVERD!$B105 -> -0.0783 | G4: =HAVERD!F105-HAVERD!$B105 -> -0.1833
A5: 45917 | B5: =IF(F5<0,-F5/0.25,F5/0.25) -> 0.2696 | C5: =IF(G5<0,-G5/0.25,G5/0.25) -> 0.6816 | D5: 0.5 | F5: =HAVERD!E106-HAVERD!$B106 -> -0.0674 | G5: =HAVERD!F106-HAVERD!$B106 -> -0.1704
A6: 45918 | B6: =IF(F6<0,-F6/0.25,F6/0.25) -> 0.2656 | C6: =IF(G6<0,-G6/0.25,G6/0.25) -> 0.6856 | D6: 0.5 | F6: =HAVERD!E107-HAVERD!$B107 -> -0.0664 | G6: =HAVERD!F107-HAVERD!$B107 -> -0.1714
A7: 45919 | B7: =IF(F7<0,-F7/0.25,F7/0.25) -> 0.2412 | C7: =IF(G7<0,-G7/0.25,G7/0.25) -> 0.6692 | D7: 0.5 | F7: =HAVERD!D108-HAVERD!$B108 -> -0.0603 | G7: =HAVERD!E108-HAVERD!$B108 -> -0.1673
A8: =A3+7 -> 45922 | B8: =IF(F8<0,-F8/0.25,F8/0.25) -> 0.2404 | C8: =IF(G8<0,-G8/0.25,G8/0.25) -> 0.6644 | D8: 0.5 | F8: =HAVERD!D109-HAVERD!$B109 -> -0.0601 | G8: =HAVERD!E109-HAVERD!$B109 -> -0.1661
A9: =A4+7 -> 45923 | B9: =IF(F9<0,-F9/0.25,F9/0.25) -> 0.2472 | C9: =IF(G9<0,-G9/0.25,G9/0.25) -> 0.7072 | D9: 0.5 | F9: =HAVERD!D110-HAVERD!$B110 -> -0.0618 | G9: =HAVERD!E110-HAVERD!$B110 -> -0.1768
A10: =A5+7 -> 45924 | B10: =IF(F10<0,-F10/0.25,F10/0.25) -> 0.2428 | C10: =IF(G10<0,-G10/0.25,G10/0.25) -> 0.7148 | D10: 0.5 | F10: =HAVERD!D111-HAVERD!$B111 -> -0.0607 | G10: =HAVERD!E111-HAVERD!$B111 -> -0.1787
A11: =A6+7 -> 45925 | B11: =IF(F11<0,-F11/0.25,F11/0.25) -> 0.198 | C11: =IF(G11<0,-G11/0.25,G11/0.25) -> 0.638 | D11: 0.5 | F11: =HAVERD!D112-HAVERD!$B112 -> -0.0495 | G11: =HAVERD!E112-HAVERD!$B112 -> -0.1595
A12: =A7+7 -> 45926 | B12: =IF(F12<0,-F12/0.25,F12/0.25) -> 0.1876 | C12: =IF(G12<0,-G12/0.25,G12/0.25) -> 0.6076 | D12: 0.5 | F12: =HAVERD!D113-HAVERD!$B113 -> -0.0469 | G12: =HAVERD!E113-HAVERD!$B113 -> -0.1519
A13: =A8+7 -> 45929 | B13: =IF(F13<0,-F13/0.25,F13/0.25) -> 0.1868 | C13: =IF(G13<0,-G13/0.25,G13/0.25) -> 0.6148 | D13: 0.5 | F13: =HAVERD!D114-HAVERD!$B114 -> -0.0467 | G13: =HAVERD!E114-HAVERD!$B114 -> -0.1537
A14: =A9+7 -> 45930 | B14: =IF(F14<0,-F14/0.25,F14/0.25) -> 0.1924 | C14: =IF(G14<0,-G14/0.25,G14/0.25) -> 0.6204 | D14: 0.5 | F14: =HAVERD!D115-HAVERD!$B115 -> -0.0481 | G14: =HAVERD!E115-HAVERD!$B115 -> -0.1551
A15: =A10+7 -> 45931 | B15: =IF(F15<0,-F15/0.25,F15/0.25) -> 0.2216 | C15: =IF(G15<0,-G15/0.25,G15/0.25) -> 0.6616 | D15: 0.5 | F15: =HAVERD!D116-HAVERD!$B116 -> -0.0554 | G15: =HAVERD!E116-HAVERD!$B116 -> -0.1654
A16: =A11+7 -> 45932 | B16: =IF(F16<0,-F16/0.25,F16/0.25) -> 0.1816 | C16: =IF(G16<0,-G16/0.25,G16/0.25) -> 0.6016 | D16: 0.5 | F16: =HAVERD!D117-HAVERD!$B117 -> -0.0454 | G16: =HAVERD!E117-HAVERD!$B117 -> -0.1504
A17: =A12+7 -> 45933 | B17: =IF(F17<0,-F17/0.25,F17/0.25) -> 0.2048 | C17: =IF(G17<0,-G17/0.25,G17/0.25) -> 0.6408 | D17: 0.5 | F17: =HAVERD!D118-HAVERD!$B118 -> -0.0512 | G17: =HAVERD!E118-HAVERD!$B118 -> -0.1602
A18: =A13+7 -> 45936 | B18: =IF(F18<0,-F18/0.25,F18/0.25) -> 0.2056 | C18: =IF(G18<0,-G18/0.25,G18/0.25) -> 0.6256 | D18: 0.5 | F18: =HAVERD!D119-HAVERD!$B119 -> -0.0514 | G18: =HAVERD!E119-HAVERD!$B119 -> -0.1564
A19: =A14+7 -> 45937 | B19: =IF(F19<0,-F19/0.25,F19/0.25) -> 0.1904 | C19: =IF(G19<0,-G19/0.25,G19/0.25) -> 0.6104 | D19: 0.5 | F19: =HAVERD!D120-HAVERD!$B120 -> -0.0476 | G19: =HAVERD!E120-HAVERD!$B120 -> -0.1526
... A22: =A17+7 -> 45940 | B22: =IF(F22<0,-F22/0.25,F22/0.25) -> 0.1992 | C22: =IF(G22<0,-G22/0.25,G22/0.25) -> 0.6232 | D22: 0.5 | F22: =HAVERD!D123-HAVERD!$B123 -> -0.0498 | G22: =HAVERD!E123-HAVERD!$B123 -> -0.1558
A23: =+A18+7 -> 45943 | B23: =IF(F23<0,-F23/0.25,F23/0.25) -> 0.2288 | C23: =IF(G23<0,-G23/0.25,G23/0.25) -> 0.6728 | D23: 0.5 | F23: =HAVERD!D124-HAVERD!$B124 -> -0.0572 | G23: =HAVERD!E124-HAVERD!$B124 -> -0.1682
A24: =+A19+7 -> 45944 | B24: =IF(F24<0,-F24/0.25,F24/0.25) -> 0.3376 | C24: =IF(G24<0,-G24/0.25,G24/0.25) -> 0.8496 | D24: 0.5 | F24: =HAVERD!D125-HAVERD!$B125 -> -0.0844 | G24: =HAVERD!E125-HAVERD!$B125 -> -0.2124
A25: =+A20+7 -> 45945 | B25: =IF(F25<0,-F25/0.25,F25/0.25) -> 0.3564 | C25: =IF(G25<0,-G25/0.25,G25/0.25) -> 0.8884 | D25: 0.5 | F25: =HAVERD!D126-HAVERD!$B126 -> -0.0891 | G25: =HAVERD!E126-HAVERD!$B126 -> -0.2221
A26: =+A21+7 -> 45946 | B26: =IF(F26<0,-F26/0.25,F26/0.25) -> 0.4064 | C26: =IF(G26<0,-G26/0.25,G26/0.25) -> 0.9784 | D26: 0.5 | F26: =HAVERD!D127-HAVERD!$B127 -> -0.1016 | G26: =HAVERD!E127-HAVERD!$B127 -> -0.2446
A27: =+A22+7 -> 45947 | B27: =IF(F27<0,-F27/0.25,F27/0.25) -> 0.3768 | C27: =IF(G27<0,-G27/0.25,G27/0.25) -> 0.9208 | D27: 0.5 | F27: =HAVERD!D128-HAVERD!$B128 -> -0.0942 | G27: =HAVERD!E128-HAVERD!$B128 -> -0.2302
A28: =+A23+7 -> 45950 | B28: =IF(F28<0,-F28/0.25,F28/0.25) -> 0.3928 | C28: =IF(G28<0,-G28/0.25,G28/0.25) -> 0.9408 | D28: 0.5 | F28: =HAVERD!D129-HAVERD!$B129 -> -0.0982 | G28: =HAVERD!E129-HAVERD!$B129 -> -0.2352
A29: =+A24+7 -> 45951 | B29: =IF(F29<0,-F29/0.25,F29/0.25) -> 0.3752 | C29: =IF(G29<0,-G29/0.25,G29/0.25) -> 0.9152 | D29: 0.5 | F29: =HAVERD!D130-HAVERD!$B130 -> -0.0938 | G29: =HAVERD!E130-HAVERD!$B130 -> -0.2288
A30: =+A25+7 -> 45952 | B30: =IF(F30<0,-F30/0.25,F30/0.25) -> 0.6908 | C30: =IF(G30<0,-G30/0.25,G30/0.25) -> 1.2788 | D30: 0.5 | F30: =HAVERD!D131-HAVERD!$B131 -> -0.1727 | G30: =HAVERD!E131-HAVERD!$B131 -> -0.3197
A31: =+A26+7 -> 45953 | B31: =IF(F31<0,-F31/0.25,F31/0.25) -> 0.6724 | C31: =IF(G31<0,-G31/0.25,G31/0.25) -> 1.2804 | D31: 0.5 | F31: =HAVERD!D132-HAVERD!$B132 -> -0.1681 | G31: =HAVERD!E132-HAVERD!$B132 -> -0.3201
A32: =+A27+7 -> 45954 | B32: =IF(F32<0,-F32/0.25,F32/0.25) -> 0.6004 | C32: =IF(G32<0,-G32/0.25,G32/0.25) -> 1.2284 | D32: 0.5 | F32: =HAVERD!D133-HAVERD!$B133 -> -0.1501 | G32: =HAVERD!E133-HAVERD!$B133 -> -0.3071
A33: =+A28+7 -> 45957 | B33: =IF(F33<0,-F33/0.25,F33/0.25) -> 0.5932 | C33: =IF(G33<0,-G33/0.25,G33/0.25) -> 1.2012 | D33: 0.5 | F33: =HAVERD!D134-HAVERD!$B134 -> -0.1483 | G33: =HAVERD!E134-HAVERD!$B134 -> -0.3003
A34: =+A29+7 -> 45958 | B34: =IF(F34<0,-F34/0.25,F34/0.25) -> 0.6536 | C34: =IF(G34<0,-G34/0.25,G34/0.25) -> 1.2656 | D34: 0.5 | F34: =HAVERD!D135-HAVERD!$B135 -> -0.1634 | G34: =HAVERD!E135-HAVERD!$B135 -> -0.3164
... A41: =+A36+7 -> 45967 | B41: =IF(F41<0,-F41/0.25,F41/0.25) -> 0.6732 | C41: =IF(G41<0,-G41/0.25,G41/0.25) -> 1.1052 | D41: 0.5 | F41: =HAVERD!D142-HAVERD!$B142 -> -0.1683 | G41: =HAVERD!E142-HAVERD!$B142 -> -0.2763
A42: =+A37+7 -> 45968 | B42: =IF(F42<0,-F42/0.25,F42/0.25) -> 0.6828 | C42: =IF(G42<0,-G42/0.25,G42/0.25) -> 1.0588 | D42: 0.5 | F42: =HAVERD!C143-HAVERD!$B143 -> -0.1707 | G42: =HAVERD!D143-HAVERD!$B143 -> -0.2647
A43: =+A38+7 -> 45971 | B43: =IF(F43<0,-F43/0.25,F43/0.25) -> 0.6816 | C43: =IF(G43<0,-G43/0.25,G43/0.25) -> 1.0256 | D43: 0.5 | F43: =HAVERD!C144-HAVERD!$B144 -> -0.1704 | G43: =HAVERD!D144-HAVERD!$B144 -> -0.2564
A44: =+A39+7 -> 45972 | B44: =IF(F44<0,-F44/0.25,F44/0.25) -> 0.8296 | C44: =IF(G44<0,-G44/0.25,G44/0.25) -> 1.2496 | D44: 0.5 | F44: =HAVERD!C145-HAVERD!$B145 -> -0.2074 | G44: =HAVERD!D145-HAVERD!$B145 -> -0.3124
A45: =+A40+7 -> 45973 | B45: =IF(F45<0,-F45/0.25,F45/0.25) -> 0.8168 | C45: =IF(G45<0,-G45/0.25,G45/0.25) -> 1.2528 | D45: 0.5 | F45: =HAVERD!C146-HAVERD!$B146 -> -0.2042 | G45: =HAVERD!D146-HAVERD!$B146 -> -0.3132
A46: =+A41+7 -> 45974 | B46: =IF(F46<0,-F46/0.25,F46/0.25) -> 0.8072 | C46: =IF(G46<0,-G46/0.25,G46/0.25) -> 1.1952 | D46: 0.5 | F46: =HAVERD!C147-HAVERD!$B147 -> -0.2018 | G46: =HAVERD!D147-HAVERD!$B147 -> -0.2988
A47: =+A42+7 -> 45975 | B47: =IF(F47<0,-F47/0.25,F47/0.25) -> 0.7496 | C47: =IF(G47<0,-G47/0.25,G47/0.25) -> 1.0936 | D47: 0.5 | F47: =HAVERD!C148-HAVERD!$B148 -> -0.1874 | G47: =HAVERD!D148-HAVERD!$B148 -> -0.2734
A48: =+A43+7 -> 45978 | B48: =IF(F48<0,-F48/0.25,F48/0.25) -> 0.7288 | C48: =IF(G48<0,-G48/0.25,G48/0.25) -> 1.0648 | D48: 0.5 | F48: =HAVERD!C149-HAVERD!$B149 -> -0.1822 | G48: =HAVERD!D149-HAVERD!$B149 -> -0.2662
...

Sheet HAVERD
A1: 20250501 !D | B1: R112LOS@INTDAILY | C1: M112MOT@INTDAILY | D1: M112MTH@INTDAILY | E1: M112MHF@INTDAILY | F1: M112MHV@INTDAILY
A2: .DESC | B2: UK:Lending Rate: Sterling Overnight Interbank Average [SONIA] (% pa) | C2: UK: Forward OIS: MPC Mtg Date # 1 vs MPC Mtg Date # 2: Mid Rate (% p.a.) | D2: UK: Forward OIS: MPC Mtg Date # 2 vs MPC Mtg Date # 3: Mid Rate (% p.a.) | E2: UK: Forward OIS: MPC Mtg Date # 3 vs MPC Mtg Date # 4: Mid Rate (% p.a.) | F2: UK: Forward OIS: MPC Mtg Date # 4 vs MPC Mtg Date # 5: Mid Rate (% p.a.)
A3: .T1 | B3: 02-Jan-1997 | C3: 16-May-2007 | D3: 16-May-2007 | E3: 16-May-2007 | F3: 16-May-2007
A4: .TN | B4: 08-Dec-2025 | C4: 10-Dec-2025 | D4: 10-Dec-2025 | E4: 10-Dec-2025 | F4: 10-Dec-2025
A5: .LSOURCE | B5: Bank of England | C5: Tullett Prebon Information/Haver Analytics | D5: Tullett Prebon Information/Haver Analytics | E5: Tullett Prebon Information/Haver Analytics | F5: Tullett Prebon Information/Haver Analytics
A6: .DTLM | B6: Dec-10-2025 09:31 | C6: Dec-10-2025 19:12 | D6: Dec-10-2025 19:12 | E6: Dec-10-2025 19:12 | F6: Dec-10-2025 19:12
A7: 20250501 | B7: 4.4586 | C7: 4.2 | D7: 4.062 | E7: 3.852 | F7: 3.715
A8: 20250502 | B8: 4.4594 | C8: 4.204 | D8: 4.075 | E8: 3.873 | F8: 3.735
A9: 20250505 | B9: #N/A | C9: 4.208 | D9: 4.078 | E9: 3.875 | F9: 3.74
A10: 20250506 | B10: 4.459 | C10: 4.2 | D10: 4.068 | E10: 3.866 | F10: 3.725
A11: 20250507 | B11: 4.4601 | C11: 4.204 | D11: 4.073 | E11: 3.872 | F11: 3.726
A12: 20250508 | B12: 4.21 | C12: 4.219 | D12: 4.172 | E12: 3.987 | F12: 3.876
A13: 20250509 | B13: 4.2103 | C13: 4.166 | D13: 3.976 | E13: 3.873 | F13: 3.712
A14: 20250512 | B14: 4.21 | C14: 4.19 | D14: 4.01 | E14: 3.934 | F14: 3.792
A15: 20250513 | B15: 4.2106 | C15: 4.195 | D15: 4.018 | E15: 3.946 | F15: 3.798
A16: 20250514 | B16: 4.2108 | C16: 4.199 | D16: 4.041 | E16: 3.984 | F16: 3.853
A17: 20250515 | B17: 4.2111 | C17: 4.199 | D17: 4.038 | E17: 3.971 | F17: 3.833
A18: 20250516 | B18: 4.2106 | C18: 4.202 | D18: 4.049 | E18: 3.98 | F18: 3.846
A19: 20250519 | B19: 4.2109 | C19: 4.199 | D19: 4.041 | E19: 3.981 | F19: 3.853
A20: 20250520 | B20: 4.2108 | C20: 4.203 | D20: 4.056 | E20: 3.996 | F20: 3.872
A21: 20250521 | B21: 4.2115 | C21: 4.213 | D21: 4.095 | E21: 4.035 | F21: 3.908
... A23: 20250523 | B23: 4.2108 | C23: 4.215 | D23: 4.088 | E23: 4.028 | F23: 3.884
A24: 20250526 | B24: #N/A | C24: 4.218 | D24: 4.093 | E24: 4.033 | F24: 3.884
A25: 20250527 | B25: 4.2107 | C25: 4.218 | D25: 4.102 | E25: 4.052 | F25: 3.912
A26: 20250528 | B26: 4.2104 | C26: 4.219 | D26: 4.104 | E26: 4.061 | F26: 3.924
A27: 20250529 | B27: 4.2107 | C27: 4.217 | D27: 4.101 | E27: 4.056 | F27: 3.907
A28: 20250530 | B28: 4.2111 | C28: 4.21 | D28: 4.098 | E28: 4.053 | F28: 3.909
A29: 20250602 | B29: 4.2112 | C29: 4.216 | D29: 4.1 | E29: 4.056 | F29: 3.916
A30: 20250603 | B30: 4.2112 | C30: 4.217 | D30: 4.074 | E30: 4.028 | F30: 3.889
A31: 20250604 | B31: 4.2111 | C31: 4.213 | D31: 4.065 | E31: 4.016 | F31: 3.869
A32: 20250605 | B32: 4.2119 | C32: 4.217 | D32: 4.063 | E32: 4.019 | F32: 3.877
A33: 20250606 | B33: 4.2118 | C33: 4.216 | D33: 4.062 | E33: 4.025 | F33: 3.891
A34: 20250609 | B34: 4.2128 | C34: 4.214 | D34: 4.054 | E34: 4.01 | F34: 3.867
A35: 20250610 | B35: 4.2126 | C35: 4.207 | D35: 4.017 | E35: 3.957 | F35: 3.802
A36: 20250611 | B36: 4.2129 | C36: 4.208 | D36: 4.018 | E36: 3.956 | F36: 3.801
... A88: 20250822 | B88: 3.9671 | C88: 3.973 | D88: 3.914 | E88: 3.866 | F88: 3.769
A89: 20250825 | B89: #N/A | C89: 3.975 | D89: 3.914 | E89: 3.863 | F89: 3.764
A90: 20250826 | B90: 3.9674 | C90: 3.975 | D90: 3.918 | E90: 3.87 | F90: 3.775
A91: 20250827 | B91: 3.9675 | C91: 3.977 | D91: 3.924 | E91: 3.879 | F91: 3.784
A92: 20250828 | B92: 3.9675 | C92: 3.974 | D92: 3.924 | E92: 3.872 | F92: 3.773
...
