Workbook
Name _DLX1.INC: HAVERM!$A$1:$G$6
Name _DLX2.INC: HAVERQ!$A$2:$CM$7
Name _DLX3.INC: HAVERA!$A$1:$E$6
Name Data: [1]sheet0!$C$2

Sheet CHARTS>>

Sheet DATA>>

Sheet Chart Data
A1: Labour income cont to PEDY! | F1: Labour income cont to PEDY | M1: Unit wage costs & profits | Q1: BoE DMP | Y1: NICs simulation | BC1: ASHE annual pay by sector | BK1: ASHE annual pay by sector | BR1: ASHE annual pay by sector | BY1: NICs & NLW calculation - FT workers | DQ1: NICs & NLW calculation - all workers | FI1: NICs timeseries | FJ1: NLW | FR1: Median | FZ1: Business surveys | GH1: MEAN | GI1: =AVERAGE(GL4:GL103) -> 18.023755 | GJ1: =AVERAGE(GM4:GM103) -> 7.3895901 | GR1: Company profits | GV1: Company profits | GZ1: Employment forecasts - ETILO | HK1: Employment forecasts - ET | HV1: CIPD - impact of employment allowance
R2: =RANK(R6,$R$6:$W$6) -> 4 | S2: =RANK(S6,$R$6:$W$6) -> 3 | T2: =RANK(T6,$R$6:$W$6) -> 2 | U2: =RANK(U6,$R$6:$W$6) -> 1 | V2: =RANK(V6,$R$6:$W$6) -> 5 | W2: =RANK(W6,$R$6:$W$6) -> 6 | Z2: Unemployment | AH2: Employment | AQ2: Earnings | AT2: Earnings | BZ2: Salary | CM2: Employers NICs | DA2: Salary + NICs | DN2: Employers NICs | DR2: Salary | EE2: Employers NICs | ES2: Salary + NICs | FF2: Employers NICs | FO2: Employers NICs | FW2: Employers NICs | GC2: Range of surveys (LHS) | GH2: STDEV | GI2: =STDEV(GL4:GL103) -> 10.904487 | GJ2: =STDEV(GM4:GM103) -> 16.407212 | GL2: Weighted averages
B3: Labour income | C3: Other | D3: Nominal household income | G3: Labour income | H3: Other | I3: Real household income | K3: PC | N3: Unit wage costs (LHS) | O3: Corporate profits (RHS) | R3: ='DMP - NICs Reaction'!B3 -> Lower employee wages | S3: ='DMP - NICs Reaction'!C3 -> Lower number of employees | T3: ='DMP - NICs Reaction'!D3 -> Higher prices | U3: ='DMP - NICs Reaction'!E3 -> Lower profit margins | V3: ='DMP - NICs Reaction'!F3 -> Other | W3: ='DMP - NICs Reaction'!G3 -> None of the above | Z3: Baseline | AA3: No NICs rise | AC3: 45566 | AD3: NICs scenario | AE3: Diff | AH3: Baseline | AI3: No NICs rise | AJ3: Diff | AL3: 45566 | AM3: NICs scenario | AN3: Diff | AQ3: Baseline | AR3: No NICs rise | AS3: Diff | AT3: Baseline | AU3: No NICs rise | AV3: Diff | AX3: 45566 | AY3: NICs scenario | AZ3: Diff | BC3: Sector | BD3: 10 | BE3: 25 | BF3: Median | BG3: 75 | BK3: Sector | BL3: 10 | BM3: 25 | BN3: Median | BO3: 75 | BR3: Sector | BS3: 10 | BT3: 25 | BU3: Median | BV3: 75 | BZ3: 10 | CA3: 20 | CB3: 30 | CC3: 40 | CD3: Median | CE3: 60 | CF3: 70 | CG3: 80 | CH3: 90 | CJ3: NLW | CK3: Mean | CM3: 10 | CN3: 20 | CO3: 30 | CP3: 40 | CQ3: Median | CR3: 60 | CS3: 70 | CT3: 80 | CU3: 90 | CW3: NLW | CX3: Mean | DA3: 10 | DB3: 20 | DC3: 30 | DD3: 40 | DE3: Median | DF3: 60 | DG3: 70 | DH3: 80 | DI3: 90 | DK3: NLW | DL3: Mean | DN3: Rate | DO3: Seconday threshold | DR3: 10 | DS3: 20 | DT3: 30 | DU3: 40 | DV3: Median | DW3: 60 | DX3: 70 | DY3: 80 | DZ3: 90 | EB3: NLW | EC3: Mean | EE3: 10 | EF3: 20 | EG3: 30 | EH3: 40 | EI3: Median | EJ3: 60 | EK3: 70 | EL3: 80 | EM3: 90 | EO3: NLW | EP3: Mean | ES3: 10 | ET3: 20 | EU3: 30 | EV3: 40 | EW3: Median | EX3: 60 | EY3: 70 | EZ3: 80 | FA3: 90 | FC3: NLW | FD3: Mean | FF3: Rate | FG3: Seconday threshold | FJ3: NLW | FK3: NICs payable | FL3: Total cost | FO3: Rate | FP3: Seconday threshold | FR3: Median | FS3: NICs payable | FT3: Total cost | FW3: Rate | FX3: Seconday threshold | GA3: ONS workforce jobs (LHS) | GB3: Min | GC3: Range of CBI & BCC surveys, advanced three months (RHS) | GD3: Average | GF3: Max | GI3: BCC | GJ3: CBI | GL3: BCC | GM3: CBI | GO3: BoE agents | GP3: BoE DMP | GS3: Corporate profits | GT3: Average 2020-2024 | GW3: Corporate profits (LHS) | GX3: Unit wage costs (RHS) | HA3: 45566 | HB3: 45689 | HC3: Difference | HE3: 45566 | HF3: 45689 | HH3: 45566 | HI3: 45689 | HL3: 45566 | HM3: 45689 | HN3: Difference | HP3: 45566 | HQ3: 45689 | HS3: 45566 | HT3: 45689 | HW3: All small firms (2-49 employees) | HX3: 2 to 9 employees | HY3: 10 to 49 employees
A4: 2014 | B4: =100*((DataA!G48-DataA!G47)/DataA!H47) -> 2.2545386 | C4: =D4-B4 -> 1.2449333 | D4: =100*((DataA!H48/DataA!H47)-1) -> 3.4994719 | F4: 2014 | G4: =B4-K4 -> 1.0973014 | H4: =I4-G4 -> 1.1592146 | I4: =100*((DataA!I48/DataA!I47)-1) -> 2.2565161 | K4: =100*((DataA!J48/DataA!J47)-1) -> 1.1572372 | M4: 2012 | N4: =100*((DataQ!F163/DataQ!F159)-1) -> -1.0460326 | O4: =100*(DataQ!I163/DataQ!J163) -> 21.990625 | Q4: ='DMP - NICs Reaction'!A4 -> 45597 | R4: ='DMP - NICs Reaction'!B4 -> 37.88 | S4: ='DMP - NICs Reaction'!C4 -> 53.68 | T4: ='DMP - NICs Reaction'!D4 -> 53.64 | U4: ='DMP - NICs Reaction'!E4 -> 58.72 | V4: ='DMP - NICs Reaction'!F4 -> 7.51 | W4: ='DMP - NICs Reaction'!G4 -> 2.67 | Y4: 44562 | Z4: =DataQ!Q203 -> 3.8 | AA4: =Z4 -> 3.8 | AC4: =DataQ!V203 -> 3.9 | AD4: =DataQ!AB203 -> 3.9 | AE4: =AD4-AC4 -> 0 | AG4: 44562 | AH4: =DataQ!O203 -> 32784 | AI4: =AH4 -> 32784 | AJ4: =AI4-AH4 -> 0 | AL4: =DataQ!T203 -> 32775 | AM4: =DataQ!Z203 -> 32775 | AN4: =AM4-AL4 -> 0 | AP4: 44562 | AQ4: =100*((DataQ!R203/DataQ!R199)-1) -> 5.98157 | AR4: =AQ4 -> 5.98157 | AS4: =AR4-AQ4 -> 0 | AT4: =DataQ!R203 -> 8707.29 | AU4: =AT4 -> 8707.29 | AV4: =AU4-AT4 -> 0 | AX4: =DataQ!U203 -> 8762.161 | AY4: =DataQ!AA203 -> 8762.161 | AZ4: =AY4-AX4 -> 0 | BB4: =RANK(BE4,$BE$4:$BE$22) -> 14 | BC4: Agriculture | BD4: ='ASHE Annual pay All SIC'!H26 -> 9753 | BE4: ='ASHE Annual pay All SIC'!J26 -> 18000 | BF4: ='ASHE Annual pay All SIC'!D26 -> 27288 | BG4: ='ASHE Annual pay All SIC'!O26 -> 36266 | BH4: 1.5 | BJ4: 1 | BK4: =VLOOKUP($BJ4,$BB$4:$BG$22,2,FALSE) -> Utilities | BL4: =VLOOKUP($BJ4,$BB$4:$BG$22,3,FALSE) -> 25643 | BM4: =VLOOKUP($BJ4,$BB$4:$BG$22,4,FALSE) -> 37550 | BN4: =VLOOKUP($BJ4,$BB$4:$BG$22,5,FALSE) -> 51886 | BO4: =VLOOKUP($BJ4,$BB$4:$BG$22,6,FALSE) -> 73580 | BP4: 1.5 | BR4: Agriculture | BS4: =BD4 -> 9753 | BT4: =BE4-BS4 -> 8247 | BU4: =BF4-BT4 -> 19041 | BV4: =BG4-BU4 -> 17225 | BW4: 0.5 | BY4: 2024-2025 | BZ4: ='ASHE Annual pay FT'!H6 -> 22763 | CA4: ='ASHE Annual pay FT'!I6 -> 26250 | CB4: ='ASHE Annual pay FT'!K6 -> 29731 | CC4: ='ASHE Annual pay FT'!L6 -> 33276 | CD4: ='ASHE Annual pay FT'!D6 -> 37430 | CE4: ='ASHE Annual pay FT'!M6 -> 42148 | CF4: ='ASHE Annual pay FT'!N6 -> 47898 | CG4: ='ASHE Annual pay FT'!O6 -> 51391 | CH4: ='ASHE Annual pay FT'!P6 -> 55912 | CJ4: =HAVERM!D549*$CJ$8*52 -> 20820.8 | CK4: ='ASHE Annual pay FT'!F6 -> 45836 | CM4: =(BZ4-$DO4)*$DN4 -> 1885.494 | CN4: =(CA4-$DO4)*$DN4 -> 2366.7 | CO4: =(CB4-$DO4)*$DN4 -> 2847.078 | CP4: =(CC4-$DO4)*$DN4 -> 3336.288 | CQ4: =(CD4-$DO4)*$DN4 -> 3909.54 | CR4: =(CE4-$DO4)*$DN4 -> 4560.624 | CS4: =(CF4-$DO4)*$DN4 -> 5354.124 | CT4: =(CG4-$DO4)*$DN4 -> 5836.158 | CU4: =(CH4-$DO4)*$DN4 -> 6460.056 | CW4: =(CJ4-$DO4)*$DN4 -> 1617.4704 | CX4: =(CK4-$DO4)*$DN4 -> 5069.568 | DA4: =BZ4+CM4 -> 24648.494 | DB4: =CA4+CN4 -> 28616.7 | DC4: =CB4+CO4 -> 32578.078 | DD4: =CC4+CP4 -> 36612.288 | DE4: =CD4+CQ4 -> 41339.54 | DF4: =CE4+CR4 -> 46708.624 | DG4: =CF4+CS4 -> 53252.124 | DH4: =CG4+CT4 -> 57227.158 | DI4: =CH4+CU4 -> 62372.056 | DK4: =CJ4+CW4 -> 22438.27 | DL4: =CK4+CX4 -> 50905.568 | DN4: 0.138 | DO4: 9100 | DQ4: 2024-2025 | DR4: ='ASHE Annual pay All SIC'!H6 -> 11004 | DS4: ='ASHE Annual pay All SIC'!I6 -> 17995 | DT4: ='ASHE Annual pay All SIC'!K6 -> 23541 | DU4: ='ASHE Annual pay All SIC'!L6 -> 27440 | DV4: ='ASHE Annual pay All SIC'!D6 -> 31602 | DW4: ='ASHE Annual pay All SIC'!M6 -> 36538 | DX4: ='ASHE Annual pay All SIC'!N6 -> 42519 | DY4: ='ASHE Annual pay All SIC'!P6 -> 50344 | DZ4: ='ASHE Annual pay All SIC'!Q6 -> 65227 | EB4: =HAVERM!D549*$EB$8*52 -> 20820.8 | EC4: ='ASHE Annual pay All SIC'!F6 -> 38224 | EE4: =(DR4-$FG4)*$FF4 -> 262.752 | EF4: =(DS4-$FG4)*$FF4 -> 1227.51 | EG4: =(DT4-$FG4)*$FF4 -> 1992.858 | EH4: =(DU4-$FG4)*$FF4 -> 2530.92 | EI4: =(DV4-$FG4)*$FF4 -> 3105.276 | EJ4: =(DW4-$FG4)*$FF4 -> 3786.444 | EK4: =(DX4-$FG4)*$FF4 -> 4611.822 | EL4: =(DY4-$FG4)*$FF4 -> 5691.672 | EM4: =(DZ4-$FG4)*$FF4 -> 7745.526 | EO4: =(EB4-$FG4)*$FF4 -> 1617.4704 | EP4: =(EC4-$FG4)*$FF4 -> 4019.112 | ES4: =DR4+EE4 -> 11266.752 | ET4: =DS4+EF4 -> 19222.51 | EU4: =DT4+EG4 -> 25533.858 | EV4: =DU4+EH4 -> 29970.92 | EW4: =DV4+EI4 -> 34707.276 | EX4: =DW4+EJ4 -> 40324.444 | EY4: =DX4+EK4 -> 47130.822 | EZ4: =DY4+EL4 -> 56035.672 | FA4: =DZ4+EM4 -> 72972.526 | FC4: =EB4+EO4 -> 22438.27 | FD4: =EC4+EP4 -> 42243.112 | FF4: 0.138 | FG4: 9100 | FI4: FY19 | FJ4: =HAVERM!D478*35*52 -> 14942.2 | FK4: =(FJ4-$FP4)*$FO4 -> 870.8076 | FL4: =+FK4+FJ4 -> 15813.008 | FO4: 0.138 | FP4: 8632 | FR4: =HAVERA!B26 -> 30378 | FS4: =(FR4-$FX4)*$FW4 -> 3000.948 | FT4: =+FS4+FR4 -> 33378.948 | FW4: 0.138 | FX4: 8632 | FZ4: 36526 | GA4: =100*((HAVERQ!S88/HAVERQ!S84)-1) -> 1.3920717 | GB4: =MIN(GI3:GJ3) -> 0 | GC4: =+GF4-GB4 -> 0 | GD4: =AVERAGE(GB4,GF4) -> 0 | GF4: =MAX(GI3:GJ3) -> 0 | GH4: 36526 | GI4: =(GL4-GI$1)/GI$2 -> 0.66633495 | GJ4: =(GM4-GJ$1)/GJ$2 -> 1.0550526 | GL4: =(HAVERQ!BJ88*HAVERQ!$BJ$1)+(HAVERQ!BK88*HAVERQ!$BK$1) -> 25.289796 | GM4: =(HAVERQ!BL88*HAVERQ!$BL$1)+(HAVERQ!BM88*HAVERQ!$BM$1)+(HAVERQ!BN88*HAVERQ!$BN$1)+(HAVERQ!BO88*HAVERQ!$BO$1) -> 24.700061 | GR4: 36526 | GS4: =100*(HAVERQ!BP88/HAVERQ!BR88) -> 25.409106 | GT4: =AVERAGE($GS$4:$GS$103) -> 24.605137 | GV4: 36526 | GW4: =100*(HAVERQ!BP88/HAVERQ!BR88) -> 25.409106 | GX4: =100*((DataQ!F119/DataQ!F115)-1) -> 6.6139866 | GZ4: 44927 | HA4: =HH4-HH$11 -> 44.09 | HB4: =HI4-HI$11 -> -455.7 | HC4: =HB4-HA4 -> -499.79 | HE4: =100*(HH4/$HH$11) -> 100.13297 | HF4: =100*(HI4/$HI$11) -> 98.650805 | HH4: =DataQ!AE207 -> 33201 | HI4: =DataQ!O207 -> 33320 | HK4: 44927 | HL4: =HS4-HS$11 -> -366.92 | HM4: =HT4-HT$11 -> -393.34 | HN4: =HM4-HL4 -> -26.42 | HP4: =100*(HS4/HS$11) -> 99.010942 | HQ4: =100*(HT4/HT$11) -> 98.934914 | HS4: =DataQ!AF207 -> 36731 | HT4: =DataQ!P207 -> 36537 | HV4: Lower to a large extent | HW4: 5 | HX4: 5 | HY4: 5
A5: 2015 | B5: =100*((DataA!G49-DataA!G48)/DataA!H48) -> 2.0418208 | C5: =D5-B5 -> 3.649196 | D5: =100*((DataA!H49/DataA!H48)-1) -> 5.6910168 | F5: 2015 | G5: =B5-K5 -> 2.4131255 | H5: =I5-G5 -> 3.6485662 | I5: =100*((DataA!I49/DataA!I48)-1) -> 6.0616917 | K5: =100*((DataA!J49/DataA!J48)-1) -> -0.37130467 | N5: =100*((DataQ!F164/DataQ!F160)-1) -> 0.71283454 | O5: =100*(DataQ!I164/DataQ!J164) -> 21.877964 | Q5: ='DMP - NICs Reaction'!A5 -> 45627 | R5: ='DMP - NICs Reaction'!B5 -> 40.67 | S5: ='DMP - NICs Reaction'!C5 -> 52.76 | T5: ='DMP - NICs Reaction'!D5 -> 54.45 | U5: ='DMP - NICs Reaction'!E5 -> 63.5 | V5: ='DMP - NICs Reaction'!F5 -> 7.33 | W5: ='DMP - NICs Reaction'!G5 -> 3.75 | Y5: 44652 | Z5: =DataQ!Q204 -> 3.8 | AA5: =Z5 -> 3.8 | AC5: =DataQ!V204 -> 3.9 | AD5: =DataQ!AB204 -> 3.9 | AE5: =AD5-AC5 -> 0 | AG5: 44652 | AH5: =DataQ!O204 -> 33007 | AI5: =AH5 -> 33007 | AJ5: =AI5-AH5 -> 0 | AL5: =DataQ!T204 -> 32958 | AM5: =DataQ!Z204 -> 32958 | AN5: =AM5-AL5 -> 0 | AP5: 44652 | AQ5: =100*((DataQ!R204/DataQ!R200)-1) -> 3.9892354 | AR5: =AQ5 -> 3.9892354 | AS5: =AR5-AQ5 -> 0 | AT5: =DataQ!R204 -> 8783.535 | AU5: =AT5 -> 8783.535 | AV5: =AU5-AT5 -> 0 | AX5: =DataQ!U204 -> 8858.754 | AY5: =DataQ!AA204 -> 8858.754 | AZ5: =AY5-AX5 -> 0 | BB5: =RANK(BE5,$BE$4:$BE$22) -> 2 | BC5: Extraction | BD5: ='ASHE Annual pay All SIC'!H30 -> 25213 | BE5: ='ASHE Annual pay All SIC'!J30 -> 33999 | BF5: ='ASHE Annual pay All SIC'!D30 -> 47022 | BG5: ='ASHE Annual pay All SIC'!O30 -> 64863 | BH5: =+BH4+1 -> 2.5 | BJ5: 2 | BK5: =VLOOKUP($BJ5,$BB$4:$BG$22,2,FALSE) -> Extraction | BL5: =VLOOKUP($BJ5,$BB$4:$BG$22,3,FALSE) -> 25213 | BM5: =VLOOKUP($BJ5,$BB$4:$BG$22,4,FALSE) -> 33999 | BN5: =VLOOKUP($BJ5,$BB$4:$BG$22,5,FALSE) -> 47022 | BO5: =VLOOKUP($BJ5,$BB$4:$BG$22,6,FALSE) -> 64863 | BP5: =+BP4+1 -> 2.5 | BR5: Extraction | BS5: =BD5 -> 25213 | BT5: =BE5-BS5 -> 8786 | BU5: =BF5-BT5 -> 38236 | BV5: =BG5-BU5 -> 26627 | BW5: =+BW4+1 -> 1.5 | BY5: 2025-2026 | BZ5: =BZ4*DataQ!$H$216/DataQ!$H$212 -> 23926.006 | CA5: =CA4*DataQ!$H$216/DataQ!$H$212 -> 27591.164 | CB5: =CB4*DataQ!$H$216/DataQ!$H$212 -> 31250.015 | CC5: =CC4*DataQ!$H$216/DataQ!$H$212 -> 34976.136 | CD5: =CD4*DataQ!$H$216/DataQ!$H$212 -> 39342.372 | CE5: =CE4*DataQ!$H$216/DataQ!$H$212 -> 44301.424 | CF5: =CF4*DataQ!$H$216/DataQ!$H$212 -> 50345.202 | CG5: =CG4*DataQ!$H$216/DataQ!$H$212 -> 54016.667 | CH5: =CH4*DataQ!$H$216/DataQ!$H$212 -> 58768.653 | CJ5: =HAVERM!D550*$CJ$8*52 -> 22222.2 | CK5: =CK4*DataQ!$H$216/DataQ!$H$212 -> 48177.851 | CM5: =(BZ5-$DO5)*$DN5 -> 2838.9009 | CN5: =(CA5-$DO5)*$DN5 -> 3388.6746 | CO5: =(CB5-$DO5)*$DN5 -> 3937.5022 | CP5: =(CC5-$DO5)*$DN5 -> 4496.4204 | CQ5: =(CD5-$DO5)*$DN5 -> 5151.3558 | CR5: =(CE5-$DO5)*$DN5 -> 5895.2135 | CS5: =(CF5-$DO5)*$DN5 -> 6801.7803 | CT5: =(CG5-$DO5)*$DN5 -> 7352.5 | CU5: =(CH5-$DO5)*$DN5 -> 8065.298 | CW5: =(CJ5-$DO5)*$DN5 -> 2583.33 | CX5: =(CK5-$DO5)*$DN5 -> 6476.6776 | DA5: =BZ5+CM5 -> 26764.907 | DB5: =CA5+CN5 -> 30979.838 | DC5: =CB5+CO5 -> 35187.517 | DD5: =CC5+CP5 -> 39472.556 | DE5: =CD5+CQ5 -> 44493.728 | DF5: =CE5+CR5 -> 50196.637 | DG5: =CF5+CS5 -> 57146.983 | DH5: =CG5+CT5 -> 61369.166 | DI5: =CH5+CU5 -> 66833.951 | DK5: =CJ5+CW5 -> 24805.53 | DL5: =CK5+CX5 -> 54654.528 | DN5: 0.15 | DO5: 5000 | DQ5: 2025-2026 | DR5: =DR4*EB5/EB4 -> 11744.654 | DS5: =DS4*DR5/DR4 -> 19206.202 | DT5: =DT4*DataQ!$H$216/DataQ!$H$212 -> 24743.756 | DU5: =DU4*DataQ!$H$216/DataQ!$H$212 -> 28841.963 | DV5: =DV4*DataQ!$H$216/DataQ!$H$212 -> 33216.608 | DW5: =DW4*DataQ!$H$216/DataQ!$H$212 -> 38404.798 | DX5: =DX4*DataQ!$H$216/DataQ!$H$212 -> 44691.379 | DY5: =DY4*DataQ!$H$216/DataQ!$H$212 -> 52916.173 | DZ5: =DZ4*DataQ!$H$216/DataQ!$H$212 -> 68559.575 | EB5: =HAVERM!D550*$EB$8*52 -> 22222.2 | EC5: =EC4*DataQ!$H$216/DataQ!$H$212 -> 40176.939 | EE5: =(DR5-$FG5)*$FF5 -> 1011.6981 | EF5: =(DS5-$FG5)*$FF5 -> 2130.9303 | EG5: =(DT5-$FG5)*$FF5 -> 2961.5633 | EH5: =(DU5-$FG5)*$FF5 -> 3576.2945 | EI5: =(DV5-$FG5)*$FF5 -> 4232.4912 | EJ5: =(DW5-$FG5)*$FF5 -> 5010.7197 | EK5: =(DX5-$FG5)*$FF5 -> 5953.7068 | EL5: =(DY5-$FG5)*$FF5 -> 7187.426 | EM5: =(DZ5-$FG5)*$FF5 -> 9533.9362 | EO5: =(EB5-$FG5)*$FF5 -> 2583.33 | EP5: =(EC5-$FG5)*$FF5 -> 5276.5408 | ES5: =DR5+EE5 -> 12756.352 | ET5: =DS5+EF5 -> 21337.132 | EU5: =DT5+EG5 -> 27705.319 | EV5: =DU5+EH5 -> 32418.258 | EW5: =DV5+EI5 -> 37449.099 | EX5: =DW5+EJ5 -> 43415.517 | EY5: =DX5+EK5 -> 50645.086 | EZ5: =DY5+EL5 -> 60103.599 | FA5: =DZ5+EM5 -> 78093.511 | FC5: =EB5+EO5 -> 24805.53 | FD5: =EC5+EP5 -> 45453.48 | FF5: 0.15 | FG5: 5000 | FI5: FY20 | FJ5: =HAVERM!D490*35*52 -> 15870.4 | FK5: =(FJ5-$FP5)*$FO5 -> 977.3712 | FL5: =+FK5+FJ5 -> 16847.771 | FM5: =100*((FL5/FL4)-1) -> 6.5437495 | FO5: 0.138 | FP5: 8788 | FR5: =HAVERA!B27 -> 31487 | FS5: =(FR5-$FX5)*$FW5 -> 3132.462 | FT5: =+FS5+FR5 -> 34619.462 | FU5: =100*((FT5/FT4)-1) -> 3.7164563 | FW5: 0.138 | FX5: 8788 | FZ5: 36617 | GA5: =100*((HAVERQ!S89/HAVERQ!S85)-1) -> 1.5276026 | GB5: =MIN(GI4:GJ4) -> 0.66633495 | GC5: =+GF5-GB5 -> 0.38871763 | GD5: =AVERAGE(GB5,GF5) -> 0.86069377 | GF5: =MAX(GI4:GJ4) -> 1.0550526 | GH5: 36617 | GI5: =(GL5-GI$1)/GI$2 -> 1.0688007 | GJ5: =(GM5-GJ$1)/GJ$2 -> 1.1152209 | GL5: =(HAVERQ!BJ89*HAVERQ!$BJ$1)+(HAVERQ!BK89*HAVERQ!$BK$1) -> 29.678479 | GM5: =(HAVERQ!BL89*HAVERQ!$BL$1)+(HAVERQ!BM89*HAVERQ!$BM$1)+(HAVERQ!BN89*HAVERQ!$BN$1)+(HAVERQ!BO89*HAVERQ!$BO$1) -> 25.687255 | GR5: 36617 | GS5: =100*(HAVERQ!BP89/HAVERQ!BR89) -> 24.420992 | GT5: =AVERAGE($GS$4:$GS$103) -> 24.605137 | GV5: 36617 | GW5: =100*(HAVERQ!BP89/HAVERQ!BR89) -> 24.420992 | GX5: =100*((DataQ!F120/DataQ!F116)-1) -> 4.3324967 | GZ5: 45017 | HA5: =HH5-HH$11 -> 6.09 | HB5: =HI5-HI$11 -> -419.7 | HC5: =HB5-HA5 -> -425.79 | HE5: =100*(HH5/$HH$11) -> 100.01837 | HF5: =100*(HI5/$HI$11) -> 98.757391 | HH5: =DataQ!AE208 -> 33163 | HI5: =DataQ!O208 -> 33356 | HK5: 45017 | HL5: =HS5-HS$11 -> -511.92 | HM5: =HT5-HT$11 -> -626.34 | HN5: =HM5-HL5 -> -114.42 | HP5: =100*(HS5/HS$11) -> 98.620084 | HQ5: =100*(HT5/HT$11) -> 98.303996 | HS5: =DataQ!AF208 -> 36586 | HT5: =DataQ!P208 -> 36304 | HV5: Lower to some extent | HW5: 23 | HX5: 18.33 | HY5: 27
A6: 2016 | B6: =100*((DataA!G50-DataA!G49)/DataA!H49) -> 2.0449227 | C6: =D6-B6 -> -0.089021233 | D6: =100*((DataA!H50/DataA!H49)-1) -> 1.9559014 | F6: 2016 | G6: =B6-K6 -> 0.77782891 | H6: =I6-G6 -> -0.083554616 | I6: =100*((DataA!I50/DataA!I49)-1) -> 0.6942743 | K6: =100*((DataA!J50/DataA!J49)-1) -> 1.2670938 | N6: =100*((DataQ!F165/DataQ!F161)-1) -> 0.63328293 | O6: =100*(DataQ!I165/DataQ!J165) -> 22.746912 | Q6: ='DMP - NICs Reaction'!A6 -> 45658 | R6: ='DMP - NICs Reaction'!B6 -> 36.63 | S6: ='DMP - NICs Reaction'!C6 -> 53.63 | T6: ='DMP - NICs Reaction'!D6 -> 61.1 | U6: ='DMP - NICs Reaction'!E6 -> 63.46 | V6: ='DMP - NICs Reaction'!F6 -> 11.88 | W6: ='DMP - NICs Reaction'!G6 -> 2.94 | Y6: 44743 | Z6: =DataQ!Q205 -> 3.7 | AA6: =Z6 -> 3.7 | AC6: =DataQ!V205 -> 3.8 | AD6: =DataQ!AB205 -> 3.8 | AE6: =AD6-AC6 -> 0 | AG6: 44743 | AH6: =DataQ!O205 -> 32904 | AI6: =AH6 -> 32904 | AJ6: =AI6-AH6 -> 0 | AL6: =DataQ!T205 -> 32916 | AM6: =DataQ!Z205 -> 32916 | AN6: =AM6-AL6 -> 0 | AP6: 44743 | AQ6: =100*((DataQ!R205/DataQ!R201)-1) -> 6.1822603 | AR6: =AQ6 -> 6.1822603 | AS6: =AR6-AQ6 -> 0 | AT6: =DataQ!R205 -> 8975.527 | AU6: =AT6 -> 8975.527 | AV6: =AU6-AT6 -> 0 | AX6: =DataQ!U205 -> 8972.382 | AY6: =DataQ!AA205 -> 8972.382 | AZ6: =AY6-AX6 -> 0 | BB6: =RANK(BE6,$BE$4:$BE$22) -> 8 | BC6: Manufacturing | BD6: ='ASHE Annual pay All SIC'!H36 -> 21424 | BE6: ='ASHE Annual pay All SIC'!J36 -> 26686 | BF6: ='ASHE Annual pay All SIC'!D36 -> 35518 | BG6: ='ASHE Annual pay All SIC'!O36 -> 49243 | BH6: =+BH5+1 -> 3.5 | BJ6: 3 | BK6: =VLOOKUP($BJ6,$BB$4:$BG$22,2,FALSE) -> Communications | BL6: =VLOOKUP($BJ6,$BB$4:$BG$22,3,FALSE) -> 23599 | BM6: =VLOOKUP($BJ6,$BB$4:$BG$22,4,FALSE) -> 32656 | BN6: =VLOOKUP($BJ6,$BB$4:$BG$22,5,FALSE) -> 46063 | BO6: =VLOOKUP($BJ6,$BB$4:$BG$22,6,FALSE) -> 68998 | BP6: =+BP5+1 -> 3.5 | BR6: Manufacturing | BS6: =BD6 -> 21424 | BT6: =BE6-BS6 -> 5262 | BU6: =BF6-BT6 -> 30256 | BV6: =BG6-BU6 -> 18987 | BW6: =+BW5+1 -> 2.5 | BZ6: =100*((BZ5/BZ4)-1) -> 5.1091952 | CA6: =100*((CA5/CA4)-1) -> 5.1091952 | CB6: =100*((CB5/CB4)-1) -> 5.1091952 | CC6: =100*((CC5/CC4)-1) -> 5.1091952 | CD6: =100*((CD5/CD4)-1) -> 5.1091952 | CE6: =100*((CE5/CE4)-1) -> 5.1091952 | CF6: =100*((CF5/CF4)-1) -> 5.1091952 | CG6: =100*((CG5/CG4)-1) -> 5.1091952 | CH6: =100*((CH5/CH4)-1) -> 5.1091952 | CJ6: =100*((CJ5/CJ4)-1) -> 6.7307692 | CK6: =100*((CK5/CK4)-1) -> 5.1091952 | DR6: =100*((DR5/DR4)-1) -> 6.7307692 | DS6: =100*((DS5/DS4)-1) -> 6.7307692 | DT6: =100*((DT5/DT4)-1) -> 5.1091952 | DU6: =100*((DU5/DU4)-1) -> 5.1091952 | DV6: =100*((DV5/DV4)-1) -> 5.1091952 | DW6: =100*((DW5/DW4)-1) -> 5.1091952 | DX6: =100*((DX5/DX4)-1) -> 5.1091952 | DY6: =100*((DY5/DY4)-1) -> 5.1091952 | DZ6: =100*((DZ5/DZ4)-1) -> 5.1091952 | EB6: =100*((EB5/EB4)-1) -> 6.7307692 | EC6: =100*((EC5/EC4)-1) -> 5.1091952 | FI6: FY21 | FJ6: =HAVERM!D502*35*52 -> 16216.2 | FK6: =(FJ6-$FP6)*$FO6 -> 1017.9156 | FL6: =+FK6+FJ6 -> 17234.116 | FM6: =100*((FL6/FL5)-1) -> 2.2931484 | FO6: 0.138 | FP6: 8840 | FR6: =HAVERA!B28 -> 31285 | FS6: =(FR6-$FX6)*$FW6 -> 3097.41 | FT6: =+FS6+FR6 -> 34382.41 | FU6: =100*((FT6/FT5)-1) -> -0.68473623 | FW6: 0.138 | FX6: 8840 | FZ6: 36708 | GA6: =100*((HAVERQ!S90/HAVERQ!S86)-1) -> 1.2608167 | GB6: =MIN(GI5:GJ5) -> 1.0688007 | GC6: =+GF6-GB6 -> 0.046420155 | GD6: =AVERAGE(GB6,GF6) -> 1.0920108 | GF6: =MAX(GI5:GJ5) -> 1.1152209 | GH6: 36708 | GI6: =(GL6-GI$1)/GI$2 -> 0.77942689 | GJ6: =(GM6-GJ$1)/GJ$2 -> 1.0055043 | GL6: =(HAVERQ!BJ90*HAVERQ!$BJ$1)+(HAVERQ!BK90*HAVERQ!$BK$1) -> 26.523006 | GM6: =(HAVERQ!BL90*HAVERQ!$BL$1)+(HAVERQ!BM90*HAVERQ!$BM$1)+(HAVERQ!BN90*HAVERQ!$BN$1)+(HAVERQ!BO90*HAVERQ!$BO$1) -> 23.887112 | GR6: 36708 | GS6: =100*(HAVERQ!BP90/HAVERQ!BR90) -> 23.762266 | GT6: =AVERAGE($GS$4:$GS$103) -> 24.605137 | GV6: 36708 | GW6: =100*(HAVERQ!BP90/HAVERQ!BR90) -> 23.762266 | GX6: =100*((DataQ!F121/DataQ!F117)-1) -> 2.8586523 | GZ6: 45108 | HA6: =HH6-HH$11 -> -54.91 | HB6: =HI6-HI$11 -> -449.7 | HC6: =HB6-HA6 -> -394.79 | HE6: =100*(HH6/$HH$11) -> 99.834393 | HF6: =100*(HI6/$HI$11) -> 98.668569 | HH6: =DataQ!AE209 -> 33102 | HI6: =DataQ!O209 -> 33326 | HK6: 45108 | HL6: =HS6-HS$11 -> -312.92 | HM6: =HT6-HT$11 -> -501.34 | HN6: =HM6-HL6 -> -188.42 | HP6: =100*(HS6/HS$11) -> 99.156503 | HQ6: =100*(HT6/HT$11) -> 98.642471 | HS6: =DataQ!AF209 -> 36785 | HT6: =DataQ!P209 -> 36429 | HV6: Lower to a small extent | HW6: 24 | HX6: 25.33 | HY6: 23
A7: 2017 | B7: =100*((DataA!G51-DataA!G50)/DataA!H50) -> 2.4443958 | C7: =D7-B7 -> 0.27841176 | D7: =100*((DataA!H51/DataA!H50)-1) -> 2.7228076 | F7: 2017 | G7: =B7-K7 -> 0.59145313 | H7: =I7-G7 -> 0.29775587 | I7: =100*((DataA!I51/DataA!I50)-1) -> 0.889209 | K7: =100*((DataA!J51/DataA!J50)-1) -> 1.8529427 | N7: =100*((DataQ!F166/DataQ!F162)-1) -> 1.2250741 | O7: =100*(DataQ!I166/DataQ!J166) -> 22.658746 | Y7: 44835 | Z7: =DataQ!Q206 -> 3.9 | AA7: =Z7 -> 3.9 | AC7: =DataQ!V206 -> 3.9 | AD7: =DataQ!AB206 -> 3.9 | AE7: =AD7-AC7 -> 0 | AG7: 44835 | AH7: =DataQ!O206 -> 33114 | AI7: =AH7 -> 33114 | AJ7: =AI7-AH7 -> 0 | AL7: =DataQ!T206 -> 33067 | AM7: =DataQ!Z206 -> 33067 | AN7: =AM7-AL7 -> 0 | AP7: 44835 | AQ7: =100*((DataQ!R206/DataQ!R202)-1) -> 7.6937643 | AR7: =AQ7 -> 7.6937643 | AS7: =AR7-AQ7 -> 0 | AT7: =DataQ!R206 -> 9173.315 | AU7: =AT7 -> 9173.315 | AV7: =AU7-AT7 -> 0 | AX7: =DataQ!U206 -> 9187.092 | AY7: =DataQ!AA206 -> 9187.092 | AZ7: =AY7-AX7 -> 0 | BB7: =RANK(BE7,$BE$4:$BE$22) -> 1 | BC7: Utilities | BD7: ='ASHE Annual pay All SIC'!H61 -> 25643 | BE7: ='ASHE Annual pay All SIC'!J61 -> 37550 | BF7: ='ASHE Annual pay All SIC'!D61 -> 51886 | BG7: ='ASHE Annual pay All SIC'!O61 -> 73580 | BH7: =+BH6+1 -> 4.5 | BJ7: 4 | BK7: =VLOOKUP($BJ7,$BB$4:$BG$22,2,FALSE) -> Financial services | BL7: =VLOOKUP($BJ7,$BB$4:$BG$22,3,FALSE) -> 21567 | BM7: =VLOOKUP($BJ7,$BB$4:$BG$22,4,FALSE) -> 29873 | BN7: =VLOOKUP($BJ7,$BB$4:$BG$22,5,FALSE) -> 47248 | BO7: =VLOOKUP($BJ7,$BB$4:$BG$22,6,FALSE) -> 78520 | BP7: =+BP6+1 -> 4.5 | BR7: Utilities | BS7: =BD7 -> 25643 | BT7: =BE7-BS7 -> 11907 | BU7: =BF7-BT7 -> 39979 | BV7: =BG7-BU7 -> 33601 | BW7: =+BW6+1 -> 3.5 | DA7: =DA4/1000 -> 24.648494 | DB7: =DB4/1000 -> 28.6167 | DC7: =DC4/1000 -> 32.578078 | DD7: =DD4/1000 -> 36.612288 | DE7: =DE4/1000 -> 41.33954 | DF7: =DF4/1000 -> 46.708624 | DG7: =DG4/1000 -> 53.252124 | DH7: =DH4/1000 -> 57.227158 | DI7: =DI4/1000 -> 62.372056 | DK7: =DK4/1000 -> 22.43827 | DL7: =DL4/1000 -> 50.905568 | ES7: =ES4/1000 -> 11.266752 | ET7: =ET4/1000 -> 19.22251 | EU7: =EU4/1000 -> 25.533858 | EV7: =EV4/1000 -> 29.97092 | EW7: =EW4/1000 -> 34.707276 | EX7: =EX4/1000 -> 40.324444 | EY7: =EY4/1000 -> 47.130822 | EZ7: =EZ4/1000 -> 56.035672 | FA7: =FA4/1000 -> 72.972526 | FC7: =FC4/1000 -> 22.43827 | FD7: =FD4/1000 -> 42.243112 | FI7: FY22 | FJ7: =HAVERM!D514*35*52 -> 17290 | FK7: =(FJ7-$FP7)*$FO7 -> 1181.4075 | FL7: =+FK7+FJ7 -> 18471.408 | FM7: =100*((FL7/FL6)-1) -> 7.1793176 | FO7: =AVERAGE(0.1505,0.138) -> 0.14425 | FP7: 9100 | FR7: =HAVERA!B29 -> 33061 | FS7: =(FR7-$FX7)*$FW7 -> 3456.3742 | FT7: =+FS7+FR7 -> 36517.374 | FU7: =100*((FT7/FT6)-1) -> 6.2094666 | FW7: =AVERAGE(0.1505,0.138) -> 0.14425 | FX7: 9100 | FZ7: 36800 | GA7: =100*((HAVERQ!S91/HAVERQ!S87)-1) -> 0.9994952 | GB7: =MIN(GI6:GJ6) -> 0.77942689 | GC7: =+GF7-GB7 -> 0.22607741 | GD7: =AVERAGE(GB7,GF7) -> 0.8924656 | GF7: =MAX(GI6:GJ6) -> 1.0055043 | GH7: 36800 | GI7: =(GL7-GI$1)/GI$2 -> 0.40547657 | GJ7: =(GM7-GJ$1)/GJ$2 -> 0.83773775 | GL7: =(HAVERQ!BJ91*HAVERQ!$BJ$1)+(HAVERQ!BK91*HAVERQ!$BK$1) -> 22.445269 | GM7: =(HAVERQ!BL91*HAVERQ!$BL$1)+(HAVERQ!BM91*HAVERQ!$BM$1)+(HAVERQ!BN91*HAVERQ!$BN$1)+(HAVERQ!BO91*HAVERQ!$BO$1) -> 21.134531 | GR7: 36800 | GS7: =100*(HAVERQ!BP91/HAVERQ!BR91) -> 22.877807 | GT7: =AVERAGE($GS$4:$GS$103) -> 24.605137 | GV7: 36800 | GW7: =100*(HAVERQ!BP91/HAVERQ!BR91) -> 22.877807 | GX7: =100*((DataQ!F122/DataQ!F118)-1) -> 1.4319515 | GZ7: 45200 | HA7: =HH7-HH$11 -> 17.09 | HB7: =HI7-HI$11 -> -398.7 | HC7: =HB7-HA7 -> -415.79 | HE7: =100*(HH7/$HH$11) -> 100.05154 | HF7: =100*(HI7/$HI$11) -> 98.819566 | HH7: =DataQ!AE210 -> 33174 | HI7: =DataQ!O210 -> 33377 | HK7: 45200 | HL7: =HS7-HS$11 -> -233.92 | HM7: =HT7-HT$11 -> -424.34 | HN7: =HM7-HL7 -> -190.42 | HP7: =100*(HS7/HS$11) -> 99.369453 | HQ7: =100*(HT7/HT$11) -> 98.850972 | HS7: =DataQ!AF210 -> 36864 | HT7: =DataQ!P210 -> 36506 | HV7: Not lower at all | HW7: 29 | HX7: 33.34 | HY7: 24
A8: 2018 | B8: =100*((DataA!G52-DataA!G51)/DataA!H51) -> 2.6151515 | C8: =D8-B8 -> 1.494945 | D8: =100*((DataA!H52/DataA!H51)-1) -> 4.1100965 | F8: 2018 | G8: =B8-K8 -> 0.51580887 | H8: =I8-G8 -> 1.4675349 | I8: =100*((DataA!I52/DataA!I51)-1) -> 1.9833437 | K8: =100*((DataA!J52/DataA!J51)-1) -> 2.0993427 | M8: 2013 | N8: =100*((DataQ!F167/DataQ!F163)-1) -> 0.66949357 | O8: =100*(DataQ!I167/DataQ!J167) -> 22.990853 | R8: 1 | S8: 2 | T8: 3 | U8: 4 | V8: 5 | W8: 6 | Y8: 44927 | Z8: =DataQ!Q207 -> 4 | AA8: =Z8 -> 4 | AC8: =DataQ!V207 -> 4 | AD8: =DataQ!AB207 -> 4 | AE8: =AD8-AC8 -> 0 | AG8: 44927 | AH8: =DataQ!O207 -> 33320 | AI8: =AH8 -> 33320 | AJ8: =AI8-AH8 -> 0 | AL8: =DataQ!T207 -> 33201 | AM8: =DataQ!Z207 -> 33201 | AN8: =AM8-AL8 -> 0 | AP8: 44927 | AQ8: =100*((DataQ!R207/DataQ!R203)-1) -> 7.9306076 | AR8: =AQ8 -> 7.9306076 | AS8: =AR8-AQ8 -> 0 | AT8: =DataQ!R207 -> 9397.831 | AU8: =AT8 -> 9397.831 | AV8: =AU8-AT8 -> 0 | AX8: =DataQ!U207 -> 9460.302 | AY8: =DataQ!AA207 -> 9460.302 | AZ8: =AY8-AX8 -> 0 | BB8: =RANK(BE8,$BE$4:$BE$22) -> 5 | BC8: Water | BD8: ='ASHE Annual pay All SIC'!H63 -> 23302 | BE8: ='ASHE Annual pay All SIC'!J63 -> 29282 | BF8: ='ASHE Annual pay All SIC'!D63 -> 38435 | BG8: ='ASHE Annual pay All SIC'!O63 -> 48565 | BH8: =+BH7+1 -> 5.5 | BJ8: 5 | BK8: =VLOOKUP($BJ8,$BB$4:$BG$22,2,FALSE) -> Water | BL8: =VLOOKUP($BJ8,$BB$4:$BG$22,3,FALSE) -> 23302 | BM8: =VLOOKUP($BJ8,$BB$4:$BG$22,4,FALSE) -> 29282 | BN8: =VLOOKUP($BJ8,$BB$4:$BG$22,5,FALSE) -> 38435 | BO8: =VLOOKUP($BJ8,$BB$4:$BG$22,6,FALSE) -> 48565 | BP8: =+BP7+1 -> 5.5 | BR8: Water | BS8: =BD8 -> 23302 | BT8: =BE8-BS8 -> 5980 | BU8: =BF8-BT8 -> 32455 | BV8: =BG8-BU8 -> 16110 | BW8: =+BW7+1 -> 4.5 | BY8: Hours/week | CJ8: 35 | CZ8: 2025-2026 change | DA8: =100*((DA5/DA4)-1) -> 8.5863786 | DB8: =100*((DB5/DB4)-1) -> 8.2578994 | DC8: =100*((DC5/DC4)-1) -> 8.0098005 | DD8: =100*((DD5/DD4)-1) -> 7.8123175 | DE8: =100*((DE5/DE4)-1) -> 7.6299531 | DF8: =100*((DF5/DF4)-1) -> 7.4675998 | DG8: =100*((DG5/DG4)-1) -> 7.3139968 | DH8: =100*((DH5/DH4)-1) -> 7.2378371 | DI8: =100*((DI5/DI4)-1) -> 7.1536766 | DK8: =100*((DK5/DK4)-1) -> 10.550098 | DL8: =100*((DL5/DL4)-1) -> 7.3645388 | DQ8: Hours/week | EB8: 35 | ER8: 2025-2026 change | ES8: =100*((ES5/ES4)-1) -> 13.221201 | ET8: =100*((ET5/ET4)-1) -> 11.00076 | EU8: =100*((EU5/EU4)-1) -> 8.5042417 | EV8: =100*((EV5/EV4)-1) -> 8.1657074 | EW8: =100*((EW5/EW4)-1) -> 7.8998509 | EX8: =100*((EX5/EX4)-1) -> 7.6655078 | EY8: =100*((EY5/EY4)-1) -> 7.4564019 | EZ8: =100*((EZ5/EZ4)-1) -> 7.2595314 | FA8: =100*((FA5/FA4)-1) -> 7.0176891 | FC8: =100*((FC5/FC4)-1) -> 10.550098 | FD8: =100*((FD5/FD4)-1) -> 7.5997422 | FI8: FY23 | FJ8: =HAVERM!D526*35*52 -> 18964.4 | FK8: =(FJ8-$FP8)*$FO8 -> 1361.2872 | FL8: =+FK8+FJ8 -> 20325.687 | FM8: =100*((FL8/FL7)-1) -> 10.038649 | FO8: 0.138 | FP8: 9100 | FR8: =HAVERA!B30 -> 34963 | FS8: =(FR8-$FX8)*$FW8 -> 3569.094 | FT8: =+FS8+FR8 -> 38532.094 | FU8: =100*((FT8/FT7)-1) -> 5.5171539 | FW8: 0.138 | FX8: 9100 | FZ8: 36892 | GA8: =100*((HAVERQ!S92/HAVERQ!S88)-1) -> 1.288625 | GB8: =MIN(GI7:GJ7) -> 0.40547657 | GC8: =+GF8-GB8 -> 0.43226118 | GD8: =AVERAGE(GB8,GF8) -> 0.62160716 | GF8: =MAX(GI7:GJ7) -> 0.83773775 | GH8: 36892 | GI8: =(GL8-GI$1)/GI$2 -> 0.38505978 | GJ8: =(GM8-GJ$1)/GJ$2 -> 0.21956 | GL8: =(HAVERQ!BJ92*HAVERQ!$BJ$1)+(HAVERQ!BK92*HAVERQ!$BK$1) -> 22.222635 | GM8: =(HAVERQ!BL92*HAVERQ!$BL$1)+(HAVERQ!BM92*HAVERQ!$BM$1)+(HAVERQ!BN92*HAVERQ!$BN$1)+(HAVERQ!BO92*HAVERQ!$BO$1) -> 10.991957 | GR8: 36892 | GS8: =100*(HAVERQ!BP92/HAVERQ!BR92) -> 22.598775 | GT8: =AVERAGE($GS$4:$GS$103) -> 24.605137 | GV8: 36892 | GW8: =100*(HAVERQ!BP92/HAVERQ!BR92) -> 22.598775 | GX8: =100*((DataQ!F123/DataQ!F119)-1) -> 0.28021329 | GZ8: 45292 | HA8: =HH8-HH$11 -> -159.91 | HB8: =HI8-HI$11 -> -444.7 | HC8: =HB8-HA8 -> -284.79 | HE8: =100*(HH8/$HH$11) -> 99.517717 | HF8: =100*(HI8/$HI$11) -> 98.683373 | HH8: =DataQ!AE211 -> 32997 | HI8: =DataQ!O211 -> 33331 | HK8: 45292 | HL8: =HS8-HS$11 -> 19.08 | HM8: =HT8-HT$11 -> -139.34 | HN8: =HM8-HL8 -> -158.42 | HP8: =100*(HS8/HS$11) -> 100.05143 | HQ8: =100*(HT8/HT$11) -> 99.622695 | HS8: =DataQ!AF211 -> 37117 | HT8: =DataQ!P211 -> 36791 | HV8: Don't know | HW8: 19 | HX8: 18 | HY8: 21
A9: 2019 | B9: =100*((DataA!G53-DataA!G52)/DataA!H52) -> 2.1285774 | C9: =D9-B9 -> 1.4739322 | D9: =100*((DataA!H53/DataA!H52)-1) -> 3.6025096 | F9: 2019 | G9: =B9-K9 -> 0.64390525 | H9: =I9-G9 -> 1.409085 | I9: =100*((DataA!I53/DataA!I52)-1) -> 2.0529903 | K9: =100*((DataA!J53/DataA!J52)-1) -> 1.4846722 | N9: =100*((DataQ!F168/DataQ!F164)-1) -> 2.583742 | O9: =100*(DataQ!I168/DataQ!J168) -> 21.880591 | R9: =HLOOKUP(R$8,$R$2:$W$6,2,FALSE) -> Lower profit margins | S9: =HLOOKUP(S$8,$R$2:$W$6,2,FALSE) -> Higher prices | T9: =HLOOKUP(T$8,$R$2:$W$6,2,FALSE) -> Lower number of employees | U9: =HLOOKUP(U$8,$R$2:$W$6,2,FALSE) -> Lower employee wages | V9: =HLOOKUP(V$8,$R$2:$W$6,2,FALSE) -> Other | W9: =HLOOKUP(W$8,$R$2:$W$6,2,FALSE) -> None of the above | Y9: 45017 | Z9: =DataQ!Q208 -> 4.2 | AA9: =Z9 -> 4.2 | AC9: =DataQ!V208 -> 4.2 | AD9: =DataQ!AB208 -> 4.2 | AE9: =AD9-AC9 -> 0 | AG9: 45017 | AH9: =DataQ!O208 -> 33356 | AI9: =AH9 -> 33356 | AJ9: =AI9-AH9 -> 0 | AL9: =DataQ!T208 -> 33163 | AM9: =DataQ!Z208 -> 33163 | AN9: =AM9-AL9 -> 0 | AP9: 45017 | AQ9: =100*((DataQ!R208/DataQ!R204)-1) -> 9.0108254 | AR9: =AQ9 -> 9.0108254 | AS9: =AR9-AQ9 -> 0 | AT9: =DataQ!R208 -> 9575.004 | AU9: =AT9 -> 9575.004 | AV9: =AU9-AT9 -> 0 | AX9: =DataQ!U208 -> 9660.59 | AY9: =DataQ!AA208 -> 9660.59 | AZ9: =AY9-AX9 -> 0 | BB9: =RANK(BE9,$BE$4:$BE$22) -> 7 | BC9: Construction | BD9: ='ASHE Annual pay All SIC'!H68 -> 14049 | BE9: ='ASHE Annual pay All SIC'!J68 -> 26871 | BF9: ='ASHE Annual pay All SIC'!D68 -> 38209 | BG9: ='ASHE Annual pay All SIC'!O68 -> 53463 | BH9: =+BH8+1 -> 6.5 | BJ9: 6 | BK9: =VLOOKUP($BJ9,$BB$4:$BG$22,2,FALSE) -> Transport | BL9: =VLOOKUP($BJ9,$BB$4:$BG$22,3,FALSE) -> 19034 | BM9: =VLOOKUP($BJ9,$BB$4:$BG$22,4,FALSE) -> 27347 | BN9: =VLOOKUP($BJ9,$BB$4:$BG$22,5,FALSE) -> 35868 | BO9: =VLOOKUP($BJ9,$BB$4:$BG$22,6,FALSE) -> 47741 | BP9: =+BP8+1 -> 6.5 | BR9: Construction | BS9: =BD9 -> 14049 | BT9: =BE9-BS9 -> 12822 | BU9: =BF9-BT9 -> 25387 | BV9: =BG9-BU9 -> 28076 | BW9: =+BW8+1 -> 5.5 | FI9: FY24 | FJ9: =HAVERM!D538*35*52 -> 20820.8 | FK9: =(FJ9-$FP9)*$FO9 -> 1617.4704 | FL9: =+FK9+FJ9 -> 22438.27 | FM9: =100*((FL9/FL8)-1) -> 10.393662 | FO9: 0.138 | FP9: 9100 | FR9: =HAVERA!B31 -> 37430 | FS9: =(FR9-$FX9)*$FW9 -> 3909.54 | FT9: =+FS9+FR9 -> 41339.54 | FU9: =100*((FT9/FT8)-1) -> 7.2859939 | FW9: 0.138 | FX9: 9100 | FZ9: 36982 | GA9: =100*((HAVERQ!S93/HAVERQ!S89)-1) -> 1.2124265 | GB9: =MIN(GI8:GJ8) -> 0.21956 | GC9: =+GF9-GB9 -> 0.16549978 | GD9: =AVERAGE(GB9,GF9) -> 0.30230989 | GF9: =MAX(GI8:GJ8) -> 0.38505978 | GH9: 36982 | GI9: =(GL9-GI$1)/GI$2 -> 0.22206584 | GJ9: =(GM9-GJ$1)/GJ$2 -> 0.0754623 | GL9: =(HAVERQ!BJ93*HAVERQ!$BJ$1)+(HAVERQ!BK93*HAVERQ!$BK$1) -> 20.445269 | GM9: =(HAVERQ!BL93*HAVERQ!$BL$1)+(HAVERQ!BM93*HAVERQ!$BM$1)+(HAVERQ!BN93*HAVERQ!$BN$1)+(HAVERQ!BO93*HAVERQ!$BO$1) -> 8.627716 | GR9: 36982 | GS9: =100*(HAVERQ!BP93/HAVERQ!BR93) -> 23.450622 | GT9: =AVERAGE($GS$4:$GS$103) -> 24.605137 | GV9: 36982 | GW9: =100*(HAVERQ!BP93/HAVERQ!BR93) -> 23.450622 | GX9: =100*((DataQ!F124/DataQ!F120)-1) -> 0.75233745 | GZ9: 45383 | HA9: =HH9-HH$11 -> -62.91 | HB9: =HI9-HI$11 -> -279.7 | HC9: =HB9-HA9 -> -216.79 | HE9: =100*(HH9/$HH$11) -> 99.810266 | HF9: =100*(HI9/$HI$11) -> 99.17189 | HH9: =DataQ!AE212 -> 33094 | HI9: =DataQ!O212 -> 33496 | HK9: 45383 | HL9: =HS9-HS$11 -> -8.92 | HM9: =HT9-HT$11 -> -210.34 | HN9: =HM9-HL9 -> -201.42 | HP9: =100*(HS9/HS$11) -> 99.975956 | HQ9: =100*(HT9/HT$11) -> 99.430441 | HS9: =DataQ!AF212 -> 37089 | HT9: =DataQ!P212 -> 36720 | HW9: =SUM(HW4:HW8) -> 100 | HX9: =SUM(HX4:HX8) -> 100 | HY9: =SUM(HY4:HY8) -> 100
A10: 2020 | B10: =100*((DataA!G54-DataA!G53)/DataA!H53) -> 0.0012388486 | C10: =D10-B10 -> 0.098281992 | D10: =100*((DataA!H54/DataA!H53)-1) -> 0.099520841 | F10: 2020 | G10: =B10-K10 -> -0.067846845 | H10: =I10-G10 -> -0.30916746 | I10: =100*((DataA!I54/DataA!I53)-1) -> -0.3770143 | K10: =100*((DataA!J54/DataA!J53)-1) -> 0.069085694 | N10: =100*((DataQ!F169/DataQ!F165)-1) -> 2.7966777 | O10: =100*(DataQ!I169/DataQ!J169) -> 22.178476 | Q10: =Q4 -> 45597 | R10: =HLOOKUP(R$8,$R$2:$W$6,3,FALSE) -> 58.72 | S10: =HLOOKUP(S$8,$R$2:$W$6,3,FALSE) -> 53.64 | T10: =HLOOKUP(T$8,$R$2:$W$6,3,FALSE) -> 53.68 | U10: =HLOOKUP(U$8,$R$2:$W$6,3,FALSE) -> 37.88 | V10: =HLOOKUP(V$8,$R$2:$W$6,3,FALSE) -> 7.51 | W10: =HLOOKUP(W$8,$R$2:$W$6,3,FALSE) -> 2.67 | Y10: 45108 | Z10: =DataQ!Q209 -> 4.1 | AA10: =Z10 -> 4.1 | AC10: =DataQ!V209 -> 4.1 | AD10: =DataQ!AB209 -> 4.1 | AE10: =AD10-AC10 -> 0 | AG10: 45108 | AH10: =DataQ!O209 -> 33326 | AI10: =AH10 -> 33326 | AJ10: =AI10-AH10 -> 0 | AL10: =DataQ!T209 -> 33102 | AM10: =DataQ!Z209 -> 33102 | AN10: =AM10-AL10 -> 0 | AP10: 45108 | AQ10: =100*((DataQ!R209/DataQ!R205)-1) -> 7.6947348 | AR10: =AQ10 -> 7.6947348 | AS10: =AR10-AQ10 -> 0 | AT10: =DataQ!R209 -> 9666.17 | AU10: =AT10 -> 9666.17 | AV10: =AU10-AT10 -> 0 | AX10: =DataQ!U209 -> 9771.033 | AY10: =DataQ!AA209 -> 9771.033 | AZ10: =AY10-AX10 -> 0 | BB10: =RANK(BE10,$BE$4:$BE$22) -> 16 | BC10: Wholesale & retail | BD10: ='ASHE Annual pay All SIC'!H72 -> 9031 | BE10: ='ASHE Annual pay All SIC'!J72 -> 15193 | BF10: ='ASHE Annual pay All SIC'!D72 -> 25560 | BG10: ='ASHE Annual pay All SIC'!O72 -> 37000 | BH10: =+BH9+1 -> 7.5 | BJ10: 7 | BK10: =VLOOKUP($BJ10,$BB$4:$BG$22,2,FALSE) -> Construction | BL10: =VLOOKUP($BJ10,$BB$4:$BG$22,3,FALSE) -> 14049 | BM10: =VLOOKUP($BJ10,$BB$4:$BG$22,4,FALSE) -> 26871 | BN10: =VLOOKUP($BJ10,$BB$4:$BG$22,5,FALSE) -> 38209 | BO10: =VLOOKUP($BJ10,$BB$4:$BG$22,6,FALSE) -> 53463 | BP10: =+BP9+1 -> 7.5 | BR10: Wholesale & retail | BS10: =BD10 -> 9031 | BT10: =BE10-BS10 -> 6162 | BU10: =BF10-BT10 -> 19398 | BV10: =BG10-BU10 -> 17602 | BW10: =+BW9+1 -> 6.5 | BY10: How much NI does an employer pay in the UK? It depends on the National Insurance category of your employees but for most employees in the tax year 2024/25, employers need to pay a 13.8% contribution on any employee earnings exceeding the secondary threshold, which is £175/week or £758/month | DQ10: How much NI does an employer pay in the UK? It depends on the National Insurance category of your employees but for most employees in the tax year 2024/25, employers need to pay a 13.8% contribution on any employee earnings exceeding the secondary threshold, which is £175/week or £758/month | FI10: FY25 | FJ10: =HAVERM!D550*35*52 -> 22222.2 | FK10: =(FJ10-$FP10)*$FO10 -> 2583.33 | FL10: =+FK10+FJ10 -> 24805.53 | FM10: =100*((FL10/FL9)-1) -> 10.550098 | FO10: 0.15 | FP10: 5000 | FR10: =CD5 -> 39342.372 | FS10: =(FR10-$FX10)*$FW10 -> 5151.3558 | FT10: =+FS10+FR10 -> 44493.728 | FU10: =100*((FT10/FT9)-1) -> 7.6299531 | FW10: 0.15 | FX10: 5000 | FZ10: 37073 | GA10: =100*((HAVERQ!S94/HAVERQ!S90)-1) -> 1.1983844 | GB10: =MIN(GI9:GJ9) -> 0.0754623 | GC10: =+GF10-GB10 -> 0.14660354 | GD10: =AVERAGE(GB10,GF10) -> 0.14876407 | GF10: =MAX(GI9:GJ9) -> 0.22206584 | GH10: 37073 | GI10: =(GL10-GI$1)/GI$2 -> -0.32103749 | GJ10: =(GM10-GJ$1)/GJ$2 -> -0.5335829 | GL10: =(HAVERQ!BJ94*HAVERQ!$BJ$1)+(HAVERQ!BK94*HAVERQ!$BK$1) -> 14.523006 | GM10: =(HAVERQ!BL94*HAVERQ!$BL$1)+(HAVERQ!BM94*HAVERQ!$BM$1)+(HAVERQ!BN94*HAVERQ!$BN$1)+(HAVERQ!BO94*HAVERQ!$BO$1) -> -1.3650174 | GR10: 37073 | GS10: =100*(HAVERQ!BP94/HAVERQ!BR94) -> 23.511473 | GT10: =AVERAGE($GS$4:$GS$103) -> 24.605137 | GV10: 37073 | GW10: =100*(HAVERQ!BP94/HAVERQ!BR94) -> 23.511473 | GX10: =100*((DataQ!F125/DataQ!F121)-1) -> 0.69965392 | GZ10: 45474 | HA10: =HH10-HH$11 -> 150 | HB10: =HI10-HI$11 -> -26.7 | HC10: =HB10-HA10 -> -176.7 | HE10: =100*(HH10/$HH$11) -> 100.45239 | HF10: =100*(HI10/$HI$11) -> 99.920949 | HH10: =DataQ!AE213 -> 33306.91 | HI10: =DataQ!O213 -> 33749 | HK10: 45474 | HL10: =HS10-HS$11 -> -33.49 | HM10: =HT10-HT$11 -> -137.34 | HN10: =HM10-HL10 -> -103.85 | HP10: =100*(HS10/HS$11) -> 99.909725 | HQ10: =100*(HT10/HT$11) -> 99.628111 | HS10: =DataQ!AF213 -> 37064.43 | HT10: =DataQ!P213 -> 36793
A11: 2021 | B11: =100*((DataA!G55-DataA!G54)/DataA!H54) -> 3.8447946 | C11: =D11-B11 -> 0.29847196 | D11: =100*((DataA!H55/DataA!H54)-1) -> 4.1432665 | F11: 2021 | G11: =B11-K11 -> 1.1780466 | H11: =I11-G11 -> 0.41896108 | I11: =100*((DataA!I55/DataA!I54)-1) -> 1.5970077 | K11: =100*((DataA!J55/DataA!J54)-1) -> 2.666748 | N11: =100*((DataQ!F170/DataQ!F166)-1) -> 2.2815277 | O11: =100*(DataQ!I170/DataQ!J170) -> 22.016086 | Q11: =Q5 -> 45627 | R11: =HLOOKUP(R$8,$R$2:$W$6,4,FALSE) -> 63.5 | S11: =HLOOKUP(S$8,$R$2:$W$6,4,FALSE) -> 54.45 | T11: =HLOOKUP(T$8,$R$2:$W$6,4,FALSE) -> 52.76 | U11: =HLOOKUP(U$8,$R$2:$W$6,4,FALSE) -> 40.67 | V11: =HLOOKUP(V$8,$R$2:$W$6,4,FALSE) -> 7.33 | W11: =HLOOKUP(W$8,$R$2:$W$6,4,FALSE) -> 3.75 | Y11: 45200 | Z11: =DataQ!Q210 -> 3.9 | AA11: =Z11 -> 3.9 | AC11: =DataQ!V210 -> 3.8 | AD11: =DataQ!AB210 -> 3.8 | AE11: =AD11-AC11 -> 0 | AG11: 45200 | AH11: =DataQ!O210 -> 33377 | AI11: =AH11 -> 33377 | AJ11: =AI11-AH11 -> 0 | AL11: =DataQ!T210 -> 33174 | AM11: =DataQ!Z210 -> 33174 | AN11: =AM11-AL11 -> 0 | AP11: 45200 | AQ11: =100*((DataQ!R210/DataQ!R206)-1) -> 5.9569959 | AR11: =AQ11 -> 5.9569959 | AS11: =AR11-AQ11 -> 0 | AT11: =DataQ!R210 -> 9719.769 | AU11: =AT11 -> 9719.769 | AV11: =AU11-AT11 -> 0 | AX11: =DataQ!U210 -> 9774.984 | AY11: =DataQ!AA210 -> 9774.984 | AZ11: =AY11-AX11 -> 0 | BB11: =RANK(BE11,$BE$4:$BE$22) -> 6 | BC11: Transport | BD11: ='ASHE Annual pay All SIC'!H76 -> 19034 | BE11: ='ASHE Annual pay All SIC'!J76 -> 27347 | BF11: ='ASHE Annual pay All SIC'!D76 -> 35868 | BG11: ='ASHE Annual pay All SIC'!O76 -> 47741 | BH11: =+BH10+1 -> 8.5 | BJ11: 8 | BK11: =VLOOKUP($BJ11,$BB$4:$BG$22,2,FALSE) -> Manufacturing | BL11: =VLOOKUP($BJ11,$BB$4:$BG$22,3,FALSE) -> 21424 | BM11: =VLOOKUP($BJ11,$BB$4:$BG$22,4,FALSE) -> 26686 | BN11: =VLOOKUP($BJ11,$BB$4:$BG$22,5,FALSE) -> 35518 | BO11: =VLOOKUP($BJ11,$BB$4:$BG$22,6,FALSE) -> 49243 | BP11: =+BP10+1 -> 8.5 | BR11: Transport | BS11: =BD11 -> 19034 | BT11: =BE11-BS11 -> 8313 | BU11: =BF11-BT11 -> 27555 | BV11: =BG11-BU11 -> 20186 | BW11: =+BW10+1 -> 7.5 | BY11: The government will increase the rate of employer NICs from 13.8% to 15% from 6 April 2025. | DQ11: The government will increase the rate of employer NICs from 13.8% to 15% from 6 April 2025. | FZ11: 37165 | GA11: =100*((HAVERQ!S95/HAVERQ!S91)-1) -> 1.0329202 | GB11: =MIN(GI10:GJ10) -> -0.5335829 | GC11: =+GF11-GB11 -> 0.2125454 | GD11: =AVERAGE(GB11,GF11) -> -0.42731019 | GF11: =MAX(GI10:GJ10) -> -0.32103749 | GH11: 37165 | GI11: =(GL11-GI$1)/GI$2 -> -0.63179787 | GJ11: =(GM11-GJ$1)/GJ$2 -> -1.5733116 | GL11: =(HAVERQ!BJ95*HAVERQ!$BJ$1)+(HAVERQ!BK95*HAVERQ!$BK$1) -> 11.134323 | GM11: =(HAVERQ!BL95*HAVERQ!$BL$1)+(HAVERQ!BM95*HAVERQ!$BM$1)+(HAVERQ!BN95*HAVERQ!$BN$1)+(HAVERQ!BO95*HAVERQ!$BO$1) -> -18.424066 | GR11: 37165 | GS11: =100*(HAVERQ!BP95/HAVERQ!BR95) -> 23.194699 | GT11: =AVERAGE($GS$4:$GS$103) -> 24.605137 | GV11: 37165 | GW11: =100*(HAVERQ!BP95/HAVERQ!BR95) -> 23.194699 | GX11: =100*((DataQ!F126/DataQ!F122)-1) -> 0.80160473 | GZ11: 45566 | HA11: =HH11-HH$11 -> 0 | HB11: =HI11-HI$11 -> 0 | HC11: =HB11-HA11 -> 0 | HE11: =100*(HH11/$HH$11) -> 100 | HF11: =100*(HI11/$HI$11) -> 100 | HH11: =DataQ!AE214 -> 33156.91 | HI11: =DataQ!O214 -> 33775.7 | HK11: 45566 | HL11: =HS11-HS$11 -> 0 | HM11: =HT11-HT$11 -> 0 | HN11: =HM11-HL11 -> 0 | HP11: =100*(HS11/HS$11) -> 100 | HQ11: =100*(HT11/HT$11) -> 100 | HS11: =DataQ!AF214 -> 37097.92 | HT11: =DataQ!P214 -> 36930.34
A12: 2022 | B12: =100*((DataA!G56-DataA!G55)/DataA!H55) -> 4.5968489 | C12: =D12-B12 -> 1.6454431 | D12: =100*((DataA!H56/DataA!H55)-1) -> 6.242292 | F12: 2022 | G12: =B12-K12 -> -3.898532 | H12: =I12-G12 -> 2.148227 | I12: =100*((DataA!I56/DataA!I55)-1) -> -1.750305 | K12: =100*((DataA!J56/DataA!J55)-1) -> 8.4953809 | M12: 2014 | N12: =100*((DataQ!F171/DataQ!F167)-1) -> 2.457354 | O12: =100*(DataQ!I171/DataQ!J171) -> 21.695584 | Q12: =Q6 -> 45658 | R12: =HLOOKUP(R$8,$R$2:$W$6,5,FALSE) -> 63.46 | S12: =HLOOKUP(S$8,$R$2:$W$6,5,FALSE) -> 61.1 | T12: =HLOOKUP(T$8,$R$2:$W$6,5,FALSE) -> 53.63 | U12: =HLOOKUP(U$8,$R$2:$W$6,5,FALSE) -> 36.63 | V12: =HLOOKUP(V$8,$R$2:$W$6,5,FALSE) -> 11.88 | W12: =HLOOKUP(W$8,$R$2:$W$6,5,FALSE) -> 2.94 | Y12: 45292 | Z12: =DataQ!Q211 -> 4.3 | AA12: =Z12 -> 4.3 | AC12: =DataQ!V211 -> 4.3 | AD12: =DataQ!AB211 -> 4.3 | AE12: =AD12-AC12 -> 0 | AG12: 45292 | AH12: =DataQ!O211 -> 33331 | AI12: =AH12 -> 33331 | AJ12: =AI12-AH12 -> 0 | AL12: =DataQ!T211 -> 32997 | AM12: =DataQ!Z211 -> 32997 | AN12: =AM12-AL12 -> 0 | AP12: 45292 | AQ12: =100*((AT12/AT8)-1) -> 4.8107058 | AR12: =100*((AU12/AU8)-1) -> 4.8107058 | AS12: =AR12-AQ12 -> 0 | AT12: =DataQ!R211 -> 9849.933 | AU12: =AT12 -> 9849.933 | AV12: =AU12-AT12 -> 0 | AX12: =DataQ!U211 -> 9898.726 | AY12: =DataQ!AA211 -> 9898.726 | AZ12: =AY12-AX12 -> 0 | BB12: =RANK(BE12,$BE$4:$BE$22) -> 19 | BC12: Accommodation & food | BD12: ='ASHE Annual pay All SIC'!H82 -> 4239 | BE12: ='ASHE Annual pay All SIC'!J82 -> 8951 | BF12: ='ASHE Annual pay All SIC'!D82 -> 16800 | BG12: ='ASHE Annual pay All SIC'!O82 -> 27056 | BH12: =+BH11+1 -> 9.5 | BJ12: 9 | BK12: =VLOOKUP($BJ12,$BB$4:$BG$22,2,FALSE) -> Public admin | BL12: =VLOOKUP($BJ12,$BB$4:$BG$22,3,FALSE) -> 16564 | BM12: =VLOOKUP($BJ12,$BB$4:$BG$22,4,FALSE) -> 26528 | BN12: =VLOOKUP($BJ12,$BB$4:$BG$22,5,FALSE) -> 36109 | BO12: =VLOOKUP($BJ12,$BB$4:$BG$22,6,FALSE) -> 47310 | BP12: =+BP11+1 -> 9.5 | BR12: Accommodation & food | BS12: =BD12 -> 4239 | BT12: =BE12-BS12 -> 4712 | BU12: =BF12-BT12 -> 12088 | BV12: =BG12-BU12 -> 14968 | BW12: =+BW11+1 -> 8.5 | BY12: The Secondary Threshold is the point at which employers become liable to pay NICs on employees’ earnings, and is currently set at £9,100 a year. The government will reduce the Secondary Threshold to £5,000 a year from 6 April 2025 until 6 April 2028, and then increase it by Consumer Price Index (CPI) thereafter | DQ12: The Secondary Threshold is the point at which employers become liable to pay NICs on employees’ earnings, and is currently set at £9,100 a year. The government will reduce the Secondary Threshold to £5,000 a year from 6 April 2025 until 6 April 2028, and then increase it by Consumer Price Index (CPI) thereafter | FL12: =100*((FL10/FL6)-1) -> 43.932712 | FT12: =100*((FT10/FT6)-1) -> 29.408403 | FZ12: 37257 | GA12: =100*((HAVERQ!S96/HAVERQ!S92)-1) -> 0.95583827 | GB12: =MIN(GI11:GJ11) -> -1.5733116 | GC12: =+GF12-GB12 -> 0.94151371 | GD12: =AVERAGE(GB12,GF12) -> -1.1025547 | GF12: =MAX(GI11:GJ11) -> -0.63179787 | GH12: 37257 | GI12: =(GL12-GI$1)/GI$2 -> 0.433992 | GJ12: =(GM12-GJ$1)/GJ$2 -> 0.11417725 | GL12: =(HAVERQ!BJ96*HAVERQ!$BJ$1)+(HAVERQ!BK96*HAVERQ!$BK$1) -> 22.756215 | GM12: =(HAVERQ!BL96*HAVERQ!$BL$1)+(HAVERQ!BM96*HAVERQ!$BM$1)+(HAVERQ!BN96*HAVERQ!$BN$1)+(HAVERQ!BO96*HAVERQ!$BO$1) -> 9.2629203 | GR12: 37257 | GS12: =100*(HAVERQ!BP96/HAVERQ!BR96) -> 23.492579 | GT12: =AVERAGE($GS$4:$GS$103) -> 24.605137 | GV12: 37257 | GW12: =100*(HAVERQ!BP96/HAVERQ!BR96) -> 23.492579 | GX12: =100*((DataQ!F127/DataQ!F123)-1) -> 1.1604897 | GZ12: 45658 | HA12: =HH12-HH$11 -> 103.93 | HB12: =HI12-HI$11 -> -20 | HC12: =HB12-HA12 -> -123.93 | HE12: =100*(HH12/$HH$11) -> 100.31345 | HF12: =100*(HI12/$HI$11) -> 99.940786 | HH12: =DataQ!AE215 -> 33260.84 | HI12: =DataQ!O215 -> 33755.7 | HK12: 45658 | HL12: =HS12-HS$11 -> 86.29 | HM12: =HT12-HT$11 -> 72.29 | HN12: =HM12-HL12 -> -14 | HP12: =100*(HS12/HS$11) -> 100.2326 | HQ12: =100*(HT12/HT$11) -> 100.19575 | HS12: =DataQ!AF215 -> 37184.21 | HT12: =DataQ!P215 -> 37002.63
A13: 2023 | B13: =100*((DataA!G57-DataA!G56)/DataA!H56) -> 5.4343165 | C13: =D13-B13 -> 3.6829069 | D13: =100*((DataA!H57/DataA!H56)-1) -> 9.1172234 | F13: 2023 | G13: =B13-K13 -> -1.4588863 | H13: =I13-G13 -> 3.5919099 | I13: =100*((DataA!I57/DataA!I56)-1) -> 2.1330236 | K13: =100*((DataA!J57/DataA!J56)-1) -> 6.8932028 | N13: =100*((DataQ!F172/DataQ!F168)-1) -> -1.5163896 | O13: =100*(DataQ!I172/DataQ!J172) -> 22.422755 | Y13: 45383 | Z13: =DataQ!Q212 -> 4.2 | AA13: =Z13 -> 4.2 | AC13: =DataQ!V212 -> 4.2 | AD13: =DataQ!AB212 -> 4.2 | AE13: =AD13-AC13 -> 0 | AG13: 45383 | AH13: =DataQ!O212 -> 33496 | AI13: =AH13 -> 33496 | AJ13: =AI13-AH13 -> 0 | AL13: =DataQ!T212 -> 33094 | AM13: =DataQ!Z212 -> 33094 | AN13: =AM13-AL13 -> 0 | AP13: 45383 | AQ13: =100*((AT13/AT9)-1) -> 4.4659616 | AR13: =100*((AU13/AU9)-1) -> 4.4659616 | AS13: =AR13-AQ13 -> 0 | AT13: =DataQ!R212 -> 10002.62 | AU13: =AT13 -> 10002.62 | AV13: =AU13-AT13 -> 0 | AX13: =DataQ!U212 -> 10025.21 | AY13: =DataQ!AA212 -> 10025.21 | AZ13: =AY13-AX13 -> 0 | BB13: =RANK(BE13,$BE$4:$BE$22) -> 3 | BC13: Communications | BD13: ='ASHE Annual pay All SIC'!H85 -> 23599 | BE13: ='ASHE Annual pay All SIC'!J85 -> 32656 | BF13: ='ASHE Annual pay All SIC'!D85 -> 46063 | BG13: ='ASHE Annual pay All SIC'!O85 -> 68998 | BH13: =+BH12+1 -> 10.5 | BJ13: 10 | BK13: =VLOOKUP($BJ13,$BB$4:$BG$22,2,FALSE) -> Professional services | BL13: =VLOOKUP($BJ13,$BB$4:$BG$22,3,FALSE) -> 15685 | BM13: =VLOOKUP($BJ13,$BB$4:$BG$22,4,FALSE) -> 26405 | BN13: =VLOOKUP($BJ13,$BB$4:$BG$22,5,FALSE) -> 39880 | BO13: =VLOOKUP($BJ13,$BB$4:$BG$22,6,FALSE) -> 59607 | BP13: =+BP12+1 -> 10.5 | BR13: Communications | BS13: =BD13 -> 23599 | BT13: =BE13-BS13 -> 9057 | BU13: =BF13-BT13 -> 37006 | BV13: =BG13-BU13 -> 31992 | BW13: =+BW12+1 -> 9.5 | FZ13: 37347 | GA13: =100*((HAVERQ!S97/HAVERQ!S93)-1) -> 0.93907619 | GB13: =MIN(GI12:GJ12) -> 0.11417725 | GC13: =+GF13-GB13 -> 0.31981475 | GD13: =AVERAGE(GB13,GF13) -> 0.27408462 | GF13: =MAX(GI12:GJ12) -> 0.433992 | GH13: 37347 | GI13: =(GL13-GI$1)/GI$2 -> 0.18026248 | GJ13: =(GM13-GJ$1)/GJ$2 -> -0.30226419 | GL13: =(HAVERQ!BJ97*HAVERQ!$BJ$1)+(HAVERQ!BK97*HAVERQ!$BK$1) -> 19.989425 | GM13: =(HAVERQ!BL97*HAVERQ!$BL$1)+(HAVERQ!BM97*HAVERQ!$BM$1)+(HAVERQ!BN97*HAVERQ!$BN$1)+(HAVERQ!BO97*HAVERQ!$BO$1) -> 2.4302776 | GR13: 37347 | GS13: =100*(HAVERQ!BP97/HAVERQ!BR97) -> 23.852336 | GT13: =AVERAGE($GS$4:$GS$103) -> 24.605137 | GV13: 37347 | GW13: =100*(HAVERQ!BP97/HAVERQ!BR97) -> 23.852336 | GX13: =100*((DataQ!F128/DataQ!F124)-1) -> 1.440918 | GZ13: 45748 | HA13: =HH13-HH$11 -> 218.14 | HB13: =HI13-HI$11 -> 41.5 | HC13: =HB13-HA13 -> -176.64 | HE13: =100*(HH13/$HH$11) -> 100.6579 | HF13: =100*(HI13/$HI$11) -> 100.12287 | HH13: =DataQ!AE216 -> 33375.05 | HI13: =DataQ!O216 -> 33817.2 | HK13: 45748 | HL13: =HS13-HS$11 -> 193.97 | HM13: =HT13-HT$11 -> 138.52 | HN13: =HM13-HL13 -> -55.45 | HP13: =100*(HS13/HS$11) -> 100.52286 | HQ13: =100*(HT13/HT$11) -> 100.37508 | HS13: =DataQ!AF216 -> 37291.89 | HT13: =DataQ!P216 -> 37068.86
A14: 2024 | B14: =100*((DataA!G58-DataA!G57)/DataA!H57) -> 3.3758444 | C14: =D14-B14 -> 3.2222111 | D14: =100*((DataA!H58/DataA!H57)-1) -> 6.5980555 | F14: 2024 | G14: =B14-K14 -> 0.8032885 | H14: =I14-G14 -> 3.0470276 | I14: =100*((DataA!I58/DataA!I57)-1) -> 3.8503161 | K14: =100*((DataA!J58/DataA!J57)-1) -> 2.5725559 | N14: =100*((DataQ!F173/DataQ!F169)-1) -> -1.8918891 | O14: =100*(DataQ!I173/DataQ!J173) -> 23.797129 | Y14: 45474 | Z14: =DataQ!Q213 -> 4.3 | AA14: =Z14 -> 4.3 | AC14: =DataQ!V213 -> 4.243108 | AD14: =DataQ!AB213 -> 4.243108 | AE14: =AD14-AC14 -> 0 | AG14: 45474 | AH14: =DataQ!O213 -> 33749 | AI14: =AH14 -> 33749 | AJ14: =AI14-AH14 -> 0 | AL14: =DataQ!T213 -> 33306.91 | AM14: =DataQ!Z213 -> 33306.91 | AN14: =AM14-AL14 -> 0 | AP14: 45474 | AQ14: =100*((AT14/AT10)-1) -> 3.2989798 | AR14: =100*((AU14/AU10)-1) -> 3.2989798 | AS14: =AR14-AQ14 -> 0 | AT14: =DataQ!R213 -> 9985.055 | AU14: =AT14 -> 9985.055 | AV14: =AU14-AT14 -> 0 | AX14: =DataQ!U213 -> 10139.5 | AY14: =DataQ!AA213 -> 10139.5 | AZ14: =AY14-AX14 -> 0 | BB14: =RANK(BE14,$BE$4:$BE$22) -> 4 | BC14: Financial services | BD14: ='ASHE Annual pay All SIC'!H92 -> 21567 | BE14: ='ASHE Annual pay All SIC'!J92 -> 29873 | BF14: ='ASHE Annual pay All SIC'!D92 -> 47248 | BG14: ='ASHE Annual pay All SIC'!O92 -> 78520 | BH14: =+BH13+1 -> 11.5 | BJ14: 11 | BK14: =VLOOKUP($BJ14,$BB$4:$BG$22,2,FALSE) -> Real estate | BL14: =VLOOKUP($BJ14,$BB$4:$BG$22,3,FALSE) -> 12244 | BM14: =VLOOKUP($BJ14,$BB$4:$BG$22,4,FALSE) -> 22774 | BN14: =VLOOKUP($BJ14,$BB$4:$BG$22,5,FALSE) -> 30891 | BO14: =VLOOKUP($BJ14,$BB$4:$BG$22,6,FALSE) -> 41645 | BP14: =+BP13+1 -> 11.5 | BR14: Financial services | BS14: =BD14 -> 21567 | BT14: =BE14-BS14 -> 8306 | BU14: =BF14-BT14 -> 38942 | BV14: =BG14-BU14 -> 39578 | BW14: =+BW13+1 -> 10.5 | BY14: https://zelt.app/blog/how-to-calculate-employers-ni-employer-s-ni-calculator-2024-2025-2026/#:~:text=How%20much%20NI%20does%20an,week%20or%20%C2%A3758%2Fmonth. | DQ14: https://zelt.app/blog/how-to-calculate-employers-ni-employer-s-ni-calculator-2024-2025-2026/#:~:text=How%20much%20NI%20does%20an,week%20or%20%C2%A3758%2Fmonth. | FZ14: 37438 | GA14: =100*((HAVERQ!S98/HAVERQ!S94)-1) -> 0.63003035 | GB14: =MIN(GI13:GJ13) -> -0.30226419 | GC14: =+GF14-GB14 -> 0.48252666 | GD14: =AVERAGE(GB14,GF14) -> -0.061000856 | GF14: =MAX(GI13:GJ13) -> 0.18026248 | GH14: 37438 | GI14: =(GL14-GI$1)/GI$2 -> -0.17943013 | GJ14: =(GM14-GJ$1)/GJ$2 -> -0.79337559 | GL14: =(HAVERQ!BJ98*HAVERQ!$BJ$1)+(HAVERQ!BK98*HAVERQ!$BK$1) -> 16.067162 | GM14: =(HAVERQ!BL98*HAVERQ!$BL$1)+(HAVERQ!BM98*HAVERQ!$BM$1)+(HAVERQ!BN98*HAVERQ!$BN$1)+(HAVERQ!BO98*HAVERQ!$BO$1) -> -5.6274912 | GR14: 37438 | GS14: =100*(HAVERQ!BP98/HAVERQ!BR98) -> 24.361057 | GT14: =AVERAGE($GS$4:$GS$103) -> 24.605137 | GV14: 37438 | GW14: =100*(HAVERQ!BP98/HAVERQ!BR98) -> 24.361057 | GX14: =100*((DataQ!F129/DataQ!F125)-1) -> 2.9935054 | GZ14: 45839 | HA14: =HH14-HH$11 -> 327.98 | HB14: =HI14-HI$11 -> 116.09 | HC14: =HB14-HA14 -> -211.89 | HE14: =100*(HH14/$HH$11) -> 100.98918 | HF14: =100*(HI14/$HI$11) -> 100.34371 | HH14: =DataQ!AE217 -> 33484.89 | HI14: =DataQ!O217 -> 33891.79 | HK14: 45839 | HL14: =HS14-HS$11 -> 296.71 | HM14: =HT14-HT$11 -> 218.72 | HN14: =HM14-HL14 -> -77.99 | HP14: =100*(HS14/HS$11) -> 100.7998 | HQ14: =100*(HT14/HT$11) -> 100.59225 | HS14: =DataQ!AF217 -> 37394.63 | HT14: =DataQ!P217 -> 37149.06
A15: 2025 | B15: =100*((DataA!G59-DataA!G58)/DataA!H58) -> 3.0681355 | C15: =D15-B15 -> 0.98726808 | D15: =100*((DataA!H59/DataA!H58)-1) -> 4.0554036 | F15: 2025 | G15: =B15-K15 -> -0.033234759 | H15: =I15-G15 -> 0.95504008 | I15: =100*((DataA!I59/DataA!I58)-1) -> 0.92180532 | K15: =100*((DataA!J59/DataA!J58)-1) -> 3.1013703 | N15: =100*((DataQ!F174/DataQ!F170)-1) -> -1.6332789 | O15: =100*(DataQ!I174/DataQ!J174) -> 23.392813 | Y15: 45566 | Z15: =DataQ!Q214 -> 4.408384 | AA15: =Z15 -> 4.408384 | AC15: =DataQ!V214 -> 4.408679 | AD15: =DataQ!AB214 -> 4.408679 | AE15: =AD15-AC15 -> 0 | AG15: 45566 | AH15: =DataQ!O214 -> 33775.7 | AI15: =AH15 -> 33775.7 | AJ15: =AI15-AH15 -> 0 | AL15: =DataQ!T214 -> 33156.91 | AM15: =DataQ!Z214 -> 33156.91 | AN15: =AM15-AL15 -> 0 | AP15: 45566 | AQ15: =100*((AT15/AT11)-1) -> 4.7839717 | AR15: =100*((AU15/AU11)-1) -> 4.7839717 | AS15: =AR15-AQ15 -> 0 | AT15: =DataQ!R214 -> 10184.76 | AU15: =AT15 -> 10184.76 | AV15: =AU15-AT15 -> 0 | AX15: =DataQ!U214 -> 10244.95 | AY15: =DataQ!AA214 -> 10244.95 | AZ15: =AY15-AX15 -> 0 | BB15: =RANK(BE15,$BE$4:$BE$22) -> 11 | BC15: Real estate | BD15: ='ASHE Annual pay All SIC'!H96 -> 12244 | BE15: ='ASHE Annual pay All SIC'!J96 -> 22774 | BF15: ='ASHE Annual pay All SIC'!D96 -> 30891 | BG15: ='ASHE Annual pay All SIC'!O96 -> 41645 | BH15: =+BH14+1 -> 12.5 | BJ15: 12 | BK15: =VLOOKUP($BJ15,$BB$4:$BG$22,2,FALSE) -> Education | BL15: =VLOOKUP($BJ15,$BB$4:$BG$22,3,FALSE) -> 10561 | BM15: =VLOOKUP($BJ15,$BB$4:$BG$22,4,FALSE) -> 19555 | BN15: =VLOOKUP($BJ15,$BB$4:$BG$22,5,FALSE) -> 31094 | BO15: =VLOOKUP($BJ15,$BB$4:$BG$22,6,FALSE) -> 44533 | BP15: =+BP14+1 -> 12.5 | BR15: Real estate | BS15: =BD15 -> 12244 | BT15: =BE15-BS15 -> 10530 | BU15: =BF15-BT15 -> 20361 | BV15: =BG15-BU15 -> 21284 | BW15: =+BW14+1 -> 11.5 | FZ15: 37530 | GA15: =100*((HAVERQ!S99/HAVERQ!S95)-1) -> 0.54415936 | GB15: =MIN(GI14:GJ14) -> -0.79337559 | GC15: =+GF15-GB15 -> 0.61394547 | GD15: =AVERAGE(GB15,GF15) -> -0.48640286 | GF15: =MAX(GI14:GJ14) -> -0.17943013 | GH15: 37530 | GI15: =(GL15-GI$1)/GI$2 -> -0.82849654 | GJ15: =(GM15-GJ$1)/GJ$2 -> -0.13299086 | GL15: =(HAVERQ!BJ99*HAVERQ!$BJ$1)+(HAVERQ!BK99*HAVERQ!$BK$1) -> 8.9894251 | GM15: =(HAVERQ!BL99*HAVERQ!$BL$1)+(HAVERQ!BM99*HAVERQ!$BM$1)+(HAVERQ!BN99*HAVERQ!$BN$1)+(HAVERQ!BO99*HAVERQ!$BO$1) -> 5.207581 | GR15: 37530 | GS15: =100*(HAVERQ!BP99/HAVERQ!BR99) -> 24.914941 | GT15: =AVERAGE($GS$4:$GS$103) -> 24.605137 | GV15: 37530 | GW15: =100*(HAVERQ!BP99/HAVERQ!BR99) -> 24.914941 | GX15: =100*((DataQ!F130/DataQ!F126)-1) -> 3.0185753 | GZ15: 45931 | HA15: =HH15-HH$11 -> 443.66 | HB15: =HI15-HI$11 -> 212.07 | HC15: =HB15-HA15 -> -231.59 | HE15: =100*(HH15/$HH$11) -> 101.33806 | HF15: =100*(HI15/$HI$11) -> 100.62788 | HH15: =DataQ!AE218 -> 33600.57 | HI15: =DataQ!O218 -> 33987.77 | HK15: 45931 | HL15: =HS15-HS$11 -> 405.88 | HM15: =HT15-HT$11 -> 323.4 | HN15: =HM15-HL15 -> -82.48 | HP15: =100*(HS15/HS$11) -> 101.09408 | HQ15: =100*(HT15/HT$11) -> 100.8757 | HS15: =DataQ!AF218 -> 37503.8 | HT15: =DataQ!P218 -> 37253.74
A16: 2026 | B16: =100*((DataA!G60-DataA!G59)/DataA!H59) -> 2.4224673 | C16: =D16-B16 -> 1.1063715 | D16: =100*((DataA!H60/DataA!H59)-1) -> 3.5288388 | F16: 2026 | G16: =B16-K16 -> -0.067460705 | H16: =I16-G16 -> 1.082811 | I16: =100*((DataA!I60/DataA!I59)-1) -> 1.0153503 | K16: =100*((DataA!J60/DataA!J59)-1) -> 2.489928 | M16: 2015 | N16: =100*((DataQ!F175/DataQ!F171)-1) -> -0.69899237 | O16: =100*(DataQ!I175/DataQ!J175) -> 22.828221 | Y16: 45658 | Z16: =DataQ!Q215 -> 4.492019 | AA16: =Z16+AC16-AD16 -> 4.492019 | AC16: =DataQ!V215 -> 4.380091 | AD16: =DataQ!AB215 -> 4.380091 | AE16: =AD16-AC16 -> 0 | AG16: 45658 | AH16: =DataQ!O215 -> 33755.7 | AI16: =AH16*AL16/AM16 -> 33755.7 | AJ16: =AI16-AH16 -> 0 | AL16: =DataQ!T215 -> 33260.84 | AM16: =DataQ!Z215 -> 33260.84 | AN16: =AM16-AL16 -> 0 | AP16: 45658 | AQ16: =100*((AT16/AT12)-1) -> 4.4331977 | AR16: =100*((AU16/AU12)-1) -> 4.4331977 | AS16: =AR16-AQ16 -> 0 | AT16: =DataQ!R215 -> 10286.6 | AU16: =AT16*AX16/AY16 -> 10286.6 | AV16: =AU16-AT16 -> 0 | AX16: =DataQ!U215 -> 10327.93 | AY16: =DataQ!AA215 -> 10327.93 | AZ16: =AY16-AX16 -> 0 | BB16: =RANK(BE16,$BE$4:$BE$22) -> 10 | BC16: Professional services | BD16: ='ASHE Annual pay All SIC'!H98 -> 15685 | BE16: ='ASHE Annual pay All SIC'!J98 -> 26405 | BF16: ='ASHE Annual pay All SIC'!D98 -> 39880 | BG16: ='ASHE Annual pay All SIC'!O98 -> 59607 | BH16: =+BH15+1 -> 13.5 | BJ16: 13 | BK16: =VLOOKUP($BJ16,$BB$4:$BG$22,2,FALSE) -> Health | BL16: =VLOOKUP($BJ16,$BB$4:$BG$22,3,FALSE) -> 11105 | BM16: =VLOOKUP($BJ16,$BB$4:$BG$22,4,FALSE) -> 18893 | BN16: =VLOOKUP($BJ16,$BB$4:$BG$22,5,FALSE) -> 28150 | BO16: =VLOOKUP($BJ16,$BB$4:$BG$22,6,FALSE) -> 40481 | BP16: =+BP15+1 -> 13.5 | BR16: Professional services | BS16: =BD16 -> 15685 | BT16: =BE16-BS16 -> 10720 | BU16: =BF16-BT16 -> 29160 | BV16: =BG16-BU16 -> 30447 | BW16: =+BW15+1 -> 12.5 | FZ16: 37622 | GA16: =100*((HAVERQ!S100/HAVERQ!S96)-1) -> 0.72576122 | GB16: =MIN(GI15:GJ15) -> -0.82849654 | GC16: =+GF16-GB16 -> 0.69550569 | GD16: =AVERAGE(GB16,GF16) -> -0.4807437 | GF16: =MAX(GI15:GJ15) -> -0.13299086 | GH16: 37622 | GI16: =(GL16-GI$1)/GI$2 -> -0.55338045 | GJ16: =(GM16-GJ$1)/GJ$2 -> -0.66977625 | GL16: =(HAVERQ!BJ100*HAVERQ!$BJ$1)+(HAVERQ!BK100*HAVERQ!$BK$1) -> 11.989425 | GM16: =(HAVERQ!BL100*HAVERQ!$BL$1)+(HAVERQ!BM100*HAVERQ!$BM$1)+(HAVERQ!BN100*HAVERQ!$BN$1)+(HAVERQ!BO100*HAVERQ!$BO$1) -> -3.5995706 | GR16: 37622 | GS16: =100*(HAVERQ!BP100/HAVERQ!BR100) -> 24.61206 | GT16: =AVERAGE($GS$4:$GS$103) -> 24.605137 | GV16: 37622 | GW16: =100*(HAVERQ!BP100/HAVERQ!BR100) -> 24.61206 | GX16: =100*((DataQ!F131/DataQ!F127)-1) -> 4.0886884 | GZ16: 46023 | HA16: =HH16-HH$11 -> 557.91 | HB16: =HI16-HI$11 -> 319.16 | HC16: =HB16-HA16 -> -238.75 | HE16: =100*(HH16/$HH$11) -> 101.68264 | HF16: =100*(HI16/$HI$11) -> 100.94494 | HH16: =DataQ!AE219 -> 33714.82 | HI16: =DataQ!O219 -> 34094.86 | HK16: 46023 | HL16: =HS16-HS$11 -> 513.41 | HM16: =HT16-HT$11 -> 437.05 | HN16: =HM16-HL16 -> -76.36 | HP16: =100*(HS16/HS$11) -> 101.38393 | HQ16: =100*(HT16/HT$11) -> 101.18344 | HS16: =DataQ!AF219 -> 37611.33 | HT16: =DataQ!P219 -> 37367.39
N17: =100*((DataQ!F176/DataQ!F172)-1) -> 0.6717141 | O17: =100*(DataQ!I176/DataQ!J176) -> 22.391736 | Y17: 45748 | Z17: =DataQ!Q216 -> 4.502507 | AA17: =Z17+AC17-AD17 -> 4.42974 | AC17: =DataQ!V216 -> 4.351475 | AD17: =DataQ!AB216 -> 4.424242 | AE17: =AD17-AC17 -> 0.072767 | AG17: 45748 | AH17: =DataQ!O216 -> 33817.2 | AI17: =AH17*AL17/AM17 -> 33842.926 | AJ17: =AI17-AH17 -> 25.725655 | AL17: =DataQ!T216 -> 33375.05 | AM17: =DataQ!Z216 -> 33349.68 | AN17: =AM17-AL17 -> -25.37 | AP17: 45748 | AQ17: =100*((AT17/AT13)-1) -> 4.0731328 | AR17: =100*((AU17/AU13)-1) -> 4.1253998 | AS17: =AR17-AQ17 -> 0.052266962 | AT17: =DataQ!R216 -> 10410.04 | AU17: =AT17*AX17/AY17 -> 10415.268 | AV17: =AU17-AT17 -> 5.2280656 | AX17: =DataQ!U216 -> 10399.2 | AY17: =DataQ!AA216 -> 10393.98 | AZ17: =AY17-AX17 -> -5.22 | BB17: =RANK(BE17,$BE$4:$BE$22) -> 15 | BC17: Administrative services | BD17: ='ASHE Annual pay All SIC'!H106 -> 7394 | BE17: ='ASHE Annual pay All SIC'!J106 -> 15239 | BF17: ='ASHE Annual pay All SIC'!D106 -> 26803 | BG17: ='ASHE Annual pay All SIC'!O106 -> 40000 | BH17: =+BH16+1 -> 14.5 | BJ17: 14 | BK17: =VLOOKUP($BJ17,$BB$4:$BG$22,2,FALSE) -> Agriculture | BL17: =VLOOKUP($BJ17,$BB$4:$BG$22,3,FALSE) -> 9753 | BM17: =VLOOKUP($BJ17,$BB$4:$BG$22,4,FALSE) -> 18000 | BN17: =VLOOKUP($BJ17,$BB$4:$BG$22,5,FALSE) -> 27288 | BO17: =VLOOKUP($BJ17,$BB$4:$BG$22,6,FALSE) -> 36266 | BP17: =+BP16+1 -> 14.5 | BR17: Administrative services | BS17: =BD17 -> 7394 | BT17: =BE17-BS17 -> 7845 | BU17: =BF17-BT17 -> 18958 | BV17: =BG17-BU17 -> 21042 | BW17: =+BW16+1 -> 13.5 | FZ17: 37712 | GA17: =100*((HAVERQ!S101/HAVERQ!S97)-1) -> 0.94348927 | GB17: =MIN(GI16:GJ16) -> -0.66977625 | GC17: =+GF17-GB17 -> 0.1163958 | GD17: =AVERAGE(GB17,GF17) -> -0.61157835 | GF17: =MAX(GI16:GJ16) -> -0.55338045 | GH17: 37712 | GI17: =(GL17-GI$1)/GI$2 -> -0.39135629 | GJ17: =(GM17-GJ$1)/GJ$2 -> -0.69616021 | GL17: =(HAVERQ!BJ101*HAVERQ!$BJ$1)+(HAVERQ!BK101*HAVERQ!$BK$1) -> 13.756215 | GM17: =(HAVERQ!BL101*HAVERQ!$BL$1)+(HAVERQ!BM101*HAVERQ!$BM$1)+(HAVERQ!BN101*HAVERQ!$BN$1)+(HAVERQ!BO101*HAVERQ!$BO$1) -> -4.0324578 | GR17: 37712 | GS17: =100*(HAVERQ!BP101/HAVERQ!BR101) -> 25.268379 | GT17: =AVERAGE($GS$4:$GS$103) -> 24.605137 | GV17: 37712 | GW17: =100*(HAVERQ!BP101/HAVERQ!BR101) -> 25.268379 | GX17: =100*((DataQ!F132/DataQ!F128)-1) -> 3.882517 | GZ17: 46113 | HA17: =HH17-HH$11 -> 669.22 | HB17: =HI17-HI$11 -> 416.37 | HC17: =HB17-HA17 -> -252.85 | HE17: =100*(HH17/$HH$11) -> 102.01834 | HF17: =100*(HI17/$HI$11) -> 101.23275 | HH17: =DataQ!AE220 -> 33826.13 | HI17: =DataQ!O220 -> 34192.07 | HK17: 46113 | HL17: =HS17-HS$11 -> 617.58 | HM17: =HT17-HT$11 -> 536.12 | HN17: =HM17-HL17 -> -81.46 | HP17: =100*(HS17/HS$11) -> 101.66473 | HQ17: =100*(HT17/HT$11) -> 101.45171 | HS17: =DataQ!AF220 -> 37715.5 | HT17: =DataQ!P220 -> 37466.46
