Workbook
Name Data: [1]sheet0!$C$2

Sheet CHARTS>>

Sheet DATA>>

Sheet Chart Data
B1: Contributions to GDP growth | M1: G7 GDP growth | V1: Contributions to GDP growth | AF1: 2026 forecast vs consensus (HMT survey) | AI1: High | AJ1: Low | AL1: 2026 forecast vs consensus (Focus) | AO1: High | AP1: Low | AR1: Contributions to CPI inflation | AZ1: WFJ forecast - public sector, private sector by pay level | BE1: WFJ forecast - public sector, private sector by pay level | BK1: WFJ forecast - public sector, private sector by pay level | BS1: AE debt dynamics (2026-2030) | CO1: GDIP/GGDBT
B2: Consumer spending | C2: Private investment | D2: Government | E2: Net trade | F2: Other | G2: GDP growth | I2: Private investment | J2: Government | K2: Net trade | N2: ='Annual Data'!AJ2 -> UK | O2: ='Annual Data'!AK2 -> US | P2: ='Annual Data'!AL2 -> Japan | Q2: ='Annual Data'!AM2 -> Germany | R2: ='Annual Data'!AN2 -> France | S2: ='Annual Data'!AO2 -> Italy | T2: ='Annual Data'!AP2 -> Canada | X2: Government consumption & investment | Y2: Other | Z2: GDP growth | AC2: Government consumption & investment | AD2: Other | AG2: OE | AH2: Consensus forecast | AI2: Consensus range* | AJ2: Consensus low | AM2: OE | AN2: Consensus forecast | AO2: Consensus range* | AP2: Consensus low | AS2: Food | AT2: Petrol | AU2: Energy | AV2: Other | AW2: CPI | AX2: 2% LINE | BA2: Government & other services | BB2: Private sector - higher paid* | BC2: Private sector - lower paid* | BF2: Government & other services | BG2: Private sector - higher paid* | BH2: Private sector - lower paid* | BI2: Total | BL2: Government & other services | BM2: Private sector - higher paid* | BN2: Private sector - lower paid* | BO2: Check | BQ2: Private sector | BT2: ='Annual Data'!AQ2 -> UK | BU2: ='Annual Data'!AR2 -> US | BV2: ='Annual Data'!AS2 -> Japan | BW2: ='Annual Data'!AT2 -> Canada | BX2: ='Annual Data'!AU2 -> Australia | BY2: ='Annual Data'!AV2 -> Denmark | BZ2: ='Annual Data'!AW2 -> Sweden | CA2: ='Annual Data'!AX2 -> Switzerland | ... CM2: ='Annual Data'!BJ2 -> Portugal | CP2: ='Annual Data'!AQ2 -> UK | CQ2: ='Annual Data'!BM2 -> Japan | CR2: ='Annual Data'!BN2 -> Canada | CS2: ='Annual Data'!BO2 -> Australia | CT2: ='Annual Data'!BP2 -> Denmark | CU2: ='Annual Data'!BQ2 -> Sweden | CV2: ='Annual Data'!BR2 -> Switzerland | CW2: ='Annual Data'!BS2 -> S Korea | CX2: ='Annual Data'!BT2 -> Germany | ... DI2: ='Annual Data'!CE2 -> UK
A3: 2000- 2009 | B3: =AVERAGE(B22:B31) -> 1.1768592 | C3: =AVERAGE(C22:C31) -> 0.083159375 | D3: =AVERAGE(D22:D31) -> 0.7700912 | E3: =AVERAGE(E22:E31) -> -0.1076214 | F3: =AVERAGE(F22:F31) -> -0.17813516 | G3: =AVERAGE(G22:G31) -> 1.7443533 | M3: 2025 | N3: =100*(('Annual Data'!AJ59/'Annual Data'!AJ58)-1) -> 1.4175184 | O3: =100*(('Annual Data'!AK59/'Annual Data'!AK58)-1) -> 2.0417858 | P3: =100*(('Annual Data'!AL59/'Annual Data'!AL58)-1) -> 1.2519868 | Q3: =100*(('Annual Data'!AM59/'Annual Data'!AM58)-1) -> 0.24336057 | R3: =100*(('Annual Data'!AN59/'Annual Data'!AN58)-1) -> 0.89005196 | S3: =100*(('Annual Data'!AO59/'Annual Data'!AO58)-1) -> 0.55983715 | T3: =100*(('Annual Data'!AP59/'Annual Data'!AP58)-1) -> 1.6286911 | V3: 44562 | W3: Q1 22 | X3: =100*((AC3-AC$6)/'Quarterly Data'!$G$206) -> 0.42406038 | Y3: =100*((AD3-AD$6)/'Quarterly Data'!$G$206) -> -1.3372202 | Z3: =100*(('Quarterly Data'!G203/'Quarterly Data'!$G$206)-1) -> -0.91315981 | AB3: 44562 | AC3: ='Quarterly Data'!J203+'Quarterly Data'!N203 -> 162821 | AD3: ='Quarterly Data'!G203-'Chart Data'!AC3 -> 519706 | AF3: GDP | AG3: =100*(('Annual Data'!B60/'Annual Data'!B59)-1) -> 0.96143326 | AH3: 1.2 | AI3: 1.4 | AJ3: =AG3 -> 0.96143326 | AL3: GDP | AM3: =100*(('Annual Data'!B$60/'Annual Data'!B$59)-1) -> 0.96143326 | AN3: 1.1 | AO3: 1.5 | AP3: 0.9 | AR3: =[2]Contributions!B291 -> 44562 | AS3: =[2]Contributions!C291 -> 0.63444514 | AT3: =[2]Contributions!D291 -> 0.61451004 | AU3: =[2]Contributions!E291 -> 0.75582035 | AV3: =AW3-AS3-AT3-AU3 -> 3.4507378 | AW3: =[2]Contributions!G291 -> 5.4555133 | AX3: 2 | AZ3: 43466 | BE3: 43466 | BF3: =BL3-AVERAGE(BL$23:BL$26) -> -1049.75 | BG3: =BM3-AVERAGE(BM$23:BM$26) -> -352.25 | BH3: =BN3-AVERAGE(BN$23:BN$26) -> 47.75 | BI3: =SUM(BF3:BH3) -> -1354.25 | BK3: 43466 | BL3: ='Quarterly Data'!AH191+'Quarterly Data'!AI191+'Quarterly Data'!AJ191+'Quarterly Data'!AK191+'Quarterly Data'!AL191 -> 10881 | BM3: ='Quarterly Data'!W191+'Quarterly Data'!AD191+'Quarterly Data'!U191+'Quarterly Data'!AC191+'Quarterly Data'!AF191+'Quarterly Data'!X191+'Quarterly Data'!Y191 -> 8593 | BN3: ='Quarterly Data'!AA191+'Quarterly Data'!V191+'Quarterly Data'!AE191+'Quarterly Data'!T191+'Quarterly Data'!AG191+'Quarterly Data'!Z191+'Quarterly Data'!AB191 -> 15966 | BO3: ='Quarterly Data'!S191-'Chart Data'!BL3-'Chart Data'!BM3-'Chart Data'!BN3 -> -2 | BQ3: =BM3+BN3 -> 24559 | BS3: Expected effective interest rates on government debt (r) | BT3: =AVERAGE(CP4:CP8) -> 4.0835467 | BU3: =AVERAGE(CQ4:CQ8) -> 3.6723736 | BV3: =AVERAGE(CR4:CR8) -> 1.3884507 | BW3: =AVERAGE(CS4:CS8) -> 3.2244087 | BX3: =AVERAGE(CT4:CT8) -> 2.4758953 | BY3: =AVERAGE(CU4:CU8) -> 2.0233731 | BZ3: =AVERAGE(CV4:CV8) -> 1.6343447 | CA3: =AVERAGE(CW4:CW8) -> 1.2277289 | ... CM3: =AVERAGE(DI4:DI8) -> 2.2590555 | CO3: 2025 | CP3: =100*('Annual Data'!AQ59/'Annual Data'!BK59) -> 4.5351829 | CQ3: =100*('Annual Data'!AR59/'Annual Data'!BL59) -> 3.5211869 | CR3: =100*('Annual Data'!AS59/'Annual Data'!BM59) -> 0.63596444 | CS3: =100*('Annual Data'!AT59/'Annual Data'!BN59) -> 3.1973737 | CT3: =100*('Annual Data'!AU59/'Annual Data'!BO59) -> 1.6137146 | CU3: =100*('Annual Data'!AV59/'Annual Data'!BP59) -> 2.0153289 | CV3: =100*('Annual Data'!AW59/'Annual Data'!BQ59) -> 1.3512695 | CW3: =100*('Annual Data'!AX59/'Annual Data'!BR59) -> 1.1661427 | ... DI3: =100*('Annual Data'!BJ59/'Annual Data'!CD59) -> 2.0533644
A4: 2010- 2019 | B4: =AVERAGE(B32:B41) -> 1.3065392 | C4: =AVERAGE(C32:C41) -> 0.57229441 | D4: =AVERAGE(D32:D41) -> 0.20639226 | E4: =AVERAGE(E32:E41) -> -0.21890157 | F4: =AVERAGE(F32:F41) -> 0.10334206 | G4: =AVERAGE(G32:G41) -> 1.9696664 | V4: 44652 | W4: Q2 22 | X4: =100*((AC4-AC$6)/'Quarterly Data'!$G$206) -> -0.33332511 | Y4: =100*((AD4-AD$6)/'Quarterly Data'!$G$206) -> -0.027002818 | Z4: =100*(('Quarterly Data'!G204/'Quarterly Data'!$G$206)-1) -> -0.36032792 | AB4: 44652 | AC4: ='Quarterly Data'!J204+'Quarterly Data'!N204 -> 157604 | AD4: ='Quarterly Data'!G204-'Chart Data'!AC4 -> 528731 | AF4: Consumer spending | AG4: =100*(('Annual Data'!C60/'Annual Data'!C59)-1) -> 1.009535 | AH4: 1.1 | AI4: 1.7 | AJ4: 0.7 | AL4: Consumer spending | AM4: =100*(('Annual Data'!C$60/'Annual Data'!C$59)-1) -> 1.009535 | AN4: 1.1 | AO4: 1.5 | AP4: 0.6 | AR4: =[2]Contributions!B292 -> 44593 | AS4: =[2]Contributions!C292 -> 0.74294251 | AT4: =[2]Contributions!D292 -> 0.61728816 | AU4: =[2]Contributions!E292 -> 0.76192273 | AV4: =AW4-AS4-AT4-AU4 -> 4.0544547 | AW4: =[2]Contributions!G292 -> 6.1766081 | AX4: 2 | AZ4: 43556 | BE4: 43556 | BF4: =BL4-AVERAGE(BL$23:BL$26) -> -1030.75 | BG4: =BM4-AVERAGE(BM$23:BM$26) -> -337.25 | BH4: =BN4-AVERAGE(BN$23:BN$26) -> 118.75 | BI4: =SUM(BF4:BH4) -> -1249.25 | BK4: 43556 | BL4: ='Quarterly Data'!AH192+'Quarterly Data'!AI192+'Quarterly Data'!AJ192+'Quarterly Data'!AK192+'Quarterly Data'!AL192 -> 10900 | BM4: ='Quarterly Data'!W192+'Quarterly Data'!AD192+'Quarterly Data'!U192+'Quarterly Data'!AC192+'Quarterly Data'!AF192+'Quarterly Data'!X192+'Quarterly Data'!Y192 -> 8608 | BN4: ='Quarterly Data'!AA192+'Quarterly Data'!V192+'Quarterly Data'!AE192+'Quarterly Data'!T192+'Quarterly Data'!AG192+'Quarterly Data'!Z192+'Quarterly Data'!AB192 -> 16037 | BO4: ='Quarterly Data'!S192-'Chart Data'!BL4-'Chart Data'!BM4-'Chart Data'!BN4 -> 1 | BQ4: =BM4+BN4 -> 24645 | BS4: Expected annual average nominal GDP growth (g) | BT4: =100*(('Annual Data'!CE64/'Annual Data'!CE59)^(1/5)-1) -> 3.7091669 | BU4: =100*(('Annual Data'!CF64/'Annual Data'!CF59)^(1/5)-1) -> 4.1857812 | BV4: =100*(('Annual Data'!CG64/'Annual Data'!CG59)^(1/5)-1) -> 1.3615849 | BW4: =100*(('Annual Data'!CH64/'Annual Data'!CH59)^(1/5)-1) -> 3.5042386 | BX4: =100*(('Annual Data'!CI64/'Annual Data'!CI59)^(1/5)-1) -> 4.6471878 | BY4: =100*(('Annual Data'!CJ64/'Annual Data'!CJ59)^(1/5)-1) -> 4.1015374 | BZ4: =100*(('Annual Data'!CK64/'Annual Data'!CK59)^(1/5)-1) -> 4.014006 | CA4: =100*(('Annual Data'!CL64/'Annual Data'!CL59)^(1/5)-1) -> 2.3464219 | ... CM4: =100*(('Annual Data'!CX64/'Annual Data'!CX59)^(1/5)-1) -> 2.9984881 | CO4: 2026 | CP4: =100*('Annual Data'!AQ60/'Annual Data'!BK60) -> 4.0409321 | CQ4: =100*('Annual Data'!AR60/'Annual Data'!BL60) -> 3.6149732 | CR4: =100*('Annual Data'!AS60/'Annual Data'!BM60) -> 0.83901696 | CS4: =100*('Annual Data'!AT60/'Annual Data'!BN60) -> 3.1886173 | CT4: =100*('Annual Data'!AU60/'Annual Data'!BO60) -> 2.2993875 | CU4: =100*('Annual Data'!AV60/'Annual Data'!BP60) -> 2.00407 | CV4: =100*('Annual Data'!AW60/'Annual Data'!BQ60) -> 1.5709356 | CW4: =100*('Annual Data'!AX60/'Annual Data'!BR60) -> 1.1778994 | ... DI4: =100*('Annual Data'!BJ60/'Annual Data'!CD60) -> 2.1069456
V5: 44743 | W5: Q3 22 | X5: =100*((AC5-AC$6)/'Quarterly Data'!$G$206) -> -0.0078395278 | Y5: =100*((AD5-AD$6)/'Quarterly Data'!$G$206) -> -0.25173595 | Z5: =100*(('Quarterly Data'!G205/'Quarterly Data'!$G$206)-1) -> -0.25957548 | AB5: 44743 | AC5: ='Quarterly Data'!J205+'Quarterly Data'!N205 -> 159846 | AD5: ='Quarterly Data'!G205-'Chart Data'!AC5 -> 527183 | AF5: Fixed investment | AG5: =100*(('Annual Data'!D60/'Annual Data'!D59)-1) -> 0.93629904 | AH5: 1.7 | AI5: 2.9 | AJ5: =AG5 -> 0.93629904 | AL5: Fixed investment | AM5: =100*(('Annual Data'!D$60/'Annual Data'!D$59)-1) -> 0.93629904 | AN5: 1.7 | AO5: 2.9 | AP5: -0.1 | AR5: =[2]Contributions!B293 -> 44621 | AS5: =[2]Contributions!C293 -> 0.88985377 | AT5: =[2]Contributions!D293 -> 0.86461908 | AU5: =[2]Contributions!E293 -> 0.81185819 | AV5: =AW5-AS5-AT5-AU5 -> 4.456793 | AW5: =[2]Contributions!G293 -> 7.023124 | AX5: 2 | AZ5: 43647 | BE5: 43647 | BF5: =BL5-AVERAGE(BL$23:BL$26) -> -968.75 | BG5: =BM5-AVERAGE(BM$23:BM$26) -> -364.25 | BH5: =BN5-AVERAGE(BN$23:BN$26) -> 154.75 | BI5: =SUM(BF5:BH5) -> -1178.25 | BK5: 43647 | BL5: ='Quarterly Data'!AH193+'Quarterly Data'!AI193+'Quarterly Data'!AJ193+'Quarterly Data'!AK193+'Quarterly Data'!AL193 -> 10962 | BM5: ='Quarterly Data'!W193+'Quarterly Data'!AD193+'Quarterly Data'!U193+'Quarterly Data'!AC193+'Quarterly Data'!AF193+'Quarterly Data'!X193+'Quarterly Data'!Y193 -> 8581 | BN5: ='Quarterly Data'!AA193+'Quarterly Data'!V193+'Quarterly Data'!AE193+'Quarterly Data'!T193+'Quarterly Data'!AG193+'Quarterly Data'!Z193+'Quarterly Data'!AB193 -> 16073 | BO5: ='Quarterly Data'!S193-'Chart Data'!BL5-'Chart Data'!BM5-'Chart Data'!BN5 -> -1 | BQ5: =BM5+BN5 -> 24654 | CO5: 2027 | CP5: =100*('Annual Data'!AQ61/'Annual Data'!BK61) -> 4.0897531 | CQ5: =100*('Annual Data'!AR61/'Annual Data'!BL61) -> 3.6703991 | CR5: =100*('Annual Data'!AS61/'Annual Data'!BM61) -> 1.1113602 | CS5: =100*('Annual Data'!AT61/'Annual Data'!BN61) -> 3.2086801 | CT5: =100*('Annual Data'!AU61/'Annual Data'!BO61) -> 2.527882 | CU5: =100*('Annual Data'!AV61/'Annual Data'!BP61) -> 2.0189826 | CV5: =100*('Annual Data'!AW61/'Annual Data'!BQ61) -> 1.6092971 | CW5: =100*('Annual Data'!AX61/'Annual Data'!BR61) -> 1.2040547 | ... DI5: =100*('Annual Data'!BJ61/'Annual Data'!CD61) -> 2.1857001
A6: 2023 | B6: =B45 -> -0.19444691 | C6: =C45 -> -0.051918091 | D6: =D45 -> 0.56220917 | E6: =E45 -> -0.2284396 | F6: =F45 -> 0.18424546 | G6: =G45 -> 0.27165003 | V6: 44835 | W6: Q4 22 | X6: =100*((AC6-AC$6)/'Quarterly Data'!$G$206) -> 0 | Y6: =100*((AD6-AD$6)/'Quarterly Data'!$G$206) -> 0 | Z6: =100*(('Quarterly Data'!G206/'Quarterly Data'!$G$206)-1) -> 0 | AB6: 44835 | AC6: ='Quarterly Data'!J206+'Quarterly Data'!N206 -> 159900 | AD6: ='Quarterly Data'!G206-'Chart Data'!AC6 -> 528917 | AF6: Govt consumption | AG6: =100*(('Annual Data'!E60/'Annual Data'!E59)-1) -> 2.0010144 | AH6: 1.7 | AI6: 2.2 | AJ6: 1.2 | AR6: =[2]Contributions!B294 -> 44652 | AS6: =[2]Contributions!C294 -> 0.96773224 | AT6: =[2]Contributions!D294 -> 0.89042504 | AU6: =[2]Contributions!E294 -> 2.344496 | AV6: =AW6-AS6-AT6-AU6 -> 4.8080084 | AW6: =[2]Contributions!G294 -> 9.0106617 | AX6: 2 | AZ6: 43739 | BE6: 43739 | BF6: =BL6-AVERAGE(BL$23:BL$26) -> -912.75 | BG6: =BM6-AVERAGE(BM$23:BM$26) -> -350.25 | BH6: =BN6-AVERAGE(BN$23:BN$26) -> 128.75 | BI6: =SUM(BF6:BH6) -> -1134.25 | BK6: 43739 | BL6: ='Quarterly Data'!AH194+'Quarterly Data'!AI194+'Quarterly Data'!AJ194+'Quarterly Data'!AK194+'Quarterly Data'!AL194 -> 11018 | BM6: ='Quarterly Data'!W194+'Quarterly Data'!AD194+'Quarterly Data'!U194+'Quarterly Data'!AC194+'Quarterly Data'!AF194+'Quarterly Data'!X194+'Quarterly Data'!Y194 -> 8595 | BN6: ='Quarterly Data'!AA194+'Quarterly Data'!V194+'Quarterly Data'!AE194+'Quarterly Data'!T194+'Quarterly Data'!AG194+'Quarterly Data'!Z194+'Quarterly Data'!AB194 -> 16047 | BO6: ='Quarterly Data'!S194-'Chart Data'!BL6-'Chart Data'!BM6-'Chart Data'!BN6 -> 1 | BQ6: =BM6+BN6 -> 24642 | CO6: 2028 | CP6: =100*('Annual Data'!AQ62/'Annual Data'!BK62) -> 4.0698033 | CQ6: =100*('Annual Data'!AR62/'Annual Data'!BL62) -> 3.6830863 | CR6: =100*('Annual Data'!AS62/'Annual Data'!BM62) -> 1.4228995 | CS6: =100*('Annual Data'!AT62/'Annual Data'!BN62) -> 3.226594 | CT6: =100*('Annual Data'!AU62/'Annual Data'!BO62) -> 2.5506286 | CU6: =100*('Annual Data'!AV62/'Annual Data'!BP62) -> 2.0317969 | CV6: =100*('Annual Data'!AW62/'Annual Data'!BQ62) -> 1.6391828 | CW6: =100*('Annual Data'!AX62/'Annual Data'!BR62) -> 1.2316285 | ... DI6: =100*('Annual Data'!BJ62/'Annual Data'!CD62) -> 2.2623814
A7: 2024 | B7: =B46 -> -0.10726105 | C7: =C46 -> 0.19875269 | D7: =D46 -> 0.82436948 | E7: =E46 -> -0.65879068 | F7: =F46 -> 0.86608211 | G7: =G46 -> 1.1231525 | V7: 44927 | W7: Q1 23 | X7: =100*((AC7-AC$6)/'Quarterly Data'!$G$206) -> 0.16985644 | Y7: =100*((AD7-AD$6)/'Quarterly Data'!$G$206) -> -0.1133828 | Z7: =100*(('Quarterly Data'!G207/'Quarterly Data'!$G$206)-1) -> 0.056473635 | AB7: 44927 | AC7: ='Quarterly Data'!J207+'Quarterly Data'!N207 -> 161070 | AD7: ='Quarterly Data'!G207-'Chart Data'!AC7 -> 528136 | AF7: Exports | AG7: =100*(('Annual Data'!F60/'Annual Data'!F59)-1) -> -0.36591598 | AH7: 1.2 | AI7: 3.3 | AJ7: -0.4 | AR7: =[2]Contributions!B295 -> 44682 | AS7: =[2]Contributions!C295 -> 1.2132102 | AT7: =[2]Contributions!D295 -> 0.93372095 | AU7: =[2]Contributions!E295 -> 2.3435002 | AV7: =AW7-AS7-AT7-AU7 -> 4.59227 | AW7: =[2]Contributions!G295 -> 9.0827013 | AX7: 2 | AZ7: 43831 | BA7: =100*((BL7/BL3)-1) -> 0.86389119 | BB7: =100*((BM7/BM3)-1) -> 0.52368207 | BC7: =100*((BN7/BN3)-1) -> 0.1941626 | BE7: 43831 | BF7: =BL7-AVERAGE(BL$23:BL$26) -> -955.75 | BG7: =BM7-AVERAGE(BM$23:BM$26) -> -307.25 | BH7: =BN7-AVERAGE(BN$23:BN$26) -> 78.75 | BI7: =SUM(BF7:BH7) -> -1184.25 | BK7: 43831 | BL7: ='Quarterly Data'!AH195+'Quarterly Data'!AI195+'Quarterly Data'!AJ195+'Quarterly Data'!AK195+'Quarterly Data'!AL195 -> 10975 | BM7: ='Quarterly Data'!W195+'Quarterly Data'!AD195+'Quarterly Data'!U195+'Quarterly Data'!AC195+'Quarterly Data'!AF195+'Quarterly Data'!X195+'Quarterly Data'!Y195 -> 8638 | BN7: ='Quarterly Data'!AA195+'Quarterly Data'!V195+'Quarterly Data'!AE195+'Quarterly Data'!T195+'Quarterly Data'!AG195+'Quarterly Data'!Z195+'Quarterly Data'!AB195 -> 15997 | BO7: ='Quarterly Data'!S195-'Chart Data'!BL7-'Chart Data'!BM7-'Chart Data'!BN7 -> -1 | BQ7: =BM7+BN7 -> 24635 | CO7: 2029 | CP7: =100*('Annual Data'!AQ63/'Annual Data'!BK63) -> 4.1358825 | CQ7: =100*('Annual Data'!AR63/'Annual Data'!BL63) -> 3.6933855 | CR7: =100*('Annual Data'!AS63/'Annual Data'!BM63) -> 1.6834901 | CS7: =100*('Annual Data'!AT63/'Annual Data'!BN63) -> 3.241977 | CT7: =100*('Annual Data'!AU63/'Annual Data'!BO63) -> 2.5161783 | CU7: =100*('Annual Data'!AV63/'Annual Data'!BP63) -> 2.0408062 | CV7: =100*('Annual Data'!AW63/'Annual Data'!BQ63) -> 1.6659256 | CW7: =100*('Annual Data'!AX63/'Annual Data'!BR63) -> 1.253381 | ... DI7: =100*('Annual Data'!BJ63/'Annual Data'!CD63) -> 2.3353486
A8: 2025 | B8: =B47 -> 0.51482982 | C8: =C47 -> 0.46433244 | D8: =D47 -> 0.52687693 | E8: =E47 -> -0.31060248 | F8: =F47 -> 0.22208169 | G8: =G47 -> 1.4175184 | V8: 45017 | W8: Q2 23 | X8: =100*((AC8-AC$6)/'Quarterly Data'!$G$206) -> 0.41404321 | Y8: =100*((AD8-AD$6)/'Quarterly Data'!$G$206) -> -0.31619429 | Z8: =100*(('Quarterly Data'!G208/'Quarterly Data'!$G$206)-1) -> 0.097848921 | AB8: 45017 | AC8: ='Quarterly Data'!J208+'Quarterly Data'!N208 -> 162752 | AD8: ='Quarterly Data'!G208-'Chart Data'!AC8 -> 526739 | AF8: Imports | AG8: =100*(('Annual Data'!G60/'Annual Data'!G59)-1) -> -0.43116331 | AH8: 1.2 | AI8: 2.3 | AJ8: -0.9 | AR8: =[2]Contributions!B296 -> 44713 | AS8: =[2]Contributions!C296 -> 1.3259122 | AT8: =[2]Contributions!D296 -> 1.220663 | AU8: =[2]Contributions!E296 -> 2.3445813 | AV8: =AW8-AS8-AT8-AU8 -> 4.5209569 | AW8: =[2]Contributions!G296 -> 9.4121135 | AX8: 2 | AZ8: 43922 | BA8: =100*((BL8/BL4)-1) -> 0.70642202 | BB8: =100*((BM8/BM4)-1) -> -1.4521375 | BC8: =100*((BN8/BN4)-1) -> -2.2635156 | BE8: 43922 | BF8: =BL8-AVERAGE(BL$23:BL$26) -> -953.75 | BG8: =BM8-AVERAGE(BM$23:BM$26) -> -462.25 | BH8: =BN8-AVERAGE(BN$23:BN$26) -> -244.25 | BI8: =SUM(BF8:BH8) -> -1660.25 | BK8: 43922 | BL8: ='Quarterly Data'!AH196+'Quarterly Data'!AI196+'Quarterly Data'!AJ196+'Quarterly Data'!AK196+'Quarterly Data'!AL196 -> 10977 | BM8: ='Quarterly Data'!W196+'Quarterly Data'!AD196+'Quarterly Data'!U196+'Quarterly Data'!AC196+'Quarterly Data'!AF196+'Quarterly Data'!X196+'Quarterly Data'!Y196 -> 8483 | BN8: ='Quarterly Data'!AA196+'Quarterly Data'!V196+'Quarterly Data'!AE196+'Quarterly Data'!T196+'Quarterly Data'!AG196+'Quarterly Data'!Z196+'Quarterly Data'!AB196 -> 15674 | BO8: ='Quarterly Data'!S196-'Chart Data'!BL8-'Chart Data'!BM8-'Chart Data'!BN8 -> 1 | BQ8: =BM8+BN8 -> 24157 | CO8: 2030 | CP8: =100*('Annual Data'!AQ64/'Annual Data'!BK64) -> 4.0813627 | CQ8: =100*('Annual Data'!AR64/'Annual Data'!BL64) -> 3.7000238 | CR8: =100*('Annual Data'!AS64/'Annual Data'!BM64) -> 1.8854865 | CS8: =100*('Annual Data'!AT64/'Annual Data'!BN64) -> 3.2561751 | CT8: =100*('Annual Data'!AU64/'Annual Data'!BO64) -> 2.4854001 | CU8: =100*('Annual Data'!AV64/'Annual Data'!BP64) -> 2.0212095 | CV8: =100*('Annual Data'!AW64/'Annual Data'!BQ64) -> 1.6863823 | CW8: =100*('Annual Data'!AX64/'Annual Data'!BR64) -> 1.2716807 | ... DI8: =100*('Annual Data'!BJ64/'Annual Data'!CD64) -> 2.4049019
A9: 2026 | B9: =B48 -> 0.59504155 | C9: =C48 -> -0.056271943 | D9: =D48 -> 0.6611522 | E9: =E48 -> 0.029997956 | F9: =F48 -> -0.26848649 | G9: =G48 -> 0.96143326 | V9: 45108 | W9: Q3 23 | X9: =100*((AC9-AC$6)/'Quarterly Data'!$G$206) -> 0.80761654 | Y9: =100*((AD9-AD$6)/'Quarterly Data'!$G$206) -> -0.9495991 | Z9: =100*(('Quarterly Data'!G209/'Quarterly Data'!$G$206)-1) -> -0.14198256 | AB9: 45108 | AC9: ='Quarterly Data'!J209+'Quarterly Data'!N209 -> 165463 | AD9: ='Quarterly Data'!G209-'Chart Data'!AC9 -> 522376 | AR9: =[2]Contributions!B297 -> 44743 | AS9: =[2]Contributions!C297 -> 1.6820304 | AT9: =[2]Contributions!D297 -> 1.2826645 | AU9: =[2]Contributions!E297 -> 2.3502743 | AV9: =AW9-AS9-AT9-AU9 -> 4.785932 | AW9: =[2]Contributions!G297 -> 10.100901 | AX9: 2 | AZ9: 44013 | BA9: =100*((BL9/BL5)-1) -> -1.0855683 | BB9: =100*((BM9/BM5)-1) -> -3.1464864 | BC9: =100*((BN9/BN5)-1) -> -3.9382816 | BE9: 44013 | BF9: =BL9-AVERAGE(BL$23:BL$26) -> -1087.75 | BG9: =BM9-AVERAGE(BM$23:BM$26) -> -634.25 | BH9: =BN9-AVERAGE(BN$23:BN$26) -> -478.25 | BI9: =SUM(BF9:BH9) -> -2200.25 | BK9: 44013 | BL9: ='Quarterly Data'!AH197+'Quarterly Data'!AI197+'Quarterly Data'!AJ197+'Quarterly Data'!AK197+'Quarterly Data'!AL197 -> 10843 | BM9: ='Quarterly Data'!W197+'Quarterly Data'!AD197+'Quarterly Data'!U197+'Quarterly Data'!AC197+'Quarterly Data'!AF197+'Quarterly Data'!X197+'Quarterly Data'!Y197 -> 8311 | BN9: ='Quarterly Data'!AA197+'Quarterly Data'!V197+'Quarterly Data'!AE197+'Quarterly Data'!T197+'Quarterly Data'!AG197+'Quarterly Data'!Z197+'Quarterly Data'!AB197 -> 15440 | BO9: ='Quarterly Data'!S197-'Chart Data'!BL9-'Chart Data'!BM9-'Chart Data'!BN9 -> 0 | BQ9: =BM9+BN9 -> 23751
V10: 45200 | W10: Q4 23 | X10: =100*((AC10-AC$6)/'Quarterly Data'!$G$206) -> 0.93159722 | Y10: =100*((AD10-AD$6)/'Quarterly Data'!$G$206) -> -1.3945649 | Z10: =100*(('Quarterly Data'!G210/'Quarterly Data'!$G$206)-1) -> -0.46296767 | AB10: 45200 | AC10: ='Quarterly Data'!J210+'Quarterly Data'!N210 -> 166317 | AD10: ='Quarterly Data'!G210-'Chart Data'!AC10 -> 519311 | AR10: =[2]Contributions!B298 -> 44774 | AS10: =[2]Contributions!C298 -> 1.7481531 | AT10: =[2]Contributions!D298 -> 0.94983699 | AU10: =[2]Contributions!E298 -> 2.3137985 | AV10: =AW10-AS10-AT10-AU10 -> 4.8583992 | AW10: =[2]Contributions!G298 -> 9.8701878 | AX10: 2 | AZ10: 44105 | BA10: =100*((BL10/BL6)-1) -> -1.3069523 | BB10: =100*((BM10/BM6)-1) -> -2.6294357 | BC10: =100*((BN10/BN6)-1) -> -4.7734779 | BE10: 44105 | BF10: =BL10-AVERAGE(BL$23:BL$26) -> -1056.75 | BG10: =BM10-AVERAGE(BM$23:BM$26) -> -576.25 | BH10: =BN10-AVERAGE(BN$23:BN$26) -> -637.25 | BI10: =SUM(BF10:BH10) -> -2270.25 | BK10: 44105 | BL10: ='Quarterly Data'!AH198+'Quarterly Data'!AI198+'Quarterly Data'!AJ198+'Quarterly Data'!AK198+'Quarterly Data'!AL198 -> 10874 | BM10: ='Quarterly Data'!W198+'Quarterly Data'!AD198+'Quarterly Data'!U198+'Quarterly Data'!AC198+'Quarterly Data'!AF198+'Quarterly Data'!X198+'Quarterly Data'!Y198 -> 8369 | BN10: ='Quarterly Data'!AA198+'Quarterly Data'!V198+'Quarterly Data'!AE198+'Quarterly Data'!T198+'Quarterly Data'!AG198+'Quarterly Data'!Z198+'Quarterly Data'!AB198 -> 15281 | BO10: ='Quarterly Data'!S198-'Chart Data'!BL10-'Chart Data'!BM10-'Chart Data'!BN10 -> -2 | BQ10: =BM10+BN10 -> 23650
A11: 1989 | I11: ='Annual Data'!D23-'Annual Data'!I23 -> 278440.92 | J11: ='Annual Data'!E23+'Annual Data'!I23 -> 323786.08 | K11: ='Annual Data'!F23-'Annual Data'!G23 -> -4159 | V11: 45292 | W11: Q1 24 | X11: =100*((AC11-AC$6)/'Quarterly Data'!$G$206) -> 1.1773809 | Y11: =100*((AD11-AD$6)/'Quarterly Data'!$G$206) -> -0.8115363 | Z11: =100*(('Quarterly Data'!G211/'Quarterly Data'!$G$206)-1) -> 0.36584463 | AB11: 45292 | AC11: ='Quarterly Data'!J211+'Quarterly Data'!N211 -> 168010 | AD11: ='Quarterly Data'!G211-'Chart Data'!AC11 -> 523327 | AR11: =[2]Contributions!B299 -> 44805 | AS11: =[2]Contributions!C299 -> 1.9149772 | AT11: =[2]Contributions!D299 -> 0.78413565 | AU11: =[2]Contributions!E299 -> 2.3238543 | AV11: =AW11-AS11-AT11-AU11 -> 5.0726606 | AW11: =[2]Contributions!G299 -> 10.095628 | AX11: 2 | AZ11: 44197 | BA11: =100*((BL11/BL7)-1) -> -0.10022779 | BB11: =100*((BM11/BM7)-1) -> -2.5468859 | BC11: =100*((BN11/BN7)-1) -> -4.0257548 | BE11: 44197 | BF11: =BL11-AVERAGE(BL$23:BL$26) -> -966.75 | BG11: =BM11-AVERAGE(BM$23:BM$26) -> -527.25 | BH11: =BN11-AVERAGE(BN$23:BN$26) -> -565.25 | BI11: =SUM(BF11:BH11) -> -2059.25 | BK11: 44197 | BL11: ='Quarterly Data'!AH199+'Quarterly Data'!AI199+'Quarterly Data'!AJ199+'Quarterly Data'!AK199+'Quarterly Data'!AL199 -> 10964 | BM11: ='Quarterly Data'!W199+'Quarterly Data'!AD199+'Quarterly Data'!U199+'Quarterly Data'!AC199+'Quarterly Data'!AF199+'Quarterly Data'!X199+'Quarterly Data'!Y199 -> 8418 | BN11: ='Quarterly Data'!AA199+'Quarterly Data'!V199+'Quarterly Data'!AE199+'Quarterly Data'!T199+'Quarterly Data'!AG199+'Quarterly Data'!Z199+'Quarterly Data'!AB199 -> 15353 | BO11: ='Quarterly Data'!S199-'Chart Data'!BL11-'Chart Data'!BM11-'Chart Data'!BN11 -> -1 | BQ11: =BM11+BN11 -> 23771
A12: 1990 | B12: =100*(('Annual Data'!C24-'Annual Data'!C23)/'Annual Data'!$B23) -> 0.79640579 | C12: =100*((I12-I11)/'Annual Data'!$B23) -> -0.74265839 | D12: =100*((J12-J11)/'Annual Data'!$B23) -> 0.72168462 | E12: =100*((K12-K11)/'Annual Data'!$B23) -> 0.83105233 | F12: =G12-B12-C12-D12-E12 -> -1.038467 | G12: =100*(('Annual Data'!B24/'Annual Data'!B23)-1) -> 0.56801739 | I12: ='Annual Data'!D24-'Annual Data'!I24 -> 267251.71 | J12: ='Annual Data'!E24+'Annual Data'!I24 -> 334659.29 | K12: ='Annual Data'!F24-'Annual Data'!G24 -> 8362 | V12: 45383 | W12: Q2 24 | X12: =100*((AC12-AC$6)/'Quarterly Data'!$G$206) -> 1.2540341 | Y12: =100*((AD12-AD$6)/'Quarterly Data'!$G$206) -> -0.27249618 | Z12: =100*(('Quarterly Data'!G212/'Quarterly Data'!$G$206)-1) -> 0.98153791 | AB12: 45383 | AC12: ='Quarterly Data'!J212+'Quarterly Data'!N212 -> 168538 | AD12: ='Quarterly Data'!G212-'Chart Data'!AC12 -> 527040 | AR12: =[2]Contributions!B300 -> 44835 | AS12: =[2]Contributions!C300 -> 2.1203898 | AT12: =[2]Contributions!D300 -> 0.66663702 | AU12: =[2]Contributions!E300 -> 3.2501679 | AV12: =AW12-AS12-AT12-AU12 -> 5.0143716 | AW12: =[2]Contributions!G300 -> 11.051566 | AX12: 2 | AZ12: 44287 | BA12: =100*((BL12/BL8)-1) -> 0.92010568 | BB12: =100*((BM12/BM8)-1) -> 0.14145939 | BC12: =100*((BN12/BN8)-1) -> -1.1164987 | BE12: 44287 | BF12: =BL12-AVERAGE(BL$23:BL$26) -> -852.75 | BG12: =BM12-AVERAGE(BM$23:BM$26) -> -450.25 | BH12: =BN12-AVERAGE(BN$23:BN$26) -> -419.25 | BI12: =SUM(BF12:BH12) -> -1722.25 | BK12: 44287 | BL12: ='Quarterly Data'!AH200+'Quarterly Data'!AI200+'Quarterly Data'!AJ200+'Quarterly Data'!AK200+'Quarterly Data'!AL200 -> 11078 | BM12: ='Quarterly Data'!W200+'Quarterly Data'!AD200+'Quarterly Data'!U200+'Quarterly Data'!AC200+'Quarterly Data'!AF200+'Quarterly Data'!X200+'Quarterly Data'!Y200 -> 8495 | BN12: ='Quarterly Data'!AA200+'Quarterly Data'!V200+'Quarterly Data'!AE200+'Quarterly Data'!T200+'Quarterly Data'!AG200+'Quarterly Data'!Z200+'Quarterly Data'!AB200 -> 15499 | BO12: ='Quarterly Data'!S200-'Chart Data'!BL12-'Chart Data'!BM12-'Chart Data'!BN12 -> 0 | BQ12: =BM12+BN12 -> 23994
A13: 1991 | B13: =100*(('Annual Data'!C25-'Annual Data'!C24)/'Annual Data'!$B24) -> -0.49366355 | C13: =100*((I13-I12)/'Annual Data'!$B24) -> -1.53306 | D13: =100*((J13-J12)/'Annual Data'!$B24) -> 0.62757019 | E13: =100*((K13-K12)/'Annual Data'!$B24) -> 0.76115264 | F13: =G13-B13-C13-D13-E13 -> -0.76768642 | G13: =100*(('Annual Data'!B25/'Annual Data'!B24)-1) -> -1.4056872 | I13: ='Annual Data'!D25-'Annual Data'!I25 -> 244022.75 | J13: ='Annual Data'!E25+'Annual Data'!I25 -> 344168.25 | K13: ='Annual Data'!F25-'Annual Data'!G25 -> 19895 | V13: 45474 | W13: Q3 24 | X13: =100*((AC13-AC$6)/'Quarterly Data'!$G$206) -> 1.5278369 | Y13: =100*((AD13-AD$6)/'Quarterly Data'!$G$206) -> -0.30385429 | Z13: =100*(('Quarterly Data'!G213/'Quarterly Data'!$G$206)-1) -> 1.2239826 | AB13: 45474 | AC13: ='Quarterly Data'!J213+'Quarterly Data'!N213 -> 170424 | AD13: ='Quarterly Data'!G213-'Chart Data'!AC13 -> 526824 | AR13: =[2]Contributions!B301 -> 44866 | AS13: =[2]Contributions!C301 -> 2.0673238 | AT13: =[2]Contributions!D301 -> 0.53644982 | AU13: =[2]Contributions!E301 -> 3.2074822 | AV13: =AW13-AS13-AT13-AU13 -> 4.860757 | AW13: =[2]Contributions!G301 -> 10.672013 | AX13: 2 | AZ13: 44378 | BA13: =100*((BL13/BL9)-1) -> 2.5177534 | BB13: =100*((BM13/BM9)-1) -> 2.7192877 | BC13: =100*((BN13/BN9)-1) -> 1.2435233 | BE13: 44378 | BF13: =BL13-AVERAGE(BL$23:BL$26) -> -814.75 | BG13: =BM13-AVERAGE(BM$23:BM$26) -> -408.25 | BH13: =BN13-AVERAGE(BN$23:BN$26) -> -286.25 | BI13: =SUM(BF13:BH13) -> -1509.25 | BK13: 44378 | BL13: ='Quarterly Data'!AH201+'Quarterly Data'!AI201+'Quarterly Data'!AJ201+'Quarterly Data'!AK201+'Quarterly Data'!AL201 -> 11116 | BM13: ='Quarterly Data'!W201+'Quarterly Data'!AD201+'Quarterly Data'!U201+'Quarterly Data'!AC201+'Quarterly Data'!AF201+'Quarterly Data'!X201+'Quarterly Data'!Y201 -> 8537 | BN13: ='Quarterly Data'!AA201+'Quarterly Data'!V201+'Quarterly Data'!AE201+'Quarterly Data'!T201+'Quarterly Data'!AG201+'Quarterly Data'!Z201+'Quarterly Data'!AB201 -> 15632 | BO13: ='Quarterly Data'!S201-'Chart Data'!BL13-'Chart Data'!BM13-'Chart Data'!BN13 -> 1 | BQ13: =BM13+BN13 -> 24169
A14: 1992 | B14: =100*(('Annual Data'!C26-'Annual Data'!C25)/'Annual Data'!$B25) -> 0.56067897 | C14: =100*((I14-I13)/'Annual Data'!$B25) -> -0.46008395 | D14: =100*((J14-J13)/'Annual Data'!$B25) -> 0.38377378 | E14: =100*((K14-K13)/'Annual Data'!$B25) -> -0.32525539 | F14: =G14-B14-C14-D14-E14 -> 0.11667424 | G14: =100*(('Annual Data'!B26/'Annual Data'!B25)-1) -> 0.27578765 | I14: ='Annual Data'!D26-'Annual Data'!I26 -> 237149.54 | J14: ='Annual Data'!E26+'Annual Data'!I26 -> 349901.46 | K14: ='Annual Data'!F26-'Annual Data'!G26 -> 15036 | V14: 45566 | W14: Q4 24 | X14: =100*((AC14-AC$6)/'Quarterly Data'!$G$206) -> 1.6576246 | Y14: =100*((AD14-AD$6)/'Quarterly Data'!$G$206) -> -0.19206843 | Z14: =100*(('Quarterly Data'!G214/'Quarterly Data'!$G$206)-1) -> 1.4655562 | AB14: 45566 | AC14: ='Quarterly Data'!J214+'Quarterly Data'!N214 -> 171318 | AD14: ='Quarterly Data'!G214-'Chart Data'!AC14 -> 527594 | AR14: =[2]Contributions!B302 -> 44896 | AS14: =[2]Contributions!C302 -> 2.1053691 | AT14: =[2]Contributions!D302 -> 0.3565041 | AU14: =[2]Contributions!E302 -> 3.1787972 | AV14: =AW14-AS14-AT14-AU14 -> 4.887704 | AW14: =[2]Contributions!G302 -> 10.528374 | AX14: 2 | AZ14: 44470 | BA14: =100*((BL14/BL10)-1) -> 2.4737907 | BB14: =100*((BM14/BM10)-1) -> 2.282232 | BC14: =100*((BN14/BN10)-1) -> 2.2511616 | BE14: 44470 | BF14: =BL14-AVERAGE(BL$23:BL$26) -> -787.75 | BG14: =BM14-AVERAGE(BM$23:BM$26) -> -385.25 | BH14: =BN14-AVERAGE(BN$23:BN$26) -> -293.25 | BI14: =SUM(BF14:BH14) -> -1466.25 | BK14: 44470 | BL14: ='Quarterly Data'!AH202+'Quarterly Data'!AI202+'Quarterly Data'!AJ202+'Quarterly Data'!AK202+'Quarterly Data'!AL202 -> 11143 | BM14: ='Quarterly Data'!W202+'Quarterly Data'!AD202+'Quarterly Data'!U202+'Quarterly Data'!AC202+'Quarterly Data'!AF202+'Quarterly Data'!X202+'Quarterly Data'!Y202 -> 8560 | BN14: ='Quarterly Data'!AA202+'Quarterly Data'!V202+'Quarterly Data'!AE202+'Quarterly Data'!T202+'Quarterly Data'!AG202+'Quarterly Data'!Z202+'Quarterly Data'!AB202 -> 15625 | BO14: ='Quarterly Data'!S202-'Chart Data'!BL14-'Chart Data'!BM14-'Chart Data'!BN14 -> 0 | BQ14: =BM14+BN14 -> 24185
A15: 1993 | B15: =100*(('Annual Data'!C27-'Annual Data'!C26)/'Annual Data'!$B26) -> 1.6377586 | C15: =100*((I15-I14)/'Annual Data'!$B26) -> 0.021772897 | D15: =100*((J15-J14)/'Annual Data'!$B26) -> 0.011137145 | E15: =100*((K15-K14)/'Annual Data'!$B26) -> 0.25907479 | F15: =G15-B15-C15-D15-E15 -> 0.3438532 | G15: =100*(('Annual Data'!B27/'Annual Data'!B26)-1) -> 2.2735966 | I15: ='Annual Data'!D27-'Annual Data'!I27 -> 237475.71 | J15: ='Annual Data'!E27+'Annual Data'!I27 -> 350068.29 | K15: ='Annual Data'!F27-'Annual Data'!G27 -> 18917 | V15: 45658 | W15: Q1 25 | X15: =100*((AC15-AC$6)/'Quarterly Data'!$G$206) -> 1.5099802 | Y15: =100*((AD15-AD$6)/'Quarterly Data'!$G$206) -> 0.62629116 | Z15: =100*(('Quarterly Data'!G215/'Quarterly Data'!$G$206)-1) -> 2.1362713 | AB15: 45658 | AC15: ='Quarterly Data'!J215+'Quarterly Data'!N215 -> 170301 | AD15: ='Quarterly Data'!G215-'Chart Data'!AC15 -> 533231 | AR15: =[2]Contributions!B303 -> 44927 | AS15: =[2]Contributions!C303 -> 2.1442356 | AT15: =[2]Contributions!D303 -> 0.23985336 | AU15: =[2]Contributions!E303 -> 3.2214337 | AV15: =AW15-AS15-AT15-AU15 -> 4.4460012 | AW15: =[2]Contributions!G303 -> 10.051524 | AX15: 2 | AZ15: 44562 | BA15: =100*((BL15/BL11)-1) -> 2.4990879 | BB15: =100*((BM15/BM11)-1) -> 2.6134474 | BC15: =100*((BN15/BN11)-1) -> 3.1394516 | BE15: 44562 | BF15: =BL15-AVERAGE(BL$23:BL$26) -> -692.75 | BG15: =BM15-AVERAGE(BM$23:BM$26) -> -307.25 | BH15: =BN15-AVERAGE(BN$23:BN$26) -> -83.25 | BI15: =SUM(BF15:BH15) -> -1083.25 | BK15: 44562 | BL15: ='Quarterly Data'!AH203+'Quarterly Data'!AI203+'Quarterly Data'!AJ203+'Quarterly Data'!AK203+'Quarterly Data'!AL203 -> 11238 | BM15: ='Quarterly Data'!W203+'Quarterly Data'!AD203+'Quarterly Data'!U203+'Quarterly Data'!AC203+'Quarterly Data'!AF203+'Quarterly Data'!X203+'Quarterly Data'!Y203 -> 8638 | BN15: ='Quarterly Data'!AA203+'Quarterly Data'!V203+'Quarterly Data'!AE203+'Quarterly Data'!T203+'Quarterly Data'!AG203+'Quarterly Data'!Z203+'Quarterly Data'!AB203 -> 15835 | BO15: ='Quarterly Data'!S203-'Chart Data'!BL15-'Chart Data'!BM15-'Chart Data'!BN15 -> 1 | BQ15: =BM15+BN15 -> 24473
A16: 1994 | B16: =100*(('Annual Data'!C28-'Annual Data'!C27)/'Annual Data'!$B27) -> 1.8941545 | C16: =100*((I16-I15)/'Annual Data'!$B27) -> 0.14839989 | D16: =100*((J16-J15)/'Annual Data'!$B27) -> 0.39621848 | E16: =100*((K16-K15)/'Annual Data'!$B27) -> 0.69930983 | F16: =G16-B16-C16-D16-E16 -> 0.28059856 | G16: =100*(('Annual Data'!B28/'Annual Data'!B27)-1) -> 3.4186812 | I16: ='Annual Data'!D28-'Annual Data'!I28 -> 239749.31 | J16: ='Annual Data'!E28+'Annual Data'!I28 -> 356138.69 | K16: ='Annual Data'!F28-'Annual Data'!G28 -> 29631 | V16: 45748 | W16: Q2 25 | X16: =100*((AC16-AC$6)/'Quarterly Data'!$G$206) -> 1.9232975 | Y16: =100*((AD16-AD$6)/'Quarterly Data'!$G$206) -> 0.4966486 | Z16: =100*(('Quarterly Data'!G216/'Quarterly Data'!$G$206)-1) -> 2.4199461 | AB16: 45748 | AC16: ='Quarterly Data'!J216+'Quarterly Data'!N216 -> 173148 | AD16: ='Quarterly Data'!G216-'Chart Data'!AC16 -> 532338 | AR16: =[2]Contributions!B304 -> 44958 | AS16: =[2]Contributions!C304 -> 2.3586634 | AT16: =[2]Contributions!D304 -> 0.14412908 | AU16: =[2]Contributions!E304 -> 3.1778898 | AV16: =AW16-AS16-AT16-AU16 -> 4.7357145 | AW16: =[2]Contributions!G304 -> 10.416397 | AX16: 2 | AZ16: 44652 | BA16: =100*((BL16/BL12)-1) -> 2.2838057 | BB16: =100*((BM16/BM12)-1) -> 1.624485 | BC16: =100*((BN16/BN12)-1) -> 2.9550294 | BE16: 44652 | BF16: =BL16-AVERAGE(BL$23:BL$26) -> -599.75 | BG16: =BM16-AVERAGE(BM$23:BM$26) -> -312.25 | BH16: =BN16-AVERAGE(BN$23:BN$26) -> 38.75 | BI16: =SUM(BF16:BH16) -> -873.25 | BK16: 44652 | BL16: ='Quarterly Data'!AH204+'Quarterly Data'!AI204+'Quarterly Data'!AJ204+'Quarterly Data'!AK204+'Quarterly Data'!AL204 -> 11331 | BM16: ='Quarterly Data'!W204+'Quarterly Data'!AD204+'Quarterly Data'!U204+'Quarterly Data'!AC204+'Quarterly Data'!AF204+'Quarterly Data'!X204+'Quarterly Data'!Y204 -> 8633 | BN16: ='Quarterly Data'!AA204+'Quarterly Data'!V204+'Quarterly Data'!AE204+'Quarterly Data'!T204+'Quarterly Data'!AG204+'Quarterly Data'!Z204+'Quarterly Data'!AB204 -> 15957 | BO16: ='Quarterly Data'!S204-'Chart Data'!BL16-'Chart Data'!BM16-'Chart Data'!BN16 -> -1 | BQ16: =BM16+BN16 -> 24590
A17: 1995 | B17: =100*(('Annual Data'!C29-'Annual Data'!C28)/'Annual Data'!$B28) -> 1.2249607 | C17: =100*((I17-I16)/'Annual Data'!$B28) -> 0.05222445 | D17: =100*((J17-J16)/'Annual Data'!$B28) -> 0.16103446 | E17: =100*((K17-K16)/'Annual Data'!$B28) -> 0.86117722 | F17: =G17-B17-C17-D17-E17 -> 0.10628233 | G17: =100*(('Annual Data'!B29/'Annual Data'!B28)-1) -> 2.4056792 | I17: ='Annual Data'!D29-'Annual Data'!I29 -> 240576.79 | J17: ='Annual Data'!E29+'Annual Data'!I29 -> 358690.21 | K17: ='Annual Data'!F29-'Annual Data'!G29 -> 43276 | V17: 45839 | W17: Q3 25 | X17: =100*((AC17-AC$6)/'Quarterly Data'!$G$206) -> 2.1205923 | Y17: =100*((AD17-AD$6)/'Quarterly Data'!$G$206) -> 0.38297545 | Z17: =100*(('Quarterly Data'!G217/'Quarterly Data'!$G$206)-1) -> 2.5035677 | AB17: 45839 | AC17: ='Quarterly Data'!J217+'Quarterly Data'!N217 -> 174507 | AD17: ='Quarterly Data'!G217-'Chart Data'!AC17 -> 531555 | AR17: =[2]Contributions!B305 -> 44986 | AS17: =[2]Contributions!C305 -> 2.4389848 | AT17: =[2]Contributions!D305 -> -0.20308559 | AU17: =[2]Contributions!E305 -> 3.0831151 | AV17: =AW17-AS17-AT17-AU17 -> 4.7378631 | AW17: =[2]Contributions!G305 -> 10.056877 | AX17: 2 | AZ17: 44743 | BA17: =100*((BL17/BL13)-1) -> 1.7992083 | BB17: =100*((BM17/BM13)-1) -> 0.77310531 | BC17: =100*((BN17/BN13)-1) -> 2.7699591 | BE17: 44743 | BF17: =BL17-AVERAGE(BL$23:BL$26) -> -614.75 | BG17: =BM17-AVERAGE(BM$23:BM$26) -> -342.25 | BH17: =BN17-AVERAGE(BN$23:BN$26) -> 146.75 | BI17: =SUM(BF17:BH17) -> -810.25 | BK17: 44743 | BL17: ='Quarterly Data'!AH205+'Quarterly Data'!AI205+'Quarterly Data'!AJ205+'Quarterly Data'!AK205+'Quarterly Data'!AL205 -> 11316 | BM17: ='Quarterly Data'!W205+'Quarterly Data'!AD205+'Quarterly Data'!U205+'Quarterly Data'!AC205+'Quarterly Data'!AF205+'Quarterly Data'!X205+'Quarterly Data'!Y205 -> 8603 | BN17: ='Quarterly Data'!AA205+'Quarterly Data'!V205+'Quarterly Data'!AE205+'Quarterly Data'!T205+'Quarterly Data'!AG205+'Quarterly Data'!Z205+'Quarterly Data'!AB205 -> 16065 | BO17: ='Quarterly Data'!S205-'Chart Data'!BL17-'Chart Data'!BM17-'Chart Data'!BN17 -> 1 | BQ17: =BM17+BN17 -> 24668
A18: 1996 | B18: =100*(('Annual Data'!C30-'Annual Data'!C29)/'Annual Data'!$B29) -> 2.1586046 | C18: =100*((I18-I17)/'Annual Data'!$B29) -> 1.084603 | D18: =100*((J18-J17)/'Annual Data'!$B29) -> -0.1581749 | E18: =100*((K18-K17)/'Annual Data'!$B29) -> -0.21644595 | F18: =G18-B18-C18-D18-E18 -> -0.25367071 | G18: =100*(('Annual Data'!B30/'Annual Data'!B29)-1) -> 2.614916 | I18: ='Annual Data'!D30-'Annual Data'!I30 -> 258175.3 | J18: ='Annual Data'!E30+'Annual Data'!I30 -> 356123.7 | K18: ='Annual Data'!F30-'Annual Data'!G30 -> 39764 | V18: 45931 | W18: Q4 25 | X18: =100*((AC18-AC$6)/'Quarterly Data'!$G$206) -> 2.1917839 | Y18: =100*((AD18-AD$6)/'Quarterly Data'!$G$206) -> 0.51264995 | Z18: =100*(('Quarterly Data'!G218/'Quarterly Data'!$G$206)-1) -> 2.7044338 | AB18: 45931 | AC18: ='Quarterly Data'!J218+'Quarterly Data'!N218 -> 174997.38 | AD18: ='Quarterly Data'!G218-'Chart Data'!AC18 -> 532448.22 | AR18: =[2]Contributions!B306 -> 45017 | AS18: =[2]Contributions!C306 -> 2.5552057 | AT18: =[2]Contributions!D306 -> -0.30234716 | AU18: =[2]Contributions!E306 -> 1.2789752 | AV18: =AW18-AS18-AT18-AU18 -> 5.1264022 | AW18: =[2]Contributions!G306 -> 8.6582359 | AX18: 2 | AZ18: 44835 | BA18: =100*((BL18/BL14)-1) -> 1.8307458 | BB18: =100*((BM18/BM14)-1) -> 2.0560748 | BC18: =100*((BN18/BN14)-1) -> 3.0272 | BE18: 44835 | BF18: =BL18-AVERAGE(BL$23:BL$26) -> -583.75 | BG18: =BM18-AVERAGE(BM$23:BM$26) -> -209.25 | BH18: =BN18-AVERAGE(BN$23:BN$26) -> 179.75 | BI18: =SUM(BF18:BH18) -> -613.25 | BK18: 44835 | BL18: ='Quarterly Data'!AH206+'Quarterly Data'!AI206+'Quarterly Data'!AJ206+'Quarterly Data'!AK206+'Quarterly Data'!AL206 -> 11347 | BM18: ='Quarterly Data'!W206+'Quarterly Data'!AD206+'Quarterly Data'!U206+'Quarterly Data'!AC206+'Quarterly Data'!AF206+'Quarterly Data'!X206+'Quarterly Data'!Y206 -> 8736 | BN18: ='Quarterly Data'!AA206+'Quarterly Data'!V206+'Quarterly Data'!AE206+'Quarterly Data'!T206+'Quarterly Data'!AG206+'Quarterly Data'!Z206+'Quarterly Data'!AB206 -> 16098 | BO18: ='Quarterly Data'!S206-'Chart Data'!BL18-'Chart Data'!BM18-'Chart Data'!BN18 -> 0 | BQ18: =BM18+BN18 -> 24834
A19: 1997 | B19: =100*(('Annual Data'!C31-'Annual Data'!C30)/'Annual Data'!$B30) -> 2.7819736 | C19: =100*((I19-I18)/'Annual Data'!$B30) -> -0.38025694 | D19: =100*((J19-J18)/'Annual Data'!$B30) -> 0.15761496 | E19: =100*((K19-K18)/'Annual Data'!$B30) -> 0.77537305 | F19: =G19-B19-C19-D19-E19 -> 1.5452806 | G19: =100*(('Annual Data'!B31/'Annual Data'!B30)-1) -> 4.8799853 | I19: ='Annual Data'!D31-'Annual Data'!I31 -> 251844 | J19: ='Annual Data'!E31+'Annual Data'!I31 -> 358748 | K19: ='Annual Data'!F31-'Annual Data'!G31 -> 52674 | V19: 46023 | W19: Q1 26 | X19: =100*((AC19-AC$6)/'Quarterly Data'!$G$206) -> 2.3661001 | Y19: =100*((AD19-AD$6)/'Quarterly Data'!$G$206) -> 0.62055669 | Z19: =100*(('Quarterly Data'!G219/'Quarterly Data'!$G$206)-1) -> 2.9866568 | AB19: 46023 | AC19: ='Quarterly Data'!J219+'Quarterly Data'!N219 -> 176198.1 | AD19: ='Quarterly Data'!G219-'Chart Data'!AC19 -> 533191.5 | AR19: =[2]Contributions!B307 -> 45047 | AS19: =[2]Contributions!C307 -> 2.4891086 | AT19: =[2]Contributions!D307 -> -0.45580316 | AU19: =[2]Contributions!E307 -> 1.2467361 | AV19: =AW19-AS19-AT19-AU19 -> 5.4006406 | AW19: =[2]Contributions!G307 -> 8.680682 | AX19: 2 | AZ19: 44927 | BA19: =100*((BL19/BL15)-1) -> 2.1445097 | BB19: =100*((BM19/BM15)-1) -> 3.056263 | BC19: =100*((BN19/BN15)-1) -> 2.027155 | BE19: 44927 | BF19: =BL19-AVERAGE(BL$23:BL$26) -> -451.75 | BG19: =BM19-AVERAGE(BM$23:BM$26) -> -43.25 | BH19: =BN19-AVERAGE(BN$23:BN$26) -> 237.75 | BI19: =SUM(BF19:BH19) -> -257.25 | BK19: 44927 | BL19: ='Quarterly Data'!AH207+'Quarterly Data'!AI207+'Quarterly Data'!AJ207+'Quarterly Data'!AK207+'Quarterly Data'!AL207 -> 11479 | BM19: ='Quarterly Data'!W207+'Quarterly Data'!AD207+'Quarterly Data'!U207+'Quarterly Data'!AC207+'Quarterly Data'!AF207+'Quarterly Data'!X207+'Quarterly Data'!Y207 -> 8902 | BN19: ='Quarterly Data'!AA207+'Quarterly Data'!V207+'Quarterly Data'!AE207+'Quarterly Data'!T207+'Quarterly Data'!AG207+'Quarterly Data'!Z207+'Quarterly Data'!AB207 -> 16156 | BO19: ='Quarterly Data'!S207-'Chart Data'!BL19-'Chart Data'!BM19-'Chart Data'!BN19 -> 0 | BQ19: =BM19+BN19 -> 25058
A20: 1998 | B20: =100*(('Annual Data'!C32-'Annual Data'!C31)/'Annual Data'!$B31) -> 2.3707851 | C20: =100*((I20-I19)/'Annual Data'!$B31) -> 0.78579499 | D20: =100*((J20-J19)/'Annual Data'!$B31) -> 0.87713321 | E20: =100*((K20-K19)/'Annual Data'!$B31) -> -0.89156407 | F20: =G20-B20-C20-D20-E20 -> 0.10416565 | G20: =100*(('Annual Data'!B32/'Annual Data'!B31)-1) -> 3.2463148 | I20: ='Annual Data'!D32-'Annual Data'!I32 -> 265566 | J20: ='Annual Data'!E32+'Annual Data'!I32 -> 374065 | K20: ='Annual Data'!F32-'Annual Data'!G32 -> 37105 | V20: 46113 | W20: Q2 26 | X20: =100*((AC20-AC$6)/'Quarterly Data'!$G$206) -> 2.5335786 | Y20: =100*((AD20-AD$6)/'Quarterly Data'!$G$206) -> 0.71712516 | Z20: =100*(('Quarterly Data'!G220/'Quarterly Data'!$G$206)-1) -> 3.2507037 | AB20: 46113 | AC20: ='Quarterly Data'!J220+'Quarterly Data'!N220 -> 177351.72 | AD20: ='Quarterly Data'!G220-'Chart Data'!AC20 -> 533856.68 | AR20: =[2]Contributions!B308 -> 45078 | AS20: =[2]Contributions!C308 -> 2.3774168 | AT20: =[2]Contributions!D308 -> -0.85163887 | AU20: =[2]Contributions!E308 -> 1.2177235 | AV20: =AW20-AS20-AT20-AU20 -> 5.2061829 | AW20: =[2]Contributions!G308 -> 7.9496843 | AX20: 2 | AZ20: 45017 | BA20: =100*((BL20/BL16)-1) -> 1.4120554 | BB20: =100*((BM20/BM16)-1) -> 2.4672767 | BC20: =100*((BN20/BN16)-1) -> 0.22560632 | BE20: 45017 | BF20: =BL20-AVERAGE(BL$23:BL$26) -> -439.75 | BG20: =BM20-AVERAGE(BM$23:BM$26) -> -99.25 | BH20: =BN20-AVERAGE(BN$23:BN$26) -> 74.75 | BI20: =SUM(BF20:BH20) -> -464.25 | BK20: 45017 | BL20: ='Quarterly Data'!AH208+'Quarterly Data'!AI208+'Quarterly Data'!AJ208+'Quarterly Data'!AK208+'Quarterly Data'!AL208 -> 11491 | BM20: ='Quarterly Data'!W208+'Quarterly Data'!AD208+'Quarterly Data'!U208+'Quarterly Data'!AC208+'Quarterly Data'!AF208+'Quarterly Data'!X208+'Quarterly Data'!Y208 -> 8846 | BN20: ='Quarterly Data'!AA208+'Quarterly Data'!V208+'Quarterly Data'!AE208+'Quarterly Data'!T208+'Quarterly Data'!AG208+'Quarterly Data'!Z208+'Quarterly Data'!AB208 -> 15993 | BO20: ='Quarterly Data'!S208-'Chart Data'!BL20-'Chart Data'!BM20-'Chart Data'!BN20 -> 0 | BQ20: =BM20+BN20 -> 24839
A21: 1999 | B21: =100*(('Annual Data'!C33-'Annual Data'!C32)/'Annual Data'!$B32) -> 2.5122217 | C21: =100*((I21-I20)/'Annual Data'!$B32) -> 0.36712137 | D21: =100*((J21-J20)/'Annual Data'!$B32) -> 0.55686637 | E21: =100*((K21-K20)/'Annual Data'!$B32) -> -0.81666339 | F21: =G21-B21-C21-D21-E21 -> 0.32491267 | G21: =100*(('Annual Data'!B33/'Annual Data'!B32)-1) -> 2.9444587 | I21: ='Annual Data'!D33-'Annual Data'!I33 -> 272185 | J21: ='Annual Data'!E33+'Annual Data'!I33 -> 384105 | K21: ='Annual Data'!F33-'Annual Data'!G33 -> 22381 | V21: 46204 | W21: Q3 26 | X21: =100*((AC21-AC$6)/'Quarterly Data'!$G$206) -> 2.6981129 | Y21: =100*((AD21-AD$6)/'Quarterly Data'!$G$206) -> 0.86717372 | Z21: =100*(('Quarterly Data'!G221/'Quarterly Data'!$G$206)-1) -> 3.5652866 | AB21: 46204 | AC21: ='Quarterly Data'!J221+'Quarterly Data'!N221 -> 178485.06 | AD21: ='Quarterly Data'!G221-'Chart Data'!AC21 -> 534890.24 | AR21: =[2]Contributions!B309 -> 45108 | AS21: =[2]Contributions!C309 -> 2.1219679 | AT21: =[2]Contributions!D309 -> -0.95626278 | AU21: =[2]Contributions!E309 -> 0.45317659 | AV21: =AW21-AS21-AT21-AU21 -> 5.2083325 | AW21: =[2]Contributions!G309 -> 6.8272142 | AX21: 2 | AZ21: 45108 | BA21: =100*((BL21/BL17)-1) -> 2.2357724 | BB21: =100*((BM21/BM17)-1) -> 2.6037429 | BC21: =100*((BN21/BN17)-1) -> -0.29256147 | BE21: 45108 | BF21: =BL21-AVERAGE(BL$23:BL$26) -> -361.75 | BG21: =BM21-AVERAGE(BM$23:BM$26) -> -118.25 | BH21: =BN21-AVERAGE(BN$23:BN$26) -> 99.75 | BI21: =SUM(BF21:BH21) -> -380.25 | BK21: 45108 | BL21: ='Quarterly Data'!AH209+'Quarterly Data'!AI209+'Quarterly Data'!AJ209+'Quarterly Data'!AK209+'Quarterly Data'!AL209 -> 11569 | BM21: ='Quarterly Data'!W209+'Quarterly Data'!AD209+'Quarterly Data'!U209+'Quarterly Data'!AC209+'Quarterly Data'!AF209+'Quarterly Data'!X209+'Quarterly Data'!Y209 -> 8827 | BN21: ='Quarterly Data'!AA209+'Quarterly Data'!V209+'Quarterly Data'!AE209+'Quarterly Data'!T209+'Quarterly Data'!AG209+'Quarterly Data'!Z209+'Quarterly Data'!AB209 -> 16018 | BO21: ='Quarterly Data'!S209-'Chart Data'!BL21-'Chart Data'!BM21-'Chart Data'!BN21 -> 1 | BQ21: =BM21+BN21 -> 24845
A22: 2000 | B22: =100*(('Annual Data'!C34-'Annual Data'!C33)/'Annual Data'!$B33) -> 2.7657375 | C22: =100*((I22-I21)/'Annual Data'!$B33) -> 0.952246 | D22: =100*((J22-J21)/'Annual Data'!$B33) -> 0.68775717 | E22: =100*((K22-K21)/'Annual Data'!$B33) -> 0.27090036 | F22: =G22-B22-C22-D22-E22 -> -0.15226022 | G22: =100*(('Annual Data'!B34/'Annual Data'!B33)-1) -> 4.5243808 | I22: ='Annual Data'!D34-'Annual Data'!I34 -> 289859 | J22: ='Annual Data'!E34+'Annual Data'!I34 -> 396870 | K22: ='Annual Data'!F34-'Annual Data'!G34 -> 27409 | V22: 46296 | W22: Q4 26 | X22: =100*((AC22-AC$6)/'Quarterly Data'!$G$206) -> 2.8570273 | Y22: =100*((AD22-AD$6)/'Quarterly Data'!$G$206) -> 1.044154 | Z22: =100*(('Quarterly Data'!G222/'Quarterly Data'!$G$206)-1) -> 3.9011813 | AB22: 46296 | AC22: ='Quarterly Data'!J222+'Quarterly Data'!N222 -> 179579.69 | AD22: ='Quarterly Data'!G222-'Chart Data'!AC22 -> 536109.31 | AR22: =[2]Contributions!B310 -> 45139 | AS22: =[2]Contributions!C310 -> 2.0333022 | AT22: =[2]Contributions!D310 -> -0.58279347 | AU22: =[2]Contributions!E310 -> 0.48414516 | AV22: =AW22-AS22-AT22-AU22 -> 4.7223767 | AW22: =[2]Contributions!G310 -> 6.6570306 | AX22: 2 | AZ22: 45200 | BA22: =100*((BL22/BL18)-1) -> 2.8553803 | BB22: =100*((BM22/BM18)-1) -> 0.8470696 | BC22: =100*((BN22/BN18)-1) -> -0.45347248 | BE22: 45200 | BF22: =BL22-AVERAGE(BL$23:BL$26) -> -259.75 | BG22: =BM22-AVERAGE(BM$23:BM$26) -> -135.25 | BH22: =BN22-AVERAGE(BN$23:BN$26) -> 106.75 | BI22: =SUM(BF22:BH22) -> -288.25 | BK22: 45200 | BL22: ='Quarterly Data'!AH210+'Quarterly Data'!AI210+'Quarterly Data'!AJ210+'Quarterly Data'!AK210+'Quarterly Data'!AL210 -> 11671 | BM22: ='Quarterly Data'!W210+'Quarterly Data'!AD210+'Quarterly Data'!U210+'Quarterly Data'!AC210+'Quarterly Data'!AF210+'Quarterly Data'!X210+'Quarterly Data'!Y210 -> 8810 | BN22: ='Quarterly Data'!AA210+'Quarterly Data'!V210+'Quarterly Data'!AE210+'Quarterly Data'!T210+'Quarterly Data'!AG210+'Quarterly Data'!Z210+'Quarterly Data'!AB210 -> 16025 | BO22: ='Quarterly Data'!S210-'Chart Data'!BL22-'Chart Data'!BM22-'Chart Data'!BN22 -> -3 | BQ22: =BM22+BN22 -> 24835
A23: 2001 | B23: =100*(('Annual Data'!C35-'Annual Data'!C34)/'Annual Data'!$B34) -> 1.9862815 | C23: =100*((I23-I22)/'Annual Data'!$B34) -> 0.091133692 | D23: =100*((J23-J22)/'Annual Data'!$B34) -> 1.2701501 | E23: =100*((K23-K22)/'Annual Data'!$B34) -> -0.88927514 | F23: =G23-B23-C23-D23-E23 -> -0.067267799 | G23: =100*(('Annual Data'!B35/'Annual Data'!B34)-1) -> 2.3910223 | I23: ='Annual Data'!D35-'Annual Data'!I35 -> 291627 | J23: ='Annual Data'!E35+'Annual Data'!I35 -> 421511 | K23: ='Annual Data'!F35-'Annual Data'!G35 -> 10157 | AR23: =[2]Contributions!B311 -> 45170 | AS23: =[2]Contributions!C311 -> 1.8973456 | AT23: =[2]Contributions!D311 -> -0.32853829 | AU23: =[2]Contributions!E311 -> 0.46832106 | AV23: =AW23-AS23-AT23-AU23 -> 4.6150483 | AW23: =[2]Contributions!G311 -> 6.6521767 | AX23: 2 | AZ23: 45292 | BA23: =100*((BL23/BL19)-1) -> 3.7895287 | BB23: =100*((BM23/BM19)-1) -> 0.033700292 | BC23: =100*((BN23/BN19)-1) -> -1.1450854 | BE23: 45292 | BF23: =BL23-AVERAGE(BL$23:BL$26) -> -16.75 | BG23: =BM23-AVERAGE(BM$23:BM$26) -> -40.25 | BH23: =BN23-AVERAGE(BN$23:BN$26) -> 52.75 | BI23: =SUM(BF23:BH23) -> -4.25 | BK23: 45292 | BL23: ='Quarterly Data'!AH211+'Quarterly Data'!AI211+'Quarterly Data'!AJ211+'Quarterly Data'!AK211+'Quarterly Data'!AL211 -> 11914 | BM23: ='Quarterly Data'!W211+'Quarterly Data'!AD211+'Quarterly Data'!U211+'Quarterly Data'!AC211+'Quarterly Data'!AF211+'Quarterly Data'!X211+'Quarterly Data'!Y211 -> 8905 | BN23: ='Quarterly Data'!AA211+'Quarterly Data'!V211+'Quarterly Data'!AE211+'Quarterly Data'!T211+'Quarterly Data'!AG211+'Quarterly Data'!Z211+'Quarterly Data'!AB211 -> 15971 | BO23: ='Quarterly Data'!S211-'Chart Data'!BL23-'Chart Data'!BM23-'Chart Data'!BN23 -> -1 | BQ23: =BM23+BN23 -> 24876
A24: 2002 | B24: =100*(('Annual Data'!C36-'Annual Data'!C35)/'Annual Data'!$B35) -> 1.6153903 | C24: =100*((I24-I23)/'Annual Data'!$B35) -> 0.14387888 | D24: =100*((J24-J23)/'Annual Data'!$B35) -> 0.84691197 | E24: =100*((K24-K23)/'Annual Data'!$B35) -> -0.92665449 | F24: =G24-B24-C24-D24-E24 -> 0.029500708 | G24: =100*(('Annual Data'!B36/'Annual Data'!B35)-1) -> 1.7090274 | I24: ='Annual Data'!D36-'Annual Data'!I36 -> 294485 | J24: ='Annual Data'!E36+'Annual Data'!I36 -> 438334 | K24: ='Annual Data'!F36-'Annual Data'!G36 -> -8250 | AC24: =AC17/'Quarterly Data'!G217 -> 0.24715535 | AR24: =[2]Contributions!B312 -> 45200 | AS24: =[2]Contributions!C312 -> 1.639459 | AT24: =[2]Contributions!D312 -> -0.25121814 | AU24: =[2]Contributions!E312 -> -1.0539877 | AV24: =AW24-AS24-AT24-AU24 -> 4.2656248 | AW24: =[2]Contributions!G312 -> 4.599878 | AX24: 2 | AZ24: 45383 | BA24: =100*((BL24/BL20)-1) -> 3.8812984 | BB24: =100*((BM24/BM20)-1) -> 0.1017409 | BC24: =100*((BN24/BN20)-1) -> -0.46270243 | BE24: 45383 | BF24: =BL24-AVERAGE(BL$23:BL$26) -> 6.25 | BG24: =BM24-AVERAGE(BM$23:BM$26) -> -90.25 | BH24: =BN24-AVERAGE(BN$23:BN$26) -> 0.75 | BI24: =SUM(BF24:BH24) -> -83.25 | BK24: 45383 | BL24: ='Quarterly Data'!AH212+'Quarterly Data'!AI212+'Quarterly Data'!AJ212+'Quarterly Data'!AK212+'Quarterly Data'!AL212 -> 11937 | BM24: ='Quarterly Data'!W212+'Quarterly Data'!AD212+'Quarterly Data'!U212+'Quarterly Data'!AC212+'Quarterly Data'!AF212+'Quarterly Data'!X212+'Quarterly Data'!Y212 -> 8855 | BN24: ='Quarterly Data'!AA212+'Quarterly Data'!V212+'Quarterly Data'!AE212+'Quarterly Data'!T212+'Quarterly Data'!AG212+'Quarterly Data'!Z212+'Quarterly Data'!AB212 -> 15919 | BO24: ='Quarterly Data'!S212-'Chart Data'!BL24-'Chart Data'!BM24-'Chart Data'!BN24 -> -1 | BQ24: =BM24+BN24 -> 24774
A25: 2003 | B25: =100*(('Annual Data'!C37-'Annual Data'!C36)/'Annual Data'!$B36) -> 2.0667303 | C25: =100*((I25-I24)/'Annual Data'!$B36) -> 0.15532031 | D25: =100*((J25-J24)/'Annual Data'!$B36) -> 1.0731852 | E25: =100*((K25-K24)/'Annual Data'!$B36) -> -0.01628438 | F25: =G25-B25-C25-D25-E25 -> -0.060435342 | G25: =100*(('Annual Data'!B37/'Annual Data'!B36)-1) -> 3.2185161 | I25: ='Annual Data'!D37-'Annual Data'!I37 -> 297623 | J25: ='Annual Data'!E37+'Annual Data'!I37 -> 460016 | K25: ='Annual Data'!F37-'Annual Data'!G37 -> -8579 | AR25: =[2]Contributions!B313 -> 45231 | AS25: =[2]Contributions!C313 -> 1.5053144 | AT25: =[2]Contributions!D313 -> -0.35236691 | AU25: =[2]Contributions!E313 -> -1.0437809 | AV25: =AW25-AS25-AT25-AU25 -> 3.8318251 | AW25: =[2]Contributions!G313 -> 3.9409917 | AX25: 2 | AZ25: 45474 | BA25: =100*((BL25/BL21)-1) -> 2.9043133 | BB25: =100*((BM25/BM21)-1) -> 1.8805936 | BC25: =100*((BN25/BN21)-1) -> -0.92396054 | BE25: 45474 | BF25: =BL25-AVERAGE(BL$23:BL$26) -> -25.75 | BG25: =BM25-AVERAGE(BM$23:BM$26) -> 47.75 | BH25: =BN25-AVERAGE(BN$23:BN$26) -> -48.25 | BI25: =SUM(BF25:BH25) -> -26.25 | BK25: 45474 | BL25: ='Quarterly Data'!AH213+'Quarterly Data'!AI213+'Quarterly Data'!AJ213+'Quarterly Data'!AK213+'Quarterly Data'!AL213 -> 11905 | BM25: ='Quarterly Data'!W213+'Quarterly Data'!AD213+'Quarterly Data'!U213+'Quarterly Data'!AC213+'Quarterly Data'!AF213+'Quarterly Data'!X213+'Quarterly Data'!Y213 -> 8993 | BN25: ='Quarterly Data'!AA213+'Quarterly Data'!V213+'Quarterly Data'!AE213+'Quarterly Data'!T213+'Quarterly Data'!AG213+'Quarterly Data'!Z213+'Quarterly Data'!AB213 -> 15870 | BO25: ='Quarterly Data'!S213-'Chart Data'!BL25-'Chart Data'!BM25-'Chart Data'!BN25 -> -2 | BQ25: =BM25+BN25 -> 24863
A26: 2004 | B26: =100*(('Annual Data'!C38-'Annual Data'!C37)/'Annual Data'!$B37) -> 1.6888163 | C26: =100*((I26-I25)/'Annual Data'!$B37) -> -0.050878359 | D26: =100*((J26-J25)/'Annual Data'!$B37) -> 1.3038958 | E26: =100*((K26-K25)/'Annual Data'!$B37) -> -0.59030405 | F26: =G26-B26-C26-D26-E26 -> -0.025511109 | G26: =100*(('Annual Data'!B38/'Annual Data'!B37)-1) -> 2.3260186 | I26: ='Annual Data'!D38-'Annual Data'!I38 -> 296562 | J26: ='Annual Data'!E38+'Annual Data'!I38 -> 487207 | K26: ='Annual Data'!F38-'Annual Data'!G38 -> -20889 | AR26: =[2]Contributions!B314 -> 45261 | AS26: =[2]Contributions!C314 -> 1.4800743 | AT26: =[2]Contributions!D314 -> -0.34448789 | AU26: =[2]Contributions!E314 -> -1.030636 | AV26: =AW26-AS26-AT26-AU26 -> 3.8883181 | AW26: =[2]Contributions!G314 -> 3.9932685 | AX26: 2 | AZ26: 45566 | BA26: =100*((BL26/BL22)-1) -> 2.5362008 | BB26: =100*((BM26/BM22)-1) -> 2.4744608 | BC26: =100*((BN26/BN22)-1) -> -0.69890796 | BE26: 45566 | BF26: =BL26-AVERAGE(BL$23:BL$26) -> 36.25 | BG26: =BM26-AVERAGE(BM$23:BM$26) -> 82.75 | BH26: =BN26-AVERAGE(BN$23:BN$26) -> -5.25 | BI26: =SUM(BF26:BH26) -> 113.75 | BK26: 45566 | BL26: ='Quarterly Data'!AH214+'Quarterly Data'!AI214+'Quarterly Data'!AJ214+'Quarterly Data'!AK214+'Quarterly Data'!AL214 -> 11967 | BM26: ='Quarterly Data'!W214+'Quarterly Data'!AD214+'Quarterly Data'!U214+'Quarterly Data'!AC214+'Quarterly Data'!AF214+'Quarterly Data'!X214+'Quarterly Data'!Y214 -> 9028 | BN26: ='Quarterly Data'!AA214+'Quarterly Data'!V214+'Quarterly Data'!AE214+'Quarterly Data'!T214+'Quarterly Data'!AG214+'Quarterly Data'!Z214+'Quarterly Data'!AB214 -> 15913 | BO26: ='Quarterly Data'!S214-'Chart Data'!BL26-'Chart Data'!BM26-'Chart Data'!BN26 -> -2 | BQ26: =BM26+BN26 -> 24941
A27: 2005 | B27: =100*(('Annual Data'!C39-'Annual Data'!C38)/'Annual Data'!$B38) -> 1.6400234 | C27: =100*((I27-I26)/'Annual Data'!$B38) -> 1.1316752 | D27: =100*((J27-J26)/'Annual Data'!$B38) -> 0.61355601 | E27: =100*((K27-K26)/'Annual Data'!$B38) -> -0.027789858 | F27: =G27-B27-C27-D27-E27 -> -0.56681001 | G27: =100*(('Annual Data'!B39/'Annual Data'!B38)-1) -> 2.7906547 | I27: ='Annual Data'!D39-'Annual Data'!I39 -> 320710.5 | J27: ='Annual Data'!E39+'Annual Data'!I39 -> 500299.5 | K27: ='Annual Data'!F39-'Annual Data'!G39 -> -21482 | AR27: =[2]Contributions!B315 -> 45292 | AS27: =[2]Contributions!C315 -> 1.3226708 | AT27: =[2]Contributions!D315 -> -0.29421019 | AU27: =[2]Contributions!E315 -> -0.88012568 | AV27: =AW27-AS27-AT27-AU27 -> 3.8327797 | AW27: =[2]Contributions!G315 -> 3.9811146 | AX27: 2 | AZ27: 45658 | BA27: =100*((BL27/BL23)-1) -> 2.1487326 | BB27: =100*((BM27/BM23)-1) -> 0.68500842 | BC27: =100*((BN27/BN23)-1) -> -0.48212385 | BE27: 45658 | BF27: =BL27-AVERAGE(BL$23:BL$26) -> 239.25 | BG27: =BM27-AVERAGE(BM$23:BM$26) -> 20.75 | BH27: =BN27-AVERAGE(BN$23:BN$26) -> -24.25 | BI27: =SUM(BF27:BH27) -> 235.75 | BK27: 45658 | BL27: ='Quarterly Data'!AH215+'Quarterly Data'!AI215+'Quarterly Data'!AJ215+'Quarterly Data'!AK215+'Quarterly Data'!AL215 -> 12170 | BM27: ='Quarterly Data'!W215+'Quarterly Data'!AD215+'Quarterly Data'!U215+'Quarterly Data'!AC215+'Quarterly Data'!AF215+'Quarterly Data'!X215+'Quarterly Data'!Y215 -> 8966 | BN27: ='Quarterly Data'!AA215+'Quarterly Data'!V215+'Quarterly Data'!AE215+'Quarterly Data'!T215+'Quarterly Data'!AG215+'Quarterly Data'!Z215+'Quarterly Data'!AB215 -> 15894 | BO27: ='Quarterly Data'!S215-'Chart Data'!BL27-'Chart Data'!BM27-'Chart Data'!BN27 -> 0 | BQ27: =BM27+BN27 -> 24860
A28: 2006 | B28: =100*(('Annual Data'!C40-'Annual Data'!C39)/'Annual Data'!$B39) -> 0.4870474 | C28: =100*((I28-I27)/'Annual Data'!$B39) -> 0.61650271 | D28: =100*((J28-J27)/'Annual Data'!$B39) -> 0.1555333 | E28: =100*((K28-K27)/'Annual Data'!$B39) -> 0.35401321 | F28: =G28-B28-C28-D28-E28 -> 0.57672467 | G28: =100*(('Annual Data'!B40/'Annual Data'!B39)-1) -> 2.1898213 | I28: ='Annual Data'!D40-'Annual Data'!I40 -> 334233 | J28: ='Annual Data'!E40+'Annual Data'!I40 -> 503711 | K28: ='Annual Data'!F40-'Annual Data'!G40 -> -13717 | AR28: =[2]Contributions!B316 -> 45323 | AS28: =[2]Contributions!C316 -> 1.0836049 | AT28: =[2]Contributions!D316 -> -0.18987115 | AU28: =[2]Contributions!E316 -> -0.87917176 | AV28: =AW28-AS28-AT28-AU28 -> 3.3969102 | AW28: =[2]Contributions!G316 -> 3.4114722 | AX28: 2 | AZ28: 45748 | BA28: =100*((BL28/BL24)-1) -> 1.5330485 | BB28: =100*((BM28/BM24)-1) -> 0.32749859 | BC28: =100*((BN28/BN24)-1) -> -0.47113512 | BE28: 45748 | BF28: =BL28-AVERAGE(BL$23:BL$26) -> 189.25 | BG28: =BM28-AVERAGE(BM$23:BM$26) -> -61.25 | BH28: =BN28-AVERAGE(BN$23:BN$26) -> -74.25 | BI28: =SUM(BF28:BH28) -> 53.75 | BK28: 45748 | BL28: ='Quarterly Data'!AH216+'Quarterly Data'!AI216+'Quarterly Data'!AJ216+'Quarterly Data'!AK216+'Quarterly Data'!AL216 -> 12120 | BM28: ='Quarterly Data'!W216+'Quarterly Data'!AD216+'Quarterly Data'!U216+'Quarterly Data'!AC216+'Quarterly Data'!AF216+'Quarterly Data'!X216+'Quarterly Data'!Y216 -> 8884 | BN28: ='Quarterly Data'!AA216+'Quarterly Data'!V216+'Quarterly Data'!AE216+'Quarterly Data'!T216+'Quarterly Data'!AG216+'Quarterly Data'!Z216+'Quarterly Data'!AB216 -> 15844 | BO28: ='Quarterly Data'!S216-'Chart Data'!BL28-'Chart Data'!BM28-'Chart Data'!BN28 -> 0 | BQ28: =BM28+BN28 -> 24728
A29: 2007 | B29: =100*(('Annual Data'!C41-'Annual Data'!C40)/'Annual Data'!$B40) -> 2.1543615 | C29: =100*((I29-I28)/'Annual Data'!$B40) -> 0.82482211 | D29: =100*((J29-J28)/'Annual Data'!$B40) -> 0.40143603 | E29: =100*((K29-K28)/'Annual Data'!$B40) -> -0.13352946 | F29: =G29-B29-C29-D29-E29 -> -0.31617884 | G29: =100*(('Annual Data'!B41/'Annual Data'!B40)-1) -> 2.9309113 | I29: ='Annual Data'!D41-'Annual Data'!I41 -> 352721 | J29: ='Annual Data'!E41+'Annual Data'!I41 -> 512709 | K29: ='Annual Data'!F41-'Annual Data'!G41 -> -16710 | AR29: =[2]Contributions!B317 -> 45352 | AS29: =[2]Contributions!C317 -> 0.97087291 | AT29: =[2]Contributions!D317 -> -0.094867963 | AU29: =[2]Contributions!E317 -> -0.87097105 | AV29: =AW29-AS29-AT29-AU29 -> 3.2230254 | AW29: =[2]Contributions!G317 -> 3.2280593 | AX29: 2 | AZ29: 45839 | BA29: =100*((BL29/BL25)-1) -> 2.2435111 | BB29: =100*((BM29/BM25)-1) -> -0.73713333 | BC29: =100*((BN29/BN25)-1) -> -0.28030057 | BE29: 45839 | BF29: =BL29-AVERAGE(BL$23:BL$26) -> 241.34 | BG29: =BM29-AVERAGE(BM$23:BM$26) -> -18.5404 | BH29: =BN29-AVERAGE(BN$23:BN$26) -> -92.7337 | BI29: =SUM(BF29:BH29) -> 130.0659 | BK29: 45839 | BL29: ='Quarterly Data'!AH217+'Quarterly Data'!AI217+'Quarterly Data'!AJ217+'Quarterly Data'!AK217+'Quarterly Data'!AL217 -> 12172.09 | BM29: ='Quarterly Data'!W217+'Quarterly Data'!AD217+'Quarterly Data'!U217+'Quarterly Data'!AC217+'Quarterly Data'!AF217+'Quarterly Data'!X217+'Quarterly Data'!Y217 -> 8926.7096 | BN29: ='Quarterly Data'!AA217+'Quarterly Data'!V217+'Quarterly Data'!AE217+'Quarterly Data'!T217+'Quarterly Data'!AG217+'Quarterly Data'!Z217+'Quarterly Data'!AB217 -> 15825.516 | BO29: ='Quarterly Data'!S217-'Chart Data'!BL29-'Chart Data'!BM29-'Chart Data'!BN29 -> 0.0041 | BQ29: =BM29+BN29 -> 24752.226
