Workbook
Name Data: [1]sheet0!$C$2

Sheet Chart Data
A1: Annualised growth in 2025 | J1: Budget deficit in 2025 | S1: Gross government debt in 2025
B2: UK | C2: US | D2: Japan | E2: Germany | F2: France | G2: Italy | H2: Canada | K2: =RANK(K4,$K$4:$Q$4) -> 5 | L2: =RANK(L4,$K$4:$Q$4) -> 7 | M2: =RANK(M4,$K$4:$Q$4) -> 3 | N2: =RANK(N4,$K$4:$Q$4) -> 2 | O2: =RANK(O4,$K$4:$Q$4) -> 6 | P2: =RANK(P4,$K$4:$Q$4) -> 4 | Q2: =RANK(Q4,$K$4:$Q$4) -> 1 | T2: =RANK(T4,$T$4:$Z$4) -> 6 | U2: =RANK(U4,$T$4:$Z$4) -> 3 | V2: =RANK(V4,$T$4:$Z$4) -> 1 | W2: =RANK(W4,$T$4:$Z$4) -> 7 | X2: =RANK(X4,$T$4:$Z$4) -> 4 | Y2: =RANK(Y4,$T$4:$Z$4) -> 2 | Z2: =RANK(Z4,$T$4:$Z$4) -> 5
A3: H1 2025 | B3: =100*((B7/B6)^2-1) -> 1.925908 | C3: =100*((C7/C6)^2-1) -> 1.1703616 | D3: =100*((D7/D6)^2-1) -> 1.1324058 | E3: =100*((E7/E6)^2-1) -> 0.51810504 | F3: =100*((F7/F6)^2-1) -> 0.50566345 | G3: =100*((G7/G6)^2-1) -> 0.74627187 | H3: =100*((H7/H6)^2-1) -> 1.12204 | K3: UK | L3: US | M3: Japan | N3: Germany | O3: France | P3: Italy | Q3: Canada | T3: UK | U3: US | V3: Japan | W3: Germany | X3: France | Y3: Italy | Z3: Canada
A4: H2 2025 | B4: =100*((B8/B7)^2-1) -> 0.64216098 | C4: =100*((C8/C7)^2-1) -> 2.3462452 | D4: =100*((D8/D7)^2-1) -> -0.020202818 | E4: =100*((E8/E7)^2-1) -> -0.092323007 | F4: =100*((F8/F7)^2-1) -> 0.51507841 | G4: =100*((G8/G7)^2-1) -> 0.3049117 | H4: =100*((H8/H7)^2-1) -> -0.24697282 | J4: 2025 | K4: =100*(DataA!I60/DataA!W60) -> -4.5090271 | L4: =100*(DataA!J60/DataA!X60) -> -7.0961317 | M4: =100*(DataA!K60/DataA!Y60) -> -2.9490875 | N4: =100*(DataA!L60/DataA!Z60) -> -2.0656985 | O4: =100*(DataA!M60/DataA!AA60) -> -5.3818188 | P4: =100*(DataA!N60/DataA!AB60) -> -3.0009128 | Q4: =100*(DataA!O60/DataA!AC60) -> -1.5627124 | S4: 2025 | T4: =100*(DataA!P60/DataA!W60) -> 102.50331 | U4: =100*(DataA!Q60/DataA!X60) -> 139.37292 | V4: =100*(DataA!R60/DataA!Y60) -> 217.09153 | W4: =100*(DataA!S60/DataA!Z60) -> 58.229624 | X4: =100*(DataA!T60/DataA!AA60) -> 127.49831 | Y4: =100*(DataA!U60/DataA!AB60) -> 150.0575 | Z4: =100*(DataA!V60/DataA!AC60) -> 107.07335
A6: H2 2024 | B6: =SUM(DataQ!G213:G214) -> 1283962 | C6: =SUM(DataQ!H213:H214) -> 11735.65 | D6: =SUM(DataQ!I213:I214) -> 279556.3 | E6: =SUM(DataQ!J213:J214) -> 1801.19 | F6: =SUM(DataQ!K213:K214) -> 1309.636 | G6: =SUM(DataQ!L213:L214) -> 966.861 | H6: =SUM(DataQ!M213:M214) -> 1218310.6
A7: H1 2025 | B7: =SUM(DataQ!G215:G216) -> 1296267 | C7: =SUM(DataQ!H215:H216) -> 11804.125 | D7: =SUM(DataQ!I215:I216) -> 281134.7 | E7: =SUM(DataQ!J215:J216) -> 1805.85 | F7: =SUM(DataQ!K215:K216) -> 1312.943 | G7: =SUM(DataQ!L215:L216) -> 970.462 | H7: =SUM(DataQ!M215:M216) -> 1225126.5
A8: H2 2025 | B8: =SUM(DataQ!G217:G218) -> 1300422.4 | C8: =SUM(DataQ!H217:H218) -> 11941.799 | D8: =SUM(DataQ!I217:I218) -> 281106.3 | E8: =SUM(DataQ!J217:J218) -> 1805.0162 | F8: =SUM(DataQ!K217:K218) -> 1316.32 | G8: =SUM(DataQ!L217:L218) -> 971.9404 | H8: =SUM(DataQ!M217:M218) -> 1223612.7

Sheet DataA
B1: CY total | P1: CY end | W1: CY total
B2: =DataQ!G1 -> SEP008W.db | C2: =DataQ!H1 -> SEP008W.db | D2: =DataQ!I1 -> SEP008W.db | E2: =DataQ!J1 -> SEP008W.db | F2: =DataQ!K1 -> SEP008W.db | G2: =DataQ!L1 -> SEP008W.db | H2: =DataQ!M1 -> SEP008W.db | I2: =DataQ!N1 -> SEP008W.db | ... AC2: =DataQ!AH1 -> SEP008W.db
B3: =DataQ!G2 -> UK | C3: =DataQ!H2 -> US | D3: =DataQ!I2 -> Japan | E3: =DataQ!J2 -> Germany | F3: =DataQ!K2 -> France | G3: =DataQ!L2 -> Italy | H3: =DataQ!M2 -> Canada | I3: =DataQ!N2 -> UK | ... AC3: =DataQ!AH2 -> Canada
B4: =DataQ!G3 -> GDP | C4: =DataQ!H3 -> GDP | D4: =DataQ!I3 -> GDP | E4: =DataQ!J3 -> GDP | F4: =DataQ!K3 -> GDP | G4: =DataQ!L3 -> GDP | H4: =DataQ!M3 -> GDP | I4: =DataQ!N3 -> GB | ... AC4: =DataQ!AH3 -> GDP!
B5: =DataQ!G4 -> GBR | C5: =DataQ!H4 -> USA | D5: =DataQ!I4 -> JPN | E5: =DataQ!J4 -> DEU | F5: =DataQ!K4 -> FRA | G5: =DataQ!L4 -> ITA | H5: =DataQ!M4 -> CAN | I5: =DataQ!N4 -> GBR | ... AC5: =DataQ!AH4 -> CAN
B6: =DataQ!G5 -> L | C6: =DataQ!H5 -> L | D6: =DataQ!I5 -> L | E6: =DataQ!J5 -> L | F6: =DataQ!K5 -> L | G6: =DataQ!L5 -> L | H6: =DataQ!M5 -> L | I6: =DataQ!N5 -> L | ... AC6: =DataQ!AH5 -> L
B7: =DataQ!G6 -> 202502 | C7: =DataQ!H6 -> 202502 | D7: =DataQ!I6 -> 202502 | E7: =DataQ!J6 -> 202502 | F7: =DataQ!K6 -> 202502 | G7: =DataQ!L6 -> 202502 | H7: =DataQ!M6 -> 202502 | I7: =DataQ!N6 -> 202502 | ... AC7: =DataQ!AH6 -> 202502
A8: 1973 | B8: =SUMIF(DataQ!$B:$B,DataA!$A8,DataQ!G:G) -> 987527 | C8: =SUMIF(DataQ!$B:$B,DataA!$A8,DataQ!H:H) -> 6106.35 | D8: =SUMIF(DataQ!$B:$B,DataA!$A8,DataQ!I:I) -> 211380.51 | E8: =SUMIF(DataQ!$B:$B,DataA!$A8,DataQ!J:J) -> 1556.14 | F8: =SUMIF(DataQ!$B:$B,DataA!$A8,DataQ!K:K) -> 999.15 | G8: =SUMIF(DataQ!$B:$B,DataA!$A8,DataQ!L:L) -> 932.5699 | H8: =SUMIF(DataQ!$B:$B,DataA!$A8,DataQ!M:M) -> 707164.6 | I8: =SUMIF(DataQ!$B:$B,DataA!$A8,DataQ!N:N) -> -2740 | J8: =SUMIF(DataQ!$B:$B,DataA!$A8,DataQ!O:O) -> -44.59125 | K8: =SUMIF(DataQ!$B:$B,DataA!$A8,DataQ!P:P) -> -2130.75 | L8: =SUMIF(DataQ!$B:$B,DataA!$A8,DataQ!Q:Q) -> -23.045528 | M8: =SUMIF(DataQ!$B:$B,DataA!$A8,DataQ!R:R) -> 0.8040001 | N8: =SUMIF(DataQ!$B:$B,DataA!$A8,DataQ!S:S) -> -3.2833435 | O8: =SUMIF(DataQ!$B:$B,DataA!$A8,DataQ!T:T) -> 1605 | P8: =SUMIF(DataQ!$E:$E,DataA!$A8,DataQ!U:U) -> 35969.43 | Q8: =SUMIF(DataQ!$E:$E,DataA!$A8,DataQ!V:V) -> 1158.847 | R8: =SUMIF(DataQ!$E:$E,DataA!$A8,DataQ!W:W) -> 17803 | S8: =SUMIF(DataQ!$E:$E,DataA!$A8,DataQ!X:X) -> 89.06523 | T8: =SUMIF(DataQ!$E:$E,DataA!$A8,DataQ!Y:Y) -> 56.7663 | U8: =SUMIF(DataQ!$E:$E,DataA!$A8,DataQ!Z:Z) -> 36.414 | V8: =SUMIF(DataQ!$E:$E,DataA!$A8,DataQ!AA:AA) -> 64923 | W8: =SUMIF(DataQ!$B:$B,DataA!$A8,DataQ!AB:AB) -> 81793 | X8: =SUMIF(DataQ!$B:$B,DataA!$A8,DataQ!AC:AC) -> 1425.375 | Y8: =SUMIF(DataQ!$B:$B,DataA!$A8,DataQ!AD:AD) -> 115345.45 | Z8: =SUMIF(DataQ!$B:$B,DataA!$A8,DataQ!AE:AE) -> 553.1868 | AA8: =SUMIF(DataQ!$B:$B,DataA!$A8,DataQ!AF:AF) -> 177.825 | AB8: =SUMIF(DataQ!$B:$B,DataA!$A8,DataQ!AG:AG) -> 53.293 | AC8: =SUMIF(DataQ!$B:$B,DataA!$A8,DataQ!AH:AH) -> 132966
A9: 1974 | B9: =SUMIF(DataQ!$B:$B,DataA!$A9,DataQ!G:G) -> 962880 | C9: =SUMIF(DataQ!$B:$B,DataA!$A9,DataQ!H:H) -> 6073.4 | D9: =SUMIF(DataQ!$B:$B,DataA!$A9,DataQ!I:I) -> 209230.97 | E9: =SUMIF(DataQ!$B:$B,DataA!$A9,DataQ!J:J) -> 1571.34 | F9: =SUMIF(DataQ!$B:$B,DataA!$A9,DataQ!K:K) -> 1043.039 | G9: =SUMIF(DataQ!$B:$B,DataA!$A9,DataQ!L:L) -> 981.7783 | H9: =SUMIF(DataQ!$B:$B,DataA!$A9,DataQ!M:M) -> 730909.6 | I9: =SUMIF(DataQ!$B:$B,DataA!$A9,DataQ!N:N) -> -4310 | J9: =SUMIF(DataQ!$B:$B,DataA!$A9,DataQ!O:O) -> -59.765 | K9: =SUMIF(DataQ!$B:$B,DataA!$A9,DataQ!P:P) -> -2482.25 | L9: =SUMIF(DataQ!$B:$B,DataA!$A9,DataQ!Q:Q) -> -36.381582 | M9: =SUMIF(DataQ!$B:$B,DataA!$A9,DataQ!R:R) -> 0.4830001 | N9: =SUMIF(DataQ!$B:$B,DataA!$A9,DataQ!S:S) -> -4.0740696 | O9: =SUMIF(DataQ!$B:$B,DataA!$A9,DataQ!T:T) -> 3052 | P9: =SUMIF(DataQ!$E:$E,DataA!$A9,DataQ!U:U) -> 48829.88 | Q9: =SUMIF(DataQ!$E:$E,DataA!$A9,DataQ!V:V) -> 1251.709 | R9: =SUMIF(DataQ!$E:$E,DataA!$A9,DataQ!W:W) -> 16534 | S9: =SUMIF(DataQ!$E:$E,DataA!$A9,DataQ!X:X) -> 106.168 | T9: =SUMIF(DataQ!$E:$E,DataA!$A9,DataQ!Y:Y) -> 61.89546 | U9: =SUMIF(DataQ!$E:$E,DataA!$A9,DataQ!Z:Z) -> 45.795 | V9: =SUMIF(DataQ!$E:$E,DataA!$A9,DataQ!AA:AA) -> 74036 | W9: =SUMIF(DataQ!$B:$B,DataA!$A9,DataQ!AB:AB) -> 92673 | X9: =SUMIF(DataQ!$B:$B,DataA!$A9,DataQ!AC:AC) -> 1545.25 | Y9: =SUMIF(DataQ!$B:$B,DataA!$A9,DataQ!AD:AD) -> 137675.47 | Z9: =SUMIF(DataQ!$B:$B,DataA!$A9,DataQ!AE:AE) -> 599.3288 | AA9: =SUMIF(DataQ!$B:$B,DataA!$A9,DataQ!AF:AF) -> 207.305 | AB9: =SUMIF(DataQ!$B:$B,DataA!$A9,DataQ!AG:AG) -> 67.409 | AC9: =SUMIF(DataQ!$B:$B,DataA!$A9,DataQ!AH:AH) -> 158176
A10: 1975 | B10: =SUMIF(DataQ!$B:$B,DataA!$A10,DataQ!G:G) -> 948361 | C10: =SUMIF(DataQ!$B:$B,DataA!$A10,DataQ!H:H) -> 6060.85 | D10: =SUMIF(DataQ!$B:$B,DataA!$A10,DataQ!I:I) -> 215781.13 | E10: =SUMIF(DataQ!$B:$B,DataA!$A10,DataQ!J:J) -> 1557.62 | F10: =SUMIF(DataQ!$B:$B,DataA!$A10,DataQ!K:K) -> 1033.444 | G10: =SUMIF(DataQ!$B:$B,DataA!$A10,DataQ!L:L) -> 961.6561 | H10: =SUMIF(DataQ!$B:$B,DataA!$A10,DataQ!M:M) -> 742205.1 | I10: =SUMIF(DataQ!$B:$B,DataA!$A10,DataQ!N:N) -> -7211 | J10: =SUMIF(DataQ!$B:$B,DataA!$A10,DataQ!O:O) -> -128.606 | K10: =SUMIF(DataQ!$B:$B,DataA!$A10,DataQ!P:P) -> -7342 | L10: =SUMIF(DataQ!$B:$B,DataA!$A10,DataQ!Q:Q) -> -62.44885 | M10: =SUMIF(DataQ!$B:$B,DataA!$A10,DataQ!R:R) -> -4.3009993 | N10: =SUMIF(DataQ!$B:$B,DataA!$A10,DataQ!S:S) -> -7.734278 | O10: =SUMIF(DataQ!$B:$B,DataA!$A10,DataQ!T:T) -> -4505 | P10: =SUMIF(DataQ!$E:$E,DataA!$A10,DataQ!U:U) -> 62646 | Q10: =SUMIF(DataQ!$E:$E,DataA!$A10,DataQ!V:V) -> 1412.028 | R10: =SUMIF(DataQ!$E:$E,DataA!$A10,DataQ!W:W) -> 29223 | S10: =SUMIF(DataQ!$E:$E,DataA!$A10,DataQ!X:X) -> 136.7461 | T10: =SUMIF(DataQ!$E:$E,DataA!$A10,DataQ!Y:Y) -> 70.28793 | U10: =SUMIF(DataQ!$E:$E,DataA!$A10,DataQ!Z:Z) -> 61.44 | V10: =SUMIF(DataQ!$E:$E,DataA!$A10,DataQ!AA:AA) -> 82299 | W10: =SUMIF(DataQ!$B:$B,DataA!$A10,DataQ!AB:AB) -> 115093 | X10: =SUMIF(DataQ!$B:$B,DataA!$A10,DataQ!AC:AC) -> 1684.9 | Y10: =SUMIF(DataQ!$B:$B,DataA!$A10,DataQ!AD:AD) -> 152524.06 | Z10: =SUMIF(DataQ!$B:$B,DataA!$A10,DataQ!AE:AE) -> 627.6409 | AA10: =SUMIF(DataQ!$B:$B,DataA!$A10,DataQ!AF:AF) -> 233.583 | AB10: =SUMIF(DataQ!$B:$B,DataA!$A10,DataQ!AG:AG) -> 76.902 | AC10: =SUMIF(DataQ!$B:$B,DataA!$A10,DataQ!AH:AH) -> 177928
A11: 1976 | B11: =SUMIF(DataQ!$B:$B,DataA!$A11,DataQ!G:G) -> 976967 | C11: =SUMIF(DataQ!$B:$B,DataA!$A11,DataQ!H:H) -> 6387.425 | D11: =SUMIF(DataQ!$B:$B,DataA!$A11,DataQ!I:I) -> 224484.6 | E11: =SUMIF(DataQ!$B:$B,DataA!$A11,DataQ!J:J) -> 1626.82 | F11: =SUMIF(DataQ!$B:$B,DataA!$A11,DataQ!K:K) -> 1078.312 | G11: =SUMIF(DataQ!$B:$B,DataA!$A11,DataQ!L:L) -> 1024.4384 | H11: =SUMIF(DataQ!$B:$B,DataA!$A11,DataQ!M:M) -> 785915.6 | I11: =SUMIF(DataQ!$B:$B,DataA!$A11,DataQ!N:N) -> -7961 | J11: =SUMIF(DataQ!$B:$B,DataA!$A11,DataQ!O:O) -> -104.50225 | K11: =SUMIF(DataQ!$B:$B,DataA!$A11,DataQ!P:P) -> -9301 | L11: =SUMIF(DataQ!$B:$B,DataA!$A11,DataQ!Q:Q) -> -53.17428 | M11: =SUMIF(DataQ!$B:$B,DataA!$A11,DataQ!R:R) -> -1.5120001 | N11: =SUMIF(DataQ!$B:$B,DataA!$A11,DataQ!S:S) -> -7.402609 | O11: =SUMIF(DataQ!$B:$B,DataA!$A11,DataQ!T:T) -> -4501 | P11: =SUMIF(DataQ!$E:$E,DataA!$A11,DataQ!U:U) -> 73402.75 | Q11: =SUMIF(DataQ!$E:$E,DataA!$A11,DataQ!V:V) -> 1521.477 | R11: =SUMIF(DataQ!$E:$E,DataA!$A11,DataQ!W:W) -> 44086 | S11: =SUMIF(DataQ!$E:$E,DataA!$A11,DataQ!X:X) -> 155.0151 | T11: =SUMIF(DataQ!$E:$E,DataA!$A11,DataQ!Y:Y) -> 77.04875 | U11: =SUMIF(DataQ!$E:$E,DataA!$A11,DataQ!Z:Z) -> 76.946 | V11: =SUMIF(DataQ!$E:$E,DataA!$A11,DataQ!AA:AA) -> 91437 | W11: =SUMIF(DataQ!$B:$B,DataA!$A11,DataQ!AB:AB) -> 136999 | X11: =SUMIF(DataQ!$B:$B,DataA!$A11,DataQ!AC:AC) -> 1873.425 | Y11: =SUMIF(DataQ!$B:$B,DataA!$A11,DataQ!AD:AD) -> 171384.16 | Z11: =SUMIF(DataQ!$B:$B,DataA!$A11,DataQ!AE:AE) -> 677.2367 | AA11: =SUMIF(DataQ!$B:$B,DataA!$A11,DataQ!AF:AF) -> 269.714 | AB11: =SUMIF(DataQ!$B:$B,DataA!$A11,DataQ!AG:AG) -> 96.562 | AC11: =SUMIF(DataQ!$B:$B,DataA!$A11,DataQ!AH:AH) -> 205986
A12: 1977 | B12: =SUMIF(DataQ!$B:$B,DataA!$A12,DataQ!G:G) -> 1001004 | C12: =SUMIF(DataQ!$B:$B,DataA!$A12,DataQ!H:H) -> 6682.825 | D12: =SUMIF(DataQ!$B:$B,DataA!$A12,DataQ!I:I) -> 234520.75 | E12: =SUMIF(DataQ!$B:$B,DataA!$A12,DataQ!J:J) -> 1683.93 | F12: =SUMIF(DataQ!$B:$B,DataA!$A12,DataQ!K:K) -> 1116.289 | G12: =SUMIF(DataQ!$B:$B,DataA!$A12,DataQ!L:L) -> 1048.6038 | H12: =SUMIF(DataQ!$B:$B,DataA!$A12,DataQ!M:M) -> 813696.4 | I12: =SUMIF(DataQ!$B:$B,DataA!$A12,DataQ!N:N) -> -5836 | J12: =SUMIF(DataQ!$B:$B,DataA!$A12,DataQ!O:O) -> -88.151 | K12: =SUMIF(DataQ!$B:$B,DataA!$A12,DataQ!P:P) -> -10191.75 | L12: =SUMIF(DataQ!$B:$B,DataA!$A12,DataQ!Q:Q) -> -44.70044 | M12: =SUMIF(DataQ!$B:$B,DataA!$A12,DataQ!R:R) -> -1.9469999 | N12: =SUMIF(DataQ!$B:$B,DataA!$A12,DataQ!S:S) -> -7.911603 | O12: =SUMIF(DataQ!$B:$B,DataA!$A12,DataQ!T:T) -> -7329 | P12: =SUMIF(DataQ!$E:$E,DataA!$A12,DataQ!U:U) -> 83765.5 | Q12: =SUMIF(DataQ!$E:$E,DataA!$A12,DataQ!V:V) -> 1639.112 | R12: =SUMIF(DataQ!$E:$E,DataA!$A12,DataQ!W:W) -> 58926 | S12: =SUMIF(DataQ!$E:$E,DataA!$A12,DataQ!X:X) -> 172.103 | T12: =SUMIF(DataQ!$E:$E,DataA!$A12,DataQ!Y:Y) -> 85.55736 | U12: =SUMIF(DataQ!$E:$E,DataA!$A12,DataQ!Z:Z) -> 97.55 | V12: =SUMIF(DataQ!$E:$E,DataA!$A12,DataQ!AA:AA) -> 104504 | W12: =SUMIF(DataQ!$B:$B,DataA!$A12,DataQ!AB:AB) -> 159786 | X12: =SUMIF(DataQ!$B:$B,DataA!$A12,DataQ!AC:AC) -> 2081.825 | Y12: =SUMIF(DataQ!$B:$B,DataA!$A12,DataQ!AD:AD) -> 191055.77 | Z12: =SUMIF(DataQ!$B:$B,DataA!$A12,DataQ!AE:AE) -> 722.7076 | AA12: =SUMIF(DataQ!$B:$B,DataA!$A12,DataQ!AF:AF) -> 303.907 | AB12: =SUMIF(DataQ!$B:$B,DataA!$A12,DataQ!AG:AG) -> 117.316 | AC12: =SUMIF(DataQ!$B:$B,DataA!$A12,DataQ!AH:AH) -> 227601
A13: 1978 | B13: =SUMIF(DataQ!$B:$B,DataA!$A13,DataQ!G:G) -> 1042953 | C13: =SUMIF(DataQ!$B:$B,DataA!$A13,DataQ!H:H) -> 7052.725 | D13: =SUMIF(DataQ!$B:$B,DataA!$A13,DataQ!I:I) -> 247036.86 | E13: =SUMIF(DataQ!$B:$B,DataA!$A13,DataQ!J:J) -> 1736.22 | F13: =SUMIF(DataQ!$B:$B,DataA!$A13,DataQ!K:K) -> 1160.514 | G13: =SUMIF(DataQ!$B:$B,DataA!$A13,DataQ!L:L) -> 1086.8867 | H13: =SUMIF(DataQ!$B:$B,DataA!$A13,DataQ!M:M) -> 844095.8 | I13: =SUMIF(DataQ!$B:$B,DataA!$A13,DataQ!N:N) -> -8334 | J13: =SUMIF(DataQ!$B:$B,DataA!$A13,DataQ!O:O) -> -81.16925 | K13: =SUMIF(DataQ!$B:$B,DataA!$A13,DataQ!P:P) -> -13458 | L13: =SUMIF(DataQ!$B:$B,DataA!$A13,DataQ!Q:Q) -> -52.05288 | M13: =SUMIF(DataQ!$B:$B,DataA!$A13,DataQ!R:R) -> -6.702 | N13: =SUMIF(DataQ!$B:$B,DataA!$A13,DataQ!S:S) -> -11.376781 | O13: =SUMIF(DataQ!$B:$B,DataA!$A13,DataQ!T:T) -> -10455 | P13: =SUMIF(DataQ!$E:$E,DataA!$A13,DataQ!U:U) -> 94137.5 | Q13: =SUMIF(DataQ!$E:$E,DataA!$A13,DataQ!V:V) -> 1778.414 | R13: =SUMIF(DataQ!$E:$E,DataA!$A13,DataQ!W:W) -> 82162 | S13: =SUMIF(DataQ!$E:$E,DataA!$A13,DataQ!X:X) -> 193.9361 | T13: =SUMIF(DataQ!$E:$E,DataA!$A13,DataQ!Y:Y) -> 100.8063 | U13: =SUMIF(DataQ!$E:$E,DataA!$A13,DataQ!Z:Z) -> 121.674 | V13: =SUMIF(DataQ!$E:$E,DataA!$A13,DataQ!AA:AA) -> 123288 | W13: =SUMIF(DataQ!$B:$B,DataA!$A13,DataQ!AB:AB) -> 186158 | X13: =SUMIF(DataQ!$B:$B,DataA!$A13,DataQ!AC:AC) -> 2351.6 | Y13: =SUMIF(DataQ!$B:$B,DataA!$A13,DataQ!AD:AD) -> 210468.72 | Z13: =SUMIF(DataQ!$B:$B,DataA!$A13,DataQ!AE:AE) -> 771.5664 | AA13: =SUMIF(DataQ!$B:$B,DataA!$A13,DataQ!AF:AF) -> 345.187 | AB13: =SUMIF(DataQ!$B:$B,DataA!$A13,DataQ!AG:AG) -> 138.022 | AC13: =SUMIF(DataQ!$B:$B,DataA!$A13,DataQ!AH:AH) -> 252075
A14: 1979 | B14: =SUMIF(DataQ!$B:$B,DataA!$A14,DataQ!G:G) -> 1081838 | C14: =SUMIF(DataQ!$B:$B,DataA!$A14,DataQ!H:H) -> 7276 | D14: =SUMIF(DataQ!$B:$B,DataA!$A14,DataQ!I:I) -> 261577.77 | E14: =SUMIF(DataQ!$B:$B,DataA!$A14,DataQ!J:J) -> 1810.62 | F14: =SUMIF(DataQ!$B:$B,DataA!$A14,DataQ!K:K) -> 1203.514 | G14: =SUMIF(DataQ!$B:$B,DataA!$A14,DataQ!L:L) -> 1147.0066 | H14: =SUMIF(DataQ!$B:$B,DataA!$A14,DataQ!M:M) -> 875540.1 | I14: =SUMIF(DataQ!$B:$B,DataA!$A14,DataQ!N:N) -> -9364 | J14: =SUMIF(DataQ!$B:$B,DataA!$A14,DataQ!O:O) -> -78.56225 | K14: =SUMIF(DataQ!$B:$B,DataA!$A14,DataQ!P:P) -> -12426.5 | L14: =SUMIF(DataQ!$B:$B,DataA!$A14,DataQ!Q:Q) -> -58.44036 | M14: =SUMIF(DataQ!$B:$B,DataA!$A14,DataQ!R:R) -> -1.934 | N14: =SUMIF(DataQ!$B:$B,DataA!$A14,DataQ!S:S) -> -13.51795 | O14: =SUMIF(DataQ!$B:$B,DataA!$A14,DataQ!T:T) -> -8532 | P14: =SUMIF(DataQ!$E:$E,DataA!$A14,DataQ!U:U) -> 104807 | Q14: =SUMIF(DataQ!$E:$E,DataA!$A14,DataQ!V:V) -> 1922.42 | R14: =SUMIF(DataQ!$E:$E,DataA!$A14,DataQ!W:W) -> 98956 | S14: =SUMIF(DataQ!$E:$E,DataA!$A14,DataQ!X:X) -> 217.6445 | T14: =SUMIF(DataQ!$E:$E,DataA!$A14,DataQ!Y:Y) -> 115.7283 | U14: =SUMIF(DataQ!$E:$E,DataA!$A14,DataQ!Z:Z) -> 146.611 | V14: =SUMIF(DataQ!$E:$E,DataA!$A14,DataQ!AA:AA) -> 132680 | W14: =SUMIF(DataQ!$B:$B,DataA!$A14,DataQ!AB:AB) -> 220981 | X14: =SUMIF(DataQ!$B:$B,DataA!$A14,DataQ!AC:AC) -> 2627.325 | Y14: =SUMIF(DataQ!$B:$B,DataA!$A14,DataQ!AD:AD) -> 227860.58 | Z14: =SUMIF(DataQ!$B:$B,DataA!$A14,DataQ!AE:AE) -> 839.0251 | AA14: =SUMIF(DataQ!$B:$B,DataA!$A14,DataQ!AF:AF) -> 394.491 | AB14: =SUMIF(DataQ!$B:$B,DataA!$A14,DataQ!AG:AG) -> 168.884 | AC14: =SUMIF(DataQ!$B:$B,DataA!$A14,DataQ!AH:AH) -> 287608
A15: 1980 | B15: =SUMIF(DataQ!$B:$B,DataA!$A15,DataQ!G:G) -> 1059660 | C15: =SUMIF(DataQ!$B:$B,DataA!$A15,DataQ!H:H) -> 7257.325 | D15: =SUMIF(DataQ!$B:$B,DataA!$A15,DataQ!I:I) -> 272992.43 | E15: =SUMIF(DataQ!$B:$B,DataA!$A15,DataQ!J:J) -> 1833.95 | F15: =SUMIF(DataQ!$B:$B,DataA!$A15,DataQ!K:K) -> 1223.307 | G15: =SUMIF(DataQ!$B:$B,DataA!$A15,DataQ!L:L) -> 1186.9547 | H15: =SUMIF(DataQ!$B:$B,DataA!$A15,DataQ!M:M) -> 894602.4 | I15: =SUMIF(DataQ!$B:$B,DataA!$A15,DataQ!N:N) -> -10041 | J15: =SUMIF(DataQ!$B:$B,DataA!$A15,DataQ!O:O) -> -128.273 | K15: =SUMIF(DataQ!$B:$B,DataA!$A15,DataQ!P:P) -> -11822.5 | L15: =SUMIF(DataQ!$B:$B,DataA!$A15,DataQ!Q:Q) -> -62.0868 | M15: =SUMIF(DataQ!$B:$B,DataA!$A15,DataQ!R:R) -> -1.928 | N15: =SUMIF(DataQ!$B:$B,DataA!$A15,DataQ!S:S) -> -14.305154 | O15: =SUMIF(DataQ!$B:$B,DataA!$A15,DataQ!T:T) -> -11149 | P15: =SUMIF(DataQ!$E:$E,DataA!$A15,DataQ!U:U) -> 121541.3 | Q15: =SUMIF(DataQ!$E:$E,DataA!$A15,DataQ!V:V) -> 2062.851 | R15: =SUMIF(DataQ!$E:$E,DataA!$A15,DataQ!W:W) -> 117360 | S15: =SUMIF(DataQ!$E:$E,DataA!$A15,DataQ!X:X) -> 248.8942 | T15: =SUMIF(DataQ!$E:$E,DataA!$A15,DataQ!Y:Y) -> 129.1328 | U15: =SUMIF(DataQ!$E:$E,DataA!$A15,DataQ!Z:Z) -> 178.644 | V15: =SUMIF(DataQ!$E:$E,DataA!$A15,DataQ!AA:AA) -> 150393 | W15: =SUMIF(DataQ!$B:$B,DataA!$A15,DataQ!AB:AB) -> 259970 | X15: =SUMIF(DataQ!$B:$B,DataA!$A15,DataQ!AC:AC) -> 2857.325 | Y15: =SUMIF(DataQ!$B:$B,DataA!$A15,DataQ!AD:AD) -> 255596.35 | Z15: =SUMIF(DataQ!$B:$B,DataA!$A15,DataQ!AE:AE) -> 896.4522 | AA15: =SUMIF(DataQ!$B:$B,DataA!$A15,DataQ!AF:AF) -> 447.345 | AB15: =SUMIF(DataQ!$B:$B,DataA!$A15,DataQ!AG:AG) -> 217.501 | AC15: =SUMIF(DataQ!$B:$B,DataA!$A15,DataQ!AH:AH) -> 322782
A16: 1981 | B16: =SUMIF(DataQ!$B:$B,DataA!$A16,DataQ!G:G) -> 1052374 | C16: =SUMIF(DataQ!$B:$B,DataA!$A16,DataQ!H:H) -> 7441.475 | D16: =SUMIF(DataQ!$B:$B,DataA!$A16,DataQ!I:I) -> 284947.89 | E16: =SUMIF(DataQ!$B:$B,DataA!$A16,DataQ!J:J) -> 1845.86 | F16: =SUMIF(DataQ!$B:$B,DataA!$A16,DataQ!K:K) -> 1237.82 | G16: =SUMIF(DataQ!$B:$B,DataA!$A16,DataQ!L:L) -> 1197.887 | H16: =SUMIF(DataQ!$B:$B,DataA!$A16,DataQ!M:M) -> 925153.7 | I16: =SUMIF(DataQ!$B:$B,DataA!$A16,DataQ!N:N) -> -8825 | J16: =SUMIF(DataQ!$B:$B,DataA!$A16,DataQ!O:O) -> -130.469 | K16: =SUMIF(DataQ!$B:$B,DataA!$A16,DataQ!P:P) -> -10937.75 | L16: =SUMIF(DataQ!$B:$B,DataA!$A16,DataQ!Q:Q) -> -75.16716 | M16: =SUMIF(DataQ!$B:$B,DataA!$A16,DataQ!R:R) -> -12.242 | N16: =SUMIF(DataQ!$B:$B,DataA!$A16,DataQ!S:S) -> -27.037463 | O16: =SUMIF(DataQ!$B:$B,DataA!$A16,DataQ!T:T) -> -7830 | P16: =SUMIF(DataQ!$E:$E,DataA!$A16,DataQ!U:U) -> 131791.5 | Q16: =SUMIF(DataQ!$E:$E,DataA!$A16,DataQ!V:V) -> 2256.733 | R16: =SUMIF(DataQ!$E:$E,DataA!$A16,DataQ!W:W) -> 141470 | S16: =SUMIF(DataQ!$E:$E,DataA!$A16,DataQ!X:X) -> 287.4771 | T16: =SUMIF(DataQ!$E:$E,DataA!$A16,DataQ!Y:Y) -> 141.5108 | U16: =SUMIF(DataQ!$E:$E,DataA!$A16,DataQ!Z:Z) -> 224.365 | V16: =SUMIF(DataQ!$E:$E,DataA!$A16,DataQ!AA:AA) -> 177353 | W16: =SUMIF(DataQ!$B:$B,DataA!$A16,DataQ!AB:AB) -> 290180 | X16: =SUMIF(DataQ!$B:$B,DataA!$A16,DataQ!AC:AC) -> 3207.025 | Y16: =SUMIF(DataQ!$B:$B,DataA!$A16,DataQ!AD:AD) -> 274362.5 | Z16: =SUMIF(DataQ!$B:$B,DataA!$A16,DataQ!AE:AE) -> 939.7564 | AA16: =SUMIF(DataQ!$B:$B,DataA!$A16,DataQ!AF:AF) -> 504.566 | AB16: =SUMIF(DataQ!$B:$B,DataA!$A16,DataQ!AG:AG) -> 260.06 | AC16: =SUMIF(DataQ!$B:$B,DataA!$A16,DataQ!AH:AH) -> 368358
A17: 1982 | B17: =SUMIF(DataQ!$B:$B,DataA!$A17,DataQ!G:G) -> 1073055 | C17: =SUMIF(DataQ!$B:$B,DataA!$A17,DataQ!H:H) -> 7307.3 | D17: =SUMIF(DataQ!$B:$B,DataA!$A17,DataQ!I:I) -> 294351.01 | E17: =SUMIF(DataQ!$B:$B,DataA!$A17,DataQ!J:J) -> 1836.61 | F17: =SUMIF(DataQ!$B:$B,DataA!$A17,DataQ!K:K) -> 1267.574 | G17: =SUMIF(DataQ!$B:$B,DataA!$A17,DataQ!L:L) -> 1201.783 | H17: =SUMIF(DataQ!$B:$B,DataA!$A17,DataQ!M:M) -> 895861.9 | I17: =SUMIF(DataQ!$B:$B,DataA!$A17,DataQ!N:N) -> -7359 | J17: =SUMIF(DataQ!$B:$B,DataA!$A17,DataQ!O:O) -> -220.126 | K17: =SUMIF(DataQ!$B:$B,DataA!$A17,DataQ!P:P) -> -11134.25 | L17: =SUMIF(DataQ!$B:$B,DataA!$A17,DataQ!Q:Q) -> -74.95508 | M17: =SUMIF(DataQ!$B:$B,DataA!$A17,DataQ!R:R) -> -16.498 | N17: =SUMIF(DataQ!$B:$B,DataA!$A17,DataQ!S:S) -> -29.281416 | O17: =SUMIF(DataQ!$B:$B,DataA!$A17,DataQ!T:T) -> -23407 | P17: =SUMIF(DataQ!$E:$E,DataA!$A17,DataQ!U:U) -> 140578.8 | Q17: =SUMIF(DataQ!$E:$E,DataA!$A17,DataQ!V:V) -> 2532.298 | R17: =SUMIF(DataQ!$E:$E,DataA!$A17,DataQ!W:W) -> 165196 | S17: =SUMIF(DataQ!$E:$E,DataA!$A17,DataQ!X:X) -> 320.4308 | T17: =SUMIF(DataQ!$E:$E,DataA!$A17,DataQ!Y:Y) -> 184.3563 | U17: =SUMIF(DataQ!$E:$E,DataA!$A17,DataQ!Z:Z) -> 275.674 | V17: =SUMIF(DataQ!$E:$E,DataA!$A17,DataQ!AA:AA) -> 209732 | W17: =SUMIF(DataQ!$B:$B,DataA!$A17,DataQ!AB:AB) -> 319558 | X17: =SUMIF(DataQ!$B:$B,DataA!$A17,DataQ!AC:AC) -> 3343.8 | Y17: =SUMIF(DataQ!$B:$B,DataA!$A17,DataQ!AD:AD) -> 288540.02 | Z17: =SUMIF(DataQ!$B:$B,DataA!$A17,DataQ!AE:AE) -> 977.803 | AA17: =SUMIF(DataQ!$B:$B,DataA!$A17,DataQ!AF:AF) -> 578.925 | AB17: =SUMIF(DataQ!$B:$B,DataA!$A17,DataQ!AG:AG) -> 306.689 | AC17: =SUMIF(DataQ!$B:$B,DataA!$A17,DataQ!AH:AH) -> 388181
A18: 1983 | B18: =SUMIF(DataQ!$B:$B,DataA!$A18,DataQ!G:G) -> 1117759 | C18: =SUMIF(DataQ!$B:$B,DataA!$A18,DataQ!H:H) -> 7642.275 | D18: =SUMIF(DataQ!$B:$B,DataA!$A18,DataQ!I:I) -> 304984.68 | E18: =SUMIF(DataQ!$B:$B,DataA!$A18,DataQ!J:J) -> 1863.58 | F18: =SUMIF(DataQ!$B:$B,DataA!$A18,DataQ!K:K) -> 1283.577 | G18: =SUMIF(DataQ!$B:$B,DataA!$A18,DataQ!L:L) -> 1218.202 | H18: =SUMIF(DataQ!$B:$B,DataA!$A18,DataQ!M:M) -> 918816.2 | I18: =SUMIF(DataQ!$B:$B,DataA!$A18,DataQ!N:N) -> -10582 | J18: =SUMIF(DataQ!$B:$B,DataA!$A18,DataQ!O:O) -> -265.23725 | K18: =SUMIF(DataQ!$B:$B,DataA!$A18,DataQ!P:P) -> -11809.25 | L18: =SUMIF(DataQ!$B:$B,DataA!$A18,DataQ!Q:Q) -> -71.17676 | M18: =SUMIF(DataQ!$B:$B,DataA!$A18,DataQ!R:R) -> -16.481 | N18: =SUMIF(DataQ!$B:$B,DataA!$A18,DataQ!S:S) -> -34.423509 | O18: =SUMIF(DataQ!$B:$B,DataA!$A18,DataQ!T:T) -> -30637 | P18: =SUMIF(DataQ!$E:$E,DataA!$A18,DataQ!U:U) -> 152083.3 | Q18: =SUMIF(DataQ!$E:$E,DataA!$A18,DataQ!V:V) -> 2812.196 | R18: =SUMIF(DataQ!$E:$E,DataA!$A18,DataQ!W:W) -> 189884 | S18: =SUMIF(DataQ!$E:$E,DataA!$A18,DataQ!X:X) -> 347.2786 | T18: =SUMIF(DataQ!$E:$E,DataA!$A18,DataQ!Y:Y) -> 210.6735 | U18: =SUMIF(DataQ!$E:$E,DataA!$A18,DataQ!Z:Z) -> 269.128 | V18: =SUMIF(DataQ!$E:$E,DataA!$A18,DataQ!AA:AA) -> 251868 | W18: =SUMIF(DataQ!$B:$B,DataA!$A18,DataQ!AB:AB) -> 351347 | X18: =SUMIF(DataQ!$B:$B,DataA!$A18,DataQ!AC:AC) -> 3634.025 | Y18: =SUMIF(DataQ!$B:$B,DataA!$A18,DataQ!AD:AD) -> 301733.15 | Z18: =SUMIF(DataQ!$B:$B,DataA!$A18,DataQ!AE:AE) -> 1020.0841 | AA18: =SUMIF(DataQ!$B:$B,DataA!$A18,DataQ!AF:AF) -> 642.54 | AB18: =SUMIF(DataQ!$B:$B,DataA!$A18,DataQ!AG:AG) -> 357.802 | AC18: =SUMIF(DataQ!$B:$B,DataA!$A18,DataQ!AH:AH) -> 421316
A19: 1984 | B19: =SUMIF(DataQ!$B:$B,DataA!$A19,DataQ!G:G) -> 1142579 | C19: =SUMIF(DataQ!$B:$B,DataA!$A19,DataQ!H:H) -> 8195.3 | D19: =SUMIF(DataQ!$B:$B,DataA!$A19,DataQ!I:I) -> 318480.11 | E19: =SUMIF(DataQ!$B:$B,DataA!$A19,DataQ!J:J) -> 1917.61 | F19: =SUMIF(DataQ!$B:$B,DataA!$A19,DataQ!K:K) -> 1305.053 | G19: =SUMIF(DataQ!$B:$B,DataA!$A19,DataQ!L:L) -> 1257.309 | H19: =SUMIF(DataQ!$B:$B,DataA!$A19,DataQ!M:M) -> 973013.1 | I19: =SUMIF(DataQ!$B:$B,DataA!$A19,DataQ!N:N) -> -12423 | J19: =SUMIF(DataQ!$B:$B,DataA!$A19,DataQ!O:O) -> -249.608 | K19: =SUMIF(DataQ!$B:$B,DataA!$A19,DataQ!P:P) -> -8204.75 | L19: =SUMIF(DataQ!$B:$B,DataA!$A19,DataQ!Q:Q) -> -66.7484 | M19: =SUMIF(DataQ!$B:$B,DataA!$A19,DataQ!R:R) -> -19.303 | N19: =SUMIF(DataQ!$B:$B,DataA!$A19,DataQ!S:S) -> -44.8364 | O19: =SUMIF(DataQ!$B:$B,DataA!$A19,DataQ!T:T) -> -33224.999 | P19: =SUMIF(DataQ!$E:$E,DataA!$A19,DataQ!U:U) -> 163648.5 | Q19: =SUMIF(DataQ!$E:$E,DataA!$A19,DataQ!V:V) -> 3127.651 | R19: =SUMIF(DataQ!$E:$E,DataA!$A19,DataQ!W:W) -> 208326 | S19: =SUMIF(DataQ!$E:$E,DataA!$A19,DataQ!X:X) -> 369.349 | T19: =SUMIF(DataQ!$E:$E,DataA!$A19,DataQ!Y:Y) -> 240.8142 | U19: =SUMIF(DataQ!$E:$E,DataA!$A19,DataQ!Z:Z) -> 318.727 | V19: =SUMIF(DataQ!$E:$E,DataA!$A19,DataQ!AA:AA) -> 290671 | W19: =SUMIF(DataQ!$B:$B,DataA!$A19,DataQ!AB:AB) -> 377920 | X19: =SUMIF(DataQ!$B:$B,DataA!$A19,DataQ!AC:AC) -> 4037.65 | Y19: =SUMIF(DataQ!$B:$B,DataA!$A19,DataQ!AD:AD) -> 319635.48 | Z19: =SUMIF(DataQ!$B:$B,DataA!$A19,DataQ!AE:AE) -> 1070.7138 | AA19: =SUMIF(DataQ!$B:$B,DataA!$A19,DataQ!AF:AF) -> 699.5 | AB19: =SUMIF(DataQ!$B:$B,DataA!$A19,DataQ!AG:AG) -> 409.026 | AC19: =SUMIF(DataQ!$B:$B,DataA!$A19,DataQ!AH:AH) -> 461986
... A95: 2060 | B95: =SUMIF(DataQ!$B:$B,DataA!$A95,DataQ!G:G) -> 4282693 | C95: =SUMIF(DataQ!$B:$B,DataA!$A95,DataQ!H:H) -> 43611.64 | D95: =SUMIF(DataQ!$B:$B,DataA!$A95,DataQ!I:I) -> 575869.8 | E95: =SUMIF(DataQ!$B:$B,DataA!$A95,DataQ!J:J) -> 4940.229 | F95: =SUMIF(DataQ!$B:$B,DataA!$A95,DataQ!K:K) -> 3240.5261 | G95: =SUMIF(DataQ!$B:$B,DataA!$A95,DataQ!L:L) -> 2172.8906 | H95: =SUMIF(DataQ!$B:$B,DataA!$A95,DataQ!M:M) -> 4690331 | I95: =SUMIF(DataQ!$B:$B,DataA!$A95,DataQ!N:N) -> -422235.08 | J95: =SUMIF(DataQ!$B:$B,DataA!$A95,DataQ!O:O) -> -4085.043 | K95: =SUMIF(DataQ!$B:$B,DataA!$A95,DataQ!P:P) -> -9856.876 | L95: =SUMIF(DataQ!$B:$B,DataA!$A95,DataQ!Q:Q) -> -175.23095 | M95: =SUMIF(DataQ!$B:$B,DataA!$A95,DataQ!R:R) -> -244.19832 | N95: =SUMIF(DataQ!$B:$B,DataA!$A95,DataQ!S:S) -> -87.62374 | O95: =SUMIF(DataQ!$B:$B,DataA!$A95,DataQ!T:T) -> -287749.88 | P95: =SUMIF(DataQ!$E:$E,DataA!$A95,DataQ!U:U) -> 11324100 | Q95: =SUMIF(DataQ!$E:$E,DataA!$A95,DataQ!V:V) -> 181081 | R95: =SUMIF(DataQ!$E:$E,DataA!$A95,DataQ!W:W) -> 1741352 | S95: =SUMIF(DataQ!$E:$E,DataA!$A95,DataQ!X:X) -> 7253.72 | T95: =SUMIF(DataQ!$E:$E,DataA!$A95,DataQ!Y:Y) -> 9996.658 | U95: =SUMIF(DataQ!$E:$E,DataA!$A95,DataQ!Z:Z) -> 5756.39 | V95: =SUMIF(DataQ!$E:$E,DataA!$A95,DataQ!AA:AA) -> 9232492 | W95: =SUMIF(DataQ!$B:$B,DataA!$A95,DataQ!AB:AB) -> 10420241 | X95: =SUMIF(DataQ!$B:$B,DataA!$A95,DataQ!AC:AC) -> 107862.69 | Y95: =SUMIF(DataQ!$B:$B,DataA!$A95,DataQ!AD:AD) -> 1059071.7 | Z95: =SUMIF(DataQ!$B:$B,DataA!$A95,DataQ!AE:AE) -> 12560.15 | AA95: =SUMIF(DataQ!$B:$B,DataA!$A95,DataQ!AF:AF) -> 7400.093 | AB95: =SUMIF(DataQ!$B:$B,DataA!$A95,DataQ!AG:AG) -> 4938.557 | AC95: =SUMIF(DataQ!$B:$B,DataA!$A95,DataQ!AH:AH) -> 11878789

Sheet DataQ
G1: =GMW!NF2 -> SEP008W.db | H1: =$G$1 -> SEP008W.db | I1: =$G$1 -> SEP008W.db | J1: =$G$1 -> SEP008W.db | K1: =$G$1 -> SEP008W.db | L1: =$G$1 -> SEP008W.db | M1: =$G$1 -> SEP008W.db | N1: =$G$1 -> SEP008W.db | O1: =$G$1 -> SEP008W.db | ... AH1: =$G$1 -> SEP008W.db
G2: UK | H2: US | I2: Japan | J2: Germany | K2: France | L2: Italy | M2: Canada | N2: UK | O2: US | P2: Japan | Q2: Germany | R2: France | S2: Italy | T2: Canada | U2: UK | V2: US | W2: Japan | X2: Germany | Y2: France | Z2: Italy | AA2: Canada | AB2: UK | AC2: US | AD2: Japan | AE2: Germany | AF2: France | AG2: Italy | AH2: Canada
G3: GDP | H3: GDP | I3: GDP | J3: GDP | K3: GDP | L3: GDP | M3: GDP | N3: GB | O3: GB | P3: GB | Q3: GB | R3: GB | S3: GB | T3: GB | U3: GGDBT | V3: GGDBT | W3: GGDBT | X3: GGDBT | Y3: GGDBT | Z3: GGDBT | AA3: GGDBT | AB3: GDP! | AC3: GDP! | AD3: GDP! | AE3: GDP! | AF3: GDP! | AG3: GDP! | AH3: GDP!
G4: GBR | H4: USA | I4: JPN | J4: DEU | K4: FRA | L4: ITA | M4: CAN | N4: GBR | O4: USA | P4: JPN | Q4: DEU | R4: FRA | S4: ITA | T4: CAN | U4: GBR | V4: USA | W4: JPN | X4: DEU | Y4: FRA | Z4: ITA | AA4: CAN | AB4: GBR | AC4: USA | AD4: JPN | AE4: DEU | AF4: FRA | AG4: ITA | AH4: CAN
G5: L | H5: L | I5: L | J5: L | K5: L | L5: L | M5: L | N5: L | O5: L | P5: L | Q5: L | R5: L | S5: L | T5: L | U5: L | V5: L | W5: L | X5: L | Y5: L | Z5: L | AA5: L | AB5: L | AC5: L | AD5: L | AE5: L | AF5: L | AG5: L | AH5: L
B6: CYs | C6: FYs | D6: FY end | E6: CY end | F6: =F358+5 -> 2329 | G6: {=_xlfn.CONCAT(INDEX(GMW!$A$2:$NE$60,MATCH(1,(GMW!$NE$2:$NE$60=G$3)*(GMW!$ND$2:$ND$60=G$4)*(GMW!$NF$2:$NF$60=G$1),0),$F6-1966),"0",(INDEX(GMW!$A$2:$NE$60,MATCH(1,(GMW!$NE$2:$NE$60=G$3)*(GMW!$ND$2:$ND$60=G$4)*(GMW!$NF$2:$NF$60=G$1),0),$F6-1965)))} -> 202502 | H6: {=_xlfn.CONCAT(INDEX(GMW!$A$2:$NE$60,MATCH(1,(GMW!$NE$2:$NE$60=H$3)*(GMW!$ND$2:$ND$60=H$4)*(GMW!$NF$2:$NF$60=H$1),0),$F6-1966),"0",(INDEX(GMW!$A$2:$NE$60,MATCH(1,(GMW!$NE$2:$NE$60=H$3)*(GMW!$ND$2:$ND$60=H$4)*(GMW!$NF$2:$NF$60=H$1),0),$F6-1965)))} -> 202502 | I6: {=_xlfn.CONCAT(INDEX(GMW!$A$2:$NE$60,MATCH(1,(GMW!$NE$2:$NE$60=I$3)*(GMW!$ND$2:$ND$60=I$4)*(GMW!$NF$2:$NF$60=I$1),0),$F6-1966),"0",(INDEX(GMW!$A$2:$NE$60,MATCH(1,(GMW!$NE$2:$NE$60=I$3)*(GMW!$ND$2:$ND$60=I$4)*(GMW!$NF$2:$NF$60=I$1),0),$F6-1965)))} -> 202502 | J6: {=_xlfn.CONCAT(INDEX(GMW!$A$2:$NE$60,MATCH(1,(GMW!$NE$2:$NE$60=J$3)*(GMW!$ND$2:$ND$60=J$4)*(GMW!$NF$2:$NF$60=J$1),0),$F6-1966),"0",(INDEX(GMW!$A$2:$NE$60,MATCH(1,(GMW!$NE$2:$NE$60=J$3)*(GMW!$ND$2:$ND$60=J$4)*(GMW!$NF$2:$NF$60=J$1),0),$F6-1965)))} -> 202502 | K6: {=_xlfn.CONCAT(INDEX(GMW!$A$2:$NE$60,MATCH(1,(GMW!$NE$2:$NE$60=K$3)*(GMW!$ND$2:$ND$60=K$4)*(GMW!$NF$2:$NF$60=K$1),0),$F6-1966),"0",(INDEX(GMW!$A$2:$NE$60,MATCH(1,(GMW!$NE$2:$NE$60=K$3)*(GMW!$ND$2:$ND$60=K$4)*(GMW!$NF$2:$NF$60=K$1),0),$F6-1965)))} -> 202502 | L6: {=_xlfn.CONCAT(INDEX(GMW!$A$2:$NE$60,MATCH(1,(GMW!$NE$2:$NE$60=L$3)*(GMW!$ND$2:$ND$60=L$4)*(GMW!$NF$2:$NF$60=L$1),0),$F6-1966),"0",(INDEX(GMW!$A$2:$NE$60,MATCH(1,(GMW!$NE$2:$NE$60=L$3)*(GMW!$ND$2:$ND$60=L$4)*(GMW!$NF$2:$NF$60=L$1),0),$F6-1965)))} -> 202502 | M6: {=_xlfn.CONCAT(INDEX(GMW!$A$2:$NE$60,MATCH(1,(GMW!$NE$2:$NE$60=M$3)*(GMW!$ND$2:$ND$60=M$4)*(GMW!$NF$2:$NF$60=M$1),0),$F6-1966),"0",(INDEX(GMW!$A$2:$NE$60,MATCH(1,(GMW!$NE$2:$NE$60=M$3)*(GMW!$ND$2:$ND$60=M$4)*(GMW!$NF$2:$NF$60=M$1),0),$F6-1965)))} -> 202502 | N6: {=_xlfn.CONCAT(INDEX(GMW!$A$2:$NE$60,MATCH(1,(GMW!$NE$2:$NE$60=N$3)*(GMW!$ND$2:$ND$60=N$4)*(GMW!$NF$2:$NF$60=N$1),0),$F6-1966),"0",(INDEX(GMW!$A$2:$NE$60,MATCH(1,(GMW!$NE$2:$NE$60=N$3)*(GMW!$ND$2:$ND$60=N$4)*(GMW!$NF$2:$NF$60=N$1),0),$F6-1965)))} -> 202502 | ... AH6: {=_xlfn.CONCAT(INDEX(GMW!$A$2:$NE$60,MATCH(1,(GMW!$NE$2:$NE$60=AH$3)*(GMW!$ND$2:$ND$60=AH$4)*(GMW!$NF$2:$NF$60=AH$1),0),$F6-1966),"0",(INDEX(GMW!$A$2:$NE$60,MATCH(1,(GMW!$NE$2:$NE$60=AH$3)*(GMW!$ND$2:$ND$60=AH$4)*(GMW!$NF$2:$NF$60=AH$1),0),$F6-1965)))} -> 202502
A7: 1973 | B7: 1973 | F7: 1973 | G7: {=INDEX(GMW!$A$2:$NF$60,MATCH(1,(GMW!$NE$2:$NE$60=G$3)*(GMW!$ND$2:$ND$60=G$4)*(GMW!$NF$2:$NF$60=G$1),0),$F7-1966)} -> 247921 | H7: {=INDEX(GMW!$A$2:$NF$60,MATCH(1,(GMW!$NE$2:$NE$60=H$3)*(GMW!$ND$2:$ND$60=H$4)*(GMW!$NF$2:$NF$60=H$1),0),$F7-1966)} -> 1514.625 | I7: {=INDEX(GMW!$A$2:$NF$60,MATCH(1,(GMW!$NE$2:$NE$60=I$3)*(GMW!$ND$2:$ND$60=I$4)*(GMW!$NF$2:$NF$60=I$1),0),$F7-1966)} -> 52242.65 | J7: {=INDEX(GMW!$A$2:$NF$60,MATCH(1,(GMW!$NE$2:$NE$60=J$3)*(GMW!$ND$2:$ND$60=J$4)*(GMW!$NF$2:$NF$60=J$1),0),$F7-1966)} -> 386.07 | K7: {=INDEX(GMW!$A$2:$NF$60,MATCH(1,(GMW!$NE$2:$NE$60=K$3)*(GMW!$ND$2:$ND$60=K$4)*(GMW!$NF$2:$NF$60=K$1),0),$F7-1966)} -> 244.379 | L7: {=INDEX(GMW!$A$2:$NF$60,MATCH(1,(GMW!$NE$2:$NE$60=L$3)*(GMW!$ND$2:$ND$60=L$4)*(GMW!$NF$2:$NF$60=L$1),0),$F7-1966)} -> 223.0287 | M7: {=INDEX(GMW!$A$2:$NF$60,MATCH(1,(GMW!$NE$2:$NE$60=M$3)*(GMW!$ND$2:$ND$60=M$4)*(GMW!$NF$2:$NF$60=M$1),0),$F7-1966)} -> 174319.5 | N7: {=INDEX(GMW!$A$2:$NF$60,MATCH(1,(GMW!$NE$2:$NE$60=N$3)*(GMW!$ND$2:$ND$60=N$4)*(GMW!$NF$2:$NF$60=N$1),0),$F7-1966)} -> -145 | ... AH7: {=INDEX(GMW!$A$2:$NF$60,MATCH(1,(GMW!$NE$2:$NE$60=AH$3)*(GMW!$ND$2:$ND$60=AH$4)*(GMW!$NF$2:$NF$60=AH$1),0),$F7-1966)} -> 31189
B8: 1973 | C8: 1973 | F8: =+F7+1 -> 1974 | G8: {=INDEX(GMW!$A$2:$NF$60,MATCH(1,(GMW!$NE$2:$NE$60=G$3)*(GMW!$ND$2:$ND$60=G$4)*(GMW!$NF$2:$NF$60=G$1),0),$F8-1966)} -> 248384 | H8: {=INDEX(GMW!$A$2:$NF$60,MATCH(1,(GMW!$NE$2:$NE$60=H$3)*(GMW!$ND$2:$ND$60=H$4)*(GMW!$NF$2:$NF$60=H$1),0),$F8-1966)} -> 1531.125 | I8: {=INDEX(GMW!$A$2:$NF$60,MATCH(1,(GMW!$NE$2:$NE$60=I$3)*(GMW!$ND$2:$ND$60=I$4)*(GMW!$NF$2:$NF$60=I$1),0),$F8-1966)} -> 52722.43 | J8: {=INDEX(GMW!$A$2:$NF$60,MATCH(1,(GMW!$NE$2:$NE$60=J$3)*(GMW!$ND$2:$ND$60=J$4)*(GMW!$NF$2:$NF$60=J$1),0),$F8-1966)} -> 388.81 | K8: {=INDEX(GMW!$A$2:$NF$60,MATCH(1,(GMW!$NE$2:$NE$60=K$3)*(GMW!$ND$2:$ND$60=K$4)*(GMW!$NF$2:$NF$60=K$1),0),$F8-1966)} -> 247.949 | L8: {=INDEX(GMW!$A$2:$NF$60,MATCH(1,(GMW!$NE$2:$NE$60=L$3)*(GMW!$ND$2:$ND$60=L$4)*(GMW!$NF$2:$NF$60=L$1),0),$F8-1966)} -> 229.7104 | M8: {=INDEX(GMW!$A$2:$NF$60,MATCH(1,(GMW!$NE$2:$NE$60=M$3)*(GMW!$ND$2:$ND$60=M$4)*(GMW!$NF$2:$NF$60=M$1),0),$F8-1966)} -> 175982.5 | N8: {=INDEX(GMW!$A$2:$NF$60,MATCH(1,(GMW!$NE$2:$NE$60=N$3)*(GMW!$ND$2:$ND$60=N$4)*(GMW!$NF$2:$NF$60=N$1),0),$F8-1966)} -> -1195 | ... AH8: {=INDEX(GMW!$A$2:$NF$60,MATCH(1,(GMW!$NE$2:$NE$60=AH$3)*(GMW!$ND$2:$ND$60=AH$4)*(GMW!$NF$2:$NF$60=AH$1),0),$F8-1966)} -> 32510
B9: 1973 | C9: 1973 | F9: =+F8+1 -> 1975 | G9: {=INDEX(GMW!$A$2:$NF$60,MATCH(1,(GMW!$NE$2:$NE$60=G$3)*(GMW!$ND$2:$ND$60=G$4)*(GMW!$NF$2:$NF$60=G$1),0),$F9-1966)} -> 246082 | H9: {=INDEX(GMW!$A$2:$NF$60,MATCH(1,(GMW!$NE$2:$NE$60=H$3)*(GMW!$ND$2:$ND$60=H$4)*(GMW!$NF$2:$NF$60=H$1),0),$F9-1966)} -> 1523.075 | I9: {=INDEX(GMW!$A$2:$NF$60,MATCH(1,(GMW!$NE$2:$NE$60=I$3)*(GMW!$ND$2:$ND$60=I$4)*(GMW!$NF$2:$NF$60=I$1),0),$F9-1966)} -> 52875.77 | J9: {=INDEX(GMW!$A$2:$NF$60,MATCH(1,(GMW!$NE$2:$NE$60=J$3)*(GMW!$ND$2:$ND$60=J$4)*(GMW!$NF$2:$NF$60=J$1),0),$F9-1966)} -> 390.14 | K9: {=INDEX(GMW!$A$2:$NF$60,MATCH(1,(GMW!$NE$2:$NE$60=K$3)*(GMW!$ND$2:$ND$60=K$4)*(GMW!$NF$2:$NF$60=K$1),0),$F9-1966)} -> 251.887 | L9: {=INDEX(GMW!$A$2:$NF$60,MATCH(1,(GMW!$NE$2:$NE$60=L$3)*(GMW!$ND$2:$ND$60=L$4)*(GMW!$NF$2:$NF$60=L$1),0),$F9-1966)} -> 237.0208 | M9: {=INDEX(GMW!$A$2:$NF$60,MATCH(1,(GMW!$NE$2:$NE$60=M$3)*(GMW!$ND$2:$ND$60=M$4)*(GMW!$NF$2:$NF$60=M$1),0),$F9-1966)} -> 176800.8 | N9: {=INDEX(GMW!$A$2:$NF$60,MATCH(1,(GMW!$NE$2:$NE$60=N$3)*(GMW!$ND$2:$ND$60=N$4)*(GMW!$NF$2:$NF$60=N$1),0),$F9-1966)} -> -676 | ... AH9: {=INDEX(GMW!$A$2:$NF$60,MATCH(1,(GMW!$NE$2:$NE$60=AH$3)*(GMW!$ND$2:$ND$60=AH$4)*(GMW!$NF$2:$NF$60=AH$1),0),$F9-1966)} -> 33631
B10: 1973 | C10: 1973 | E10: 1973 | F10: =+F9+1 -> 1976 | G10: {=INDEX(GMW!$A$2:$NF$60,MATCH(1,(GMW!$NE$2:$NE$60=G$3)*(GMW!$ND$2:$ND$60=G$4)*(GMW!$NF$2:$NF$60=G$1),0),$F10-1966)} -> 245140 | H10: {=INDEX(GMW!$A$2:$NF$60,MATCH(1,(GMW!$NE$2:$NE$60=H$3)*(GMW!$ND$2:$ND$60=H$4)*(GMW!$NF$2:$NF$60=H$1),0),$F10-1966)} -> 1537.525 | I10: {=INDEX(GMW!$A$2:$NF$60,MATCH(1,(GMW!$NE$2:$NE$60=I$3)*(GMW!$ND$2:$ND$60=I$4)*(GMW!$NF$2:$NF$60=I$1),0),$F10-1966)} -> 53539.66 | J10: {=INDEX(GMW!$A$2:$NF$60,MATCH(1,(GMW!$NE$2:$NE$60=J$3)*(GMW!$ND$2:$ND$60=J$4)*(GMW!$NF$2:$NF$60=J$1),0),$F10-1966)} -> 391.12 | K10: {=INDEX(GMW!$A$2:$NF$60,MATCH(1,(GMW!$NE$2:$NE$60=K$3)*(GMW!$ND$2:$ND$60=K$4)*(GMW!$NF$2:$NF$60=K$1),0),$F10-1966)} -> 254.935 | L10: {=INDEX(GMW!$A$2:$NF$60,MATCH(1,(GMW!$NE$2:$NE$60=L$3)*(GMW!$ND$2:$ND$60=L$4)*(GMW!$NF$2:$NF$60=L$1),0),$F10-1966)} -> 242.81 | M10: {=INDEX(GMW!$A$2:$NF$60,MATCH(1,(GMW!$NE$2:$NE$60=M$3)*(GMW!$ND$2:$ND$60=M$4)*(GMW!$NF$2:$NF$60=M$1),0),$F10-1966)} -> 180061.8 | N10: {=INDEX(GMW!$A$2:$NF$60,MATCH(1,(GMW!$NE$2:$NE$60=N$3)*(GMW!$ND$2:$ND$60=N$4)*(GMW!$NF$2:$NF$60=N$1),0),$F10-1966)} -> -724 | ... AH10: {=INDEX(GMW!$A$2:$NF$60,MATCH(1,(GMW!$NE$2:$NE$60=AH$3)*(GMW!$ND$2:$ND$60=AH$4)*(GMW!$NF$2:$NF$60=AH$1),0),$F10-1966)} -> 35636
A11: 1974 | B11: =+B7+1 -> 1974 | C11: 1973 | D11: 1973 | F11: =+F10+1 -> 1977 | G11: {=INDEX(GMW!$A$2:$NF$60,MATCH(1,(GMW!$NE$2:$NE$60=G$3)*(GMW!$ND$2:$ND$60=G$4)*(GMW!$NF$2:$NF$60=G$1),0),$F11-1966)} -> 238319 | H11: {=INDEX(GMW!$A$2:$NF$60,MATCH(1,(GMW!$NE$2:$NE$60=H$3)*(GMW!$ND$2:$ND$60=H$4)*(GMW!$NF$2:$NF$60=H$1),0),$F11-1966)} -> 1524.325 | I11: {=INDEX(GMW!$A$2:$NF$60,MATCH(1,(GMW!$NE$2:$NE$60=I$3)*(GMW!$ND$2:$ND$60=I$4)*(GMW!$NF$2:$NF$60=I$1),0),$F11-1966)} -> 51759.14 | J11: {=INDEX(GMW!$A$2:$NF$60,MATCH(1,(GMW!$NE$2:$NE$60=J$3)*(GMW!$ND$2:$ND$60=J$4)*(GMW!$NF$2:$NF$60=J$1),0),$F11-1966)} -> 394.27 | K11: {=INDEX(GMW!$A$2:$NF$60,MATCH(1,(GMW!$NE$2:$NE$60=K$3)*(GMW!$ND$2:$ND$60=K$4)*(GMW!$NF$2:$NF$60=K$1),0),$F11-1966)} -> 259.118 | L11: {=INDEX(GMW!$A$2:$NF$60,MATCH(1,(GMW!$NE$2:$NE$60=L$3)*(GMW!$ND$2:$ND$60=L$4)*(GMW!$NF$2:$NF$60=L$1),0),$F11-1966)} -> 244.7785 | M11: {=INDEX(GMW!$A$2:$NF$60,MATCH(1,(GMW!$NE$2:$NE$60=M$3)*(GMW!$ND$2:$ND$60=M$4)*(GMW!$NF$2:$NF$60=M$1),0),$F11-1966)} -> 181552 | N11: {=INDEX(GMW!$A$2:$NF$60,MATCH(1,(GMW!$NE$2:$NE$60=N$3)*(GMW!$ND$2:$ND$60=N$4)*(GMW!$NF$2:$NF$60=N$1),0),$F11-1966)} -> -788 | ... AH11: {=INDEX(GMW!$A$2:$NF$60,MATCH(1,(GMW!$NE$2:$NE$60=AH$3)*(GMW!$ND$2:$ND$60=AH$4)*(GMW!$NF$2:$NF$60=AH$1),0),$F11-1966)} -> 37325
B12: =+B8+1 -> 1974 | C12: =+C8+1 -> 1974 | F12: =+F11+1 -> 1978 | G12: {=INDEX(GMW!$A$2:$NF$60,MATCH(1,(GMW!$NE$2:$NE$60=G$3)*(GMW!$ND$2:$ND$60=G$4)*(GMW!$NF$2:$NF$60=G$1),0),$F12-1966)} -> 241752 | H12: {=INDEX(GMW!$A$2:$NF$60,MATCH(1,(GMW!$NE$2:$NE$60=H$3)*(GMW!$ND$2:$ND$60=H$4)*(GMW!$NF$2:$NF$60=H$1),0),$F12-1966)} -> 1527.95 | I12: {=INDEX(GMW!$A$2:$NF$60,MATCH(1,(GMW!$NE$2:$NE$60=I$3)*(GMW!$ND$2:$ND$60=I$4)*(GMW!$NF$2:$NF$60=I$1),0),$F12-1966)} -> 52134.51 | J12: {=INDEX(GMW!$A$2:$NF$60,MATCH(1,(GMW!$NE$2:$NE$60=J$3)*(GMW!$ND$2:$ND$60=J$4)*(GMW!$NF$2:$NF$60=J$1),0),$F12-1966)} -> 393.93 | K12: {=INDEX(GMW!$A$2:$NF$60,MATCH(1,(GMW!$NE$2:$NE$60=K$3)*(GMW!$ND$2:$ND$60=K$4)*(GMW!$NF$2:$NF$60=K$1),0),$F12-1966)} -> 260.946 | L12: {=INDEX(GMW!$A$2:$NF$60,MATCH(1,(GMW!$NE$2:$NE$60=L$3)*(GMW!$ND$2:$ND$60=L$4)*(GMW!$NF$2:$NF$60=L$1),0),$F12-1966)} -> 247.1172 | M12: {=INDEX(GMW!$A$2:$NF$60,MATCH(1,(GMW!$NE$2:$NE$60=M$3)*(GMW!$ND$2:$ND$60=M$4)*(GMW!$NF$2:$NF$60=M$1),0),$F12-1966)} -> 183414.3 | N12: {=INDEX(GMW!$A$2:$NF$60,MATCH(1,(GMW!$NE$2:$NE$60=N$3)*(GMW!$ND$2:$ND$60=N$4)*(GMW!$NF$2:$NF$60=N$1),0),$F12-1966)} -> -631 | ... AH12: {=INDEX(GMW!$A$2:$NF$60,MATCH(1,(GMW!$NE$2:$NE$60=AH$3)*(GMW!$ND$2:$ND$60=AH$4)*(GMW!$NF$2:$NF$60=AH$1),0),$F12-1966)} -> 38990
B13: =+B9+1 -> 1974 | C13: =+C9+1 -> 1974 | F13: =+F12+1 -> 1979 | G13: {=INDEX(GMW!$A$2:$NF$60,MATCH(1,(GMW!$NE$2:$NE$60=G$3)*(GMW!$ND$2:$ND$60=G$4)*(GMW!$NF$2:$NF$60=G$1),0),$F13-1966)} -> 243197 | H13: {=INDEX(GMW!$A$2:$NF$60,MATCH(1,(GMW!$NE$2:$NE$60=H$3)*(GMW!$ND$2:$ND$60=H$4)*(GMW!$NF$2:$NF$60=H$1),0),$F13-1966)} -> 1513.5 | I13: {=INDEX(GMW!$A$2:$NF$60,MATCH(1,(GMW!$NE$2:$NE$60=I$3)*(GMW!$ND$2:$ND$60=I$4)*(GMW!$NF$2:$NF$60=I$1),0),$F13-1966)} -> 52810.48 | J13: {=INDEX(GMW!$A$2:$NF$60,MATCH(1,(GMW!$NE$2:$NE$60=J$3)*(GMW!$ND$2:$ND$60=J$4)*(GMW!$NF$2:$NF$60=J$1),0),$F13-1966)} -> 394.09 | K13: {=INDEX(GMW!$A$2:$NF$60,MATCH(1,(GMW!$NE$2:$NE$60=K$3)*(GMW!$ND$2:$ND$60=K$4)*(GMW!$NF$2:$NF$60=K$1),0),$F13-1966)} -> 263.841 | L13: {=INDEX(GMW!$A$2:$NF$60,MATCH(1,(GMW!$NE$2:$NE$60=L$3)*(GMW!$ND$2:$ND$60=L$4)*(GMW!$NF$2:$NF$60=L$1),0),$F13-1966)} -> 247.5283 | M13: {=INDEX(GMW!$A$2:$NF$60,MATCH(1,(GMW!$NE$2:$NE$60=M$3)*(GMW!$ND$2:$ND$60=M$4)*(GMW!$NF$2:$NF$60=M$1),0),$F13-1966)} -> 183449.5 | N13: {=INDEX(GMW!$A$2:$NF$60,MATCH(1,(GMW!$NE$2:$NE$60=N$3)*(GMW!$ND$2:$ND$60=N$4)*(GMW!$NF$2:$NF$60=N$1),0),$F13-1966)} -> -1345 | ... AH13: {=INDEX(GMW!$A$2:$NF$60,MATCH(1,(GMW!$NE$2:$NE$60=AH$3)*(GMW!$ND$2:$ND$60=AH$4)*(GMW!$NF$2:$NF$60=AH$1),0),$F13-1966)} -> 40561
B14: =+B10+1 -> 1974 | C14: =+C10+1 -> 1974 | E14: =+E10+1 -> 1974 | F14: =+F13+1 -> 1980 | G14: {=INDEX(GMW!$A$2:$NF$60,MATCH(1,(GMW!$NE$2:$NE$60=G$3)*(GMW!$ND$2:$ND$60=G$4)*(GMW!$NF$2:$NF$60=G$1),0),$F14-1966)} -> 239612 | H14: {=INDEX(GMW!$A$2:$NF$60,MATCH(1,(GMW!$NE$2:$NE$60=H$3)*(GMW!$ND$2:$ND$60=H$4)*(GMW!$NF$2:$NF$60=H$1),0),$F14-1966)} -> 1507.625 | I14: {=INDEX(GMW!$A$2:$NF$60,MATCH(1,(GMW!$NE$2:$NE$60=I$3)*(GMW!$ND$2:$ND$60=I$4)*(GMW!$NF$2:$NF$60=I$1),0),$F14-1966)} -> 52526.84 | J14: {=INDEX(GMW!$A$2:$NF$60,MATCH(1,(GMW!$NE$2:$NE$60=J$3)*(GMW!$ND$2:$ND$60=J$4)*(GMW!$NF$2:$NF$60=J$1),0),$F14-1966)} -> 389.05 | K14: {=INDEX(GMW!$A$2:$NF$60,MATCH(1,(GMW!$NE$2:$NE$60=K$3)*(GMW!$ND$2:$ND$60=K$4)*(GMW!$NF$2:$NF$60=K$1),0),$F14-1966)} -> 259.134 | L14: {=INDEX(GMW!$A$2:$NF$60,MATCH(1,(GMW!$NE$2:$NE$60=L$3)*(GMW!$ND$2:$ND$60=L$4)*(GMW!$NF$2:$NF$60=L$1),0),$F14-1966)} -> 242.3543 | M14: {=INDEX(GMW!$A$2:$NF$60,MATCH(1,(GMW!$NE$2:$NE$60=M$3)*(GMW!$ND$2:$ND$60=M$4)*(GMW!$NF$2:$NF$60=M$1),0),$F14-1966)} -> 182493.8 | N14: {=INDEX(GMW!$A$2:$NF$60,MATCH(1,(GMW!$NE$2:$NE$60=N$3)*(GMW!$ND$2:$ND$60=N$4)*(GMW!$NF$2:$NF$60=N$1),0),$F14-1966)} -> -1546 | ... AH14: {=INDEX(GMW!$A$2:$NF$60,MATCH(1,(GMW!$NE$2:$NE$60=AH$3)*(GMW!$ND$2:$ND$60=AH$4)*(GMW!$NF$2:$NF$60=AH$1),0),$F14-1966)} -> 41300
A15: 1975 | B15: =+B11+1 -> 1975 | C15: =+C11+1 -> 1974 | D15: =+D11+1 -> 1974 | F15: =+F14+1 -> 1981 | G15: {=INDEX(GMW!$A$2:$NF$60,MATCH(1,(GMW!$NE$2:$NE$60=G$3)*(GMW!$ND$2:$ND$60=G$4)*(GMW!$NF$2:$NF$60=G$1),0),$F15-1966)} -> 239702 | H15: {=INDEX(GMW!$A$2:$NF$60,MATCH(1,(GMW!$NE$2:$NE$60=H$3)*(GMW!$ND$2:$ND$60=H$4)*(GMW!$NF$2:$NF$60=H$1),0),$F15-1966)} -> 1489.25 | I15: {=INDEX(GMW!$A$2:$NF$60,MATCH(1,(GMW!$NE$2:$NE$60=I$3)*(GMW!$ND$2:$ND$60=I$4)*(GMW!$NF$2:$NF$60=I$1),0),$F15-1966)} -> 52595.21 | J15: {=INDEX(GMW!$A$2:$NF$60,MATCH(1,(GMW!$NE$2:$NE$60=J$3)*(GMW!$ND$2:$ND$60=J$4)*(GMW!$NF$2:$NF$60=J$1),0),$F15-1966)} -> 386.82 | K15: {=INDEX(GMW!$A$2:$NF$60,MATCH(1,(GMW!$NE$2:$NE$60=K$3)*(GMW!$ND$2:$ND$60=K$4)*(GMW!$NF$2:$NF$60=K$1),0),$F15-1966)} -> 257.134 | L15: {=INDEX(GMW!$A$2:$NF$60,MATCH(1,(GMW!$NE$2:$NE$60=L$3)*(GMW!$ND$2:$ND$60=L$4)*(GMW!$NF$2:$NF$60=L$1),0),$F15-1966)} -> 238.1379 | M15: {=INDEX(GMW!$A$2:$NF$60,MATCH(1,(GMW!$NE$2:$NE$60=M$3)*(GMW!$ND$2:$ND$60=M$4)*(GMW!$NF$2:$NF$60=M$1),0),$F15-1966)} -> 181499.5 | N15: {=INDEX(GMW!$A$2:$NF$60,MATCH(1,(GMW!$NE$2:$NE$60=N$3)*(GMW!$ND$2:$ND$60=N$4)*(GMW!$NF$2:$NF$60=N$1),0),$F15-1966)} -> -2070 | ... AH15: {=INDEX(GMW!$A$2:$NF$60,MATCH(1,(GMW!$NE$2:$NE$60=AH$3)*(GMW!$ND$2:$ND$60=AH$4)*(GMW!$NF$2:$NF$60=AH$1),0),$F15-1966)} -> 41861
B16: =+B12+1 -> 1975 | C16: =+C12+1 -> 1975 | F16: =+F15+1 -> 1982 | G16: {=INDEX(GMW!$A$2:$NF$60,MATCH(1,(GMW!$NE$2:$NE$60=G$3)*(GMW!$ND$2:$ND$60=G$4)*(GMW!$NF$2:$NF$60=G$1),0),$F16-1966)} -> 235807 | H16: {=INDEX(GMW!$A$2:$NF$60,MATCH(1,(GMW!$NE$2:$NE$60=H$3)*(GMW!$ND$2:$ND$60=H$4)*(GMW!$NF$2:$NF$60=H$1),0),$F16-1966)} -> 1499.9 | I16: {=INDEX(GMW!$A$2:$NF$60,MATCH(1,(GMW!$NE$2:$NE$60=I$3)*(GMW!$ND$2:$ND$60=I$4)*(GMW!$NF$2:$NF$60=I$1),0),$F16-1966)} -> 53789.34 | J16: {=INDEX(GMW!$A$2:$NF$60,MATCH(1,(GMW!$NE$2:$NE$60=J$3)*(GMW!$ND$2:$ND$60=J$4)*(GMW!$NF$2:$NF$60=J$1),0),$F16-1966)} -> 384.92 | K16: {=INDEX(GMW!$A$2:$NF$60,MATCH(1,(GMW!$NE$2:$NE$60=K$3)*(GMW!$ND$2:$ND$60=K$4)*(GMW!$NF$2:$NF$60=K$1),0),$F16-1966)} -> 257.051 | L16: {=INDEX(GMW!$A$2:$NF$60,MATCH(1,(GMW!$NE$2:$NE$60=L$3)*(GMW!$ND$2:$ND$60=L$4)*(GMW!$NF$2:$NF$60=L$1),0),$F16-1966)} -> 238.0164 | M16: {=INDEX(GMW!$A$2:$NF$60,MATCH(1,(GMW!$NE$2:$NE$60=M$3)*(GMW!$ND$2:$ND$60=M$4)*(GMW!$NF$2:$NF$60=M$1),0),$F16-1966)} -> 183828 | N16: {=INDEX(GMW!$A$2:$NF$60,MATCH(1,(GMW!$NE$2:$NE$60=N$3)*(GMW!$ND$2:$ND$60=N$4)*(GMW!$NF$2:$NF$60=N$1),0),$F16-1966)} -> -1658 | ... AH16: {=INDEX(GMW!$A$2:$NF$60,MATCH(1,(GMW!$NE$2:$NE$60=AH$3)*(GMW!$ND$2:$ND$60=AH$4)*(GMW!$NF$2:$NF$60=AH$1),0),$F16-1966)} -> 43406
B17: =+B13+1 -> 1975 | C17: =+C13+1 -> 1975 | F17: =+F16+1 -> 1983 | G17: {=INDEX(GMW!$A$2:$NF$60,MATCH(1,(GMW!$NE$2:$NE$60=G$3)*(GMW!$ND$2:$ND$60=G$4)*(GMW!$NF$2:$NF$60=G$1),0),$F17-1966)} -> 235105 | H17: {=INDEX(GMW!$A$2:$NF$60,MATCH(1,(GMW!$NE$2:$NE$60=H$3)*(GMW!$ND$2:$ND$60=H$4)*(GMW!$NF$2:$NF$60=H$1),0),$F17-1966)} -> 1525.575 | I17: {=INDEX(GMW!$A$2:$NF$60,MATCH(1,(GMW!$NE$2:$NE$60=I$3)*(GMW!$ND$2:$ND$60=I$4)*(GMW!$NF$2:$NF$60=I$1),0),$F17-1966)} -> 54409.61 | J17: {=INDEX(GMW!$A$2:$NF$60,MATCH(1,(GMW!$NE$2:$NE$60=J$3)*(GMW!$ND$2:$ND$60=J$4)*(GMW!$NF$2:$NF$60=J$1),0),$F17-1966)} -> 389.05 | K17: {=INDEX(GMW!$A$2:$NF$60,MATCH(1,(GMW!$NE$2:$NE$60=K$3)*(GMW!$ND$2:$ND$60=K$4)*(GMW!$NF$2:$NF$60=K$1),0),$F17-1966)} -> 256.883 | L17: {=INDEX(GMW!$A$2:$NF$60,MATCH(1,(GMW!$NE$2:$NE$60=L$3)*(GMW!$ND$2:$ND$60=L$4)*(GMW!$NF$2:$NF$60=L$1),0),$F17-1966)} -> 241.3983 | M17: {=INDEX(GMW!$A$2:$NF$60,MATCH(1,(GMW!$NE$2:$NE$60=M$3)*(GMW!$ND$2:$ND$60=M$4)*(GMW!$NF$2:$NF$60=M$1),0),$F17-1966)} -> 187354.8 | N17: {=INDEX(GMW!$A$2:$NF$60,MATCH(1,(GMW!$NE$2:$NE$60=N$3)*(GMW!$ND$2:$ND$60=N$4)*(GMW!$NF$2:$NF$60=N$1),0),$F17-1966)} -> -1874 | ... AH17: {=INDEX(GMW!$A$2:$NF$60,MATCH(1,(GMW!$NE$2:$NE$60=AH$3)*(GMW!$ND$2:$ND$60=AH$4)*(GMW!$NF$2:$NF$60=AH$1),0),$F17-1966)} -> 45554
B18: =+B14+1 -> 1975 | C18: =+C14+1 -> 1975 | E18: =+E14+1 -> 1975 | F18: =+F17+1 -> 1984 | G18: {=INDEX(GMW!$A$2:$NF$60,MATCH(1,(GMW!$NE$2:$NE$60=G$3)*(GMW!$ND$2:$ND$60=G$4)*(GMW!$NF$2:$NF$60=G$1),0),$F18-1966)} -> 237747 | H18: {=INDEX(GMW!$A$2:$NF$60,MATCH(1,(GMW!$NE$2:$NE$60=H$3)*(GMW!$ND$2:$ND$60=H$4)*(GMW!$NF$2:$NF$60=H$1),0),$F18-1966)} -> 1546.125 | I18: {=INDEX(GMW!$A$2:$NF$60,MATCH(1,(GMW!$NE$2:$NE$60=I$3)*(GMW!$ND$2:$ND$60=I$4)*(GMW!$NF$2:$NF$60=I$1),0),$F18-1966)} -> 54986.97 | J18: {=INDEX(GMW!$A$2:$NF$60,MATCH(1,(GMW!$NE$2:$NE$60=J$3)*(GMW!$ND$2:$ND$60=J$4)*(GMW!$NF$2:$NF$60=J$1),0),$F18-1966)} -> 396.83 | K18: {=INDEX(GMW!$A$2:$NF$60,MATCH(1,(GMW!$NE$2:$NE$60=K$3)*(GMW!$ND$2:$ND$60=K$4)*(GMW!$NF$2:$NF$60=K$1),0),$F18-1966)} -> 262.376 | L18: {=INDEX(GMW!$A$2:$NF$60,MATCH(1,(GMW!$NE$2:$NE$60=L$3)*(GMW!$ND$2:$ND$60=L$4)*(GMW!$NF$2:$NF$60=L$1),0),$F18-1966)} -> 244.1035 | M18: {=INDEX(GMW!$A$2:$NF$60,MATCH(1,(GMW!$NE$2:$NE$60=M$3)*(GMW!$ND$2:$ND$60=M$4)*(GMW!$NF$2:$NF$60=M$1),0),$F18-1966)} -> 189522.8 | N18: {=INDEX(GMW!$A$2:$NF$60,MATCH(1,(GMW!$NE$2:$NE$60=N$3)*(GMW!$ND$2:$ND$60=N$4)*(GMW!$NF$2:$NF$60=N$1),0),$F18-1966)} -> -1609 | ... AH18: {=INDEX(GMW!$A$2:$NF$60,MATCH(1,(GMW!$NE$2:$NE$60=AH$3)*(GMW!$ND$2:$ND$60=AH$4)*(GMW!$NF$2:$NF$60=AH$1),0),$F18-1966)} -> 47107
A19: 1976 | B19: =+B15+1 -> 1976 | C19: =+C15+1 -> 1975 | D19: =+D15+1 -> 1975 | F19: =+F18+1 -> 1985 | G19: {=INDEX(GMW!$A$2:$NF$60,MATCH(1,(GMW!$NE$2:$NE$60=G$3)*(GMW!$ND$2:$ND$60=G$4)*(GMW!$NF$2:$NF$60=G$1),0),$F19-1966)} -> 241709 | H19: {=INDEX(GMW!$A$2:$NF$60,MATCH(1,(GMW!$NE$2:$NE$60=H$3)*(GMW!$ND$2:$ND$60=H$4)*(GMW!$NF$2:$NF$60=H$1),0),$F19-1966)} -> 1580.9 | I19: {=INDEX(GMW!$A$2:$NF$60,MATCH(1,(GMW!$NE$2:$NE$60=I$3)*(GMW!$ND$2:$ND$60=I$4)*(GMW!$NF$2:$NF$60=I$1),0),$F19-1966)} -> 55458.37 | J19: {=INDEX(GMW!$A$2:$NF$60,MATCH(1,(GMW!$NE$2:$NE$60=J$3)*(GMW!$ND$2:$ND$60=J$4)*(GMW!$NF$2:$NF$60=J$1),0),$F19-1966)} -> 400.23 | K19: {=INDEX(GMW!$A$2:$NF$60,MATCH(1,(GMW!$NE$2:$NE$60=K$3)*(GMW!$ND$2:$ND$60=K$4)*(GMW!$NF$2:$NF$60=K$1),0),$F19-1966)} -> 264.851 | L19: {=INDEX(GMW!$A$2:$NF$60,MATCH(1,(GMW!$NE$2:$NE$60=L$3)*(GMW!$ND$2:$ND$60=L$4)*(GMW!$NF$2:$NF$60=L$1),0),$F19-1966)} -> 248.4038 | M19: {=INDEX(GMW!$A$2:$NF$60,MATCH(1,(GMW!$NE$2:$NE$60=M$3)*(GMW!$ND$2:$ND$60=M$4)*(GMW!$NF$2:$NF$60=M$1),0),$F19-1966)} -> 192825.5 | N19: {=INDEX(GMW!$A$2:$NF$60,MATCH(1,(GMW!$NE$2:$NE$60=N$3)*(GMW!$ND$2:$ND$60=N$4)*(GMW!$NF$2:$NF$60=N$1),0),$F19-1966)} -> -2510 | ... AH19: {=INDEX(GMW!$A$2:$NF$60,MATCH(1,(GMW!$NE$2:$NE$60=AH$3)*(GMW!$ND$2:$ND$60=AH$4)*(GMW!$NF$2:$NF$60=AH$1),0),$F19-1966)} -> 49062
B20: =+B16+1 -> 1976 | C20: =+C16+1 -> 1976 | F20: =+F19+1 -> 1986 | G20: {=INDEX(GMW!$A$2:$NF$60,MATCH(1,(GMW!$NE$2:$NE$60=G$3)*(GMW!$ND$2:$ND$60=G$4)*(GMW!$NF$2:$NF$60=G$1),0),$F20-1966)} -> 241380 | H20: {=INDEX(GMW!$A$2:$NF$60,MATCH(1,(GMW!$NE$2:$NE$60=H$3)*(GMW!$ND$2:$ND$60=H$4)*(GMW!$NF$2:$NF$60=H$1),0),$F20-1966)} -> 1592.5 | I20: {=INDEX(GMW!$A$2:$NF$60,MATCH(1,(GMW!$NE$2:$NE$60=I$3)*(GMW!$ND$2:$ND$60=I$4)*(GMW!$NF$2:$NF$60=I$1),0),$F20-1966)} -> 55787.51 | J20: {=INDEX(GMW!$A$2:$NF$60,MATCH(1,(GMW!$NE$2:$NE$60=J$3)*(GMW!$ND$2:$ND$60=J$4)*(GMW!$NF$2:$NF$60=J$1),0),$F20-1966)} -> 406.27 | K20: {=INDEX(GMW!$A$2:$NF$60,MATCH(1,(GMW!$NE$2:$NE$60=K$3)*(GMW!$ND$2:$ND$60=K$4)*(GMW!$NF$2:$NF$60=K$1),0),$F20-1966)} -> 268.472 | L20: {=INDEX(GMW!$A$2:$NF$60,MATCH(1,(GMW!$NE$2:$NE$60=L$3)*(GMW!$ND$2:$ND$60=L$4)*(GMW!$NF$2:$NF$60=L$1),0),$F20-1966)} -> 252.8942 | M20: {=INDEX(GMW!$A$2:$NF$60,MATCH(1,(GMW!$NE$2:$NE$60=M$3)*(GMW!$ND$2:$ND$60=M$4)*(GMW!$NF$2:$NF$60=M$1),0),$F20-1966)} -> 196983.8 | N20: {=INDEX(GMW!$A$2:$NF$60,MATCH(1,(GMW!$NE$2:$NE$60=N$3)*(GMW!$ND$2:$ND$60=N$4)*(GMW!$NF$2:$NF$60=N$1),0),$F20-1966)} -> -1926 | ... AH20: {=INDEX(GMW!$A$2:$NF$60,MATCH(1,(GMW!$NE$2:$NE$60=AH$3)*(GMW!$ND$2:$ND$60=AH$4)*(GMW!$NF$2:$NF$60=AH$1),0),$F20-1966)} -> 51563
B21: =+B17+1 -> 1976 | C21: =+C17+1 -> 1976 | F21: =+F20+1 -> 1987 | G21: {=INDEX(GMW!$A$2:$NF$60,MATCH(1,(GMW!$NE$2:$NE$60=G$3)*(GMW!$ND$2:$ND$60=G$4)*(GMW!$NF$2:$NF$60=G$1),0),$F21-1966)} -> 244367 | H21: {=INDEX(GMW!$A$2:$NF$60,MATCH(1,(GMW!$NE$2:$NE$60=H$3)*(GMW!$ND$2:$ND$60=H$4)*(GMW!$NF$2:$NF$60=H$1),0),$F21-1966)} -> 1601.225 | I21: {=INDEX(GMW!$A$2:$NF$60,MATCH(1,(GMW!$NE$2:$NE$60=I$3)*(GMW!$ND$2:$ND$60=I$4)*(GMW!$NF$2:$NF$60=I$1),0),$F21-1966)} -> 56585.37 | J21: {=INDEX(GMW!$A$2:$NF$60,MATCH(1,(GMW!$NE$2:$NE$60=J$3)*(GMW!$ND$2:$ND$60=J$4)*(GMW!$NF$2:$NF$60=J$1),0),$F21-1966)} -> 406.44 | K21: {=INDEX(GMW!$A$2:$NF$60,MATCH(1,(GMW!$NE$2:$NE$60=K$3)*(GMW!$ND$2:$ND$60=K$4)*(GMW!$NF$2:$NF$60=K$1),0),$F21-1966)} -> 271.536 | L21: {=INDEX(GMW!$A$2:$NF$60,MATCH(1,(GMW!$NE$2:$NE$60=L$3)*(GMW!$ND$2:$ND$60=L$4)*(GMW!$NF$2:$NF$60=L$1),0),$F21-1966)} -> 259.3207 | M21: {=INDEX(GMW!$A$2:$NF$60,MATCH(1,(GMW!$NE$2:$NE$60=M$3)*(GMW!$ND$2:$ND$60=M$4)*(GMW!$NF$2:$NF$60=M$1),0),$F21-1966)} -> 197893.3 | N21: {=INDEX(GMW!$A$2:$NF$60,MATCH(1,(GMW!$NE$2:$NE$60=N$3)*(GMW!$ND$2:$ND$60=N$4)*(GMW!$NF$2:$NF$60=N$1),0),$F21-1966)} -> -2444 | ... AH21: {=INDEX(GMW!$A$2:$NF$60,MATCH(1,(GMW!$NE$2:$NE$60=AH$3)*(GMW!$ND$2:$ND$60=AH$4)*(GMW!$NF$2:$NF$60=AH$1),0),$F21-1966)} -> 52112
B22: =+B18+1 -> 1976 | C22: =+C18+1 -> 1976 | E22: =+E18+1 -> 1976 | F22: =+F21+1 -> 1988 | G22: {=INDEX(GMW!$A$2:$NF$60,MATCH(1,(GMW!$NE$2:$NE$60=G$3)*(GMW!$ND$2:$ND$60=G$4)*(GMW!$NF$2:$NF$60=G$1),0),$F22-1966)} -> 249511 | H22: {=INDEX(GMW!$A$2:$NF$60,MATCH(1,(GMW!$NE$2:$NE$60=H$3)*(GMW!$ND$2:$ND$60=H$4)*(GMW!$NF$2:$NF$60=H$1),0),$F22-1966)} -> 1612.8 | I22: {=INDEX(GMW!$A$2:$NF$60,MATCH(1,(GMW!$NE$2:$NE$60=I$3)*(GMW!$ND$2:$ND$60=I$4)*(GMW!$NF$2:$NF$60=I$1),0),$F22-1966)} -> 56653.35 | J22: {=INDEX(GMW!$A$2:$NF$60,MATCH(1,(GMW!$NE$2:$NE$60=J$3)*(GMW!$ND$2:$ND$60=J$4)*(GMW!$NF$2:$NF$60=J$1),0),$F22-1966)} -> 413.88 | K22: {=INDEX(GMW!$A$2:$NF$60,MATCH(1,(GMW!$NE$2:$NE$60=K$3)*(GMW!$ND$2:$ND$60=K$4)*(GMW!$NF$2:$NF$60=K$1),0),$F22-1966)} -> 273.453 | L22: {=INDEX(GMW!$A$2:$NF$60,MATCH(1,(GMW!$NE$2:$NE$60=L$3)*(GMW!$ND$2:$ND$60=L$4)*(GMW!$NF$2:$NF$60=L$1),0),$F22-1966)} -> 263.8197 | M22: {=INDEX(GMW!$A$2:$NF$60,MATCH(1,(GMW!$NE$2:$NE$60=M$3)*(GMW!$ND$2:$ND$60=M$4)*(GMW!$NF$2:$NF$60=M$1),0),$F22-1966)} -> 198213 | N22: {=INDEX(GMW!$A$2:$NF$60,MATCH(1,(GMW!$NE$2:$NE$60=N$3)*(GMW!$ND$2:$ND$60=N$4)*(GMW!$NF$2:$NF$60=N$1),0),$F22-1966)} -> -1081 | ... AH22: {=INDEX(GMW!$A$2:$NF$60,MATCH(1,(GMW!$NE$2:$NE$60=AH$3)*(GMW!$ND$2:$ND$60=AH$4)*(GMW!$NF$2:$NF$60=AH$1),0),$F22-1966)} -> 53249
A23: 1977 | B23: =+B19+1 -> 1977 | C23: =+C19+1 -> 1976 | D23: =+D19+1 -> 1976 | F23: =+F22+1 -> 1989 | G23: {=INDEX(GMW!$A$2:$NF$60,MATCH(1,(GMW!$NE$2:$NE$60=G$3)*(GMW!$ND$2:$ND$60=G$4)*(GMW!$NF$2:$NF$60=G$1),0),$F23-1966)} -> 249671 | H23: {=INDEX(GMW!$A$2:$NF$60,MATCH(1,(GMW!$NE$2:$NE$60=H$3)*(GMW!$ND$2:$ND$60=H$4)*(GMW!$NF$2:$NF$60=H$1),0),$F23-1966)} -> 1631.925 | I23: {=INDEX(GMW!$A$2:$NF$60,MATCH(1,(GMW!$NE$2:$NE$60=I$3)*(GMW!$ND$2:$ND$60=I$4)*(GMW!$NF$2:$NF$60=I$1),0),$F23-1966)} -> 57921.84 | J23: {=INDEX(GMW!$A$2:$NF$60,MATCH(1,(GMW!$NE$2:$NE$60=J$3)*(GMW!$ND$2:$ND$60=J$4)*(GMW!$NF$2:$NF$60=J$1),0),$F23-1966)} -> 417.53 | K23: {=INDEX(GMW!$A$2:$NF$60,MATCH(1,(GMW!$NE$2:$NE$60=K$3)*(GMW!$ND$2:$ND$60=K$4)*(GMW!$NF$2:$NF$60=K$1),0),$F23-1966)} -> 276.547 | L23: {=INDEX(GMW!$A$2:$NF$60,MATCH(1,(GMW!$NE$2:$NE$60=L$3)*(GMW!$ND$2:$ND$60=L$4)*(GMW!$NF$2:$NF$60=L$1),0),$F23-1966)} -> 263.9241 | M23: {=INDEX(GMW!$A$2:$NF$60,MATCH(1,(GMW!$NE$2:$NE$60=M$3)*(GMW!$ND$2:$ND$60=M$4)*(GMW!$NF$2:$NF$60=M$1),0),$F23-1966)} -> 201253.3 | N23: {=INDEX(GMW!$A$2:$NF$60,MATCH(1,(GMW!$NE$2:$NE$60=N$3)*(GMW!$ND$2:$ND$60=N$4)*(GMW!$NF$2:$NF$60=N$1),0),$F23-1966)} -> -1553 | ... AH23: {=INDEX(GMW!$A$2:$NF$60,MATCH(1,(GMW!$NE$2:$NE$60=AH$3)*(GMW!$ND$2:$ND$60=AH$4)*(GMW!$NF$2:$NF$60=AH$1),0),$F23-1966)} -> 54978
B24: =+B20+1 -> 1977 | C24: =+C20+1 -> 1977 | F24: =+F23+1 -> 1990 | G24: {=INDEX(GMW!$A$2:$NF$60,MATCH(1,(GMW!$NE$2:$NE$60=G$3)*(GMW!$ND$2:$ND$60=G$4)*(GMW!$NF$2:$NF$60=G$1),0),$F24-1966)} -> 247936 | H24: {=INDEX(GMW!$A$2:$NF$60,MATCH(1,(GMW!$NE$2:$NE$60=H$3)*(GMW!$ND$2:$ND$60=H$4)*(GMW!$NF$2:$NF$60=H$1),0),$F24-1966)} -> 1663.625 | I24: {=INDEX(GMW!$A$2:$NF$60,MATCH(1,(GMW!$NE$2:$NE$60=I$3)*(GMW!$ND$2:$ND$60=I$4)*(GMW!$NF$2:$NF$60=I$1),0),$F24-1966)} -> 58330.15 | J24: {=INDEX(GMW!$A$2:$NF$60,MATCH(1,(GMW!$NE$2:$NE$60=J$3)*(GMW!$ND$2:$ND$60=J$4)*(GMW!$NF$2:$NF$60=J$1),0),$F24-1966)} -> 419.84 | K24: {=INDEX(GMW!$A$2:$NF$60,MATCH(1,(GMW!$NE$2:$NE$60=K$3)*(GMW!$ND$2:$ND$60=K$4)*(GMW!$NF$2:$NF$60=K$1),0),$F24-1966)} -> 277.655 | L24: {=INDEX(GMW!$A$2:$NF$60,MATCH(1,(GMW!$NE$2:$NE$60=L$3)*(GMW!$ND$2:$ND$60=L$4)*(GMW!$NF$2:$NF$60=L$1),0),$F24-1966)} -> 262.4543 | M24: {=INDEX(GMW!$A$2:$NF$60,MATCH(1,(GMW!$NE$2:$NE$60=M$3)*(GMW!$ND$2:$ND$60=M$4)*(GMW!$NF$2:$NF$60=M$1),0),$F24-1966)} -> 202280.3 | N24: {=INDEX(GMW!$A$2:$NF$60,MATCH(1,(GMW!$NE$2:$NE$60=N$3)*(GMW!$ND$2:$ND$60=N$4)*(GMW!$NF$2:$NF$60=N$1),0),$F24-1966)} -> -1256 | ... AH24: {=INDEX(GMW!$A$2:$NF$60,MATCH(1,(GMW!$NE$2:$NE$60=AH$3)*(GMW!$ND$2:$ND$60=AH$4)*(GMW!$NF$2:$NF$60=AH$1),0),$F24-1966)} -> 56202
B25: =+B21+1 -> 1977 | C25: =+C21+1 -> 1977 | F25: =+F24+1 -> 1991 | G25: {=INDEX(GMW!$A$2:$NF$60,MATCH(1,(GMW!$NE$2:$NE$60=G$3)*(GMW!$ND$2:$ND$60=G$4)*(GMW!$NF$2:$NF$60=G$1),0),$F25-1966)} -> 249578 | H25: {=INDEX(GMW!$A$2:$NF$60,MATCH(1,(GMW!$NE$2:$NE$60=H$3)*(GMW!$ND$2:$ND$60=H$4)*(GMW!$NF$2:$NF$60=H$1),0),$F25-1966)} -> 1693.625 | I25: {=INDEX(GMW!$A$2:$NF$60,MATCH(1,(GMW!$NE$2:$NE$60=I$3)*(GMW!$ND$2:$ND$60=I$4)*(GMW!$NF$2:$NF$60=I$1),0),$F25-1966)} -> 58729.51 | J25: {=INDEX(GMW!$A$2:$NF$60,MATCH(1,(GMW!$NE$2:$NE$60=J$3)*(GMW!$ND$2:$ND$60=J$4)*(GMW!$NF$2:$NF$60=J$1),0),$F25-1966)} -> 419.68 | K25: {=INDEX(GMW!$A$2:$NF$60,MATCH(1,(GMW!$NE$2:$NE$60=K$3)*(GMW!$ND$2:$ND$60=K$4)*(GMW!$NF$2:$NF$60=K$1),0),$F25-1966)} -> 279.927 | L25: {=INDEX(GMW!$A$2:$NF$60,MATCH(1,(GMW!$NE$2:$NE$60=L$3)*(GMW!$ND$2:$ND$60=L$4)*(GMW!$NF$2:$NF$60=L$1),0),$F25-1966)} -> 259.9991 | M25: {=INDEX(GMW!$A$2:$NF$60,MATCH(1,(GMW!$NE$2:$NE$60=M$3)*(GMW!$ND$2:$ND$60=M$4)*(GMW!$NF$2:$NF$60=M$1),0),$F25-1966)} -> 203469.3 | N25: {=INDEX(GMW!$A$2:$NF$60,MATCH(1,(GMW!$NE$2:$NE$60=N$3)*(GMW!$ND$2:$ND$60=N$4)*(GMW!$NF$2:$NF$60=N$1),0),$F25-1966)} -> -1656 | ... AH25: {=INDEX(GMW!$A$2:$NF$60,MATCH(1,(GMW!$NE$2:$NE$60=AH$3)*(GMW!$ND$2:$ND$60=AH$4)*(GMW!$NF$2:$NF$60=AH$1),0),$F25-1966)} -> 57431
B26: =+B22+1 -> 1977 | C26: =+C22+1 -> 1977 | E26: =+E22+1 -> 1977 | F26: =+F25+1 -> 1992 | G26: {=INDEX(GMW!$A$2:$NF$60,MATCH(1,(GMW!$NE$2:$NE$60=G$3)*(GMW!$ND$2:$ND$60=G$4)*(GMW!$NF$2:$NF$60=G$1),0),$F26-1966)} -> 253819 | H26: {=INDEX(GMW!$A$2:$NF$60,MATCH(1,(GMW!$NE$2:$NE$60=H$3)*(GMW!$ND$2:$ND$60=H$4)*(GMW!$NF$2:$NF$60=H$1),0),$F26-1966)} -> 1693.65 | I26: {=INDEX(GMW!$A$2:$NF$60,MATCH(1,(GMW!$NE$2:$NE$60=I$3)*(GMW!$ND$2:$ND$60=I$4)*(GMW!$NF$2:$NF$60=I$1),0),$F26-1966)} -> 59539.25 | J26: {=INDEX(GMW!$A$2:$NF$60,MATCH(1,(GMW!$NE$2:$NE$60=J$3)*(GMW!$ND$2:$ND$60=J$4)*(GMW!$NF$2:$NF$60=J$1),0),$F26-1966)} -> 426.88 | K26: {=INDEX(GMW!$A$2:$NF$60,MATCH(1,(GMW!$NE$2:$NE$60=K$3)*(GMW!$ND$2:$ND$60=K$4)*(GMW!$NF$2:$NF$60=K$1),0),$F26-1966)} -> 282.16 | L26: {=INDEX(GMW!$A$2:$NF$60,MATCH(1,(GMW!$NE$2:$NE$60=L$3)*(GMW!$ND$2:$ND$60=L$4)*(GMW!$NF$2:$NF$60=L$1),0),$F26-1966)} -> 262.2263 | M26: {=INDEX(GMW!$A$2:$NF$60,MATCH(1,(GMW!$NE$2:$NE$60=M$3)*(GMW!$ND$2:$ND$60=M$4)*(GMW!$NF$2:$NF$60=M$1),0),$F26-1966)} -> 206693.5 | N26: {=INDEX(GMW!$A$2:$NF$60,MATCH(1,(GMW!$NE$2:$NE$60=N$3)*(GMW!$ND$2:$ND$60=N$4)*(GMW!$NF$2:$NF$60=N$1),0),$F26-1966)} -> -1371 | ... AH26: {=INDEX(GMW!$A$2:$NF$60,MATCH(1,(GMW!$NE$2:$NE$60=AH$3)*(GMW!$ND$2:$ND$60=AH$4)*(GMW!$NF$2:$NF$60=AH$1),0),$F26-1966)} -> 58990
A27: 1978 | B27: =+B23+1 -> 1978 | C27: =+C23+1 -> 1977 | D27: =+D23+1 -> 1977 | F27: =+F26+1 -> 1993 | G27: {=INDEX(GMW!$A$2:$NF$60,MATCH(1,(GMW!$NE$2:$NE$60=G$3)*(GMW!$ND$2:$ND$60=G$4)*(GMW!$NF$2:$NF$60=G$1),0),$F27-1966)} -> 256193 | H27: {=INDEX(GMW!$A$2:$NF$60,MATCH(1,(GMW!$NE$2:$NE$60=H$3)*(GMW!$ND$2:$ND$60=H$4)*(GMW!$NF$2:$NF$60=H$1),0),$F27-1966)} -> 1699.075 | I27: {=INDEX(GMW!$A$2:$NF$60,MATCH(1,(GMW!$NE$2:$NE$60=I$3)*(GMW!$ND$2:$ND$60=I$4)*(GMW!$NF$2:$NF$60=I$1),0),$F27-1966)} -> 60686.21 | J27: {=INDEX(GMW!$A$2:$NF$60,MATCH(1,(GMW!$NE$2:$NE$60=J$3)*(GMW!$ND$2:$ND$60=J$4)*(GMW!$NF$2:$NF$60=J$1),0),$F27-1966)} -> 428.69 | K27: {=INDEX(GMW!$A$2:$NF$60,MATCH(1,(GMW!$NE$2:$NE$60=K$3)*(GMW!$ND$2:$ND$60=K$4)*(GMW!$NF$2:$NF$60=K$1),0),$F27-1966)} -> 286.062 | L27: {=INDEX(GMW!$A$2:$NF$60,MATCH(1,(GMW!$NE$2:$NE$60=L$3)*(GMW!$ND$2:$ND$60=L$4)*(GMW!$NF$2:$NF$60=L$1),0),$F27-1966)} -> 266.513 | M27: {=INDEX(GMW!$A$2:$NF$60,MATCH(1,(GMW!$NE$2:$NE$60=M$3)*(GMW!$ND$2:$ND$60=M$4)*(GMW!$NF$2:$NF$60=M$1),0),$F27-1966)} -> 208478.5 | N27: {=INDEX(GMW!$A$2:$NF$60,MATCH(1,(GMW!$NE$2:$NE$60=N$3)*(GMW!$ND$2:$ND$60=N$4)*(GMW!$NF$2:$NF$60=N$1),0),$F27-1966)} -> -2141 | ... AH27: {=INDEX(GMW!$A$2:$NF$60,MATCH(1,(GMW!$NE$2:$NE$60=AH$3)*(GMW!$ND$2:$ND$60=AH$4)*(GMW!$NF$2:$NF$60=AH$1),0),$F27-1966)} -> 60330
B28: =+B24+1 -> 1978 | C28: =+C24+1 -> 1978 | F28: =+F27+1 -> 1994 | G28: {=INDEX(GMW!$A$2:$NF$60,MATCH(1,(GMW!$NE$2:$NE$60=G$3)*(GMW!$ND$2:$ND$60=G$4)*(GMW!$NF$2:$NF$60=G$1),0),$F28-1966)} -> 259127 | H28: {=INDEX(GMW!$A$2:$NF$60,MATCH(1,(GMW!$NE$2:$NE$60=H$3)*(GMW!$ND$2:$ND$60=H$4)*(GMW!$NF$2:$NF$60=H$1),0),$F28-1966)} -> 1764.725 | I28: {=INDEX(GMW!$A$2:$NF$60,MATCH(1,(GMW!$NE$2:$NE$60=I$3)*(GMW!$ND$2:$ND$60=I$4)*(GMW!$NF$2:$NF$60=I$1),0),$F28-1966)} -> 61280.64 | J28: {=INDEX(GMW!$A$2:$NF$60,MATCH(1,(GMW!$NE$2:$NE$60=J$3)*(GMW!$ND$2:$ND$60=J$4)*(GMW!$NF$2:$NF$60=J$1),0),$F28-1966)} -> 430.44 | K28: {=INDEX(GMW!$A$2:$NF$60,MATCH(1,(GMW!$NE$2:$NE$60=K$3)*(GMW!$ND$2:$ND$60=K$4)*(GMW!$NF$2:$NF$60=K$1),0),$F28-1966)} -> 289.179 | L28: {=INDEX(GMW!$A$2:$NF$60,MATCH(1,(GMW!$NE$2:$NE$60=L$3)*(GMW!$ND$2:$ND$60=L$4)*(GMW!$NF$2:$NF$60=L$1),0),$F28-1966)} -> 271.1233 | M28: {=INDEX(GMW!$A$2:$NF$60,MATCH(1,(GMW!$NE$2:$NE$60=M$3)*(GMW!$ND$2:$ND$60=M$4)*(GMW!$NF$2:$NF$60=M$1),0),$F28-1966)} -> 209897.5 | N28: {=INDEX(GMW!$A$2:$NF$60,MATCH(1,(GMW!$NE$2:$NE$60=N$3)*(GMW!$ND$2:$ND$60=N$4)*(GMW!$NF$2:$NF$60=N$1),0),$F28-1966)} -> -1905 | ... AH28: {=INDEX(GMW!$A$2:$NF$60,MATCH(1,(GMW!$NE$2:$NE$60=AH$3)*(GMW!$ND$2:$ND$60=AH$4)*(GMW!$NF$2:$NF$60=AH$1),0),$F28-1966)} -> 62171
B29: =+B25+1 -> 1978 | C29: =+C25+1 -> 1978 | F29: =+F28+1 -> 1995 | G29: {=INDEX(GMW!$A$2:$NF$60,MATCH(1,(GMW!$NE$2:$NE$60=G$3)*(GMW!$ND$2:$ND$60=G$4)*(GMW!$NF$2:$NF$60=G$1),0),$F29-1966)} -> 262661 | H29: {=INDEX(GMW!$A$2:$NF$60,MATCH(1,(GMW!$NE$2:$NE$60=H$3)*(GMW!$ND$2:$ND$60=H$4)*(GMW!$NF$2:$NF$60=H$1),0),$F29-1966)} -> 1782.475 | I29: {=INDEX(GMW!$A$2:$NF$60,MATCH(1,(GMW!$NE$2:$NE$60=I$3)*(GMW!$ND$2:$ND$60=I$4)*(GMW!$NF$2:$NF$60=I$1),0),$F29-1966)} -> 62081.49 | J29: {=INDEX(GMW!$A$2:$NF$60,MATCH(1,(GMW!$NE$2:$NE$60=J$3)*(GMW!$ND$2:$ND$60=J$4)*(GMW!$NF$2:$NF$60=J$1),0),$F29-1966)} -> 435.98 | K29: {=INDEX(GMW!$A$2:$NF$60,MATCH(1,(GMW!$NE$2:$NE$60=K$3)*(GMW!$ND$2:$ND$60=K$4)*(GMW!$NF$2:$NF$60=K$1),0),$F29-1966)} -> 290.979 | L29: {=INDEX(GMW!$A$2:$NF$60,MATCH(1,(GMW!$NE$2:$NE$60=L$3)*(GMW!$ND$2:$ND$60=L$4)*(GMW!$NF$2:$NF$60=L$1),0),$F29-1966)} -> 272.5487 | M29: {=INDEX(GMW!$A$2:$NF$60,MATCH(1,(GMW!$NE$2:$NE$60=M$3)*(GMW!$ND$2:$ND$60=M$4)*(GMW!$NF$2:$NF$60=M$1),0),$F29-1966)} -> 211855.5 | N29: {=INDEX(GMW!$A$2:$NF$60,MATCH(1,(GMW!$NE$2:$NE$60=N$3)*(GMW!$ND$2:$ND$60=N$4)*(GMW!$NF$2:$NF$60=N$1),0),$F29-1966)} -> -2710 | ... AH29: {=INDEX(GMW!$A$2:$NF$60,MATCH(1,(GMW!$NE$2:$NE$60=AH$3)*(GMW!$ND$2:$ND$60=AH$4)*(GMW!$NF$2:$NF$60=AH$1),0),$F29-1966)} -> 63801
