Workbook
Name Data: [1]sheet0!$C$2

Sheet CHARTS>>

Sheet DATA>>

Sheet Chart Data
A1: AE debt dynamics (2025-2029) | W1: Budget deficit in 2025 | AF1: Gross government debt in 2025 | AO1: Budget deficit & debt | AX1: Term premium | BD1: Scenario - conts to GDP change | BM1: Financial market assumptions | BN1: $/£ | BR1: RLG | BU1: CPI inflation
B2: =DataA!BK2 -> UK | C2: =DataA!BL2 -> US | D2: =DataA!BM2 -> Japan | E2: =DataA!BN2 -> Canada | F2: =DataA!BO2 -> Australia | G2: =DataA!BP2 -> Denmark | H2: =DataA!BQ2 -> Sweden | I2: =DataA!BR2 -> Switzerland | ... U2: =DataA!CD2 -> Portugal | X2: =RANK(X4,$X$4:$AD$4) -> 5 | Y2: =RANK(Y4,$X$4:$AD$4) -> 7 | Z2: =RANK(Z4,$X$4:$AD$4) -> 3 | AA2: =RANK(AA4,$X$4:$AD$4) -> 2 | AB2: =RANK(AB4,$X$4:$AD$4) -> 6 | AC2: =RANK(AC4,$X$4:$AD$4) -> 4 | AD2: =RANK(AD4,$X$4:$AD$4) -> 1 | AG2: =RANK(AG4,$AG$4:$AM$4) -> 6 | AH2: =RANK(AH4,$AG$4:$AM$4) -> 3 | AI2: =RANK(AI4,$AG$4:$AM$4) -> 1 | AJ2: =RANK(AJ4,$AG$4:$AM$4) -> 7 | AK2: =RANK(AK4,$AG$4:$AM$4) -> 4 | AL2: =RANK(AL4,$AG$4:$AM$4) -> 2 | AM2: =RANK(AM4,$AG$4:$AM$4) -> 5 | AO2: 2025 | AP2: =X3&", "&$AO2 -> UK, 2025 | AQ2: =Y3&", "&$AO2 -> US, 2025 | AR2: =Z3&", "&$AO2 -> Japan, 2025 | AS2: =AA3&", "&$AO2 -> Germany, 2025 | AT2: =AB3&", "&$AO2 -> France, 2025 | AU2: =AC3&", "&$AO2 -> Italy, 2025 | AV2: =AD3&", "&$AO2 -> Canada, 2025 | AY2: UK | AZ2: US | BA2: Germany | BB2: Japan | BF2: Consumer spending | BG2: Fixed investment | BH2: Government consumption | BI2: Net exports | BJ2: Other | BK2: GDP | BN2: Baseline | BO2: Scenario | BR2: Baseline | BS2: Scenario | BV2: Baseline | BW2: Scenario
A3: Expected effective interest rates on government debt (r) | B3: =AVERAGE(DataA!BK59:BK63) -> 4.0541862 | C3: =AVERAGE(DataA!BL59:BL63) -> 3.4859128 | D3: =AVERAGE(DataA!BM59:BM63) -> 1.0367112 | E3: =AVERAGE(DataA!BN59:BN63) -> 3.262102 | F3: =AVERAGE(DataA!BO59:BO63) -> 2.226878 | G3: =AVERAGE(DataA!BP59:BP63) -> 1.9487714 | H3: =AVERAGE(DataA!BQ59:BQ63) -> 1.5550773 | I3: =AVERAGE(DataA!BR59:BR63) -> 1.2049825 | ... U3: =AVERAGE(DataA!CD59:CD63) -> 2.322023 | X3: UK | Y3: US | Z3: Japan | AA3: Germany | AB3: France | AC3: Italy | AD3: Canada | AG3: UK | AH3: US | AI3: Japan | AJ3: Germany | AK3: France | AL3: Italy | AM3: Canada | AP3: =X3 -> UK | AQ3: =Y3 -> US | AR3: =Z3 -> Japan | AS3: =AA3 -> Germany | AT3: =AB3 -> France | AU3: =AC3 -> Italy | AV3: =AD3 -> Canada | AX3: 43831 | AY3: =DataQ!AI195 -> -1.415394 | AZ3: =DataQ!AJ195 -> -1.280833 | BA3: =DataQ!AK195 -> -1.552948 | BB3: =DataQ!AL195 -> -0.3934202 | BD3: 45931 | BE3: Q4 25 | BF3: =100*((DataScen!X218-DataScen!H218)/DataScen!$G218) -> -0.048749908 | BG3: =100*((DataScen!Y218-DataScen!I218)/DataScen!$G218) -> -0.0090382217 | BH3: =100*((DataScen!Z218-DataScen!J218)/DataScen!$G218) -> 0 | BI3: =100*(((DataScen!AA218-DataScen!AB218)-(DataScen!K218-DataScen!L218))/DataScen!$G218) -> 0.053028941 | BJ3: =BK3-BF3-BG3-BH3-BI3 -> -1.4122221e-05 | BK3: =100*((DataScen!W218/DataScen!G218)-1) -> -0.0047733108 | BM3: 45292 | BN3: =DataScen!R211 -> 1.267967 | BO3: =DataScen!AH211 -> 1.267967 | BQ3: 45292 | BR3: =DataScen!O211 -> 3.972031 | BS3: =DataScen!AE211 -> 3.972031 | BU3: 45292 | BV3: =100*((DataScen!M211/DataScen!M207)-1) -> 3.5491137 | BW3: =100*((DataScen!AC211/DataScen!AC207)-1) -> 3.5491137
A4: Expected annual average nominal GDP growth (g) | B4: =100*((DataA!AP63/DataA!AP58)^(1/5)-1) -> 3.9672499 | C4: =100*((DataA!AQ63/DataA!AQ58)^(1/5)-1) -> 4.3583029 | D4: =100*((DataA!AR63/DataA!AR58)^(1/5)-1) -> 1.7591278 | E4: =100*((DataA!AS63/DataA!AS58)^(1/5)-1) -> 3.6123652 | F4: =100*((DataA!AT63/DataA!AT58)^(1/5)-1) -> 4.3438259 | G4: =100*((DataA!AU63/DataA!AU58)^(1/5)-1) -> 3.8570117 | H4: =100*((DataA!AV63/DataA!AV58)^(1/5)-1) -> 3.778961 | I4: =100*((DataA!AW63/DataA!AW58)^(1/5)-1) -> 2.0447691 | ... U4: =100*((DataA!BI63/DataA!BI58)^(1/5)-1) -> 3.4305293 | W4: 2025 | X4: =100*('Data Q to A'!I60/'Data Q to A'!W60) -> -4.6502172 | Y4: =100*('Data Q to A'!J60/'Data Q to A'!X60) -> -7.4168274 | Z4: =100*('Data Q to A'!K60/'Data Q to A'!Y60) -> -2.9476509 | AA4: =100*('Data Q to A'!L60/'Data Q to A'!Z60) -> -2.07748 | AB4: =100*('Data Q to A'!M60/'Data Q to A'!AA60) -> -5.4069183 | AC4: =100*('Data Q to A'!N60/'Data Q to A'!AB60) -> -2.9942321 | AD4: =100*('Data Q to A'!O60/'Data Q to A'!AC60) -> -1.5593717 | AF4: 2025 | AG4: =100*('Data Q to A'!P60/'Data Q to A'!W60) -> 101.22663 | AH4: =100*('Data Q to A'!Q60/'Data Q to A'!X60) -> 139.4818 | AI4: =100*('Data Q to A'!R60/'Data Q to A'!Y60) -> 216.98578 | AJ4: =100*('Data Q to A'!S60/'Data Q to A'!Z60) -> 58.235605 | AK4: =100*('Data Q to A'!T60/'Data Q to A'!AA60) -> 127.41761 | AL4: =100*('Data Q to A'!U60/'Data Q to A'!AB60) -> 149.72344 | AM4: =100*('Data Q to A'!V60/'Data Q to A'!AC60) -> 107.05075 | AO4: Budget deficit | AP4: =X4 -> -4.6502172 | AQ4: =Y4 -> -7.4168274 | AR4: =Z4 -> -2.9476509 | AS4: =AA4 -> -2.07748 | AT4: =AB4 -> -5.4069183 | AU4: =AC4 -> -2.9942321 | AV4: =AD4 -> -1.5593717 | AX4: 43922 | AY4: =DataQ!AI196 -> -0.4839782 | AZ4: =DataQ!AJ196 -> -1.337862 | BA4: =DataQ!AK196 -> -1.164785 | BB4: =DataQ!AL196 -> -0.3085212 | BD4: 46023 | BE4: Q1 26 | BF4: =100*((DataScen!X219-DataScen!H219)/DataScen!$G219) -> -0.14160034 | BG4: =100*((DataScen!Y219-DataScen!I219)/DataScen!$G219) -> -0.0059452136 | BH4: =100*((DataScen!Z219-DataScen!J219)/DataScen!$G219) -> 0 | BI4: =100*(((DataScen!AA219-DataScen!AB219)-(DataScen!K219-DataScen!L219))/DataScen!$G219) -> 0.25815188 | BJ4: =BK4-BF4-BG4-BH4-BI4 -> -0.00074667374 | BK4: =100*((DataScen!W219/DataScen!G219)-1) -> 0.10985966 | BM4: 45383 | BN4: =DataScen!R212 -> 1.261867 | BO4: =DataScen!AH212 -> 1.261867 | BQ4: 45383 | BR4: =DataScen!O212 -> 4.183968 | BS4: =DataScen!AE212 -> 4.183968 | BU4: 45383 | BV4: =100*((DataScen!M212/DataScen!M208)-1) -> 2.1108336 | BW4: =100*((DataScen!AC212/DataScen!AC208)-1) -> 2.1108336
AO5: Government debt | AP5: =AG4 -> 101.22663 | AQ5: =AH4 -> 139.4818 | AR5: =AI4 -> 216.98578 | AS5: =AJ4 -> 58.235605 | AT5: =AK4 -> 127.41761 | AU5: =AL4 -> 149.72344 | AV5: =AM4 -> 107.05075 | AX5: 44013 | AY5: =DataQ!AI197 -> 0.2473059 | AZ5: =DataQ!AJ197 -> -1.26913 | BA5: =DataQ!AK197 -> -1.138384 | BB5: =DataQ!AL197 -> -0.1991098 | BD5: 46113 | BE5: Q2 26 | BF5: =100*((DataScen!X220-DataScen!H220)/DataScen!$G220) -> -0.36596958 | BG5: =100*((DataScen!Y220-DataScen!I220)/DataScen!$G220) -> -0.061772652 | BH5: =100*((DataScen!Z220-DataScen!J220)/DataScen!$G220) -> -0.1381065 | BI5: =100*(((DataScen!AA220-DataScen!AB220)-(DataScen!K220-DataScen!L220))/DataScen!$G220) -> 0.40580205 | BJ5: =BK5-BF5-BG5-BH5-BI5 -> 0.016613259 | BK5: =100*((DataScen!W220/DataScen!G220)-1) -> -0.14343343 | BM5: 45474 | BN5: =DataScen!R213 -> 1.300467 | BO5: =DataScen!AH213 -> 1.300467 | BQ5: 45474 | BR5: =DataScen!O213 -> 3.986061 | BS5: =DataScen!AE213 -> 3.986061 | BU5: 45474 | BV5: =100*((DataScen!M213/DataScen!M209)-1) -> 2.0547945 | BW5: =100*((DataScen!AC213/DataScen!AC209)-1) -> 2.0547945
A6: AE debt dynamics (2026-2030) | X6: 1 | Y6: 2 | Z6: 3 | AA6: 4 | AB6: 5 | AC6: 6 | AD6: 7 | AG6: 1 | AH6: 2 | AI6: 3 | AJ6: 4 | AK6: 5 | AL6: 6 | AM6: 7 | AX6: 44105 | AY6: =DataQ!AI198 -> 0.7989324 | AZ6: =DataQ!AJ198 -> -0.9776321 | BA6: =DataQ!AK198 -> -1.120849 | BB6: =DataQ!AL198 -> -0.07849678 | BD6: 46204 | BE6: Q3 26 | BF6: =100*((DataScen!X221-DataScen!H221)/DataScen!$G221) -> -0.50096645 | BG6: =100*((DataScen!Y221-DataScen!I221)/DataScen!$G221) -> -0.10430667 | BH6: =100*((DataScen!Z221-DataScen!J221)/DataScen!$G221) -> -0.13843066 | BI6: =100*(((DataScen!AA221-DataScen!AB221)-(DataScen!K221-DataScen!L221))/DataScen!$G221) -> 0.54494629 | BJ6: =BK6-BF6-BG6-BH6-BI6 -> -0.024688717 | BK6: =100*((DataScen!W221/DataScen!G221)-1) -> -0.22344621 | BM6: 45566 | BN6: =DataScen!R214 -> 1.2814 | BO6: =DataScen!AH214 -> 1.2814 | BQ6: 45566 | BR6: =DataScen!O214 -> 4.34127 | BS6: =DataScen!AE214 -> 4.34127 | BU6: 45566 | BV6: =100*((DataScen!M214/DataScen!M210)-1) -> 2.4753214 | BW6: =100*((DataScen!AC214/DataScen!AC210)-1) -> 2.4753214
B7: =DataA!BK2 -> UK | C7: =DataA!BL2 -> US | D7: =DataA!BM2 -> Japan | E7: =DataA!BN2 -> Canada | F7: =DataA!BO2 -> Australia | G7: =DataA!BP2 -> Denmark | H7: =DataA!BQ2 -> Sweden | I7: =DataA!BR2 -> Switzerland | ... U7: =DataA!CD2 -> Portugal | X7: =HLOOKUP(X$6,$X$2:$AD$4,2,FALSE) -> Canada | Y7: =HLOOKUP(Y$6,$X$2:$AD$4,2,FALSE) -> Germany | Z7: =HLOOKUP(Z$6,$X$2:$AD$4,2,FALSE) -> Japan | AA7: =HLOOKUP(AA$6,$X$2:$AD$4,2,FALSE) -> Italy | AB7: =HLOOKUP(AB$6,$X$2:$AD$4,2,FALSE) -> UK | AC7: =HLOOKUP(AC$6,$X$2:$AD$4,2,FALSE) -> France | AD7: =HLOOKUP(AD$6,$X$2:$AD$4,2,FALSE) -> US | AG7: =HLOOKUP(AG$6,$AF$2:$AM$4,2,FALSE) -> Japan | AH7: =HLOOKUP(AH$6,$AF$2:$AM$4,2,FALSE) -> Italy | AI7: =HLOOKUP(AI$6,$AF$2:$AM$4,2,FALSE) -> US | AJ7: =HLOOKUP(AJ$6,$AF$2:$AM$4,2,FALSE) -> France | AK7: =HLOOKUP(AK$6,$AF$2:$AM$4,2,FALSE) -> Canada | AL7: =HLOOKUP(AL$6,$AF$2:$AM$4,2,FALSE) -> UK | AM7: =HLOOKUP(AM$6,$AF$2:$AM$4,2,FALSE) -> Germany | AO7: 2030 | AP7: =X13&", "&$AO7 -> UK, 2030 | AQ7: =Y13&", "&$AO7 -> US, 2030 | AR7: =Z13&", "&$AO7 -> Japan, 2030 | AS7: =AA13&", "&$AO7 -> Germany, 2030 | AT7: =AB13&", "&$AO7 -> France, 2030 | AU7: =AC13&", "&$AO7 -> Italy, 2030 | AV7: =AD13&", "&$AO7 -> Canada, 2030 | AX7: 44197 | AY7: =DataQ!AI199 -> 1.557647 | AZ7: =DataQ!AJ199 -> -0.5086092 | BA7: =DataQ!AK199 -> -0.8559847 | BB7: =DataQ!AL199 -> 0.01564632 | BD7: 46296 | BE7: Q4 26 | BF7: =100*((DataScen!X222-DataScen!H222)/DataScen!$G222) -> -0.58576697 | BG7: =100*((DataScen!Y222-DataScen!I222)/DataScen!$G222) -> -0.13811948 | BH7: =100*((DataScen!Z222-DataScen!J222)/DataScen!$G222) -> -0.13888844 | BI7: =100*(((DataScen!AA222-DataScen!AB222)-(DataScen!K222-DataScen!L222))/DataScen!$G222) -> 0.65652541 | BJ7: =BK7-BF7-BG7-BH7-BI7 -> -0.03184899 | BK7: =100*((DataScen!W222/DataScen!G222)-1) -> -0.23809847 | BM7: 45658 | BN7: =DataScen!R215 -> 1.260133 | BO7: =DataScen!AH215 -> 1.260133 | BQ7: 45658 | BR7: =DataScen!O215 -> 4.627143 | BS7: =DataScen!AE215 -> 4.627143 | BU7: 45658 | BV7: =100*((DataScen!M215/DataScen!M211)-1) -> 2.7973783 | BW7: =100*((DataScen!AC215/DataScen!AC211)-1) -> 2.7973783
A8: Expected effective interest rates on government debt (r) | B8: =AVERAGE(DataA!BK60:BK64) -> 3.9219808 | C8: =AVERAGE(DataA!BL60:BL64) -> 3.5225755 | D8: =AVERAGE(DataA!BM60:BM64) -> 1.2385339 | E8: =AVERAGE(DataA!BN60:BN64) -> 3.2698792 | F8: =AVERAGE(DataA!BO60:BO64) -> 2.3844976 | G8: =AVERAGE(DataA!BP60:BP64) -> 1.9092147 | H8: =AVERAGE(DataA!BQ60:BQ64) -> 1.6031096 | I8: =AVERAGE(DataA!BR60:BR64) -> 1.2243915 | ... U8: =AVERAGE(DataA!CD60:CD64) -> 2.3960688 | W8: =W4 -> 2025 | X8: =HLOOKUP(X$6,$X$2:$AD$4,3,FALSE) -> -1.5593717 | Y8: =HLOOKUP(Y$6,$X$2:$AD$4,3,FALSE) -> -2.07748 | Z8: =HLOOKUP(Z$6,$X$2:$AD$4,3,FALSE) -> -2.9476509 | AA8: =HLOOKUP(AA$6,$X$2:$AD$4,3,FALSE) -> -2.9942321 | AB8: =HLOOKUP(AB$6,$X$2:$AD$4,3,FALSE) -> -4.6502172 | AC8: =HLOOKUP(AC$6,$X$2:$AD$4,3,FALSE) -> -5.4069183 | AD8: =HLOOKUP(AD$6,$X$2:$AD$4,3,FALSE) -> -7.4168274 | AF8: =AF4 -> 2025 | AG8: =HLOOKUP(AG$6,$AF$2:$AM$4,3,FALSE) -> 216.98578 | AH8: =HLOOKUP(AH$6,$AF$2:$AM$4,3,FALSE) -> 149.72344 | AI8: =HLOOKUP(AI$6,$AF$2:$AM$4,3,FALSE) -> 139.4818 | AJ8: =HLOOKUP(AJ$6,$AF$2:$AM$4,3,FALSE) -> 127.41761 | AK8: =HLOOKUP(AK$6,$AF$2:$AM$4,3,FALSE) -> 107.05075 | AL8: =HLOOKUP(AL$6,$AF$2:$AM$4,3,FALSE) -> 101.22663 | AM8: =HLOOKUP(AM$6,$AF$2:$AM$4,3,FALSE) -> 58.235605 | AP8: =X13 -> UK | AQ8: =Y13 -> US | AR8: =Z13 -> Japan | AS8: =AA13 -> Germany | AT8: =AB13 -> France | AU8: =AC13 -> Italy | AV8: =AD13 -> Canada | AX8: 44287 | AY8: =DataQ!AI200 -> 1.208585 | AZ8: =DataQ!AJ200 -> -0.3946431 | BA8: =DataQ!AK200 -> -1.171975 | BB8: =DataQ!AL200 -> 0.08187032 | BD8: 46388 | BE8: Q1 27 | BF8: =100*((DataScen!X223-DataScen!H223)/DataScen!$G223) -> -0.67656064 | BG8: =100*((DataScen!Y223-DataScen!I223)/DataScen!$G223) -> -0.16016065 | BH8: =100*((DataScen!Z223-DataScen!J223)/DataScen!$G223) -> -0.13942103 | BI8: =100*(((DataScen!AA223-DataScen!AB223)-(DataScen!K223-DataScen!L223))/DataScen!$G223) -> 0.67702059 | BJ8: =BK8-BF8-BG8-BH8-BI8 -> -0.027875843 | BK8: =100*((DataScen!W223/DataScen!G223)-1) -> -0.32699757 | BM8: 45748 | BN8: =DataScen!R216 -> 1.335467 | BO8: =DataScen!AH216 -> 1.335467 | BQ8: 45748 | BR8: =DataScen!O216 -> 4.584677 | BS8: =DataScen!AE216 -> 4.584677 | BU8: 45748 | BV8: =100*((DataScen!M216/DataScen!M212)-1) -> 3.4869498 | BW8: =100*((DataScen!AC216/DataScen!AC212)-1) -> 3.4869498
A9: Expected annual average nominal GDP growth (g) | B9: =100*((DataA!AP64/DataA!AP59)^(1/5)-1) -> 3.702996 | C9: =100*((DataA!AQ64/DataA!AQ59)^(1/5)-1) -> 4.2135937 | D9: =100*((DataA!AR64/DataA!AR59)^(1/5)-1) -> 1.2375372 | E9: =100*((DataA!AS64/DataA!AS59)^(1/5)-1) -> 3.7440525 | F9: =100*((DataA!AT64/DataA!AT59)^(1/5)-1) -> 4.6409095 | G9: =100*((DataA!AU64/DataA!AU59)^(1/5)-1) -> 4.2067184 | H9: =100*((DataA!AV64/DataA!AV59)^(1/5)-1) -> 4.0481623 | I9: =100*((DataA!AW64/DataA!AW59)^(1/5)-1) -> 2.344035 | ... U9: =100*((DataA!BI64/DataA!BI59)^(1/5)-1) -> 3.0486017 | AO9: Budget deficit | AP9: =X14 -> -2.6955346 | AQ9: =Y14 -> -7.656273 | AR9: =Z14 -> -2.903139 | AS9: =AA14 -> -3.2496949 | AT9: =AB14 -> -4.4268838 | AU9: =AC14 -> -2.6555728 | AV9: =AD14 -> -2.8483556 | AX9: 44378 | AY9: =DataQ!AI201 -> 0.603907 | AZ9: =DataQ!AJ201 -> -0.8853215 | BA9: =DataQ!AK201 -> -1.291921 | BB9: =DataQ!AL201 -> 0.03307072 | BD9: 46478 | BE9: Q2 27 | BF9: =100*((DataScen!X224-DataScen!H224)/DataScen!$G224) -> -0.77637834 | BG9: =100*((DataScen!Y224-DataScen!I224)/DataScen!$G224) -> -0.18448691 | BH9: =100*((DataScen!Z224-DataScen!J224)/DataScen!$G224) -> -0.13588947 | BI9: =100*(((DataScen!AA224-DataScen!AB224)-(DataScen!K224-DataScen!L224))/DataScen!$G224) -> 0.69457243 | BJ9: =BK9-BF9-BG9-BH9-BI9 -> -0.036180711 | BK9: =100*((DataScen!W224/DataScen!G224)-1) -> -0.438363 | BM9: 45839 | BN9: =DataScen!R217 -> 1.348233 | BO9: =DataScen!AH217 -> 1.348233 | BQ9: 45839 | BR9: =DataScen!O217 -> 4.641692 | BS9: =DataScen!AE217 -> 4.641692 | BU9: 45839 | BV9: =100*((DataScen!M217/DataScen!M213)-1) -> 3.856525 | BW9: =100*((DataScen!AC217/DataScen!AC213)-1) -> 3.856525
AO10: Government debt | AP10: =AG14 -> 98.067934 | AQ10: =AH14 -> 149.4809 | AR10: =AI14 -> 219.82424 | AS10: =AJ14 -> 61.798331 | AT10: =AK14 -> 132.60008 | AU10: =AL14 -> 149.90342 | AV10: =AM14 -> 104.55796 | AX10: 44470 | AY10: =DataQ!AI202 -> 0.4656473 | AZ10: =DataQ!AJ202 -> -0.9625124 | BA10: =DataQ!AK202 -> -1.156949 | BB10: =DataQ!AL202 -> 0.03946926 | BD10: 46569 | BE10: Q3 27 | BF10: =100*((DataScen!X225-DataScen!H225)/DataScen!$G225) -> -0.86970041 | BG10: =100*((DataScen!Y225-DataScen!I225)/DataScen!$G225) -> -0.21376666 | BH10: =100*((DataScen!Z225-DataScen!J225)/DataScen!$G225) -> -0.13625463 | BI10: =100*(((DataScen!AA225-DataScen!AB225)-(DataScen!K225-DataScen!L225))/DataScen!$G225) -> 0.71867368 | BJ10: =BK10-BF10-BG10-BH10-BI10 -> -0.046460187 | BK10: =100*((DataScen!W225/DataScen!G225)-1) -> -0.5475082 | BM10: 45931 | BN10: =DataScen!R218 -> 1.344331 | BO10: =DataScen!AH218 -> 1.296493 | BQ10: 45931 | BR10: =DataScen!O218 -> 4.699989 | BS10: =DataScen!AE218 -> 4.799991 | BU10: 45931 | BV10: =100*((DataScen!M218/DataScen!M214)-1) -> 3.7064835 | BW10: =100*((DataScen!AC218/DataScen!AC214)-1) -> 4.0897471
W11: Budget deficit in 2030 | AF11: Gross government debt in 2030 | AX11: 44562 | AY11: =DataQ!AI203 -> 0.02904415 | AZ11: =DataQ!AJ203 -> -1.047033 | BA11: =DataQ!AK203 -> -1.003417 | BB11: =DataQ!AL203 -> 0.06193143 | BD11: 46661 | BE11: Q4 27 | BF11: =100*((DataScen!X226-DataScen!H226)/DataScen!$G226) -> -0.95574645 | BG11: =100*((DataScen!Y226-DataScen!I226)/DataScen!$G226) -> -0.23989025 | BH11: =100*((DataScen!Z226-DataScen!J226)/DataScen!$G226) -> -0.13656668 | BI11: =100*(((DataScen!AA226-DataScen!AB226)-(DataScen!K226-DataScen!L226))/DataScen!$G226) -> 0.74816288 | BJ11: =BK11-BF11-BG11-BH11-BI11 -> -0.054656969 | BK11: =100*((DataScen!W226/DataScen!G226)-1) -> -0.63869746 | BM11: 46023 | BN11: =DataScen!R219 -> 1.342767 | BO11: =DataScen!AH219 -> 1.200001 | BQ11: 46023 | BR11: =DataScen!O219 -> 4.67632 | BS11: =DataScen!AE219 -> 4.885736 | BU11: 46023 | BV11: =100*((DataScen!M219/DataScen!M215)-1) -> 3.3849465 | BW11: =100*((DataScen!AC219/DataScen!AC215)-1) -> 4.3103201
X12: =RANK(X14,$X$14:$AD$14) -> 2 | Y12: =RANK(Y14,$X$14:$AD$14) -> 7 | Z12: =RANK(Z14,$X$14:$AD$14) -> 4 | AA12: =RANK(AA14,$X$14:$AD$14) -> 5 | AB12: =RANK(AB14,$X$14:$AD$14) -> 6 | AC12: =RANK(AC14,$X$14:$AD$14) -> 1 | AD12: =RANK(AD14,$X$14:$AD$14) -> 3 | AG12: =RANK(AG14,$AG$14:$AM$14) -> 6 | AH12: =RANK(AH14,$AG$14:$AM$14) -> 3 | AI12: =RANK(AI14,$AG$14:$AM$14) -> 1 | AJ12: =RANK(AJ14,$AG$14:$AM$14) -> 7 | AK12: =RANK(AK14,$AG$14:$AM$14) -> 4 | AL12: =RANK(AL14,$AG$14:$AM$14) -> 2 | AM12: =RANK(AM14,$AG$14:$AM$14) -> 5 | AO12: 2026 | AP12: =X19&", "&$AO12 -> UK, 2026 | AQ12: =Y19&", "&$AO12 -> US, 2026 | AR12: =Z19&", "&$AO12 -> Japan, 2026 | AS12: =AA19&", "&$AO12 -> Germany, 2026 | AT12: =AB19&", "&$AO12 -> France, 2026 | AU12: =AC19&", "&$AO12 -> Italy, 2026 | AV12: =AD19&", "&$AO12 -> Canada, 2026 | AX12: 44652 | AY12: =DataQ!AI204 -> -1.077437 | AZ12: =DataQ!AJ204 -> -0.956619 | BA12: =DataQ!AK204 -> -0.8716033 | BB12: =DataQ!AL204 -> -0.07522872 | BD12: 46753 | BE12: Q1 28 | BF12: =100*((DataScen!X227-DataScen!H227)/DataScen!$G227) -> -1.0238964 | BG12: =100*((DataScen!Y227-DataScen!I227)/DataScen!$G227) -> -0.25701954 | BH12: =100*((DataScen!Z227-DataScen!J227)/DataScen!$G227) -> -0.1369281 | BI12: =100*(((DataScen!AA227-DataScen!AB227)-(DataScen!K227-DataScen!L227))/DataScen!$G227) -> 0.78435792 | BJ12: =BK12-BF12-BG12-BH12-BI12 -> -0.058887171 | BK12: =100*((DataScen!W227/DataScen!G227)-1) -> -0.69237328 | BM12: 46113 | BN12: =DataScen!R220 -> 1.341715 | BO12: =DataScen!AH220 -> 1.2 | BQ12: 46113 | BR12: =DataScen!O220 -> 4.596054 | BS12: =DataScen!AE220 -> 4.895629 | BU12: 46113 | BV12: =100*((DataScen!M220/DataScen!M216)-1) -> 2.5638267 | BW12: =100*((DataScen!AC220/DataScen!AC216)-1) -> 3.6692419
X13: UK | Y13: US | Z13: Japan | AA13: Germany | AB13: France | AC13: Italy | AD13: Canada | AG13: UK | AH13: US | AI13: Japan | AJ13: Germany | AK13: France | AL13: Italy | AM13: Canada | AP13: =X18 -> 5 | AQ13: =Y18 -> 7 | AR13: =Z18 -> 3 | AS13: =AA18 -> 1 | AT13: =AB18 -> 6 | AU13: =AC18 -> 2 | AV13: =AD18 -> 4 | AX13: 44743 | AY13: =DataQ!AI205 -> -2.220368 | AZ13: =DataQ!AJ205 -> -2.037583 | BA13: =DataQ!AK205 -> -1.227004 | BB13: =DataQ!AL205 -> -0.3186778 | BD13: 46844 | BE13: Q2 28 | BF13: =100*((DataScen!X228-DataScen!H228)/DataScen!$G228) -> -1.0631036 | BG13: =100*((DataScen!Y228-DataScen!I228)/DataScen!$G228) -> -0.26073834 | BH13: =100*((DataScen!Z228-DataScen!J228)/DataScen!$G228) -> -0.13272413 | BI13: =100*(((DataScen!AA228-DataScen!AB228)-(DataScen!K228-DataScen!L228))/DataScen!$G228) -> 0.81345065 | BJ13: =BK13-BF13-BG13-BH13-BI13 -> -0.056819361 | BK13: =100*((DataScen!W228/DataScen!G228)-1) -> -0.6999348 | BM13: 46204 | BN13: =DataScen!R221 -> 1.340664 | BO13: =DataScen!AH221 -> 1.200001 | BQ13: 46204 | BR13: =DataScen!O221 -> 4.470532 | BS13: =DataScen!AE221 -> 4.810573 | BU13: 46204 | BV13: =100*((DataScen!M221/DataScen!M217)-1) -> 2.633631 | BW13: =100*((DataScen!AC221/DataScen!AC217)-1) -> 3.8613041
W14: 2030 | X14: =100*('Data Q to A'!I65/'Data Q to A'!W65) -> -2.6955346 | Y14: =100*('Data Q to A'!J65/'Data Q to A'!X65) -> -7.656273 | Z14: =100*('Data Q to A'!K65/'Data Q to A'!Y65) -> -2.903139 | AA14: =100*('Data Q to A'!L65/'Data Q to A'!Z65) -> -3.2496949 | AB14: =100*('Data Q to A'!M65/'Data Q to A'!AA65) -> -4.4268838 | AC14: =100*('Data Q to A'!N65/'Data Q to A'!AB65) -> -2.6555728 | AD14: =100*('Data Q to A'!O65/'Data Q to A'!AC65) -> -2.8483556 | AF14: 2030 | AG14: =100*('Data Q to A'!P65/'Data Q to A'!W65) -> 98.067934 | AH14: =100*('Data Q to A'!Q65/'Data Q to A'!X65) -> 149.4809 | AI14: =100*('Data Q to A'!R65/'Data Q to A'!Y65) -> 219.82424 | AJ14: =100*('Data Q to A'!S65/'Data Q to A'!Z65) -> 61.798331 | AK14: =100*('Data Q to A'!T65/'Data Q to A'!AA65) -> 132.60008 | AL14: =100*('Data Q to A'!U65/'Data Q to A'!AB65) -> 149.90342 | AM14: =100*('Data Q to A'!V65/'Data Q to A'!AC65) -> 104.55796 | AO14: Budget deficit | AP14: =X20 -> -3.7166276 | AQ14: =Y20 -> -8.1781006 | AR14: =Z20 -> -3.5055345 | AS14: =AA20 -> -2.5893717 | AT14: =AB20 -> -5.6696548 | AU14: =AC20 -> -2.8028244 | AV14: =AD20 -> -3.5934936 | AX14: 44835 | AY14: =DataQ!AI206 -> -2.703098 | AZ14: =DataQ!AJ206 -> -2.388281 | BA14: =DataQ!AK206 -> -1.518819 | BB14: =DataQ!AL206 -> -0.5677544 | BD14: 46935 | BE14: Q3 28 | BF14: =100*((DataScen!X229-DataScen!H229)/DataScen!$G229) -> -1.085522 | BG14: =100*((DataScen!Y229-DataScen!I229)/DataScen!$G229) -> -0.25307282 | BH14: =100*((DataScen!Z229-DataScen!J229)/DataScen!$G229) -> -0.13301953 | BI14: =100*(((DataScen!AA229-DataScen!AB229)-(DataScen!K229-DataScen!L229))/DataScen!$G229) -> 0.83515391 | BJ14: =BK14-BF14-BG14-BH14-BI14 -> -0.048630213 | BK14: =100*((DataScen!W229/DataScen!G229)-1) -> -0.68509069 | BM14: 46296 | BN14: =DataScen!R222 -> 1.339612 | BO14: =DataScen!AH222 -> 1.2 | BQ14: 46296 | BR14: =DataScen!O222 -> 4.327124 | BS14: =DataScen!AE222 -> 4.693847 | BU14: 46296 | BV14: =100*((DataScen!M222/DataScen!M218)-1) -> 2.5655689 | BW14: =100*((DataScen!AC222/DataScen!AC218)-1) -> 3.5251201
AO15: Government debt | AP15: =AG20 -> 101.65539 | AQ15: =AH20 -> 141.75638 | AR15: =AI20 -> 217.02748 | AS15: =AJ20 -> 59.008035 | AT15: =AK20 -> 130.10576 | AU15: =AL20 -> 152.02351 | AV15: =AM20 -> 108.15788 | AX15: 44927 | AY15: =DataQ!AI207 -> -4.149235 | AZ15: =DataQ!AJ207 -> -3.100953 | BA15: =DataQ!AK207 -> -2.404197 | BB15: =DataQ!AL207 -> -0.6169774 | BD15: 47027 | BE15: Q4 28 | BF15: =100*((DataScen!X230-DataScen!H230)/DataScen!$G230) -> -1.0909165 | BG15: =100*((DataScen!Y230-DataScen!I230)/DataScen!$G230) -> -0.23630434 | BH15: =100*((DataScen!Z230-DataScen!J230)/DataScen!$G230) -> -0.13334326 | BI15: =100*(((DataScen!AA230-DataScen!AB230)-(DataScen!K230-DataScen!L230))/DataScen!$G230) -> 0.84854923 | BJ15: =BK15-BF15-BG15-BH15-BI15 -> -0.038921669 | BK15: =100*((DataScen!W230/DataScen!G230)-1) -> -0.6509365 | BM15: 46388 | BN15: =DataScen!R223 -> 1.338561 | BO15: =DataScen!AH223 -> 1.215806 | BQ15: 46388 | BR15: =DataScen!O223 -> 4.182954 | BS15: =DataScen!AE223 -> 4.59452 | BU15: 46388 | BV15: =100*((DataScen!M223/DataScen!M219)-1) -> 2.6026346 | BW15: =100*((DataScen!AC223/DataScen!AC219)-1) -> 3.0687322
AX16: 45017 | AY16: =DataQ!AI208 -> -3.705824 | AZ16: =DataQ!AJ208 -> -3.350867 | BA16: =DataQ!AK208 -> -2.505757 | BB16: =DataQ!AL208 -> -0.8306971 | BM16: 46478 | BN16: =DataScen!R224 -> 1.337874 | BO16: =DataScen!AH224 -> 1.229295 | BQ16: 46478 | BR16: =DataScen!O224 -> 4.048969 | BS16: =DataScen!AE224 -> 4.497655 | BU16: 46478 | BV16: =100*((DataScen!M224/DataScen!M220)-1) -> 2.5581675 | BW16: =100*((DataScen!AC224/DataScen!AC220)-1) -> 2.8930527
W17: Budget deficit in 2026 | AF17: Gross government debt in 2026 | AX17: 45108 | AY17: =DataQ!AI209 -> -3.457875 | AZ17: =DataQ!AJ209 -> -2.826797 | BA17: =DataQ!AK209 -> -2.697079 | BB17: =DataQ!AL209 -> -0.7969345 | BM17: 46569 | BN17: =DataScen!R225 -> 1.337551 | BO17: =DataScen!AH225 -> 1.24054 | BQ17: 46569 | BR17: =DataScen!O225 -> 3.9281 | BS17: =DataScen!AE225 -> 4.401708 | BU17: 46569 | BV17: =100*((DataScen!M225/DataScen!M221)-1) -> 2.4956712 | BW17: =100*((DataScen!AC225/DataScen!AC221)-1) -> 2.7723605
X18: =RANK(X20,$X$20:$AD$20) -> 5 | Y18: =RANK(Y20,$X$20:$AD$20) -> 7 | Z18: =RANK(Z20,$X$20:$AD$20) -> 3 | AA18: =RANK(AA20,$X$20:$AD$20) -> 1 | AB18: =RANK(AB20,$X$20:$AD$20) -> 6 | AC18: =RANK(AC20,$X$20:$AD$20) -> 2 | AD18: =RANK(AD20,$X$20:$AD$20) -> 4 | AG18: =RANK(AG20,$AG$20:$AM$20) -> 6 | AH18: =RANK(AH20,$AG$20:$AM$20) -> 3 | AI18: =RANK(AI20,$AG$20:$AM$20) -> 1 | AJ18: =RANK(AJ20,$AG$20:$AM$20) -> 7 | AK18: =RANK(AK20,$AG$20:$AM$20) -> 4 | AL18: =RANK(AL20,$AG$20:$AM$20) -> 2 | AM18: =RANK(AM20,$AG$20:$AM$20) -> 5 | AX18: 45200 | AY18: =DataQ!AI210 -> -3.401873 | AZ18: =DataQ!AJ210 -> -2.325372 | BA18: =DataQ!AK210 -> -2.819133 | BB18: =DataQ!AL210 -> -0.6955835 | BM18: 46661 | BN18: =DataScen!R226 -> 1.337228 | BO18: =DataScen!AH226 -> 1.249791 | BQ18: 46661 | BR18: =DataScen!O226 -> 3.829388 | BS18: =DataScen!AE226 -> 4.318294 | BU18: 46661 | BV18: =100*((DataScen!M226/DataScen!M222)-1) -> 2.387868 | BW18: =100*((DataScen!AC226/DataScen!AC222)-1) -> 2.5961719
X19: UK | Y19: US | Z19: Japan | AA19: Germany | AB19: France | AC19: Italy | AD19: Canada | AG19: UK | AH19: US | AI19: Japan | AJ19: Germany | AK19: France | AL19: Italy | AM19: Canada | AX19: 45292 | AY19: =DataQ!AI211 -> -3.181256 | AZ19: =DataQ!AJ211 -> -2.302343 | BA19: =DataQ!AK211 -> -2.815394 | BB19: =DataQ!AL211 -> -0.8791806
W20: 2026 | X20: =100*('Data Q to A'!I61/'Data Q to A'!W61) -> -3.7166276 | Y20: =100*('Data Q to A'!J61/'Data Q to A'!X61) -> -8.1781006 | Z20: =100*('Data Q to A'!K61/'Data Q to A'!Y61) -> -3.5055345 | AA20: =100*('Data Q to A'!L61/'Data Q to A'!Z61) -> -2.5893717 | AB20: =100*('Data Q to A'!M61/'Data Q to A'!AA61) -> -5.6696548 | AC20: =100*('Data Q to A'!N61/'Data Q to A'!AB61) -> -2.8028244 | AD20: =100*('Data Q to A'!O61/'Data Q to A'!AC61) -> -3.5934936 | AF20: 2030 | AG20: =100*('Data Q to A'!P61/'Data Q to A'!W61) -> 101.65539 | AH20: =100*('Data Q to A'!Q61/'Data Q to A'!X61) -> 141.75638 | AI20: =100*('Data Q to A'!R61/'Data Q to A'!Y61) -> 217.02748 | AJ20: =100*('Data Q to A'!S61/'Data Q to A'!Z61) -> 59.008035 | AK20: =100*('Data Q to A'!T61/'Data Q to A'!AA61) -> 130.10576 | AL20: =100*('Data Q to A'!U61/'Data Q to A'!AB61) -> 152.02351 | AM20: =100*('Data Q to A'!V61/'Data Q to A'!AC61) -> 108.15788 | AX20: 45383 | AY20: =DataQ!AI212 -> -2.509396 | AZ20: =DataQ!AJ212 -> -1.723849 | BA20: =DataQ!AK212 -> -2.279839 | BB20: =DataQ!AL212 -> -0.7389167
AX21: 45474 | AY21: =DataQ!AI213 -> -2.278532 | AZ21: =DataQ!AJ213 -> -1.775833 | BA21: =DataQ!AK213 -> -1.942126 | BB21: =DataQ!AL213 -> -0.7493371
AX22: 45566 | AY22: =DataQ!AI214 -> -1.373426 | AZ22: =DataQ!AJ214 -> -0.872263 | BA22: =DataQ!AK214 -> -1.38094 | BB22: =DataQ!AL214 -> -0.6486924
AX23: 45658 | AY23: =DataQ!AI215 -> -0.5658989 | AZ23: =DataQ!AJ215 -> -0.4111123 | BA23: =DataQ!AK215 -> -0.5560845 | BB23: =DataQ!AL215 -> -0.449419
AX24: 45748 | AY24: =DataQ!AI216 -> -0.2743466 | AZ24: =DataQ!AJ216 -> -0.4273167 | BA24: =DataQ!AK216 -> -0.1488339 | BB24: =DataQ!AL216 -> -0.4773142
AX25: 45839 | AY25: =DataQ!AI217 -> 0.02999306 | AZ25: =DataQ!AJ217 -> -0.447391 | BA25: =DataQ!AK217 -> 0.2001213 | BB25: =DataQ!AL217 -> -0.3751646

Sheet DataA
B1: =GMWA!$DB$2 -> OCT004A.db | C1: =$B$1 -> OCT004A.db | D1: =$B$1 -> OCT004A.db | E1: =$B$1 -> OCT004A.db | F1: =$B$1 -> OCT004A.db | G1: =$B$1 -> OCT004A.db | H1: =$B$1 -> OCT004A.db | I1: =$B$1 -> OCT004A.db | J1: =$B$1 -> OCT004A.db | ... BI1: =$B$1 -> OCT004A.db | CF1: FYs | CN1: CYs
B2: UK | C2: US | D2: Japan | E2: Canada | F2: Australia | G2: Denmark | H2: Sweden | I2: Switzerland | J2: S Korea | K2: Germany | L2: France | M2: Italy | N2: Spain | O2: Netherlands | P2: Belgium | Q2: Austria | R2: Finland | S2: Ireland | T2: Greece | U2: Portugal | V2: UK | W2: US | X2: Japan | Y2: Canada | Z2: Australia | AA2: Denmark | AB2: Sweden | AC2: Switzerland | AD2: S Korea | AE2: Germany | AF2: France | AG2: Italy | AH2: Spain | AI2: Netherlands | AJ2: Belgium | AK2: Austria | AL2: Finland | AM2: Ireland | AN2: Greece | AO2: Portugal | AP2: UK | AQ2: US | AR2: Japan | AS2: Canada | AT2: Australia | AU2: Denmark | AV2: Sweden | AW2: Switzerland | AX2: S Korea | AY2: Germany | AZ2: France | BA2: Italy | BB2: Spain | BC2: Netherlands | BD2: Belgium | BE2: Austria | BF2: Finland | BG2: Ireland | BH2: Greece | BI2: Portugal | BK2: =B2 -> UK | BL2: =C2 -> US | BM2: =D2 -> Japan | BN2: =E2 -> Canada | BO2: =F2 -> Australia | BP2: =G2 -> Denmark | BQ2: =H2 -> Sweden | BR2: =I2 -> Switzerland | ... CD2: =U2 -> Portugal
B3: GDIP | C3: GDIP | D3: GDIP | E3: GDIP | F3: GDIP | G3: GDIP | H3: GDIP | I3: GDIP | J3: GDIP | K3: GDIP | L3: GDIP | M3: GDIP | N3: GDIP | O3: GDIP | P3: GDIP | Q3: GDIP | R3: GDIP | S3: GDIP | T3: GDIP | U3: GDIP | V3: GGDBT | W3: GGDBT | X3: GGDBT | Y3: GGDBT | Z3: GGDBT | AA3: GGDBT | AB3: GGDBT | AC3: GGDBT | AD3: GGDBT | AE3: GGDBT | AF3: GGDBT | AG3: GGDBT | AH3: GGDBT | AI3: GGDBT | AJ3: GGDBT | AK3: GGDBT | AL3: GGDBT | AM3: GGDBT | AN3: GGDBT | AO3: GGDBT | AP3: GDP! | AQ3: GDP! | AR3: GDP! | AS3: GDP! | AT3: GDP! | AU3: GDP! | AV3: GDP! | AW3: GDP! | AX3: GDP! | AY3: GDP! | AZ3: GDP! | BA3: GDP! | BB3: GDP! | BC3: GDP! | BD3: GDP! | BE3: GDP! | BF3: GDP! | BG3: GDP! | BH3: GDP! | BI3: GDP! | BK3: GDIP/GGDBT | BL3: GDIP/GGDBT | BM3: GDIP/GGDBT | BN3: GDIP/GGDBT | BO3: GDIP/GGDBT | BP3: GDIP/GGDBT | BQ3: GDIP/GGDBT | BR3: GDIP/GGDBT | BS3: GDIP/GGDBT | BT3: GDIP/GGDBT | BU3: GDIP/GGDBT | BV3: GDIP/GGDBT | BW3: GDIP/GGDBT | BX3: GDIP/GGDBT | BY3: GDIP/GGDBT | BZ3: GDIP/GGDBT | CA3: GDIP/GGDBT | CB3: GDIP/GGDBT | CC3: GDIP/GGDBT | CD3: GDIP/GGDBT | CF3: =DataQ!H3 -> GDP | CG3: =DataQ!I3 -> GDP | CH3: =DataQ!J3 -> GDP | CI3: =DataQ!K3 -> GDP | CJ3: =DataQ!L3 -> GDP | CK3: =DataQ!M3 -> GDP | CL3: =DataQ!N3 -> GB | CN3: =DataQ!O3 -> GB | CO3: =DataQ!P3 -> GB | CP3: =DataQ!Q3 -> GB
B4: GBR | C4: USA | D4: JPN | E4: CAN | F4: AUS | G4: DNK | H4: SWE | I4: CHE | J4: KOR | K4: DEU | L4: FRA | M4: ITA | N4: ESP | O4: NLD | P4: BEL | Q4: AUT | R4: FIN | S4: IRL | T4: GRC | U4: PRT | V4: GBR | W4: USA | X4: JPN | Y4: CAN | Z4: AUS | AA4: DNK | AB4: SWE | AC4: CHE | AD4: KOR | AE4: DEU | AF4: FRA | AG4: ITA | AH4: ESP | AI4: NLD | AJ4: BEL | AK4: AUT | AL4: FIN | AM4: IRL | AN4: GRC | AO4: PRT | AP4: GBR | AQ4: USA | AR4: JPN | AS4: CAN | AT4: AUS | AU4: DNK | AV4: SWE | AW4: CHE | AX4: KOR | AY4: DEU | AZ4: FRA | BA4: ITA | BB4: ESP | BC4: NLD | BD4: BEL | BE4: AUT | BF4: FIN | BG4: IRL | BH4: GRC | BI4: PRT | BK4: =B4 -> GBR | BL4: =C4 -> USA | BM4: =D4 -> JPN | BN4: =E4 -> CAN | BO4: =F4 -> AUS | BP4: =G4 -> DNK | BQ4: =H4 -> SWE | BR4: =I4 -> CHE | ... CD4: =U4 -> PRT
B5: L | C5: L | D5: L | E5: L | F5: L | G5: L | H5: L | I5: L | J5: L | K5: L | L5: L | M5: L | N5: L | O5: L | P5: L | Q5: L | R5: L | S5: L | T5: L | U5: L | V5: L | W5: L | X5: L | Y5: L | Z5: L | AA5: L | AB5: L | AC5: L | AD5: L | AE5: L | AF5: L | AG5: L | AH5: L | AI5: L | AJ5: L | AK5: L | AL5: L | AM5: L | AN5: L | AO5: L | AP5: L | AQ5: L | AR5: L | AS5: L | AT5: L | AU5: L | AV5: L | AW5: L | AX5: L | AY5: L | AZ5: L | BA5: L | BB5: L | BC5: L | BD5: L | BE5: L | BF5: L | BG5: L | BH5: L | BI5: L
A6: =A94+5 -> 2065 | B6: {=_xlfn.CONCAT(INDEX(GMWA!$A$2:$DB$600,MATCH(1,(GMWA!$DA$2:$DA$600=B$3)*(GMWA!$CZ$2:$CZ$600=B$4)*(GMWA!$DB$2:$DB$600=B$1),0),$A6-1966),"0",(INDEX(GMWA!$A$2:$DB$600,MATCH(1,(GMWA!$DA$2:$DA$600=B$3)*(GMWA!$CZ$2:$CZ$600=B$4)*(GMWA!$DB$2:$DB$600=B$1),0),$A6-1965)))} -> 202502 | C6: {=_xlfn.CONCAT(INDEX(GMWA!$A$2:$DB$600,MATCH(1,(GMWA!$DA$2:$DA$600=C$3)*(GMWA!$CZ$2:$CZ$600=C$4)*(GMWA!$DB$2:$DB$600=C$1),0),$A6-1966),"0",(INDEX(GMWA!$A$2:$DB$600,MATCH(1,(GMWA!$DA$2:$DA$600=C$3)*(GMWA!$CZ$2:$CZ$600=C$4)*(GMWA!$DB$2:$DB$600=C$1),0),$A6-1965)))} -> 202502 | D6: {=_xlfn.CONCAT(INDEX(GMWA!$A$2:$DB$600,MATCH(1,(GMWA!$DA$2:$DA$600=D$3)*(GMWA!$CZ$2:$CZ$600=D$4)*(GMWA!$DB$2:$DB$600=D$1),0),$A6-1966),"0",(INDEX(GMWA!$A$2:$DB$600,MATCH(1,(GMWA!$DA$2:$DA$600=D$3)*(GMWA!$CZ$2:$CZ$600=D$4)*(GMWA!$DB$2:$DB$600=D$1),0),$A6-1965)))} -> 202402 | E6: {=_xlfn.CONCAT(INDEX(GMWA!$A$2:$DB$600,MATCH(1,(GMWA!$DA$2:$DA$600=E$3)*(GMWA!$CZ$2:$CZ$600=E$4)*(GMWA!$DB$2:$DB$600=E$1),0),$A6-1966),"0",(INDEX(GMWA!$A$2:$DB$600,MATCH(1,(GMWA!$DA$2:$DA$600=E$3)*(GMWA!$CZ$2:$CZ$600=E$4)*(GMWA!$DB$2:$DB$600=E$1),0),$A6-1965)))} -> 202502 | F6: {=_xlfn.CONCAT(INDEX(GMWA!$A$2:$DB$600,MATCH(1,(GMWA!$DA$2:$DA$600=F$3)*(GMWA!$CZ$2:$CZ$600=F$4)*(GMWA!$DB$2:$DB$600=F$1),0),$A6-1966),"0",(INDEX(GMWA!$A$2:$DB$600,MATCH(1,(GMWA!$DA$2:$DA$600=F$3)*(GMWA!$CZ$2:$CZ$600=F$4)*(GMWA!$DB$2:$DB$600=F$1),0),$A6-1965)))} -> 202502 | G6: {=_xlfn.CONCAT(INDEX(GMWA!$A$2:$DB$600,MATCH(1,(GMWA!$DA$2:$DA$600=G$3)*(GMWA!$CZ$2:$CZ$600=G$4)*(GMWA!$DB$2:$DB$600=G$1),0),$A6-1966),"0",(INDEX(GMWA!$A$2:$DB$600,MATCH(1,(GMWA!$DA$2:$DA$600=G$3)*(GMWA!$CZ$2:$CZ$600=G$4)*(GMWA!$DB$2:$DB$600=G$1),0),$A6-1965)))} -> 202501 | H6: {=_xlfn.CONCAT(INDEX(GMWA!$A$2:$DB$600,MATCH(1,(GMWA!$DA$2:$DA$600=H$3)*(GMWA!$CZ$2:$CZ$600=H$4)*(GMWA!$DB$2:$DB$600=H$1),0),$A6-1966),"0",(INDEX(GMWA!$A$2:$DB$600,MATCH(1,(GMWA!$DA$2:$DA$600=H$3)*(GMWA!$CZ$2:$CZ$600=H$4)*(GMWA!$DB$2:$DB$600=H$1),0),$A6-1965)))} -> 202501 | I6: {=_xlfn.CONCAT(INDEX(GMWA!$A$2:$DB$600,MATCH(1,(GMWA!$DA$2:$DA$600=I$3)*(GMWA!$CZ$2:$CZ$600=I$4)*(GMWA!$DB$2:$DB$600=I$1),0),$A6-1966),"0",(INDEX(GMWA!$A$2:$DB$600,MATCH(1,(GMWA!$DA$2:$DA$600=I$3)*(GMWA!$CZ$2:$CZ$600=I$4)*(GMWA!$DB$2:$DB$600=I$1),0),$A6-1965)))} -> 202004 | ... BI6: {=_xlfn.CONCAT(INDEX(GMWA!$A$2:$DB$600,MATCH(1,(GMWA!$DA$2:$DA$600=BI$3)*(GMWA!$CZ$2:$CZ$600=BI$4)*(GMWA!$DB$2:$DB$600=BI$1),0),$A6-1966),"0",(INDEX(GMWA!$A$2:$DB$600,MATCH(1,(GMWA!$DA$2:$DA$600=BI$3)*(GMWA!$CZ$2:$CZ$600=BI$4)*(GMWA!$DB$2:$DB$600=BI$1),0),$A6-1965)))} -> 202502 | CF6: =DataQ!H6 -> 202502 | CG6: =DataQ!I6 -> 202502 | CH6: =DataQ!J6 -> 202502 | CI6: =DataQ!K6 -> 202502 | CJ6: =DataQ!L6 -> 202502 | CK6: =DataQ!M6 -> 202502 | CL6: =DataQ!N6 -> 202502 | CN6: =DataQ!O6 -> 202502 | CO6: =DataQ!P6 -> 202402 | CP6: =DataQ!Q6 -> 202502
A7: 1973 | B7: {=INDEX(GMWA!$A$2:$DB$600,MATCH(1,(GMWA!$DA$2:$DA$600=B$3)*(GMWA!$CZ$2:$CZ$600=B$4)*(GMWA!$DB$2:$DB$600=B$1),0),$A7-1966)} -> 3087 | C7: {=INDEX(GMWA!$A$2:$DB$600,MATCH(1,(GMWA!$DA$2:$DA$600=C$3)*(GMWA!$CZ$2:$CZ$600=C$4)*(GMWA!$DB$2:$DB$600=C$1),0),$A7-1966)} -> 61.95 | D7: {=INDEX(GMWA!$A$2:$DB$600,MATCH(1,(GMWA!$DA$2:$DA$600=D$3)*(GMWA!$CZ$2:$CZ$600=D$4)*(GMWA!$DB$2:$DB$600=D$1),0),$A7-1966)} -> 922.9716 | E7: {=INDEX(GMWA!$A$2:$DB$600,MATCH(1,(GMWA!$DA$2:$DA$600=E$3)*(GMWA!$CZ$2:$CZ$600=E$4)*(GMWA!$DB$2:$DB$600=E$1),0),$A7-1966)} -> 4910 | F7: {=INDEX(GMWA!$A$2:$DB$600,MATCH(1,(GMWA!$DA$2:$DA$600=F$3)*(GMWA!$CZ$2:$CZ$600=F$4)*(GMWA!$DB$2:$DB$600=F$1),0),$A7-1966)} -> 738.1701 | G7: {=INDEX(GMWA!$A$2:$DB$600,MATCH(1,(GMWA!$DA$2:$DA$600=G$3)*(GMWA!$CZ$2:$CZ$600=G$4)*(GMWA!$DB$2:$DB$600=G$1),0),$A7-1966)} -> 1.986917 | H7: {=INDEX(GMWA!$A$2:$DB$600,MATCH(1,(GMWA!$DA$2:$DA$600=H$3)*(GMWA!$CZ$2:$CZ$600=H$4)*(GMWA!$DB$2:$DB$600=H$1),0),$A7-1966)} -> 3553.037 | I7: {=INDEX(GMWA!$A$2:$DB$600,MATCH(1,(GMWA!$DA$2:$DA$600=I$3)*(GMWA!$CZ$2:$CZ$600=I$4)*(GMWA!$DB$2:$DB$600=I$1),0),$A7-1966)} -> 1.915308 | ... BI7: {=INDEX(GMWA!$A$2:$DB$600,MATCH(1,(GMWA!$DA$2:$DA$600=BI$3)*(GMWA!$CZ$2:$CZ$600=BI$4)*(GMWA!$DB$2:$DB$600=BI$1),0),$A7-1966)} -> 23.33603 | BK7: =100*(B7/V7) -> 8.5822878 | BL7: =100*(C7/W7) -> 5.3458308 | BM7: =100*(D7/X7) -> 5.1843599 | BN7: =100*(E7/Y7) -> 7.5628052 | BO7: =100*(F7/Z7) -> 73817010 | BP7: =100*(G7/AA7) -> 1.1897707 | BQ7: =100*(H7/AB7) -> 5.1876507 | BR7: =100*(I7/AC7) -> 1.8912737 | ... CD7: =100*(U7/AO7) -> 1.139807 | CF7: =SUMIF(DataQ!$C:$C,DataA!$A7,DataQ!H:H) -> 6116.05 | CG7: =SUMIF(DataQ!$C:$C,DataA!$A7,DataQ!I:I) -> 210897 | CH7: =SUMIF(DataQ!$C:$C,DataA!$A7,DataQ!J:J) -> 1564.34 | CI7: =SUMIF(DataQ!$C:$C,DataA!$A7,DataQ!K:K) -> 1013.889 | CJ7: =SUMIF(DataQ!$C:$C,DataA!$A7,DataQ!L:L) -> 954.3197 | CK7: =AVERAGEIF(DataQ!$C:$C,DataA!$A7,DataQ!M:M) -> 178599.27 | CL7: =SUMIF(DataQ!$C:$C,DataA!$A7,DataQ!N:N) -> -3383 | CN7: =SUMIF(DataQ!$B:$B,DataA!$A7,DataQ!O:O) -> -44.59125 | CO7: =SUMIF(DataQ!$B:$B,DataA!$A7,DataQ!P:P) -> -2130.75 | CP7: =SUMIF(DataQ!$B:$B,DataA!$A7,DataQ!Q:Q) -> -23.045528
A8: =+A7+1 -> 1974 | B8: {=INDEX(GMWA!$A$2:$DB$600,MATCH(1,(GMWA!$DA$2:$DA$600=B$3)*(GMWA!$CZ$2:$CZ$600=B$4)*(GMWA!$DB$2:$DB$600=B$1),0),$A8-1966)} -> 4131 | C8: {=INDEX(GMWA!$A$2:$DB$600,MATCH(1,(GMWA!$DA$2:$DA$600=C$3)*(GMWA!$CZ$2:$CZ$600=C$4)*(GMWA!$DB$2:$DB$600=C$1),0),$A8-1966)} -> 69.55 | D8: {=INDEX(GMWA!$A$2:$DB$600,MATCH(1,(GMWA!$DA$2:$DA$600=D$3)*(GMWA!$CZ$2:$CZ$600=D$4)*(GMWA!$DB$2:$DB$600=D$1),0),$A8-1966)} -> 1196.62 | E8: {=INDEX(GMWA!$A$2:$DB$600,MATCH(1,(GMWA!$DA$2:$DA$600=E$3)*(GMWA!$CZ$2:$CZ$600=E$4)*(GMWA!$DB$2:$DB$600=E$1),0),$A8-1966)} -> 5488 | F8: {=INDEX(GMWA!$A$2:$DB$600,MATCH(1,(GMWA!$DA$2:$DA$600=F$3)*(GMWA!$CZ$2:$CZ$600=F$4)*(GMWA!$DB$2:$DB$600=F$1),0),$A8-1966)} -> 807 | G8: {=INDEX(GMWA!$A$2:$DB$600,MATCH(1,(GMWA!$DA$2:$DA$600=G$3)*(GMWA!$CZ$2:$CZ$600=G$4)*(GMWA!$DB$2:$DB$600=G$1),0),$A8-1966)} -> 2.163271 | H8: {=INDEX(GMWA!$A$2:$DB$600,MATCH(1,(GMWA!$DA$2:$DA$600=H$3)*(GMWA!$CZ$2:$CZ$600=H$4)*(GMWA!$DB$2:$DB$600=H$1),0),$A8-1966)} -> 4397.595 | I8: {=INDEX(GMWA!$A$2:$DB$600,MATCH(1,(GMWA!$DA$2:$DA$600=I$3)*(GMWA!$CZ$2:$CZ$600=I$4)*(GMWA!$DB$2:$DB$600=I$1),0),$A8-1966)} -> 2.263996 | ... BI8: {=INDEX(GMWA!$A$2:$DB$600,MATCH(1,(GMWA!$DA$2:$DA$600=BI$3)*(GMWA!$CZ$2:$CZ$600=BI$4)*(GMWA!$DB$2:$DB$600=BI$1),0),$A8-1966)} -> 23.33603 | BK8: =100*(B8/V8) -> 8.4599839 | BL8: =100*(C8/W8) -> 5.5564033 | BM8: =100*(D8/X8) -> 7.2373291 | BN8: =100*(E8/Y8) -> 7.4126101 | BO8: =100*(F8/Z8) -> 80700000 | BP8: =100*(G8/AA8) -> 1.2953719 | BQ8: =100*(H8/AB8) -> 5.6119733 | BR8: =100*(I8/AC8) -> 2.1942007 | ... CD8: =100*(U8/AO8) -> 0.96902159 | CF8: =SUMIF(DataQ!$C:$C,DataA!$A8,DataQ!H:H) -> 6038.325 | CG8: =SUMIF(DataQ!$C:$C,DataA!$A8,DataQ!I:I) -> 210067.04 | CH8: =SUMIF(DataQ!$C:$C,DataA!$A8,DataQ!J:J) -> 1563.89 | CI8: =SUMIF(DataQ!$C:$C,DataA!$A8,DataQ!K:K) -> 1041.055 | CJ8: =SUMIF(DataQ!$C:$C,DataA!$A8,DataQ!L:L) -> 975.1377 | CK8: =AVERAGEIF(DataQ!$C:$C,DataA!$A8,DataQ!M:M) -> 182714.27 | CL8: =SUMIF(DataQ!$C:$C,DataA!$A8,DataQ!N:N) -> -5592 | CN8: =SUMIF(DataQ!$B:$B,DataA!$A8,DataQ!O:O) -> -59.765 | CO8: =SUMIF(DataQ!$B:$B,DataA!$A8,DataQ!P:P) -> -2482.25 | CP8: =SUMIF(DataQ!$B:$B,DataA!$A8,DataQ!Q:Q) -> -36.381582
A9: =+A8+1 -> 1975 | B9: {=INDEX(GMWA!$A$2:$DB$600,MATCH(1,(GMWA!$DA$2:$DA$600=B$3)*(GMWA!$CZ$2:$CZ$600=B$4)*(GMWA!$DB$2:$DB$600=B$1),0),$A9-1966)} -> 4939 | C9: {=INDEX(GMWA!$A$2:$DB$600,MATCH(1,(GMWA!$DA$2:$DA$600=C$3)*(GMWA!$CZ$2:$CZ$600=C$4)*(GMWA!$DB$2:$DB$600=C$1),0),$A9-1966)} -> 77.425 | D9: {=INDEX(GMWA!$A$2:$DB$600,MATCH(1,(GMWA!$DA$2:$DA$600=D$3)*(GMWA!$CZ$2:$CZ$600=D$4)*(GMWA!$DB$2:$DB$600=D$1),0),$A9-1966)} -> 1681.87 | E9: {=INDEX(GMWA!$A$2:$DB$600,MATCH(1,(GMWA!$DA$2:$DA$600=E$3)*(GMWA!$CZ$2:$CZ$600=E$4)*(GMWA!$DB$2:$DB$600=E$1),0),$A9-1966)} -> 6639 | F9: {=INDEX(GMWA!$A$2:$DB$600,MATCH(1,(GMWA!$DA$2:$DA$600=F$3)*(GMWA!$CZ$2:$CZ$600=F$4)*(GMWA!$DB$2:$DB$600=F$1),0),$A9-1966)} -> 916 | G9: {=INDEX(GMWA!$A$2:$DB$600,MATCH(1,(GMWA!$DA$2:$DA$600=G$3)*(GMWA!$CZ$2:$CZ$600=G$4)*(GMWA!$DB$2:$DB$600=G$1),0),$A9-1966)} -> 2.374895 | H9: {=INDEX(GMWA!$A$2:$DB$600,MATCH(1,(GMWA!$DA$2:$DA$600=H$3)*(GMWA!$CZ$2:$CZ$600=H$4)*(GMWA!$DB$2:$DB$600=H$1),0),$A9-1966)} -> 5346.4 | I9: {=INDEX(GMWA!$A$2:$DB$600,MATCH(1,(GMWA!$DA$2:$DA$600=I$3)*(GMWA!$CZ$2:$CZ$600=I$4)*(GMWA!$DB$2:$DB$600=I$1),0),$A9-1966)} -> 2.686347 | ... BI9: {=INDEX(GMWA!$A$2:$DB$600,MATCH(1,(GMWA!$DA$2:$DA$600=BI$3)*(GMWA!$CZ$2:$CZ$600=BI$4)*(GMWA!$DB$2:$DB$600=BI$1),0),$A9-1966)} -> 23.33603 | BK9: =100*(B9/V9) -> 7.883983 | BL9: =100*(C9/W9) -> 5.4832482 | BM9: =100*(D9/X9) -> 5.7552955 | BN9: =100*(E9/Y9) -> 8.0669267 | BO9: =100*(F9/Z9) -> 91600000 | BP9: =100*(G9/AA9) -> 1.4220928 | BQ9: =100*(H9/AB9) -> 5.9776213 | BR9: =100*(I9/AC9) -> 2.5110529 | ... CD9: =100*(U9/AO9) -> 0.60098917 | CF9: =SUMIF(DataQ!$C:$C,DataA!$A9,DataQ!H:H) -> 6152.5 | CG9: =SUMIF(DataQ!$C:$C,DataA!$A9,DataQ!I:I) -> 218644.29 | CH9: =SUMIF(DataQ!$C:$C,DataA!$A9,DataQ!J:J) -> 1571.03 | CI9: =SUMIF(DataQ!$C:$C,DataA!$A9,DataQ!K:K) -> 1041.161 | CJ9: =SUMIF(DataQ!$C:$C,DataA!$A9,DataQ!L:L) -> 971.922 | CK9: =AVERAGEIF(DataQ!$C:$C,DataA!$A9,DataQ!M:M) -> 188382.77 | CL9: =SUMIF(DataQ!$C:$C,DataA!$A9,DataQ!N:N) -> -7651 | CN9: =SUMIF(DataQ!$B:$B,DataA!$A9,DataQ!O:O) -> -128.606 | CO9: =SUMIF(DataQ!$B:$B,DataA!$A9,DataQ!P:P) -> -7342 | CP9: =SUMIF(DataQ!$B:$B,DataA!$A9,DataQ!Q:Q) -> -62.44885
A10: =+A9+1 -> 1976 | B10: {=INDEX(GMWA!$A$2:$DB$600,MATCH(1,(GMWA!$DA$2:$DA$600=B$3)*(GMWA!$CZ$2:$CZ$600=B$4)*(GMWA!$DB$2:$DB$600=B$1),0),$A10-1966)} -> 6380 | C10: {=INDEX(GMWA!$A$2:$DB$600,MATCH(1,(GMWA!$DA$2:$DA$600=C$3)*(GMWA!$CZ$2:$CZ$600=C$4)*(GMWA!$DB$2:$DB$600=C$1),0),$A10-1966)} -> 86.725 | D10: {=INDEX(GMWA!$A$2:$DB$600,MATCH(1,(GMWA!$DA$2:$DA$600=D$3)*(GMWA!$CZ$2:$CZ$600=D$4)*(GMWA!$DB$2:$DB$600=D$1),0),$A10-1966)} -> 2416.859 | E10: {=INDEX(GMWA!$A$2:$DB$600,MATCH(1,(GMWA!$DA$2:$DA$600=E$3)*(GMWA!$CZ$2:$CZ$600=E$4)*(GMWA!$DB$2:$DB$600=E$1),0),$A10-1966)} -> 8242 | F10: {=INDEX(GMWA!$A$2:$DB$600,MATCH(1,(GMWA!$DA$2:$DA$600=F$3)*(GMWA!$CZ$2:$CZ$600=F$4)*(GMWA!$DB$2:$DB$600=F$1),0),$A10-1966)} -> 1191 | G10: {=INDEX(GMWA!$A$2:$DB$600,MATCH(1,(GMWA!$DA$2:$DA$600=G$3)*(GMWA!$CZ$2:$CZ$600=G$4)*(GMWA!$DB$2:$DB$600=G$1),0),$A10-1966)} -> 3.083249 | H10: {=INDEX(GMWA!$A$2:$DB$600,MATCH(1,(GMWA!$DA$2:$DA$600=H$3)*(GMWA!$CZ$2:$CZ$600=H$4)*(GMWA!$DB$2:$DB$600=H$1),0),$A10-1966)} -> 5906.224 | I10: {=INDEX(GMWA!$A$2:$DB$600,MATCH(1,(GMWA!$DA$2:$DA$600=I$3)*(GMWA!$CZ$2:$CZ$600=I$4)*(GMWA!$DB$2:$DB$600=I$1),0),$A10-1966)} -> 2.877871 | ... BI10: {=INDEX(GMWA!$A$2:$DB$600,MATCH(1,(GMWA!$DA$2:$DA$600=BI$3)*(GMWA!$CZ$2:$CZ$600=BI$4)*(GMWA!$DB$2:$DB$600=BI$1),0),$A10-1966)} -> 23.33603 | BK10: =100*(B10/V10) -> 8.6917724 | BL10: =100*(C10/W10) -> 5.7000533 | BM10: =100*(D10/X10) -> 5.4821463 | BN10: =100*(E10/Y10) -> 9.0138565 | BO10: =100*(F10/Z10) -> 119100000 | BP10: =100*(G10/AA10) -> 1.8462569 | BQ10: =100*(H10/AB10) -> 6.2582121 | BR10: =100*(I10/AC10) -> 2.6295615 | ... CD10: =100*(U10/AO10) -> 0.39665304 | CF10: =SUMIF(DataQ!$C:$C,DataA!$A10,DataQ!H:H) -> 6438.45 | CG10: =SUMIF(DataQ!$C:$C,DataA!$A10,DataQ!I:I) -> 226948.07 | CH10: =SUMIF(DataQ!$C:$C,DataA!$A10,DataQ!J:J) -> 1644.12 | CI10: =SUMIF(DataQ!$C:$C,DataA!$A10,DataQ!K:K) -> 1090.008 | CJ10: =SUMIF(DataQ!$C:$C,DataA!$A10,DataQ!L:L) -> 1039.9587 | CK10: =AVERAGEIF(DataQ!$C:$C,DataA!$A10,DataQ!M:M) -> 198585.85 | CL10: =SUMIF(DataQ!$C:$C,DataA!$A10,DataQ!N:N) -> -7004 | CN10: =SUMIF(DataQ!$B:$B,DataA!$A10,DataQ!O:O) -> -104.50225 | CO10: =SUMIF(DataQ!$B:$B,DataA!$A10,DataQ!P:P) -> -9301 | CP10: =SUMIF(DataQ!$B:$B,DataA!$A10,DataQ!Q:Q) -> -53.17428
A11: =+A10+1 -> 1977 | B11: {=INDEX(GMWA!$A$2:$DB$600,MATCH(1,(GMWA!$DA$2:$DA$600=B$3)*(GMWA!$CZ$2:$CZ$600=B$4)*(GMWA!$DB$2:$DB$600=B$1),0),$A11-1966)} -> 7333 | C11: {=INDEX(GMWA!$A$2:$DB$600,MATCH(1,(GMWA!$DA$2:$DA$600=C$3)*(GMWA!$CZ$2:$CZ$600=C$4)*(GMWA!$DB$2:$DB$600=C$1),0),$A11-1966)} -> 95.75 | D11: {=INDEX(GMWA!$A$2:$DB$600,MATCH(1,(GMWA!$DA$2:$DA$600=D$3)*(GMWA!$CZ$2:$CZ$600=D$4)*(GMWA!$DB$2:$DB$600=D$1),0),$A11-1966)} -> 3374.968 | E11: {=INDEX(GMWA!$A$2:$DB$600,MATCH(1,(GMWA!$DA$2:$DA$600=E$3)*(GMWA!$CZ$2:$CZ$600=E$4)*(GMWA!$DB$2:$DB$600=E$1),0),$A11-1966)} -> 9432 | F11: {=INDEX(GMWA!$A$2:$DB$600,MATCH(1,(GMWA!$DA$2:$DA$600=F$3)*(GMWA!$CZ$2:$CZ$600=F$4)*(GMWA!$DB$2:$DB$600=F$1),0),$A11-1966)} -> 1532 | G11: {=INDEX(GMWA!$A$2:$DB$600,MATCH(1,(GMWA!$DA$2:$DA$600=G$3)*(GMWA!$CZ$2:$CZ$600=G$4)*(GMWA!$DB$2:$DB$600=G$1),0),$A11-1966)} -> 4.659654 | H11: {=INDEX(GMWA!$A$2:$DB$600,MATCH(1,(GMWA!$DA$2:$DA$600=H$3)*(GMWA!$CZ$2:$CZ$600=H$4)*(GMWA!$DB$2:$DB$600=H$1),0),$A11-1966)} -> 7658.689 | I11: {=INDEX(GMWA!$A$2:$DB$600,MATCH(1,(GMWA!$DA$2:$DA$600=I$3)*(GMWA!$CZ$2:$CZ$600=I$4)*(GMWA!$DB$2:$DB$600=I$1),0),$A11-1966)} -> 3.113591 | ... BI11: {=INDEX(GMWA!$A$2:$DB$600,MATCH(1,(GMWA!$DA$2:$DA$600=BI$3)*(GMWA!$CZ$2:$CZ$600=BI$4)*(GMWA!$DB$2:$DB$600=BI$1),0),$A11-1966)} -> 23.33603 | BK11: =100*(B11/V11) -> 8.7542007 | BL11: =100*(C11/W11) -> 5.8415776 | BM11: =100*(D11/X11) -> 5.7274684 | BN11: =100*(E11/Y11) -> 9.0254918 | BO11: =100*(F11/Z11) -> 153200000 | BP11: =100*(G11/AA11) -> 2.790212 | BQ11: =100*(H11/AB11) -> 6.8751057 | BR11: =100*(I11/AC11) -> 2.8045341 | ... CD11: =100*(U11/AO11) -> 0.28413531 | CF11: =SUMIF(DataQ!$C:$C,DataA!$A11,DataQ!H:H) -> 6749.975 | CG11: =SUMIF(DataQ!$C:$C,DataA!$A11,DataQ!I:I) -> 237285.12 | CH11: =SUMIF(DataQ!$C:$C,DataA!$A11,DataQ!J:J) -> 1695.09 | CI11: =SUMIF(DataQ!$C:$C,DataA!$A11,DataQ!K:K) -> 1125.804 | CJ11: =SUMIF(DataQ!$C:$C,DataA!$A11,DataQ!L:L) -> 1051.1927 | CK11: =AVERAGEIF(DataQ!$C:$C,DataA!$A11,DataQ!M:M) -> 205230.4 | CL11: =SUMIF(DataQ!$C:$C,DataA!$A11,DataQ!N:N) -> -6424 | CN11: =SUMIF(DataQ!$B:$B,DataA!$A11,DataQ!O:O) -> -88.151 | CO11: =SUMIF(DataQ!$B:$B,DataA!$A11,DataQ!P:P) -> -10191.75 | CP11: =SUMIF(DataQ!$B:$B,DataA!$A11,DataQ!Q:Q) -> -44.70044
A12: =+A11+1 -> 1978 | B12: {=INDEX(GMWA!$A$2:$DB$600,MATCH(1,(GMWA!$DA$2:$DA$600=B$3)*(GMWA!$CZ$2:$CZ$600=B$4)*(GMWA!$DB$2:$DB$600=B$1),0),$A12-1966)} -> 8160 | C12: {=INDEX(GMWA!$A$2:$DB$600,MATCH(1,(GMWA!$DA$2:$DA$600=C$3)*(GMWA!$CZ$2:$CZ$600=C$4)*(GMWA!$DB$2:$DB$600=C$1),0),$A12-1966)} -> 112.45 | D12: {=INDEX(GMWA!$A$2:$DB$600,MATCH(1,(GMWA!$DA$2:$DA$600=D$3)*(GMWA!$CZ$2:$CZ$600=D$4)*(GMWA!$DB$2:$DB$600=D$1),0),$A12-1966)} -> 4369.668 | E12: {=INDEX(GMWA!$A$2:$DB$600,MATCH(1,(GMWA!$DA$2:$DA$600=E$3)*(GMWA!$CZ$2:$CZ$600=E$4)*(GMWA!$DB$2:$DB$600=E$1),0),$A12-1966)} -> 11741 | F12: {=INDEX(GMWA!$A$2:$DB$600,MATCH(1,(GMWA!$DA$2:$DA$600=F$3)*(GMWA!$CZ$2:$CZ$600=F$4)*(GMWA!$DB$2:$DB$600=F$1),0),$A12-1966)} -> 1796 | G12: {=INDEX(GMWA!$A$2:$DB$600,MATCH(1,(GMWA!$DA$2:$DA$600=G$3)*(GMWA!$CZ$2:$CZ$600=G$4)*(GMWA!$DB$2:$DB$600=G$1),0),$A12-1966)} -> 6.209607 | H12: {=INDEX(GMWA!$A$2:$DB$600,MATCH(1,(GMWA!$DA$2:$DA$600=H$3)*(GMWA!$CZ$2:$CZ$600=H$4)*(GMWA!$DB$2:$DB$600=H$1),0),$A12-1966)} -> 9006.922 | I12: {=INDEX(GMWA!$A$2:$DB$600,MATCH(1,(GMWA!$DA$2:$DA$600=I$3)*(GMWA!$CZ$2:$CZ$600=I$4)*(GMWA!$DB$2:$DB$600=I$1),0),$A12-1966)} -> 3.064492 | ... BI12: {=INDEX(GMWA!$A$2:$DB$600,MATCH(1,(GMWA!$DA$2:$DA$600=BI$3)*(GMWA!$CZ$2:$CZ$600=BI$4)*(GMWA!$DB$2:$DB$600=BI$1),0),$A12-1966)} -> 23.33603 | BK12: =100*(B12/V12) -> 8.6681716 | BL12: =100*(C12/W12) -> 6.3230496 | BM12: =100*(D12/X12) -> 5.3183564 | BN12: =100*(E12/Y12) -> 9.5232302 | BO12: =100*(F12/Z12) -> 179600000 | BP12: =100*(G12/AA12) -> 3.7183275 | BQ12: =100*(H12/AB12) -> 6.2798084 | BR12: =100*(I12/AC12) -> 2.7169626 | ... CD12: =100*(U12/AO12) -> 0.20127852 | CF12: =SUMIF(DataQ!$C:$C,DataA!$A12,DataQ!H:H) -> 7163.325 | CG12: =SUMIF(DataQ!$C:$C,DataA!$A12,DataQ!I:I) -> 250526.42 | CH12: =SUMIF(DataQ!$C:$C,DataA!$A12,DataQ!J:J) -> 1749.22 | CI12: =SUMIF(DataQ!$C:$C,DataA!$A12,DataQ!K:K) -> 1172.004 | CJ12: =SUMIF(DataQ!$C:$C,DataA!$A12,DataQ!L:L) -> 1101.4476 | CK12: =AVERAGEIF(DataQ!$C:$C,DataA!$A12,DataQ!M:M) -> 212796.95 | CL12: =SUMIF(DataQ!$C:$C,DataA!$A12,DataQ!N:N) -> -8685 | CN12: =SUMIF(DataQ!$B:$B,DataA!$A12,DataQ!O:O) -> -81.16925 | CO12: =SUMIF(DataQ!$B:$B,DataA!$A12,DataQ!P:P) -> -13458 | CP12: =SUMIF(DataQ!$B:$B,DataA!$A12,DataQ!Q:Q) -> -52.05288
A13: =+A12+1 -> 1979 | B13: {=INDEX(GMWA!$A$2:$DB$600,MATCH(1,(GMWA!$DA$2:$DA$600=B$3)*(GMWA!$CZ$2:$CZ$600=B$4)*(GMWA!$DB$2:$DB$600=B$1),0),$A13-1966)} -> 9791 | C13: {=INDEX(GMWA!$A$2:$DB$600,MATCH(1,(GMWA!$DA$2:$DA$600=C$3)*(GMWA!$CZ$2:$CZ$600=C$4)*(GMWA!$DB$2:$DB$600=C$1),0),$A13-1966)} -> 128.475 | D13: {=INDEX(GMWA!$A$2:$DB$600,MATCH(1,(GMWA!$DA$2:$DA$600=D$3)*(GMWA!$CZ$2:$CZ$600=D$4)*(GMWA!$DB$2:$DB$600=D$1),0),$A13-1966)} -> 5571.224 | E13: {=INDEX(GMWA!$A$2:$DB$600,MATCH(1,(GMWA!$DA$2:$DA$600=E$3)*(GMWA!$CZ$2:$CZ$600=E$4)*(GMWA!$DB$2:$DB$600=E$1),0),$A13-1966)} -> 14057 | F13: {=INDEX(GMWA!$A$2:$DB$600,MATCH(1,(GMWA!$DA$2:$DA$600=F$3)*(GMWA!$CZ$2:$CZ$600=F$4)*(GMWA!$DB$2:$DB$600=F$1),0),$A13-1966)} -> 2136 | G13: {=INDEX(GMWA!$A$2:$DB$600,MATCH(1,(GMWA!$DA$2:$DA$600=G$3)*(GMWA!$CZ$2:$CZ$600=G$4)*(GMWA!$DB$2:$DB$600=G$1),0),$A13-1966)} -> 11.05835 | H13: {=INDEX(GMWA!$A$2:$DB$600,MATCH(1,(GMWA!$DA$2:$DA$600=H$3)*(GMWA!$CZ$2:$CZ$600=H$4)*(GMWA!$DB$2:$DB$600=H$1),0),$A13-1966)} -> 11487.63 | I13: {=INDEX(GMWA!$A$2:$DB$600,MATCH(1,(GMWA!$DA$2:$DA$600=I$3)*(GMWA!$CZ$2:$CZ$600=I$4)*(GMWA!$DB$2:$DB$600=I$1),0),$A13-1966)} -> 2.971176 | ... BI13: {=INDEX(GMWA!$A$2:$DB$600,MATCH(1,(GMWA!$DA$2:$DA$600=BI$3)*(GMWA!$CZ$2:$CZ$600=BI$4)*(GMWA!$DB$2:$DB$600=BI$1),0),$A13-1966)} -> 23.33603 | BK13: =100*(B13/V13) -> 9.3419333 | BL13: =100*(C13/W13) -> 6.6829829 | BM13: =100*(D13/X13) -> 5.6300012 | BN13: =100*(E13/Y13) -> 10.594664 | BO13: =100*(F13/Z13) -> 213600000 | BP13: =100*(G13/AA13) -> 6.6217665 | BQ13: =100*(H13/AB13) -> 6.2358653 | BR13: =100*(I13/AC13) -> 2.534986 | ... CD13: =100*(U13/AO13) -> 0.23387546 | CF13: =SUMIF(DataQ!$C:$C,DataA!$A13,DataQ!H:H) -> 7301.725 | CG13: =SUMIF(DataQ!$C:$C,DataA!$A13,DataQ!I:I) -> 264833.65 | CH13: =SUMIF(DataQ!$C:$C,DataA!$A13,DataQ!J:J) -> 1830.73 | CI13: =SUMIF(DataQ!$C:$C,DataA!$A13,DataQ!K:K) -> 1213.536 | CJ13: =SUMIF(DataQ!$C:$C,DataA!$A13,DataQ!L:L) -> 1160.2021 | CK13: =AVERAGEIF(DataQ!$C:$C,DataA!$A13,DataQ!M:M) -> 220753.85 | CL13: =SUMIF(DataQ!$C:$C,DataA!$A13,DataQ!N:N) -> -8546 | CN13: =SUMIF(DataQ!$B:$B,DataA!$A13,DataQ!O:O) -> -78.56225 | CO13: =SUMIF(DataQ!$B:$B,DataA!$A13,DataQ!P:P) -> -12426.5 | CP13: =SUMIF(DataQ!$B:$B,DataA!$A13,DataQ!Q:Q) -> -58.44036
A14: =+A13+1 -> 1980 | B14: {=INDEX(GMWA!$A$2:$DB$600,MATCH(1,(GMWA!$DA$2:$DA$600=B$3)*(GMWA!$CZ$2:$CZ$600=B$4)*(GMWA!$DB$2:$DB$600=B$1),0),$A14-1966)} -> 11972 | C14: {=INDEX(GMWA!$A$2:$DB$600,MATCH(1,(GMWA!$DA$2:$DA$600=C$3)*(GMWA!$CZ$2:$CZ$600=C$4)*(GMWA!$DB$2:$DB$600=C$1),0),$A14-1966)} -> 148.775 | D14: {=INDEX(GMWA!$A$2:$DB$600,MATCH(1,(GMWA!$DA$2:$DA$600=D$3)*(GMWA!$CZ$2:$CZ$600=D$4)*(GMWA!$DB$2:$DB$600=D$1),0),$A14-1966)} -> 7259.869 | E14: {=INDEX(GMWA!$A$2:$DB$600,MATCH(1,(GMWA!$DA$2:$DA$600=E$3)*(GMWA!$CZ$2:$CZ$600=E$4)*(GMWA!$DB$2:$DB$600=E$1),0),$A14-1966)} -> 17033 | F14: {=INDEX(GMWA!$A$2:$DB$600,MATCH(1,(GMWA!$DA$2:$DA$600=F$3)*(GMWA!$CZ$2:$CZ$600=F$4)*(GMWA!$DB$2:$DB$600=F$1),0),$A14-1966)} -> 2396 | G14: {=INDEX(GMWA!$A$2:$DB$600,MATCH(1,(GMWA!$DA$2:$DA$600=G$3)*(GMWA!$CZ$2:$CZ$600=G$4)*(GMWA!$DB$2:$DB$600=G$1),0),$A14-1966)} -> 13.37152 | H14: {=INDEX(GMWA!$A$2:$DB$600,MATCH(1,(GMWA!$DA$2:$DA$600=H$3)*(GMWA!$CZ$2:$CZ$600=H$4)*(GMWA!$DB$2:$DB$600=H$1),0),$A14-1966)} -> 16780.39 | I14: {=INDEX(GMWA!$A$2:$DB$600,MATCH(1,(GMWA!$DA$2:$DA$600=I$3)*(GMWA!$CZ$2:$CZ$600=I$4)*(GMWA!$DB$2:$DB$600=I$1),0),$A14-1966)} -> 3.154236 | ... BI14: {=INDEX(GMWA!$A$2:$DB$600,MATCH(1,(GMWA!$DA$2:$DA$600=BI$3)*(GMWA!$CZ$2:$CZ$600=BI$4)*(GMWA!$DB$2:$DB$600=BI$1),0),$A14-1966)} -> 23.33603 | BK14: =100*(B14/V14) -> 9.8501497 | BL14: =100*(C14/W14) -> 7.212106 | BM14: =100*(D14/X14) -> 6.1859824 | BN14: =100*(E14/Y14) -> 11.32566 | BO14: =100*(F14/Z14) -> 239600000 | BP14: =100*(G14/AA14) -> 7.5300266 | BQ14: =100*(H14/AB14) -> 6.4159937 | BR14: =100*(I14/AC14) -> 2.6313609 | ... CD14: =100*(U14/AO14) -> 0.12653751 | CF14: =SUMIF(DataQ!$C:$C,DataA!$A14,DataQ!H:H) -> 7286.675 | CG14: =SUMIF(DataQ!$C:$C,DataA!$A14,DataQ!I:I) -> 276054.26 | CH14: =SUMIF(DataQ!$C:$C,DataA!$A14,DataQ!J:J) -> 1834.03 | CI14: =SUMIF(DataQ!$C:$C,DataA!$A14,DataQ!K:K) -> 1221.947 | CJ14: =SUMIF(DataQ!$C:$C,DataA!$A14,DataQ!L:L) -> 1191.0443 | CK14: =AVERAGEIF(DataQ!$C:$C,DataA!$A14,DataQ!M:M) -> 225566.85 | CL14: =SUMIF(DataQ!$C:$C,DataA!$A14,DataQ!N:N) -> -11537 | CN14: =SUMIF(DataQ!$B:$B,DataA!$A14,DataQ!O:O) -> -128.273 | CO14: =SUMIF(DataQ!$B:$B,DataA!$A14,DataQ!P:P) -> -11822.5 | CP14: =SUMIF(DataQ!$B:$B,DataA!$A14,DataQ!Q:Q) -> -62.0868
A15: =+A14+1 -> 1981 | B15: {=INDEX(GMWA!$A$2:$DB$600,MATCH(1,(GMWA!$DA$2:$DA$600=B$3)*(GMWA!$CZ$2:$CZ$600=B$4)*(GMWA!$DB$2:$DB$600=B$1),0),$A15-1966)} -> 14207 | C15: {=INDEX(GMWA!$A$2:$DB$600,MATCH(1,(GMWA!$DA$2:$DA$600=C$3)*(GMWA!$CZ$2:$CZ$600=C$4)*(GMWA!$DB$2:$DB$600=C$1),0),$A15-1966)} -> 180.075 | D15: {=INDEX(GMWA!$A$2:$DB$600,MATCH(1,(GMWA!$DA$2:$DA$600=D$3)*(GMWA!$CZ$2:$CZ$600=D$4)*(GMWA!$DB$2:$DB$600=D$1),0),$A15-1966)} -> 8747.427 | E15: {=INDEX(GMWA!$A$2:$DB$600,MATCH(1,(GMWA!$DA$2:$DA$600=E$3)*(GMWA!$CZ$2:$CZ$600=E$4)*(GMWA!$DB$2:$DB$600=E$1),0),$A15-1966)} -> 22530 | F15: {=INDEX(GMWA!$A$2:$DB$600,MATCH(1,(GMWA!$DA$2:$DA$600=F$3)*(GMWA!$CZ$2:$CZ$600=F$4)*(GMWA!$DB$2:$DB$600=F$1),0),$A15-1966)} -> 2661 | G15: {=INDEX(GMWA!$A$2:$DB$600,MATCH(1,(GMWA!$DA$2:$DA$600=G$3)*(GMWA!$CZ$2:$CZ$600=G$4)*(GMWA!$DB$2:$DB$600=G$1),0),$A15-1966)} -> 19.54586 | H15: {=INDEX(GMWA!$A$2:$DB$600,MATCH(1,(GMWA!$DA$2:$DA$600=H$3)*(GMWA!$CZ$2:$CZ$600=H$4)*(GMWA!$DB$2:$DB$600=H$1),0),$A15-1966)} -> 24984.48 | I15: {=INDEX(GMWA!$A$2:$DB$600,MATCH(1,(GMWA!$DA$2:$DA$600=I$3)*(GMWA!$CZ$2:$CZ$600=I$4)*(GMWA!$DB$2:$DB$600=I$1),0),$A15-1966)} -> 3.402169 | ... BI15: {=INDEX(GMWA!$A$2:$DB$600,MATCH(1,(GMWA!$DA$2:$DA$600=BI$3)*(GMWA!$CZ$2:$CZ$600=BI$4)*(GMWA!$DB$2:$DB$600=BI$1),0),$A15-1966)} -> 23.33603 | BK15: =100*(B15/V15) -> 10.779906 | BL15: =100*(C15/W15) -> 7.9794553 | BM15: =100*(D15/X15) -> 6.1832381 | BN15: =100*(E15/Y15) -> 12.703478 | BO15: =100*(F15/Z15) -> 266100000 | BP15: =100*(G15/AA15) -> 8.206133 | BQ15: =100*(H15/AB15) -> 7.4091182 | BR15: =100*(I15/AC15) -> 2.8492899 | ... CD15: =100*(U15/AO15) -> 0.084084135 | CF15: =SUMIF(DataQ!$C:$C,DataA!$A15,DataQ!H:H) -> 7400.625 | CG15: =SUMIF(DataQ!$C:$C,DataA!$A15,DataQ!I:I) -> 287278.26 | CH15: =SUMIF(DataQ!$C:$C,DataA!$A15,DataQ!J:J) -> 1847.27 | CI15: =SUMIF(DataQ!$C:$C,DataA!$A15,DataQ!K:K) -> 1246.444 | CJ15: =SUMIF(DataQ!$C:$C,DataA!$A15,DataQ!L:L) -> 1200.915 | CK15: =AVERAGEIF(DataQ!$C:$C,DataA!$A15,DataQ!M:M) -> 230470.8 | CL15: =SUMIF(DataQ!$C:$C,DataA!$A15,DataQ!N:N) -> -5999 | CN15: =SUMIF(DataQ!$B:$B,DataA!$A15,DataQ!O:O) -> -130.469 | CO15: =SUMIF(DataQ!$B:$B,DataA!$A15,DataQ!P:P) -> -10937.75 | CP15: =SUMIF(DataQ!$B:$B,DataA!$A15,DataQ!Q:Q) -> -75.16716
A16: =+A15+1 -> 1982 | B16: {=INDEX(GMWA!$A$2:$DB$600,MATCH(1,(GMWA!$DA$2:$DA$600=B$3)*(GMWA!$CZ$2:$CZ$600=B$4)*(GMWA!$DB$2:$DB$600=B$1),0),$A16-1966)} -> 15540 | C16: {=INDEX(GMWA!$A$2:$DB$600,MATCH(1,(GMWA!$DA$2:$DA$600=C$3)*(GMWA!$CZ$2:$CZ$600=C$4)*(GMWA!$DB$2:$DB$600=C$1),0),$A16-1966)} -> 206.175 | D16: {=INDEX(GMWA!$A$2:$DB$600,MATCH(1,(GMWA!$DA$2:$DA$600=D$3)*(GMWA!$CZ$2:$CZ$600=D$4)*(GMWA!$DB$2:$DB$600=D$1),0),$A16-1966)} -> 10090.23 | E16: {=INDEX(GMWA!$A$2:$DB$600,MATCH(1,(GMWA!$DA$2:$DA$600=E$3)*(GMWA!$CZ$2:$CZ$600=E$4)*(GMWA!$DB$2:$DB$600=E$1),0),$A16-1966)} -> 27419 | F16: {=INDEX(GMWA!$A$2:$DB$600,MATCH(1,(GMWA!$DA$2:$DA$600=F$3)*(GMWA!$CZ$2:$CZ$600=F$4)*(GMWA!$DB$2:$DB$600=F$1),0),$A16-1966)} -> 3141 | G16: {=INDEX(GMWA!$A$2:$DB$600,MATCH(1,(GMWA!$DA$2:$DA$600=G$3)*(GMWA!$CZ$2:$CZ$600=G$4)*(GMWA!$DB$2:$DB$600=G$1),0),$A16-1966)} -> 25.32144 | H16: {=INDEX(GMWA!$A$2:$DB$600,MATCH(1,(GMWA!$DA$2:$DA$600=H$3)*(GMWA!$CZ$2:$CZ$600=H$4)*(GMWA!$DB$2:$DB$600=H$1),0),$A16-1966)} -> 36744.3 | I16: {=INDEX(GMWA!$A$2:$DB$600,MATCH(1,(GMWA!$DA$2:$DA$600=I$3)*(GMWA!$CZ$2:$CZ$600=I$4)*(GMWA!$DB$2:$DB$600=I$1),0),$A16-1966)} -> 3.559402 | ... BI16: {=INDEX(GMWA!$A$2:$DB$600,MATCH(1,(GMWA!$DA$2:$DA$600=BI$3)*(GMWA!$CZ$2:$CZ$600=BI$4)*(GMWA!$DB$2:$DB$600=BI$1),0),$A16-1966)} -> 23.33603 | BK16: =100*(B16/V16) -> 11.054298 | BL16: =100*(C16/W16) -> 8.1418143 | BM16: =100*(D16/X16) -> 6.1080353 | BN16: =100*(E16/Y16) -> 13.073351 | BO16: =100*(F16/Z16) -> 314100000 | BP16: =100*(G16/AA16) -> 7.6570143 | BQ16: =100*(H16/AB16) -> 8.4123511 | BR16: =100*(I16/AC16) -> 3.0338252 | ... CD16: =100*(U16/AO16) -> 0.06360694 | CF16: =SUMIF(DataQ!$C:$C,DataA!$A16,DataQ!H:H) -> 7333.425 | CG16: =SUMIF(DataQ!$C:$C,DataA!$A16,DataQ!I:I) -> 296695.96 | CH16: =SUMIF(DataQ!$C:$C,DataA!$A16,DataQ!J:J) -> 1834.54 | CI16: =SUMIF(DataQ!$C:$C,DataA!$A16,DataQ!K:K) -> 1272.743 | CJ16: =SUMIF(DataQ!$C:$C,DataA!$A16,DataQ!L:L) -> 1200.73 | CK16: =AVERAGEIF(DataQ!$C:$C,DataA!$A16,DataQ!M:M) -> 223200.35 | CL16: =SUMIF(DataQ!$C:$C,DataA!$A16,DataQ!N:N) -> -8542 | CN16: =SUMIF(DataQ!$B:$B,DataA!$A16,DataQ!O:O) -> -220.126 | CO16: =SUMIF(DataQ!$B:$B,DataA!$A16,DataQ!P:P) -> -11134.25 | CP16: =SUMIF(DataQ!$B:$B,DataA!$A16,DataQ!Q:Q) -> -74.95508
A17: =+A16+1 -> 1983 | B17: {=INDEX(GMWA!$A$2:$DB$600,MATCH(1,(GMWA!$DA$2:$DA$600=B$3)*(GMWA!$CZ$2:$CZ$600=B$4)*(GMWA!$DB$2:$DB$600=B$1),0),$A17-1966)} -> 15996 | C17: {=INDEX(GMWA!$A$2:$DB$600,MATCH(1,(GMWA!$DA$2:$DA$600=C$3)*(GMWA!$CZ$2:$CZ$600=C$4)*(GMWA!$DB$2:$DB$600=C$1),0),$A17-1966)} -> 227.975 | D17: {=INDEX(GMWA!$A$2:$DB$600,MATCH(1,(GMWA!$DA$2:$DA$600=D$3)*(GMWA!$CZ$2:$CZ$600=D$4)*(GMWA!$DB$2:$DB$600=D$1),0),$A17-1966)} -> 11534.9 | E17: {=INDEX(GMWA!$A$2:$DB$600,MATCH(1,(GMWA!$DA$2:$DA$600=E$3)*(GMWA!$CZ$2:$CZ$600=E$4)*(GMWA!$DB$2:$DB$600=E$1),0),$A17-1966)} -> 29858 | F17: {=INDEX(GMWA!$A$2:$DB$600,MATCH(1,(GMWA!$DA$2:$DA$600=F$3)*(GMWA!$CZ$2:$CZ$600=F$4)*(GMWA!$DB$2:$DB$600=F$1),0),$A17-1966)} -> 3764 | G17: {=INDEX(GMWA!$A$2:$DB$600,MATCH(1,(GMWA!$DA$2:$DA$600=G$3)*(GMWA!$CZ$2:$CZ$600=G$4)*(GMWA!$DB$2:$DB$600=G$1),0),$A17-1966)} -> 37.50747 | H17: {=INDEX(GMWA!$A$2:$DB$600,MATCH(1,(GMWA!$DA$2:$DA$600=H$3)*(GMWA!$CZ$2:$CZ$600=H$4)*(GMWA!$DB$2:$DB$600=H$1),0),$A17-1966)} -> 43218.67 | I17: {=INDEX(GMWA!$A$2:$DB$600,MATCH(1,(GMWA!$DA$2:$DA$600=I$3)*(GMWA!$CZ$2:$CZ$600=I$4)*(GMWA!$DB$2:$DB$600=I$1),0),$A17-1966)} -> 3.657443 | ... BI17: {=INDEX(GMWA!$A$2:$DB$600,MATCH(1,(GMWA!$DA$2:$DA$600=BI$3)*(GMWA!$CZ$2:$CZ$600=BI$4)*(GMWA!$DB$2:$DB$600=BI$1),0),$A17-1966)} -> 23.33603 | BK17: =100*(B17/V17) -> 10.51792 | BL17: =100*(C17/W17) -> 8.106654 | BM17: =100*(D17/X17) -> 6.0747088 | BN17: =100*(E17/Y17) -> 11.854622 | BO17: =100*(F17/Z17) -> 376400000 | BP17: =100*(G17/AA17) -> 8.8404927 | BQ17: =100*(H17/AB17) -> 8.3091047 | BR17: =100*(I17/AC17) -> 3.1183198 | ... CD17: =100*(U17/AO17) -> 0.0458311 | CF17: =SUMIF(DataQ!$C:$C,DataA!$A17,DataQ!H:H) -> 7800.95 | CG17: =SUMIF(DataQ!$C:$C,DataA!$A17,DataQ!I:I) -> 307848.46 | CH17: =SUMIF(DataQ!$C:$C,DataA!$A17,DataQ!J:J) -> 1879.96 | CI17: =SUMIF(DataQ!$C:$C,DataA!$A17,DataQ!K:K) -> 1287.699 | CJ17: =SUMIF(DataQ!$C:$C,DataA!$A17,DataQ!L:L) -> 1229.587 | CK17: =AVERAGEIF(DataQ!$C:$C,DataA!$A17,DataQ!M:M) -> 233186.72 | CL17: =SUMIF(DataQ!$C:$C,DataA!$A17,DataQ!N:N) -> -11802 | CN17: =SUMIF(DataQ!$B:$B,DataA!$A17,DataQ!O:O) -> -265.23725 | CO17: =SUMIF(DataQ!$B:$B,DataA!$A17,DataQ!P:P) -> -11809.25 | CP17: =SUMIF(DataQ!$B:$B,DataA!$A17,DataQ!Q:Q) -> -71.17676
