Workbook
Name _DLX1.INC: 'Haver Q'!$P$3:$T$8
Name _DLX2.INC: 'Haver Q'!$A$3:$L$8
Name _DLX3.INC: 'Series construction'!$A$4:$K$9
Name _DLX4.INC: 'Haver Q'!$W$3:$BA$8
Name Annual_Data: GMWQ!$A$1:$A$2

Sheet Notes
A2: Notes:
A4: - | B4: First step is to have everything setup in a proper workfile structure so Eviews imports the data from an excel file (incl REPO and WORMRT), generates certain variables, then can try and save various regressions - Alessandro won't help unless the Eviews work is set out nicely
A6: - | B6: Try logging everything (e.g. ARR/NOMORT, PEDIP_UNADJ/PEDY!, MRTPE/PEDY!, maybe HHLIAB), have UPILO in levels as already stationary (and the differenced UPILO series is essentially just noise). Logged ratios is fine because these ratios never really come too close to zero.
A7: - | B7: Can try adding MRTPE/MVH (mortgage liabilities as % of housing value) because greater liabilities aren't a huge issue if the collateralised asset has appreciated markedly
A8: - | B8: Can try adding RBM as an explanatory variable
A9: - | B9: Can try adding a variable for personal loans (as % of incomes) as a big jump in credit card payments could make you miss mortgage payments (unlikely in my opinion).
A10: - | B10: Generally it's best to not have self-lags as it's a false fit (over fit). Means the forecast will be very sticky in scenarios which is silly
A11: - | B11: Can spread coefficients over more than one lag, e.g. if coeff on PEDIP_UNADJ/PEDY!(-1) is 0.5 then can adjust this to 0.05 on contemporaneous and 0.45 on first lag
A12: - | B12: Andy is happy for the forecast to be driven by the data rather than pure narrative, so a gradual fall from here is absolutely fine (will want a residual transformation which always smoothes back to zero/1)
A13: - | B13: If nothing works then can try ARR/WORMRT (but it's sequentially illogical to model arrears that way, but could try something like that with REPO?)
A15: - | B15: When doing REPO, sensible to just have this running off ARR (e.g. REPO(-1) X% of arrears turn into repossessions)
A16: - | B16: If adding a behavioural equation, can do the eviews work with a pandemic dummy to get senisble coefficients, then remove the dummy when adding it to the model and adjust the coefficient.
Q19: R2 | R19: Adj R2 | S19: SE | T19: RSS | U19: AIC | V19: SBC | W19: HQN
B20: arr/nomort = c(1) + c(2) * log(pedip_unadj_pedy(-1)) + c(3) * log(mrtpe/mvh(-1)) + c(4) * upilo(-1) | P20: 1 | Q20: 0.90663364 | R20: 0.90204185 | S20: 1.0774257 | T20: 70.811609 | U20: 3.0465897 | V20: 3.1803981 | W20: 3.0993857
B21: arr/nomort = c(1) + c(2) * log(pedip_unadj_pedy(-1)) + c(3) * log(mrtpe/mvh(-1)) + c(4) * upilo(-2) | P21: 2 | Q21: 0.90365432 | R21: 0.89883703 | S21: 1.1027297 | T21: 72.960771 | U21: 3.0939159 | V21: 3.2288461 | W21: 3.1470717
B22: arr/nomort = c(1) + c(2) * log(pedip_unadj_pedy(-1)) + c(3) * log(mrtpe/mvh(-2)) + c(4) * upilo(-2) | P22: 3 | Q22: 0.90343464 | R22: 0.89860637 | S22: 1.1039862 | T22: 73.127131 | U22: 3.0961934 | V22: 3.2311236 | W22: 3.1493492
B23: arr/nomort = c(1) + c(2) * log(pedip_unadj_pedy(-2)) + c(3) * log(mrtpe/mvh(-2)) + c(4) * upilo(-2) | P23: 4 | Q23: 0.91418844 | R23: 0.90989786 | S23: 1.0407007 | T23: 64.983482 | U23: 2.9781271 | V23: 3.1130573 | W23: 3.0312829
B25: arr/nomort = c(1) + c(2) * log(pedip_unadj_pedy(-1)) + c(3) * log(pedip_unadj_pedy(-2)) + c(4) * log(mrtpe/mvh(-1)) + c(5) * upilo(-1) | P25: 5 | Q25: 0.93533384 | R25: 0.93094969 | S25: 0.91104772 | T25: 48.970468 | U25: 2.7264614 | V25: 2.8951242 | W25: 2.7929062
B26: arr/nomort = c(1) + c(2) * log(pedip_unadj_pedy(-1)) + c(3) * log(pedip_unadj_pedy(-2)) + c(4) * log(mrtpe/mvh(-1)) + c(5) * upilo(-2) | P26: 6 | Q26: 0.91513996 | R26: 0.90938674 | S26: 1.0436484 | T26: 64.262912 | U26: 2.9982267 | V26: 3.1668894 | W26: 3.0646714
B28: arr/nomort = c(1) + c(2) * log(pedip_unadj_pedy(-1)) + c(3) * log(mrtpe/mvh(-1)) + c(4) * upilo(-1) + c(5) * pinsolv_popw(-1) | P28: 7 | Q28: 0.93817004 | R28: 0.93404804 | S28: 0.88405828 | T28: 46.893542 | U28: 2.6652159 | V28: 2.8324765 | W28: 2.7312109
B29: arr/nomort = c(1) + c(2) * log(pedip_unadj_pedy(-1)) + c(3) * upilo(-1) + c(4) * pinsolv_popw(-1) | P29: 8 | Q29: 0.93145155 | R29: 0.92808031 | S29: 0.92318965 | T29: 51.989027 | U29: 2.7375994 | V29: 2.8714078 | W29: 2.7903954
B30: arr/nomort = c(1) + c(2) * log(pedip_unadj_pedy(-1)) + c(3) * upilo(-2) + c(4) * pinsolv_popw(-2) | P30: 9 | Q30: 0.93106026 | R30: 0.92761327 | S30: 0.93279837 | T30: 52.206768 | U30: 2.7592061 | V30: 2.8941363 | W30: 2.8123619
B31: arr/nomort = c(1) + c(2) * log(pedip_unadj_pedy(-2)) + c(3) * upilo(-2) + c(4) * pinsolv_popw(-2) | P31: 10 | Q31: 0.93512962 | R31: 0.9318861 | S31: 0.90484912 | T31: 49.125116 | U31: 2.6983644 | V31: 2.8332946 | W31: 2.7515202
B32: arr/nomort = c(1) + c(2) * log(pedip_unadj_pedy(-2)) + c(3) * upilo(-2) + c(4) * pinsolv_popw(-2) | P32: 11 | Q32: 0.93512962 | R32: 0.9318861 | S32: 0.90484912 | T32: 49.125116 | U32: 2.6983644 | V32: 2.8332946 | W32: 2.7515202
A33: * | B33: arr/nomort = c(1) + c(2) * log(pedip_unadj_pedy(-1)) + c(3) * upilo(-1) + c(4) * pinsolv_popw(-1) + c(5) * rrh(-1) | P33: 12 | Q33: 0.9549819 | R33: 0.9519807 | S33: 0.75435357 | T33: 34.142959 | U33: 2.3478923 | V33: 2.5151529 | W33: 2.4138873
B34: arr/nomort = c(1) + c(2) * log(pedip_unadj_pedy(-1)) + c(3) * upilo(-2) + c(4) * pinsolv_popw(-1) + c(5) * rrh(-1) | P34: 13 | Q34: 0.95386652 | R34: 0.95073883 | S34: 0.76950361 | T34: 34.936012 | U34: 2.3887621 | V34: 2.5574249 | W34: 2.4552069
B35: arr/nomort = c(1) + c(2) * log(pedip_unadj_pedy(-1)) + c(3) * upilo(-2) + c(4) * pinsolv_popw(-2) + c(5) * rrh(-2) | P35: 14 | Q35: 0.95045896 | R35: 0.94710025 | S35: 0.79741633 | T35: 37.516496 | U35: 2.4600247 | V35: 2.6286874 | W35: 2.5264695
B36: arr/nomort = c(1) + c(2) * log(pedip_unadj_pedy(-2)) + c(3) * upilo(-2) + c(4) * pinsolv_popw(-2) + c(5) * rrh(-2) | P36: 15 | Q36: 0.94928193 | R36: 0.94584341 | S36: 0.80683356 | T36: 38.407843 | U36: 2.4835057 | V36: 2.6521684 | W36: 2.5499504
A37: * | B37: arr/nomort = c(1) + c(2) * log(pedip_unadj_pedy(-1)) + c(3) * upilo(-1) + c(4) * pinsolv(-1) + c(5) * rrh(-1) | P37: 16 | Q37: 0.95592001 | R37: 0.95298134 | S37: 0.74645247 | T37: 33.431477 | U37: 2.3268338 | V37: 2.4940944 | W37: 2.3928288
A39: * | B39: arr/nomort = c(1) + c(2) * log(pedip_unadj_pedy(-1)) + c(3) * upilo(-1) + c(4) * rrh(-1) | P39: 17 | Q39: 0.94205151 | R39: 0.93920158 | S39: 0.84881524 | T39: 43.949726 | U39: 2.5696131 | V39: 2.7034216 | W39: 2.6224091
A40: * | B40: arr/nomort = c(1) + c(2) * log(pedip_unadj_pedy(-1)) + c(3) * upilo(-2) + c(4) * rrh(-1) | P40: 18 | Q40: 0.93991231 | R40: 0.93690793 | S40: 0.87085469 | T40: 45.503273 | U40: 2.6217782 | V40: 2.7567084 | W40: 2.6749341
B41: arr/nomort = c(1) + c(2) * log(pedip_unadj_pedy(-1)) + c(3) * upilo(-2) + c(4) * rrh(-2) | P41: 19 | Q41: 0.93718986 | R41: 0.93404935 | S41: 0.89036452 | T41: 47.564939 | U41: 2.6660899 | V41: 2.8010201 | W41: 2.7192457
A42: * | B42: arr/nomort = c(1) + c(2) * log(pedip_unadj_pedy(-1)) + c(3) * upilo(-1) + c(4) * mrtpe_mvh(-1) + c(5) * rrh(-1) | P42: 20 | Q42: 0.94298727 | R42: 0.93918642 | S42: 0.84892105 | T42: 43.240017 | U42: 2.5841023 | V42: 2.7513629 | W42: 2.6500973
B44: arr/nomort = c(1) + c(2) * log(pedip_unadj_pedy(-1)) + c(3) * upilo(-1) + c(4) * rbm(-1) | P44: 21 | Q44: 0.92921076 | R44: 0.92572932 | S44: 0.93815744 | T44: 53.688502 | U44: 2.7697656 | V44: 2.903574 | W44: 2.8225616
B45: arr/nomort = c(1) + c(2) * log(pedip_unadj_pedy(-1)) + c(3) * upilo(-2) + c(4) * rbm(-1) | P45: 22 | Q45: 0.93486561 | R45: 0.93160889 | S45: 0.90668853 | T45: 49.325045 | U45: 2.7024259 | V45: 2.8373561 | W45: 2.7555818
B46: arr/nomort = c(1) + c(2) * log(pedip_unadj_pedy(-1)) + c(3) * upilo(-2) + c(4) * rbm(-2) | P46: 23 | Q46: 0.90894113 | R46: 0.90438819 | S46: 1.0720476 | T46: 68.957169 | U46: 3.0374796 | V46: 3.1724097 | W46: 3.0906354
B47: arr/nomort = c(1) + c(2) * log(pedip_unadj_pedy(-1)) + c(3) * upilo(-1) + c(4) * mrtpe_mvh(-1) + c(5) * rbm(-1) | P47: 24 | Q47: 0.93400029 | R47: 0.92960031 | S47: 0.91338193 | T47: 50.055993 | U47: 2.7304782 | V47: 2.8977388 | W47: 2.7964732
B49: arr/nomort = c(1) + c(2) * log(pedip_unadj_pedy(-1)) + c(3) * upilo(-1) + c(4) * rrh(-1) + c(5) * hhliaby(-1)
Q55: R2 | R55: Adj R2 | S55: SE | T55: RSS | U55: AIC | V55: SBC | W55: HQN
B56: log(arr_nomort) = c(1) + c(2) * log(pedip_unadj_pedy(-1)) + c(3) * upilo_1(-1) + c(4) * rrh_1(-1) | Q56: 0.78342012 | R56: 0.77767021 | S56: 0.20731925 | T56: 4.8568836 | U56: -0.2755238 | V56: -0.18109051 | W56: -0.23718505
...

Sheet Data >>>

Sheet Series construction
A1: Very old discontinued Haver UKF data >>> | J1: Historical interpolations >>> | V1: 2008-2015 UKF backseries from client >>> | AA1: Splicing history together via changes >>> | AF1: Splicing total history with new UKF haver data >>>
B3: Arrears | G3: Repossessions | J3: Arrears | R3: Repossessions
A4: 19901 !Q | B4: UNMARP22@UK | C4: UNMARP24@UK | D4: UNMARP26@UK | E4: UNMARP28@UK | G4: UNMARP44@UK
A5: .DESC | B5: UK: CML: No of Mortgages between 2.5% & 5% in Arrears DISC(NSA EOPNumber) | C5: UK: CML: No of Mortgages between 5% & 7.5% in Arrears DISC(NSA EOPNumber) | D5: UK: CML: No of Mortgages btw 7.5% & 10% in Arrears DISC(NSA EOP Number) | E5: UK: CML: Number of Mortgages 10% or Over in Arrears DISC(NSA,EOP, Number) | G5: UK: CML: Number of Properties in Possession DISC(NSA, EOP, Number) | J5: Arrears (2.5% - 5%) | K5: Arrears (5% - 7.5%) | L5: Arrears (7.5% - 10%) | M5: Arrears (10+%) | N5: TOTAL (calcs) | O5: CHANGES (calcs) | R5: Calc repo | S5: CHANGES | W5: Homeowner + BTL arrears (over 2.5% of balance) | X5: Mortgage repossessions (homeowner + BTL) | AB5: Note: red = discontinued haver series (pre-2008, blue = old client data (2008-2015) | AG5: Note: red = discontinued haver series (pre-2008, blue = old client data (2008-2015), green = new haver data (2015-current)
A6: .T1 | B6: Q4-1994 | C6: Q2-1993 | D6: Q2-1993 | E6: Q2-1993 | G6: Q4-1990 | AB6: ARR | AC6: REPO | AG6: ARR | AH6: REPO | AJ6: ARR/NOMORT | AK6: REPO/NOMORT
A7: .TN | B7: Q3-2008 | C7: Q3-2008 | D7: Q3-2008 | E7: Q3-2008 | G7: Q3-2008 | V7: Date | AA7: Date | AF7: Date
A8: .LSOURCE | B8: Discontinued | C8: Discontinued | D8: Discontinued | E8: Discontinued | G8: Discontinued
A9: .DTLM | B9: Nov-21-2008 10:42 | C9: Nov-21-2008 10:42 | D9: Nov-21-2008 10:42 | E9: Nov-21-2008 10:42 | G9: Nov-21-2008 10:42
A10: 19901 | B10: #N/A | C10: #N/A | D10: #N/A | E10: #N/A | G10: #N/A | J10: =NA() -> #N/A | K10: =NA() -> #N/A | L10: =NA() -> #N/A | M10: =NA() -> #N/A | N10: =SUM(J10:M10) -> #N/A | R10: =NA() -> #N/A | V10: ='Eviews input'!A2 -> 39479 | W10: ='Eviews input'!B2 -> 127000 | X10: ='Eviews input'!C2 -> 15600 | AA10: 32905 | AB10: =NA() -> #N/A | AC10: =NA() -> #N/A | AF10: 32905 | AG10: =NA() -> #N/A | AH10: =NA() -> #N/A | AJ10: =AG10/(DataQ!C75*1000) -> #N/A | AK10: =AH10/(DataQ!D75*1000) -> #N/A
A11: 19902 | B11: #N/A | C11: #N/A | D11: #N/A | E11: #N/A | G11: #N/A | J11: =NA() -> #N/A | K11: =NA() -> #N/A | L11: =NA() -> #N/A | M11: =NA() -> #N/A | N11: =SUM(J11:M11) -> #N/A | R11: =NA() -> #N/A | V11: ='Eviews input'!A3 -> 39569 | W11: ='Eviews input'!B3 -> 139700 | X11: ='Eviews input'!C3 -> 18700 | AA11: 32994 | AB11: =NA() -> #N/A | AC11: =NA() -> #N/A | AF11: 32994 | AG11: =NA() -> #N/A | AH11: =NA() -> #N/A | AJ11: =AG11/(DataQ!C76*1000) -> #N/A | AK11: =AH11/(DataQ!D76*1000) -> #N/A
A12: 19903 | B12: #N/A | C12: #N/A | D12: #N/A | E12: #N/A | G12: #N/A | J12: =NA() -> #N/A | K12: =NA() -> #N/A | L12: =NA() -> #N/A | M12: =NA() -> #N/A | N12: =SUM(J12:M12) -> #N/A | R12: =NA() -> #N/A | V12: ='Eviews input'!A4 -> 39661 | W12: ='Eviews input'!B4 -> 150800 | X12: ='Eviews input'!C4 -> 22600 | AA12: 33086 | AB12: =NA() -> #N/A | AC12: =NA() -> #N/A | AF12: 33086 | AG12: =NA() -> #N/A | AH12: =NA() -> #N/A | AJ12: =AG12/(DataQ!C77*1000) -> #N/A | AK12: =AH12/(DataQ!D77*1000) -> #N/A
A13: 19904 | B13: #N/A | C13: #N/A | D13: #N/A | E13: #N/A | G13: 36200 | J13: =NA() -> #N/A | K13: =NA() -> #N/A | L13: =NA() -> #N/A | M13: =NA() -> #N/A | N13: =SUM(J13:M13) -> #N/A | R13: =G13 -> 36200 | S13: =R14-R13 -> 8650 | V13: ='Eviews input'!A5 -> 39753 | W13: ='Eviews input'!B5 -> 182600 | X13: ='Eviews input'!C5 -> 22700 | AA13: 33178 | AB13: =NA() -> #N/A | AC13: =AC14-(R14-R13) -> 36100 | AF13: 33178 | AG13: =NA() -> #N/A | AH13: =AC13 -> 36100 | AJ13: =AG13/(DataQ!C78*1000) -> #N/A | AK13: =AH13/(DataQ!D78*1000) -> 0.0031413157
A14: 19911 | B14: #N/A | C14: #N/A | D14: #N/A | E14: #N/A | G14: #N/A | J14: =NA() -> #N/A | K14: =NA() -> #N/A | L14: =NA() -> #N/A | M14: =NA() -> #N/A | N14: =SUM(J14:M14) -> #N/A | R14: =R13+0.5*(R15-R13) -> 44850 | S14: =R15-R14 -> 8650 | V14: ='Eviews input'!A6 -> 39845 | W14: ='Eviews input'!B6 -> 209600 | X14: ='Eviews input'!C6 -> 24400 | AA14: 33270 | AB14: =NA() -> #N/A | AC14: =AC15-(R15-R14) -> 44750 | AF14: 33270 | AG14: =NA() -> #N/A | AH14: =AC14 -> 44750 | AJ14: =AG14/(DataQ!C79*1000) -> #N/A | AK14: =AH14/(DataQ!D79*1000) -> 0.0039069321
A15: 19912 | B15: #N/A | C15: #N/A | D15: #N/A | E15: #N/A | G15: 53500 | J15: =NA() -> #N/A | K15: =NA() -> #N/A | L15: =NA() -> #N/A | M15: =NA() -> #N/A | N15: =SUM(J15:M15) -> #N/A | R15: =G15 -> 53500 | S15: =R16-R15 -> 6950 | V15: ='Eviews input'!A7 -> 39934 | W15: ='Eviews input'!B7 -> 216400 | X15: ='Eviews input'!C7 -> 21900 | AA15: 33359 | AB15: =NA() -> #N/A | AC15: =AC16-(R16-R15) -> 53400 | AF15: 33359 | AG15: =NA() -> #N/A | AH15: =AC15 -> 53400 | AJ15: =AG15/(DataQ!C80*1000) -> #N/A | AK15: =AH15/(DataQ!D80*1000) -> 0.0049476513
A16: 19913 | B16: #N/A | C16: #N/A | D16: #N/A | E16: #N/A | G16: #N/A | J16: =NA() -> #N/A | K16: =NA() -> #N/A | L16: =NA() -> #N/A | M16: =NA() -> #N/A | N16: =SUM(J16:M16) -> #N/A | R16: =R15+0.5*(R17-R15) -> 60450 | S16: =R17-R16 -> 6950 | V16: ='Eviews input'!A8 -> 40026 | W16: ='Eviews input'!B8 -> 207200 | X16: ='Eviews input'!C8 -> 19300 | AA16: 33451 | AB16: =NA() -> #N/A | AC16: =AC17-(R17-R16) -> 60350 | AF16: 33451 | AG16: =NA() -> #N/A | AH16: =AC16 -> 60350 | AJ16: =AG16/(DataQ!C81*1000) -> #N/A | AK16: =AH16/(DataQ!D81*1000) -> 0.0058872305
A17: 19914 | B17: #N/A | C17: #N/A | D17: #N/A | E17: #N/A | G17: 67400 | J17: =NA() -> #N/A | K17: =NA() -> #N/A | L17: =NA() -> #N/A | M17: =NA() -> #N/A | N17: =SUM(J17:M17) -> #N/A | R17: =G17 -> 67400 | S17: =R18-R17 -> 550 | V17: ='Eviews input'!A9 -> 40118 | W17: ='Eviews input'!B9 -> 199600 | X17: ='Eviews input'!C9 -> 16200 | AA17: 33543 | AB17: =NA() -> #N/A | AC17: =AC18-(R18-R17) -> 67300 | AF17: 33543 | AG17: =NA() -> #N/A | AH17: =AC17 -> 67300 | AJ17: =AG17/(DataQ!C82*1000) -> #N/A | AK17: =AH17/(DataQ!D82*1000) -> 0.0067536377
A18: 19921 | B18: #N/A | C18: #N/A | D18: #N/A | E18: #N/A | G18: #N/A | J18: =NA() -> #N/A | K18: =NA() -> #N/A | L18: =NA() -> #N/A | M18: =NA() -> #N/A | N18: =SUM(J18:M18) -> #N/A | R18: =R17+0.5*(R19-R17) -> 67950 | S18: =R19-R18 -> 550 | V18: ='Eviews input'!A10 -> 40210 | W18: ='Eviews input'!B10 -> 196500 | X18: ='Eviews input'!C10 -> 15900 | AA18: 33635 | AB18: =NA() -> #N/A | AC18: =AC19-(R19-R18) -> 67850 | AF18: 33635 | AG18: =NA() -> #N/A | AH18: =AC18 -> 67850 | AJ18: =AG18/(DataQ!C83*1000) -> #N/A | AK18: =AH18/(DataQ!D83*1000) -> 0.0061275174
A19: 19922 | B19: #N/A | C19: #N/A | D19: #N/A | E19: #N/A | G19: 68500 | J19: =NA() -> #N/A | K19: =NA() -> #N/A | L19: =NA() -> #N/A | M19: =NA() -> #N/A | N19: =SUM(J19:M19) -> #N/A | R19: =G19 -> 68500 | S19: =R20-R19 -> -1750 | V19: ='Eviews input'!A11 -> 40299 | W19: ='Eviews input'!B11 -> 185500 | X19: ='Eviews input'!C11 -> 15200 | AA19: 33725 | AB19: =NA() -> #N/A | AC19: =AC20-(R20-R19) -> 68400 | AF19: 33725 | AG19: =NA() -> #N/A | AH19: =AC19 -> 68400 | AJ19: =AG19/(DataQ!C84*1000) -> #N/A | AK19: =AH19/(DataQ!D84*1000) -> 0.0067843682
A20: 19923 | B20: #N/A | C20: #N/A | D20: #N/A | E20: #N/A | G20: #N/A | J20: =NA() -> #N/A | K20: =NA() -> #N/A | L20: =NA() -> #N/A | M20: =NA() -> #N/A | N20: =SUM(J20:M20) -> #N/A | R20: =R19+0.5*(R21-R19) -> 66750 | S20: =R21-R20 -> -1750 | V20: ='Eviews input'!A12 -> 40391 | W20: ='Eviews input'!B12 -> 179800 | X20: ='Eviews input'!C12 -> 14700 | AA20: 33817 | AB20: =NA() -> #N/A | AC20: =AC21-(R21-R20) -> 66650 | AF20: 33817 | AG20: =NA() -> #N/A | AH20: =AC20 -> 66650 | AJ20: =AG20/(DataQ!C85*1000) -> #N/A | AK20: =AH20/(DataQ!D85*1000) -> 0.0068839083
A21: 19924 | B21: #N/A | C21: #N/A | D21: #N/A | E21: #N/A | G21: 65000 | J21: =NA() -> #N/A | K21: =NA() -> #N/A | L21: =NA() -> #N/A | M21: =NA() -> #N/A | N21: =SUM(J21:M21) -> #N/A | R21: =G21 -> 65000 | S21: =R22-R21 -> -5350 | V21: ='Eviews input'!A13 -> 40483 | W21: ='Eviews input'!B13 -> 175800 | X21: ='Eviews input'!C13 -> 13700 | AA21: 33909 | AB21: =NA() -> #N/A | AC21: =AC22-(R22-R21) -> 64900 | AF21: 33909 | AG21: =NA() -> #N/A | AH21: =AC21 -> 64900 | AJ21: =AG21/(DataQ!C86*1000) -> #N/A | AK21: =AH21/(DataQ!D86*1000) -> 0.0076932195
A22: 19931 | B22: #N/A | C22: #N/A | D22: #N/A | E22: #N/A | G22: #N/A | J22: =NA() -> #N/A | K22: =NA() -> #N/A | L22: =NA() -> #N/A | M22: =NA() -> #N/A | N22: =SUM(J22:M22) -> #N/A | R22: =R21+0.5*(R23-R21) -> 59650 | S22: =R23-R22 -> -5350 | V22: ='Eviews input'!A14 -> 40575 | W22: ='Eviews input'!B14 -> 171900 | X22: ='Eviews input'!C14 -> 14200 | AA22: 34001 | AB22: =NA() -> #N/A | AC22: =AC23-(R23-R22) -> 59550 | AF22: 34001 | AG22: =NA() -> #N/A | AH22: =AC22 -> 59550 | AJ22: =AG22/(DataQ!C87*1000) -> #N/A | AK22: =AH22/(DataQ!D87*1000) -> 0.0078895072
A23: 19932 | B23: #N/A | C23: 121200 | D23: 78100 | E23: 177700 | G23: 54300 | J23: =NA() -> #N/A | K23: =C23 -> 121200 | L23: =D23 -> 78100 | M23: =E23 -> 177700 | N23: =SUM(J23:M23) -> #N/A | R23: =G23 -> 54300 | S23: =R24-R23 -> -7200 | V23: ='Eviews input'!A15 -> 40664 | W23: ='Eviews input'!B15 -> 169200 | X23: ='Eviews input'!C15 -> 14500 | AA23: 34090 | AB23: =NA() -> #N/A | AC23: =AC24-(R24-R23) -> 54200 | AF23: 34090 | AG23: =NA() -> #N/A | AH23: =AC23 -> 54200 | AJ23: =AG23/(DataQ!C88*1000) -> #N/A | AK23: =AH23/(DataQ!D88*1000) -> 0.0074003277
A24: 19933 | B24: #N/A | C24: #N/A | D24: #N/A | E24: #N/A | G24: #N/A | J24: =NA() -> #N/A | K24: =K23+0.5*(K25-K23) -> 114400 | L24: =L23+0.5*(L25-L23) -> 73950 | M24: =M23+0.5*(M25-M23) -> 171850 | N24: =SUM(J24:M24) -> #N/A | R24: =R23+0.5*(R25-R23) -> 47100 | S24: =R25-R24 -> -7200 | V24: ='Eviews input'!A16 -> 40756 | W24: ='Eviews input'!B16 -> 165300 | X24: ='Eviews input'!C16 -> 14700 | AA24: 34182 | AB24: =NA() -> #N/A | AC24: =AC25-(R25-R24) -> 47000 | AF24: 34182 | AG24: =NA() -> #N/A | AH24: =AC24 -> 47000 | AJ24: =AG24/(DataQ!C89*1000) -> #N/A | AK24: =AH24/(DataQ!D89*1000) -> 0.0063772049
A25: 19934 | B25: #N/A | C25: 107600 | D25: 69800 | E25: 166000 | G25: 39900 | J25: =NA() -> #N/A | K25: =C25 -> 107600 | L25: =D25 -> 69800 | M25: =E25 -> 166000 | N25: =SUM(J25:M25) -> #N/A | R25: =G25 -> 39900 | S25: =R26-R25 -> -3350 | V25: ='Eviews input'!A17 -> 40848 | W25: ='Eviews input'!B17 -> 161400 | X25: ='Eviews input'!C17 -> 13900 | AA25: 34274 | AB25: =NA() -> #N/A | AC25: =AC26-(R26-R25) -> 39800 | AF25: 34274 | AG25: =NA() -> #N/A | AH25: =AC25 -> 39800 | AJ25: =AG25/(DataQ!C90*1000) -> #N/A | AK25: =AH25/(DataQ!D90*1000) -> 0.0054260395
A26: 19941 | B26: #N/A | C26: #N/A | D26: #N/A | E26: #N/A | G26: #N/A | J26: =NA() -> #N/A | K26: =K25+0.5*(K27-K25) -> 102750 | L26: =L25+0.5*(L27-L25) -> 66350 | M26: =M25+0.5*(M27-M25) -> 158450 | N26: =SUM(J26:M26) -> #N/A | R26: =R25+0.5*(R27-R25) -> 36550 | S26: =R27-R26 -> -3350 | V26: ='Eviews input'!A18 -> 40940 | W26: ='Eviews input'!B18 -> 159100 | X26: ='Eviews input'!C18 -> 13900 | AA26: 34366 | AB26: =NA() -> #N/A | AC26: =AC27-(R27-R26) -> 36450 | AF26: 34366 | AG26: =NA() -> #N/A | AH26: =AC26 -> 36450 | AJ26: =AG26/(DataQ!C91*1000) -> #N/A | AK26: =AH26/(DataQ!D91*1000) -> 0.0050020585
A27: 19942 | B27: #N/A | C27: 97900 | D27: 62900 | E27: 150900 | G27: 33200 | J27: =NA() -> #N/A | K27: =C27 -> 97900 | L27: =D27 -> 62900 | M27: =E27 -> 150900 | N27: =SUM(J27:M27) -> #N/A | R27: =G27 -> 33200 | S27: =R28-R27 -> -1900 | V27: ='Eviews input'!A19 -> 41030 | W27: ='Eviews input'!B19 -> 158700 | X27: ='Eviews input'!C19 -> 13500 | AA27: 34455 | AB27: =NA() -> #N/A | AC27: =AC28-(R28-R27) -> 33100 | AF27: 34455 | AG27: =NA() -> #N/A | AH27: =AC27 -> 33100 | AJ27: =AG27/(DataQ!C92*1000) -> #N/A | AK27: =AH27/(DataQ!D92*1000) -> 0.0042864543
A28: 19943 | B28: #N/A | C28: #N/A | D28: #N/A | E28: #N/A | G28: #N/A | J28: =NA() -> #N/A | K28: =K27+0.5*(K29-K27) -> 90300 | L28: =L27+0.5*(L29-L27) -> 56250 | M28: =M27+0.5*(M29-M27) -> 133600 | R28: =R27+0.5*(R29-R27) -> 31300 | S28: =R29-R28 -> -1900 | V28: ='Eviews input'!A20 -> 41122 | W28: ='Eviews input'!B20 -> 159100 | X28: ='Eviews input'!C20 -> 13000 | AA28: 34547 | AB28: =NA() -> #N/A | AC28: =AC29-(R29-R28) -> 31200 | AF28: 34547 | AG28: =NA() -> #N/A | AH28: =AC28 -> 31200 | AJ28: =AG28/(DataQ!C93*1000) -> #N/A | AK28: =AH28/(DataQ!D93*1000) -> 0.0041677799
A29: 19944 | B29: 176600 | C29: 82700 | D29: 49600 | E29: 116300 | G29: 29400 | J29: =B29 -> 176600 | K29: =C29 -> 82700 | L29: =D29 -> 49600 | M29: =E29 -> 116300 | N29: =SUM(J29:M29) -> 425200 | O29: =N30-N29 -> 2300 | R29: =G29 -> 29400 | S29: =R30-R29 -> 200 | V29: ='Eviews input'!A21 -> 41214 | W29: ='Eviews input'!B21 -> 157900 | X29: ='Eviews input'!C21 -> 11500 | AA29: 34639 | AB29: =AB30-(N30-N29) -> 423600 | AC29: =AC30-(R30-R29) -> 29300 | AF29: 34639 | AG29: =AB29 -> 423600 | AH29: =AC29 -> 29300 | AJ29: =AG29/(DataQ!C94*1000) -> 0.040691643 | AK29: =AH29/(DataQ!D94*1000) -> 0.0037953368 | AM29: =AG29/(DataQ!C94) -> 40.691643
A30: 19951 | B30: #N/A | C30: #N/A | D30: #N/A | E30: #N/A | G30: #N/A | J30: =J29+0.5*(J31-J29) -> 181150 | K30: =K29+0.5*(K31-K29) -> 82500 | L30: =L29+0.5*(L31-L29) -> 50750 | M30: =M29+0.5*(M31-M29) -> 113100 | N30: =SUM(J30:M30) -> 427500 | O30: =N31-N30 -> 2300 | R30: =R29+0.5*(R31-R29) -> 29600 | S30: =R31-R30 -> 200 | V30: ='Eviews input'!A22 -> 41306 | W30: ='Eviews input'!B22 -> 159600 | X30: ='Eviews input'!C22 -> 11100 | AA30: 34731 | AB30: =AB31-(N31-N30) -> 425900 | AC30: =AC31-(R31-R30) -> 29500 | AF30: 34731 | AG30: =AB30 -> 425900 | AH30: =AC30 -> 29500 | AJ30: =AG30/(DataQ!C95*1000) -> 0.04084784 | AK30: =AH30/(DataQ!D95*1000) -> 0.0035615115 | AM30: =AG30/(DataQ!C95) -> 40.84784
A31: 19952 | B31: 185700 | C31: 82300 | D31: 51900 | E31: 109900 | G31: 29800 | J31: =B31 -> 185700 | K31: =C31 -> 82300 | L31: =D31 -> 51900 | M31: =E31 -> 109900 | N31: =SUM(J31:M31) -> 429800 | O31: =N32-N31 -> -16050 | R31: =G31 -> 29800 | S31: =R32-R31 -> -1300 | V31: ='Eviews input'!A23 -> 41395 | W31: ='Eviews input'!B23 -> 154900 | X31: ='Eviews input'!C23 -> 10300 | AA31: 34820 | AB31: =AB32-(N32-N31) -> 428200 | AC31: =AC32-(R32-R31) -> 29700 | AF31: 34820 | AG31: =AB31 -> 428200 | AH31: =AC31 -> 29700 | AJ31: =AG31/(DataQ!C96*1000) -> 0.041003543 | AK31: =AH31/(DataQ!D96*1000) -> 0.0034635569 | AM31: =AG31/(DataQ!C96) -> 41.003543
A32: 19953 | B32: #N/A | C32: #N/A | D32: #N/A | E32: #N/A | G32: #N/A | J32: =J31+0.5*(J33-J31) -> 180050 | K32: =K31+0.5*(K33-K31) -> 81100 | L32: =L31+0.5*(L33-L31) -> 48700 | M32: =M31+0.5*(M33-M31) -> 103900 | N32: =SUM(J32:M32) -> 413750 | O32: =N33-N32 -> -16050 | R32: =R31+0.5*(R33-R31) -> 28500 | S32: =R33-R32 -> -1300 | V32: ='Eviews input'!A24 -> 41487 | W32: ='Eviews input'!B24 -> 149400 | X32: ='Eviews input'!C24 -> 9900 | AA32: 34912 | AB32: =AB33-(N33-N32) -> 412150 | AC32: =AC33-(R33-R32) -> 28400 | AF32: 34912 | AG32: =AB32 -> 412150 | AH32: =AC32 -> 28400 | AJ32: =AG32/(DataQ!C97*1000) -> 0.039319786 | AK32: =AH32/(DataQ!D97*1000) -> 0.00337132 | AM32: =AG32/(DataQ!C97) -> 39.319786
A33: 19954 | B33: 174400 | C33: 79900 | D33: 45500 | E33: 97900 | G33: 27200 | J33: =B33 -> 174400 | K33: =C33 -> 79900 | L33: =D33 -> 45500 | M33: =E33 -> 97900 | N33: =SUM(J33:M33) -> 397700 | O33: =N34-N33 -> -23900 | R33: =G33 -> 27200 | S33: =R34-R33 -> -1600 | V33: ='Eviews input'!A25 -> 41579 | W33: ='Eviews input'!B25 -> 144600 | X33: ='Eviews input'!C25 -> 8400 | AA33: 35004 | AB33: =AB34-(N34-N33) -> 396100 | AC33: =AC34-(R34-R33) -> 27100 | AF33: 35004 | AG33: =AB33 -> 396100 | AH33: =AC33 -> 27100 | AJ33: =AG33/(DataQ!C98*1000) -> 0.037648512 | AK33: =AH33/(DataQ!D98*1000) -> 0.0033271946 | AM33: =AG33/(DataQ!C98) -> 37.648512
A34: 19961 | B34: #N/A | C34: #N/A | D34: #N/A | E34: #N/A | G34: #N/A | J34: =J33+0.5*(J35-J33) -> 164050 | K34: =K33+0.5*(K35-K33) -> 75100 | L34: =L33+0.5*(L35-L33) -> 42700 | M34: =M33+0.5*(M35-M33) -> 91950 | N34: =SUM(J34:M34) -> 373800 | O34: =N35-N34 -> -23900 | R34: =R33+0.5*(R35-R33) -> 25600 | S34: =R35-R34 -> -1600 | V34: ='Eviews input'!A26 -> 41671 | W34: ='Eviews input'!B26 -> 138200 | X34: ='Eviews input'!C26 -> 8500 | AA34: 35096 | AB34: =AB35-(N35-N34) -> 372200 | AC34: =AC35-(R35-R34) -> 25500 | AF34: 35096 | AG34: =AB34 -> 372200 | AH34: =AC34 -> 25500 | AJ34: =AG34/(DataQ!C99*1000) -> 0.035259568 | AK34: =AH34/(DataQ!D99*1000) -> 0.0031851112 | AM34: =AG34/(DataQ!C99) -> 35.259568
A35: 19962 | B35: 153700 | C35: 70300 | D35: 39900 | E35: 86000 | G35: 24000 | J35: =B35 -> 153700 | K35: =C35 -> 70300 | L35: =D35 -> 39900 | M35: =E35 -> 86000 | N35: =SUM(J35:M35) -> 349900 | O35: =N36-N35 -> -26550 | R35: =G35 -> 24000 | S35: =R36-R35 -> -3900 | V35: ='Eviews input'!A27 -> 41760 | W35: ='Eviews input'!B27 -> 129170 | X35: ='Eviews input'!C27 -> 7880 | AA35: 35186 | AB35: =AB36-(N36-N35) -> 348300 | AC35: =AC36-(R36-R35) -> 23900 | AF35: 35186 | AG35: =AB35 -> 348300 | AH35: =AC35 -> 23900 | AJ35: =AG35/(DataQ!C100*1000) -> 0.032886413 | AK35: =AH35/(DataQ!D100*1000) -> 0.0030755373 | AM35: =AG35/(DataQ!C100) -> 32.886413
A36: 19963 | B36: #N/A | C36: #N/A | D36: #N/A | E36: #N/A | G36: #N/A | J36: =J35+0.5*(J37-J35) -> 141700 | K36: =K35+0.5*(K37-K35) -> 64700 | L36: =L35+0.5*(L37-L35) -> 36600 | M36: =M35+0.5*(M37-M35) -> 80350 | N36: =SUM(J36:M36) -> 323350 | O36: =N37-N36 -> -26550 | R36: =R35+0.5*(R37-R35) -> 20100 | S36: =R37-R36 -> -3900 | V36: ='Eviews input'!A28 -> 41852 | W36: ='Eviews input'!B28 -> 122110 | X36: ='Eviews input'!C28 -> 7150 | AA36: 35278 | AB36: =AB37-(N37-N36) -> 321750 | AC36: =AC37-(R37-R36) -> 20000 | AF36: 35278 | AG36: =AB36 -> 321750 | AH36: =AC36 -> 20000 | AJ36: =AG36/(DataQ!C101*1000) -> 0.030313737 | AK36: =AH36/(DataQ!D101*1000) -> 0.0026364355 | AM36: =AG36/(DataQ!C101) -> 30.313737
A37: 19964 | B37: 129700 | C37: 59100 | D37: 33300 | E37: 74700 | G37: 16200 | J37: =B37 -> 129700 | K37: =C37 -> 59100 | L37: =D37 -> 33300 | M37: =E37 -> 74700 | N37: =SUM(J37:M37) -> 296800 | O37: =N38-N37 -> -15000 | R37: =G37 -> 16200 | S37: =R38-R37 -> -1050 | V37: ='Eviews input'!A29 -> 41944 | W37: ='Eviews input'!B29 -> 114410 | X37: ='Eviews input'!C29 -> 6170 | AA37: 35370 | AB37: =AB38-(N38-N37) -> 295200 | AC37: =AC38-(R38-R37) -> 16100 | AF37: 35370 | AG37: =AB37 -> 295200 | AH37: =AC37 -> 16100 | AJ37: =AG37/(DataQ!C102*1000) -> 0.027752186 | AK37: =AH37/(DataQ!D102*1000) -> 0.0021633969 | AM37: =AG37/(DataQ!C102) -> 27.752186
A38: 19971 | B38: #N/A | C38: #N/A | D38: #N/A | E38: #N/A | G38: #N/A | J38: =J37+0.5*(J39-J37) -> 125400 | K38: =K37+0.5*(K39-K37) -> 56200 | L38: =L37+0.5*(L39-L37) -> 30850 | M38: =M37+0.5*(M39-M37) -> 69350 | N38: =SUM(J38:M38) -> 281800 | O38: =N39-N38 -> -15000 | R38: =R37+0.5*(R39-R37) -> 15150 | S38: =R39-R38 -> -1050 | V38: ='Eviews input'!A30 -> 42036 | W38: ='Eviews input'!B30 -> 111190 | X38: ='Eviews input'!C30 -> 4880 | AA38: 35462 | AB38: =AB39-(N39-N38) -> 280200 | AC38: =AC39-(R39-R38) -> 15050 | AF38: 35462 | AG38: =AB38 -> 280200 | AH38: =AC38 -> 15050 | AJ38: =AG38/(DataQ!C103*1000) -> 0.026242098 | AK38: =AH38/(DataQ!D103*1000) -> 0.0019351935 | AM38: =AG38/(DataQ!C103) -> 26.242098
A39: 19972 | B39: 121100 | C39: 53300 | D39: 28400 | E39: 64000 | G39: 14100 | J39: =B39 -> 121100 | K39: =C39 -> 53300 | L39: =D39 -> 28400 | M39: =E39 -> 64000 | N39: =SUM(J39:M39) -> 266800 | O39: =N40-N39 -> -6450 | R39: =G39 -> 14100 | S39: =R40-R39 -> -100 | AA39: 35551 | AB39: =AB40-(N40-N39) -> 265200 | AC39: =AC40-(R40-R39) -> 14000 | AF39: 35551 | AG39: =AB39 -> 265200 | AH39: =AC39 -> 14000 | AJ39: =AG39/(DataQ!C104*1000) -> 0.024743422 | AK39: =AH39/(DataQ!D104*1000) -> 0.0017687934 | AM39: =AG39/(DataQ!C104) -> 24.743422
A40: 19973 | B40: #N/A | C40: #N/A | D40: #N/A | E40: #N/A | G40: #N/A | J40: =J39+0.5*(J41-J39) -> 119450 | K40: =K39+0.5*(K41-K39) -> 51350 | L40: =L39+0.5*(L41-L39) -> 27350 | M40: =M39+0.5*(M41-M39) -> 62200 | N40: =SUM(J40:M40) -> 260350 | O40: =N41-N40 -> -6450 | R40: =R39+0.5*(R41-R39) -> 14000 | S40: =R41-R40 -> -100 | AA40: 35643 | AB40: =AB41-(N41-N40) -> 258750 | AC40: =AC41-(R41-R40) -> 13900 | AF40: 35643 | AG40: =AB40 -> 258750 | AH40: =AC40 -> 13900 | AJ40: =AG40/(DataQ!C105*1000) -> 0.024119128 | AK40: =AH40/(DataQ!D105*1000) -> 0.0016228838 | AM40: =AG40/(DataQ!C105) -> 24.119128
A41: 19974 | B41: 117800 | C41: 49400 | D41: 26300 | E41: 60400 | G41: 13900 | J41: =B41 -> 117800 | K41: =C41 -> 49400 | L41: =D41 -> 26300 | M41: =E41 -> 60400 | N41: =SUM(J41:M41) -> 253900 | O41: =N42-N41 -> 3350 | R41: =G41 -> 13900 | S41: =R42-R41 -> 650 | AA41: 35735 | AB41: =AB42-(N42-N41) -> 252300 | AC41: =AC42-(R42-R41) -> 13800 | AF41: 35735 | AG41: =AB41 -> 252300 | AH41: =AC41 -> 13800 | AJ41: =AG41/(DataQ!C106*1000) -> 0.023495996 | AK41: =AH41/(DataQ!D106*1000) -> 0.0015040872 | AM41: =AG41/(DataQ!C106) -> 23.495996
...

Sheet GMWQ
A1: Location | B1: Indicator | C1: Scenario | D1: Units | E1: Scale | F1: Measurement | G1: 1973 Q1 | H1: 1973 Q2 | I1: 1973 Q3 | J1: 1973 Q4 | K1: 1974 Q1 | L1: 1974 Q2 | M1: 1974 Q3 | N1: 1974 Q4 | O1: 1975 Q1 | P1: 1975 Q2 | Q1: 1975 Q3 | R1: 1975 Q4 | S1: 1976 Q1 | T1: 1976 Q2 | U1: 1976 Q3 | V1: 1976 Q4 | W1: 1977 Q1 | X1: 1977 Q2 | Y1: 1977 Q3 | Z1: 1977 Q4 | AA1: 1978 Q1 | AB1: 1978 Q2 | AC1: 1978 Q3 | AD1: 1978 Q4 | AE1: 1979 Q1 | AF1: 1979 Q2 | AG1: 1979 Q3 | AH1: 1979 Q4 | AI1: 1980 Q1 | AJ1: 1980 Q2 | AK1: 1980 Q3 | AL1: 1980 Q4 | AM1: 1981 Q1 | AN1: 1981 Q2 | AO1: 1981 Q3 | AP1: 1981 Q4 | AQ1: 1982 Q1 | AR1: 1982 Q2 | AS1: 1982 Q3 | AT1: 1982 Q4 | AU1: 1983 Q1 | AV1: 1983 Q2 | AW1: 1983 Q3 | AX1: 1983 Q4 | AY1: 1984 Q1 | AZ1: 1984 Q2 | BA1: 1984 Q3 | BB1: 1984 Q4 | BC1: 1985 Q1 | BD1: 1985 Q2 | BE1: 1985 Q3 | BF1: 1985 Q4 | BG1: 1986 Q1 | BH1: 1986 Q2 | BI1: 1986 Q3 | BJ1: 1986 Q4 | BK1: 1987 Q1 | BL1: 1987 Q2 | BM1: 1987 Q3 | BN1: 1987 Q4 | BO1: 1988 Q1 | BP1: 1988 Q2 | BQ1: 1988 Q3 | BR1: 1988 Q4 | BS1: 1989 Q1 | BT1: 1989 Q2 | BU1: 1989 Q3 | BV1: 1989 Q4 | BW1: 1990 Q1 | BX1: 1990 Q2 | BY1: 1990 Q3 | BZ1: 1990 Q4 | CA1: 1991 Q1 | CB1: 1991 Q2 | CC1: 1991 Q3 | CD1: 1991 Q4 | CE1: 1992 Q1 | CF1: 1992 Q2 | CG1: 1992 Q3 | CH1: 1992 Q4 | CI1: 1993 Q1 | CJ1: 1993 Q2 | CK1: 1993 Q3 | CL1: 1993 Q4 | CM1: 1994 Q1 | CN1: 1994 Q2 | CO1: 1994 Q3 | CP1: 1994 Q4 | CQ1: 1995 Q1 | CR1: 1995 Q2 | CS1: 1995 Q3 | CT1: 1995 Q4 | CU1: 1996 Q1 | CV1: 1996 Q2 | CW1: 1996 Q3 | CX1: 1996 Q4 | CY1: 1997 Q1 | CZ1: 1997 Q2 | DA1: 1997 Q3 | DB1: 1997 Q4 | DC1: 1998 Q1 | DD1: 1998 Q2 | DE1: 1998 Q3 | DF1: 1998 Q4 | DG1: 1999 Q1 | DH1: 1999 Q2 | DI1: 1999 Q3 | DJ1: 1999 Q4 | DK1: 2000 Q1 | DL1: 2000 Q2 | DM1: 2000 Q3 | DN1: 2000 Q4 | DO1: 2001 Q1 | DP1: 2001 Q2 | DQ1: 2001 Q3 | DR1: 2001 Q4 | DS1: 2002 Q1 | DT1: 2002 Q2 | DU1: 2002 Q3 | DV1: 2002 Q4 | DW1: 2003 Q1 | DX1: 2003 Q2 | DY1: 2003 Q3 | DZ1: 2003 Q4 | EA1: 2004 Q1 | EB1: 2004 Q2 | EC1: 2004 Q3 | ED1: 2004 Q4 | EE1: 2005 Q1 | EF1: 2005 Q2 | EG1: 2005 Q3 | EH1: 2005 Q4 | EI1: 2006 Q1 | EJ1: 2006 Q2 | EK1: 2006 Q3 | EL1: 2006 Q4 | EM1: 2007 Q1 | EN1: 2007 Q2 | EO1: 2007 Q3 | EP1: 2007 Q4 | EQ1: 2008 Q1 | ER1: 2008 Q2 | ES1: 2008 Q3 | ET1: 2008 Q4 | EU1: 2009 Q1 | EV1: 2009 Q2 | EW1: 2009 Q3 | EX1: 2009 Q4 | EY1: 2010 Q1 | EZ1: 2010 Q2 | FA1: 2010 Q3 | FB1: 2010 Q4 | FC1: 2011 Q1 | FD1: 2011 Q2 | FE1: 2011 Q3 | FF1: 2011 Q4 | FG1: 2012 Q1 | FH1: 2012 Q2 | FI1: 2012 Q3 | FJ1: 2012 Q4 | FK1: 2013 Q1 | FL1: 2013 Q2 | FM1: 2013 Q3 | FN1: 2013 Q4 | FO1: 2014 Q1 | FP1: 2014 Q2 | FQ1: 2014 Q3 | FR1: 2014 Q4 | FS1: 2015 Q1 | FT1: 2015 Q2 | FU1: 2015 Q3 | FV1: 2015 Q4 | FW1: 2016 Q1 | FX1: 2016 Q2 | FY1: 2016 Q3 | FZ1: 2016 Q4 | GA1: 2017 Q1 | GB1: 2017 Q2 | GC1: 2017 Q3 | GD1: 2017 Q4 | GE1: 2018 Q1 | GF1: 2018 Q2 | GG1: 2018 Q3 | GH1: 2018 Q4 | GI1: 2019 Q1 | GJ1: 2019 Q2 | GK1: 2019 Q3 | GL1: 2019 Q4 | GM1: 2020 Q1 | GN1: 2020 Q2 | GO1: 2020 Q3 | GP1: 2020 Q4 | GQ1: 2021 Q1 | GR1: 2021 Q2 | GS1: 2021 Q3 | GT1: 2021 Q4 | GU1: 2022 Q1 | GV1: 2022 Q2 | GW1: 2022 Q3 | GX1: 2022 Q4 | GY1: 2023 Q1 | GZ1: 2023 Q2 | HA1: 2023 Q3 | HB1: 2023 Q4 | HC1: 2024 Q1 | HD1: 2024 Q2 | HE1: 2024 Q3 | HF1: 2024 Q4 | HG1: 2025 Q1 | HH1: 2025 Q2 | HI1: 2025 Q3 | HJ1: 2025 Q4 | HK1: 2026 Q1 | HL1: 2026 Q2 | HM1: 2026 Q3 | HN1: 2026 Q4 | HO1: 2027 Q1 | HP1: 2027 Q2 | HQ1: 2027 Q3 | HR1: 2027 Q4 | HS1: 2028 Q1 | HT1: 2028 Q2 | HU1: 2028 Q3 | HV1: 2028 Q4 | HW1: 2029 Q1 | HX1: 2029 Q2 | HY1: 2029 Q3 | HZ1: 2029 Q4 | IA1: 2030 Q1 | IB1: 2030 Q2 | IC1: 2030 Q3 | ID1: 2030 Q4 | IE1: 2031 Q1 | IF1: 2031 Q2 | IG1: 2031 Q3 | IH1: 2031 Q4 | II1: 2032 Q1 | IJ1: 2032 Q2 | IK1: 2032 Q3 | IL1: 2032 Q4 | IM1: 2033 Q1 | IN1: 2033 Q2 | IO1: 2033 Q3 | IP1: 2033 Q4 | IQ1: 2034 Q1 | IR1: 2034 Q2 | IS1: 2034 Q3 | IT1: 2034 Q4 | IU1: 2035 Q1 | IV1: 2035 Q2 | IW1: 2035 Q3 | IX1: 2035 Q4 | IY1: 2036 Q1 | IZ1: 2036 Q2 | JA1: 2036 Q3 | JB1: 2036 Q4 | JC1: 2037 Q1 | JD1: 2037 Q2 | JE1: 2037 Q3 | JF1: 2037 Q4 | JG1: 2038 Q1 | JH1: 2038 Q2 | JI1: 2038 Q3 | JJ1: 2038 Q4 | JK1: 2039 Q1 | JL1: 2039 Q2 | JM1: 2039 Q3 | JN1: 2039 Q4 | JO1: 2040 Q1 | JP1: 2040 Q2 | JQ1: 2040 Q3 | JR1: 2040 Q4 | JS1: 2041 Q1 | JT1: 2041 Q2 | JU1: 2041 Q3 | JV1: 2041 Q4 | JW1: 2042 Q1 | JX1: 2042 Q2 | JY1: 2042 Q3 | JZ1: 2042 Q4 | KA1: 2043 Q1 | KB1: 2043 Q2 | KC1: 2043 Q3 | KD1: 2043 Q4 | KE1: 2044 Q1 | KF1: 2044 Q2 | KG1: 2044 Q3 | KH1: 2044 Q4 | KI1: 2045 Q1 | KJ1: 2045 Q2 | KK1: 2045 Q3 | KL1: 2045 Q4 | KM1: 2046 Q1 | KN1: 2046 Q2 | KO1: 2046 Q3 | KP1: 2046 Q4 | KQ1: 2047 Q1 | KR1: 2047 Q2 | KS1: 2047 Q3 | KT1: 2047 Q4 | KU1: 2048 Q1 | KV1: 2048 Q2 | KW1: 2048 Q3 | KX1: 2048 Q4 | KY1: 2049 Q1 | KZ1: 2049 Q2 | LA1: 2049 Q3 | LB1: 2049 Q4 | LC1: 2050 Q1 | LD1: 2050 Q2 | LE1: 2050 Q3 | LF1: 2050 Q4 | LG1: 2051 Q1 | LH1: 2051 Q2 | LI1: 2051 Q3 | LJ1: 2051 Q4 | LK1: 2052 Q1 | LL1: 2052 Q2 | LM1: 2052 Q3 | LN1: 2052 Q4 | LO1: 2053 Q1 | LP1: 2053 Q2 | LQ1: 2053 Q3 | LR1: 2053 Q4 | LS1: 2054 Q1 | LT1: 2054 Q2 | LU1: 2054 Q3 | LV1: 2054 Q4 | LW1: 2055 Q1 | LX1: 2055 Q2 | LY1: 2055 Q3 | LZ1: 2055 Q4 | MA1: 2056 Q1 | MB1: 2056 Q2 | MC1: 2056 Q3 | MD1: 2056 Q4 | ME1: 2057 Q1 | MF1: 2057 Q2 | MG1: 2057 Q3 | MH1: 2057 Q4 | MI1: 2058 Q1 | MJ1: 2058 Q2 | MK1: 2058 Q3 | ML1: 2058 Q4 | MM1: 2059 Q1 | MN1: 2059 Q2 | MO1: 2059 Q3 | MP1: 2059 Q4 | MQ1: 2060 Q1 | MR1: 2060 Q2 | MS1: 2060 Q3 | MT1: 2060 Q4 | MU1: Source | MV1: Seasonally adjusted | MW1: Base year price | MX1: Base year index | MY1: Historical end year | MZ1: Historical end quarter | NA1: Date of last update | NB1: Source details | NC1: Additional source details | ND1: Location code | NE1: Indicator code | NF1: Databank code
A2: United Kingdom | B2: Number of mortgage repossessions | C2: JAN003G | D2: Number | E2: Thousands | F2: Level | G2: 0.001 | H2: 0.001 | I2: 0.001 | J2: 0.001 | K2: 0.001 | L2: 0.001 | M2: 0.001 | N2: 0.001 | O2: 0.001 | P2: 0.001 | Q2: 0.001 | R2: 0.001 | S2: 0.001 | T2: 0.001 | U2: 0.001 | V2: 0.001 | W2: 0.001 | X2: 0.001 | Y2: 0.001 | Z2: 0.001 | AA2: 0.001 | AB2: 0.001 | AC2: 0.001 | AD2: 0.001 | AE2: 0.001 | AF2: 0.001 | AG2: 0.001 | AH2: 0.001 | AI2: 0.001 | AJ2: 0.001 | AK2: 0.001 | AL2: 0.001 | AM2: 0.001 | AN2: 0.001 | AO2: 0.001 | AP2: 0.001 | AQ2: 0.001 | AR2: 0.001 | AS2: 0.001 | AT2: 0.001 | AU2: 0.001 | AV2: 0.001 | AW2: 0.001 | AX2: 0.001 | AY2: 0.001 | AZ2: 0.001 | BA2: 0.001 | BB2: 0.001 | BC2: 0.001 | BD2: 0.001 | BE2: 0.001 | BF2: 0.001 | BG2: 0.001 | BH2: 0.001 | BI2: 0.001 | BJ2: 0.001 | BK2: 0.001 | BL2: 0.001 | BM2: 0.001 | BN2: 0.001 | BO2: 0.001 | BP2: 0.001 | BQ2: 0.001 | BR2: 0.001 | BS2: 0.001 | BT2: 0.001 | BU2: 0.001 | BV2: 0.001 | BW2: 0.001 | BX2: 0.001 | BY2: 0.001 | BZ2: 36.2 | CA2: 44.85 | CB2: 53.5 | CC2: 60.45 | CD2: 67.4 | CE2: 67.95 | CF2: 68.5 | CG2: 66.75 | CH2: 65 | CI2: 59.65 | CJ2: 54.3 | CK2: 47.1 | CL2: 39.9 | CM2: 36.55 | CN2: 33.2 | CO2: 31.3 | CP2: 29.4 | CQ2: 29.6 | CR2: 29.8 | CS2: 28.5 | CT2: 27.2 | CU2: 25.6 | CV2: 24 | CW2: 20.1 | CX2: 16.2 | CY2: 15.15 | CZ2: 14.1 | DA2: 14 | DB2: 13.9 | DC2: 14.55 | DD2: 15.2 | DE2: 14.55 | DF2: 13.9 | DG2: 13.5 | DH2: 13.1 | DI2: 11.95 | DJ2: 10.8 | DK2: 10 | DL2: 9.2 | DM2: 8.55 | DN2: 7.9 | DO2: 7.6 | DP2: 7.3 | DQ2: 6.45 | DR2: 5.6 | DS2: 4.85 | DT2: 4.1 | DU2: 3.45 | DV2: 2.8 | DW2: 2.75 | DX2: 2.7 | DY2: 2.7 | DZ2: 2.7 | EA2: 2.65 | EB2: 2.6 | EC2: 3.1 | ED2: 3.6 | EE2: 4.8 | EF2: 6 | EG2: 5.95 | EH2: 5.9 | EI2: 7 | EJ2: 8.1 | EK2: 8.3 | EL2: 8.5 | EM2: 9.2 | EN2: 9.9 | EO2: 11.1 | EP2: 12.3 | EQ2: 15.6 | ER2: 18.7 | ES2: 22.6 | ET2: 22.7 | EU2: 24.4 | EV2: 21.9 | EW2: 19.3 | EX2: 16.2 | EY2: 15.9 | EZ2: 15.2 | FA2: 14.7 | FB2: 13.7 | FC2: 14.2 | FD2: 14.5 | FE2: 14.7 | FF2: 13.9 | FG2: 13.9 | FH2: 13.5 | FI2: 13 | FJ2: 11.5 | FK2: 11.1 | FL2: 10.3 | FM2: 9.9 | FN2: 8.4 | FO2: 8.5 | FP2: 7.88 | FQ2: 7.15 | FR2: 6.17 | FS2: 4.88 | FT2: 2.5 | FU2: 2.49 | FV2: 2.17 | FW2: 2.11 | FX2: 1.89 | FY2: 1.86 | FZ2: 1.8 | GA2: 1.88 | GB2: 1.8 | GC2: 1.95 | GD2: 1.79 | GE2: 1.91 | GF2: 1.68 | GG2: 1.69 | GH2: 1.69 | GI2: 1.98 | GJ2: 1.92 | GK2: 2.13 | GL2: 1.99 | GM2: 1.71 | GN2: 0.22 | GO2: 0.37 | GP2: 0.33 | GQ2: 0.38 | GR2: 0.45 | GS2: 0.73 | GT2: 0.72 | GU2: 1.04 | GV2: 1.18 | GW2: 1.28 | GX2: 1.09 | GY2: 1.26 | GZ2: 1.22 | HA2: 1.12 | HB2: 1.18 | HC2: 1.54 | HD2: 1.69 | HE2: 1.7 | HF2: 1.746393 | HG2: 1.784214 | HH2: 1.797525 | HI2: 1.809034 | HJ2: 1.813369 | HK2: 1.816119 | HL2: 1.817599 | HM2: 1.816996 | HN2: 1.818873 | HO2: 1.820224 | HP2: 1.820462 | HQ2: 1.816683 | HR2: 1.809648 | HS2: 1.798269 | HT2: 1.790842 | HU2: 1.78359 | HV2: 1.774141 | HW2: 1.767284 | HX2: 1.763394 | HY2: 1.761174 | HZ2: 1.759614 | IA2: 1.75839 | IB2: 1.757393 | IC2: 1.756232 | ID2: 1.754842 | IE2: 1.754077 | IF2: 1.755198 | IG2: 1.756245 | IH2: 1.757191 | II2: 1.758213 | IJ2: 1.759779 | IK2: 1.761361 | IL2: 1.762824 | IM2: 1.764329 | IN2: 1.766207 | IO2: 1.767966 | IP2: 1.769603 | IQ2: 1.77128 | IR2: 1.773313 | IS2: 1.775176 | IT2: 1.77689 | IU2: 1.778688 | IV2: 1.780937 | IW2: 1.783163 | IX2: 1.785373 | IY2: 1.787682 | IZ2: 1.790295 | JA2: 1.79277 | JB2: 1.795356 | JC2: 1.798006 | JD2: 1.800921 | JE2: 1.803647 | JF2: 1.806466 | JG2: 1.809328 | JH2: 1.812451 | JI2: 1.815395 | JJ2: 1.818422 | JK2: 1.821479 | JL2: 1.824765 | JM2: 1.827839 | JN2: 1.830988 | JO2: 1.834153 | JP2: 1.837544 | JQ2: 1.840711 | JR2: 1.843955 | JS2: 1.847198 | JT2: 1.850646 | JU2: 1.85383 | JV2: 1.85708 | JW2: 1.860328 | JX2: 1.8638 | JY2: 1.867037 | JZ2: 1.870338 | KA2: 1.873635 | KB2: 1.877151 | KC2: 1.880428 | KD2: 1.883766 | KE2: 1.8871 | KF2: 1.890648 | KG2: 1.893957 | KH2: 1.897328 | KI2: 1.900684 | KJ2: 1.904254 | KK2: 1.907586 | KL2: 1.910976 | KM2: 1.914351 | KN2: 1.917939 | KO2: 1.921285 | KP2: 1.92469 | KQ2: 1.928079 | KR2: 1.93168 | KS2: 1.935032 | KT2: 1.938447 | KU2: 1.941841 | KV2: 1.945452 | KW2: 1.948812 | KX2: 1.952236 | KY2: 1.95563 | KZ2: 1.959243 | LA2: 1.962609 | LB2: 1.966029 | LC2: 1.969425 | LD2: 1.973042 | LE2: 1.97642 | LF2: 1.97986 | LG2: 1.98275 | LH2: 1.986012 | LI2: 1.988874 | LJ2: 1.99218 | LK2: 1.994921 | LL2: 1.998069 | LM2: 2.000919 | LN2: 2.0042 | LO2: 2.006899 | LP2: 2.010019 | LQ2: 2.012831 | LR2: 2.016087 | LS2: 2.01879 | LT2: 2.021909 | LU2: 2.02472 | LV2: 2.027972 | LW2: 2.030661 | LX2: 2.033758 | LY2: 2.036548 | LZ2: 2.039783 | MA2: 2.042448 | MB2: 2.045532 | MC2: 2.048303 | MD2: 2.051521 | ME2: 2.054188 | MF2: 2.057265 | MG2: 2.060032 | MH2: 2.063253 | MI2: 2.065929 | MJ2: 2.069016 | MK2: 2.071795 | ML2: 2.075014 | MM2: 2.077675 | MN2: 2.080746 | MO2: 2.083511 | MP2: 2.086728 | MQ2: 2.089398 | MR2: 2.092476 | MS2: 2.095242 | MT2: 2.098455 | MU2: CML\Haver Analytics | MV2: False | MW2: NA | MX2: NA | MY2: 2024 | MZ2: 3 | NA2: NA | NB2: Number of mortgage repossessions | NC2: UNMARP42@UK, interpolated/1000 | ND2: GBR | NE2: REPO | NF2: JAN003G.db
A3: United Kingdom | B3: Loans, liabilities of the household sector, LCU | C3: JAN003G | D3: Pound | E3: Millions | F3: Level | G3: 0 | H3: 0 | I3: 0 | J3: 0 | K3: 0 | L3: 0 | M3: 0 | N3: 0 | O3: 0 | P3: 0 | Q3: 0 | R3: 0 | S3: 0 | T3: 0 | U3: 0 | V3: 0 | W3: 0 | X3: 0 | Y3: 0 | Z3: 0 | AA3: 0 | AB3: 0 | AC3: 0 | AD3: 0 | AE3: 0 | AF3: 0 | AG3: 0 | AH3: 0 | AI3: 64761.59 | AJ3: 67638.73 | AK3: 70091.01 | AL3: 72610.32 | AM3: 75025.47 | AN3: 78545.08 | AO3: 81974.97 | AP3: 87375.55 | AQ3: 88820.3 | AR3: 93446.43 | AS3: 98690.26 | AT3: 103494.8 | AU3: 108127.1 | AV3: 113141 | AW3: 118131.1 | AX3: 122827.4 | AY3: 133258.3 | AZ3: 139291 | BA3: 145310.4 | BB3: 150762.5 | BC3: 156486.9 | BD3: 162450.5 | BE3: 169618.6 | BF3: 177527.2 | BG3: 183769.3 | BH3: 192567.8 | BI3: 200615.5 | BJ3: 209439.8 | BK3: 216611 | BL3: 225716 | BM3: 235970 | BN3: 246373 | BO3: 255791 | BP3: 269794 | BQ3: 285703 | BR3: 297630 | BS3: 307440 | BT3: 318905 | BU3: 331089 | BV3: 342452 | BW3: 351756 | BX3: 366288 | BY3: 376714 | BZ3: 386248 | CA3: 392051 | CB3: 402389 | CC3: 409627 | CD3: 413615 | CE3: 415419 | CF3: 420035 | CG3: 427788 | CH3: 430722 | CI3: 431530 | CJ3: 435635 | CK3: 441328 | CL3: 447646 | CM3: 452748 | CN3: 457911 | CO3: 464101 | CP3: 471362 | CQ3: 475489 | CR3: 481275 | CS3: 488139 | CT3: 493365 | CU3: 495738 | CV3: 503790 | CW3: 510436 | CX3: 514960 | CY3: 518156 | CZ3: 528534 | DA3: 538689 | DB3: 547859 | DC3: 561587 | DD3: 571995 | DE3: 584273 | DF3: 594941 | DG3: 607994 | DH3: 620553 | DI3: 636829 | DJ3: 655674 | DK3: 667552 | DL3: 688202 | DM3: 703014 | DN3: 715604 | DO3: 729342 | DP3: 747987 | DQ3: 769137 | DR3: 790305 | DS3: 809928 | DT3: 834201 | DU3: 865435 | DV3: 890807 | DW3: 910822 | DX3: 939241 | DY3: 971319 | DZ3: 1003798 | EA3: 1032893 | EB3: 1065242 | EC3: 1099554 | ED3: 1128681 | EE3: 1146523 | EF3: 1175403 | EG3: 1199192 | EH3: 1222723 | EI3: 1243570 | EJ3: 1276132 | EK3: 1317180 | EL3: 1346853 | EM3: 1372001 | EN3: 1406912 | EO3: 1441224 | EP3: 1461726 | EQ3: 1483670 | ER3: 1502996 | ES3: 1515434 | ET3: 1516691 | EU3: 1514202 | EV3: 1512964 | EW3: 1513803 | EX3: 1517589 | EY3: 1528845 | EZ3: 1524838 | FA3: 1529150 | FB3: 1525911 | FC3: 1524719 | FD3: 1528931 | FE3: 1531162 | FF3: 1533793 | FG3: 1532024 | FH3: 1543909 | FI3: 1552045 | FJ3: 1555841 | FK3: 1567829 | FL3: 1574108 | FM3: 1586260 | FN3: 1596106 | FO3: 1600626 | FP3: 1610589 | FQ3: 1624951 | FR3: 1641938 | FS3: 1649383 | FT3: 1660855 | FU3: 1675207 | FV3: 1685986 | FW3: 1701053 | FX3: 1721660 | FY3: 1739143 | FZ3: 1751607 | GA3: 1773709 | GB3: 1781329 | GC3: 1799927 | GD3: 1812901 | GE3: 1818355 | GF3: 1831264 | GG3: 1851239 | GH3: 1865855 | GI3: 1848327 | GJ3: 1873490 | GK3: 1893215 | GL3: 1910658 | GM3: 1915251 | GN3: 1913499 | GO3: 1932687 | GP3: 1950608 | GQ3: 1961737 | GR3: 1989263 | GS3: 2002133 | GT3: 2001814 | GU3: 2019506 | GV3: 2037978 | GW3: 2062121 | GX3: 2077011 | GY3: 2081928 | GZ3: 2090036 | HA3: 2117180 | HB3: 2117452 | HC3: 2127290 | HD3: 2138212 | HE3: 2156961 | HF3: 2178342 | HG3: 2204166 | HH3: 2220027 | HI3: 2239353 | HJ3: 2260036 | HK3: 2281944 | HL3: 2304880 | HM3: 2328195 | HN3: 2351317 | HO3: 2374451 | HP3: 2397886 | HQ3: 2422010 | HR3: 2446894 | HS3: 2472476 | HT3: 2498685 | HU3: 2525553 | HV3: 2553163 | HW3: 2581601 | HX3: 2610791 | HY3: 2640770 | HZ3: 2671465 | IA3: 2702893 | IB3: 2734964 | IC3: 2767595 | ID3: 2800649 | IE3: 2834093 | IF3: 2867798 | IG3: 2901650 | IH3: 2935533 | II3: 2969464 | IJ3: 3003360 | IK3: 3037159 | IL3: 3070795 | IM3: 3104337 | IN3: 3137746 | IO3: 3170999 | IP3: 3204058 | IQ3: 3237016 | IR3: 3269851 | IS3: 3302543 | IT3: 3335056 | IU3: 3366632 | IV3: 3397367 | IW3: 3427348 | IX3: 3456639 | IY3: 3485321 | IZ3: 3513454 | JA3: 3541098 | JB3: 3568299 | JC3: 3595101 | JD3: 3621544 | JE3: 3647663 | JF3: 3673491 | JG3: 3699059 | JH3: 3724395 | JI3: 3749530 | JJ3: 3774490 | JK3: 3799294 | JL3: 3823964 | JM3: 3848518 | JN3: 3872971 | JO3: 3897341 | JP3: 3921641 | JQ3: 3945885 | JR3: 3970085 | JS3: 3994254 | JT3: 4018399 | JU3: 4042522 | JV3: 4066631 | JW3: 4090734 | JX3: 4114840 | JY3: 4138956 | JZ3: 4163089 | KA3: 4187247 | KB3: 4211435 | KC3: 4235661 | KD3: 4259929 | KE3: 4284246 | KF3: 4308616 | KG3: 4333045 | KH3: 4357536 | KI3: 4382095 | KJ3: 4406724 | KK3: 4431429 | KL3: 4456214 | KM3: 4481082 | KN3: 4506037 | KO3: 4531081 | KP3: 4556219 | KQ3: 4581453 | KR3: 4606787 | KS3: 4632223 | KT3: 4657765 | KU3: 4683414 | KV3: 4709175 | KW3: 4735050 | KX3: 4761040 | KY3: 4787150 | KZ3: 4813380 | LA3: 4839735 | LB3: 4866215 | LC3: 4892824 | LD3: 4919563 | LE3: 4946438 | LF3: 4973451 | LG3: 5000604 | LH3: 5027896 | LI3: 5055304 | LJ3: 5082826 | LK3: 5110460 | LL3: 5138204 | LM3: 5166061 | LN3: 5194033 | LO3: 5222113 | LP3: 5250304 | LQ3: 5278606 | LR3: 5307022 | LS3: 5335554 | LT3: 5364203 | LU3: 5392973 | LV3: 5421863 | LW3: 5450874 | LX3: 5480006 | LY3: 5509261 | LZ3: 5538642 | MA3: 5568145 | MB3: 5597775 | MC3: 5627531 | MD3: 5657416 | ME3: 5687432 | MF3: 5717581 | MG3: 5747865 | MH3: 5778285 | MI3: 5808850 | MJ3: 5839559 | MK3: 5870416 | ML3: 5901423 | MM3: 5932579 | MN3: 5963887 | MO3: 5995349 | MP3: 6026967 | MQ3: 6058747 | MR3: 6090691 | MS3: 6122801 | MT3: 6155078 | MU3: Office for National Statistics\Haver Analytics | MV3: False | MW3: NA | MX3: NA | MY3: 2024 | MZ3: 3 | NA3: NA | NB3: NNREQ@UK | NC3: UK: HH & NPISH: Financial Liabilities: Level: Total Loans (NSA, Mil.GBP) | ND3: GBR | NE3: LNPE | NF3: JAN003G.db
A4: United Kingdom | B4: Stock of owner-occupied houses | C4: JAN003G | D4: Number | E4: Thousands | F4: Level | G4: 13384.75 | H4: 13421.5 | I4: 13458.25 | J4: 13495 | K4: 13514.5 | L4: 13534 | M4: 13553.5 | N4: 13573 | O4: 10185.5 | P4: 6798 | Q4: 3410.5 | R4: 23 | S4: 3455 | T4: 6887 | U4: 10319 | V4: 13751 | W4: 13719 | X4: 13687 | Y4: 13655 | Z4: 13623 | AA4: 13658.5 | AB4: 13694 | AC4: 13729.5 | AD4: 13765 | AE4: 13800 | AF4: 13835 | AG4: 13870 | AH4: 13905 | AI4: 13935.75 | AJ4: 13966.5 | AK4: 13997.25 | AL4: 14028 | AM4: 14077 | AN4: 14126 | AO4: 14175 | AP4: 14224 | AQ4: 14307.5 | AR4: 14391 | AS4: 14474.5 | AT4: 14558 | AU4: 14633.75 | AV4: 14709.5 | AW4: 14785.25 | AX4: 14861 | AY4: 14930.5 | AZ4: 15000 | BA4: 15069.5 | BB4: 15139 | BC4: 15205 | BD4: 15271 | BE4: 15337 | BF4: 15403 | BG4: 15471 | BH4: 15539 | BI4: 15607 | BJ4: 15675 | BK4: 15783 | BL4: 15891 | BM4: 15999 | BN4: 16107 | BO4: 16205.5 | BP4: 16304 | BQ4: 16402.5 | BR4: 16501 | BS4: 16601 | BT4: 16701 | BU4: 16801 | BV4: 16901 | BW4: 16981.25 | BX4: 17061.5 | BY4: 17141.75 | BZ4: 17222 | CA4: 17202.75 | CB4: 17183.5 | CC4: 17164.25 | CD4: 17145 | CE4: 17215 | CF4: 17285 | CG4: 17355 | CH4: 17425 | CI4: 17479.5 | CJ4: 17534 | CK4: 17588.5 | CL4: 17643 | CM4: 17702 | CN4: 17761 | CO4: 17820 | CP4: 17879 | CQ4: 17940.25 | CR4: 18001.5 | CS4: 18062.75 | CT4: 18124 | CU4: 18179.25 | CV4: 18234.5 | CW4: 18289.75 | CX4: 18345 | CY4: 18402.75 | CZ4: 18460.5 | DA4: 18518.25 | DB4: 18576 | DC4: 18639 | DD4: 18702 | DE4: 18765 | DF4: 18828 | DG4: 18885.5 | DH4: 18943 | DI4: 19000.5 | DJ4: 19058 | DK4: 19118.25 | DL4: 19178.5 | DM4: 19238.75 | DN4: 19299 | DO4: 19354.25 | DP4: 19409.5 | DQ4: 19464.75 | DR4: 19520 | DS4: 19576.25 | DT4: 19632.5 | DU4: 19688.75 | DV4: 19745 | DW4: 19822.75 | DX4: 19900.5 | DY4: 19978.25 | DZ4: 20056 | EA4: 20135.25 | EB4: 20214.5 | EC4: 20293.75 | ED4: 20373 | EE4: 20449.5 | EF4: 20526 | EG4: 20602.5 | EH4: 20679 | EI4: 20745 | EJ4: 20811 | EK4: 20877 | EL4: 20943 | EM4: 21012.25 | EN4: 21081.5 | EO4: 21150.75 | EP4: 21220 | EQ4: 21289.5 | ER4: 21359 | ES4: 21428.5 | ET4: 21498 | EU4: 21547 | EV4: 21596 | EW4: 21645 | EX4: 21694 | EY4: 21732.25 | EZ4: 21770.5 | FA4: 21808.75 | FB4: 21847 | FC4: 21883.5 | FD4: 21920 | FE4: 21956.5 | FF4: 21993 | FG4: 22024 | FH4: 22055 | FI4: 22086 | FJ4: 22117 | FK4: 22149.5 | FL4: 22182 | FM4: 22214.5 | FN4: 22247 | FO4: 22288.5 | FP4: 22330 | FQ4: 22371.5 | FR4: 22413 | FS4: 22458 | FT4: 22503 | FU4: 22548 | FV4: 22593 | FW4: 22643 | FX4: 22693 | FY4: 22743 | FZ4: 22793 | GA4: 22853 | GB4: 22913 | GC4: 22973 | GD4: 23033 | GE4: 23097.5 | GF4: 23162 | GG4: 23226.5 | GH4: 23291 | GI4: 23374.8 | GJ4: 23458.59 | GK4: 23542.39 | GL4: 23626.19 | GM4: 23686.86 | GN4: 23747.54 | GO4: 23808.21 | GP4: 23868.88 | GQ4: 23919.73 | GR4: 23970.58 | GS4: 24021.43 | GT4: 24072.28 | GU4: 24160.58 | GV4: 24248.89 | GW4: 24337.19 | GX4: 24425.5 | GY4: 24489.61 | GZ4: 24553.71 | HA4: 24617.82 | HB4: 24681.93 | HC4: 24731.67 | HD4: 24789.1 | HE4: 24835 | HF4: 24882.48 | HG4: 24934.87 | HH4: 24992.58 | HI4: 25050.26 | HJ4: 25108.84 | HK4: 25168.53 | HL4: 25230.78 | HM4: 25289.96 | HN4: 25349.83 | HO4: 25410.61 | HP4: 25474.44 | HQ4: 25535.02 | HR4: 25596.08 | HS4: 25657.87 | HT4: 25722.4 | HU4: 25783.39 | HV4: 25844.97 | HW4: 25906.97 | HX4: 25971.93 | HY4: 26033.36 | HZ4: 26095.29 | IA4: 26157.49 | IB4: 26222.69 | IC4: 26284.33 | ID4: 26346.5 | IE4: 26408.9 | IF4: 26474.33 | IG4: 26536.17 | IH4: 26598.58 | II4: 26661.18 | IJ4: 26726.83 | IK4: 26788.87 | IL4: 26851.5 | IM4: 26914.29 | IN4: 26980.16 | IO4: 27042.4 | IP4: 27105.26 | IQ4: 27168.23 | IR4: 27234.31 | IS4: 27296.74 | IT4: 27359.81 | IU4: 27422.97 | IV4: 27489.26 | IW4: 27551.87 | IX4: 27615.16 | IY4: 27678.5 | IZ4: 27744.98 | JA4: 27807.78 | JB4: 27871.27 | JC4: 27934.78 | JD4: 28001.47 | JE4: 28064.44 | JF4: 28128.14 | JG4: 28191.82 | JH4: 28258.7 | JI4: 28321.85 | JJ4: 28385.76 | JK4: 28449.61 | JL4: 28516.68 | JM4: 28580 | JN4: 28644.11 | JO4: 28708.13 | JP4: 28775.39 | JQ4: 28838.89 | JR4: 28903.2 | JS4: 28967.38 | JT4: 29034.84 | JU4: 29098.51 | JV4: 29163.01 | JW4: 29227.36 | JX4: 29295.01 | JY4: 29358.85 | JZ4: 29423.55 | KA4: 29488.07 | KB4: 29555.9 | KC4: 29619.91 | KD4: 29684.8 | KE4: 29749.48 | KF4: 29817.5 | KG4: 29881.68 | KH4: 29946.77 | KI4: 30011.61 | KJ4: 30079.81 | KK4: 30144.15 | KL4: 30209.43 | KM4: 30274.43 | KN4: 30342.81 | KO4: 30407.32 | KP4: 30472.78 | KQ4: 30537.93 | KR4: 30606.49 | KS4: 30671.15 | KT4: 30736.79 | KU4: 30802.1 | KV4: 30870.83 | KW4: 30935.65 | KX4: 31001.47 | KY4: 31066.92 | KZ4: 31135.81 | LA4: 31200.78 | LB4: 31266.77 | LC4: 31332.36 | LD4: 31401.42 | LE4: 31466.54 | LF4: 31532.69 | LG4: 31590.09 | LH4: 31654.1 | LI4: 31713.26 | LJ4: 31779.58 | LK4: 31837.11 | LL4: 31901.27 | LM4: 31960.56 | LN4: 32027.03 | LO4: 32084.69 | LP4: 32149 | LQ4: 32208.43 | LR4: 32275.05 | LS4: 32332.83 | LT4: 32397.28 | LU4: 32456.84 | LV4: 32523.6 | LW4: 32581.51 | LX4: 32646.09 | LY4: 32705.77 | LZ4: 32772.67 | MA4: 32830.69 | MB4: 32895.41 | MC4: 32955.21 | MD4: 33022.25 | ME4: 33080.38 | MF4: 33145.23 | MG4: 33205.14 | MH4: 33272.32 | MI4: 33330.57 | MJ4: 33395.55 | MK4: 33455.58 | ML4: 33522.89 | MM4: 33581.25 | MN4: 33646.35 | MO4: 33706.5 | MP4: 33773.93 | MQ4: 33832.4 | MR4: 33897.63 | MS4: 33957.89 | MT4: 34025.46 | MU4: Department for Communities and Local Government\Haver Analytics | MV4: False | MW4: NA | MX4: NA | MY4: 2023 | MZ4: 4 | NA4: NA | NB4: UKBHKW@UK + UKBHKP@UK | NC4: Great Britain: Dwelling Stock: Owner Occupied (Thous) + Great Britain: Dwelling Stock: Rented Priv or with a Job/Business (Thous) | ND4: GBR | NE4: HSA | NF4: JAN003G.db
A5: United Kingdom | B5: Consumer price index | C5: JAN003G | D5: Index | E5: NA | F5: Level | G5: 11.88749 | H5: 12.3046 | I5: 12.51315 | J5: 13.00846 | K5: 13.47771 | L5: 14.23371 | M5: 14.57261 | N5: 15.2504 | O5: 16.05854 | P5: 17.46627 | Q5: 18.22228 | R5: 18.84793 | S5: 19.42145 | T5: 20.12532 | U5: 20.59456 | V5: 21.50698 | W5: 22.47153 | X5: 23.41002 | Y5: 23.82713 | Z5: 24.13995 | AA5: 24.45278 | AB5: 25.07844 | AC5: 25.46948 | AD5: 25.86051 | AE5: 26.43403 | AF5: 27.26824 | AG5: 28.91059 | AH5: 29.71873 | AI5: 30.60508 | AJ5: 32.24743 | AK5: 32.9513 | AL5: 33.55088 | AM5: 34.3851 | AN5: 36.07959 | AO5: 36.73131 | AP5: 37.43518 | AQ5: 37.87835 | AR5: 39.1818 | AS5: 39.41642 | AT5: 39.88567 | AU5: 40.17243 | AV5: 40.85022 | AW5: 41.2934 | AX5: 41.76264 | AY5: 41.86692 | AZ5: 42.77934 | BA5: 42.98789 | BB5: 43.43106 | BC5: 43.87423 | BD5: 44.9952 | BE5: 45.12555 | BF5: 45.49052 | BG5: 45.64693 | BH5: 46.3508 | BI5: 46.53328 | BJ5: 46.92432 | BK5: 47.23714 | BL5: 47.83673 | BM5: 47.88887 | BN5: 48.43632 | BO5: 48.56667 | BP5: 49.5 | BQ5: 49.9 | BR5: 50.46667 | BS5: 51 | BT5: 52.13334 | BU5: 52.46667 | BV5: 53.26667 | BW5: 53.93333 | BX5: 55.6 | BY5: 56.4 | BZ5: 57.46667 | CA5: 57.66667 | CB5: 60.26667 | CC5: 60.83333 | CD5: 61.46667 | CE5: 61.7 | CF5: 62.83333 | CG5: 62.73333 | CH5: 63.13334 | CI5: 63.2 | CJ5: 64.43333 | CK5: 64.5 | CL5: 64.66666 | CM5: 64.76667 | CN5: 65.7 | CO5: 65.63333 | CP5: 65.8 | CQ5: 66.33334 | CR5: 67.26667 | CS5: 67.4 | CT5: 67.73333 | CU5: 68.1 | CV5: 68.86667 | CW5: 68.93333 | CX5: 69.36667 | CY5: 69.36667 | CZ5: 70 | DA5: 70.26667 | DB5: 70.63333 | DC5: 70.5 | DD5: 71.26667 | DE5: 71.23333 | DF5: 71.63333 | DG5: 71.6 | DH5: 72.3 | DI5: 72.13333 | DJ5: 72.43333 | DK5: 72.13333 | DL5: 72.76667 | DM5: 72.7 | DN5: 73.16666 | DO5: 72.76667 | DP5: 73.83334 | DQ5: 73.86667 | DR5: 73.9 | DS5: 73.86667 | DT5: 74.53333 | DU5: 74.6 | DV5: 75 | DW5: 75 | DX5: 75.46667 | DY5: 75.6 | DZ5: 76.03333 | EA5: 75.96667 | EB5: 76.53333 | EC5: 76.56667 | ED5: 77.1 | EE5: 77.23333 | EF5: 78 | EG5: 78.4 | EH5: 78.76667 | EI5: 78.73333 | EJ5: 79.8 | EK5: 80.3 | EL5: 80.9 | EM5: 81 | EN5: 81.8 | EO5: 81.73333 | EP5: 82.6 | EQ5: 82.93333 | ER5: 84.6 | ES5: 85.63333 | ET5: 85.73333 | EU5: 85.43333 | EV5: 86.36667 | EW5: 86.93333 | EX5: 87.56667 | EY5: 88.23333 | EZ5: 89.36667 | FA5: 89.63333 | FB5: 90.5 | FC5: 91.83334 | FD5: 93.3 | FE5: 93.83334 | FF5: 94.73333 | FG5: 95.03333 | FH5: 95.8 | FI5: 96.06667 | FJ5: 97.26667 | FK5: 97.66666 | FL5: 98.36667 | FM5: 98.7 | FN5: 99.3 | FO5: 99.4 | FP5: 100.1 | FQ5: 100.1333 | FR5: 100.2 | FS5: 99.5 | FT5: 100.0667 | FU5: 100.1667 | FV5: 100.3 | FW5: 99.83334 | FX5: 100.4 | FY5: 100.8667 | FZ5: 101.5 | GA5: 102 | GB5: 103.1667 | GC5: 103.7 | GD5: 104.5667 | GE5: 104.7667 | GF5: 105.6667 | GG5: 106.3 | GH5: 106.9333 | GI5: 106.7 | GJ5: 107.8 | GK5: 108.2667 | GL5: 108.4333 | GM5: 108.4667 | GN5: 108.5333 | GO5: 108.9333 | GP5: 109.0667 | GQ5: 109.1667 | GR5: 110.7333 | GS5: 111.9333 | GT5: 114.4 | GU5: 115.9333 | GV5: 120.8667 | GW5: 123.1333 | GX5: 126.7 | GY5: 127.7333 | GZ5: 131.0667 | HA5: 131.4 | HB5: 131.9667 | HC5: 132.2667 | HD5: 133.8333 | HE5: 134.1 | HF5: 135.3304 | HG5: 135.8286 | HH5: 137.4183 | HI5: 138.2367 | HJ5: 139.1495 | HK5: 139.4458 | HL5: 140.7172 | HM5: 141.3141 | HN5: 142.0627 | HO5: 142.3412 | HP5: 143.5906 | HQ5: 144.21 | HR5: 144.9618 | HS5: 145.3065 | HT5: 146.6218 | HU5: 147.3075 | HV5: 148.1067 | HW5: 148.4103 | HX5: 149.7147 | HY5: 150.389 | HZ5: 151.1608 | IA5: 151.4411 | IB5: 152.7486 | IC5: 153.4264 | ID5: 154.1881 | IE5: 154.4699 | IF5: 155.8036 | IG5: 156.4949 | IH5: 157.2719 | II5: 157.5593 | IJ5: 158.9196 | IK5: 159.6248 | IL5: 160.4173 | IM5: 160.7104 | IN5: 162.098 | IO5: 162.8173 | IP5: 163.6257 | IQ5: 163.9247 | IR5: 165.34 | IS5: 166.0737 | IT5: 166.8982 | IU5: 167.2032 | IV5: 168.6468 | IW5: 169.3952 | IX5: 170.2362 | IY5: 170.5472 | IZ5: 172.0197 | JA5: 172.7831 | JB5: 173.6409 | JC5: 173.9582 | JD5: 175.4601 | JE5: 176.2387 | JF5: 177.1137 | JG5: 177.4373 | JH5: 178.9693 | JI5: 179.7635 | JJ5: 180.656 | JK5: 180.9861 | JL5: 182.5487 | JM5: 183.3588 | JN5: 184.2691 | JO5: 184.6058 | JP5: 186.1997 | JQ5: 187.0259 | JR5: 187.9545 | JS5: 188.2979 | JT5: 189.9237 | JU5: 190.7665 | JV5: 191.7136 | JW5: 192.0639 | JX5: 193.7221 | JY5: 194.5818 | JZ5: 195.5479 | KA5: 195.9052 | KB5: 197.5966 | KC5: 198.4734 | KD5: 199.4588 | KE5: 199.8233 | KF5: 201.5485 | KG5: 202.4429 | KH5: 203.448 | KI5: 203.8197 | KJ5: 205.5795 | KK5: 206.4918 | KL5: 207.5169 | KM5: 207.8961 | KN5: 209.6911 | KO5: 210.6216 | KP5: 211.6673 | KQ5: 212.054 | KR5: 213.8849 | KS5: 214.834 | KT5: 215.9006 | KU5: 216.2951 | KV5: 218.1626 | KW5: 219.1307 | KX5: 220.2186 | KY5: 220.621 | KZ5: 222.5258 | LA5: 223.5133 | LB5: 224.623 | LC5: 225.0334 | LD5: 226.9763 | LE5: 227.9836 | LF5: 229.1155 | LG5: 229.5341 | LH5: 231.5159 | LI5: 232.5433 | LJ5: 233.6978 | LK5: 234.1248 | LL5: 236.1462 | LM5: 237.1941 | LN5: 238.3717 | LO5: 238.8073 | LP5: 240.8691 | LQ5: 241.938 | LR5: 243.1392 | LS5: 243.5834 | LT5: 245.6865 | LU5: 246.7768 | LV5: 248.002 | LW5: 248.4551 | LX5: 250.6002 | LY5: 251.7123 | LZ5: 252.962 | MA5: 253.4242 | MB5: 255.6122 | MC5: 256.7466 | MD5: 258.0212 | ME5: 258.4927 | MF5: 260.7245 | MG5: 261.8815 | MH5: 263.1817 | MI5: 263.6625 | MJ5: 265.939 | MK5: 267.1191 | ML5: 268.4453 | MM5: 268.9358 | MN5: 271.2578 | MO5: 272.4615 | MP5: 273.8142 | MQ5: 274.3145 | MR5: 276.6829 | MS5: 277.9107 | MT5: 279.2905 | MU5: Office for National Statistics\Haver Analytics | MV5: False | MW5: NA | MX5: 2015 | MY5: 2024 | MZ5: 3 | NA5: NA | NB5: D7BT@UK | NC5: UK: Consumer Price Index: All Items (NSA, 2015=100) | ND5: GBR | NE5: CPI | NF5: JAN003G.db
