Workbook
Name _DLX1.INC: HAVERM!$A$1:$G$6
Name _DLX2.INC: HAVERQ!$A$2:$BM$7
Name Data: [1]sheet0!$C$2

Sheet CHARTS>>

Sheet DATA>>

Sheet Chart Data
A1: Labour income cont to PEDY! | F1: Labour income cont to PEDY | M1: LFS unemployment - single-month & three-month rates | Q1: LFS unemployment - single-month range & 3-month rate | X1: Change in jobs since 2019 - private vs public | AB1: Composition of public sector employment | AJ1: Composition of public sector employment (shares) | AR1: Change in WFJ since 2019 | AS1: =HAVERQ!T186 -> 361 | AT1: =HAVERQ!U186 -> 46 | AU1: =HAVERQ!V186 -> 2580 | AV1: =HAVERQ!W186 -> 141 | AW1: =HAVERQ!X186 -> 242 | AX1: =HAVERQ!Y186 -> 2227 | AY1: =HAVERQ!Z186 -> 4741 | AZ1: =HAVERQ!AA186 -> 1883 | ... BJ1: =HAVERQ!AK186 -> 1100 | BK1: =HAVERQ!AL186+HAVERQ!AK186 -> 2028 | BO1: Change in WFJ since 2019 | CK1: Unit wage costs & profits | CO1: BoE DMP | CW1: Measures of labour market health | CX1: Av | CY1: =AVERAGE(HAVERQ!AQ$128:AQ$183) -> 5.5214286 | CZ1: =AVERAGE(DL$5:DL$59) -> 1.6315868 | DA1: =AVERAGE(DO$5:DO$59) -> 9.6646096 | DB1: =AVERAGE(HAVERQ!AR$128:AR$183) -> 4.6142857 | DC1: =AVERAGE(DM$5:DM$59) -> 0.46379323 | DD1: =AVERAGE(DN$29:DN$59) -> 1.1947846 | DE1: =AVERAGE(HAVERQ!AZ$128:AZ$167,AZ$174:AZ$183) -> 31.9575 | DF1: =AVERAGE(HAVERQ!AS$128:AS$183) -> 0.9985119 | DG1: =AVERAGE(DP$5:DP$59) -> 2.9941664 | DH1: =AVERAGE(HAVERQ!AX$128:AX$183) -> 63.439286 | DJ1: =AVERAGE(DR$5:DR$59) -> 62.615979 | DU1: -ve | DV1: -ve | DW1: -ve | DX1: -ve
CP2: =RANK(CP5,$CP$5:$CU$5) -> 4 | CQ2: =RANK(CQ5,$CP$5:$CU$5) -> 3 | CR2: =RANK(CR5,$CP$5:$CU$5) -> 2 | CS2: =RANK(CS5,$CP$5:$CU$5) -> 1 | CT2: =RANK(CT5,$CP$5:$CU$5) -> 5 | CU2: =RANK(CU5,$CP$5:$CU$5) -> 6 | CX2: STDEV | CY2: =STDEV(HAVERQ!AQ$128:AQ$183) -> 1.6422506 | CZ2: =STDEV(DL$5:DL$59) -> 0.7489078 | DA2: =STDEV(DO$5:DO$59) -> 1.5084142 | DB2: =STDEV(HAVERQ!AR$128:AR$183) -> 1.8546677 | DC2: =STDEV(DM$5:DM$59) -> 0.23599838 | DD2: =STDEV(DN$29:DN$59) -> 1.4625982 | DE2: =STDEV(HAVERQ!AZ$128:AZ$167,AZ$174:AZ$183) -> 0.23302635 | DF2: =STDEV(HAVERQ!AS$128:AS$183) -> 1.8996791 | DG2: =STDEV(DP$5:DP$59) -> 1.942251 | DH2: =STDEV(HAVERQ!AZ$128:AZ$183) -> 1.0292965 | DJ2: =STDEV(DR$5:DR$59) -> 9.9243632
B3: Labour income | C3: Other | D3: Nominal household income | G3: Labour income | H3: Other | I3: Real household income | K3: PC | N3: Single month rate | O3: Three-month rate | R3: Single month range - min | S3: Range of single-month estimates | T3: Three-month rate | V3: Single month range - max | Y3: Public sector | Z3: Private sector | AC3: NHS | AD3: Education | AE3: Public administration | AF3: Police | AG3: HM forces | AH3: Other | AK3: NHS | AL3: Education | AM3: Public administration | AN3: Police | AO3: HM forces | AP3: Other | AS3: Agriculture | AT3: Extraction | AU3: Manufacturing | AV3: Utilities | AW3: Water | AX3: Construction | AY3: Wholesale & retail | AZ3: Transport | BA3: Accommodation & food | BB3: Communications | BC3: Financial services | BD3: Real estate | BE3: Professional services | BF3: Administrative services | BG3: Public admin | BH3: Education | BI3: Health | BJ3: Art & recreation | BK3: Other services | BM3: Other services | BP3: Agriculture | BQ3: Extraction & utilities | BR3: Manufacturing | BS3: Construction | BT3: Distribution, accommodation & food | BU3: Transport & comms | BV3: Financial services | BW3: Business services | BX3: Public services | BZ3: Agriculture | CA3: Extraction & utilities | CB3: Manufacturing | CC3: Construction | CD3: Distribution, accommodation & food | CE3: Transport & comms | CF3: Financial services | CG3: Business services | CH3: Public services | CI3: Check | CL3: Unit wage costs (LHS) | CM3: Corporate profits (RHS) | CP3: ='DMP - NICs Reaction'!B3 -> Lower employee wages | CQ3: ='DMP - NICs Reaction'!C3 -> Lower number of employees | CR3: ='DMP - NICs Reaction'!D3 -> Higher prices | CS3: ='DMP - NICs Reaction'!E3 -> Lower profit margins | CT3: ='DMP - NICs Reaction'!F3 -> Other | CU3: ='DMP - NICs Reaction'!G3 -> None of the above | CY3: Unemployment rate | CZ3: Unemployed >12 months | DA3: Underemployment | DB3: Redundancy rate | DC3: Vacancy/ Unemployed ratio | DD3: HMRC payroll employment | DE3: Average hours | DF3: BoE recruitment difficulties | DG3: Private sector regular pay growth | DH3: Participation rate | DJ3: BCC recruitment difficulties | DL3: Unemployed >12 months | DM3: V/U ratio | DN3: Employment growth | DO3: Underemployment rate | DP3: Private sector regular pay growth | DR3: BCC recruitment difficulties | DU3: =CY3&"*" -> Unemployment rate* | DV3: =CZ3&"*" -> Unemployed >12 months* | DW3: =DA3&"*" -> Underemployment* | DX3: =DB3&"*" -> Redundancy rate* | DY3: =DC3&"*" -> Vacancy/ Unemployed ratio* | DZ3: =DE3&"*" -> Average hours* | EA3: =DD3 -> HMRC payroll employment | EB3: =DF3 -> BoE recruitment difficulties | EC3: =DG3 -> Private sector regular pay growth | ED3: =DH3&"*" -> Participation rate* | EF3: =DJ3 -> BCC recruitment difficulties
A4: 2014 | B4: =100*((DataA!G48-DataA!G47)/DataA!H47) -> 2.2545386 | C4: =D4-B4 -> 1.2449333 | D4: =100*((DataA!H48/DataA!H47)-1) -> 3.4994719 | F4: 2014 | G4: =B4-K4 -> 1.0973014 | H4: =I4-G4 -> 1.1592146 | I4: =100*((DataA!I48/DataA!I47)-1) -> 2.2565161 | K4: =100*((DataA!J48/DataA!J47)-1) -> 1.1572372 | M4: 42370 | N4: =HAVERM!C439 -> 4.926 | O4: =HAVERM!B439 -> 5.1 | Q4: 42370 | R4: =MIN(HAVERM!C438:C440) -> 4.926 | S4: =V4-R4 -> 0.327 | T4: =HAVERM!B439 -> 5.1 | V4: =MAX(HAVERM!C438:C440) -> 5.253 | X4: 43466 | Y4: =HAVERQ!E164-AVERAGE(HAVERQ!E$164:E$167) -> -30.75 | Z4: =HAVERQ!F164-AVERAGE(HAVERQ!F$164:F$167) -> -64.75 | AB4: 36526 | AC4: =HAVERQ!P88 -> 1197 | AD4: =HAVERQ!O88 -> 1406 | AE4: =HAVERQ!N88 -> 1184 | AF4: =HAVERQ!M88 -> 225 | AG4: =HAVERQ!L88 -> 217 | AH4: =HAVERQ!E88-AC4-AD4-AE4-AF4-AG4 -> 800 | AJ4: 36526 | AK4: =100*(AC4/SUM($AC4:$AH4)) -> 23.801949 | AL4: =100*(AD4/SUM($AC4:$AH4)) -> 27.957845 | AM4: =100*(AE4/SUM($AC4:$AH4)) -> 23.543448 | AN4: =100*(AF4/SUM($AC4:$AH4)) -> 4.4740505 | AO4: =100*(AG4/SUM($AC4:$AH4)) -> 4.3149732 | AP4: =100*(AH4/SUM($AC4:$AH4)) -> 15.907735 | AR4: 43466 | AS4: =HAVERQ!T164-AVERAGE(HAVERQ!T$164:T$167) -> -11.25 | AT4: =HAVERQ!U164-AVERAGE(HAVERQ!U$164:U$167) -> 0.75 | AU4: =HAVERQ!V164-AVERAGE(HAVERQ!V$164:V$167) -> 14.25 | AV4: =HAVERQ!W164-AVERAGE(HAVERQ!W$164:W$167) -> -0.75 | AW4: =HAVERQ!X164-AVERAGE(HAVERQ!X$164:X$167) -> 5.5 | AX4: =HAVERQ!Y164-AVERAGE(HAVERQ!Y$164:Y$167) -> 27.75 | AY4: =HAVERQ!Z164-AVERAGE(HAVERQ!Z$164:Z$167) -> 27.5 | AZ4: =HAVERQ!AA164-AVERAGE(HAVERQ!AA$164:AA$167) -> -20 | ... BJ4: =HAVERQ!AK164-AVERAGE(HAVERQ!AK$164:AK$167) -> -5.75 | BK4: =BM4-AVERAGE(BM$4:BM$7) -> -9.5 | BM4: =HAVERQ!AL164+HAVERQ!AM164 -> 1008 | BO4: 43466 | BP4: =BZ4-AVERAGE(BZ$4:BZ$7) -> -11.25 | BQ4: =CA4-AVERAGE(CA$4:CA$7) -> 5.5 | BR4: =CB4-AVERAGE(CB$4:CB$7) -> 14.25 | BS4: =CC4-AVERAGE(CC$4:CC$7) -> 27.75 | BT4: =CD4-AVERAGE(CD$4:CD$7) -> -5.5 | BU4: =CE4-AVERAGE(CE$4:CE$7) -> -36.25 | BV4: =CF4-AVERAGE(CF$4:CF$7) -> -3.25 | BW4: =CG4-AVERAGE(CG$4:CG$7) -> -57.25 | BX4: =CH4-AVERAGE(CH$4:CH$7) -> -59.25 | BZ4: =HAVERQ!T164 -> 387 | CA4: =HAVERQ!U164+HAVERQ!W164+HAVERQ!X164 -> 431 | CB4: =HAVERQ!V164 -> 2705 | CC4: =HAVERQ!Y164 -> 2361 | CD4: =HAVERQ!Z164+HAVERQ!AB164 -> 7499 | CE4: =HAVERQ!AA164+HAVERQ!AC164 -> 3270 | CF4: =HAVERQ!AD164 -> 1132 | CG4: =HAVERQ!AE164+HAVERQ!AF164+HAVERQ!AG164 -> 6774 | CH4: =HAVERQ!AH164+HAVERQ!AI164+HAVERQ!AJ164+HAVERQ!AK164+HAVERQ!AL164+HAVERQ!AM164 -> 10881 | CI4: =HAVERQ!S164-SUM('Chart Data'!BZ4:CH4) -> -2 | CK4: 2012 | CL4: =100*((DataQ!F163/DataQ!F159)-1) -> -1.0460326 | CM4: =100*(DataQ!I163/DataQ!J163) -> 21.990625 | CO4: ='DMP - NICs Reaction'!A4 -> 45597 | CP4: ='DMP - NICs Reaction'!B4 -> 37.88 | CQ4: ='DMP - NICs Reaction'!C4 -> 53.68 | CR4: ='DMP - NICs Reaction'!D4 -> 53.64 | CS4: ='DMP - NICs Reaction'!E4 -> 58.72 | CT4: ='DMP - NICs Reaction'!F4 -> 7.51 | CU4: ='DMP - NICs Reaction'!G4 -> 2.67 | CX4: 2010 | CY4: =(HAVERQ!AQ128-AVERAGE(HAVERQ!AQ$128:AQ$183))/STDEV(HAVERQ!AQ$128:AQ$183) -> 1.5092529 | CZ4: =(DL4-AVERAGE(DL$5:DL$59))/STDEV(DL$5:DL$59) -> 1.0741155 | DA4: =(DO4-AVERAGE(DO$5:DO$59))/STDEV(DO$5:DO$59) -> 0.90570461 | DB4: =(HAVERQ!AR128-AVERAGE(HAVERQ!AR$128:AR$183))/STDEV(HAVERQ!AR$128:AR$183) -> 1.3402478 | DC4: =(DM4-AVERAGE(DM$5:DM$59))/STDEV(DM$5:DM$59) -> -1.2243516 | DD4: =(DN4-AVERAGE(DN$29:DN$59))/STDEV(DN$29:DN$59) -> #N/A | DE4: =(HAVERQ!AZ128-AVERAGE(HAVERQ!AZ$128:AZ$183))/STDEV(HAVERQ!AZ$128:AZ$183) -> -0.026023322 | DF4: =(HAVERQ!AS128-AVERAGE(HAVERQ!AS$128:AS$183))/STDEV(HAVERQ!AS$128:AS$183) -> -2.052195 | DG4: =(DP4-AVERAGE(DP$5:DP$59))/STDEV(DP$5:DP$59) -> -1.0724467 | DH4: =(HAVERQ!AX128-AVERAGE(HAVERQ!AX$128:AX$183))/STDEV(HAVERQ!AX$128:AX$183) -> -1.3285019 | DJ4: =(DR4-AVERAGE(DR$5:DR$59))/STDEV(DR$5:DR$59) -> -1.9765479 | DL4: =100*(HAVERQ!AV128/(HAVERQ!AW128*HAVERQ!AX128/100)) -> 2.4360003 | DM4: =HAVERQ!AO128/HAVERQ!AP128 -> 0.17484824 | DN4: =100*((AVERAGE(HAVERQ!BC125:BC128)/AVERAGE(HAVERQ!BC121:BC124))-1) -> #N/A | DO4: =100*(HAVERQ!BE128+HAVERQ!BF128)/(HAVERQ!BB128+HAVERQ!BG128) -> 11.030787 | DP4: =100*((AVERAGE(HAVERQ!BA125:BA128)/AVERAGE(HAVERQ!BA121:BA124))-1) -> 0.91120589 | DR4: =(HAVERQ!AT128*HAVERQ!$AT$1)+(HAVERQ!AU128*HAVERQ!$AU$1) -> 43 | DT4: Latest (Q3 2024) | DU4: =-CY62 -> 0.74375286 | DV4: =-CZ62 -> 0.88680621 | DW4: =-DA62 -> 1.1066331 | DX4: =-DB62 -> 0.76255478 | DY4: =DC62 -> 0.43375455 | DZ4: =DE62 -> 0.61151881 | EA4: =DD62 -> -0.10928383 | EB4: =DF62 -> 0.00078334033 | EC4: =DG62 -> 1.2174405 | ED4: =DH62 -> -0.72365552 | EF4: =DJ62 -> 1.2019085
A5: 2015 | B5: =100*((DataA!G49-DataA!G48)/DataA!H48) -> 2.0418208 | C5: =D5-B5 -> 3.649196 | D5: =100*((DataA!H49/DataA!H48)-1) -> 5.6910168 | F5: 2015 | G5: =B5-K5 -> 2.4131255 | H5: =I5-G5 -> 3.6485662 | I5: =100*((DataA!I49/DataA!I48)-1) -> 6.0616917 | K5: =100*((DataA!J49/DataA!J48)-1) -> -0.37130467 | M5: 42401 | N5: =HAVERM!C440 -> 5.116 | O5: =HAVERM!B440 -> 5.1 | Q5: 42401 | R5: =MIN(HAVERM!C439:C441) -> 4.926 | S5: =V5-R5 -> 0.24 | T5: =HAVERM!B440 -> 5.1 | V5: =MAX(HAVERM!C439:C441) -> 5.166 | X5: 43556 | Y5: =HAVERQ!E165-AVERAGE(HAVERQ!E$164:E$167) -> -10.75 | Z5: =HAVERQ!F165-AVERAGE(HAVERQ!F$164:F$167) -> -22.75 | AB5: 36617 | AC5: =HAVERQ!P89 -> 1204 | AD5: =HAVERQ!O89 -> 1441 | AE5: =HAVERQ!N89 -> 1178 | AF5: =HAVERQ!M89 -> 225 | AG5: =HAVERQ!L89 -> 217 | AH5: =HAVERQ!E89-AC5-AD5-AE5-AF5-AG5 -> 784 | AJ5: 36617 | AK5: =100*(AC5/SUM($AC5:$AH5)) -> 23.846306 | AL5: =100*(AD5/SUM($AC5:$AH5)) -> 28.540305 | AM5: =100*(AE5/SUM($AC5:$AH5)) -> 23.331353 | AN5: =100*(AF5/SUM($AC5:$AH5)) -> 4.456328 | AO5: =100*(AG5/SUM($AC5:$AH5)) -> 4.2978808 | AP5: =100*(AH5/SUM($AC5:$AH5)) -> 15.527827 | AR5: 43556 | AS5: =HAVERQ!T165-AVERAGE(HAVERQ!T$164:T$167) -> -0.25 | AT5: =HAVERQ!U165-AVERAGE(HAVERQ!U$164:U$167) -> -1.25 | AU5: =HAVERQ!V165-AVERAGE(HAVERQ!V$164:V$167) -> -1.75 | AV5: =HAVERQ!W165-AVERAGE(HAVERQ!W$164:W$167) -> -0.75 | AW5: =HAVERQ!X165-AVERAGE(HAVERQ!X$164:X$167) -> 0.5 | AX5: =HAVERQ!Y165-AVERAGE(HAVERQ!Y$164:Y$167) -> 5.75 | AY5: =HAVERQ!Z165-AVERAGE(HAVERQ!Z$164:Z$167) -> 11.5 | AZ5: =HAVERQ!AA165-AVERAGE(HAVERQ!AA$164:AA$167) -> 13 | ... BJ5: =HAVERQ!AK165-AVERAGE(HAVERQ!AK$164:AK$167) -> -9.75 | BK5: =BM5-AVERAGE(BM$4:BM$7) -> -8.5 | BM5: =HAVERQ!AL165+HAVERQ!AM165 -> 1009 | BO5: 43556 | BP5: =BZ5-AVERAGE(BZ$4:BZ$7) -> -0.25 | BQ5: =CA5-AVERAGE(CA$4:CA$7) -> -1.5 | BR5: =CB5-AVERAGE(CB$4:CB$7) -> -1.75 | BS5: =CC5-AVERAGE(CC$4:CC$7) -> 5.75 | BT5: =CD5-AVERAGE(CD$4:CD$7) -> 24.5 | BU5: =CE5-AVERAGE(CE$4:CE$7) -> 1.75 | BV5: =CF5-AVERAGE(CF$4:CF$7) -> -0.25 | BW5: =CG5-AVERAGE(CG$4:CG$7) -> -8.25 | BX5: =CH5-AVERAGE(CH$4:CH$7) -> -40.25 | BZ5: =HAVERQ!T165 -> 398 | CA5: =HAVERQ!U165+HAVERQ!W165+HAVERQ!X165 -> 424 | CB5: =HAVERQ!V165 -> 2689 | CC5: =HAVERQ!Y165 -> 2339 | CD5: =HAVERQ!Z165+HAVERQ!AB165 -> 7529 | CE5: =HAVERQ!AA165+HAVERQ!AC165 -> 3308 | CF5: =HAVERQ!AD165 -> 1135 | CG5: =HAVERQ!AE165+HAVERQ!AF165+HAVERQ!AG165 -> 6823 | CH5: =HAVERQ!AH165+HAVERQ!AI165+HAVERQ!AJ165+HAVERQ!AK165+HAVERQ!AL165+HAVERQ!AM165 -> 10900 | CI5: =HAVERQ!S165-SUM('Chart Data'!BZ5:CH5) -> 1 | CL5: =100*((DataQ!F164/DataQ!F160)-1) -> 0.71283454 | CM5: =100*(DataQ!I164/DataQ!J164) -> 21.877964 | CO5: ='DMP - NICs Reaction'!A5 -> 45627 | CP5: ='DMP - NICs Reaction'!B5 -> 40.67 | CQ5: ='DMP - NICs Reaction'!C5 -> 52.76 | CR5: ='DMP - NICs Reaction'!D5 -> 54.45 | CS5: ='DMP - NICs Reaction'!E5 -> 63.5 | CT5: ='DMP - NICs Reaction'!F5 -> 7.33 | CU5: ='DMP - NICs Reaction'!G5 -> 3.75 | CY5: =(HAVERQ!AQ129-AVERAGE(HAVERQ!AQ$128:AQ$183))/STDEV(HAVERQ!AQ$128:AQ$183) -> 1.4483608 | CZ5: =(DL5-AVERAGE(DL$5:DL$59))/STDEV(DL$5:DL$59) -> 1.204019 | DA5: =(DO5-AVERAGE(DO$5:DO$59))/STDEV(DO$5:DO$59) -> 0.80200723 | DB5: =(HAVERQ!AR129-AVERAGE(HAVERQ!AR$128:AR$183))/STDEV(HAVERQ!AR$128:AR$183) -> 0.80106765 | DC5: =(DM5-AVERAGE(DM$5:DM$59))/STDEV(DM$5:DM$59) -> -1.1295838 | DD5: =(DN5-AVERAGE(DN$29:DN$59))/STDEV(DN$29:DN$59) -> #N/A | DE5: =(HAVERQ!AZ129-AVERAGE(HAVERQ!AZ$128:AZ$167,AZ$174:AZ$183))/STDEV(HAVERQ!AZ$128:AZ$167,AZ$174:AZ$183) -> -1.5341612 | DF5: =(HAVERQ!AS129-AVERAGE(HAVERQ!AS$128:AS$183))/STDEV(HAVERQ!AS$128:AS$183) -> -1.753899 | DG5: =(DP5-AVERAGE(DP$5:DP$59))/STDEV(DP$5:DP$59) -> -1.1127899 | DH5: =(HAVERQ!AX129-AVERAGE(HAVERQ!AX$128:AX$183))/STDEV(HAVERQ!AX$128:AX$183) -> -0.72365552 | DJ5: =(DR5-AVERAGE(DR$5:DR$59))/STDEV(DR$5:DR$59) -> -1.0305242 | DL5: =100*(HAVERQ!AV129/(HAVERQ!AW129*HAVERQ!AX129/100)) -> 2.5332861 | DM5: =HAVERQ!AO129/HAVERQ!AP129 -> 0.19721329 | DN5: =100*((AVERAGE(HAVERQ!BC126:BC129)/AVERAGE(HAVERQ!BC122:BC125))-1) -> #N/A | DO5: =100*(HAVERQ!BE129+HAVERQ!BF129)/(HAVERQ!BB129+HAVERQ!BG129) -> 10.874369 | DP5: =100*((AVERAGE(HAVERQ!BA126:BA129)/AVERAGE(HAVERQ!BA122:BA125))-1) -> 0.83284912 | DR5: =(HAVERQ!AT129*HAVERQ!$AT$1)+(HAVERQ!AU129*HAVERQ!$AU$1) -> 52.388683 | DT5: 2023 | DU5: =-AVERAGE(CY$56:CY$59) -> 0.89598297 | DV5: =-AVERAGE(CZ$56:CZ$59) -> 1.0785846 | DW5: =-AVERAGE(DA$56:DA$59) -> 1.3531895 | DX5: =-AVERAGE(DB$56:DB$59) -> 0.72211627 | DY5: =AVERAGE(DC$56:DC$59) -> 1.0951349 | DZ5: =AVERAGE(DE$56:DE$59) -> -1.4268772 | EA5: =AVERAGE(DD$56:DD$59) -> 0.68602673 | EB5: =AVERAGE(DF$56:DF$59) -> 0.52718804 | EC5: =AVERAGE(DG$56:DG$59) -> 1.9522052 | ED5: =AVERAGE(DH$56:DH$59) -> -0.95047292 | EF5: =AVERAGE(DJ$56:DJ$59) -> 1.3393442
A6: 2016 | B6: =100*((DataA!G50-DataA!G49)/DataA!H49) -> 2.0449227 | C6: =D6-B6 -> -0.089021233 | D6: =100*((DataA!H50/DataA!H49)-1) -> 1.9559014 | F6: 2016 | G6: =B6-K6 -> 0.77782891 | H6: =I6-G6 -> -0.083554616 | I6: =100*((DataA!I50/DataA!I49)-1) -> 0.6942743 | K6: =100*((DataA!J50/DataA!J49)-1) -> 1.2670938 | M6: 42430 | N6: =HAVERM!C441 -> 5.166 | O6: =HAVERM!B441 -> 5 | Q6: 42430 | R6: =MIN(HAVERM!C440:C442) -> 4.728 | S6: =V6-R6 -> 0.438 | T6: =HAVERM!B441 -> 5 | V6: =MAX(HAVERM!C440:C442) -> 5.166 | X6: 43647 | Y6: =HAVERQ!E166-AVERAGE(HAVERQ!E$164:E$167) -> 13.25 | Z6: =HAVERQ!F166-AVERAGE(HAVERQ!F$164:F$167) -> -47.75 | AB6: 36708 | AC6: =HAVERQ!P90 -> 1213 | AD6: =HAVERQ!O90 -> 1455 | AE6: =HAVERQ!N90 -> 1177 | AF6: =HAVERQ!M90 -> 226 | AG6: =HAVERQ!L90 -> 216 | AH6: =HAVERQ!E90-AC6-AD6-AE6-AF6-AG6 -> 785 | AJ6: 36708 | AK6: =100*(AC6/SUM($AC6:$AH6)) -> 23.915615 | AL6: =100*(AD6/SUM($AC6:$AH6)) -> 28.686909 | AM6: =100*(AE6/SUM($AC6:$AH6)) -> 23.205836 | AN6: =100*(AF6/SUM($AC6:$AH6)) -> 4.455836 | AO6: =100*(AG6/SUM($AC6:$AH6)) -> 4.2586751 | AP6: =100*(AH6/SUM($AC6:$AH6)) -> 15.477129 | AR6: 43647 | AS6: =HAVERQ!T166-AVERAGE(HAVERQ!T$164:T$167) -> 4.75 | AT6: =HAVERQ!U166-AVERAGE(HAVERQ!U$164:U$167) -> -0.25 | AU6: =HAVERQ!V166-AVERAGE(HAVERQ!V$164:V$167) -> 3.25 | AV6: =HAVERQ!W166-AVERAGE(HAVERQ!W$164:W$167) -> -2.75 | AW6: =HAVERQ!X166-AVERAGE(HAVERQ!X$164:X$167) -> -2.5 | AX6: =HAVERQ!Y166-AVERAGE(HAVERQ!Y$164:Y$167) -> -25.25 | AY6: =HAVERQ!Z166-AVERAGE(HAVERQ!Z$164:Z$167) -> -4.5 | AZ6: =HAVERQ!AA166-AVERAGE(HAVERQ!AA$164:AA$167) -> 2 | ... BJ6: =HAVERQ!AK166-AVERAGE(HAVERQ!AK$164:AK$167) -> 2.25 | BK6: =BM6-AVERAGE(BM$4:BM$7) -> 1.5 | BM6: =HAVERQ!AL166+HAVERQ!AM166 -> 1019 | BO6: 43647 | BP6: =BZ6-AVERAGE(BZ$4:BZ$7) -> 4.75 | BQ6: =CA6-AVERAGE(CA$4:CA$7) -> -5.5 | BR6: =CB6-AVERAGE(CB$4:CB$7) -> 3.25 | BS6: =CC6-AVERAGE(CC$4:CC$7) -> -25.25 | BT6: =CD6-AVERAGE(CD$4:CD$7) -> 2.5 | BU6: =CE6-AVERAGE(CE$4:CE$7) -> 1.75 | BV6: =CF6-AVERAGE(CF$4:CF$7) -> 7.75 | BW6: =CG6-AVERAGE(CG$4:CG$7) -> 39.75 | BX6: =CH6-AVERAGE(CH$4:CH$7) -> 21.75 | BZ6: =HAVERQ!T166 -> 403 | CA6: =HAVERQ!U166+HAVERQ!W166+HAVERQ!X166 -> 420 | CB6: =HAVERQ!V166 -> 2694 | CC6: =HAVERQ!Y166 -> 2308 | CD6: =HAVERQ!Z166+HAVERQ!AB166 -> 7507 | CE6: =HAVERQ!AA166+HAVERQ!AC166 -> 3308 | CF6: =HAVERQ!AD166 -> 1143 | CG6: =HAVERQ!AE166+HAVERQ!AF166+HAVERQ!AG166 -> 6871 | CH6: =HAVERQ!AH166+HAVERQ!AI166+HAVERQ!AJ166+HAVERQ!AK166+HAVERQ!AL166+HAVERQ!AM166 -> 10962 | CI6: =HAVERQ!S166-SUM('Chart Data'!BZ6:CH6) -> -1 | CL6: =100*((DataQ!F165/DataQ!F161)-1) -> 0.63328293 | CM6: =100*(DataQ!I165/DataQ!J165) -> 22.746912 | CY6: =(HAVERQ!AQ130-AVERAGE(HAVERQ!AQ$128:AQ$183))/STDEV(HAVERQ!AQ$128:AQ$183) -> 1.3874688 | CZ6: =(DL6-AVERAGE(DL$5:DL$59))/STDEV(DL$5:DL$59) -> 1.2695637 | DA6: =(DO6-AVERAGE(DO$5:DO$59))/STDEV(DO$5:DO$59) -> 1.014221 | DB6: =(HAVERQ!AR130-AVERAGE(HAVERQ!AR$128:AR$183))/STDEV(HAVERQ!AR$128:AR$183) -> 0.63931361 | DC6: =(DM6-AVERAGE(DM$5:DM$59))/STDEV(DM$5:DM$59) -> -1.1583761 | DD6: =(DN6-AVERAGE(DN$29:DN$59))/STDEV(DN$29:DN$59) -> #N/A | DE6: =(HAVERQ!AZ130-AVERAGE(HAVERQ!AZ$128:AZ$167,AZ$174:AZ$183))/STDEV(HAVERQ!AZ$128:AZ$167,AZ$174:AZ$183) -> -1.5341612 | DF6: =(HAVERQ!AS130-AVERAGE(HAVERQ!AS$128:AS$183))/STDEV(HAVERQ!AS$128:AS$183) -> -1.3678689 | DG6: =(DP6-AVERAGE(DP$5:DP$59))/STDEV(DP$5:DP$59) -> -0.8528448 | DH6: =(HAVERQ!AX130-AVERAGE(HAVERQ!AX$128:AX$183))/STDEV(HAVERQ!AX$128:AX$183) -> -0.11880912 | DJ6: =(DR6-AVERAGE(DR$5:DR$59))/STDEV(DR$5:DR$59) -> -1.4090085 | DL6: =100*(HAVERQ!AV130/(HAVERQ!AW130*HAVERQ!AX130/100)) -> 2.582373 | DM6: =HAVERQ!AO130/HAVERQ!AP130 -> 0.19041835 | DN6: =100*((AVERAGE(HAVERQ!BC127:BC130)/AVERAGE(HAVERQ!BC123:BC126))-1) -> #N/A | DO6: =100*(HAVERQ!BE130+HAVERQ!BF130)/(HAVERQ!BB130+HAVERQ!BG130) -> 11.194475 | DP6: =100*((AVERAGE(HAVERQ!BA127:BA130)/AVERAGE(HAVERQ!BA123:BA126))-1) -> 1.3377278 | DR6: =(HAVERQ!AT130*HAVERQ!$AT$1)+(HAVERQ!AU130*HAVERQ!$AU$1) -> 48.632467 | DT6: 2019 | DU6: =-AVERAGE(CY$40:CY$44) -> 0.99949945 | DV6: =-AVERAGE(CZ$40:CZ$44) -> 0.9306432 | DW6: =-AVERAGE(DA$40:DA$44) -> 0.99695734 | DX6: =-AVERAGE(DB$40:DB$44) -> 0.42826309 | DY6: =AVERAGE(DC$40:DC$44) -> 0.62782346 | DZ6: =AVERAGE(DE$40:DE$44) -> -0.33258041 | EA6: =AVERAGE(DD$40:DD$44) -> -0.086403277 | EB6: =AVERAGE(DF$40:DF$44) -> 0.99568823 | EC6: =AVERAGE(DG$40:DG$44) -> 0.21155322 | ED6: =AVERAGE(DH$40:DH$44) -> 1.9981533 | EF6: =AVERAGE(DJ$40:DJ$44) -> 0.66405934
A7: 2017 | B7: =100*((DataA!G51-DataA!G50)/DataA!H50) -> 2.4443958 | C7: =D7-B7 -> 0.27841176 | D7: =100*((DataA!H51/DataA!H50)-1) -> 2.7228076 | F7: 2017 | G7: =B7-K7 -> 0.59145313 | H7: =I7-G7 -> 0.29775587 | I7: =100*((DataA!I51/DataA!I50)-1) -> 0.889209 | K7: =100*((DataA!J51/DataA!J50)-1) -> 1.8529427 | M7: 42461 | N7: =HAVERM!C442 -> 4.728 | O7: =HAVERM!B442 -> 4.9 | Q7: 42461 | R7: =MIN(HAVERM!C441:C443) -> 4.728 | S7: =V7-R7 -> 0.438 | T7: =HAVERM!B442 -> 4.9 | V7: =MAX(HAVERM!C441:C443) -> 5.166 | X7: 43739 | Y7: =HAVERQ!E167-AVERAGE(HAVERQ!E$164:E$167) -> 28.25 | Z7: =HAVERQ!F167-AVERAGE(HAVERQ!F$164:F$167) -> 135.25 | AB7: 36800 | AC7: =HAVERQ!P91 -> 1223 | AD7: =HAVERQ!O91 -> 1457 | AE7: =HAVERQ!N91 -> 1177 | AF7: =HAVERQ!M91 -> 227 | AG7: =HAVERQ!L91 -> 215 | AH7: =HAVERQ!E91-AC7-AD7-AE7-AF7-AG7 -> 782 | AJ7: 36800 | AK7: =100*(AC7/SUM($AC7:$AH7)) -> 24.070065 | AL7: =100*(AD7/SUM($AC7:$AH7)) -> 28.675458 | AM7: =100*(AE7/SUM($AC7:$AH7)) -> 23.164731 | AN7: =100*(AF7/SUM($AC7:$AH7)) -> 4.4676245 | AO7: =100*(AG7/SUM($AC7:$AH7)) -> 4.2314505 | AP7: =100*(AH7/SUM($AC7:$AH7)) -> 15.390671 | AR7: 43739 | AS7: =HAVERQ!T167-AVERAGE(HAVERQ!T$164:T$167) -> 6.75 | AT7: =HAVERQ!U167-AVERAGE(HAVERQ!U$164:U$167) -> 0.75 | AU7: =HAVERQ!V167-AVERAGE(HAVERQ!V$164:V$167) -> -15.75 | AV7: =HAVERQ!W167-AVERAGE(HAVERQ!W$164:W$167) -> 4.25 | AW7: =HAVERQ!X167-AVERAGE(HAVERQ!X$164:X$167) -> -3.5 | AX7: =HAVERQ!Y167-AVERAGE(HAVERQ!Y$164:Y$167) -> -8.25 | AY7: =HAVERQ!Z167-AVERAGE(HAVERQ!Z$164:Z$167) -> -34.5 | AZ7: =HAVERQ!AA167-AVERAGE(HAVERQ!AA$164:AA$167) -> 5 | ... BJ7: =HAVERQ!AK167-AVERAGE(HAVERQ!AK$164:AK$167) -> 13.25 | BK7: =BM7-AVERAGE(BM$4:BM$7) -> 16.5 | BM7: =HAVERQ!AL167+HAVERQ!AM167 -> 1034 | BO7: 43739 | BP7: =BZ7-AVERAGE(BZ$4:BZ$7) -> 6.75 | BQ7: =CA7-AVERAGE(CA$4:CA$7) -> 1.5 | BR7: =CB7-AVERAGE(CB$4:CB$7) -> -15.75 | BS7: =CC7-AVERAGE(CC$4:CC$7) -> -8.25 | BT7: =CD7-AVERAGE(CD$4:CD$7) -> -21.5 | BU7: =CE7-AVERAGE(CE$4:CE$7) -> 32.75 | BV7: =CF7-AVERAGE(CF$4:CF$7) -> -4.25 | BW7: =CG7-AVERAGE(CG$4:CG$7) -> 25.75 | BX7: =CH7-AVERAGE(CH$4:CH$7) -> 77.75 | BZ7: =HAVERQ!T167 -> 405 | CA7: =HAVERQ!U167+HAVERQ!W167+HAVERQ!X167 -> 427 | CB7: =HAVERQ!V167 -> 2675 | CC7: =HAVERQ!Y167 -> 2325 | CD7: =HAVERQ!Z167+HAVERQ!AB167 -> 7483 | CE7: =HAVERQ!AA167+HAVERQ!AC167 -> 3339 | CF7: =HAVERQ!AD167 -> 1131 | CG7: =HAVERQ!AE167+HAVERQ!AF167+HAVERQ!AG167 -> 6857 | CH7: =HAVERQ!AH167+HAVERQ!AI167+HAVERQ!AJ167+HAVERQ!AK167+HAVERQ!AL167+HAVERQ!AM167 -> 11018 | CI7: =HAVERQ!S167-SUM('Chart Data'!BZ7:CH7) -> 1 | CL7: =100*((DataQ!F166/DataQ!F162)-1) -> 1.2250741 | CM7: =100*(DataQ!I166/DataQ!J166) -> 22.658746 | CP7: 1 | CQ7: 2 | CR7: 3 | CS7: 4 | CT7: 5 | CU7: 6 | CY7: =(HAVERQ!AQ131-AVERAGE(HAVERQ!AQ$128:AQ$183))/STDEV(HAVERQ!AQ$128:AQ$183) -> 1.4483608 | CZ7: =(DL7-AVERAGE(DL$5:DL$59))/STDEV(DL$5:DL$59) -> 1.3354819 | DA7: =(DO7-AVERAGE(DO$5:DO$59))/STDEV(DO$5:DO$59) -> 1.0874051 | DB7: =(HAVERQ!AR131-AVERAGE(HAVERQ!AR$128:AR$183))/STDEV(HAVERQ!AR$128:AR$183) -> 0.69323162 | DC7: =(DM7-AVERAGE(DM$5:DM$59))/STDEV(DM$5:DM$59) -> -1.1470063 | DD7: =(DN7-AVERAGE(DN$29:DN$59))/STDEV(DN$29:DN$59) -> #N/A | DE7: =(HAVERQ!AZ131-AVERAGE(HAVERQ!AZ$128:AZ$167,AZ$174:AZ$183))/STDEV(HAVERQ!AZ$128:AZ$167,AZ$174:AZ$183) -> -0.67588921 | DF7: =(HAVERQ!AS131-AVERAGE(HAVERQ!AS$128:AS$183))/STDEV(HAVERQ!AS$128:AS$183) -> -1.157307 | DG7: =(DP7-AVERAGE(DP$5:DP$59))/STDEV(DP$5:DP$59) -> -0.58221745 | DH7: =(HAVERQ!AX131-AVERAGE(HAVERQ!AX$128:AX$183))/STDEV(HAVERQ!AX$128:AX$183) -> -0.72365552 | DJ7: =(DR7-AVERAGE(DR$5:DR$59))/STDEV(DR$5:DR$59) -> -1.3641422 | DL7: =100*(HAVERQ!AV131/(HAVERQ!AW131*HAVERQ!AX131/100)) -> 2.6317396 | DM7: =HAVERQ!AO131/HAVERQ!AP131 -> 0.19310161 | DN7: =100*((AVERAGE(HAVERQ!BC128:BC131)/AVERAGE(HAVERQ!BC124:BC127))-1) -> #N/A | DO7: =100*(HAVERQ!BE131+HAVERQ!BF131)/(HAVERQ!BB131+HAVERQ!BG131) -> 11.304867 | DP7: =100*((AVERAGE(HAVERQ!BA128:BA131)/AVERAGE(HAVERQ!BA124:BA127))-1) -> 1.863354 | DR7: =(HAVERQ!AT131*HAVERQ!$AT$1)+(HAVERQ!AU131*HAVERQ!$AU$1) -> 49.077737 | DT7: Post-2010 average | DU7: 0 | DV7: 0 | DW7: 0 | DX7: 0 | DY7: 0 | DZ7: 0 | EA7: 0 | EB7: 0 | EC7: 0 | ED7: 0 | EF7: 0
A8: 2018 | B8: =100*((DataA!G52-DataA!G51)/DataA!H51) -> 2.6151515 | C8: =D8-B8 -> 1.494945 | D8: =100*((DataA!H52/DataA!H51)-1) -> 4.1100965 | F8: 2018 | G8: =B8-K8 -> 0.51580887 | H8: =I8-G8 -> 1.4675349 | I8: =100*((DataA!I52/DataA!I51)-1) -> 1.9833437 | K8: =100*((DataA!J52/DataA!J51)-1) -> 2.0993427 | M8: 42491 | N8: =HAVERM!C443 -> 4.881 | O8: =HAVERM!B443 -> 4.9 | Q8: 42491 | R8: =MIN(HAVERM!C442:C444) -> 4.728 | S8: =V8-R8 -> 0.417 | T8: =HAVERM!B443 -> 4.9 | V8: =MAX(HAVERM!C442:C444) -> 5.145 | X8: 43831 | Y8: =HAVERQ!E168-AVERAGE(HAVERQ!E$164:E$167) -> 53.25 | Z8: =HAVERQ!F168-AVERAGE(HAVERQ!F$164:F$167) -> -172.75 | AB8: 36892 | AC8: =HAVERQ!P92 -> 1235 | AD8: =HAVERQ!O92 -> 1463 | AE8: =HAVERQ!N92 -> 1181 | AF8: =HAVERQ!M92 -> 228 | AG8: =HAVERQ!L92 -> 215 | AH8: =HAVERQ!E92-AC8-AD8-AE8-AF8-AG8 -> 785 | AJ8: 36892 | AK8: =100*(AC8/SUM($AC8:$AH8)) -> 24.182495 | AL8: =100*(AD8/SUM($AC8:$AH8)) -> 28.646955 | AM8: =100*(AE8/SUM($AC8:$AH8)) -> 23.125122 | AN8: =100*(AF8/SUM($AC8:$AH8)) -> 4.4644605 | AO8: =100*(AG8/SUM($AC8:$AH8)) -> 4.209908 | AP8: =100*(AH8/SUM($AC8:$AH8)) -> 15.371059 | AR8: 43831 | AS8: =HAVERQ!T168-AVERAGE(HAVERQ!T$164:T$167) -> -14.25 | AT8: =HAVERQ!U168-AVERAGE(HAVERQ!U$164:U$167) -> 6.75 | AU8: =HAVERQ!V168-AVERAGE(HAVERQ!V$164:V$167) -> -14.75 | AV8: =HAVERQ!W168-AVERAGE(HAVERQ!W$164:W$167) -> 5.25 | AW8: =HAVERQ!X168-AVERAGE(HAVERQ!X$164:X$167) -> -3.5 | AX8: =HAVERQ!Y168-AVERAGE(HAVERQ!Y$164:Y$167) -> -40.25 | AY8: =HAVERQ!Z168-AVERAGE(HAVERQ!Z$164:Z$167) -> -67.5 | AZ8: =HAVERQ!AA168-AVERAGE(HAVERQ!AA$164:AA$167) -> 1 | ... BJ8: =HAVERQ!AK168-AVERAGE(HAVERQ!AK$164:AK$167) -> -4.75 | BK8: =BM8-AVERAGE(BM$4:BM$7) -> -28.5 | BM8: =HAVERQ!AL168+HAVERQ!AM168 -> 989 | BO8: 43831 | BP8: =BZ8-AVERAGE(BZ$4:BZ$7) -> -14.25 | BQ8: =CA8-AVERAGE(CA$4:CA$7) -> 8.5 | BR8: =CB8-AVERAGE(CB$4:CB$7) -> -14.75 | BS8: =CC8-AVERAGE(CC$4:CC$7) -> -40.25 | BT8: =CD8-AVERAGE(CD$4:CD$7) -> -47.5 | BU8: =CE8-AVERAGE(CE$4:CE$7) -> 49.75 | BV8: =CF8-AVERAGE(CF$4:CF$7) -> 1.75 | BW8: =CG8-AVERAGE(CG$4:CG$7) -> 66.75 | BX8: =CH8-AVERAGE(CH$4:CH$7) -> 34.75 | BZ8: =HAVERQ!T168 -> 384 | CA8: =HAVERQ!U168+HAVERQ!W168+HAVERQ!X168 -> 434 | CB8: =HAVERQ!V168 -> 2676 | CC8: =HAVERQ!Y168 -> 2293 | CD8: =HAVERQ!Z168+HAVERQ!AB168 -> 7457 | CE8: =HAVERQ!AA168+HAVERQ!AC168 -> 3356 | CF8: =HAVERQ!AD168 -> 1137 | CG8: =HAVERQ!AE168+HAVERQ!AF168+HAVERQ!AG168 -> 6898 | CH8: =HAVERQ!AH168+HAVERQ!AI168+HAVERQ!AJ168+HAVERQ!AK168+HAVERQ!AL168+HAVERQ!AM168 -> 10975 | CI8: =HAVERQ!S168-SUM('Chart Data'!BZ8:CH8) -> -1 | CK8: 2013 | CL8: =100*((DataQ!F167/DataQ!F163)-1) -> 0.66949357 | CM8: =100*(DataQ!I167/DataQ!J167) -> 22.990853 | CP8: =HLOOKUP(CP$7,$CP$2:$CU$5,2,FALSE) -> Lower profit margins | CQ8: =HLOOKUP(CQ$7,$CP$2:$CU$5,2,FALSE) -> Higher prices | CR8: =HLOOKUP(CR$7,$CP$2:$CU$5,2,FALSE) -> Lower number of employees | CS8: =HLOOKUP(CS$7,$CP$2:$CU$5,2,FALSE) -> Lower employee wages | CT8: =HLOOKUP(CT$7,$CP$2:$CU$5,2,FALSE) -> Other | CU8: =HLOOKUP(CU$7,$CP$2:$CU$5,2,FALSE) -> None of the above | CX8: 2011 | CY8: =(HAVERQ!AQ132-AVERAGE(HAVERQ!AQ$128:AQ$183))/STDEV(HAVERQ!AQ$128:AQ$183) -> 1.3874688 | CZ8: =(DL8-AVERAGE(DL$5:DL$59))/STDEV(DL$5:DL$59) -> 1.415412 | DA8: =(DO8-AVERAGE(DO$5:DO$59))/STDEV(DO$5:DO$59) -> 1.0314069 | DB8: =(HAVERQ!AR132-AVERAGE(HAVERQ!AR$128:AR$183))/STDEV(HAVERQ!AR$128:AR$183) -> 0.15405147 | DC8: =(DM8-AVERAGE(DM$5:DM$59))/STDEV(DM$5:DM$59) -> -1.1819412 | DD8: =(DN8-AVERAGE(DN$29:DN$59))/STDEV(DN$29:DN$59) -> #N/A | DE8: =(HAVERQ!AZ132-AVERAGE(HAVERQ!AZ$128:AZ$167,AZ$174:AZ$183))/STDEV(HAVERQ!AZ$128:AZ$167,AZ$174:AZ$183) -> -1.1050252 | DF8: =(HAVERQ!AS132-AVERAGE(HAVERQ!AS$128:AS$183))/STDEV(HAVERQ!AS$128:AS$183) -> -0.96429195 | DG8: =(DP8-AVERAGE(DP$5:DP$59))/STDEV(DP$5:DP$59) -> -0.75025463 | DH8: =(HAVERQ!AX132-AVERAGE(HAVERQ!AX$128:AX$183))/STDEV(HAVERQ!AX$128:AX$183) -> -0.72365552 | DJ8: =(DR8-AVERAGE(DR$5:DR$59))/STDEV(DR$5:DR$59) -> -1.6810288 | DL8: =100*(HAVERQ!AV132/(HAVERQ!AW132*HAVERQ!AX132/100)) -> 2.6915999 | DM8: =HAVERQ!AO132/HAVERQ!AP132 -> 0.18485703 | DN8: =100*((AVERAGE(HAVERQ!BC129:BC132)/AVERAGE(HAVERQ!BC125:BC128))-1) -> #N/A | DO8: =100*(HAVERQ!BE132+HAVERQ!BF132)/(HAVERQ!BB132+HAVERQ!BG132) -> 11.220398 | DP8: =100*((AVERAGE(HAVERQ!BA129:BA132)/AVERAGE(HAVERQ!BA125:BA128))-1) -> 1.5369837 | DR8: =(HAVERQ!AT132*HAVERQ!$AT$1)+(HAVERQ!AU132*HAVERQ!$AU$1) -> 45.932838
A9: 2019 | B9: =100*((DataA!G53-DataA!G52)/DataA!H52) -> 2.1285774 | C9: =D9-B9 -> 1.4739322 | D9: =100*((DataA!H53/DataA!H52)-1) -> 3.6025096 | F9: 2019 | G9: =B9-K9 -> 0.64390525 | H9: =I9-G9 -> 1.409085 | I9: =100*((DataA!I53/DataA!I52)-1) -> 2.0529903 | K9: =100*((DataA!J53/DataA!J52)-1) -> 1.4846722 | M9: 42522 | N9: =HAVERM!C444 -> 5.145 | O9: =HAVERM!B444 -> 4.9 | Q9: 42522 | R9: =MIN(HAVERM!C443:C445) -> 4.657 | S9: =V9-R9 -> 0.488 | T9: =HAVERM!B444 -> 4.9 | V9: =MAX(HAVERM!C443:C445) -> 5.145 | X9: 43922 | Y9: =HAVERQ!E169-AVERAGE(HAVERQ!E$164:E$167) -> 97.25 | Z9: =HAVERQ!F169-AVERAGE(HAVERQ!F$164:F$167) -> -458.75 | AB9: 36982 | AC9: =HAVERQ!P93 -> 1249 | AD9: =HAVERQ!O93 -> 1468 | AE9: =HAVERQ!N93 -> 1185 | AF9: =HAVERQ!M93 -> 229 | AG9: =HAVERQ!L93 -> 214 | AH9: =HAVERQ!E93-AC9-AD9-AE9-AF9-AG9 -> 792 | AJ9: 36982 | AK9: =100*(AC9/SUM($AC9:$AH9)) -> 24.313802 | AL9: =100*(AD9/SUM($AC9:$AH9)) -> 28.57699 | AM9: =100*(AE9/SUM($AC9:$AH9)) -> 23.067938 | AN9: =100*(AF9/SUM($AC9:$AH9)) -> 4.4578548 | AO9: =100*(AG9/SUM($AC9:$AH9)) -> 4.1658556 | AP9: =100*(AH9/SUM($AC9:$AH9)) -> 15.417559 | AR9: 43922 | AS9: =HAVERQ!T169-AVERAGE(HAVERQ!T$164:T$167) -> -21.25 | AT9: =HAVERQ!U169-AVERAGE(HAVERQ!U$164:U$167) -> -0.25 | AU9: =HAVERQ!V169-AVERAGE(HAVERQ!V$164:V$167) -> -72.75 | AV9: =HAVERQ!W169-AVERAGE(HAVERQ!W$164:W$167) -> 4.25 | AW9: =HAVERQ!X169-AVERAGE(HAVERQ!X$164:X$167) -> -4.5 | AX9: =HAVERQ!Y169-AVERAGE(HAVERQ!Y$164:Y$167) -> -57.25 | AY9: =HAVERQ!Z169-AVERAGE(HAVERQ!Z$164:Z$167) -> -29.5 | AZ9: =HAVERQ!AA169-AVERAGE(HAVERQ!AA$164:AA$167) -> 1 | ... BJ9: =HAVERQ!AK169-AVERAGE(HAVERQ!AK$164:AK$167) -> -51.75 | BK9: =BM9-AVERAGE(BM$4:BM$7) -> -40.5 | BM9: =HAVERQ!AL169+HAVERQ!AM169 -> 977 | BO9: 43922 | BP9: =BZ9-AVERAGE(BZ$4:BZ$7) -> -21.25 | BQ9: =CA9-AVERAGE(CA$4:CA$7) -> -0.5 | BR9: =CB9-AVERAGE(CB$4:CB$7) -> -72.75 | BS9: =CC9-AVERAGE(CC$4:CC$7) -> -57.25 | BT9: =CD9-AVERAGE(CD$4:CD$7) -> -181.5 | BU9: =CE9-AVERAGE(CE$4:CE$7) -> 21.75 | BV9: =CF9-AVERAGE(CF$4:CF$7) -> -6.25 | BW9: =CG9-AVERAGE(CG$4:CG$7) -> -150.25 | BX9: =CH9-AVERAGE(CH$4:CH$7) -> 36.75 | BZ9: =HAVERQ!T169 -> 377 | CA9: =HAVERQ!U169+HAVERQ!W169+HAVERQ!X169 -> 425 | CB9: =HAVERQ!V169 -> 2618 | CC9: =HAVERQ!Y169 -> 2276 | CD9: =HAVERQ!Z169+HAVERQ!AB169 -> 7323 | CE9: =HAVERQ!AA169+HAVERQ!AC169 -> 3328 | CF9: =HAVERQ!AD169 -> 1129 | CG9: =HAVERQ!AE169+HAVERQ!AF169+HAVERQ!AG169 -> 6681 | CH9: =HAVERQ!AH169+HAVERQ!AI169+HAVERQ!AJ169+HAVERQ!AK169+HAVERQ!AL169+HAVERQ!AM169 -> 10977 | CI9: =HAVERQ!S169-SUM('Chart Data'!BZ9:CH9) -> 1 | CL9: =100*((DataQ!F168/DataQ!F164)-1) -> 2.583742 | CM9: =100*(DataQ!I168/DataQ!J168) -> 21.880591 | CO9: =CO4 -> 45597 | CP9: =HLOOKUP(CP$7,$CP$2:$CU$5,3,FALSE) -> 58.72 | CQ9: =HLOOKUP(CQ$7,$CP$2:$CU$5,3,FALSE) -> 53.64 | CR9: =HLOOKUP(CR$7,$CP$2:$CU$5,3,FALSE) -> 53.68 | CS9: =HLOOKUP(CS$7,$CP$2:$CU$5,3,FALSE) -> 37.88 | CT9: =HLOOKUP(CT$7,$CP$2:$CU$5,3,FALSE) -> 7.51 | CU9: =HLOOKUP(CU$7,$CP$2:$CU$5,3,FALSE) -> 2.67 | CY9: =(HAVERQ!AQ133-AVERAGE(HAVERQ!AQ$128:AQ$183))/STDEV(HAVERQ!AQ$128:AQ$183) -> 1.4483608 | CZ9: =(DL9-AVERAGE(DL$5:DL$59))/STDEV(DL$5:DL$59) -> 1.3530474 | DA9: =(DO9-AVERAGE(DO$5:DO$59))/STDEV(DO$5:DO$59) -> 1.0250466 | DB9: =(HAVERQ!AR133-AVERAGE(HAVERQ!AR$128:AR$183))/STDEV(HAVERQ!AR$128:AR$183) -> 0.85498567 | DC9: =(DM9-AVERAGE(DM$5:DM$59))/STDEV(DM$5:DM$59) -> -1.1850611 | DD9: =(DN9-AVERAGE(DN$29:DN$59))/STDEV(DN$29:DN$59) -> #N/A | DE9: =(HAVERQ!AZ133-AVERAGE(HAVERQ!AZ$128:AZ$167,AZ$174:AZ$183))/STDEV(HAVERQ!AZ$128:AZ$167,AZ$174:AZ$183) -> -2.8215693 | DF9: =(HAVERQ!AS133-AVERAGE(HAVERQ!AS$128:AS$183))/STDEV(HAVERQ!AS$128:AS$183) -> -0.85901101 | DG9: =(DP9-AVERAGE(DP$5:DP$59))/STDEV(DP$5:DP$59) -> -0.43393086 | DH9: =(HAVERQ!AX133-AVERAGE(HAVERQ!AX$128:AX$183))/STDEV(HAVERQ!AX$128:AX$183) -> -0.72365552 | DJ9: =(DR9-AVERAGE(DR$5:DR$59))/STDEV(DR$5:DR$59) -> -1.4795046 | DL9: =100*(HAVERQ!AV133/(HAVERQ!AW133*HAVERQ!AX133/100)) -> 2.6448946 | DM9: =HAVERQ!AO133/HAVERQ!AP133 -> 0.18412073 | DN9: =100*((AVERAGE(HAVERQ!BC130:BC133)/AVERAGE(HAVERQ!BC126:BC129))-1) -> #N/A | DO9: =100*(HAVERQ!BE133+HAVERQ!BF133)/(HAVERQ!BB133+HAVERQ!BG133) -> 11.210804 | DP9: =100*((AVERAGE(HAVERQ!BA130:BA133)/AVERAGE(HAVERQ!BA126:BA129))-1) -> 2.1513638 | DR9: =(HAVERQ!AT133*HAVERQ!$AT$1)+(HAVERQ!AU133*HAVERQ!$AU$1) -> 47.932838
A10: 2020 | B10: =100*((DataA!G54-DataA!G53)/DataA!H53) -> 0.0012388486 | C10: =D10-B10 -> 0.098281992 | D10: =100*((DataA!H54/DataA!H53)-1) -> 0.099520841 | F10: 2020 | G10: =B10-K10 -> -0.067846845 | H10: =I10-G10 -> -0.30916746 | I10: =100*((DataA!I54/DataA!I53)-1) -> -0.3770143 | K10: =100*((DataA!J54/DataA!J53)-1) -> 0.069085694 | M10: 42552 | N10: =HAVERM!C445 -> 4.657 | O10: =HAVERM!B445 -> 5 | Q10: 42552 | R10: =MIN(HAVERM!C444:C446) -> 4.657 | S10: =V10-R10 -> 0.488 | T10: =HAVERM!B445 -> 5 | V10: =MAX(HAVERM!C444:C446) -> 5.145 | X10: 44013 | Y10: =HAVERQ!E170-AVERAGE(HAVERQ!E$164:E$167) -> 104.25 | Z10: =HAVERQ!F170-AVERAGE(HAVERQ!F$164:F$167) -> -723.75 | AB10: 37073 | AC10: =HAVERQ!P94 -> 1263 | AD10: =HAVERQ!O94 -> 1465 | AE10: =HAVERQ!N94 -> 1188 | AF10: =HAVERQ!M94 -> 231 | AG10: =HAVERQ!L94 -> 214 | AH10: =HAVERQ!E94-AC10-AD10-AE10-AF10-AG10 -> 795 | AJ10: 37073 | AK10: =100*(AC10/SUM($AC10:$AH10)) -> 24.495733 | AL10: =100*(AD10/SUM($AC10:$AH10)) -> 28.413499 | AM10: =100*(AE10/SUM($AC10:$AH10)) -> 23.041117 | AN10: =100*(AF10/SUM($AC10:$AH10)) -> 4.4802172 | AO10: =100*(AG10/SUM($AC10:$AH10)) -> 4.1505043 | AP10: =100*(AH10/SUM($AC10:$AH10)) -> 15.418929 | AR10: 44013 | AS10: =HAVERQ!T170-AVERAGE(HAVERQ!T$164:T$167) -> 18.75 | AT10: =HAVERQ!U170-AVERAGE(HAVERQ!U$164:U$167) -> -7.25 | AU10: =HAVERQ!V170-AVERAGE(HAVERQ!V$164:V$167) -> -120.75 | AV10: =HAVERQ!W170-AVERAGE(HAVERQ!W$164:W$167) -> 1.25 | AW10: =HAVERQ!X170-AVERAGE(HAVERQ!X$164:X$167) -> 0.5 | AX10: =HAVERQ!Y170-AVERAGE(HAVERQ!Y$164:Y$167) -> -190.25 | AY10: =HAVERQ!Z170-AVERAGE(HAVERQ!Z$164:Z$167) -> -163.5 | AZ10: =HAVERQ!AA170-AVERAGE(HAVERQ!AA$164:AA$167) -> -16 | ... BJ10: =HAVERQ!AK170-AVERAGE(HAVERQ!AK$164:AK$167) -> -105.75 | BK10: =BM10-AVERAGE(BM$4:BM$7) -> -78.5 | BM10: =HAVERQ!AL170+HAVERQ!AM170 -> 939 | BO10: 44013 | BP10: =BZ10-AVERAGE(BZ$4:BZ$7) -> 18.75 | BQ10: =CA10-AVERAGE(CA$4:CA$7) -> -5.5 | BR10: =CB10-AVERAGE(CB$4:CB$7) -> -120.75 | BS10: =CC10-AVERAGE(CC$4:CC$7) -> -190.25 | BT10: =CD10-AVERAGE(CD$4:CD$7) -> -377.5 | BU10: =CE10-AVERAGE(CE$4:CE$7) -> -4.25 | BV10: =CF10-AVERAGE(CF$4:CF$7) -> -20.25 | BW10: =CG10-AVERAGE(CG$4:CG$7) -> -174.25 | BX10: =CH10-AVERAGE(CH$4:CH$7) -> -97.25 | BZ10: =HAVERQ!T170 -> 417 | CA10: =HAVERQ!U170+HAVERQ!W170+HAVERQ!X170 -> 420 | CB10: =HAVERQ!V170 -> 2570 | CC10: =HAVERQ!Y170 -> 2143 | CD10: =HAVERQ!Z170+HAVERQ!AB170 -> 7127 | CE10: =HAVERQ!AA170+HAVERQ!AC170 -> 3302 | CF10: =HAVERQ!AD170 -> 1115 | CG10: =HAVERQ!AE170+HAVERQ!AF170+HAVERQ!AG170 -> 6657 | CH10: =HAVERQ!AH170+HAVERQ!AI170+HAVERQ!AJ170+HAVERQ!AK170+HAVERQ!AL170+HAVERQ!AM170 -> 10843 | CI10: =HAVERQ!S170-SUM('Chart Data'!BZ10:CH10) -> 0 | CL10: =100*((DataQ!F169/DataQ!F165)-1) -> 2.7966777 | CM10: =100*(DataQ!I169/DataQ!J169) -> 22.178476 | CO10: =CO5 -> 45627 | CP10: =HLOOKUP(CP$7,$CP$2:$CU$5,4,FALSE) -> 63.5 | CQ10: =HLOOKUP(CQ$7,$CP$2:$CU$5,4,FALSE) -> 54.45 | CR10: =HLOOKUP(CR$7,$CP$2:$CU$5,4,FALSE) -> 52.76 | CS10: =HLOOKUP(CS$7,$CP$2:$CU$5,4,FALSE) -> 40.67 | CT10: =HLOOKUP(CT$7,$CP$2:$CU$5,4,FALSE) -> 7.33 | CU10: =HLOOKUP(CU$7,$CP$2:$CU$5,4,FALSE) -> 3.75 | CY10: =(HAVERQ!AQ134-AVERAGE(HAVERQ!AQ$128:AQ$183))/STDEV(HAVERQ!AQ$128:AQ$183) -> 1.691929 | CZ10: =(DL10-AVERAGE(DL$5:DL$59))/STDEV(DL$5:DL$59) -> 1.4915247 | DA10: =(DO10-AVERAGE(DO$5:DO$59))/STDEV(DO$5:DO$59) -> 0.98916196 | DB10: =(HAVERQ!AR134-AVERAGE(HAVERQ!AR$128:AR$183))/STDEV(HAVERQ!AR$128:AR$183) -> 0.69323162 | DC10: =(DM10-AVERAGE(DM$5:DM$59))/STDEV(DM$5:DM$59) -> -1.2046133 | DD10: =(DN10-AVERAGE(DN$29:DN$59))/STDEV(DN$29:DN$59) -> #N/A | DE10: =(HAVERQ!AZ134-AVERAGE(HAVERQ!AZ$128:AZ$167,AZ$174:AZ$183))/STDEV(HAVERQ!AZ$128:AZ$167,AZ$174:AZ$183) -> -1.1050252 | DF10: =(HAVERQ!AS134-AVERAGE(HAVERQ!AS$128:AS$183))/STDEV(HAVERQ!AS$128:AS$183) -> -0.84146419 | DG10: =(DP10-AVERAGE(DP$5:DP$59))/STDEV(DP$5:DP$59) -> -0.36943008 | DH10: =(HAVERQ!AX134-AVERAGE(HAVERQ!AX$128:AX$183))/STDEV(HAVERQ!AX$128:AX$183) -> -1.3285019 | DJ10: =(DR10-AVERAGE(DR$5:DR$59))/STDEV(DR$5:DR$59) -> -1.4022411 | DL10: =100*(HAVERQ!AV134/(HAVERQ!AW134*HAVERQ!AX134/100)) -> 2.7486013 | DM10: =HAVERQ!AO134/HAVERQ!AP134 -> 0.17950645 | DN10: =100*((AVERAGE(HAVERQ!BC131:BC134)/AVERAGE(HAVERQ!BC127:BC130))-1) -> #N/A | DO10: =100*(HAVERQ!BE134+HAVERQ!BF134)/(HAVERQ!BB134+HAVERQ!BG134) -> 11.156676 | DP10: =100*((AVERAGE(HAVERQ!BA131:BA134)/AVERAGE(HAVERQ!BA127:BA130))-1) -> 2.2766405 | DR10: =(HAVERQ!AT134*HAVERQ!$AT$1)+(HAVERQ!AU134*HAVERQ!$AU$1) -> 48.699629
A11: 2021 | B11: =100*((DataA!G55-DataA!G54)/DataA!H54) -> 3.8447946 | C11: =D11-B11 -> 0.29847196 | D11: =100*((DataA!H55/DataA!H54)-1) -> 4.1432665 | F11: 2021 | G11: =B11-K11 -> 1.1780466 | H11: =I11-G11 -> 0.41896108 | I11: =100*((DataA!I55/DataA!I54)-1) -> 1.5970077 | K11: =100*((DataA!J55/DataA!J54)-1) -> 2.666748 | M11: 42583 | N11: =HAVERM!C446 -> 5.106 | O11: =HAVERM!B446 -> 4.8 | Q11: 42583 | R11: =MIN(HAVERM!C445:C447) -> 4.657 | S11: =V11-R11 -> 0.449 | T11: =HAVERM!B446 -> 4.8 | V11: =MAX(HAVERM!C445:C447) -> 5.106 | X11: 44105 | Y11: =HAVERQ!E171-AVERAGE(HAVERQ!E$164:E$167) -> 134.25 | Z11: =HAVERQ!F171-AVERAGE(HAVERQ!F$164:F$167) -> -801.75 | AB11: 37165 | AC11: =HAVERQ!P95 -> 1278 | AD11: =HAVERQ!O95 -> 1467 | AE11: =HAVERQ!N95 -> 1197 | AF11: =HAVERQ!M95 -> 234 | AG11: =HAVERQ!L95 -> 214 | AH11: =HAVERQ!E95-AC11-AD11-AE11-AF11-AG11 -> 769 | AJ11: 37165 | AK11: =100*(AC11/SUM($AC11:$AH11)) -> 24.772243 | AL11: =100*(AD11/SUM($AC11:$AH11)) -> 28.435743 | AM11: =100*(AE11/SUM($AC11:$AH11)) -> 23.202171 | AN11: =100*(AF11/SUM($AC11:$AH11)) -> 4.5357627 | AO11: =100*(AG11/SUM($AC11:$AH11)) -> 4.1480907 | AP11: =100*(AH11/SUM($AC11:$AH11)) -> 14.90599 | AR11: 44105 | AS11: =HAVERQ!T171-AVERAGE(HAVERQ!T$164:T$167) -> -18.25 | AT11: =HAVERQ!U171-AVERAGE(HAVERQ!U$164:U$167) -> -8.25 | AU11: =HAVERQ!V171-AVERAGE(HAVERQ!V$164:V$167) -> -134.75 | AV11: =HAVERQ!W171-AVERAGE(HAVERQ!W$164:W$167) -> 4.25 | AW11: =HAVERQ!X171-AVERAGE(HAVERQ!X$164:X$167) -> 0.5 | AX11: =HAVERQ!Y171-AVERAGE(HAVERQ!Y$164:Y$167) -> -179.25 | AY11: =HAVERQ!Z171-AVERAGE(HAVERQ!Z$164:Z$167) -> -174.5 | AZ11: =HAVERQ!AA171-AVERAGE(HAVERQ!AA$164:AA$167) -> -47 | ... BJ11: =HAVERQ!AK171-AVERAGE(HAVERQ!AK$164:AK$167) -> -119.75 | BK11: =BM11-AVERAGE(BM$4:BM$7) -> -88.5 | BM11: =HAVERQ!AL171+HAVERQ!AM171 -> 929 | BO11: 44105 | BP11: =BZ11-AVERAGE(BZ$4:BZ$7) -> -18.25 | BQ11: =CA11-AVERAGE(CA$4:CA$7) -> -3.5 | BR11: =CB11-AVERAGE(CB$4:CB$7) -> -134.75 | BS11: =CC11-AVERAGE(CC$4:CC$7) -> -179.25 | BT11: =CD11-AVERAGE(CD$4:CD$7) -> -478.5 | BU11: =CE11-AVERAGE(CE$4:CE$7) -> -42.25 | BV11: =CF11-AVERAGE(CF$4:CF$7) -> 7.75 | BW11: =CG11-AVERAGE(CG$4:CG$7) -> -126.25 | BX11: =CH11-AVERAGE(CH$4:CH$7) -> -66.25 | BZ11: =HAVERQ!T171 -> 380 | CA11: =HAVERQ!U171+HAVERQ!W171+HAVERQ!X171 -> 422 | CB11: =HAVERQ!V171 -> 2556 | CC11: =HAVERQ!Y171 -> 2154 | CD11: =HAVERQ!Z171+HAVERQ!AB171 -> 7026 | CE11: =HAVERQ!AA171+HAVERQ!AC171 -> 3264 | CF11: =HAVERQ!AD171 -> 1143 | CG11: =HAVERQ!AE171+HAVERQ!AF171+HAVERQ!AG171 -> 6705 | CH11: =HAVERQ!AH171+HAVERQ!AI171+HAVERQ!AJ171+HAVERQ!AK171+HAVERQ!AL171+HAVERQ!AM171 -> 10874 | CI11: =HAVERQ!S171-SUM('Chart Data'!BZ11:CH11) -> -2 | CL11: =100*((DataQ!F170/DataQ!F166)-1) -> 2.2815277 | CM11: =100*(DataQ!I170/DataQ!J170) -> 22.016086 | CY11: =(HAVERQ!AQ135-AVERAGE(HAVERQ!AQ$128:AQ$183))/STDEV(HAVERQ!AQ$128:AQ$183) -> 1.7528211 | CZ11: =(DL11-AVERAGE(DL$5:DL$59))/STDEV(DL$5:DL$59) -> 1.4338152 | DA11: =(DO11-AVERAGE(DO$5:DO$59))/STDEV(DO$5:DO$59) -> 1.1824207 | DB11: =(HAVERQ!AR135-AVERAGE(HAVERQ!AR$128:AR$183))/STDEV(HAVERQ!AR$128:AR$183) -> 1.0706577 | DC11: =(DM11-AVERAGE(DM$5:DM$59))/STDEV(DM$5:DM$59) -> -1.2285428 | DD11: =(DN11-AVERAGE(DN$29:DN$59))/STDEV(DN$29:DN$59) -> #N/A | DE11: =(HAVERQ!AZ135-AVERAGE(HAVERQ!AZ$128:AZ$167,AZ$174:AZ$183))/STDEV(HAVERQ!AZ$128:AZ$167,AZ$174:AZ$183) -> -1.5341612 | DF11: =(HAVERQ!AS135-AVERAGE(HAVERQ!AS$128:AS$183))/STDEV(HAVERQ!AS$128:AS$183) -> -1.0169324 | DG11: =(DP11-AVERAGE(DP$5:DP$59))/STDEV(DP$5:DP$59) -> -0.29563478 | DH11: =(HAVERQ!AX135-AVERAGE(HAVERQ!AX$128:AX$183))/STDEV(HAVERQ!AX$128:AX$183) -> -1.0260787 | DJ11: =(DR11-AVERAGE(DR$5:DR$59))/STDEV(DR$5:DR$59) -> -0.72040489 | DL11: =100*(HAVERQ!AV135/(HAVERQ!AW135*HAVERQ!AX135/100)) -> 2.7053822 | DM11: =HAVERQ!AO135/HAVERQ!AP135 -> 0.17385913 | DN11: =100*((AVERAGE(HAVERQ!BC132:BC135)/AVERAGE(HAVERQ!BC128:BC131))-1) -> #N/A | DO11: =100*(HAVERQ!BE135+HAVERQ!BF135)/(HAVERQ!BB135+HAVERQ!BG135) -> 11.44819 | DP11: =100*((AVERAGE(HAVERQ!BA132:BA135)/AVERAGE(HAVERQ!BA128:BA131))-1) -> 2.4199695 | DR11: =(HAVERQ!AT135*HAVERQ!$AT$1)+(HAVERQ!AU135*HAVERQ!$AU$1) -> 55.466419 | DT11: Table 1: Most labor market variables continue to move in a looser direction
A12: 2022 | B12: =100*((DataA!G56-DataA!G55)/DataA!H55) -> 4.5968489 | C12: =D12-B12 -> 1.6454431 | D12: =100*((DataA!H56/DataA!H55)-1) -> 6.242292 | F12: 2022 | G12: =B12-K12 -> -3.898532 | H12: =I12-G12 -> 2.148227 | I12: =100*((DataA!I56/DataA!I55)-1) -> -1.750305 | K12: =100*((DataA!J56/DataA!J55)-1) -> 8.4953809 | M12: 42614 | N12: =HAVERM!C447 -> 4.736 | O12: =HAVERM!B447 -> 4.8 | Q12: 42614 | R12: =MIN(HAVERM!C446:C448) -> 4.659 | S12: =V12-R12 -> 0.447 | T12: =HAVERM!B447 -> 4.8 | V12: =MAX(HAVERM!C446:C448) -> 5.106 | X12: 44197 | Y12: =HAVERQ!E172-AVERAGE(HAVERQ!E$164:E$167) -> 214.25 | Z12: =HAVERQ!F172-AVERAGE(HAVERQ!F$164:F$167) -> -840.75 | AB12: 37257 | AC12: =HAVERQ!P96 -> 1292 | AD12: =HAVERQ!O96 -> 1471 | AE12: =HAVERQ!N96 -> 1204 | AF12: =HAVERQ!M96 -> 236 | AG12: =HAVERQ!L96 -> 214 | AH12: =HAVERQ!E96-AC12-AD12-AE12-AF12-AG12 -> 782 | AJ12: 37257 | AK12: =100*(AC12/SUM($AC12:$AH12)) -> 24.850933 | AL12: =100*(AD12/SUM($AC12:$AH12)) -> 28.293903 | AM12: =100*(AE12/SUM($AC12:$AH12)) -> 23.1583 | AN12: =100*(AF12/SUM($AC12:$AH12)) -> 4.5393345 | AO12: =100*(AG12/SUM($AC12:$AH12)) -> 4.1161762 | AP12: =100*(AH12/SUM($AC12:$AH12)) -> 15.041354 | AR12: 44197 | AS12: =HAVERQ!T172-AVERAGE(HAVERQ!T$164:T$167) -> -23.25 | AT12: =HAVERQ!U172-AVERAGE(HAVERQ!U$164:U$167) -> -8.25 | AU12: =HAVERQ!V172-AVERAGE(HAVERQ!V$164:V$167) -> -153.75 | AV12: =HAVERQ!W172-AVERAGE(HAVERQ!W$164:W$167) -> 3.25 | AW12: =HAVERQ!X172-AVERAGE(HAVERQ!X$164:X$167) -> -4.5 | AX12: =HAVERQ!Y172-AVERAGE(HAVERQ!Y$164:Y$167) -> -162.25 | AY12: =HAVERQ!Z172-AVERAGE(HAVERQ!Z$164:Z$167) -> -196.5 | AZ12: =HAVERQ!AA172-AVERAGE(HAVERQ!AA$164:AA$167) -> 24 | ... BJ12: =HAVERQ!AK172-AVERAGE(HAVERQ!AK$164:AK$167) -> -142.75 | BK12: =BM12-AVERAGE(BM$4:BM$7) -> -60.5 | BM12: =HAVERQ!AL172+HAVERQ!AM172 -> 957 | BO12: 44197 | BP12: =BZ12-AVERAGE(BZ$4:BZ$7) -> -23.25 | BQ12: =CA12-AVERAGE(CA$4:CA$7) -> -9.5 | BR12: =CB12-AVERAGE(CB$4:CB$7) -> -153.75 | BS12: =CC12-AVERAGE(CC$4:CC$7) -> -162.25 | BT12: =CD12-AVERAGE(CD$4:CD$7) -> -460.5 | BU12: =CE12-AVERAGE(CE$4:CE$7) -> 35.75 | BV12: =CF12-AVERAGE(CF$4:CF$7) -> 19.75 | BW12: =CG12-AVERAGE(CG$4:CG$7) -> -100.25 | BX12: =CH12-AVERAGE(CH$4:CH$7) -> 23.75 | BZ12: =HAVERQ!T172 -> 375 | CA12: =HAVERQ!U172+HAVERQ!W172+HAVERQ!X172 -> 416 | CB12: =HAVERQ!V172 -> 2537 | CC12: =HAVERQ!Y172 -> 2171 | CD12: =HAVERQ!Z172+HAVERQ!AB172 -> 7044 | CE12: =HAVERQ!AA172+HAVERQ!AC172 -> 3342 | CF12: =HAVERQ!AD172 -> 1155 | CG12: =HAVERQ!AE172+HAVERQ!AF172+HAVERQ!AG172 -> 6731 | CH12: =HAVERQ!AH172+HAVERQ!AI172+HAVERQ!AJ172+HAVERQ!AK172+HAVERQ!AL172+HAVERQ!AM172 -> 10964 | CI12: =HAVERQ!S172-SUM('Chart Data'!BZ12:CH12) -> -1 | CK12: 2014 | CL12: =100*((DataQ!F171/DataQ!F167)-1) -> 2.457354 | CM12: =100*(DataQ!I171/DataQ!J171) -> 21.695584 | CX12: 2012 | CY12: =(HAVERQ!AQ136-AVERAGE(HAVERQ!AQ$128:AQ$183))/STDEV(HAVERQ!AQ$128:AQ$183) -> 1.631037 | CZ12: =(DL12-AVERAGE(DL$5:DL$59))/STDEV(DL$5:DL$59) -> 1.5109721 | DA12: =(DO12-AVERAGE(DO$5:DO$59))/STDEV(DO$5:DO$59) -> 1.4091393 | DB12: =(HAVERQ!AR136-AVERAGE(HAVERQ!AR$128:AR$183))/STDEV(HAVERQ!AR$128:AR$183) -> 1.2324118 | DC12: =(DM12-AVERAGE(DM$5:DM$59))/STDEV(DM$5:DM$59) -> -1.2507048 | DD12: =(DN12-AVERAGE(DN$29:DN$59))/STDEV(DN$29:DN$59) -> #N/A | DE12: =(HAVERQ!AZ136-AVERAGE(HAVERQ!AZ$128:AZ$167,AZ$174:AZ$183))/STDEV(HAVERQ!AZ$128:AZ$167,AZ$174:AZ$183) -> -1.1050252 | DF12: =(HAVERQ!AS136-AVERAGE(HAVERQ!AS$128:AS$183))/STDEV(HAVERQ!AS$128:AS$183) -> -1.0695729 | DG12: =(DP12-AVERAGE(DP$5:DP$59))/STDEV(DP$5:DP$59) -> -0.60636075 | DH12: =(HAVERQ!AX136-AVERAGE(HAVERQ!AX$128:AX$183))/STDEV(HAVERQ!AX$128:AX$183) -> -1.0260787 | DJ12: =(DR12-AVERAGE(DR$5:DR$59))/STDEV(DR$5:DR$59) -> -1.114555 | DL12: =100*(HAVERQ!AV136/(HAVERQ!AW136*HAVERQ!AX136/100)) -> 2.7631656 | DM12: =HAVERQ!AO136/HAVERQ!AP136 -> 0.16862894 | DN12: =100*((AVERAGE(HAVERQ!BC133:BC136)/AVERAGE(HAVERQ!BC129:BC132))-1) -> #N/A | DO12: =100*(HAVERQ!BE136+HAVERQ!BF136)/(HAVERQ!BB136+HAVERQ!BG136) -> 11.790175 | DP12: =100*((AVERAGE(HAVERQ!BA133:BA136)/AVERAGE(HAVERQ!BA129:BA132))-1) -> 1.8164617 | DR12: =(HAVERQ!AT136*HAVERQ!$AT$1)+(HAVERQ!AU136*HAVERQ!$AU$1) -> 51.554731 | DU12: April indicators versus: | DV12: 45352 | DX12: 2019 | DY12: Data source
A13: 2023 | B13: =100*((DataA!G57-DataA!G56)/DataA!H56) -> 5.4343165 | C13: =D13-B13 -> 3.6829069 | D13: =100*((DataA!H57/DataA!H56)-1) -> 9.1172234 | F13: 2023 | G13: =B13-K13 -> -1.4588863 | H13: =I13-G13 -> 3.5919099 | I13: =100*((DataA!I57/DataA!I56)-1) -> 2.1330236 | K13: =100*((DataA!J57/DataA!J56)-1) -> 6.8932028 | M13: 42644 | N13: =HAVERM!C448 -> 4.659 | O13: =HAVERM!B448 -> 4.8 | Q13: 42644 | R13: =MIN(HAVERM!C447:C449) -> 4.659 | S13: =V13-R13 -> 0.293 | T13: =HAVERM!B448 -> 4.8 | V13: =MAX(HAVERM!C447:C449) -> 4.952 | X13: 44287 | Y13: =HAVERQ!E173-AVERAGE(HAVERQ!E$164:E$167) -> 225.25 | Z13: =HAVERQ!F173-AVERAGE(HAVERQ!F$164:F$167) -> -639.75 | AB13: 37347 | AC13: =HAVERQ!P97 -> 1309 | AD13: =HAVERQ!O97 -> 1473 | AE13: =HAVERQ!N97 -> 1212 | AF13: =HAVERQ!M97 -> 238 | AG13: =HAVERQ!L97 -> 214 | AH13: =HAVERQ!E97-AC13-AD13-AE13-AF13-AG13 -> 780 | AJ13: 37347 | AK13: =100*(AC13/SUM($AC13:$AH13)) -> 25.047838 | AL13: =100*(AD13/SUM($AC13:$AH13)) -> 28.185993 | AM13: =100*(AE13/SUM($AC13:$AH13)) -> 23.191734 | AN13: =100*(AF13/SUM($AC13:$AH13)) -> 4.5541523 | AO13: =100*(AG13/SUM($AC13:$AH13)) -> 4.0949101 | AP13: =100*(AH13/SUM($AC13:$AH13)) -> 14.925373 | AR13: 44287 | AS13: =HAVERQ!T173-AVERAGE(HAVERQ!T$164:T$167) -> -24.25 | AT13: =HAVERQ!U173-AVERAGE(HAVERQ!U$164:U$167) -> -7.25 | AU13: =HAVERQ!V173-AVERAGE(HAVERQ!V$164:V$167) -> -146.75 | AV13: =HAVERQ!W173-AVERAGE(HAVERQ!W$164:W$167) -> 5.25 | AW13: =HAVERQ!X173-AVERAGE(HAVERQ!X$164:X$167) -> 7.5 | AX13: =HAVERQ!Y173-AVERAGE(HAVERQ!Y$164:Y$167) -> -92.25 | AY13: =HAVERQ!Z173-AVERAGE(HAVERQ!Z$164:Z$167) -> -234.5 | AZ13: =HAVERQ!AA173-AVERAGE(HAVERQ!AA$164:AA$167) -> 10 | ... BJ13: =HAVERQ!AK173-AVERAGE(HAVERQ!AK$164:AK$167) -> -77.75 | BK13: =BM13-AVERAGE(BM$4:BM$7) -> -36.5 | BM13: =HAVERQ!AL173+HAVERQ!AM173 -> 981 | BO13: 44287 | BP13: =BZ13-AVERAGE(BZ$4:BZ$7) -> -24.25 | BQ13: =CA13-AVERAGE(CA$4:CA$7) -> 5.5 | BR13: =CB13-AVERAGE(CB$4:CB$7) -> -146.75 | BS13: =CC13-AVERAGE(CC$4:CC$7) -> -92.25 | BT13: =CD13-AVERAGE(CD$4:CD$7) -> -363.5 | BU13: =CE13-AVERAGE(CE$4:CE$7) -> -0.25 | BV13: =CF13-AVERAGE(CF$4:CF$7) -> 26.75 | BW13: =CG13-AVERAGE(CG$4:CG$7) -> -36.25 | BX13: =CH13-AVERAGE(CH$4:CH$7) -> 137.75 | BZ13: =HAVERQ!T173 -> 374 | CA13: =HAVERQ!U173+HAVERQ!W173+HAVERQ!X173 -> 431 | CB13: =HAVERQ!V173 -> 2544 | CC13: =HAVERQ!Y173 -> 2241 | CD13: =HAVERQ!Z173+HAVERQ!AB173 -> 7141 | CE13: =HAVERQ!AA173+HAVERQ!AC173 -> 3306 | CF13: =HAVERQ!AD173 -> 1162 | CG13: =HAVERQ!AE173+HAVERQ!AF173+HAVERQ!AG173 -> 6795 | CH13: =HAVERQ!AH173+HAVERQ!AI173+HAVERQ!AJ173+HAVERQ!AK173+HAVERQ!AL173+HAVERQ!AM173 -> 11078 | CI13: =HAVERQ!S173-SUM('Chart Data'!BZ13:CH13) -> 0 | CL13: =100*((DataQ!F172/DataQ!F168)-1) -> -1.5163896 | CM13: =100*(DataQ!I172/DataQ!J172) -> 22.422755 | CY13: =(HAVERQ!AQ137-AVERAGE(HAVERQ!AQ$128:AQ$183))/STDEV(HAVERQ!AQ$128:AQ$183) -> 1.5092529 | CZ13: =(DL13-AVERAGE(DL$5:DL$59))/STDEV(DL$5:DL$59) -> 1.4973913 | DA13: =(DO13-AVERAGE(DO$5:DO$59))/STDEV(DO$5:DO$59) -> 1.4934211 | DB13: =(HAVERQ!AR137-AVERAGE(HAVERQ!AR$128:AR$183))/STDEV(HAVERQ!AR$128:AR$183) -> 0.74714964 | DC13: =(DM13-AVERAGE(DM$5:DM$59))/STDEV(DM$5:DM$59) -> -1.1715306 | DD13: =(DN13-AVERAGE(DN$29:DN$59))/STDEV(DN$29:DN$59) -> #N/A | DE13: =(HAVERQ!AZ137-AVERAGE(HAVERQ!AZ$128:AZ$167,AZ$174:AZ$183))/STDEV(HAVERQ!AZ$128:AZ$167,AZ$174:AZ$183) -> -1.1050252 | DF13: =(HAVERQ!AS137-AVERAGE(HAVERQ!AS$128:AS$183))/STDEV(HAVERQ!AS$128:AS$183) -> -1.1046665 | DG13: =(DP13-AVERAGE(DP$5:DP$59))/STDEV(DP$5:DP$59) -> -0.68961686 | DH13: =(HAVERQ!AX137-AVERAGE(HAVERQ!AX$128:AX$183))/STDEV(HAVERQ!AX$128:AX$183) -> -0.42123232 | DJ13: =(DR13-AVERAGE(DR$5:DR$59))/STDEV(DR$5:DR$59) -> -1.5792011 | DL13: =100*(HAVERQ!AV137/(HAVERQ!AW137*HAVERQ!AX137/100)) -> 2.7529949 | DM13: =HAVERQ!AO137/HAVERQ!AP137 -> 0.18731392 | DN13: =100*((AVERAGE(HAVERQ!BC134:BC137)/AVERAGE(HAVERQ!BC130:BC133))-1) -> #N/A | DO13: =100*(HAVERQ!BE137+HAVERQ!BF137)/(HAVERQ!BB137+HAVERQ!BG137) -> 11.917307 | DP13: =100*((AVERAGE(HAVERQ!BA134:BA137)/AVERAGE(HAVERQ!BA130:BA133))-1) -> 1.6547574 | DR13: =(HAVERQ!AT137*HAVERQ!$AT$1)+(HAVERQ!AU137*HAVERQ!$AU$1) -> 46.943413 | DT13: Unemployment | DU13: U3 unemployment rate. | DV13: looser | DX13: looser | DY13: April household survey
A14: 2024 | B14: =100*((DataA!G58-DataA!G57)/DataA!H57) -> 3.3538561 | C14: =D14-B14 -> 3.2079907 | D14: =100*((DataA!H58/DataA!H57)-1) -> 6.5618469 | F14: 2024 | G14: =B14-K14 -> 0.8069626 | H14: =I14-G14 -> 3.0342877 | I14: =100*((DataA!I58/DataA!I57)-1) -> 3.8412503 | K14: =100*((DataA!J58/DataA!J57)-1) -> 2.5468935 | M14: 42675 | N14: =HAVERM!C449 -> 4.952 | O14: =HAVERM!B449 -> 4.7 | Q14: 42675 | R14: =MIN(HAVERM!C448:C450) -> 4.594 | S14: =V14-R14 -> 0.358 | T14: =HAVERM!B449 -> 4.7 | V14: =MAX(HAVERM!C448:C450) -> 4.952 | X14: 44378 | Y14: =HAVERQ!E174-AVERAGE(HAVERQ!E$164:E$167) -> 242.25 | Z14: =HAVERQ!F174-AVERAGE(HAVERQ!F$164:F$167) -> -491.75 | AB14: 37438 | AC14: =HAVERQ!P98 -> 1325 | AD14: =HAVERQ!O98 -> 1500 | AE14: =HAVERQ!N98 -> 1215 | AF14: =HAVERQ!M98 -> 240 | AG14: =HAVERQ!L98 -> 215 | AH14: =HAVERQ!E98-AC14-AD14-AE14-AF14-AG14 -> 767 | AJ14: 37438 | AK14: =100*(AC14/SUM($AC14:$AH14)) -> 25.18054 | AL14: =100*(AD14/SUM($AC14:$AH14)) -> 28.506271 | AM14: =100*(AE14/SUM($AC14:$AH14)) -> 23.09008 | AN14: =100*(AF14/SUM($AC14:$AH14)) -> 4.5610034 | AO14: =100*(AG14/SUM($AC14:$AH14)) -> 4.0858989 | AP14: =100*(AH14/SUM($AC14:$AH14)) -> 14.576207 | AR14: 44378 | AS14: =HAVERQ!T174-AVERAGE(HAVERQ!T$164:T$167) -> -31.25 | AT14: =HAVERQ!U174-AVERAGE(HAVERQ!U$164:U$167) -> -9.25 | AU14: =HAVERQ!V174-AVERAGE(HAVERQ!V$164:V$167) -> -153.75 | AV14: =HAVERQ!W174-AVERAGE(HAVERQ!W$164:W$167) -> 4.25 | AW14: =HAVERQ!X174-AVERAGE(HAVERQ!X$164:X$167) -> 12.5 | AX14: =HAVERQ!Y174-AVERAGE(HAVERQ!Y$164:Y$167) -> -108.25 | AY14: =HAVERQ!Z174-AVERAGE(HAVERQ!Z$164:Z$167) -> -182.5 | AZ14: =HAVERQ!AA174-AVERAGE(HAVERQ!AA$164:AA$167) -> 16 | ... BJ14: =HAVERQ!AK174-AVERAGE(HAVERQ!AK$164:AK$167) -> -58.75 | BK14: =BM14-AVERAGE(BM$4:BM$7) -> -34.5 | BM14: =HAVERQ!AL174+HAVERQ!AM174 -> 983 | BO14: 44378 | BP14: =BZ14-AVERAGE(BZ$4:BZ$7) -> -31.25 | BQ14: =CA14-AVERAGE(CA$4:CA$7) -> 7.5 | BR14: =CB14-AVERAGE(CB$4:CB$7) -> -153.75 | BS14: =CC14-AVERAGE(CC$4:CC$7) -> -108.25 | BT14: =CD14-AVERAGE(CD$4:CD$7) -> -217.5 | BU14: =CE14-AVERAGE(CE$4:CE$7) -> 43.75 | BV14: =CF14-AVERAGE(CF$4:CF$7) -> 25.75 | BW14: =CG14-AVERAGE(CG$4:CG$7) -> -22.25 | BX14: =CH14-AVERAGE(CH$4:CH$7) -> 175.75 | BZ14: =HAVERQ!T174 -> 367 | CA14: =HAVERQ!U174+HAVERQ!W174+HAVERQ!X174 -> 433 | CB14: =HAVERQ!V174 -> 2537 | CC14: =HAVERQ!Y174 -> 2225 | CD14: =HAVERQ!Z174+HAVERQ!AB174 -> 7287 | CE14: =HAVERQ!AA174+HAVERQ!AC174 -> 3350 | CF14: =HAVERQ!AD174 -> 1161 | CG14: =HAVERQ!AE174+HAVERQ!AF174+HAVERQ!AG174 -> 6809 | CH14: =HAVERQ!AH174+HAVERQ!AI174+HAVERQ!AJ174+HAVERQ!AK174+HAVERQ!AL174+HAVERQ!AM174 -> 11116 | CI14: =HAVERQ!S174-SUM('Chart Data'!BZ14:CH14) -> 1 | CL14: =100*((DataQ!F173/DataQ!F169)-1) -> -1.8918891 | CM14: =100*(DataQ!I173/DataQ!J173) -> 23.797129 | CY14: =(HAVERQ!AQ138-AVERAGE(HAVERQ!AQ$128:AQ$183))/STDEV(HAVERQ!AQ$128:AQ$183) -> 1.3874688 | CZ14: =(DL14-AVERAGE(DL$5:DL$59))/STDEV(DL$5:DL$59) -> 1.5489093 | DA14: =(DO14-AVERAGE(DO$5:DO$59))/STDEV(DO$5:DO$59) -> 1.3390521 | DB14: =(HAVERQ!AR138-AVERAGE(HAVERQ!AR$128:AR$183))/STDEV(HAVERQ!AR$128:AR$183) -> 0.2618875 | DC14: =(DM14-AVERAGE(DM$5:DM$59))/STDEV(DM$5:DM$59) -> -1.128465 | DD14: =(DN14-AVERAGE(DN$29:DN$59))/STDEV(DN$29:DN$59) -> #N/A | DE14: =(HAVERQ!AZ138-AVERAGE(HAVERQ!AZ$128:AZ$167,AZ$174:AZ$183))/STDEV(HAVERQ!AZ$128:AZ$167,AZ$174:AZ$183) -> 0.1823828 | DF14: =(HAVERQ!AS138-AVERAGE(HAVERQ!AS$128:AS$183))/STDEV(HAVERQ!AS$128:AS$183) -> -0.87655783 | DG14: =(DP14-AVERAGE(DP$5:DP$59))/STDEV(DP$5:DP$59) -> -0.74223352 | DH14: =(HAVERQ!AX138-AVERAGE(HAVERQ!AX$128:AX$183))/STDEV(HAVERQ!AX$128:AX$183) -> -0.42123232 | DJ14: =(DR14-AVERAGE(DR$5:DR$59))/STDEV(DR$5:DR$59) -> -0.9521952 | DL14: =100*(HAVERQ!AV138/(HAVERQ!AW138*HAVERQ!AX138/100)) -> 2.7915771 | DM14: =HAVERQ!AO138/HAVERQ!AP138 -> 0.19747734 | DN14: =100*((AVERAGE(HAVERQ!BC135:BC138)/AVERAGE(HAVERQ!BC131:BC134))-1) -> #N/A | DO14: =100*(HAVERQ!BE138+HAVERQ!BF138)/(HAVERQ!BB138+HAVERQ!BG138) -> 11.684455 | DP14: =100*((AVERAGE(HAVERQ!BA135:BA138)/AVERAGE(HAVERQ!BA131:BA134))-1) -> 1.5525627 | DR14: =(HAVERQ!AT138*HAVERQ!$AT$1)+(HAVERQ!AU138*HAVERQ!$AU$1) -> 53.166048 | DU14: U6 unemployment rate | DV14: looser | DX14: looser | DY14: April household survey
A15: 2025 | B15: =100*((DataA!G59-DataA!G58)/DataA!H58) -> 2.8757414 | C15: =D15-B15 -> 1.0558234 | D15: =100*((DataA!H59/DataA!H58)-1) -> 3.9315649 | F15: 2025 | G15: =B15-K15 -> 0.10644856 | H15: =I15-G15 -> 1.020778 | I15: =100*((DataA!I59/DataA!I58)-1) -> 1.1272265 | K15: =100*((DataA!J59/DataA!J58)-1) -> 2.7692929 | M15: 42705 | N15: =HAVERM!C450 -> 4.594 | O15: =HAVERM!B450 -> 4.7 | Q15: 42705 | R15: =MIN(HAVERM!C449:C451) -> 4.593 | S15: =V15-R15 -> 0.359 | T15: =HAVERM!B450 -> 4.7 | V15: =MAX(HAVERM!C449:C451) -> 4.952 | X15: 44470 | Y15: =HAVERQ!E175-AVERAGE(HAVERQ!E$164:E$167) -> 261.25 | Z15: =HAVERQ!F175-AVERAGE(HAVERQ!F$164:F$167) -> -460.75 | AB15: 37530 | AC15: =HAVERQ!P99 -> 1341 | AD15: =HAVERQ!O99 -> 1510 | AE15: =HAVERQ!N99 -> 1236 | AF15: =HAVERQ!M99 -> 242 | AG15: =HAVERQ!L99 -> 215 | AH15: =HAVERQ!E99-AC15-AD15-AE15-AF15-AG15 -> 781 | AJ15: 37530 | AK15: =100*(AC15/SUM($AC15:$AH15)) -> 25.183099 | AL15: =100*(AD15/SUM($AC15:$AH15)) -> 28.356808 | AM15: =100*(AE15/SUM($AC15:$AH15)) -> 23.211268 | AN15: =100*(AF15/SUM($AC15:$AH15)) -> 4.5446009 | AO15: =100*(AG15/SUM($AC15:$AH15)) -> 4.0375587 | AP15: =100*(AH15/SUM($AC15:$AH15)) -> 14.666667 | AR15: 44470 | AS15: =HAVERQ!T175-AVERAGE(HAVERQ!T$164:T$167) -> -50.25 | AT15: =HAVERQ!U175-AVERAGE(HAVERQ!U$164:U$167) -> -10.25 | AU15: =HAVERQ!V175-AVERAGE(HAVERQ!V$164:V$167) -> -137.75 | AV15: =HAVERQ!W175-AVERAGE(HAVERQ!W$164:W$167) -> -1.75 | AW15: =HAVERQ!X175-AVERAGE(HAVERQ!X$164:X$167) -> 8.5 | AX15: =HAVERQ!Y175-AVERAGE(HAVERQ!Y$164:Y$167) -> -110.25 | AY15: =HAVERQ!Z175-AVERAGE(HAVERQ!Z$164:Z$167) -> -245.5 | AZ15: =HAVERQ!AA175-AVERAGE(HAVERQ!AA$164:AA$167) -> 23 | ... BJ15: =HAVERQ!AK175-AVERAGE(HAVERQ!AK$164:AK$167) -> -49.75 | BK15: =BM15-AVERAGE(BM$4:BM$7) -> -45.5 | BM15: =HAVERQ!AL175+HAVERQ!AM175 -> 972 | BO15: 44470 | BP15: =BZ15-AVERAGE(BZ$4:BZ$7) -> -50.25 | BQ15: =CA15-AVERAGE(CA$4:CA$7) -> -3.5 | BR15: =CB15-AVERAGE(CB$4:CB$7) -> -137.75 | BS15: =CC15-AVERAGE(CC$4:CC$7) -> -110.25 | BT15: =CD15-AVERAGE(CD$4:CD$7) -> -249.5 | BU15: =CE15-AVERAGE(CE$4:CE$7) -> 81.75 | BV15: =CF15-AVERAGE(CF$4:CF$7) -> 7.75 | BW15: =CG15-AVERAGE(CG$4:CG$7) -> 21.75 | BX15: =CH15-AVERAGE(CH$4:CH$7) -> 202.75 | BZ15: =HAVERQ!T175 -> 348 | CA15: =HAVERQ!U175+HAVERQ!W175+HAVERQ!X175 -> 422 | CB15: =HAVERQ!V175 -> 2553 | CC15: =HAVERQ!Y175 -> 2223 | CD15: =HAVERQ!Z175+HAVERQ!AB175 -> 7255 | CE15: =HAVERQ!AA175+HAVERQ!AC175 -> 3388 | CF15: =HAVERQ!AD175 -> 1143 | CG15: =HAVERQ!AE175+HAVERQ!AF175+HAVERQ!AG175 -> 6853 | CH15: =HAVERQ!AH175+HAVERQ!AI175+HAVERQ!AJ175+HAVERQ!AK175+HAVERQ!AL175+HAVERQ!AM175 -> 11143 | CI15: =HAVERQ!S175-SUM('Chart Data'!BZ15:CH15) -> 0 | CL15: =100*((DataQ!F174/DataQ!F170)-1) -> -1.6332789 | CM15: =100*(DataQ!I174/DataQ!J174) -> 23.392813 | CY15: =(HAVERQ!AQ139-AVERAGE(HAVERQ!AQ$128:AQ$183))/STDEV(HAVERQ!AQ$128:AQ$183) -> 1.3874688 | CZ15: =(DL15-AVERAGE(DL$5:DL$59))/STDEV(DL$5:DL$59) -> 1.4607208 | DA15: =(DO15-AVERAGE(DO$5:DO$59))/STDEV(DO$5:DO$59) -> 1.2186359 | DB15: =(HAVERQ!AR139-AVERAGE(HAVERQ!AR$128:AR$183))/STDEV(HAVERQ!AR$128:AR$183) -> 0.63931361 | DC15: =(DM15-AVERAGE(DM$5:DM$59))/STDEV(DM$5:DM$59) -> -1.1230151 | DD15: =(DN15-AVERAGE(DN$29:DN$59))/STDEV(DN$29:DN$59) -> #N/A | DE15: =(HAVERQ!AZ139-AVERAGE(HAVERQ!AZ$128:AZ$167,AZ$174:AZ$183))/STDEV(HAVERQ!AZ$128:AZ$167,AZ$174:AZ$183) -> -0.24675321 | DF15: =(HAVERQ!AS139-AVERAGE(HAVERQ!AS$128:AS$183))/STDEV(HAVERQ!AS$128:AS$183) -> -0.84146419 | DG15: =(DP15-AVERAGE(DP$5:DP$59))/STDEV(DP$5:DP$59) -> -0.88065113 | DH15: =(HAVERQ!AX139-AVERAGE(HAVERQ!AX$128:AX$183))/STDEV(HAVERQ!AX$128:AX$183) -> 0.18361409 | DJ15: =(DR15-AVERAGE(DR$5:DR$59))/STDEV(DR$5:DR$59) -> -0.71933934 | DL15: =100*(HAVERQ!AV139/(HAVERQ!AW139*HAVERQ!AX139/100)) -> 2.725532 | DM15: =HAVERQ!AO139/HAVERQ!AP139 -> 0.19876348 | DN15: =100*((AVERAGE(HAVERQ!BC136:BC139)/AVERAGE(HAVERQ!BC132:BC135))-1) -> #N/A | DO15: =100*(HAVERQ!BE139+HAVERQ!BF139)/(HAVERQ!BB139+HAVERQ!BG139) -> 11.502817 | DP15: =100*((AVERAGE(HAVERQ!BA136:BA139)/AVERAGE(HAVERQ!BA132:BA135))-1) -> 1.2837209 | DR15: =(HAVERQ!AT139*HAVERQ!$AT$1)+(HAVERQ!AU139*HAVERQ!$AU$1) -> 55.476994 | DU15: Initial claims | DV15: tighter | DX15: tighter | DY15: Weekly jobless claims report
