Workbook
Name Data: [1]sheet0!$C$2

Sheet CHARTS>>

Sheet SCENARIO CHECKS>>

Sheet DATA>>

Sheet Chart Data
A1: GDP | F1: Migration assumptions | L1: POPW (%y/y) | Q1: PSCB (% of GDP) | V1: PSNFL (% of GDP) | AB1: Employment by sector & nationality | AF1: Employment by sector & nationality | AJ1: TOT | AK1: UK | AP1: Old age dependency ratio | AU1: Old age dependency ratio | BD1: SCENARIO RESULTS >> | BE1: GDP (%y/y) | BJ1: YHAT (%y/y) | BO1: Unemployment | BT1: ETILO (%y/y) | BY1: CUMOD | CD1: Bank Rate | CI1: CPI (%y/y) | CN1: GEXP per head | CS1: GREV per head | CX1: GDP per head | DC1: Potential output - baseline | DV1: Potential output - upside | EO1: Potential output - zero net migration
B2: Baseline | C2: Upside | D2: Zero net migration | G2: Baseline | H2: Upside | I2: Zero net migration | M2: =$B$2 -> Baseline | N2: =$C$2 -> Upside | O2: =$D$2 -> Zero net migration | R2: =$B$2 -> Baseline | S2: =$C$2 -> Upside | T2: =$D$2 -> Zero net migration | W2: =$B$2 -> Baseline | X2: =$C$2 -> Upside | Y2: =$D$2 -> Zero net migration | AC2: Non-UK share | AG2: Non-UK share | AJ2: Total | AK2: UK | AL2: Non-UK | AQ2: =$B$2 -> Baseline | AR2: =$C$2 -> Upside | AS2: =$D$2 -> Zero net migration | AV2: UK | AW2: US | AX2: Japan | AY2: Germany | AZ2: France | BA2: Italy | BB2: Canada | BF2: =$B$2 -> Baseline | BG2: =$C$2 -> Upside | BH2: =$D$2 -> Zero net migration | BK2: =$B$2 -> Baseline | BL2: =$C$2 -> Upside | BM2: =$D$2 -> Zero net migration | BP2: Baseline | BQ2: Upside | BR2: Zero net migration | BU2: =$B$2 -> Baseline | BV2: =$C$2 -> Upside | BW2: =$D$2 -> Zero net migration | BZ2: Baseline | CA2: Upside | CB2: Zero net migration | CE2: Baseline | CF2: Upside | CG2: Zero net migration | CJ2: =$B$2 -> Baseline | CK2: =$C$2 -> Upside | CL2: =$D$2 -> Zero net migration | CO2: =$B$2 -> Baseline | CP2: =$C$2 -> Upside | CQ2: =$D$2 -> Zero net migration | CT2: =$B$2 -> Baseline | CU2: =$C$2 -> Upside | CV2: =$D$2 -> Zero net migration | CY2: =$B$2 -> Baseline | CZ2: =$C$2 -> Upside | DA2: =$D$2 -> Zero net migration | DD2: YHAT | DE2: ESTAR | DF2: AVHR | DG2: EDUC | DH2: POP15_64 | DI2: K | DJ2: TREND | DL2: ESTAR * AVHR | DM2: EDUC / POP15_64 | DN2: K | DO2: TREND | DP2: YHAT | DQ2: GDP | DS2: Potential output | DT2: GDP | DW2: YHAT | DX2: ESTAR | DY2: AVHR | DZ2: EDUC | EA2: POP15_64 | EB2: K | EC2: TREND | EE2: ESTAR * AVHR | EF2: EDUC / POP15_64 | EG2: K | EH2: TREND | EI2: YHAT | EJ2: GDP | EL2: Potential output | EM2: GDP | EP2: YHAT | EQ2: ESTAR | ER2: AVHR | ES2: EDUC | ET2: POP15_64 | EU2: K | EV2: TREND | EX2: ESTAR * AVHR | EY2: EDUC / POP15_64 | EZ2: K | FA2: TREND | FB2: YHAT | FC2: GDP | FE2: Potential output | FF2: GDP
A3: 2020 | B3: ='GEM data - Baseline'!$F167 -> 652180 | C3: ='GEM data - Upside'!$F167 -> 652180 | D3: ='GEM data - Zero_net'!$F167 -> 652180 | F3: 2000 | G3: ='[2]Chart Data'!M4 -> 139.3 | L3: 2020 | M3: =100*(('GEM data - Baseline'!$P167/'GEM data - Baseline'!$P163)-1) -> 0.98561726 | N3: =100*(('GEM data - Upside'!$P167/'GEM data - Upside'!$P163)-1) -> 0.98561726 | O3: =100*(('GEM data - Zero_net'!$P167/'GEM data - Zero_net'!$P163)-1) -> 0.98561726 | Q3: 2020 | R3: =100*(SUMIF('GEM data - Baseline'!$C:$C,'Chart Data'!$Q3,'GEM data - Baseline'!$Q:$Q)/SUMIF('GEM data - Baseline'!$C:$C,'Chart Data'!$Q3,'GEM data - Baseline'!$S:$S)) -> -11.329793 | S3: =100*(SUMIF('GEM data - Upside'!$C:$C,'Chart Data'!$Q3,'GEM data - Upside'!$Q:$Q)/SUMIF('GEM data - Upside'!$C:$C,'Chart Data'!$Q3,'GEM data - Upside'!$S:$S)) -> -11.329793 | T3: =100*(SUMIF('GEM data - Zero_net'!$C:$C,'Chart Data'!$Q3,'GEM data - Zero_net'!$Q:$Q)/SUMIF('GEM data - Zero_net'!$C:$C,'Chart Data'!$Q3,'GEM data - Zero_net'!$S:$S)) -> -11.329793 | V3: 2020 | W3: =100*(SUMIF('GEM data - Baseline'!$D:$D,'Chart Data'!$Q3,'GEM data - Baseline'!$R:$R)/SUMIF('GEM data - Baseline'!$C:$C,'Chart Data'!$Q3,'GEM data - Baseline'!$S:$S)) -> 87.638115 | X3: =100*(SUMIF('GEM data - Upside'!$D:$D,'Chart Data'!$Q3,'GEM data - Upside'!$R:$R)/SUMIF('GEM data - Upside'!$C:$C,'Chart Data'!$Q3,'GEM data - Upside'!$S:$S)) -> 87.638115 | Y3: =100*(SUMIF('GEM data - Zero_net'!$D:$D,'Chart Data'!$Q3,'GEM data - Zero_net'!$R:$R)/SUMIF('GEM data - Zero_net'!$C:$C,'Chart Data'!$Q3,'GEM data - Zero_net'!$S:$S)) -> 87.638115 | AA3: 1 | AB3: =VLOOKUP($AA3,$AE$3:$AG$21,2,FALSE) -> Administrative services | AC3: =VLOOKUP($AA3,$AE$3:$AG$21,3,FALSE) -> 33.584697 | AE3: =RANK(AG3,$AG$3:$AG$21) -> 8 | AF3: Agriculture | AG3: =100*(AL3/AJ3) -> 18.872631 | AI3: AGR | AJ3: {=INDEX('HMRC emp by ind and nat'!$A$149:$C$233,MATCH(1,('HMRC emp by ind and nat'!$A$145:$CG$145=AJ$1)*('HMRC emp by ind and nat'!$A$146:$CG$146=$AI3),0),3)} -> 200466.67 | AK3: {=INDEX('HMRC emp by ind and nat'!$A$149:$C$233,MATCH(1,('HMRC emp by ind and nat'!$A$145:$CG$145=AK$1)*('HMRC emp by ind and nat'!$A$146:$CG$146=$AI3),0),3)} -> 162633.33 | AL3: =AJ3-AK3 -> 37833.333 | AP3: 2000 | AQ3: =AVERAGEIF('GEM data - Baseline'!$B:$B,'Chart Data'!$AP3,'GEM data - Baseline'!$AE:$AE) -> 25.758363 | AR3: =AVERAGEIF('GEM data - Upside'!$B:$B,'Chart Data'!$AP3,'GEM data - Upside'!$AE:$AE) -> 25.758363 | AS3: =AVERAGEIF('GEM data - Zero_net'!$B:$B,'Chart Data'!$AP3,'GEM data - Zero_net'!$AE:$AE) -> 25.758363 | AU3: 2000 | AV3: =AVERAGEIF('GEM data - Baseline'!$B:$B,'Chart Data'!$AP3,'GEM data - Baseline'!AE:AE) -> 25.758363 | AW3: =AVERAGEIF('GEM data - Baseline'!$B:$B,'Chart Data'!$AP3,'GEM data - Baseline'!AF:AF) -> 16.497422 | AX3: =AVERAGEIF('GEM data - Baseline'!$B:$B,'Chart Data'!$AP3,'GEM data - Baseline'!AG:AG) -> 25.58323 | AY3: =AVERAGEIF('GEM data - Baseline'!$B:$B,'Chart Data'!$AP3,'GEM data - Baseline'!AH:AH) -> 24.29539 | AZ3: =AVERAGEIF('GEM data - Baseline'!$B:$B,'Chart Data'!$AP3,'GEM data - Baseline'!AI:AI) -> 24.42167 | BA3: =AVERAGEIF('GEM data - Baseline'!$B:$B,'Chart Data'!$AP3,'GEM data - Baseline'!AJ:AJ) -> 28.48933 | BB3: =AVERAGEIF('GEM data - Baseline'!$B:$B,'Chart Data'!$AP3,'GEM data - Baseline'!AK:AK) -> 15.987073 | BE3: 2020 | BF3: =100*(('GEM data - Baseline'!$F167/'GEM data - Baseline'!$F163)-1) -> -1.995023 | BG3: =100*(('GEM data - Upside'!$F167/'GEM data - Upside'!$F163)-1) -> -1.995023 | BH3: =100*(('GEM data - Zero_net'!$F167/'GEM data - Zero_net'!$F163)-1) -> -1.995023 | BJ3: 2020 | BK3: =100*(('GEM data - Baseline'!$U167/'GEM data - Baseline'!$U163)-1) -> -0.88167579 | BL3: =100*(('GEM data - Upside'!$U167/'GEM data - Upside'!$U163)-1) -> -0.88167579 | BM3: =100*(('GEM data - Zero_net'!$U167/'GEM data - Zero_net'!$U163)-1) -> -0.88167579 | BO3: 2020 | BP3: ='GEM data - Baseline'!$O167 -> 4.1 | BQ3: ='GEM data - Upside'!$O167 -> 4.1 | BR3: ='GEM data - Zero_net'!$O167 -> 4.1 | BT3: 2020 | BU3: =100*(('GEM data - Baseline'!$L167/'GEM data - Baseline'!$L163)-1) -> 0.61020259 | BV3: =100*(('GEM data - Upside'!$L167/'GEM data - Upside'!$L163)-1) -> 0.61020259 | BW3: =100*(('GEM data - Zero_net'!$L167/'GEM data - Zero_net'!$L163)-1) -> 0.61020259 | BY3: 2020 | BZ3: ='GEM data - Baseline'!$T167 -> -0.9545326 | CA3: ='GEM data - Upside'!$T167 -> -0.9545326 | CB3: ='GEM data - Zero_net'!$T167 -> -0.9545326 | CD3: 2020 | CE3: ='GEM data - Baseline'!$J167 -> 0.6138462 | CF3: ='GEM data - Upside'!$J167 -> 0.6138462 | CG3: ='GEM data - Zero_net'!$J167 -> 0.6138462 | CI3: 2020 | CJ3: =100*(('GEM data - Baseline'!$I167/'GEM data - Baseline'!$I163)-1) -> 1.6557638 | CK3: =100*(('GEM data - Upside'!$I167/'GEM data - Upside'!$I163)-1) -> 1.6557638 | CL3: =100*(('GEM data - Zero_net'!$I167/'GEM data - Zero_net'!$I163)-1) -> 1.6557638 | CN3: 2020 | CO3: =100*('GEM data - Baseline'!$AB167/'GEM data - Baseline'!$AD167) -> 343.17064 | CP3: =100*('GEM data - Upside'!$AB167/'GEM data - Upside'!$AD167) -> 343.17064 | CQ3: =100*('GEM data - Zero_net'!$AB167/'GEM data - Zero_net'!$AD167) -> 343.17064 | CS3: 2020 | CT3: =100*('GEM data - Baseline'!$AC167/'GEM data - Baseline'!$AD167) -> 342.29224 | CU3: =100*('GEM data - Upside'!$AC167/'GEM data - Upside'!$AD167) -> 342.29224 | CV3: =100*('GEM data - Zero_net'!$AC167/'GEM data - Zero_net'!$AD167) -> 342.29224 | CX3: 2020 | CY3: =100*('GEM data - Baseline'!$F167/'GEM data - Baseline'!$AD167) -> 977.60523 | CZ3: =100*('GEM data - Upside'!$F167/'GEM data - Upside'!$AD167) -> 977.60523 | DA3: =100*('GEM data - Zero_net'!$F167/'GEM data - Zero_net'!$AD167) -> 977.60523 | DC3: 1980 | DD3: =SUMIF('GEM data - Baseline'!$B:$B,'Chart Data'!$DC3,'GEM data - Baseline'!$U:$U) -> 1164663.3 | DE3: =AVERAGEIF('GEM data - Baseline'!$B:$B,'Chart Data'!$DC3,'GEM data - Baseline'!$V:$V) -> 24765.53 | DF3: =AVERAGEIF('GEM data - Baseline'!$B:$B,'Chart Data'!$DC3,'GEM data - Baseline'!$W:$W) -> 0.001 | DG3: =AVERAGEIF('GEM data - Baseline'!$B:$B,'Chart Data'!$DC3,'GEM data - Baseline'!$X:$X) -> 306731.33 | DH3: =AVERAGEIF('GEM data - Baseline'!$B:$B,'Chart Data'!$DC3,'GEM data - Baseline'!$Y:$Y) -> 36102.315 | DI3: =AVERAGEIF('GEM data - Baseline'!$B:$B,'Chart Data'!$DC3,'GEM data - Baseline'!$Z:$Z) -> 1231755.5 | DJ3: =AVERAGEIF('GEM data - Baseline'!$B:$B,'Chart Data'!$DC3,'GEM data - Baseline'!$AA:$AA) -> -1.8272072 | DL3: =DE3*DF3 -> 24.76553 | DM3: =DG3/DH3 -> 8.4961678 | DN3: =DI3 -> 1231755.5 | DO3: =DJ3 -> -1.8272072 | DP3: =DD3 -> 1164663.3 | DQ3: =SUMIF('GEM data - Baseline'!$B:$B,'Chart Data'!$DC3,'GEM data - Baseline'!$F:$F) -> 1140989 | DV3: 1980 | DW3: =SUMIF('GEM data - Upside'!$B:$B,'Chart Data'!$DC3,'GEM data - Upside'!$U:$U) -> 1164663.3 | DX3: =AVERAGEIF('GEM data - Upside'!$B:$B,'Chart Data'!$DC3,'GEM data - Upside'!$V:$V) -> 24765.53 | DY3: =AVERAGEIF('GEM data - Upside'!$B:$B,'Chart Data'!$DC3,'GEM data - Upside'!$W:$W) -> 0.001 | DZ3: =AVERAGEIF('GEM data - Upside'!$B:$B,'Chart Data'!$DC3,'GEM data - Upside'!$X:$X) -> 306731.33 | EA3: =AVERAGEIF('GEM data - Upside'!$B:$B,'Chart Data'!$DC3,'GEM data - Upside'!$Y:$Y) -> 36102.315 | EB3: =AVERAGEIF('GEM data - Upside'!$B:$B,'Chart Data'!$DC3,'GEM data - Upside'!$Z:$Z) -> 1231755.5 | EC3: =AVERAGEIF('GEM data - Upside'!$B:$B,'Chart Data'!$DC3,'GEM data - Upside'!$AA:$AA) -> -1.8272072 | EE3: =DX3*DY3 -> 24.76553 | EF3: =DZ3/EA3 -> 8.4961678 | EG3: =EB3 -> 1231755.5 | EH3: =EC3 -> -1.8272072 | EI3: =DW3 -> 1164663.3 | EJ3: =SUMIF('GEM data - Upside'!$B:$B,'Chart Data'!$DC3,'GEM data - Upside'!$F:$F) -> 1140989 | EO3: 1980 | EP3: =SUMIF('GEM data - Zero_net'!$B:$B,'Chart Data'!$DC3,'GEM data - Zero_net'!$U:$U) -> 1164663.3 | EQ3: =AVERAGEIF('GEM data - Zero_net'!$B:$B,'Chart Data'!$DC3,'GEM data - Zero_net'!$V:$V) -> 24765.53 | ER3: =AVERAGEIF('GEM data - Zero_net'!$B:$B,'Chart Data'!$DC3,'GEM data - Zero_net'!$W:$W) -> 0.001 | ES3: =AVERAGEIF('GEM data - Zero_net'!$B:$B,'Chart Data'!$DC3,'GEM data - Zero_net'!$X:$X) -> 306731.33 | ET3: =AVERAGEIF('GEM data - Zero_net'!$B:$B,'Chart Data'!$DC3,'GEM data - Zero_net'!$Y:$Y) -> 36102.315 | EU3: =AVERAGEIF('GEM data - Zero_net'!$B:$B,'Chart Data'!$DC3,'GEM data - Zero_net'!$Z:$Z) -> 1231755.5 | EV3: =AVERAGEIF('GEM data - Zero_net'!$B:$B,'Chart Data'!$DC3,'GEM data - Zero_net'!$AA:$AA) -> -1.8272072 | EX3: =EQ3*ER3 -> 24.76553 | EY3: =ES3/ET3 -> 8.4961678 | EZ3: =EU3 -> 1231755.5 | FA3: =EV3 -> -1.8272072 | FB3: =EP3 -> 1164663.3 | FC3: =SUMIF('GEM data - Zero_net'!$B:$B,'Chart Data'!$DC3,'GEM data - Zero_net'!$F:$F) -> 1140989
B4: ='GEM data - Baseline'!$F168 -> 522356 | C4: ='GEM data - Upside'!$F168 -> 522356 | D4: ='GEM data - Zero_net'!$F168 -> 522356 | F4: 2001 | G4: ='[2]Chart Data'!M5 -> 153.2 | M4: =100*(('GEM data - Baseline'!$P168/'GEM data - Baseline'!$P164)-1) -> 0.91787615 | N4: =100*(('GEM data - Upside'!$P168/'GEM data - Upside'!$P164)-1) -> 0.91787615 | O4: =100*(('GEM data - Zero_net'!$P168/'GEM data - Zero_net'!$P164)-1) -> 0.91787615 | Q4: 2021 | R4: =100*(SUMIF('GEM data - Baseline'!$C:$C,'Chart Data'!$Q4,'GEM data - Baseline'!$Q:$Q)/SUMIF('GEM data - Baseline'!$C:$C,'Chart Data'!$Q4,'GEM data - Baseline'!$S:$S)) -> -2.8065235 | S4: =100*(SUMIF('GEM data - Upside'!$C:$C,'Chart Data'!$Q4,'GEM data - Upside'!$Q:$Q)/SUMIF('GEM data - Upside'!$C:$C,'Chart Data'!$Q4,'GEM data - Upside'!$S:$S)) -> -2.8065235 | T4: =100*(SUMIF('GEM data - Zero_net'!$C:$C,'Chart Data'!$Q4,'GEM data - Zero_net'!$Q:$Q)/SUMIF('GEM data - Zero_net'!$C:$C,'Chart Data'!$Q4,'GEM data - Zero_net'!$S:$S)) -> -2.8065235 | V4: 2021 | W4: =100*(SUMIF('GEM data - Baseline'!$D:$D,'Chart Data'!$Q4,'GEM data - Baseline'!$R:$R)/SUMIF('GEM data - Baseline'!$C:$C,'Chart Data'!$Q4,'GEM data - Baseline'!$S:$S)) -> 82.591698 | X4: =100*(SUMIF('GEM data - Upside'!$D:$D,'Chart Data'!$Q4,'GEM data - Upside'!$R:$R)/SUMIF('GEM data - Upside'!$C:$C,'Chart Data'!$Q4,'GEM data - Upside'!$S:$S)) -> 82.591698 | Y4: =100*(SUMIF('GEM data - Zero_net'!$D:$D,'Chart Data'!$Q4,'GEM data - Zero_net'!$R:$R)/SUMIF('GEM data - Zero_net'!$C:$C,'Chart Data'!$Q4,'GEM data - Zero_net'!$S:$S)) -> 82.591698 | AA4: 2 | AB4: =VLOOKUP($AA4,$AE$3:$AG$21,2,FALSE) -> Accommodation & food | AC4: =VLOOKUP($AA4,$AE$3:$AG$21,3,FALSE) -> 30.691508 | AE4: =RANK(AG4,$AG$3:$AG$21) -> 17 | AF4: Extraction | AG4: =100*(AL4/AJ4) -> 9.6848578 | AI4: MIN | AJ4: {=INDEX('HMRC emp by ind and nat'!$A$149:$C$233,MATCH(1,('HMRC emp by ind and nat'!$A$145:$CG$145=AJ$1)*('HMRC emp by ind and nat'!$A$146:$CG$146=$AI4),0),3)} -> 43366.667 | AK4: {=INDEX('HMRC emp by ind and nat'!$A$149:$C$233,MATCH(1,('HMRC emp by ind and nat'!$A$145:$CG$145=AK$1)*('HMRC emp by ind and nat'!$A$146:$CG$146=$AI4),0),3)} -> 39166.667 | AL4: =AJ4-AK4 -> 4200 | AP4: 2001 | AQ4: =AVERAGEIF('GEM data - Baseline'!$B:$B,'Chart Data'!$AP4,'GEM data - Baseline'!$AE:$AE) -> 25.742498 | AR4: =AVERAGEIF('GEM data - Upside'!$B:$B,'Chart Data'!$AP4,'GEM data - Upside'!$AE:$AE) -> 25.742498 | AS4: =AVERAGEIF('GEM data - Zero_net'!$B:$B,'Chart Data'!$AP4,'GEM data - Zero_net'!$AE:$AE) -> 25.742498 | AU4: 2001 | AV4: =AVERAGEIF('GEM data - Baseline'!$B:$B,'Chart Data'!$AP4,'GEM data - Baseline'!AE:AE) -> 25.742498 | AW4: =AVERAGEIF('GEM data - Baseline'!$B:$B,'Chart Data'!$AP4,'GEM data - Baseline'!AF:AF) -> 16.409743 | AX4: =AVERAGEIF('GEM data - Baseline'!$B:$B,'Chart Data'!$AP4,'GEM data - Baseline'!AG:AG) -> 26.620055 | AY4: =AVERAGEIF('GEM data - Baseline'!$B:$B,'Chart Data'!$AP4,'GEM data - Baseline'!AH:AH) -> 24.97196 | AZ4: =AVERAGEIF('GEM data - Baseline'!$B:$B,'Chart Data'!$AP4,'GEM data - Baseline'!AI:AI) -> 24.609677 | BA4: =AVERAGEIF('GEM data - Baseline'!$B:$B,'Chart Data'!$AP4,'GEM data - Baseline'!AJ:AJ) -> 29.065067 | BB4: =AVERAGEIF('GEM data - Baseline'!$B:$B,'Chart Data'!$AP4,'GEM data - Baseline'!AK:AK) -> 16.060247 | BF4: =100*(('GEM data - Baseline'!$F168/'GEM data - Baseline'!$F164)-1) -> -21.671078 | BG4: =100*(('GEM data - Upside'!$F168/'GEM data - Upside'!$F164)-1) -> -21.671078 | BH4: =100*(('GEM data - Zero_net'!$F168/'GEM data - Zero_net'!$F164)-1) -> -21.671078 | BK4: =100*(('GEM data - Baseline'!$U168/'GEM data - Baseline'!$U164)-1) -> -13.133792 | BL4: =100*(('GEM data - Upside'!$U168/'GEM data - Upside'!$U164)-1) -> -13.133792 | BM4: =100*(('GEM data - Zero_net'!$U168/'GEM data - Zero_net'!$U164)-1) -> -13.133792 | BP4: ='GEM data - Baseline'!$O168 -> 4.1 | BQ4: ='GEM data - Upside'!$O168 -> 4.1 | BR4: ='GEM data - Zero_net'!$O168 -> 4.1 | BU4: =100*(('GEM data - Baseline'!$L168/'GEM data - Baseline'!$L164)-1) -> -0.99808877 | BV4: =100*(('GEM data - Upside'!$L168/'GEM data - Upside'!$L164)-1) -> -0.99808877 | BW4: =100*(('GEM data - Zero_net'!$L168/'GEM data - Zero_net'!$L164)-1) -> -0.99808877 | BZ4: ='GEM data - Baseline'!$T168 -> -10.17914 | CA4: ='GEM data - Upside'!$T168 -> -10.17914 | CB4: ='GEM data - Zero_net'!$T168 -> -10.17914 | CE4: ='GEM data - Baseline'!$J168 -> 0.1 | CF4: ='GEM data - Upside'!$J168 -> 0.1 | CG4: ='GEM data - Zero_net'!$J168 -> 0.1 | CJ4: =100*(('GEM data - Baseline'!$I168/'GEM data - Baseline'!$I164)-1) -> 0.68024119 | CK4: =100*(('GEM data - Upside'!$I168/'GEM data - Upside'!$I164)-1) -> 0.68024119 | CL4: =100*(('GEM data - Zero_net'!$I168/'GEM data - Zero_net'!$I164)-1) -> 0.68024119 | CO4: =100*('GEM data - Baseline'!$AB168/'GEM data - Baseline'!$AD168) -> 450.69973 | CP4: =100*('GEM data - Upside'!$AB168/'GEM data - Upside'!$AD168) -> 450.69973 | CQ4: =100*('GEM data - Zero_net'!$AB168/'GEM data - Zero_net'!$AD168) -> 450.69973 | CT4: =100*('GEM data - Baseline'!$AC168/'GEM data - Baseline'!$AD168) -> 252.47228 | CU4: =100*('GEM data - Upside'!$AC168/'GEM data - Upside'!$AD168) -> 252.47228 | CV4: =100*('GEM data - Zero_net'!$AC168/'GEM data - Zero_net'!$AD168) -> 252.47228 | CY4: =100*('GEM data - Baseline'!$F168/'GEM data - Baseline'!$AD168) -> 782.67306 | CZ4: =100*('GEM data - Upside'!$F168/'GEM data - Upside'!$AD168) -> 782.67306 | DA4: =100*('GEM data - Zero_net'!$F168/'GEM data - Zero_net'!$AD168) -> 782.67306 | DC4: 1981 | DD4: =SUMIF('GEM data - Baseline'!$B:$B,'Chart Data'!$DC4,'GEM data - Baseline'!$U:$U) -> 1182107.9 | DE4: =AVERAGEIF('GEM data - Baseline'!$B:$B,'Chart Data'!$DC4,'GEM data - Baseline'!$V:$V) -> 24659.65 | DF4: =AVERAGEIF('GEM data - Baseline'!$B:$B,'Chart Data'!$DC4,'GEM data - Baseline'!$W:$W) -> 0.001 | DG4: =AVERAGEIF('GEM data - Baseline'!$B:$B,'Chart Data'!$DC4,'GEM data - Baseline'!$X:$X) -> 309382.7 | DH4: =AVERAGEIF('GEM data - Baseline'!$B:$B,'Chart Data'!$DC4,'GEM data - Baseline'!$Y:$Y) -> 36300.177 | DI4: =AVERAGEIF('GEM data - Baseline'!$B:$B,'Chart Data'!$DC4,'GEM data - Baseline'!$Z:$Z) -> 1243839.2 | DJ4: =AVERAGEIF('GEM data - Baseline'!$B:$B,'Chart Data'!$DC4,'GEM data - Baseline'!$AA:$AA) -> -1.8145853 | DL4: =DE4*DF4 -> 24.65965 | DM4: =DG4/DH4 -> 8.5228977 | DN4: =DI4 -> 1243839.2 | DO4: =DJ4 -> -1.8145853 | DP4: =DD4 -> 1182107.9 | DQ4: =SUMIF('GEM data - Baseline'!$B:$B,'Chart Data'!$DC4,'GEM data - Baseline'!$F:$F) -> 1134663 | DS4: =100*((DP4/DP3)-1) -> 1.4978234 | DT4: =100*((DQ4/DQ3)-1) -> -0.55443129 | DV4: 1981 | DW4: =SUMIF('GEM data - Upside'!$B:$B,'Chart Data'!$DC4,'GEM data - Upside'!$U:$U) -> 1182107.9 | DX4: =AVERAGEIF('GEM data - Upside'!$B:$B,'Chart Data'!$DC4,'GEM data - Upside'!$V:$V) -> 24659.65 | DY4: =AVERAGEIF('GEM data - Upside'!$B:$B,'Chart Data'!$DC4,'GEM data - Upside'!$W:$W) -> 0.001 | DZ4: =AVERAGEIF('GEM data - Upside'!$B:$B,'Chart Data'!$DC4,'GEM data - Upside'!$X:$X) -> 309382.7 | EA4: =AVERAGEIF('GEM data - Upside'!$B:$B,'Chart Data'!$DC4,'GEM data - Upside'!$Y:$Y) -> 36300.177 | EB4: =AVERAGEIF('GEM data - Upside'!$B:$B,'Chart Data'!$DC4,'GEM data - Upside'!$Z:$Z) -> 1243839.2 | EC4: =AVERAGEIF('GEM data - Upside'!$B:$B,'Chart Data'!$DC4,'GEM data - Upside'!$AA:$AA) -> -1.8145853 | EE4: =DX4*DY4 -> 24.65965 | EF4: =DZ4/EA4 -> 8.5228977 | EG4: =EB4 -> 1243839.2 | EH4: =EC4 -> -1.8145853 | EI4: =DW4 -> 1182107.9 | EJ4: =SUMIF('GEM data - Upside'!$B:$B,'Chart Data'!$DC4,'GEM data - Upside'!$F:$F) -> 1134663 | EL4: =100*((EI4/EI3)-1) -> 1.4978234 | EM4: =100*((EJ4/EJ3)-1) -> -0.55443129 | EO4: 1981 | EP4: =SUMIF('GEM data - Zero_net'!$B:$B,'Chart Data'!$DC4,'GEM data - Zero_net'!$U:$U) -> 1182107.9 | EQ4: =AVERAGEIF('GEM data - Zero_net'!$B:$B,'Chart Data'!$DC4,'GEM data - Zero_net'!$V:$V) -> 24659.65 | ER4: =AVERAGEIF('GEM data - Zero_net'!$B:$B,'Chart Data'!$DC4,'GEM data - Zero_net'!$W:$W) -> 0.001 | ES4: =AVERAGEIF('GEM data - Zero_net'!$B:$B,'Chart Data'!$DC4,'GEM data - Zero_net'!$X:$X) -> 309382.7 | ET4: =AVERAGEIF('GEM data - Zero_net'!$B:$B,'Chart Data'!$DC4,'GEM data - Zero_net'!$Y:$Y) -> 36300.177 | EU4: =AVERAGEIF('GEM data - Zero_net'!$B:$B,'Chart Data'!$DC4,'GEM data - Zero_net'!$Z:$Z) -> 1243839.2 | EV4: =AVERAGEIF('GEM data - Zero_net'!$B:$B,'Chart Data'!$DC4,'GEM data - Zero_net'!$AA:$AA) -> -1.8145853 | EX4: =EQ4*ER4 -> 24.65965 | EY4: =ES4/ET4 -> 8.5228977 | EZ4: =EU4 -> 1243839.2 | FA4: =EV4 -> -1.8145853 | FB4: =EP4 -> 1182107.9 | FC4: =SUMIF('GEM data - Zero_net'!$B:$B,'Chart Data'!$DC4,'GEM data - Zero_net'!$F:$F) -> 1134663 | FE4: =100*((FB4/FB3)-1) -> 1.4978234 | FF4: =100*((FC4/FC3)-1) -> -0.55443129
B5: ='GEM data - Baseline'!$F169 -> 610972 | C5: ='GEM data - Upside'!$F169 -> 610972 | D5: ='GEM data - Zero_net'!$F169 -> 610972 | F5: 2002 | G5: ='[2]Chart Data'!M6 -> 190.9 | M5: =100*(('GEM data - Baseline'!$P169/'GEM data - Baseline'!$P165)-1) -> 0.82324975 | N5: =100*(('GEM data - Upside'!$P169/'GEM data - Upside'!$P165)-1) -> 0.82324975 | O5: =100*(('GEM data - Zero_net'!$P169/'GEM data - Zero_net'!$P165)-1) -> 0.82324975 | Q5: 2022 | R5: =100*(SUMIF('GEM data - Baseline'!$C:$C,'Chart Data'!$Q5,'GEM data - Baseline'!$Q:$Q)/SUMIF('GEM data - Baseline'!$C:$C,'Chart Data'!$Q5,'GEM data - Baseline'!$S:$S)) -> -3.0590843 | S5: =100*(SUMIF('GEM data - Upside'!$C:$C,'Chart Data'!$Q5,'GEM data - Upside'!$Q:$Q)/SUMIF('GEM data - Upside'!$C:$C,'Chart Data'!$Q5,'GEM data - Upside'!$S:$S)) -> -3.0590843 | T5: =100*(SUMIF('GEM data - Zero_net'!$C:$C,'Chart Data'!$Q5,'GEM data - Zero_net'!$Q:$Q)/SUMIF('GEM data - Zero_net'!$C:$C,'Chart Data'!$Q5,'GEM data - Zero_net'!$S:$S)) -> -3.0590843 | V5: 2022 | W5: =100*(SUMIF('GEM data - Baseline'!$D:$D,'Chart Data'!$Q5,'GEM data - Baseline'!$R:$R)/SUMIF('GEM data - Baseline'!$C:$C,'Chart Data'!$Q5,'GEM data - Baseline'!$S:$S)) -> 81.818978 | X5: =100*(SUMIF('GEM data - Upside'!$D:$D,'Chart Data'!$Q5,'GEM data - Upside'!$R:$R)/SUMIF('GEM data - Upside'!$C:$C,'Chart Data'!$Q5,'GEM data - Upside'!$S:$S)) -> 81.818978 | Y5: =100*(SUMIF('GEM data - Zero_net'!$D:$D,'Chart Data'!$Q5,'GEM data - Zero_net'!$R:$R)/SUMIF('GEM data - Zero_net'!$C:$C,'Chart Data'!$Q5,'GEM data - Zero_net'!$S:$S)) -> 81.818978 | AA5: 3 | AB5: =VLOOKUP($AA5,$AE$3:$AG$21,2,FALSE) -> Health | AC5: =VLOOKUP($AA5,$AE$3:$AG$21,3,FALSE) -> 26.033779 | AE5: =RANK(AG5,$AG$3:$AG$21) -> 7 | AF5: Manufacturing | AG5: =100*(AL5/AJ5) -> 19.09214 | AI5: MAN | AJ5: {=INDEX('HMRC emp by ind and nat'!$A$149:$C$233,MATCH(1,('HMRC emp by ind and nat'!$A$145:$CG$145=AJ$1)*('HMRC emp by ind and nat'!$A$146:$CG$146=$AI5),0),3)} -> 2338833.3 | AK5: {=INDEX('HMRC emp by ind and nat'!$A$149:$C$233,MATCH(1,('HMRC emp by ind and nat'!$A$145:$CG$145=AK$1)*('HMRC emp by ind and nat'!$A$146:$CG$146=$AI5),0),3)} -> 1892300 | AL5: =AJ5-AK5 -> 446533.33 | AP5: 2002 | AQ5: =AVERAGEIF('GEM data - Baseline'!$B:$B,'Chart Data'!$AP5,'GEM data - Baseline'!$AE:$AE) -> 25.72545 | AR5: =AVERAGEIF('GEM data - Upside'!$B:$B,'Chart Data'!$AP5,'GEM data - Upside'!$AE:$AE) -> 25.72545 | AS5: =AVERAGEIF('GEM data - Zero_net'!$B:$B,'Chart Data'!$AP5,'GEM data - Zero_net'!$AE:$AE) -> 25.72545 | AU5: 2002 | AV5: =AVERAGEIF('GEM data - Baseline'!$B:$B,'Chart Data'!$AP5,'GEM data - Baseline'!AE:AE) -> 25.72545 | AW5: =AVERAGEIF('GEM data - Baseline'!$B:$B,'Chart Data'!$AP5,'GEM data - Baseline'!AF:AF) -> 16.331443 | AX5: =AVERAGEIF('GEM data - Baseline'!$B:$B,'Chart Data'!$AP5,'GEM data - Baseline'!AG:AG) -> 27.62727 | AY5: =AVERAGEIF('GEM data - Baseline'!$B:$B,'Chart Data'!$AP5,'GEM data - Baseline'!AH:AH) -> 25.666835 | AZ5: =AVERAGEIF('GEM data - Baseline'!$B:$B,'Chart Data'!$AP5,'GEM data - Baseline'!AI:AI) -> 24.764575 | BA5: =AVERAGEIF('GEM data - Baseline'!$B:$B,'Chart Data'!$AP5,'GEM data - Baseline'!AJ:AJ) -> 29.608413 | BB5: =AVERAGEIF('GEM data - Baseline'!$B:$B,'Chart Data'!$AP5,'GEM data - Baseline'!AK:AK) -> 16.10583 | BF5: =100*(('GEM data - Baseline'!$F169/'GEM data - Baseline'!$F165)-1) -> -8.8845375 | BG5: =100*(('GEM data - Upside'!$F169/'GEM data - Upside'!$F165)-1) -> -8.8845375 | BH5: =100*(('GEM data - Zero_net'!$F169/'GEM data - Zero_net'!$F165)-1) -> -8.8845375 | BK5: =100*(('GEM data - Baseline'!$U169/'GEM data - Baseline'!$U165)-1) -> -8.0989333 | BL5: =100*(('GEM data - Upside'!$U169/'GEM data - Upside'!$U165)-1) -> -8.0989333 | BM5: =100*(('GEM data - Zero_net'!$U169/'GEM data - Zero_net'!$U165)-1) -> -8.0989333 | BP5: ='GEM data - Baseline'!$O169 -> 5 | BQ5: ='GEM data - Upside'!$O169 -> 5 | BR5: ='GEM data - Zero_net'!$O169 -> 5 | BU5: =100*(('GEM data - Baseline'!$L169/'GEM data - Baseline'!$L165)-1) -> -1.6384971 | BV5: =100*(('GEM data - Upside'!$L169/'GEM data - Upside'!$L165)-1) -> -1.6384971 | BW5: =100*(('GEM data - Zero_net'!$L169/'GEM data - Zero_net'!$L165)-1) -> -1.6384971 | BZ5: ='GEM data - Baseline'!$T169 -> -0.01592636 | CA5: ='GEM data - Upside'!$T169 -> -0.01592636 | CB5: ='GEM data - Zero_net'!$T169 -> -0.01592636 | CE5: ='GEM data - Baseline'!$J169 -> 0.1 | CF5: ='GEM data - Upside'!$J169 -> 0.1 | CG5: ='GEM data - Zero_net'!$J169 -> 0.1 | CJ5: =100*(('GEM data - Baseline'!$I169/'GEM data - Baseline'!$I165)-1) -> 0.61570178 | CK5: =100*(('GEM data - Upside'!$I169/'GEM data - Upside'!$I165)-1) -> 0.61570178 | CL5: =100*(('GEM data - Zero_net'!$I169/'GEM data - Zero_net'!$I165)-1) -> 0.61570178 | CO5: =100*('GEM data - Baseline'!$AB169/'GEM data - Baseline'!$AD169) -> 395.60176 | CP5: =100*('GEM data - Upside'!$AB169/'GEM data - Upside'!$AD169) -> 395.60176 | CQ5: =100*('GEM data - Zero_net'!$AB169/'GEM data - Zero_net'!$AD169) -> 395.60176 | CT5: =100*('GEM data - Baseline'!$AC169/'GEM data - Baseline'!$AD169) -> 285.05004 | CU5: =100*('GEM data - Upside'!$AC169/'GEM data - Upside'!$AD169) -> 285.05004 | CV5: =100*('GEM data - Zero_net'!$AC169/'GEM data - Zero_net'!$AD169) -> 285.05004 | CY5: =100*('GEM data - Baseline'!$F169/'GEM data - Baseline'!$AD169) -> 914.63559 | CZ5: =100*('GEM data - Upside'!$F169/'GEM data - Upside'!$AD169) -> 914.63559 | DA5: =100*('GEM data - Zero_net'!$F169/'GEM data - Zero_net'!$AD169) -> 914.63559 | DC5: 1982 | DD5: =SUMIF('GEM data - Baseline'!$B:$B,'Chart Data'!$DC5,'GEM data - Baseline'!$U:$U) -> 1189450.8 | DE5: =AVERAGEIF('GEM data - Baseline'!$B:$B,'Chart Data'!$DC5,'GEM data - Baseline'!$V:$V) -> 24297.707 | DF5: =AVERAGEIF('GEM data - Baseline'!$B:$B,'Chart Data'!$DC5,'GEM data - Baseline'!$W:$W) -> 0.001 | DG5: =AVERAGEIF('GEM data - Baseline'!$B:$B,'Chart Data'!$DC5,'GEM data - Baseline'!$X:$X) -> 311708.92 | DH5: =AVERAGEIF('GEM data - Baseline'!$B:$B,'Chart Data'!$DC5,'GEM data - Baseline'!$Y:$Y) -> 36500.68 | DI5: =AVERAGEIF('GEM data - Baseline'!$B:$B,'Chart Data'!$DC5,'GEM data - Baseline'!$Z:$Z) -> 1254045.5 | DJ5: =AVERAGEIF('GEM data - Baseline'!$B:$B,'Chart Data'!$DC5,'GEM data - Baseline'!$AA:$AA) -> -1.8020507 | DL5: =DE5*DF5 -> 24.297707 | DM5: =DG5/DH5 -> 8.5398115 | DN5: =DI5 -> 1254045.5 | DO5: =DJ5 -> -1.8020507 | DP5: =DD5 -> 1189450.8 | DQ5: =SUMIF('GEM data - Baseline'!$B:$B,'Chart Data'!$DC5,'GEM data - Baseline'!$F:$F) -> 1157191 | DS5: =100*((DP5/DP4)-1) -> 0.62117003 | DT5: =100*((DQ5/DQ4)-1) -> 1.9854353 | DV5: 1982 | DW5: =SUMIF('GEM data - Upside'!$B:$B,'Chart Data'!$DC5,'GEM data - Upside'!$U:$U) -> 1189450.8 | DX5: =AVERAGEIF('GEM data - Upside'!$B:$B,'Chart Data'!$DC5,'GEM data - Upside'!$V:$V) -> 24297.707 | DY5: =AVERAGEIF('GEM data - Upside'!$B:$B,'Chart Data'!$DC5,'GEM data - Upside'!$W:$W) -> 0.001 | DZ5: =AVERAGEIF('GEM data - Upside'!$B:$B,'Chart Data'!$DC5,'GEM data - Upside'!$X:$X) -> 311708.92 | EA5: =AVERAGEIF('GEM data - Upside'!$B:$B,'Chart Data'!$DC5,'GEM data - Upside'!$Y:$Y) -> 36500.68 | EB5: =AVERAGEIF('GEM data - Upside'!$B:$B,'Chart Data'!$DC5,'GEM data - Upside'!$Z:$Z) -> 1254045.5 | EC5: =AVERAGEIF('GEM data - Upside'!$B:$B,'Chart Data'!$DC5,'GEM data - Upside'!$AA:$AA) -> -1.8020507 | EE5: =DX5*DY5 -> 24.297707 | EF5: =DZ5/EA5 -> 8.5398115 | EG5: =EB5 -> 1254045.5 | EH5: =EC5 -> -1.8020507 | EI5: =DW5 -> 1189450.8 | EJ5: =SUMIF('GEM data - Upside'!$B:$B,'Chart Data'!$DC5,'GEM data - Upside'!$F:$F) -> 1157191 | EL5: =100*((EI5/EI4)-1) -> 0.62117003 | EM5: =100*((EJ5/EJ4)-1) -> 1.9854353 | EO5: 1982 | EP5: =SUMIF('GEM data - Zero_net'!$B:$B,'Chart Data'!$DC5,'GEM data - Zero_net'!$U:$U) -> 1189450.8 | EQ5: =AVERAGEIF('GEM data - Zero_net'!$B:$B,'Chart Data'!$DC5,'GEM data - Zero_net'!$V:$V) -> 24297.707 | ER5: =AVERAGEIF('GEM data - Zero_net'!$B:$B,'Chart Data'!$DC5,'GEM data - Zero_net'!$W:$W) -> 0.001 | ES5: =AVERAGEIF('GEM data - Zero_net'!$B:$B,'Chart Data'!$DC5,'GEM data - Zero_net'!$X:$X) -> 311708.92 | ET5: =AVERAGEIF('GEM data - Zero_net'!$B:$B,'Chart Data'!$DC5,'GEM data - Zero_net'!$Y:$Y) -> 36500.68 | EU5: =AVERAGEIF('GEM data - Zero_net'!$B:$B,'Chart Data'!$DC5,'GEM data - Zero_net'!$Z:$Z) -> 1254045.5 | EV5: =AVERAGEIF('GEM data - Zero_net'!$B:$B,'Chart Data'!$DC5,'GEM data - Zero_net'!$AA:$AA) -> -1.8020507 | EX5: =EQ5*ER5 -> 24.297707 | EY5: =ES5/ET5 -> 8.5398115 | EZ5: =EU5 -> 1254045.5 | FA5: =EV5 -> -1.8020507 | FB5: =EP5 -> 1189450.8 | FC5: =SUMIF('GEM data - Zero_net'!$B:$B,'Chart Data'!$DC5,'GEM data - Zero_net'!$F:$F) -> 1157191 | FE5: =100*((FB5/FB4)-1) -> 0.62117003 | FF5: =100*((FC5/FC4)-1) -> 1.9854353
B6: ='GEM data - Baseline'!$F170 -> 619330 | C6: ='GEM data - Upside'!$F170 -> 619330 | D6: ='GEM data - Zero_net'!$F170 -> 619330 | F6: 2003 | G6: ='[2]Chart Data'!M7 -> 194.3 | M6: =100*(('GEM data - Baseline'!$P170/'GEM data - Baseline'!$P166)-1) -> 0.72907922 | N6: =100*(('GEM data - Upside'!$P170/'GEM data - Upside'!$P166)-1) -> 0.72907922 | O6: =100*(('GEM data - Zero_net'!$P170/'GEM data - Zero_net'!$P166)-1) -> 0.72907922 | Q6: 2023 | R6: =100*(SUMIF('GEM data - Baseline'!$C:$C,'Chart Data'!$Q6,'GEM data - Baseline'!$Q:$Q)/SUMIF('GEM data - Baseline'!$C:$C,'Chart Data'!$Q6,'GEM data - Baseline'!$S:$S)) -> -2.4070169 | S6: =100*(SUMIF('GEM data - Upside'!$C:$C,'Chart Data'!$Q6,'GEM data - Upside'!$Q:$Q)/SUMIF('GEM data - Upside'!$C:$C,'Chart Data'!$Q6,'GEM data - Upside'!$S:$S)) -> -2.4070169 | T6: =100*(SUMIF('GEM data - Zero_net'!$C:$C,'Chart Data'!$Q6,'GEM data - Zero_net'!$Q:$Q)/SUMIF('GEM data - Zero_net'!$C:$C,'Chart Data'!$Q6,'GEM data - Zero_net'!$S:$S)) -> -2.4070169 | V6: 2023 | W6: =100*(SUMIF('GEM data - Baseline'!$D:$D,'Chart Data'!$Q6,'GEM data - Baseline'!$R:$R)/SUMIF('GEM data - Baseline'!$C:$C,'Chart Data'!$Q6,'GEM data - Baseline'!$S:$S)) -> 81.627529 | X6: =100*(SUMIF('GEM data - Upside'!$D:$D,'Chart Data'!$Q6,'GEM data - Upside'!$R:$R)/SUMIF('GEM data - Upside'!$C:$C,'Chart Data'!$Q6,'GEM data - Upside'!$S:$S)) -> 81.627529 | Y6: =100*(SUMIF('GEM data - Zero_net'!$D:$D,'Chart Data'!$Q6,'GEM data - Zero_net'!$R:$R)/SUMIF('GEM data - Zero_net'!$C:$C,'Chart Data'!$Q6,'GEM data - Zero_net'!$S:$S)) -> 81.627529 | AA6: 4 | AB6: =VLOOKUP($AA6,$AE$3:$AG$21,2,FALSE) -> Transport | AC6: =VLOOKUP($AA6,$AE$3:$AG$21,3,FALSE) -> 24.217837 | AE6: =RANK(AG6,$AG$3:$AG$21) -> 16 | AF6: Utilities | AG6: =100*(AL6/AJ6) -> 10.590137 | AI6: UEGAS | AJ6: {=INDEX('HMRC emp by ind and nat'!$A$149:$C$233,MATCH(1,('HMRC emp by ind and nat'!$A$145:$CG$145=AJ$1)*('HMRC emp by ind and nat'!$A$146:$CG$146=$AI6),0),3)} -> 123700 | AK6: {=INDEX('HMRC emp by ind and nat'!$A$149:$C$233,MATCH(1,('HMRC emp by ind and nat'!$A$145:$CG$145=AK$1)*('HMRC emp by ind and nat'!$A$146:$CG$146=$AI6),0),3)} -> 110600 | AL6: =AJ6-AK6 -> 13100 | AP6: 2003 | AQ6: =AVERAGEIF('GEM data - Baseline'!$B:$B,'Chart Data'!$AP6,'GEM data - Baseline'!$AE:$AE) -> 25.725755 | AR6: =AVERAGEIF('GEM data - Upside'!$B:$B,'Chart Data'!$AP6,'GEM data - Upside'!$AE:$AE) -> 25.725755 | AS6: =AVERAGEIF('GEM data - Zero_net'!$B:$B,'Chart Data'!$AP6,'GEM data - Zero_net'!$AE:$AE) -> 25.725755 | AU6: 2003 | AV6: =AVERAGEIF('GEM data - Baseline'!$B:$B,'Chart Data'!$AP6,'GEM data - Baseline'!AE:AE) -> 25.725755 | AW6: =AVERAGEIF('GEM data - Baseline'!$B:$B,'Chart Data'!$AP6,'GEM data - Baseline'!AF:AF) -> 16.210363 | AX6: =AVERAGEIF('GEM data - Baseline'!$B:$B,'Chart Data'!$AP6,'GEM data - Baseline'!AG:AG) -> 28.517777 | AY6: =AVERAGEIF('GEM data - Baseline'!$B:$B,'Chart Data'!$AP6,'GEM data - Baseline'!AH:AH) -> 26.454957 | AZ6: =AVERAGEIF('GEM data - Baseline'!$B:$B,'Chart Data'!$AP6,'GEM data - Baseline'!AI:AI) -> 24.865965 | BA6: =AVERAGEIF('GEM data - Baseline'!$B:$B,'Chart Data'!$AP6,'GEM data - Baseline'!AJ:AJ) -> 30.04239 | BB6: =AVERAGEIF('GEM data - Baseline'!$B:$B,'Chart Data'!$AP6,'GEM data - Baseline'!AK:AK) -> 16.18965 | BF6: =100*(('GEM data - Baseline'!$F170/'GEM data - Baseline'!$F166)-1) -> -7.6436018 | BG6: =100*(('GEM data - Upside'!$F170/'GEM data - Upside'!$F166)-1) -> -7.6436018 | BH6: =100*(('GEM data - Zero_net'!$F170/'GEM data - Zero_net'!$F166)-1) -> -7.6436018 | BK6: =100*(('GEM data - Baseline'!$U170/'GEM data - Baseline'!$U166)-1) -> -3.9425066 | BL6: =100*(('GEM data - Upside'!$U170/'GEM data - Upside'!$U166)-1) -> -3.9425066 | BM6: =100*(('GEM data - Zero_net'!$U170/'GEM data - Zero_net'!$U166)-1) -> -3.9425066 | BP6: ='GEM data - Baseline'!$O170 -> 5.3 | BQ6: ='GEM data - Upside'!$O170 -> 5.3 | BR6: ='GEM data - Zero_net'!$O170 -> 5.3 | BU6: =100*(('GEM data - Baseline'!$L170/'GEM data - Baseline'!$L166)-1) -> -2.3867865 | BV6: =100*(('GEM data - Upside'!$L170/'GEM data - Upside'!$L166)-1) -> -2.3867865 | BW6: =100*(('GEM data - Zero_net'!$L170/'GEM data - Zero_net'!$L166)-1) -> -2.3867865 | BZ6: ='GEM data - Baseline'!$T170 -> -3.113651 | CA6: ='GEM data - Upside'!$T170 -> -3.113651 | CB6: ='GEM data - Zero_net'!$T170 -> -3.113651 | CE6: ='GEM data - Baseline'!$J170 -> 0.1 | CF6: ='GEM data - Upside'!$J170 -> 0.1 | CG6: ='GEM data - Zero_net'!$J170 -> 0.1 | CJ6: =100*(('GEM data - Baseline'!$I170/'GEM data - Baseline'!$I166)-1) -> 0.5841379 | CK6: =100*(('GEM data - Upside'!$I170/'GEM data - Upside'!$I166)-1) -> 0.5841379 | CL6: =100*(('GEM data - Zero_net'!$I170/'GEM data - Zero_net'!$I166)-1) -> 0.5841379 | CO6: =100*('GEM data - Baseline'!$AB170/'GEM data - Baseline'!$AD170) -> 391.39981 | CP6: =100*('GEM data - Upside'!$AB170/'GEM data - Upside'!$AD170) -> 391.39981 | CQ6: =100*('GEM data - Zero_net'!$AB170/'GEM data - Zero_net'!$AD170) -> 391.39981 | CT6: =100*('GEM data - Baseline'!$AC170/'GEM data - Baseline'!$AD170) -> 296.78278 | CU6: =100*('GEM data - Upside'!$AC170/'GEM data - Upside'!$AD170) -> 296.78278 | CV6: =100*('GEM data - Zero_net'!$AC170/'GEM data - Zero_net'!$AD170) -> 296.78278 | CY6: =100*('GEM data - Baseline'!$F170/'GEM data - Baseline'!$AD170) -> 926.32256 | CZ6: =100*('GEM data - Upside'!$F170/'GEM data - Upside'!$AD170) -> 926.32256 | DA6: =100*('GEM data - Zero_net'!$F170/'GEM data - Zero_net'!$AD170) -> 926.32256 | DC6: 1983 | DD6: =SUMIF('GEM data - Baseline'!$B:$B,'Chart Data'!$DC6,'GEM data - Baseline'!$U:$U) -> 1209349.6 | DE6: =AVERAGEIF('GEM data - Baseline'!$B:$B,'Chart Data'!$DC6,'GEM data - Baseline'!$V:$V) -> 24304.682 | DF6: =AVERAGEIF('GEM data - Baseline'!$B:$B,'Chart Data'!$DC6,'GEM data - Baseline'!$W:$W) -> 0.001 | DG6: =AVERAGEIF('GEM data - Baseline'!$B:$B,'Chart Data'!$DC6,'GEM data - Baseline'!$X:$X) -> 314668.83 | DH6: =AVERAGEIF('GEM data - Baseline'!$B:$B,'Chart Data'!$DC6,'GEM data - Baseline'!$Y:$Y) -> 36776.192 | DI6: =AVERAGEIF('GEM data - Baseline'!$B:$B,'Chart Data'!$DC6,'GEM data - Baseline'!$Z:$Z) -> 1266603.5 | DJ6: =AVERAGEIF('GEM data - Baseline'!$B:$B,'Chart Data'!$DC6,'GEM data - Baseline'!$AA:$AA) -> -1.7896025 | DL6: =DE6*DF6 -> 24.304682 | DM6: =DG6/DH6 -> 8.5563187 | DN6: =DI6 -> 1266603.5 | DO6: =DJ6 -> -1.7896025 | DP6: =DD6 -> 1209349.6 | DQ6: =SUMIF('GEM data - Baseline'!$B:$B,'Chart Data'!$DC6,'GEM data - Baseline'!$F:$F) -> 1205632 | DS6: =100*((DP6/DP5)-1) -> 1.6729402 | DT6: =100*((DQ6/DQ5)-1) -> 4.1860851 | DV6: 1983 | DW6: =SUMIF('GEM data - Upside'!$B:$B,'Chart Data'!$DC6,'GEM data - Upside'!$U:$U) -> 1209349.6 | DX6: =AVERAGEIF('GEM data - Upside'!$B:$B,'Chart Data'!$DC6,'GEM data - Upside'!$V:$V) -> 24304.682 | DY6: =AVERAGEIF('GEM data - Upside'!$B:$B,'Chart Data'!$DC6,'GEM data - Upside'!$W:$W) -> 0.001 | DZ6: =AVERAGEIF('GEM data - Upside'!$B:$B,'Chart Data'!$DC6,'GEM data - Upside'!$X:$X) -> 314668.83 | EA6: =AVERAGEIF('GEM data - Upside'!$B:$B,'Chart Data'!$DC6,'GEM data - Upside'!$Y:$Y) -> 36776.192 | EB6: =AVERAGEIF('GEM data - Upside'!$B:$B,'Chart Data'!$DC6,'GEM data - Upside'!$Z:$Z) -> 1266603.5 | EC6: =AVERAGEIF('GEM data - Upside'!$B:$B,'Chart Data'!$DC6,'GEM data - Upside'!$AA:$AA) -> -1.7896025 | EE6: =DX6*DY6 -> 24.304682 | EF6: =DZ6/EA6 -> 8.5563187 | EG6: =EB6 -> 1266603.5 | EH6: =EC6 -> -1.7896025 | EI6: =DW6 -> 1209349.6 | EJ6: =SUMIF('GEM data - Upside'!$B:$B,'Chart Data'!$DC6,'GEM data - Upside'!$F:$F) -> 1205632 | EL6: =100*((EI6/EI5)-1) -> 1.6729402 | EM6: =100*((EJ6/EJ5)-1) -> 4.1860851 | EO6: 1983 | EP6: =SUMIF('GEM data - Zero_net'!$B:$B,'Chart Data'!$DC6,'GEM data - Zero_net'!$U:$U) -> 1209349.6 | EQ6: =AVERAGEIF('GEM data - Zero_net'!$B:$B,'Chart Data'!$DC6,'GEM data - Zero_net'!$V:$V) -> 24304.682 | ER6: =AVERAGEIF('GEM data - Zero_net'!$B:$B,'Chart Data'!$DC6,'GEM data - Zero_net'!$W:$W) -> 0.001 | ES6: =AVERAGEIF('GEM data - Zero_net'!$B:$B,'Chart Data'!$DC6,'GEM data - Zero_net'!$X:$X) -> 314668.83 | ET6: =AVERAGEIF('GEM data - Zero_net'!$B:$B,'Chart Data'!$DC6,'GEM data - Zero_net'!$Y:$Y) -> 36776.192 | EU6: =AVERAGEIF('GEM data - Zero_net'!$B:$B,'Chart Data'!$DC6,'GEM data - Zero_net'!$Z:$Z) -> 1266603.5 | EV6: =AVERAGEIF('GEM data - Zero_net'!$B:$B,'Chart Data'!$DC6,'GEM data - Zero_net'!$AA:$AA) -> -1.7896025 | EX6: =EQ6*ER6 -> 24.304682 | EY6: =ES6/ET6 -> 8.5563187 | EZ6: =EU6 -> 1266603.5 | FA6: =EV6 -> -1.7896025 | FB6: =EP6 -> 1209349.6 | FC6: =SUMIF('GEM data - Zero_net'!$B:$B,'Chart Data'!$DC6,'GEM data - Zero_net'!$F:$F) -> 1205632 | FE6: =100*((FB6/FB5)-1) -> 1.6729402 | FF6: =100*((FC6/FC5)-1) -> 4.1860851
A7: 2021 | B7: ='GEM data - Baseline'!$F171 -> 612665 | C7: ='GEM data - Upside'!$F171 -> 612665 | D7: ='GEM data - Zero_net'!$F171 -> 612665 | F7: 2004 | G7: ='[2]Chart Data'!M8 -> 209.5 | L7: 2021 | M7: =100*(('GEM data - Baseline'!$P171/'GEM data - Baseline'!$P167)-1) -> 0.63536161 | N7: =100*(('GEM data - Upside'!$P171/'GEM data - Upside'!$P167)-1) -> 0.63536161 | O7: =100*(('GEM data - Zero_net'!$P171/'GEM data - Zero_net'!$P167)-1) -> 0.63536161 | Q7: 2024 | R7: =100*(SUMIF('GEM data - Baseline'!$C:$C,'Chart Data'!$Q7,'GEM data - Baseline'!$Q:$Q)/SUMIF('GEM data - Baseline'!$C:$C,'Chart Data'!$Q7,'GEM data - Baseline'!$S:$S)) -> -2.5903661 | S7: =100*(SUMIF('GEM data - Upside'!$C:$C,'Chart Data'!$Q7,'GEM data - Upside'!$Q:$Q)/SUMIF('GEM data - Upside'!$C:$C,'Chart Data'!$Q7,'GEM data - Upside'!$S:$S)) -> -2.5903661 | T7: =100*(SUMIF('GEM data - Zero_net'!$C:$C,'Chart Data'!$Q7,'GEM data - Zero_net'!$Q:$Q)/SUMIF('GEM data - Zero_net'!$C:$C,'Chart Data'!$Q7,'GEM data - Zero_net'!$S:$S)) -> -2.5903661 | V7: 2024 | W7: =100*(SUMIF('GEM data - Baseline'!$D:$D,'Chart Data'!$Q7,'GEM data - Baseline'!$R:$R)/SUMIF('GEM data - Baseline'!$C:$C,'Chart Data'!$Q7,'GEM data - Baseline'!$S:$S)) -> 83.085282 | X7: =100*(SUMIF('GEM data - Upside'!$D:$D,'Chart Data'!$Q7,'GEM data - Upside'!$R:$R)/SUMIF('GEM data - Upside'!$C:$C,'Chart Data'!$Q7,'GEM data - Upside'!$S:$S)) -> 83.085282 | Y7: =100*(SUMIF('GEM data - Zero_net'!$D:$D,'Chart Data'!$Q7,'GEM data - Zero_net'!$R:$R)/SUMIF('GEM data - Zero_net'!$C:$C,'Chart Data'!$Q7,'GEM data - Zero_net'!$S:$S)) -> 83.085282 | AA7: 5 | AB7: =VLOOKUP($AA7,$AE$3:$AG$21,2,FALSE) -> Communications | AC7: =VLOOKUP($AA7,$AE$3:$AG$21,3,FALSE) -> 22.034733 | AE7: =RANK(AG7,$AG$3:$AG$21) -> 15 | AF7: Water | AG7: =100*(AL7/AJ7) -> 10.725356 | AI7: UWSWM | AJ7: {=INDEX('HMRC emp by ind and nat'!$A$149:$C$233,MATCH(1,('HMRC emp by ind and nat'!$A$145:$CG$145=AJ$1)*('HMRC emp by ind and nat'!$A$146:$CG$146=$AI7),0),3)} -> 215066.67 | AK7: {=INDEX('HMRC emp by ind and nat'!$A$149:$C$233,MATCH(1,('HMRC emp by ind and nat'!$A$145:$CG$145=AK$1)*('HMRC emp by ind and nat'!$A$146:$CG$146=$AI7),0),3)} -> 192000 | AL7: =AJ7-AK7 -> 23066.667 | AP7: 2004 | AQ7: =AVERAGEIF('GEM data - Baseline'!$B:$B,'Chart Data'!$AP7,'GEM data - Baseline'!$AE:$AE) -> 25.696 | AR7: =AVERAGEIF('GEM data - Upside'!$B:$B,'Chart Data'!$AP7,'GEM data - Upside'!$AE:$AE) -> 25.696 | AS7: =AVERAGEIF('GEM data - Zero_net'!$B:$B,'Chart Data'!$AP7,'GEM data - Zero_net'!$AE:$AE) -> 25.696 | AU7: 2004 | AV7: =AVERAGEIF('GEM data - Baseline'!$B:$B,'Chart Data'!$AP7,'GEM data - Baseline'!AE:AE) -> 25.696 | AW7: =AVERAGEIF('GEM data - Baseline'!$B:$B,'Chart Data'!$AP7,'GEM data - Baseline'!AF:AF) -> 16.207178 | AX7: =AVERAGEIF('GEM data - Baseline'!$B:$B,'Chart Data'!$AP7,'GEM data - Baseline'!AG:AG) -> 29.490485 | AY7: =AVERAGEIF('GEM data - Baseline'!$B:$B,'Chart Data'!$AP7,'GEM data - Baseline'!AH:AH) -> 26.54218 | AZ7: =AVERAGEIF('GEM data - Baseline'!$B:$B,'Chart Data'!$AP7,'GEM data - Baseline'!AI:AI) -> 25.00869 | BA7: =AVERAGEIF('GEM data - Baseline'!$B:$B,'Chart Data'!$AP7,'GEM data - Baseline'!AJ:AJ) -> 30.534055 | BB7: =AVERAGEIF('GEM data - Baseline'!$B:$B,'Chart Data'!$AP7,'GEM data - Baseline'!AK:AK) -> 16.277442 | BE7: 2021 | BF7: =100*(('GEM data - Baseline'!$F171/'GEM data - Baseline'!$F167)-1) -> -6.0589101 | BG7: =100*(('GEM data - Upside'!$F171/'GEM data - Upside'!$F167)-1) -> -6.0589101 | BH7: =100*(('GEM data - Zero_net'!$F171/'GEM data - Zero_net'!$F167)-1) -> -6.0589101 | BJ7: 2021 | BK7: =100*(('GEM data - Baseline'!$U171/'GEM data - Baseline'!$U167)-1) -> -4.5221023 | BL7: =100*(('GEM data - Upside'!$U171/'GEM data - Upside'!$U167)-1) -> -4.5221023 | BM7: =100*(('GEM data - Zero_net'!$U171/'GEM data - Zero_net'!$U167)-1) -> -4.5221023 | BO7: 2021 | BP7: ='GEM data - Baseline'!$O171 -> 4.9 | BQ7: ='GEM data - Upside'!$O171 -> 4.9 | BR7: ='GEM data - Zero_net'!$O171 -> 4.9 | BT7: 2021 | BU7: =100*(('GEM data - Baseline'!$L171/'GEM data - Baseline'!$L167)-1) -> -2.0075206 | BV7: =100*(('GEM data - Upside'!$L171/'GEM data - Upside'!$L167)-1) -> -2.0075206 | BW7: =100*(('GEM data - Zero_net'!$L171/'GEM data - Zero_net'!$L167)-1) -> -2.0075206 | BY7: 2021 | BZ7: ='GEM data - Baseline'!$T171 -> -2.577209 | CA7: ='GEM data - Upside'!$T171 -> -2.577209 | CB7: ='GEM data - Zero_net'!$T171 -> -2.577209 | CD7: 2021 | CE7: ='GEM data - Baseline'!$J171 -> 0.1 | CF7: ='GEM data - Upside'!$J171 -> 0.1 | CG7: ='GEM data - Zero_net'!$J171 -> 0.1 | CI7: 2021 | CJ7: =100*(('GEM data - Baseline'!$I171/'GEM data - Baseline'!$I167)-1) -> 0.64535936 | CK7: =100*(('GEM data - Upside'!$I171/'GEM data - Upside'!$I167)-1) -> 0.64535936 | CL7: =100*(('GEM data - Zero_net'!$I171/'GEM data - Zero_net'!$I167)-1) -> 0.64535936 | CN7: 2021 | CO7: =100*('GEM data - Baseline'!$AB171/'GEM data - Baseline'!$AD171) -> 412.61833 | CP7: =100*('GEM data - Upside'!$AB171/'GEM data - Upside'!$AD171) -> 412.61833 | CQ7: =100*('GEM data - Zero_net'!$AB171/'GEM data - Zero_net'!$AD171) -> 412.61833 | CS7: 2021 | CT7: =100*('GEM data - Baseline'!$AC171/'GEM data - Baseline'!$AD171) -> 350.49949 | CU7: =100*('GEM data - Upside'!$AC171/'GEM data - Upside'!$AD171) -> 350.49949 | CV7: =100*('GEM data - Zero_net'!$AC171/'GEM data - Zero_net'!$AD171) -> 350.49949 | CX7: 2021 | CY7: =100*('GEM data - Baseline'!$F171/'GEM data - Baseline'!$AD171) -> 915.53905 | CZ7: =100*('GEM data - Upside'!$F171/'GEM data - Upside'!$AD171) -> 915.53905 | DA7: =100*('GEM data - Zero_net'!$F171/'GEM data - Zero_net'!$AD171) -> 915.53905 | DC7: 1984 | DD7: =SUMIF('GEM data - Baseline'!$B:$B,'Chart Data'!$DC7,'GEM data - Baseline'!$U:$U) -> 1251974.1 | DE7: =AVERAGEIF('GEM data - Baseline'!$B:$B,'Chart Data'!$DC7,'GEM data - Baseline'!$V:$V) -> 24910.802 | DF7: =AVERAGEIF('GEM data - Baseline'!$B:$B,'Chart Data'!$DC7,'GEM data - Baseline'!$W:$W) -> 0.001 | DG7: =AVERAGEIF('GEM data - Baseline'!$B:$B,'Chart Data'!$DC7,'GEM data - Baseline'!$X:$X) -> 318382.53 | DH7: =AVERAGEIF('GEM data - Baseline'!$B:$B,'Chart Data'!$DC7,'GEM data - Baseline'!$Y:$Y) -> 37029.132 | DI7: =AVERAGEIF('GEM data - Baseline'!$B:$B,'Chart Data'!$DC7,'GEM data - Baseline'!$Z:$Z) -> 1286788 | DJ7: =AVERAGEIF('GEM data - Baseline'!$B:$B,'Chart Data'!$DC7,'GEM data - Baseline'!$AA:$AA) -> -1.7772407 | DL7: =DE7*DF7 -> 24.910802 | DM7: =DG7/DH7 -> 8.5981632 | DN7: =DI7 -> 1286788 | DO7: =DJ7 -> -1.7772407 | DP7: =DD7 -> 1251974.1 | DQ7: =SUMIF('GEM data - Baseline'!$B:$B,'Chart Data'!$DC7,'GEM data - Baseline'!$F:$F) -> 1232675 | DS7: =100*((DP7/DP6)-1) -> 3.5245805 | DT7: =100*((DQ7/DQ6)-1) -> 2.2430559 | DV7: 1984 | DW7: =SUMIF('GEM data - Upside'!$B:$B,'Chart Data'!$DC7,'GEM data - Upside'!$U:$U) -> 1251974.1 | DX7: =AVERAGEIF('GEM data - Upside'!$B:$B,'Chart Data'!$DC7,'GEM data - Upside'!$V:$V) -> 24910.802 | DY7: =AVERAGEIF('GEM data - Upside'!$B:$B,'Chart Data'!$DC7,'GEM data - Upside'!$W:$W) -> 0.001 | DZ7: =AVERAGEIF('GEM data - Upside'!$B:$B,'Chart Data'!$DC7,'GEM data - Upside'!$X:$X) -> 318382.53 | EA7: =AVERAGEIF('GEM data - Upside'!$B:$B,'Chart Data'!$DC7,'GEM data - Upside'!$Y:$Y) -> 37029.132 | EB7: =AVERAGEIF('GEM data - Upside'!$B:$B,'Chart Data'!$DC7,'GEM data - Upside'!$Z:$Z) -> 1286788 | EC7: =AVERAGEIF('GEM data - Upside'!$B:$B,'Chart Data'!$DC7,'GEM data - Upside'!$AA:$AA) -> -1.7772407 | EE7: =DX7*DY7 -> 24.910802 | EF7: =DZ7/EA7 -> 8.5981632 | EG7: =EB7 -> 1286788 | EH7: =EC7 -> -1.7772407 | EI7: =DW7 -> 1251974.1 | EJ7: =SUMIF('GEM data - Upside'!$B:$B,'Chart Data'!$DC7,'GEM data - Upside'!$F:$F) -> 1232675 | EL7: =100*((EI7/EI6)-1) -> 3.5245805 | EM7: =100*((EJ7/EJ6)-1) -> 2.2430559 | EO7: 1984 | EP7: =SUMIF('GEM data - Zero_net'!$B:$B,'Chart Data'!$DC7,'GEM data - Zero_net'!$U:$U) -> 1251974.1 | EQ7: =AVERAGEIF('GEM data - Zero_net'!$B:$B,'Chart Data'!$DC7,'GEM data - Zero_net'!$V:$V) -> 24910.802 | ER7: =AVERAGEIF('GEM data - Zero_net'!$B:$B,'Chart Data'!$DC7,'GEM data - Zero_net'!$W:$W) -> 0.001 | ES7: =AVERAGEIF('GEM data - Zero_net'!$B:$B,'Chart Data'!$DC7,'GEM data - Zero_net'!$X:$X) -> 318382.53 | ET7: =AVERAGEIF('GEM data - Zero_net'!$B:$B,'Chart Data'!$DC7,'GEM data - Zero_net'!$Y:$Y) -> 37029.132 | EU7: =AVERAGEIF('GEM data - Zero_net'!$B:$B,'Chart Data'!$DC7,'GEM data - Zero_net'!$Z:$Z) -> 1286788 | EV7: =AVERAGEIF('GEM data - Zero_net'!$B:$B,'Chart Data'!$DC7,'GEM data - Zero_net'!$AA:$AA) -> -1.7772407 | EX7: =EQ7*ER7 -> 24.910802 | EY7: =ES7/ET7 -> 8.5981632 | EZ7: =EU7 -> 1286788 | FA7: =EV7 -> -1.7772407 | FB7: =EP7 -> 1251974.1 | FC7: =SUMIF('GEM data - Zero_net'!$B:$B,'Chart Data'!$DC7,'GEM data - Zero_net'!$F:$F) -> 1232675 | FE7: =100*((FB7/FB6)-1) -> 3.5245805 | FF7: =100*((FC7/FC6)-1) -> 2.2430559
B8: ='GEM data - Baseline'!$F172 -> 655443 | C8: ='GEM data - Upside'!$F172 -> 655443 | D8: ='GEM data - Zero_net'!$F172 -> 655443 | F8: 2005 | G8: ='[2]Chart Data'!M9 -> 335.6 | M8: =100*(('GEM data - Baseline'!$P172/'GEM data - Baseline'!$P168)-1) -> 0.54204657 | N8: =100*(('GEM data - Upside'!$P172/'GEM data - Upside'!$P168)-1) -> 0.54204657 | O8: =100*(('GEM data - Zero_net'!$P172/'GEM data - Zero_net'!$P168)-1) -> 0.54204657 | Q8: 2025 | R8: =100*(SUMIF('GEM data - Baseline'!$C:$C,'Chart Data'!$Q8,'GEM data - Baseline'!$Q:$Q)/SUMIF('GEM data - Baseline'!$C:$C,'Chart Data'!$Q8,'GEM data - Baseline'!$S:$S)) -> -1.8835895 | S8: =100*(SUMIF('GEM data - Upside'!$C:$C,'Chart Data'!$Q8,'GEM data - Upside'!$Q:$Q)/SUMIF('GEM data - Upside'!$C:$C,'Chart Data'!$Q8,'GEM data - Upside'!$S:$S)) -> -1.9093813 | T8: =100*(SUMIF('GEM data - Zero_net'!$C:$C,'Chart Data'!$Q8,'GEM data - Zero_net'!$Q:$Q)/SUMIF('GEM data - Zero_net'!$C:$C,'Chart Data'!$Q8,'GEM data - Zero_net'!$S:$S)) -> -1.9302828 | V8: 2025 | W8: =100*(SUMIF('GEM data - Baseline'!$D:$D,'Chart Data'!$Q8,'GEM data - Baseline'!$R:$R)/SUMIF('GEM data - Baseline'!$C:$C,'Chart Data'!$Q8,'GEM data - Baseline'!$S:$S)) -> 83.419912 | X8: =100*(SUMIF('GEM data - Upside'!$D:$D,'Chart Data'!$Q8,'GEM data - Upside'!$R:$R)/SUMIF('GEM data - Upside'!$C:$C,'Chart Data'!$Q8,'GEM data - Upside'!$S:$S)) -> 83.453237 | Y8: =100*(SUMIF('GEM data - Zero_net'!$D:$D,'Chart Data'!$Q8,'GEM data - Zero_net'!$R:$R)/SUMIF('GEM data - Zero_net'!$C:$C,'Chart Data'!$Q8,'GEM data - Zero_net'!$S:$S)) -> 83.523154 | AA8: 6 | AB8: =VLOOKUP($AA8,$AE$3:$AG$21,2,FALSE) -> Other services | AC8: =VLOOKUP($AA8,$AE$3:$AG$21,3,FALSE) -> 20.636898 | AE8: =RANK(AG8,$AG$3:$AG$21) -> 14 | AF8: Construction | AG8: =100*(AL8/AJ8) -> 12.079649 | AI8: CON | AJ8: {=INDEX('HMRC emp by ind and nat'!$A$149:$C$233,MATCH(1,('HMRC emp by ind and nat'!$A$145:$CG$145=AJ$1)*('HMRC emp by ind and nat'!$A$146:$CG$146=$AI8),0),3)} -> 1360966.7 | AK8: {=INDEX('HMRC emp by ind and nat'!$A$149:$C$233,MATCH(1,('HMRC emp by ind and nat'!$A$145:$CG$145=AK$1)*('HMRC emp by ind and nat'!$A$146:$CG$146=$AI8),0),3)} -> 1196566.7 | AL8: =AJ8-AK8 -> 164400 | AP8: 2005 | AQ8: =AVERAGEIF('GEM data - Baseline'!$B:$B,'Chart Data'!$AP8,'GEM data - Baseline'!$AE:$AE) -> 25.608593 | AR8: =AVERAGEIF('GEM data - Upside'!$B:$B,'Chart Data'!$AP8,'GEM data - Upside'!$AE:$AE) -> 25.608593 | AS8: =AVERAGEIF('GEM data - Zero_net'!$B:$B,'Chart Data'!$AP8,'GEM data - Zero_net'!$AE:$AE) -> 25.608593 | AU8: 2005 | AV8: =AVERAGEIF('GEM data - Baseline'!$B:$B,'Chart Data'!$AP8,'GEM data - Baseline'!AE:AE) -> 25.608593 | AW8: =AVERAGEIF('GEM data - Baseline'!$B:$B,'Chart Data'!$AP8,'GEM data - Baseline'!AF:AF) -> 16.201367 | AX8: =AVERAGEIF('GEM data - Baseline'!$B:$B,'Chart Data'!$AP8,'GEM data - Baseline'!AG:AG) -> 30.746955 | AY8: =AVERAGEIF('GEM data - Baseline'!$B:$B,'Chart Data'!$AP8,'GEM data - Baseline'!AH:AH) -> 27.96087 | AZ8: =AVERAGEIF('GEM data - Baseline'!$B:$B,'Chart Data'!$AP8,'GEM data - Baseline'!AI:AI) -> 25.104933 | BA8: =AVERAGEIF('GEM data - Baseline'!$B:$B,'Chart Data'!$AP8,'GEM data - Baseline'!AJ:AJ) -> 31.127795 | BB8: =AVERAGEIF('GEM data - Baseline'!$B:$B,'Chart Data'!$AP8,'GEM data - Baseline'!AK:AK) -> 16.360055 | BF8: =100*(('GEM data - Baseline'!$F172/'GEM data - Baseline'!$F168)-1) -> 25.478218 | BG8: =100*(('GEM data - Upside'!$F172/'GEM data - Upside'!$F168)-1) -> 25.478218 | BH8: =100*(('GEM data - Zero_net'!$F172/'GEM data - Zero_net'!$F168)-1) -> 25.478218 | BK8: =100*(('GEM data - Baseline'!$U172/'GEM data - Baseline'!$U168)-1) -> 12.597205 | BL8: =100*(('GEM data - Upside'!$U172/'GEM data - Upside'!$U168)-1) -> 12.597205 | BM8: =100*(('GEM data - Zero_net'!$U172/'GEM data - Zero_net'!$U168)-1) -> 12.597205 | BP8: ='GEM data - Baseline'!$O172 -> 4.7 | BQ8: ='GEM data - Upside'!$O172 -> 4.7 | BR8: ='GEM data - Zero_net'!$O172 -> 4.7 | BU8: =100*(('GEM data - Baseline'!$L172/'GEM data - Baseline'!$L168)-1) -> -0.56382914 | BV8: =100*(('GEM data - Upside'!$L172/'GEM data - Upside'!$L168)-1) -> -0.56382914 | BW8: =100*(('GEM data - Zero_net'!$L172/'GEM data - Zero_net'!$L168)-1) -> -0.56382914 | BZ8: ='GEM data - Baseline'!$T172 -> 0.6524086 | CA8: ='GEM data - Upside'!$T172 -> 0.6524086 | CB8: ='GEM data - Zero_net'!$T172 -> 0.6524086 | CE8: ='GEM data - Baseline'!$J172 -> 0.1 | CF8: ='GEM data - Upside'!$J172 -> 0.1 | CG8: ='GEM data - Zero_net'!$J172 -> 0.1 | CJ8: =100*(('GEM data - Baseline'!$I172/'GEM data - Baseline'!$I168)-1) -> 2.0270276 | CK8: =100*(('GEM data - Upside'!$I172/'GEM data - Upside'!$I168)-1) -> 2.0270276 | CL8: =100*(('GEM data - Zero_net'!$I172/'GEM data - Zero_net'!$I168)-1) -> 2.0270276 | CO8: =100*('GEM data - Baseline'!$AB172/'GEM data - Baseline'!$AD172) -> 393.9189 | CP8: =100*('GEM data - Upside'!$AB172/'GEM data - Upside'!$AD172) -> 393.9189 | CQ8: =100*('GEM data - Zero_net'!$AB172/'GEM data - Zero_net'!$AD172) -> 393.9189 | CT8: =100*('GEM data - Baseline'!$AC172/'GEM data - Baseline'!$AD172) -> 305.28084 | CU8: =100*('GEM data - Upside'!$AC172/'GEM data - Upside'!$AD172) -> 305.28084 | CV8: =100*('GEM data - Zero_net'!$AC172/'GEM data - Zero_net'!$AD172) -> 305.28084 | CY8: =100*('GEM data - Baseline'!$F172/'GEM data - Baseline'!$AD172) -> 978.59446 | CZ8: =100*('GEM data - Upside'!$F172/'GEM data - Upside'!$AD172) -> 978.59446 | DA8: =100*('GEM data - Zero_net'!$F172/'GEM data - Zero_net'!$AD172) -> 978.59446 | DC8: 1985 | DD8: =SUMIF('GEM data - Baseline'!$B:$B,'Chart Data'!$DC8,'GEM data - Baseline'!$U:$U) -> 1287059.7 | DE8: =AVERAGEIF('GEM data - Baseline'!$B:$B,'Chart Data'!$DC8,'GEM data - Baseline'!$V:$V) -> 25107.865 | DF8: =AVERAGEIF('GEM data - Baseline'!$B:$B,'Chart Data'!$DC8,'GEM data - Baseline'!$W:$W) -> 0.001 | DG8: =AVERAGEIF('GEM data - Baseline'!$B:$B,'Chart Data'!$DC8,'GEM data - Baseline'!$X:$X) -> 322872.05 | DH8: =AVERAGEIF('GEM data - Baseline'!$B:$B,'Chart Data'!$DC8,'GEM data - Baseline'!$Y:$Y) -> 37116.963 | DI8: =AVERAGEIF('GEM data - Baseline'!$B:$B,'Chart Data'!$DC8,'GEM data - Baseline'!$Z:$Z) -> 1312207.8 | DJ8: =AVERAGEIF('GEM data - Baseline'!$B:$B,'Chart Data'!$DC8,'GEM data - Baseline'!$AA:$AA) -> -1.764964 | DL8: =DE8*DF8 -> 25.107865 | DM8: =DG8/DH8 -> 8.6987735 | DN8: =DI8 -> 1312207.8 | DO8: =DJ8 -> -1.764964 | DP8: =DD8 -> 1287059.7 | DQ8: =SUMIF('GEM data - Baseline'!$B:$B,'Chart Data'!$DC8,'GEM data - Baseline'!$F:$F) -> 1283200 | DS8: =100*((DP8/DP7)-1) -> 2.8024222 | DT8: =100*((DQ8/DQ7)-1) -> 4.0988095 | DV8: 1985 | DW8: =SUMIF('GEM data - Upside'!$B:$B,'Chart Data'!$DC8,'GEM data - Upside'!$U:$U) -> 1287059.7 | DX8: =AVERAGEIF('GEM data - Upside'!$B:$B,'Chart Data'!$DC8,'GEM data - Upside'!$V:$V) -> 25107.865 | DY8: =AVERAGEIF('GEM data - Upside'!$B:$B,'Chart Data'!$DC8,'GEM data - Upside'!$W:$W) -> 0.001 | DZ8: =AVERAGEIF('GEM data - Upside'!$B:$B,'Chart Data'!$DC8,'GEM data - Upside'!$X:$X) -> 322872.05 | EA8: =AVERAGEIF('GEM data - Upside'!$B:$B,'Chart Data'!$DC8,'GEM data - Upside'!$Y:$Y) -> 37116.963 | EB8: =AVERAGEIF('GEM data - Upside'!$B:$B,'Chart Data'!$DC8,'GEM data - Upside'!$Z:$Z) -> 1312207.8 | EC8: =AVERAGEIF('GEM data - Upside'!$B:$B,'Chart Data'!$DC8,'GEM data - Upside'!$AA:$AA) -> -1.764964 | EE8: =DX8*DY8 -> 25.107865 | EF8: =DZ8/EA8 -> 8.6987735 | EG8: =EB8 -> 1312207.8 | EH8: =EC8 -> -1.764964 | EI8: =DW8 -> 1287059.7 | EJ8: =SUMIF('GEM data - Upside'!$B:$B,'Chart Data'!$DC8,'GEM data - Upside'!$F:$F) -> 1283200 | EL8: =100*((EI8/EI7)-1) -> 2.8024222 | EM8: =100*((EJ8/EJ7)-1) -> 4.0988095 | EO8: 1985 | EP8: =SUMIF('GEM data - Zero_net'!$B:$B,'Chart Data'!$DC8,'GEM data - Zero_net'!$U:$U) -> 1287059.7 | EQ8: =AVERAGEIF('GEM data - Zero_net'!$B:$B,'Chart Data'!$DC8,'GEM data - Zero_net'!$V:$V) -> 25107.865 | ER8: =AVERAGEIF('GEM data - Zero_net'!$B:$B,'Chart Data'!$DC8,'GEM data - Zero_net'!$W:$W) -> 0.001 | ES8: =AVERAGEIF('GEM data - Zero_net'!$B:$B,'Chart Data'!$DC8,'GEM data - Zero_net'!$X:$X) -> 322872.05 | ET8: =AVERAGEIF('GEM data - Zero_net'!$B:$B,'Chart Data'!$DC8,'GEM data - Zero_net'!$Y:$Y) -> 37116.963 | EU8: =AVERAGEIF('GEM data - Zero_net'!$B:$B,'Chart Data'!$DC8,'GEM data - Zero_net'!$Z:$Z) -> 1312207.8 | EV8: =AVERAGEIF('GEM data - Zero_net'!$B:$B,'Chart Data'!$DC8,'GEM data - Zero_net'!$AA:$AA) -> -1.764964 | EX8: =EQ8*ER8 -> 25.107865 | EY8: =ES8/ET8 -> 8.6987735 | EZ8: =EU8 -> 1312207.8 | FA8: =EV8 -> -1.764964 | FB8: =EP8 -> 1287059.7 | FC8: =SUMIF('GEM data - Zero_net'!$B:$B,'Chart Data'!$DC8,'GEM data - Zero_net'!$F:$F) -> 1283200 | FE8: =100*((FB8/FB7)-1) -> 2.8024222 | FF8: =100*((FC8/FC7)-1) -> 4.0988095
