Workbook
Name _DLX1.INC: HAVERM!$A$1:$G$6
Name _DLX2.INC: HAVERQ!$A$1:$E$6
Name Data: [1]sheet0!$C$2

Sheet CHARTS>>

Sheet DATA>>

Sheet Chart Data
A1: Potential output | L1: Net inward migration | R1: Population | Y1: Components of net inflows | AE1: Inflows aggregated | AN1: Inflows | BV1: Outflows aggregated | CE1: Outfflows | DM1: GDP forecast comparison | DT1: Working age population | EA1: Inactivity | EH1: Age profile of population | FW1: Output per worker long-term (5yr ma) | GL1: OBR YHAT calculations | GZ1: GDP forecasts - LT (2023=100)
AO2: Total | BC2: EU+ | BK2: Non-EU+ | CF2: Total | CI2: Total | CT2: EU+ | DB2: Non-EU+ | DU2: Working age population (LHS) | DX2: State pension age - males (RHS) | DY2: State pension age - females (RHS) | EE2: Levels | GM2: Baseline - growth | GP2: Baseline - levels | GT2: New OBR | HF2: growth rates
B3: ESTAR * AVHR | C3: EDUC / POP15_64 | D3: K | E3: TREND | F3: YHAT | G3: GDP | I3: Potential output | J3: GDP | M3: OE (Feb26) | N3: ONS principal projection (Jan25) | O3: ONS migration category variant (Jan25) | P3: OBR (Nov25) | S3: OE (Feb26) | T3: ONS principal projection (Jan25) | U3: ONS migration category variant (Jan25) | V3: OBR (Nov25) | W3: OBR Fys | Z3: Inflows | AA3: Outflows | AB3: Net inflows | AC3: Net inflows check | AF3: Work | AG3: Study | AH3: Dependents | AI3: Family | AJ3: British | AK3: Other | AL3: check | AO3: Brit+EU++Non-eu+ | AP3: Other | AQ3: British | AR3: All reasons | AS3: Work: Main applicant | AT3: Work: Dependant | AU3: Study: Main applicant | AV3: Study: Dependant | AW3: Family | AX3: Humanitarian | AY3: Asylum | AZ3: Other | BA3: check | BC3: All reasons | BD3: Work: Main applicant | BE3: Work: Dependant | BF3: Study: Main applicant | BG3: Study: Dependant | BH3: Family | BI3: check | BK3: All reasons | BL3: Work: Main applicant | BM3: Work: Dependant | BN3: Study: Main applicant | BO3: Study: Dependant | BP3: Family | BQ3: Humanitarian | BR3: Asylum | BS3: Other | BT3: check | BW3: Work | BX3: Study | BY3: Dependents | BZ3: Family | CA3: British | CB3: Other | CC3: check | CF3: Brit+EU++Non-eu+ | CG3: Other | CH3: British | CI3: All reasons | CJ3: Work: Main applicant | CK3: Work: Dependant | CL3: Study: Main applicant | CM3: Study: Dependant | CN3: Family | CO3: Humanitarian | CP3: Asylum | CQ3: Other | CR3: check | CT3: All reasons | CU3: Work: Main applicant | CV3: Work: Dependant | CW3: Study: Main applicant | CX3: Study: Dependant | CY3: Family | CZ3: check | DB3: All reasons | DC3: Work: Main applicant | DD3: Work: Dependant | DE3: Study: Main applicant | DF3: Study: Dependant | DG3: Family | DH3: Humanitarian | DI3: Asylum | DJ3: Other | DK3: check | DN3: OE | DO3: OBR | DP3: Consensus | DQ3: Consensus low | DR3: Consensus range | DU3: Working age population | DV3: Rolling 10 year average | DW3: ZERO LINE | DX3: State pension age - males | DY3: State pension age - females | EB3: % of inactive | EC3: Average 1993-2025 | EE3: LT sick | EF3: Other | EI3: 2022 | EJ3: 2023 | EK3: 2024 | EL3: 2025 | EM3: 2026 | EN3: 2027 | EO3: 2028 | EP3: 2029 | EQ3: 2030 | ER3: 2031 | ES3: 2032 | ET3: 2033 | EU3: 2034 | EV3: 2035 | EW3: 2036 | EX3: 2037 | EY3: 2038 | EZ3: 2039 | FA3: 2040 | FB3: 2041 | FC3: 2042 | FD3: 2043 | FE3: 2044 | FF3: 2045 | FG3: 2046 | FH3: 2047 | FI3: 2048 | FJ3: 2049 | FK3: 2050 | FL3: 2051 | FM3: 2052 | FN3: 2053 | FO3: 2054 | FP3: 2055 | FQ3: 2056 | FR3: 2057 | FS3: 2058 | FT3: 2059 | FU3: 2060 | FX3: 5-year moving average | FY3: 10-year moving average | FZ3: 1970-2007 average | GA3: 2008-2019 average | GD3: Pre-GFC trend calc | GG3: GFC-pandemic | GJ3: Pandemic-now | GM3: Potential pop | GN3: potential output | GP3: Potential pop | GQ3: potential output | GR3: Migrants diff | GS3: 16+ pop diff | GT3: Potential pop | GU3: Potential pop | GV3: potential output | GW3: potential output | GX3: YHAT diff | HA3: OE | HB3: OBR | HD3: Difference | HF3: OBR
A4: 1980 | B4: =Data!F14*Data!G14 -> 24.76553 | C4: =Data!H14/Data!I14 -> 8.4961659 | D4: =Data!E14 -> 1238528 | E4: =Data!J14 -> -1.827207 | F4: =Data!D14 -> 1164663 | G4: =Data!B14 -> 1140989 | L4: 2000 | M4: ='[2]2022-based'!L7 -> 139.3 | R4: 2020 | S4: ='[2]2022-based'!Q27 -> 66739.867 | Y4: 2012 | Z4: =SUMIF('ONS Nov25 T1'!$L:$L,'Chart Data'!$Y4,'ONS Nov25 T1'!$C:$C)/1000 -> 639 | AA4: =SUMIF('ONS Nov25 T1'!$M:$M,'Chart Data'!$Y4,'ONS Nov25 T1'!$C:$C)/1000 -> 477 | AB4: =SUMIF('ONS Nov25 T1'!$N:$N,'Chart Data'!$Y4,'ONS Nov25 T1'!$C:$C)/1000 -> 162 | AC4: =Z4-AA4 -> 162 | AE4: 2021 | AF4: =AS4 -> 59 | AG4: =AU4 -> 115 | AH4: =AT4+AV4 -> 59 | AI4: =AW4 -> 64 | AJ4: =AQ4 -> 74 | AK4: =AP4+AX4+AY4+AZ4 -> 447 | AL4: =AO4-SUM(AF4:AK4) -> 0 | AN4: 2021 | AO4: =+AP4+AQ4+AR4 -> 818 | AP4: =Z13-AQ4-AR4 -> 376 | AQ4: =SUMIF('ONS Nov25 T1'!$L:$L,'Chart Data'!$Y4,'ONS Nov25 T1'!$D:$D)/1000 -> 74 | AR4: =BC4+BK4 -> 368 | AS4: =BD4+BL4 -> 59 | AT4: =BE4+BM4 -> 41 | AU4: =BF4+BN4 -> 115 | AV4: =BG4+BO4 -> 18 | AW4: =BH4+BP4 -> 64 | AX4: =BQ4 -> 10 | AY4: =BR4 -> 36 | AZ4: =BS4 -> 25 | BA4: =AR4-AS4-AT4-AU4-AV4-AW4-AX4-AY4-AZ4 -> 0 | BC4: =SUMIF('ONS Nov25 T4a'!$P:$P,'Chart Data'!$AN4,'ONS Nov25 T4a'!C:C)/1000 -> 5 | BD4: =SUMIF('ONS Nov25 T4a'!$P:$P,'Chart Data'!$AN4,'ONS Nov25 T4a'!E:E)/1000 -> 4 | BE4: =SUMIF('ONS Nov25 T4a'!$P:$P,'Chart Data'!$AN4,'ONS Nov25 T4a'!F:F)/1000 -> 0 | BF4: =SUMIF('ONS Nov25 T4a'!$P:$P,'Chart Data'!$AN4,'ONS Nov25 T4a'!H:H)/1000 -> 0 | BG4: =SUMIF('ONS Nov25 T4a'!$P:$P,'Chart Data'!$AN4,'ONS Nov25 T4a'!I:I)/1000 -> 0 | BH4: =SUMIF('ONS Nov25 T4a'!$P:$P,'Chart Data'!$AN4,'ONS Nov25 T4a'!J:J)/1000 -> 0 | BI4: =BC4-BD4-BE4-BF4-BG4-BH4 -> 1 | BK4: =SUMIF('ONS Nov25 T4b'!$S:$S,'Chart Data'!$AN4,'ONS Nov25 T4b'!C:C)/1000 -> 363 | BL4: =SUMIF('ONS Nov25 T4b'!$S:$S,'Chart Data'!$AN4,'ONS Nov25 T4b'!E:E)/1000 -> 55 | BM4: =SUMIF('ONS Nov25 T4b'!$S:$S,'Chart Data'!$AN4,'ONS Nov25 T4b'!F:F)/1000 -> 41 | BN4: =SUMIF('ONS Nov25 T4b'!$S:$S,'Chart Data'!$AN4,'ONS Nov25 T4b'!H:H)/1000 -> 115 | BO4: =SUMIF('ONS Nov25 T4b'!$S:$S,'Chart Data'!$AN4,'ONS Nov25 T4b'!I:I)/1000 -> 18 | BP4: =SUMIF('ONS Nov25 T4b'!$S:$S,'Chart Data'!$AN4,'ONS Nov25 T4b'!J:J)/1000 -> 64 | BQ4: =SUMIF('ONS Nov25 T4b'!$S:$S,'Chart Data'!$AN4,'ONS Nov25 T4b'!K:K)/1000 -> 10 | BR4: =SUMIF('ONS Nov25 T4b'!$S:$S,'Chart Data'!$AN4,'ONS Nov25 T4b'!O:O)/1000 -> 36 | BS4: =SUMIF('ONS Nov25 T4b'!$S:$S,'Chart Data'!$AN4,'ONS Nov25 T4b'!P:P)/1000 -> 25 | BT4: =BK4-BL4-BM4-BN4-BO4-BP4-BQ4-BR4-BS4 -> -1 | BV4: 2021 | BW4: =CJ4 -> 24 | BX4: =CL4 -> 69 | BY4: =CK4+CM4 -> 16 | BZ4: =CN4 -> 9 | CA4: =CH4 -> 262 | CB4: =CG4+CO4+CP4+CQ4 -> 187 | CC4: =CF4-SUM(BW4:CB4) -> 0 | CE4: 2021 | CF4: =CG4+CH4+CI4 -> 567 | CG4: =AA13-CH4-CI4 -> 185 | CH4: =SUMIF('ONS Nov25 T1'!$M:$M,'Chart Data'!$CE4,'ONS Nov25 T1'!$D:$D)/1000 -> 262 | CI4: =CT4+DB4 -> 120 | CJ4: =CU4+DC4 -> 24 | CK4: =CV4+DD4 -> 12 | CL4: =CW4+DE4 -> 69 | CM4: =CX4+DF4 -> 4 | CN4: =CY4+DG4 -> 9 | CO4: =DH4 -> 0 | CP4: =DI4 -> 0 | CQ4: =DJ4 -> 2 | CR4: =CI4-CJ4-CK4-CL4-CM4-CN4-CO4-CP4-CQ4 -> 0 | CT4: =SUMIF('ONS Nov25 T4a'!$Q:$Q,'Chart Data'!$CE4,'ONS Nov25 T4a'!C:C)/1000 -> 0 | CU4: =SUMIF('ONS Nov25 T4a'!$Q:$Q,'Chart Data'!$CE4,'ONS Nov25 T4a'!E:E)/1000 -> 0 | CV4: =SUMIF('ONS Nov25 T4a'!$Q:$Q,'Chart Data'!$CE4,'ONS Nov25 T4a'!F:F)/1000 -> 0 | CW4: =SUMIF('ONS Nov25 T4a'!$Q:$Q,'Chart Data'!$CE4,'ONS Nov25 T4a'!H:H)/1000 -> 0 | CX4: =SUMIF('ONS Nov25 T4a'!$Q:$Q,'Chart Data'!$CE4,'ONS Nov25 T4a'!I:I)/1000 -> 0 | CY4: =SUMIF('ONS Nov25 T4a'!$Q:$Q,'Chart Data'!$CE4,'ONS Nov25 T4a'!J:J)/1000 -> 0 | CZ4: =CT4-CU4-CV4-CW4-CX4-CY4 -> 0 | DB4: =SUMIF('ONS Nov25 T4b'!$T:$T,'Chart Data'!$CE4,'ONS Nov25 T4b'!C:C)/1000 -> 120 | DC4: =SUMIF('ONS Nov25 T4b'!$T:$T,'Chart Data'!$CE4,'ONS Nov25 T4b'!E:E)/1000 -> 24 | DD4: =SUMIF('ONS Nov25 T4b'!$T:$T,'Chart Data'!$CE4,'ONS Nov25 T4b'!F:F)/1000 -> 12 | DE4: =SUMIF('ONS Nov25 T4b'!$T:$T,'Chart Data'!$AN4,'ONS Nov25 T4b'!H:H)/1000 -> 69 | DF4: =SUMIF('ONS Nov25 T4b'!$T:$T,'Chart Data'!$AN4,'ONS Nov25 T4b'!I:I)/1000 -> 4 | DG4: =SUMIF('ONS Nov25 T4b'!$T:$T,'Chart Data'!$AN4,'ONS Nov25 T4b'!J:J)/1000 -> 9 | DH4: =SUMIF('ONS Nov25 T4b'!$T:$T,'Chart Data'!$AN4,'ONS Nov25 T4b'!K:K)/1000 -> 0 | DI4: =SUMIF('ONS Nov25 T4b'!$T:$T,'Chart Data'!$AN4,'ONS Nov25 T4b'!O:O)/1000 -> 0 | DJ4: =SUMIF('ONS Nov25 T4b'!$T:$T,'Chart Data'!$AN4,'ONS Nov25 T4b'!P:P)/1000 -> 2 | DK4: =DB4-DC4-DD4-DE4-DF4-DG4-DH4-DI4-DJ4 -> 0 | DM4: 2024 | DN4: =100*(Data!B58/Data!$B$58) -> 100 | DO4: =100*('OBR Nov25 ST1.1'!R114/'OBR Nov25 ST1.1'!$R$114) -> 100 | DP4: ='OBR Nov25 C2.25'!M26 -> 100 | DQ4: ='OBR Nov25 C2.25'!N26 -> 100 | DR4: ='OBR Nov25 C2.25'!O26-'Chart Data'!DQ4 -> 0 | DT4: 1974 | DU4: =100*((Data!M8/Data!M7)-1) -> 0.028023783 | DW4: 0 | DX4: 65 | DY4: 60 | EA4: 33970 | EC4: =AVERAGE($EB$7:$EB$399) -> 25.050854 | EH4: 0-15 | EI4: =100*(EI10/EI$13) -> 18.338943 | EJ4: =100*(EJ10/EJ$13) -> 18.100138 | EK4: =100*(EK10/EK$13) -> 17.821261 | EL4: =100*(EL10/EL$13) -> 17.56445 | EM4: =100*(EM10/EM$13) -> 17.309362 | EN4: =100*(EN10/EN$13) -> 17.047745 | EO4: =100*(EO10/EO$13) -> 16.794473 | EP4: =100*(EP10/EP$13) -> 16.572539 | ... FU4: =100*(FU10/FU$13) -> 14.452173 | FW4: 1960 | GC4: 1970 | GD4: =AVERAGE(HAVERQ!B47:B50) -> 44.625 | GF4: 2007 | GG4: =AVERAGE(HAVERQ!B195:B198) -> 94.175 | GI4: 2019 | GJ4: =AVERAGE(HAVERQ!B243:B246) -> 98.075 | GL4: ='OBR Nov25 ST1.15'!B70 -> 2023-24 | GM4: ='OBR Nov25 ST1.15'!O70 -> 1.193242 | GN4: ='OBR Nov25 ST1.15'!M70 -> 1.1188062 | GP4: ='OBR Nov25 ST1.15'!F70 -> 55208.25 | GQ4: ='OBR Nov25 ST1.15'!D70 -> 2753907.4 | GT4: =GP4+GS4 -> 55208.25 | GW4: =GQ4 -> 2753907.4 | GZ4: 2015 | HA4: =100*(Data!B49/Data!$B$57) -> 89.717837 | HB4: =HA4 -> 89.717837 | HD4: =100*((HB4/HA4)-1) -> 0
A5: 1981 | B5: =Data!F15*Data!G15 -> 24.65965 | C5: =Data!H15/Data!I15 -> 8.5228971 | D5: =Data!E15 -> 1247026 | E5: =Data!J15 -> -1.814585 | F5: =Data!D15 -> 1182108 | G5: =Data!B15 -> 1134663 | I5: =100*((F5/F4)-1) -> 1.4978582 | J5: =100*((G5/G4)-1) -> -0.55443129 | L5: 2001 | M5: ='[2]2022-based'!L8 -> 153.2 | R5: 2021 | S5: ='[2]2022-based'!Q28 -> 66977.988 | Y5: 2013 | Z5: =SUMIF('ONS Nov25 T1'!$L:$L,'Chart Data'!$Y5,'ONS Nov25 T1'!$C:$C)/1000 -> 669 | AA5: =SUMIF('ONS Nov25 T1'!$M:$M,'Chart Data'!$Y5,'ONS Nov25 T1'!$C:$C)/1000 -> 454 | AB5: =SUMIF('ONS Nov25 T1'!$N:$N,'Chart Data'!$Y5,'ONS Nov25 T1'!$C:$C)/1000 -> 215 | AC5: =Z5-AA5 -> 215 | AE5: 2022 | AF5: =AS5 -> 134 | AG5: =AU5 -> 269 | AH5: =AT5+AV5 -> 150 | AI5: =AW5 -> 65 | AJ5: =AQ5 -> 75 | AK5: =AP5+AX5+AY5+AZ5 -> 473 | AL5: =AO5-SUM(AF5:AK5) -> 1 | AN5: 2022 | AO5: =+AP5+AQ5+AR5 -> 1167 | AP5: =Z14-AQ5-AR5 -> 224 | AQ5: =SUMIF('ONS Nov25 T1'!$L:$L,'Chart Data'!$Y5,'ONS Nov25 T1'!$D:$D)/1000 -> 75 | AR5: =BC5+BK5 -> 868 | AS5: =BD5+BL5 -> 134 | AT5: =BE5+BM5 -> 93 | AU5: =BF5+BN5 -> 269 | AV5: =BG5+BO5 -> 57 | AW5: =BH5+BP5 -> 65 | AX5: =BQ5 -> 151 | AY5: =BR5 -> 70 | AZ5: =BS5 -> 28 | BA5: =AR5-AS5-AT5-AU5-AV5-AW5-AX5-AY5-AZ5 -> 1 | BC5: =SUMIF('ONS Nov25 T4a'!$P:$P,'Chart Data'!$AN5,'ONS Nov25 T4a'!C:C)/1000 -> 30 | BD5: =SUMIF('ONS Nov25 T4a'!$P:$P,'Chart Data'!$AN5,'ONS Nov25 T4a'!E:E)/1000 -> 15 | BE5: =SUMIF('ONS Nov25 T4a'!$P:$P,'Chart Data'!$AN5,'ONS Nov25 T4a'!F:F)/1000 -> 3 | BF5: =SUMIF('ONS Nov25 T4a'!$P:$P,'Chart Data'!$AN5,'ONS Nov25 T4a'!H:H)/1000 -> 11 | BG5: =SUMIF('ONS Nov25 T4a'!$P:$P,'Chart Data'!$AN5,'ONS Nov25 T4a'!I:I)/1000 -> 0 | BH5: =SUMIF('ONS Nov25 T4a'!$P:$P,'Chart Data'!$AN5,'ONS Nov25 T4a'!J:J)/1000 -> 1 | BI5: =BC5-BD5-BE5-BF5-BG5-BH5 -> 0 | BK5: =SUMIF('ONS Nov25 T4b'!$S:$S,'Chart Data'!$AN5,'ONS Nov25 T4b'!C:C)/1000 -> 838 | BL5: =SUMIF('ONS Nov25 T4b'!$S:$S,'Chart Data'!$AN5,'ONS Nov25 T4b'!E:E)/1000 -> 119 | BM5: =SUMIF('ONS Nov25 T4b'!$S:$S,'Chart Data'!$AN5,'ONS Nov25 T4b'!F:F)/1000 -> 90 | BN5: =SUMIF('ONS Nov25 T4b'!$S:$S,'Chart Data'!$AN5,'ONS Nov25 T4b'!H:H)/1000 -> 258 | BO5: =SUMIF('ONS Nov25 T4b'!$S:$S,'Chart Data'!$AN5,'ONS Nov25 T4b'!I:I)/1000 -> 57 | BP5: =SUMIF('ONS Nov25 T4b'!$S:$S,'Chart Data'!$AN5,'ONS Nov25 T4b'!J:J)/1000 -> 64 | BQ5: =SUMIF('ONS Nov25 T4b'!$S:$S,'Chart Data'!$AN5,'ONS Nov25 T4b'!K:K)/1000 -> 151 | BR5: =SUMIF('ONS Nov25 T4b'!$S:$S,'Chart Data'!$AN5,'ONS Nov25 T4b'!O:O)/1000 -> 70 | BS5: =SUMIF('ONS Nov25 T4b'!$S:$S,'Chart Data'!$AN5,'ONS Nov25 T4b'!P:P)/1000 -> 28 | BT5: =BK5-BL5-BM5-BN5-BO5-BP5-BQ5-BR5-BS5 -> 1 | BV5: 2022 | BW5: =CJ5 -> 17 | BX5: =CL5 -> 45 | BY5: =CK5+CM5 -> 14 | BZ5: =CN5 -> 10 | CA5: =CH5 -> 240 | CB5: =CG5+CO5+CP5+CQ5 -> 160 | CC5: =CF5-SUM(BW5:CB5) -> 0 | CE5: 2022 | CF5: =CG5+CH5+CI5 -> 486 | CG5: =AA14-CH5-CI5 -> 158 | CH5: =SUMIF('ONS Nov25 T1'!$M:$M,'Chart Data'!$CE5,'ONS Nov25 T1'!$D:$D)/1000 -> 240 | CI5: =CT5+DB5 -> 88 | CJ5: =CU5+DC5 -> 17 | CK5: =CV5+DD5 -> 9 | CL5: =CW5+DE5 -> 45 | CM5: =CX5+DF5 -> 5 | CN5: =CY5+DG5 -> 10 | CO5: =DH5 -> 0 | CP5: =DI5 -> 0 | CQ5: =DJ5 -> 2 | CR5: =CI5-CJ5-CK5-CL5-CM5-CN5-CO5-CP5-CQ5 -> 0 | CT5: =SUMIF('ONS Nov25 T4a'!$Q:$Q,'Chart Data'!$CE5,'ONS Nov25 T4a'!C:C)/1000 -> 0 | CU5: =SUMIF('ONS Nov25 T4a'!$Q:$Q,'Chart Data'!$CE5,'ONS Nov25 T4a'!E:E)/1000 -> 0 | CV5: =SUMIF('ONS Nov25 T4a'!$Q:$Q,'Chart Data'!$CE5,'ONS Nov25 T4a'!F:F)/1000 -> 0 | CW5: =SUMIF('ONS Nov25 T4a'!$Q:$Q,'Chart Data'!$CE5,'ONS Nov25 T4a'!H:H)/1000 -> 0 | CX5: =SUMIF('ONS Nov25 T4a'!$Q:$Q,'Chart Data'!$CE5,'ONS Nov25 T4a'!I:I)/1000 -> 0 | CY5: =SUMIF('ONS Nov25 T4a'!$Q:$Q,'Chart Data'!$CE5,'ONS Nov25 T4a'!J:J)/1000 -> 0 | CZ5: =CT5-CU5-CV5-CW5-CX5-CY5 -> 0 | DB5: =SUMIF('ONS Nov25 T4b'!$T:$T,'Chart Data'!$CE5,'ONS Nov25 T4b'!C:C)/1000 -> 88 | DC5: =SUMIF('ONS Nov25 T4b'!$T:$T,'Chart Data'!$CE5,'ONS Nov25 T4b'!E:E)/1000 -> 17 | DD5: =SUMIF('ONS Nov25 T4b'!$T:$T,'Chart Data'!$CE5,'ONS Nov25 T4b'!F:F)/1000 -> 9 | DE5: =SUMIF('ONS Nov25 T4b'!$T:$T,'Chart Data'!$AN5,'ONS Nov25 T4b'!H:H)/1000 -> 45 | DF5: =SUMIF('ONS Nov25 T4b'!$T:$T,'Chart Data'!$AN5,'ONS Nov25 T4b'!I:I)/1000 -> 5 | DG5: =SUMIF('ONS Nov25 T4b'!$T:$T,'Chart Data'!$AN5,'ONS Nov25 T4b'!J:J)/1000 -> 10 | DH5: =SUMIF('ONS Nov25 T4b'!$T:$T,'Chart Data'!$AN5,'ONS Nov25 T4b'!K:K)/1000 -> 0 | DI5: =SUMIF('ONS Nov25 T4b'!$T:$T,'Chart Data'!$AN5,'ONS Nov25 T4b'!O:O)/1000 -> 0 | DJ5: =SUMIF('ONS Nov25 T4b'!$T:$T,'Chart Data'!$AN5,'ONS Nov25 T4b'!P:P)/1000 -> 2 | DK5: =DB5-DC5-DD5-DE5-DF5-DG5-DH5-DI5-DJ5 -> 0 | DM5: 2025 | DN5: =100*(Data!B59/Data!$B$58) -> 101.38115 | DO5: =100*('OBR Nov25 ST1.1'!R115/'OBR Nov25 ST1.1'!$R$114) -> 101.48334 | DP5: ='OBR Nov25 C2.25'!M27 -> 101.45766 | DQ5: ='OBR Nov25 C2.25'!N27 -> 101.3 | DR5: ='OBR Nov25 C2.25'!O27-'Chart Data'!DQ5 -> 0.3 | DT5: 1975 | DU5: =100*((Data!M9/Data!M8)-1) -> -0.015228704 | DW5: 0 | DX5: 65 | DY5: 60 | EA5: 34001 | EC5: =AVERAGE($EB$7:$EB$399) -> 25.050854 | EH5: 16-64 | EI5: =100*(EI11/EI$13) -> 62.821174 | EJ5: =100*(EJ11/EJ$13) -> 63.014647 | EK5: =100*(EK11/EK$13) -> 63.163697 | EL5: =100*(EL11/EL$13) -> 63.249701 | EM5: =100*(EM11/EM$13) -> 63.277552 | EN5: =100*(EN11/EN$13) -> 63.259142 | EO5: =100*(EO11/EO$13) -> 63.194181 | EP5: =100*(EP11/EP$13) -> 63.086963 | ... FU5: =100*(FU11/FU$13) -> 60.298516 | GC5: 2007 | GD5: =AVERAGE(HAVERQ!B195:B198) -> 94.175 | GF5: 2019 | GG5: =AVERAGE(HAVERQ!B243:B246) -> 98.075 | GI5: 2025 | GJ5: =AVERAGE(HAVERQ!B265:B268) -> 100.15 | GL5: ='OBR Nov25 ST1.15'!B71 -> 2024-25 | GM5: ='OBR Nov25 ST1.15'!O71 -> 1.1492848 | GN5: ='OBR Nov25 ST1.15'!M71 -> 1.8882217 | GP5: ='OBR Nov25 ST1.15'!F71 -> 55842.75 | GQ5: ='OBR Nov25 ST1.15'!D71 -> 2805907.3 | GR5: =M29-P29 -> -86.772929 | GS5: =GR5*$GR$12 -> -72.859817 | GT5: =GP5+GS5 -> 55769.89 | GU5: =100*((GT5/GT4)-1) -> 1.0173121 | GV5: =GN5-GM5+GU5 -> 1.756249 | GW5: =GW4*(1+GV5/100) -> 2802272.9 | GX5: =100*((GW5/GQ5)-1) -> -0.12952694 | GZ5: 2016 | HA5: =100*(Data!B50/Data!$B$57) -> 91.697479 | HB5: =HA5 -> 91.697479 | HD5: =100*((HB5/HA5)-1) -> 0
A6: 1982 | B6: =Data!F16*Data!G16 -> 24.29771 | C6: =Data!H16/Data!I16 -> 8.5398108 | D6: =Data!E16 -> 1258257 | E6: =Data!J16 -> -1.802051 | F6: =Data!D16 -> 1189451 | G6: =Data!B16 -> 1157191 | I6: =100*((F6/F5)-1) -> 0.62117844 | J6: =100*((G6/G5)-1) -> 1.9854353 | L6: 2002 | M6: ='[2]2022-based'!L9 -> 190.9 | R6: 2022 | S6: ='[2]2022-based'!Q29 -> 67636.134 | T6: {=TRANSPOSE('ONS popproj Jan25 pp'!C8:AO8)} -> 67602.761 | U6: {=TRANSPOSE('ONS popproj Jan25 migcv'!C8:AO8)} -> 67602.761 | V6: =S6 -> 67636.134 | W6: {=TRANSPOSE('OBR Nov25 ST4.3'!T34:AB34)} -> 67970 | Y6: 2014 | Z6: =SUMIF('ONS Nov25 T1'!$L:$L,'Chart Data'!$Y6,'ONS Nov25 T1'!$C:$C)/1000 -> 737 | AA6: =SUMIF('ONS Nov25 T1'!$M:$M,'Chart Data'!$Y6,'ONS Nov25 T1'!$C:$C)/1000 -> 489 | AB6: =SUMIF('ONS Nov25 T1'!$N:$N,'Chart Data'!$Y6,'ONS Nov25 T1'!$C:$C)/1000 -> 248 | AC6: =Z6-AA6 -> 248 | AE6: 2023 | AF6: =AS6 -> 220 | AG6: =AU6 -> 352 | AH6: =AT6+AV6 -> 318 | AI6: =AW6 -> 90 | AJ6: =AQ6 -> 82 | AK6: =AP6+AX6+AY6+AZ6 -> 402 | AL6: =AO6-SUM(AF6:AK6) -> 2 | AN6: 2023 | AO6: =+AP6+AQ6+AR6 -> 1466 | AP6: =Z15-AQ6-AR6 -> 170 | AQ6: =SUMIF('ONS Nov25 T1'!$L:$L,'Chart Data'!$Y6,'ONS Nov25 T1'!$D:$D)/1000 -> 82 | AR6: =BC6+BK6 -> 1214 | AS6: =BD6+BL6 -> 220 | AT6: =BE6+BM6 -> 187 | AU6: =BF6+BN6 -> 352 | AV6: =BG6+BO6 -> 131 | AW6: =BH6+BP6 -> 90 | AX6: =BQ6 -> 126 | AY6: =BR6 -> 85 | AZ6: =BS6 -> 21 | BA6: =AR6-AS6-AT6-AU6-AV6-AW6-AX6-AY6-AZ6 -> 2 | BC6: =SUMIF('ONS Nov25 T4a'!$P:$P,'Chart Data'!$AN6,'ONS Nov25 T4a'!C:C)/1000 -> 32 | BD6: =SUMIF('ONS Nov25 T4a'!$P:$P,'Chart Data'!$AN6,'ONS Nov25 T4a'!E:E)/1000 -> 14 | BE6: =SUMIF('ONS Nov25 T4a'!$P:$P,'Chart Data'!$AN6,'ONS Nov25 T4a'!F:F)/1000 -> 4 | BF6: =SUMIF('ONS Nov25 T4a'!$P:$P,'Chart Data'!$AN6,'ONS Nov25 T4a'!H:H)/1000 -> 11 | BG6: =SUMIF('ONS Nov25 T4a'!$P:$P,'Chart Data'!$AN6,'ONS Nov25 T4a'!I:I)/1000 -> 0 | BH6: =SUMIF('ONS Nov25 T4a'!$P:$P,'Chart Data'!$AN6,'ONS Nov25 T4a'!J:J)/1000 -> 2 | BI6: =BC6-BD6-BE6-BF6-BG6-BH6 -> 1 | BK6: =SUMIF('ONS Nov25 T4b'!$S:$S,'Chart Data'!$AN6,'ONS Nov25 T4b'!C:C)/1000 -> 1182 | BL6: =SUMIF('ONS Nov25 T4b'!$S:$S,'Chart Data'!$AN6,'ONS Nov25 T4b'!E:E)/1000 -> 206 | BM6: =SUMIF('ONS Nov25 T4b'!$S:$S,'Chart Data'!$AN6,'ONS Nov25 T4b'!F:F)/1000 -> 183 | BN6: =SUMIF('ONS Nov25 T4b'!$S:$S,'Chart Data'!$AN6,'ONS Nov25 T4b'!H:H)/1000 -> 341 | BO6: =SUMIF('ONS Nov25 T4b'!$S:$S,'Chart Data'!$AN6,'ONS Nov25 T4b'!I:I)/1000 -> 131 | BP6: =SUMIF('ONS Nov25 T4b'!$S:$S,'Chart Data'!$AN6,'ONS Nov25 T4b'!J:J)/1000 -> 88 | BQ6: =SUMIF('ONS Nov25 T4b'!$S:$S,'Chart Data'!$AN6,'ONS Nov25 T4b'!K:K)/1000 -> 126 | BR6: =SUMIF('ONS Nov25 T4b'!$S:$S,'Chart Data'!$AN6,'ONS Nov25 T4b'!O:O)/1000 -> 85 | BS6: =SUMIF('ONS Nov25 T4b'!$S:$S,'Chart Data'!$AN6,'ONS Nov25 T4b'!P:P)/1000 -> 21 | BT6: =BK6-BL6-BM6-BN6-BO6-BP6-BQ6-BR6-BS6 -> 1 | BV6: 2023 | BW6: =CJ6 -> 21 | BX6: =CL6 -> 85 | BY6: =CK6+CM6 -> 19 | BZ6: =CN6 -> 11 | CA6: =CH6 -> 252 | CB6: =CG6+CO6+CP6+CQ6 -> 153 | CC6: =CF6-SUM(BW6:CB6) -> 2 | CE6: 2023 | CF6: =CG6+CH6+CI6 -> 543 | CG6: =AA15-CH6-CI6 -> 149 | CH6: =SUMIF('ONS Nov25 T1'!$M:$M,'Chart Data'!$CE6,'ONS Nov25 T1'!$D:$D)/1000 -> 252 | CI6: =CT6+DB6 -> 142 | CJ6: =CU6+DC6 -> 21 | CK6: =CV6+DD6 -> 11 | CL6: =CW6+DE6 -> 85 | CM6: =CX6+DF6 -> 8 | CN6: =CY6+DG6 -> 11 | CO6: =DH6 -> 1 | CP6: =DI6 -> 1 | CQ6: =DJ6 -> 2 | CR6: =CI6-CJ6-CK6-CL6-CM6-CN6-CO6-CP6-CQ6 -> 2 | CT6: =SUMIF('ONS Nov25 T4a'!$Q:$Q,'Chart Data'!$CE6,'ONS Nov25 T4a'!C:C)/1000 -> 5 | CU6: =SUMIF('ONS Nov25 T4a'!$Q:$Q,'Chart Data'!$CE6,'ONS Nov25 T4a'!E:E)/1000 -> 2 | CV6: =SUMIF('ONS Nov25 T4a'!$Q:$Q,'Chart Data'!$CE6,'ONS Nov25 T4a'!F:F)/1000 -> 0 | CW6: =SUMIF('ONS Nov25 T4a'!$Q:$Q,'Chart Data'!$CE6,'ONS Nov25 T4a'!H:H)/1000 -> 2 | CX6: =SUMIF('ONS Nov25 T4a'!$Q:$Q,'Chart Data'!$CE6,'ONS Nov25 T4a'!I:I)/1000 -> 0 | CY6: =SUMIF('ONS Nov25 T4a'!$Q:$Q,'Chart Data'!$CE6,'ONS Nov25 T4a'!J:J)/1000 -> 0 | CZ6: =CT6-CU6-CV6-CW6-CX6-CY6 -> 1 | DB6: =SUMIF('ONS Nov25 T4b'!$T:$T,'Chart Data'!$CE6,'ONS Nov25 T4b'!C:C)/1000 -> 137 | DC6: =SUMIF('ONS Nov25 T4b'!$T:$T,'Chart Data'!$CE6,'ONS Nov25 T4b'!E:E)/1000 -> 19 | DD6: =SUMIF('ONS Nov25 T4b'!$T:$T,'Chart Data'!$CE6,'ONS Nov25 T4b'!F:F)/1000 -> 11 | DE6: =SUMIF('ONS Nov25 T4b'!$T:$T,'Chart Data'!$AN6,'ONS Nov25 T4b'!H:H)/1000 -> 83 | DF6: =SUMIF('ONS Nov25 T4b'!$T:$T,'Chart Data'!$AN6,'ONS Nov25 T4b'!I:I)/1000 -> 8 | DG6: =SUMIF('ONS Nov25 T4b'!$T:$T,'Chart Data'!$AN6,'ONS Nov25 T4b'!J:J)/1000 -> 11 | DH6: =SUMIF('ONS Nov25 T4b'!$T:$T,'Chart Data'!$AN6,'ONS Nov25 T4b'!K:K)/1000 -> 1 | DI6: =SUMIF('ONS Nov25 T4b'!$T:$T,'Chart Data'!$AN6,'ONS Nov25 T4b'!O:O)/1000 -> 1 | DJ6: =SUMIF('ONS Nov25 T4b'!$T:$T,'Chart Data'!$AN6,'ONS Nov25 T4b'!P:P)/1000 -> 2 | DK6: =DB6-DC6-DD6-DE6-DF6-DG6-DH6-DI6-DJ6 -> 1 | DM6: 2026 | DN6: =100*(Data!B60/Data!$B$58) -> 102.26486 | DO6: =100*('OBR Nov25 ST1.1'!R116/'OBR Nov25 ST1.1'!$R$114) -> 102.87515 | DP6: ='OBR Nov25 C2.25'!M28 -> 102.63936 | DQ6: =DN6 -> 102.26486 | DR6: ='OBR Nov25 C2.25'!O28-'Chart Data'!DQ6 -> 0.7575371 | DT6: 1976 | DU6: =100*((Data!M10/Data!M9)-1) -> 0.10264916 | DW6: 0 | DX6: 65 | DY6: 60 | EA6: 34029 | EC6: =AVERAGE($EB$7:$EB$399) -> 25.050854 | EH6: 65+ | EI6: =100*(EI12/EI$13) -> 18.839883 | EJ6: =100*(EJ12/EJ$13) -> 18.885215 | EK6: =100*(EK12/EK$13) -> 19.015042 | EL6: =100*(EL12/EL$13) -> 19.185849 | EM6: =100*(EM12/EM$13) -> 19.413087 | EN6: =100*(EN12/EN$13) -> 19.693114 | EO6: =100*(EO12/EO$13) -> 20.011347 | EP6: =100*(EP12/EP$13) -> 20.340498 | ... FU6: =100*(FU12/FU$13) -> 25.24931 | GC6: y/y | GD6: =100*((GD5/GD4)^(1/37)-1) -> 2.0390523 | GF6: y/y | GG6: =100*((GG5/GG4)^(1/12)-1) -> 0.33872019 | GI6: y/y | GJ6: =100*((GJ5/GJ4)^(4/23)-1) -> 0.36477796 | GL6: ='OBR Nov25 ST1.15'!B72 -> 2025-26 | GM6: ='OBR Nov25 ST1.15'!O72 -> 0.92630512 | GN6: ='OBR Nov25 ST1.15'!M72 -> 1.5356702 | GP6: ='OBR Nov25 ST1.15'!F72 -> 56360.024 | GQ6: ='OBR Nov25 ST1.15'!D72 -> 2848996.8 | GR6: =GR5+M30-P30 -> -255.24158 | GS6: =GR6*$GR$12 -> -214.31632 | GT6: =GP6+GS6 -> 56145.708 | GU6: =100*((GT6/GT5)-1) -> 0.67387212 | GV6: =GN6-GM6+GU6 -> 1.2832372 | GW6: =GW5*(1+GV6/100) -> 2838232.7 | GX6: =100*((GW6/GQ6)-1) -> -0.37782 | GZ6: 2017 | HA6: =100*(Data!B51/Data!$B$57) -> 94.469697 | HB6: =HA6 -> 94.469697 | HD6: =100*((HB6/HA6)-1) -> 0
A7: 1983 | B7: =Data!F17*Data!G17 -> 24.30468 | C7: =Data!H17/Data!I17 -> 8.5563186 | D7: =Data!E17 -> 1271612 | E7: =Data!J17 -> -1.789603 | F7: =Data!D17 -> 1209350 | G7: =Data!B17 -> 1205632 | I7: =100*((F7/F6)-1) -> 1.6729567 | J7: =100*((G7/G6)-1) -> 4.1860851 | L7: 2003 | M7: ='[2]2022-based'!L10 -> 194.3 | R7: 2023 | S7: ='[2]2022-based'!Q30 -> 68526.183 | T7: 68492.495 | U7: 68492.495 | V7: =S7 -> 68526.183 | W7: 68809.5 | Y7: 2015 | Z7: =SUMIF('ONS Nov25 T1'!$L:$L,'Chart Data'!$Y7,'ONS Nov25 T1'!$C:$C)/1000 -> 778 | AA7: =SUMIF('ONS Nov25 T1'!$M:$M,'Chart Data'!$Y7,'ONS Nov25 T1'!$C:$C)/1000 -> 482 | AB7: =SUMIF('ONS Nov25 T1'!$N:$N,'Chart Data'!$Y7,'ONS Nov25 T1'!$C:$C)/1000 -> 296 | AC7: =Z7-AA7 -> 296 | AE7: 2024 | AF7: =AS7 -> 202 | AG7: =AU7 -> 310 | AH7: =AT7+AV7 -> 336 | AI7: =AW7 -> 87 | AJ7: =AQ7 -> 83 | AK7: =AP7+AX7+AY7+AZ7 -> 280 | AL7: =AO7-SUM(AF7:AK7) -> 1 | AN7: 2024 | AO7: =+AP7+AQ7+AR7 -> 1299 | AP7: =Z16-AQ7-AR7 -> 122 | AQ7: =SUMIF('ONS Nov25 T1'!$L:$L,'Chart Data'!$Y7,'ONS Nov25 T1'!$D:$D)/1000 -> 83 | AR7: =BC7+BK7 -> 1094 | AS7: =BD7+BL7 -> 202 | AT7: =BE7+BM7 -> 249 | AU7: =BF7+BN7 -> 310 | AV7: =BG7+BO7 -> 87 | AW7: =BH7+BP7 -> 87 | AX7: =BQ7 -> 62 | AY7: =BR7 -> 81 | AZ7: =BS7 -> 15 | BA7: =AR7-AS7-AT7-AU7-AV7-AW7-AX7-AY7-AZ7 -> 1 | BC7: =SUMIF('ONS Nov25 T4a'!$P:$P,'Chart Data'!$AN7,'ONS Nov25 T4a'!C:C)/1000 -> 31 | BD7: =SUMIF('ONS Nov25 T4a'!$P:$P,'Chart Data'!$AN7,'ONS Nov25 T4a'!E:E)/1000 -> 12 | BE7: =SUMIF('ONS Nov25 T4a'!$P:$P,'Chart Data'!$AN7,'ONS Nov25 T4a'!F:F)/1000 -> 4 | BF7: =SUMIF('ONS Nov25 T4a'!$P:$P,'Chart Data'!$AN7,'ONS Nov25 T4a'!H:H)/1000 -> 11 | BG7: =SUMIF('ONS Nov25 T4a'!$P:$P,'Chart Data'!$AN7,'ONS Nov25 T4a'!I:I)/1000 -> 0 | BH7: =SUMIF('ONS Nov25 T4a'!$P:$P,'Chart Data'!$AN7,'ONS Nov25 T4a'!J:J)/1000 -> 3 | BI7: =BC7-BD7-BE7-BF7-BG7-BH7 -> 1 | BK7: =SUMIF('ONS Nov25 T4b'!$S:$S,'Chart Data'!$AN7,'ONS Nov25 T4b'!C:C)/1000 -> 1063 | BL7: =SUMIF('ONS Nov25 T4b'!$S:$S,'Chart Data'!$AN7,'ONS Nov25 T4b'!E:E)/1000 -> 190 | BM7: =SUMIF('ONS Nov25 T4b'!$S:$S,'Chart Data'!$AN7,'ONS Nov25 T4b'!F:F)/1000 -> 245 | BN7: =SUMIF('ONS Nov25 T4b'!$S:$S,'Chart Data'!$AN7,'ONS Nov25 T4b'!H:H)/1000 -> 299 | BO7: =SUMIF('ONS Nov25 T4b'!$S:$S,'Chart Data'!$AN7,'ONS Nov25 T4b'!I:I)/1000 -> 87 | BP7: =SUMIF('ONS Nov25 T4b'!$S:$S,'Chart Data'!$AN7,'ONS Nov25 T4b'!J:J)/1000 -> 84 | BQ7: =SUMIF('ONS Nov25 T4b'!$S:$S,'Chart Data'!$AN7,'ONS Nov25 T4b'!K:K)/1000 -> 62 | BR7: =SUMIF('ONS Nov25 T4b'!$S:$S,'Chart Data'!$AN7,'ONS Nov25 T4b'!O:O)/1000 -> 81 | BS7: =SUMIF('ONS Nov25 T4b'!$S:$S,'Chart Data'!$AN7,'ONS Nov25 T4b'!P:P)/1000 -> 15 | BT7: =BK7-BL7-BM7-BN7-BO7-BP7-BQ7-BR7-BS7 -> 0 | BV7: 2024 | BW7: =CJ7 -> 38 | BX7: =CL7 -> 128 | BY7: =CK7+CM7 -> 40 | BZ7: =CN7 -> 23 | CA7: =CH7 -> 257 | CB7: =CG7+CO7+CP7+CQ7 -> 164 | CC7: =CF7-SUM(BW7:CB7) -> 0 | CE7: 2024 | CF7: =CG7+CH7+CI7 -> 650 | CG7: =AA16-CH7-CI7 -> 145 | CH7: =SUMIF('ONS Nov25 T1'!$M:$M,'Chart Data'!$CE7,'ONS Nov25 T1'!$D:$D)/1000 -> 257 | CI7: =CT7+DB7 -> 248 | CJ7: =CU7+DC7 -> 38 | CK7: =CV7+DD7 -> 22 | CL7: =CW7+DE7 -> 128 | CM7: =CX7+DF7 -> 18 | CN7: =CY7+DG7 -> 23 | CO7: =DH7 -> 10 | CP7: =DI7 -> 4 | CQ7: =DJ7 -> 5 | CR7: =CI7-CJ7-CK7-CL7-CM7-CN7-CO7-CP7-CQ7 -> 0 | CT7: =SUMIF('ONS Nov25 T4a'!$Q:$Q,'Chart Data'!$CE7,'ONS Nov25 T4a'!C:C)/1000 -> 10 | CU7: =SUMIF('ONS Nov25 T4a'!$Q:$Q,'Chart Data'!$CE7,'ONS Nov25 T4a'!E:E)/1000 -> 4 | CV7: =SUMIF('ONS Nov25 T4a'!$Q:$Q,'Chart Data'!$CE7,'ONS Nov25 T4a'!F:F)/1000 -> 1 | CW7: =SUMIF('ONS Nov25 T4a'!$Q:$Q,'Chart Data'!$CE7,'ONS Nov25 T4a'!H:H)/1000 -> 4 | CX7: =SUMIF('ONS Nov25 T4a'!$Q:$Q,'Chart Data'!$CE7,'ONS Nov25 T4a'!I:I)/1000 -> 0 | CY7: =SUMIF('ONS Nov25 T4a'!$Q:$Q,'Chart Data'!$CE7,'ONS Nov25 T4a'!J:J)/1000 -> 0 | CZ7: =CT7-CU7-CV7-CW7-CX7-CY7 -> 1 | DB7: =SUMIF('ONS Nov25 T4b'!$T:$T,'Chart Data'!$CE7,'ONS Nov25 T4b'!C:C)/1000 -> 238 | DC7: =SUMIF('ONS Nov25 T4b'!$T:$T,'Chart Data'!$CE7,'ONS Nov25 T4b'!E:E)/1000 -> 34 | DD7: =SUMIF('ONS Nov25 T4b'!$T:$T,'Chart Data'!$CE7,'ONS Nov25 T4b'!F:F)/1000 -> 21 | DE7: =SUMIF('ONS Nov25 T4b'!$T:$T,'Chart Data'!$AN7,'ONS Nov25 T4b'!H:H)/1000 -> 124 | DF7: =SUMIF('ONS Nov25 T4b'!$T:$T,'Chart Data'!$AN7,'ONS Nov25 T4b'!I:I)/1000 -> 18 | DG7: =SUMIF('ONS Nov25 T4b'!$T:$T,'Chart Data'!$AN7,'ONS Nov25 T4b'!J:J)/1000 -> 23 | DH7: =SUMIF('ONS Nov25 T4b'!$T:$T,'Chart Data'!$AN7,'ONS Nov25 T4b'!K:K)/1000 -> 10 | DI7: =SUMIF('ONS Nov25 T4b'!$T:$T,'Chart Data'!$AN7,'ONS Nov25 T4b'!O:O)/1000 -> 4 | DJ7: =SUMIF('ONS Nov25 T4b'!$T:$T,'Chart Data'!$AN7,'ONS Nov25 T4b'!P:P)/1000 -> 5 | DK7: =DB7-DC7-DD7-DE7-DF7-DG7-DH7-DI7-DJ7 -> -1 | DM7: 2027 | DN7: =100*(Data!B61/Data!$B$58) -> 103.63217 | DO7: =100*('OBR Nov25 ST1.1'!R117/'OBR Nov25 ST1.1'!$R$114) -> 104.46214 | DP7: ='OBR Nov25 C2.25'!M29 -> 104.03723 | DQ7: =DN7 -> 103.63217 | DR7: ='OBR Nov25 C2.25'!O29-'Chart Data'!DQ7 -> 0.63202207 | DT7: 1977 | DU7: =100*((Data!M11/Data!M10)-1) -> 0.58379587 | DW7: 0 | DX7: 65 | DY7: 60 | EA7: 34060 | EB7: =100*(HAVERM!C46/HAVERM!B46) -> 21.187332 | EC7: =AVERAGE($EB$7:$EB$399) -> 25.050854 | EE7: =HAVERM!C46 -> 1813 | EF7: =HAVERM!B46-HAVERM!C46 -> 6744 | EH7: Total | EI7: =SUM(EI4:EI6) -> 100 | EJ7: =SUM(EJ4:EJ6) -> 100 | EK7: =SUM(EK4:EK6) -> 100 | EL7: =SUM(EL4:EL6) -> 100 | EM7: =SUM(EM4:EM6) -> 100 | EN7: =SUM(EN4:EN6) -> 100 | EO7: =SUM(EO4:EO6) -> 100 | EP7: =SUM(EP4:EP6) -> 100 | ... FU7: =SUM(FU4:FU6) -> 100 | GC7: q/q | GD7: =100*((GD5/GD4)^(1/144)-1) -> 0.52000047 | GF7: q/q | GG7: =100*((GG5/GG4)^(1/48)-1) -> 0.084572698 | GI7: q/q | GJ7: =100*((GJ5/GJ4)^(1/23)-1) -> 0.091070009 | GL7: ='OBR Nov25 ST1.15'!B73 -> 2026-27 | GM7: ='OBR Nov25 ST1.15'!O73 -> 0.69881766 | GN7: ='OBR Nov25 ST1.15'!M73 -> 1.2938669 | GP7: ='OBR Nov25 ST1.15'!F73 -> 56753.878 | GQ7: ='OBR Nov25 ST1.15'!D73 -> 2885859 | GR7: =GR6+M31-P31 -> -374.64021 | GS7: =GR7*$GR$12 -> -314.57065 | GT7: =GP7+GS7 -> 56439.307 | GU7: =100*((GT7/GT6)-1) -> 0.52292416 | GV7: =GN7-GM7+GU7 -> 1.1179734 | GW7: =GW6*(1+GV7/100) -> 2869963.4 | GX7: =100*((GW7/GQ7)-1) -> -0.55081067 | GZ7: 2018 | HA7: =100*(Data!B52/Data!$B$57) -> 95.935235 | HB7: =HA7 -> 95.935235 | HD7: =100*((HB7/HA7)-1) -> 0
A8: 1984 | B8: =Data!F18*Data!G18 -> 24.9108 | C8: =Data!H18/Data!I18 -> 8.5981658 | D8: =Data!E18 -> 1295894 | E8: =Data!J18 -> -1.777241 | F8: =Data!D18 -> 1251974 | G8: =Data!B18 -> 1232675 | I8: =100*((F8/F7)-1) -> 3.524538 | J8: =100*((G8/G7)-1) -> 2.2430559 | L8: 2004 | M8: ='[2]2022-based'!L11 -> 209.5 | R8: 2024 | S8: ='[2]2022-based'!Q31 -> 69281.437 | T8: 69226.231 | U8: 69226.231 | V8: =S8 -> 69281.437 | W8: 69395 | Y8: 2016 | Z8: =SUMIF('ONS Nov25 T1'!$L:$L,'Chart Data'!$Y8,'ONS Nov25 T1'!$C:$C)/1000 -> 832 | AA8: =SUMIF('ONS Nov25 T1'!$M:$M,'Chart Data'!$Y8,'ONS Nov25 T1'!$C:$C)/1000 -> 511 | AB8: =SUMIF('ONS Nov25 T1'!$N:$N,'Chart Data'!$Y8,'ONS Nov25 T1'!$C:$C)/1000 -> 321 | AC8: =Z8-AA8 -> 321 | AE8: 2025 | AF8: =AS8 -> 98 | AG8: =AU8 -> 288 | AH8: =AT8+AV8 -> 102 | AI8: =AW8 -> 63 | AJ8: =AQ8 -> 74 | AK8: =AP8+AX8+AY8+AZ8 -> 272 | AL8: =AO8-SUM(AF8:AK8) -> 1 | AN8: 2025 | AO8: =+AP8+AQ8+AR8 -> 898 | AP8: =Z17-AQ8-AR8 -> 122 | AQ8: =SUMIF('ONS Nov25 T1'!$L:$L,'Chart Data'!$Y8,'ONS Nov25 T1'!$D:$D)/1000 -> 74 | AR8: =BC8+BK8 -> 702 | AS8: =BD8+BL8 -> 98 | AT8: =BE8+BM8 -> 89 | AU8: =BF8+BN8 -> 288 | AV8: =BG8+BO8 -> 13 | AW8: =BH8+BP8 -> 63 | AX8: =BQ8 -> 41 | AY8: =BR8 -> 96 | AZ8: =BS8 -> 13 | BA8: =AR8-AS8-AT8-AU8-AV8-AW8-AX8-AY8-AZ8 -> 1 | BC8: =SUMIF('ONS Nov25 T4a'!$P:$P,'Chart Data'!$AN8,'ONS Nov25 T4a'!C:C)/1000 -> 32 | BD8: =SUMIF('ONS Nov25 T4a'!$P:$P,'Chart Data'!$AN8,'ONS Nov25 T4a'!E:E)/1000 -> 12 | BE8: =SUMIF('ONS Nov25 T4a'!$P:$P,'Chart Data'!$AN8,'ONS Nov25 T4a'!F:F)/1000 -> 4 | BF8: =SUMIF('ONS Nov25 T4a'!$P:$P,'Chart Data'!$AN8,'ONS Nov25 T4a'!H:H)/1000 -> 13 | BG8: =SUMIF('ONS Nov25 T4a'!$P:$P,'Chart Data'!$AN8,'ONS Nov25 T4a'!I:I)/1000 -> 0 | BH8: =SUMIF('ONS Nov25 T4a'!$P:$P,'Chart Data'!$AN8,'ONS Nov25 T4a'!J:J)/1000 -> 3 | BI8: =BC8-BD8-BE8-BF8-BG8-BH8 -> 0 | BK8: =SUMIF('ONS Nov25 T4b'!$S:$S,'Chart Data'!$AN8,'ONS Nov25 T4b'!C:C)/1000 -> 670 | BL8: =SUMIF('ONS Nov25 T4b'!$S:$S,'Chart Data'!$AN8,'ONS Nov25 T4b'!E:E)/1000 -> 86 | BM8: =SUMIF('ONS Nov25 T4b'!$S:$S,'Chart Data'!$AN8,'ONS Nov25 T4b'!F:F)/1000 -> 85 | BN8: =SUMIF('ONS Nov25 T4b'!$S:$S,'Chart Data'!$AN8,'ONS Nov25 T4b'!H:H)/1000 -> 275 | BO8: =SUMIF('ONS Nov25 T4b'!$S:$S,'Chart Data'!$AN8,'ONS Nov25 T4b'!I:I)/1000 -> 13 | BP8: =SUMIF('ONS Nov25 T4b'!$S:$S,'Chart Data'!$AN8,'ONS Nov25 T4b'!J:J)/1000 -> 60 | BQ8: =SUMIF('ONS Nov25 T4b'!$S:$S,'Chart Data'!$AN8,'ONS Nov25 T4b'!K:K)/1000 -> 41 | BR8: =SUMIF('ONS Nov25 T4b'!$S:$S,'Chart Data'!$AN8,'ONS Nov25 T4b'!O:O)/1000 -> 96 | BS8: =SUMIF('ONS Nov25 T4b'!$S:$S,'Chart Data'!$AN8,'ONS Nov25 T4b'!P:P)/1000 -> 13 | BT8: =BK8-BL8-BM8-BN8-BO8-BP8-BQ8-BR8-BS8 -> 1 | BV8: 2025 | BW8: =CJ8 -> 45 | BX8: =CL8 -> 122 | BY8: =CK8+CM8 -> 51 | BZ8: =CN8 -> 47 | CA8: =CH8 -> 252 | CB8: =CG8+CO8+CP8+CQ8 -> 178 | CC8: =CF8-SUM(BW8:CB8) -> -2 | CE8: 2025 | CF8: =CG8+CH8+CI8 -> 693 | CG8: =AA17-CH8-CI8 -> 145 | CH8: =SUMIF('ONS Nov25 T1'!$M:$M,'Chart Data'!$CE8,'ONS Nov25 T1'!$D:$D)/1000 -> 252 | CI8: =CT8+DB8 -> 296 | CJ8: =CU8+DC8 -> 45 | CK8: =CV8+DD8 -> 24 | CL8: =CW8+DE8 -> 122 | CM8: =CX8+DF8 -> 27 | CN8: =CY8+DG8 -> 47 | CO8: =DH8 -> 20 | CP8: =DI8 -> 6 | CQ8: =DJ8 -> 7 | CR8: =CI8-CJ8-CK8-CL8-CM8-CN8-CO8-CP8-CQ8 -> -2 | CT8: =SUMIF('ONS Nov25 T4a'!$Q:$Q,'Chart Data'!$CE8,'ONS Nov25 T4a'!C:C)/1000 -> 10 | CU8: =SUMIF('ONS Nov25 T4a'!$Q:$Q,'Chart Data'!$CE8,'ONS Nov25 T4a'!E:E)/1000 -> 4 | CV8: =SUMIF('ONS Nov25 T4a'!$Q:$Q,'Chart Data'!$CE8,'ONS Nov25 T4a'!F:F)/1000 -> 1 | CW8: =SUMIF('ONS Nov25 T4a'!$Q:$Q,'Chart Data'!$CE8,'ONS Nov25 T4a'!H:H)/1000 -> 4 | CX8: =SUMIF('ONS Nov25 T4a'!$Q:$Q,'Chart Data'!$CE8,'ONS Nov25 T4a'!I:I)/1000 -> 0 | CY8: =SUMIF('ONS Nov25 T4a'!$Q:$Q,'Chart Data'!$CE8,'ONS Nov25 T4a'!J:J)/1000 -> 1 | CZ8: =CT8-CU8-CV8-CW8-CX8-CY8 -> 0 | DB8: =SUMIF('ONS Nov25 T4b'!$T:$T,'Chart Data'!$CE8,'ONS Nov25 T4b'!C:C)/1000 -> 286 | DC8: =SUMIF('ONS Nov25 T4b'!$T:$T,'Chart Data'!$CE8,'ONS Nov25 T4b'!E:E)/1000 -> 41 | DD8: =SUMIF('ONS Nov25 T4b'!$T:$T,'Chart Data'!$CE8,'ONS Nov25 T4b'!F:F)/1000 -> 23 | DE8: =SUMIF('ONS Nov25 T4b'!$T:$T,'Chart Data'!$AN8,'ONS Nov25 T4b'!H:H)/1000 -> 118 | DF8: =SUMIF('ONS Nov25 T4b'!$T:$T,'Chart Data'!$AN8,'ONS Nov25 T4b'!I:I)/1000 -> 27 | DG8: =SUMIF('ONS Nov25 T4b'!$T:$T,'Chart Data'!$AN8,'ONS Nov25 T4b'!J:J)/1000 -> 46 | DH8: =SUMIF('ONS Nov25 T4b'!$T:$T,'Chart Data'!$AN8,'ONS Nov25 T4b'!K:K)/1000 -> 20 | DI8: =SUMIF('ONS Nov25 T4b'!$T:$T,'Chart Data'!$AN8,'ONS Nov25 T4b'!O:O)/1000 -> 6 | DJ8: =SUMIF('ONS Nov25 T4b'!$T:$T,'Chart Data'!$AN8,'ONS Nov25 T4b'!P:P)/1000 -> 7 | DK8: =DB8-DC8-DD8-DE8-DF8-DG8-DH8-DI8-DJ8 -> -2 | DM8: 2028 | DN8: =100*(Data!B62/Data!$B$58) -> 105.12535 | DO8: =100*('OBR Nov25 ST1.1'!R118/'OBR Nov25 ST1.1'!$R$114) -> 105.99506 | DP8: ='OBR Nov25 C2.25'!M30 -> 105.48614 | DQ8: ='OBR Nov25 C2.25'!N30 -> 104.98848 | DR8: ='OBR Nov25 C2.25'!O30-'Chart Data'!DQ8 -> 0.98981322 | DT8: 1978 | DU8: =100*((Data!M12/Data!M11)-1) -> 0.62030177 | DW8: 0 | DX8: 65 | DY8: 60 | EA8: 34090 | EB8: =100*(HAVERM!C47/HAVERM!B47) -> 21.412726 | EC8: =AVERAGE($EB$7:$EB$399) -> 25.050854 | EE8: =HAVERM!C47 -> 1834 | EF8: =HAVERM!B47-HAVERM!C47 -> 6731 | FW8: 1961 | GL8: ='OBR Nov25 ST1.15'!B74 -> 2027-28 | GM8: ='OBR Nov25 ST1.15'!O74 -> 0.71395504 | GN8: ='OBR Nov25 ST1.15'!M74 -> 1.2834508 | GP8: ='OBR Nov25 ST1.15'!F74 -> 57159.075 | GQ8: ='OBR Nov25 ST1.15'!D74 -> 2922897.6 | GR8: =GR7+M32-P32 -> -487.46056 | GS8: =GR8*$GR$12 -> -409.30147 | GT8: =GP8+GS8 -> 56749.774 | GU8: =100*((GT8/GT7)-1) -> 0.55008889 | GV8: =GN8-GM8+GU8 -> 1.1195846 | GW8: =GW7*(1+GV8/100) -> 2902095.1 | GX8: =100*((GW8/GQ8)-1) -> -0.71170918 | GZ8: 2019 | HA8: =100*(Data!B53/Data!$B$57) -> 97.140468 | HB8: =HA8 -> 97.140468 | HD8: =100*((HB8/HA8)-1) -> 0
A9: 1985 | B9: =Data!F19*Data!G19 -> 25.10787 | C9: =Data!H19/Data!I19 -> 8.6987754 | D9: =Data!E19 -> 1321996 | E9: =Data!J19 -> -1.764964 | F9: =Data!D19 -> 1287060 | G9: =Data!B19 -> 1283200 | I9: =100*((F9/F8)-1) -> 2.8024544 | J9: =100*((G9/G8)-1) -> 4.0988095 | L9: 2005 | M9: ='[2]2022-based'!L12 -> 335.6 | R9: 2025 | S9: ='[2]2022-based'!Q32 -> 69487 | T9: 69867.979 | U9: 69584.497 | V9: =V8*W9/W8 -> 69569.69 | W9: 69683.726 | Y9: 2017 | Z9: =SUMIF('ONS Nov25 T1'!$L:$L,'Chart Data'!$Y9,'ONS Nov25 T1'!$C:$C)/1000 -> 718 | AA9: =SUMIF('ONS Nov25 T1'!$M:$M,'Chart Data'!$Y9,'ONS Nov25 T1'!$C:$C)/1000 -> 518 | AB9: =SUMIF('ONS Nov25 T1'!$N:$N,'Chart Data'!$Y9,'ONS Nov25 T1'!$C:$C)/1000 -> 200 | AC9: =Z9-AA9 -> 200 | AE9: 2026 | AF9: =AS9 -> 39.2 | AG9: =AU9 -> 288 | AH9: =AT9+AV9 -> 57.5 | AI9: =AW9 -> 63 | AJ9: =AQ9 -> 75 | AK9: =AP9+AX9+AY9+AZ9 -> 246.5018 | AL9: =AO9-SUM(AF9:AK9) -> 0 | AN9: 2026 | AO9: ='[2]Migration calculations'!L17 -> 769.2018 | AP9: =AO9-AQ9-AR9 -> 104.5018 | AQ9: ='[2]Migration calculations'!U17 -> 75 | AR9: =SUM(AS9:AZ9) -> 589.7 | AS9: ='[2]Migration calculations'!W17 -> 39.2 | AT9: ='[2]Migration calculations'!X17 -> 44.5 | AU9: ='[2]Migration calculations'!Y17 -> 288 | AV9: ='[2]Migration calculations'!Z17 -> 13 | AW9: ='[2]Migration calculations'!AA17 -> 63 | AX9: ='[2]Migration calculations'!AB17 -> 32 | AY9: ='[2]Migration calculations'!AC17 -> 90 | AZ9: ='[2]Migration calculations'!AD17 -> 20 | BV9: 2026 | BW9: =CJ9 -> 45 | BX9: =CL9 -> 120 | BY9: =CK9+CM9 -> 43.4 | BZ9: =CN9 -> 45 | CA9: =CH9 -> 250 | CB9: =CG9+CO9+CP9+CQ9 -> 172.40146 | CC9: =CF9-SUM(BW9:CB9) -> 0 | CE9: 2026 | CF9: ='[2]Migration calculations'!M17 -> 675.80146 | CG9: =CF9-CH9-CI9 -> 141.40146 | CH9: ='[2]Migration calculations'!AL17 -> 250 | CI9: =SUM(CJ9:CQ9) -> 284.4 | CJ9: ='[2]Migration calculations'!AN17 -> 45 | CK9: ='[2]Migration calculations'!AO17 -> 23.4 | CL9: ='[2]Migration calculations'!AP17 -> 120 | CM9: ='[2]Migration calculations'!AQ17 -> 20 | CN9: ='[2]Migration calculations'!AR17 -> 45 | CO9: ='[2]Migration calculations'!AS17 -> 20 | CP9: ='[2]Migration calculations'!AT17 -> 6 | CQ9: ='[2]Migration calculations'!AU17 -> 5 | DM9: 2029 | DN9: =100*(Data!B63/Data!$B$58) -> 106.64783 | DO9: =100*('OBR Nov25 ST1.1'!R119/'OBR Nov25 ST1.1'!$R$114) -> 107.60945 | DP9: ='OBR Nov25 C2.25'!M31 -> 106.96116 | DQ9: ='OBR Nov25 C2.25'!N31 -> 105.82839 | DR9: ='OBR Nov25 C2.25'!O31-'Chart Data'!DQ9 -> 1.9043356 | DT9: 1979 | DU9: =100*((Data!M13/Data!M12)-1) -> 0.61644762 | DW9: 0 | DX9: 65 | DY9: 60 | EA9: 34121 | EB9: =100*(HAVERM!C48/HAVERM!B48) -> 21.681261 | EC9: =AVERAGE($EB$7:$EB$399) -> 25.050854 | EE9: =HAVERM!C48 -> 1857 | EF9: =HAVERM!B48-HAVERM!C48 -> 6708 | EI9: 2022 | EJ9: 2023 | EK9: 2024 | EL9: 2025 | EM9: 2026 | EN9: 2027 | EO9: 2028 | EP9: 2029 | EQ9: 2030 | ER9: 2031 | ES9: 2032 | ET9: 2033 | EU9: 2034 | EV9: 2035 | EW9: 2036 | EX9: 2037 | EY9: 2038 | EZ9: 2039 | FA9: 2040 | FB9: 2041 | FC9: 2042 | FD9: 2043 | FE9: 2044 | FF9: 2045 | FG9: 2046 | FH9: 2047 | FI9: 2048 | FJ9: 2049 | FK9: 2050 | FL9: 2051 | FM9: 2052 | FN9: 2053 | FO9: 2054 | FP9: 2055 | FQ9: 2056 | FR9: 2057 | FS9: 2058 | FT9: 2059 | FU9: 2060 | GL9: ='OBR Nov25 ST1.15'!B75 -> 2028-29 | GM9: ='OBR Nov25 ST1.15'!O75 -> 0.7367156 | GN9: ='OBR Nov25 ST1.15'!M75 -> 1.3662466 | GP9: ='OBR Nov25 ST1.15'!F75 -> 57580.175 | GQ9: ='OBR Nov25 ST1.15'!D75 -> 2962831.6 | GR9: =GR8+M33-P33 -> -610.19557 | GS9: =GR9*$GR$12 -> -512.35723 | GT9: =GP9+GS9 -> 57067.818 | GU9: =100*((GT9/GT8)-1) -> 0.56043231 | GV9: =GN9-GM9+GU9 -> 1.1899633 | GW9: =GW8*(1+GV9/100) -> 2936629 | GX9: =100*((GW9/GQ9)-1) -> -0.88437876 | GZ9: 2020 | HA9: =100*(Data!B54/Data!$B$57) -> 87.379895 | HB9: =HA9 -> 87.379895 | HD9: =100*((HB9/HA9)-1) -> 0
A10: 1986 | B10: =Data!F20*Data!G20 -> 846672.61 | C10: =Data!H20/Data!I20 -> 8.8112396 | D10: =Data!E20 -> 1343092 | E10: =Data!J20 -> -1.752906 | F10: =Data!D20 -> 1320242 | G10: =Data!B20 -> 1323173 | I10: =100*((F10/F9)-1) -> 2.5781238 | J10: =100*((G10/G9)-1) -> 3.1151029 | L10: 2006 | M10: ='[2]2022-based'!L13 -> 254.5 | R10: 2026 | S10: ='[2]2022-based'!Q33 -> 69592.921 | T10: 70414.3 | U10: 69850.426 | V10: =V9*W10/W9 -> 69831.52 | W10: 69945.985 | Y10: 2018 | Z10: =SUMIF('ONS Nov25 T1'!$L:$L,'Chart Data'!$Y10,'ONS Nov25 T1'!$C:$C)/1000 -> 757 | AA10: =SUMIF('ONS Nov25 T1'!$M:$M,'Chart Data'!$Y10,'ONS Nov25 T1'!$C:$C)/1000 -> 541 | AB10: =SUMIF('ONS Nov25 T1'!$N:$N,'Chart Data'!$Y10,'ONS Nov25 T1'!$C:$C)/1000 -> 216 | AC10: =Z10-AA10 -> 216 | AE10: 2027 | AF10: =AS10 -> 70 | AG10: =AU10 -> 288 | AH10: =AT10+AV10 -> 48 | AI10: =AW10 -> 60 | AJ10: =AQ10 -> 80 | AK10: =AP10+AX10+AY10+AZ10 -> 233.96392 | AL10: =AO10-SUM(AF10:AK10) -> 0 | AN10: 2027 | AO10: ='[2]Migration calculations'!L18 -> 779.96392 | AP10: =AO10-AQ10-AR10 -> 105.96392 | AQ10: ='[2]Migration calculations'!U18 -> 80 | AR10: =SUM(AS10:AZ10) -> 594 | AS10: ='[2]Migration calculations'!W18 -> 70 | AT10: ='[2]Migration calculations'!X18 -> 35 | AU10: ='[2]Migration calculations'!Y18 -> 288 | AV10: ='[2]Migration calculations'!Z18 -> 13 | AW10: ='[2]Migration calculations'!AA18 -> 60 | AX10: ='[2]Migration calculations'!AB18 -> 23 | AY10: ='[2]Migration calculations'!AC18 -> 85 | AZ10: ='[2]Migration calculations'!AD18 -> 20 | BV10: 2027 | BW10: =CJ10 -> 40 | BX10: =CL10 -> 120 | BY10: =CK10+CM10 -> 40.8 | BZ10: =CN10 -> 40 | CA10: =CH10 -> 250 | CB10: =CG10+CO10+CP10+CQ10 -> 150.09854 | CC10: =CF10-SUM(BW10:CB10) -> 0 | CE10: 2027 | CF10: ='[2]Migration calculations'!M18 -> 640.89854 | CG10: =CF10-CH10-CI10 -> 134.09854 | CH10: ='[2]Migration calculations'!AL18 -> 250 | CI10: =SUM(CJ10:CQ10) -> 256.8 | CJ10: ='[2]Migration calculations'!AN18 -> 40 | CK10: ='[2]Migration calculations'!AO18 -> 20.8 | CL10: ='[2]Migration calculations'!AP18 -> 120 | CM10: ='[2]Migration calculations'!AQ18 -> 20 | CN10: ='[2]Migration calculations'!AR18 -> 40 | CO10: ='[2]Migration calculations'!AS18 -> 10 | CP10: ='[2]Migration calculations'!AT18 -> 4 | CQ10: ='[2]Migration calculations'!AU18 -> 2 | DM10: 2030 | DN10: =100*(Data!B64/Data!$B$58) -> 108.2189 | DO10: =100*('OBR Nov25 ST1.1'!R120/'OBR Nov25 ST1.1'!$R$114) -> 109.27672 | DT10: 1980 | DU10: =100*((Data!M14/Data!M13)-1) -> 0.61267083 | DW10: 0 | DX10: 65 | DY10: 60 | EA10: 34151 | EB10: =100*(HAVERM!C49/HAVERM!B49) -> 21.949802 | EC10: =AVERAGE($EB$7:$EB$399) -> 25.050854 | EE10: =HAVERM!C49 -> 1889 | EF10: =HAVERM!B49-HAVERM!C49 -> 6717 | EH10: 0-15 | EI10: =SUM('ONS popproj by year Jan25'!C2:C17,'ONS popproj by year Jan25'!C109:C124) -> 12397632 | EJ10: =SUM('ONS popproj by year Jan25'!D2:D17,'ONS popproj by year Jan25'!D109:D124) -> 12397236 | EK10: =SUM('ONS popproj by year Jan25'!E2:E17,'ONS popproj by year Jan25'!E109:E124) -> 12336987 | EL10: =SUM('ONS popproj by year Jan25'!F2:F17,'ONS popproj by year Jan25'!F109:F124) -> 12271926 | EM10: =SUM('ONS popproj by year Jan25'!G2:G17,'ONS popproj by year Jan25'!G109:G124) -> 12188266 | EN10: =SUM('ONS popproj by year Jan25'!H2:H17,'ONS popproj by year Jan25'!H109:H124) -> 12080358 | EO10: =SUM('ONS popproj by year Jan25'!I2:I17,'ONS popproj by year Jan25'!I109:I124) -> 11959025 | EP10: =SUM('ONS popproj by year Jan25'!J2:J17,'ONS popproj by year Jan25'!J109:J124) -> 11857264 | ... FU10: =SUM('ONS popproj by year Jan25'!AO2:AO17,'ONS popproj by year Jan25'!AO109:AO124) -> 11389081 | GL10: ='OBR Nov25 ST1.15'!B76 -> 2029-30 | GM10: ='OBR Nov25 ST1.15'!O76 -> 0.72803113 | GN10: ='OBR Nov25 ST1.15'!M76 -> 1.4860266 | GP10: ='OBR Nov25 ST1.15'!F76 -> 57999.377 | GQ10: ='OBR Nov25 ST1.15'!D76 -> 3006860.1 | GR10: =GR9+M34-P34 -> -721.23904 | GS10: =GR10*$GR$12 -> -605.59607 | GT10: =GP10+GS10 -> 57393.781 | GU10: =100*((GT10/GT9)-1) -> 0.5711849 | GV10: =GN10-GM10+GU10 -> 1.3291803 | GW10: =GW9*(1+GV10/100) -> 2975662 | GX10: =100*((GW10/GQ10)-1) -> -1.0375615 | GZ10: 2021 | HA10: =100*(Data!B55/Data!$B$57) -> 94.844857 | HB10: =HA10 -> 94.844857 | HD10: =100*((HB10/HA10)-1) -> 0
A11: 1987 | B11: =Data!F21*Data!G21 -> 854924.91 | C11: =Data!H21/Data!I21 -> 8.9162753 | D11: =Data!E21 -> 1373292 | E11: =Data!J21 -> -1.741462 | F11: =Data!D21 -> 1357335 | G11: =Data!B21 -> 1395353 | I11: =100*((F11/F10)-1) -> 2.8095607 | J11: =100*((G11/G10)-1) -> 5.455069 | L11: 2007 | M11: ='[2]2022-based'!L14 -> 304.6 | R11: 2027 | S11: ='[2]2022-based'!Q34 -> 69742.9 | T11: 70861.913 | U11: 70106.549 | V11: =V10*W11/W10 -> 70096.392 | W11: 70211.29 | Y11: 2019 | Z11: =SUMIF('ONS Nov25 T1'!$L:$L,'Chart Data'!$Y11,'ONS Nov25 T1'!$C:$C)/1000 -> 821 | AA11: =SUMIF('ONS Nov25 T1'!$M:$M,'Chart Data'!$Y11,'ONS Nov25 T1'!$C:$C)/1000 -> 597 | AB11: =SUMIF('ONS Nov25 T1'!$N:$N,'Chart Data'!$Y11,'ONS Nov25 T1'!$C:$C)/1000 -> 224 | AC11: =Z11-AA11 -> 224 | AE11: 2028 | AF11: =AS11 -> 85 | AG11: =AU11 -> 288 | AH11: =AT11+AV11 -> 55.5 | AI11: =AW11 -> 60 | AJ11: =AQ11 -> 80 | AK11: =AP11+AX11+AY11+AZ11 -> 221.30026 | AL11: =AO11-SUM(AF11:AK11) -> 0 | AN11: 2028 | AO11: ='[2]Migration calculations'!L19 -> 789.80026 | AP11: =AO11-AQ11-AR11 -> 107.30026 | AQ11: ='[2]Migration calculations'!U19 -> 80 | AR11: =SUM(AS11:AZ11) -> 602.5 | AS11: ='[2]Migration calculations'!W19 -> 85 | AT11: ='[2]Migration calculations'!X19 -> 42.5 | AU11: ='[2]Migration calculations'!Y19 -> 288 | AV11: ='[2]Migration calculations'!Z19 -> 13 | AW11: ='[2]Migration calculations'!AA19 -> 60 | AX11: ='[2]Migration calculations'!AB19 -> 14 | AY11: ='[2]Migration calculations'!AC19 -> 80 | AZ11: ='[2]Migration calculations'!AD19 -> 20 | BV11: 2028 | BW11: =CJ11 -> 35 | BX11: =CL11 -> 120 | BY11: =CK11+CM11 -> 38.2 | BZ11: =CN11 -> 37 | CA11: =CH11 -> 250 | CB11: =CG11+CO11+CP11+CQ11 -> 132.11861 | CC11: =CF11-SUM(BW11:CB11) -> 0 | CE11: 2028 | CF11: ='[2]Migration calculations'!M19 -> 612.31861 | CG11: =CF11-CH11-CI11 -> 128.11861 | CH11: ='[2]Migration calculations'!AL19 -> 250 | CI11: =SUM(CJ11:CQ11) -> 234.2 | CJ11: ='[2]Migration calculations'!AN19 -> 35 | CK11: ='[2]Migration calculations'!AO19 -> 18.2 | CL11: ='[2]Migration calculations'!AP19 -> 120 | CM11: ='[2]Migration calculations'!AQ19 -> 20 | CN11: ='[2]Migration calculations'!AR19 -> 37 | CO11: ='[2]Migration calculations'!AS19 -> 0 | CP11: ='[2]Migration calculations'!AT19 -> 2 | CQ11: ='[2]Migration calculations'!AU19 -> 2 | DT11: 1981 | DU11: =100*((Data!M15/Data!M14)-1) -> 0.57075665 | DW11: 0 | DX11: 65 | DY11: 60 | EA11: 34182 | EB11: =100*(HAVERM!C50/HAVERM!B50) -> 21.950367 | EC11: =AVERAGE($EB$7:$EB$399) -> 25.050854 | EE11: =HAVERM!C50 -> 1884 | EF11: =HAVERM!B50-HAVERM!C50 -> 6699 | EH11: 16-64 | EI11: =SUM('ONS popproj by year Jan25'!C18:C66,'ONS popproj by year Jan25'!C125:C173) -> 42468848 | EJ11: =SUM('ONS popproj by year Jan25'!D18:D66,'ONS popproj by year Jan25'!D125:D173) -> 43160304 | EK11: =SUM('ONS popproj by year Jan25'!E18:E66,'ONS popproj by year Jan25'!E125:E173) -> 43725847 | EL11: =SUM('ONS popproj by year Jan25'!F18:F66,'ONS popproj by year Jan25'!F125:F173) -> 44191288 | EM11: =SUM('ONS popproj by year Jan25'!G18:G66,'ONS popproj by year Jan25'!G125:G173) -> 44556445 | EN11: =SUM('ONS popproj by year Jan25'!H18:H66,'ONS popproj by year Jan25'!H125:H173) -> 44826638 | EO11: =SUM('ONS popproj by year Jan25'!I18:I66,'ONS popproj by year Jan25'!I125:I173) -> 44999376 | EP11: =SUM('ONS popproj by year Jan25'!J18:J66,'ONS popproj by year Jan25'!J125:J173) -> 45137247 | ... FU11: =SUM('ONS popproj by year Jan25'!AO18:AO66,'ONS popproj by year Jan25'!AO125:AO173) -> 47518437 | GZ11: 2022 | HA11: =100*(Data!B56/Data!$B$57) -> 99.729086 | HB11: =HA11 -> 99.729086 | HD11: =100*((HB11/HA11)-1) -> 0
A12: 1988 | B12: =Data!F22*Data!G22 -> 869416.83 | C12: =Data!H22/Data!I22 -> 9.0335852 | D12: =Data!E22 -> 1416696 | E12: =Data!J22 -> -1.730137 | F12: =Data!D22 -> 1405883 | G12: =Data!B22 -> 1471002 | I12: =100*((F12/F11)-1) -> 3.5767147 | J12: =100*((G12/G11)-1) -> 5.4214955 | L12: 2008 | M12: ='[2]2022-based'!L15 -> 283.6 | R12: 2028 | S12: ='[2]2022-based'!Q35 -> 69926.569 | T12: 71208.101 | U12: 70387.142 | V12: =V11*W12/W11 -> 70387.343 | W12: 70502.718 | Y12: 2020 | Z12: =SUMIF('ONS Nov25 T1'!$L:$L,'Chart Data'!$Y12,'ONS Nov25 T1'!$C:$C)/1000 -> 736 | AA12: =SUMIF('ONS Nov25 T1'!$M:$M,'Chart Data'!$Y12,'ONS Nov25 T1'!$C:$C)/1000 -> 625 | AB12: =SUMIF('ONS Nov25 T1'!$N:$N,'Chart Data'!$Y12,'ONS Nov25 T1'!$C:$C)/1000 -> 111 | AC12: =Z12-AA12 -> 111 | AE12: 2029 | AF12: =AS12 -> 100 | AG12: =AU12 -> 292 | AH12: =AT12+AV12 -> 63 | AI12: =AW12 -> 60 | AJ12: =AQ12 -> 80 | AK12: =AP12+AX12+AY12+AZ12 -> 209.26546 | AL12: =AO12-SUM(AF12:AK12) -> 0 | AN12: 2029 | AO12: ='[2]Migration calculations'!L20 -> 804.26546 | AP12: =AO12-AQ12-AR12 -> 109.26546 | AQ12: ='[2]Migration calculations'!U20 -> 80 | AR12: =SUM(AS12:AZ12) -> 615 | AS12: ='[2]Migration calculations'!W20 -> 100 | AT12: ='[2]Migration calculations'!X20 -> 50 | AU12: ='[2]Migration calculations'!Y20 -> 292 | AV12: ='[2]Migration calculations'!Z20 -> 13 | AW12: ='[2]Migration calculations'!AA20 -> 60 | AX12: ='[2]Migration calculations'!AB20 -> 5 | AY12: ='[2]Migration calculations'!AC20 -> 75 | AZ12: ='[2]Migration calculations'!AD20 -> 20 | BV12: 2029 | BW12: =CJ12 -> 30 | BX12: =CL12 -> 120 | BY12: =CK12+CM12 -> 35.6 | BZ12: =CN12 -> 37 | CA12: =CH12 -> 250 | CB12: =CG12+CO12+CP12+CQ12 -> 127.57847 | CC12: =CF12-SUM(BW12:CB12) -> 0 | CE12: 2029 | CF12: ='[2]Migration calculations'!M20 -> 600.17847 | CG12: =CF12-CH12-CI12 -> 125.57847 | CH12: ='[2]Migration calculations'!AL20 -> 250 | CI12: =SUM(CJ12:CQ12) -> 224.6 | CJ12: ='[2]Migration calculations'!AN20 -> 30 | CK12: ='[2]Migration calculations'!AO20 -> 15.6 | CL12: ='[2]Migration calculations'!AP20 -> 120 | CM12: ='[2]Migration calculations'!AQ20 -> 20 | CN12: ='[2]Migration calculations'!AR20 -> 37 | CO12: ='[2]Migration calculations'!AS20 -> 0 | CP12: ='[2]Migration calculations'!AT20 -> 0 | CQ12: ='[2]Migration calculations'!AU20 -> 2 | DO12: =100*((DN10/DO10)-1) -> -0.96801371 | DT12: 1982 | DU12: =100*((Data!M16/Data!M15)-1) -> 0.4752789 | DW12: 0 | DX12: 65 | DY12: 60 | EA12: 34213 | EB12: =100*(HAVERM!C51/HAVERM!B51) -> 22.187282 | EC12: =AVERAGE($EB$7:$EB$399) -> 25.050854 | EE12: =HAVERM!C51 -> 1905 | EF12: =HAVERM!B51-HAVERM!C51 -> 6681 | EH12: 65+ | EI12: =SUM('ONS popproj by year Jan25'!C67:C108,'ONS popproj by year Jan25'!C174:C215) -> 12736281 | EJ12: =SUM('ONS popproj by year Jan25'!D67:D108,'ONS popproj by year Jan25'!D174:D215) -> 12934955 | EK12: =SUM('ONS popproj by year Jan25'!E67:E108,'ONS popproj by year Jan25'!E174:E215) -> 13163397 | EL12: =SUM('ONS popproj by year Jan25'!F67:F108,'ONS popproj by year Jan25'!F174:F215) -> 13404765 | EM12: =SUM('ONS popproj by year Jan25'!G67:G108,'ONS popproj by year Jan25'!G174:G215) -> 13669589 | EN12: =SUM('ONS popproj by year Jan25'!H67:H108,'ONS popproj by year Jan25'!H174:H215) -> 13954917 | EO12: =SUM('ONS popproj by year Jan25'!I67:I108,'ONS popproj by year Jan25'!I174:I215) -> 14249700 | EP12: =SUM('ONS popproj by year Jan25'!J67:J108,'ONS popproj by year Jan25'!J174:J215) -> 14553151 | ... FU12: =SUM('ONS popproj by year Jan25'!AO67:AO108,'ONS popproj by year Jan25'!AO174:AO215) -> 19897799 | FW12: 1962 | GL12: 16+ share of migrants | GR12: ='[2]2022-based'!$I$2+'[2]2022-based'!$I$4 -> 0.83966069 | GZ12: 2023 | HA12: =100*(Data!B57/Data!$B$57) -> 100 | HB12: =HA12 -> 100 | HD12: =100*((HB12/HA12)-1) -> 0
A13: 1989 | B13: =Data!F23*Data!G23 -> 881201.46 | C13: =Data!H23/Data!I23 -> 9.1558688 | D13: =Data!E23 -> 1468447 | E13: =Data!J23 -> -1.718885 | F13: =Data!D23 -> 1456761 | G13: =Data!B23 -> 1506644 | I13: =100*((F13/F12)-1) -> 3.6189356 | J13: =100*((G13/G12)-1) -> 2.4229743 | L13: 2009 | M13: ='[2]2022-based'!L16 -> 219.8 | R13: 2029 | S13: ='[2]2022-based'!Q36 -> 70130.217 | T13: 71547.662 | U13: 70696.611 | V13: =V12*W13/W12 -> 70698.372 | W13: 70814.258 | Y13: 2021 | Z13: =SUMIF('ONS Nov25 T1'!$L:$L,'Chart Data'!$Y13,'ONS Nov25 T1'!$C:$C)/1000 -> 818 | AA13: =SUMIF('ONS Nov25 T1'!$M:$M,'Chart Data'!$Y13,'ONS Nov25 T1'!$C:$C)/1000 -> 567 | AB13: =SUMIF('ONS Nov25 T1'!$N:$N,'Chart Data'!$Y13,'ONS Nov25 T1'!$C:$C)/1000 -> 251 | AC13: =Z13-AA13 -> 251 | AE13: 2030 | AF13: =AS13 -> 110 | AG13: =AU13 -> 297 | AH13: =AT13+AV13 -> 68 | AI13: =AW13 -> 61 | AJ13: =AQ13 -> 80 | AK13: =AP13+AX13+AY13+AZ13 -> 200.99485 | AL13: =AO13-SUM(AF13:AK13) -> 0 | AN13: 2030 | AO13: ='[2]Migration calculations'!L21 -> 816.99485 | AP13: =AO13-AQ13-AR13 -> 110.99485 | AQ13: ='[2]Migration calculations'!U21 -> 80 | AR13: =SUM(AS13:AZ13) -> 626 | AS13: ='[2]Migration calculations'!W21 -> 110 | AT13: ='[2]Migration calculations'!X21 -> 55 | AU13: ='[2]Migration calculations'!Y21 -> 297 | AV13: ='[2]Migration calculations'!Z21 -> 13 | AW13: ='[2]Migration calculations'!AA21 -> 61 | AX13: ='[2]Migration calculations'!AB21 -> 0 | AY13: ='[2]Migration calculations'!AC21 -> 70 | AZ13: ='[2]Migration calculations'!AD21 -> 20 | BV13: 2030 | BW13: =CJ13 -> 25 | BX13: =CL13 -> 120 | BY13: =CK13+CM13 -> 33 | BZ13: =CN13 -> 35 | CA13: =CH13 -> 250 | CB13: =CG13+CO13+CP13+CQ13 -> 125.03832 | CC13: =CF13-SUM(BW13:CB13) -> 0 | CE13: 2030 | CF13: ='[2]Migration calculations'!M21 -> 588.03832 | CG13: =CF13-CH13-CI13 -> 123.03832 | CH13: ='[2]Migration calculations'!AL21 -> 250 | CI13: =SUM(CJ13:CQ13) -> 215 | CJ13: ='[2]Migration calculations'!AN21 -> 25 | CK13: ='[2]Migration calculations'!AO21 -> 13 | CL13: ='[2]Migration calculations'!AP21 -> 120 | CM13: ='[2]Migration calculations'!AQ21 -> 20 | CN13: ='[2]Migration calculations'!AR21 -> 35 | CO13: ='[2]Migration calculations'!AS21 -> 0 | CP13: ='[2]Migration calculations'!AT21 -> 0 | CQ13: ='[2]Migration calculations'!AU21 -> 2 | DT13: 1983 | DU13: =100*((Data!M17/Data!M16)-1) -> 0.70478951 | DV13: =AVERAGE(DU4:DU13) -> 0.42994854 | DW13: 0 | DX13: 65 | DY13: 60 | EA13: 34243 | EB13: =100*(HAVERM!C52/HAVERM!B52) -> 22.563744 | EC13: =AVERAGE($EB$7:$EB$399) -> 25.050854 | EE13: =HAVERM!C52 -> 1938 | EF13: =HAVERM!B52-HAVERM!C52 -> 6651 | EH13: Total | EI13: =SUM('ONS popproj by year Jan25'!C2:C215) -> 67602761 | EJ13: =SUM('ONS popproj by year Jan25'!D2:D215) -> 68492495 | EK13: =SUM('ONS popproj by year Jan25'!E2:E215) -> 69226231 | EL13: =SUM('ONS popproj by year Jan25'!F2:F215) -> 69867979 | EM13: =SUM('ONS popproj by year Jan25'!G2:G215) -> 70414300 | EN13: =SUM('ONS popproj by year Jan25'!H2:H215) -> 70861913 | EO13: =SUM('ONS popproj by year Jan25'!I2:I215) -> 71208101 | EP13: =SUM('ONS popproj by year Jan25'!J2:J215) -> 71547662 | ... FU13: =SUM('ONS popproj by year Jan25'!AO2:AO215) -> 78805317 | GZ13: 2024 | HA13: =100*(Data!B58/Data!$B$57) -> 101.08813 | HB13: =HA13 -> 101.08813 | HD13: =100*((HB13/HA13)-1) -> 0
A14: 1990 | B14: =Data!F24*Data!G24 -> 879722.49 | C14: =Data!H24/Data!I24 -> 9.2673112 | D14: =Data!E24 -> 1526420 | E14: =Data!J24 -> -1.707707 | F14: =Data!D24 -> 1496084 | G14: =Data!B24 -> 1515202 | I14: =100*((F14/F13)-1) -> 2.6993446 | J14: =100*((G14/G13)-1) -> 0.56801739 | L14: 2010 | M14: ='[2]2022-based'!L17 -> 255.4 | R14: 2030 | S14: ='[2]2022-based'!Q37 -> 70351.5 | T14: 71879.988 | U14: 71011.585 | V14: =V13*W14/W13 -> 71009.871 | W14: 71126.267 | Y14: 2022 | Z14: =SUMIF('ONS Nov25 T1'!$L:$L,'Chart Data'!$Y14,'ONS Nov25 T1'!$C:$C)/1000 -> 1167 | AA14: =SUMIF('ONS Nov25 T1'!$M:$M,'Chart Data'!$Y14,'ONS Nov25 T1'!$C:$C)/1000 -> 486 | AB14: =SUMIF('ONS Nov25 T1'!$N:$N,'Chart Data'!$Y14,'ONS Nov25 T1'!$C:$C)/1000 -> 681 | AC14: =Z14-AA14 -> 681 | AE14: 2031 | AF14: =AS14 -> 120 | AG14: =AU14 -> 300 | AH14: =AT14+AV14 -> 73 | AI14: =AW14 -> 62 | AJ14: =AQ14 -> 80 | AK14: =AP14+AX14+AY14+AZ14 -> 198.19588 | AL14: =AO14-SUM(AF14:AK14) -> 0 | AN14: 2031 | AO14: ='[2]Migration calculations'!L22 -> 833.19588 | AP14: =AO14-AQ14-AR14 -> 113.19588 | AQ14: ='[2]Migration calculations'!U22 -> 80 | AR14: =SUM(AS14:AZ14) -> 640 | AS14: ='[2]Migration calculations'!W22 -> 120 | AT14: ='[2]Migration calculations'!X22 -> 60 | AU14: ='[2]Migration calculations'!Y22 -> 300 | AV14: ='[2]Migration calculations'!Z22 -> 13 | AW14: ='[2]Migration calculations'!AA22 -> 62 | AX14: ='[2]Migration calculations'!AB22 -> 0 | AY14: ='[2]Migration calculations'!AC22 -> 65 | AZ14: ='[2]Migration calculations'!AD22 -> 20 | BV14: 2031 | BW14: =CJ14 -> 23.5 | BX14: =CL14 -> 120 | BY14: =CK14+CM14 -> 32.22 | BZ14: =CN14 -> 33 | CA14: =CH14 -> 250 | CB14: =CG14+CO14+CP14+CQ14 -> 123.90584 | CC14: =CF14-SUM(BW14:CB14) -> 0 | CE14: 2031 | CF14: ='[2]Migration calculations'!M22 -> 582.62584 | CG14: =CF14-CH14-CI14 -> 121.90584 | CH14: ='[2]Migration calculations'!AL22 -> 250 | CI14: =SUM(CJ14:CQ14) -> 210.72 | CJ14: ='[2]Migration calculations'!AN22 -> 23.5 | CK14: ='[2]Migration calculations'!AO22 -> 12.22 | CL14: ='[2]Migration calculations'!AP22 -> 120 | CM14: ='[2]Migration calculations'!AQ22 -> 20 | CN14: ='[2]Migration calculations'!AR22 -> 33 | CO14: ='[2]Migration calculations'!AS22 -> 0 | CP14: ='[2]Migration calculations'!AT22 -> 0 | CQ14: ='[2]Migration calculations'!AU22 -> 2 | DT14: 1984 | DU14: =100*((Data!M18/Data!M17)-1) -> 0.697956 | DV14: =AVERAGE(DU5:DU14) -> 0.49694176 | DW14: 0 | DX14: 65 | DY14: 60 | EA14: 34274 | EB14: =100*(HAVERM!C53/HAVERM!B53) -> 22.481072 | EC14: =AVERAGE($EB$7:$EB$399) -> 25.050854 | EE14: =HAVERM!C53 -> 1930 | EF14: =HAVERM!B53-HAVERM!C53 -> 6655 | EH14: check | EI14: =EI13-EI10-EI11-EI12 -> 0 | EJ14: =EJ13-EJ10-EJ11-EJ12 -> 0 | EK14: =EK13-EK10-EK11-EK12 -> 0 | EL14: =EL13-EL10-EL11-EL12 -> 0 | EM14: =EM13-EM10-EM11-EM12 -> 0 | EN14: =EN13-EN10-EN11-EN12 -> 0 | EO14: =EO13-EO10-EO11-EO12 -> 0 | EP14: =EP13-EP10-EP11-EP12 -> 0 | ... FU14: =FU13-FU10-FU11-FU12 -> 0 | GL14: 5yr growth | GP14: =100*((GP10/GP5)^(1/5)-1) -> 0.76073012 | GQ14: =100*((GQ10/GQ5)^(1/5)-1) -> 1.3930014 | GT14: =100*((GT10/GT5)^(1/5)-1) -> 0.57568722 | GW14: =100*((GW10/GW5)^(1/5)-1) -> 1.2079516 | GZ14: 2025 | HA14: =100*(Data!B59/Data!$B$57) -> 102.4843 | HB14: =HB13*(1+HF14/100) -> 102.58761 | HD14: =100*((HB14/HA14)-1) -> 0.10080507 | HF14: =100*(('OBR Nov25 ST1.1'!R115/'OBR Nov25 ST1.1'!R114)-1) -> 1.4833428
A15: 1991 | B15: =Data!F25*Data!G25 -> 861885.45 | C15: =Data!H25/Data!I25 -> 9.3754123 | D15: =Data!E25 -> 1575894 | E15: =Data!J25 -> -1.696601 | F15: =Data!D25 -> 1517014 | G15: =Data!B25 -> 1493903 | I15: =100*((F15/F14)-1) -> 1.3989856 | J15: =100*((G15/G14)-1) -> -1.4056872 | L15: 2011 | M15: ='[2]2022-based'!L18 -> 270.3 | R15: 2031 | S15: ='[2]2022-based'!Q38 -> 70586.656 | T15: 72204.574 | U15: 71318.66 | Y15: 2023 | Z15: =SUMIF('ONS Nov25 T1'!$L:$L,'Chart Data'!$Y15,'ONS Nov25 T1'!$C:$C)/1000 -> 1466 | AA15: =SUMIF('ONS Nov25 T1'!$M:$M,'Chart Data'!$Y15,'ONS Nov25 T1'!$C:$C)/1000 -> 543 | AB15: =SUMIF('ONS Nov25 T1'!$N:$N,'Chart Data'!$Y15,'ONS Nov25 T1'!$C:$C)/1000 -> 924 | AC15: =Z15-AA15 -> 923 | AE15: 2032 | AF15: =AS15 -> 135 | AG15: =AU15 -> 300 | AH15: =AT15+AV15 -> 80.5 | AI15: =AW15 -> 63 | AJ15: =AQ15 -> 80 | AK15: =AP15+AX15+AY15+AZ15 -> 196.10438 | AL15: =AO15-SUM(AF15:AK15) -> 0 | AN15: 2032 | AO15: ='[2]Migration calculations'!L23 -> 854.60438 | AP15: =AO15-AQ15-AR15 -> 116.10438 | AQ15: ='[2]Migration calculations'!U23 -> 80 | AR15: =SUM(AS15:AZ15) -> 658.5 | AS15: ='[2]Migration calculations'!W23 -> 135 | AT15: ='[2]Migration calculations'!X23 -> 67.5 | AU15: ='[2]Migration calculations'!Y23 -> 300 | AV15: ='[2]Migration calculations'!Z23 -> 13 | AW15: ='[2]Migration calculations'!AA23 -> 63 | AX15: ='[2]Migration calculations'!AB23 -> 0 | AY15: ='[2]Migration calculations'!AC23 -> 60 | AZ15: ='[2]Migration calculations'!AD23 -> 20 | BV15: 2032 | BW15: =CJ15 -> 23.5 | BX15: =CL15 -> 120 | BY15: =CK15+CM15 -> 32.22 | BZ15: =CN15 -> 33 | CA15: =CH15 -> 250 | CB15: =CG15+CO15+CP15+CQ15 -> 123.90584 | CC15: =CF15-SUM(BW15:CB15) -> 0 | CE15: 2032 | CF15: ='[2]Migration calculations'!M23 -> 582.62584 | CG15: =CF15-CH15-CI15 -> 121.90584 | CH15: ='[2]Migration calculations'!AL23 -> 250 | CI15: =SUM(CJ15:CQ15) -> 210.72 | CJ15: ='[2]Migration calculations'!AN23 -> 23.5 | CK15: ='[2]Migration calculations'!AO23 -> 12.22 | CL15: ='[2]Migration calculations'!AP23 -> 120 | CM15: ='[2]Migration calculations'!AQ23 -> 20 | CN15: ='[2]Migration calculations'!AR23 -> 33 | CO15: ='[2]Migration calculations'!AS23 -> 0 | CP15: ='[2]Migration calculations'!AT23 -> 0 | CQ15: ='[2]Migration calculations'!AU23 -> 2 | DT15: 1985 | DU15: =100*((Data!M19/Data!M18)-1) -> 0.49341661 | DV15: =AVERAGE(DU6:DU15) -> 0.54780629 | DW15: 0 | DX15: 65 | DY15: 60 | EA15: 34304 | EB15: =100*(HAVERM!C54/HAVERM!B54) -> 22.434479 | EC15: =AVERAGE($EB$7:$EB$399) -> 25.050854 | EE15: =HAVERM!C54 -> 1926 | EF15: =HAVERM!B54-HAVERM!C54 -> 6659 | GW15: =GW14-GQ14 -> -0.18504975 | GZ15: 2026 | HA15: =100*(Data!B60/Data!$B$57) -> 103.37763 | HB15: =HB14*(1+HF15/100) -> 103.99456 | HD15: =100*((HB15/HA15)-1) -> 0.59677386 | HF15: =100*(('OBR Nov25 ST1.1'!R116/'OBR Nov25 ST1.1'!R115)-1) -> 1.3714665
A16: 1992 | B16: =Data!F26*Data!G26 -> 848974.43 | C16: =Data!H26/Data!I26 -> 9.4785328 | D16: =Data!E26 -> 1605639 | E16: =Data!J26 -> -1.685568 | F16: =Data!D26 -> 1538270 | G16: =Data!B26 -> 1498023 | I16: =100*((F16/F15)-1) -> 1.4011736 | J16: =100*((G16/G15)-1) -> 0.27578765 | L16: 2012 | M16: =AB4 -> 162 | R16: 2032 | S16: ='[2]2022-based'!Q39 -> 70835.233 | T16: 72521.173 | U16: 71617.737 | Y16: 2024 | Z16: =SUMIF('ONS Nov25 T1'!$L:$L,'Chart Data'!$Y16,'ONS Nov25 T1'!$C:$C)/1000 -> 1299 | AA16: =SUMIF('ONS Nov25 T1'!$M:$M,'Chart Data'!$Y16,'ONS Nov25 T1'!$C:$C)/1000 -> 650 | AB16: =SUMIF('ONS Nov25 T1'!$N:$N,'Chart Data'!$Y16,'ONS Nov25 T1'!$C:$C)/1000 -> 649 | AC16: =Z16-AA16 -> 649 | DT16: 1986 | DU16: =100*((Data!M20/Data!M19)-1) -> 0.41478282 | DV16: =AVERAGE(DU7:DU16) -> 0.57901966 | DW16: 0 | DX16: 65 | DY16: 60 | EA16: 34335 | EB16: =100*(HAVERM!C55/HAVERM!B55) -> 22.336089 | EC16: =AVERAGE($EB$7:$EB$399) -> 25.050854 | EE16: =HAVERM!C55 -> 1918 | EF16: =HAVERM!B55-HAVERM!C55 -> 6669 | FW16: 1963 | GW16: =100*((GW10/GQ10)-1) -> -1.0375615 | GZ16: 2027 | HA16: =100*(Data!B61/Data!$B$57) -> 104.75982 | HB16: =HB15*(1+HF16/100) -> 105.59882 | HD16: =100*((HB16/HA16)-1) -> 0.80088474 | HF16: =100*(('OBR Nov25 ST1.1'!R117/'OBR Nov25 ST1.1'!R116)-1) -> 1.5426381
