Workbook
Name _DLX1.INC: HAVERD!$4:$9
Name _DLX2.INC: HAVERM!$4:$9
Name Data: [1]sheet0!$C$2

Sheet DMP data
B1: Impact of increases in energy prices following the Iran conflict in 2026, % of respondents [ᴺᵒᵗᵉˢ 16]
B3: Sales volumes | F3: Employment | J3: Prices | N3: Wages | R3: Profit margins
A4: Survey date/reference period | B4: Lower | C4: No impact | D4: Higher | F4: Lower | G4: No impact | H4: Higher | J4: Lower | K4: No impact | L4: Higher | N4: Lower | O4: No impact | P4: Higher | R4: Lower | S4: No impact | T4: Higher
A5: Apr-26 | B5: 53.711 | C5: 39.693 | D5: 6.595 | F5: 29.672 | G5: 66.606 | H5: 3.722 | J5: 4.122 | K5: 31.505 | L5: 64.373 | N5: 15.699 | O5: 58.199 | P5: 26.102 | R5: 68.169 | S5: 25.85 | T5: 5.981
A6: 46143 | B6: 46.196 | C6: 48.752 | D6: 5.052 | F6: 29.377 | G6: 68.24 | H6: 2.384 | J6: 4.578 | K6: 38.536 | L6: 56.886 | N6: 18.652 | O6: 56.935 | P6: 24.413 | R6: 67.663 | S6: 25.7 | T6: 6.637
B10: =SUM(B6:D6) -> 100 | F10: =SUM(F6:H6) -> 100.001 | J10: =SUM(J6:L6) -> 100 | N10: =SUM(N6:P6) -> 100 | R10: =SUM(R6:T6) -> 100

Sheet HAVERD
A4: 20250101 !D | B4: IRACNTT@TRANSPRT | C4: IRACNTK@TRANSPRT
A5: .DESC | B5: Iran: Strait of Hormuz: Transit Calls: All Ships (Number) | C5: Iran: Strait of Hormuz: Transit Calls: Tankers (Number)
A6: .T1 | B6: 01-Jan-2019 | C6: 01-Jan-2019
A7: .TN | B7: 07-Jun-2026 | C7: 07-Jun-2026
A8: .LSOURCE | B8: International Monetary Fund | C8: International Monetary Fund
A9: .FRQ | B9: Daily (7) | C9: Daily (7)
A10: 20250101 | B10: 79 | C10: 46
A11: 20250102 | B11: 63 | C11: 35
A12: 20250103 | B12: 78 | C12: 44
A13: 20250104 | B13: 80 | C13: 42
A14: 20250105 | B14: 63 | C14: 41
A15: 20250106 | B15: 65 | C15: 32
A16: 20250107 | B16: 71 | C16: 40
A17: 20250108 | B17: 69 | C17: 30
A18: 20250109 | B18: 74 | C18: 41
A19: 20250110 | B19: 71 | C19: 40
A20: 20250111 | B20: 90 | C20: 57
A21: 20250112 | B21: 87 | C21: 53
... A532: 20260607 | B532: 2 | C532: 1

Sheet HAVERM
A4: 202301 !M | B4: UNVDCPI1@UK | C4: UNVDCPI3@UK
A5: .DESC | B5: UK: BoE Decision Maker Panel: Expected 1-Year Ahead CPI Inflation Rate (%) | C5: UK: BoE Decision Maker Panel: Expected 3-Year Ahead CPI Inflation Rate (%)
A6: .T1 | B6: May-2022 | C6: May-2022
A7: .TN | B7: May-2026 | C7: May-2026
A8: .LSOURCE | B8: Bank of England | C8: Bank of England
A9: .FRQ | B9: Monthly | C9: Monthly
A10: 202301 | B10: 6.395 | C10: 3.695
A11: 202302 | B11: 5.875 | C11: 3.407
A12: 202303 | B12: 5.84 | C12: 3.492
A13: 202304 | B13: 5.596 | C13: 3.376
A14: 202305 | B14: 5.906 | C14: 3.494
A15: 202306 | B15: 5.677 | C15: 3.662
A16: 202307 | B16: 5.383 | C16: 3.347
A17: 202308 | B17: 4.833 | C17: 3.158
A18: 202309 | B18: 4.85 | C18: 3.256
A19: 202310 | B19: 4.633 | C19: 3.081
A20: 202311 | B20: 4.386 | C20: 3.189
A21: 202312 | B21: 3.99 | C21: 2.894
... A50: 202605 | B50: 3.738 | C50: 2.875

Sheet Chart data
A1: Shipping Data >>>
A3: Date | B3: Total | C3: Tanker | F3: Date | G3: 1-year ahead | H3: 5-10 years ahead | K3: Date | L3: 1-year ahead | M3: 3 years ahead | Q3: Lower | R3: No impact | S3: Higher
A4: 46023 | B4: =HAVERD!B375 -> 68 | C4: =HAVERD!C375 -> 33 | F4: 44927 | G4: =[2]HAVERQ!L226 -> 5.4 | H4: =[2]HAVERQ!M226 -> 3.5 | K4: 44927 | L4: =HAVERM!B10 -> 6.395 | M4: =HAVERM!C10 -> 3.695 | P4: Employment | Q4: ='DMP data'!F6 -> 29.377 | R4: ='DMP data'!G6 -> 68.24 | S4: ='DMP data'!H6 -> 2.384
A5: 46024 | B5: =HAVERD!B376 -> 65 | C5: =HAVERD!C376 -> 33 | F5: 44958 | G5: =[2]HAVERQ!L227 -> 5.6 | H5: =[2]HAVERQ!M227 -> 3.8 | K5: 44958 | L5: =HAVERM!B11 -> 5.875 | M5: =HAVERM!C11 -> 3.407 | P5: Prices | Q5: ='DMP data'!J6 -> 4.578 | R5: ='DMP data'!K6 -> 38.536 | S5: ='DMP data'!L6 -> 56.886
A6: 46025 | B6: =HAVERD!B377 -> 69 | C6: =HAVERD!C377 -> 41 | F6: 44986 | G6: =[2]HAVERQ!L228 -> 5.4 | H6: =[2]HAVERQ!M228 -> 3.7 | K6: 44986 | L6: =HAVERM!B12 -> 5.84 | M6: =HAVERM!C12 -> 3.492 | P6: Wages | Q6: ='DMP data'!N6 -> 18.652 | R6: ='DMP data'!O6 -> 56.935 | S6: ='DMP data'!P6 -> 24.413
A7: 46026 | B7: =HAVERD!B378 -> 71 | C7: =HAVERD!C378 -> 35 | F7: 45017 | G7: =[2]HAVERQ!L229 -> 5.2 | H7: =[2]HAVERQ!M229 -> 3.6 | K7: 45017 | L7: =HAVERM!B13 -> 5.596 | M7: =HAVERM!C13 -> 3.376 | P7: Profit margins | Q7: ='DMP data'!R6 -> 67.663 | R7: ='DMP data'!S6 -> 25.7 | S7: ='DMP data'!T6 -> 6.637
A8: 46027 | B8: =HAVERD!B379 -> 64 | C8: =HAVERD!C379 -> 36 | F8: 45047 | G8: =[2]HAVERQ!L230 -> 4.7 | H8: =[2]HAVERQ!M230 -> 3.5 | K8: 45047 | L8: =HAVERM!B14 -> 5.906 | M8: =HAVERM!C14 -> 3.494
A9: 46028 | B9: =HAVERD!B380 -> 82 | C9: =HAVERD!C380 -> 40 | F9: 45078 | G9: =[2]HAVERQ!L231 -> 5 | H9: =[2]HAVERQ!M231 -> 3.3 | K9: 45078 | L9: =HAVERM!B15 -> 5.677 | M9: =HAVERM!C15 -> 3.662
A10: 46029 | B10: =HAVERD!B381 -> 84 | C10: =HAVERD!C381 -> 47 | F10: 45108 | G10: =[2]HAVERQ!L232 -> 4.3 | H10: =[2]HAVERQ!M232 -> 3.2 | K10: 45108 | L10: =HAVERM!B16 -> 5.383 | M10: =HAVERM!C16 -> 3.347
A11: =A4+7 -> 46030 | B11: =HAVERD!B382 -> 70 | C11: =HAVERD!C382 -> 40 | F11: 45139 | G11: =[2]HAVERQ!L233 -> 4.4 | H11: =[2]HAVERQ!M233 -> 3.3 | K11: 45139 | L11: =HAVERM!B17 -> 4.833 | M11: =HAVERM!C17 -> 3.158
A12: =A5+7 -> 46031 | B12: =HAVERD!B383 -> 90 | C12: =HAVERD!C383 -> 50 | F12: 45170 | G12: =[2]HAVERQ!L234 -> 4.2 | H12: =[2]HAVERQ!M234 -> 3.3 | K12: 45170 | L12: =HAVERM!B18 -> 4.85 | M12: =HAVERM!C18 -> 3.256
A13: =A6+7 -> 46032 | B13: =HAVERD!B384 -> 77 | C13: =HAVERD!C384 -> 41 | F13: 45200 | G13: =[2]HAVERQ!L235 -> 4.2 | H13: =[2]HAVERQ!M235 -> 3.5 | K13: 45200 | L13: =HAVERM!B19 -> 4.633 | M13: =HAVERM!C19 -> 3.081
A14: =A7+7 -> 46033 | B14: =HAVERD!B385 -> 77 | C14: =HAVERD!C385 -> 39 | F14: 45231 | G14: =[2]HAVERQ!L236 -> 3.9 | H14: =[2]HAVERQ!M236 -> 3.4 | K14: 45231 | L14: =HAVERM!B20 -> 4.386 | M14: =HAVERM!C20 -> 3.189
A15: =A8+7 -> 46034 | B15: =HAVERD!B386 -> 71 | C15: =HAVERD!C386 -> 44 | F15: 45261 | G15: =[2]HAVERQ!L237 -> 3.5 | H15: =[2]HAVERQ!M237 -> 3.4 | K15: 45261 | L15: =HAVERM!B21 -> 3.99 | M15: =HAVERM!C21 -> 2.894
A16: =A9+7 -> 46035 | B16: =HAVERD!B387 -> 63 | C16: =HAVERD!C387 -> 31 | F16: 45292 | G16: =[2]HAVERQ!L238 -> 3.9 | H16: =[2]HAVERQ!M238 -> 3.6 | K16: 45292 | L16: =HAVERM!B22 -> 3.434 | M16: =HAVERM!C22 -> 2.688
A17: =A10+7 -> 46036 | B17: =HAVERD!B388 -> 78 | C17: =HAVERD!C388 -> 42 | F17: 45323 | G17: =[2]HAVERQ!L239 -> 3.6 | H17: =[2]HAVERQ!M239 -> 3.5 | K17: 45323 | L17: =HAVERM!B23 -> 3.285 | M17: =HAVERM!C23 -> 2.708
A18: =A11+7 -> 46037 | B18: =HAVERD!B389 -> 73 | C18: =HAVERD!C389 -> 41 | F18: 45352 | G18: =[2]HAVERQ!L240 -> 3.3 | H18: =[2]HAVERQ!M240 -> 3.4 | K18: 45352 | L18: =HAVERM!B24 -> 3.146 | M18: =HAVERM!C24 -> 2.709
A19: =A12+7 -> 46038 | B19: =HAVERD!B390 -> 75 | C19: =HAVERD!C390 -> 40 | F19: 45383 | G19: =[2]HAVERQ!L241 -> 3.3 | H19: =[2]HAVERQ!M241 -> 3.5 | K19: 45383 | L19: =HAVERM!B25 -> 2.935 | M19: =HAVERM!C25 -> 2.611
A20: =A13+7 -> 46039 | B20: =HAVERD!B391 -> 55 | C20: =HAVERD!C391 -> 31 | F20: 45413 | G20: =[2]HAVERQ!L242 -> 3.1 | H20: =[2]HAVERQ!M242 -> 3.2 | K20: 45413 | L20: =HAVERM!B26 -> 2.877 | M20: =HAVERM!C26 -> 2.615
A21: =A14+7 -> 46040 | B21: =HAVERD!B392 -> 72 | C21: =HAVERD!C392 -> 29 | F21: 45444 | G21: =[2]HAVERQ!L243 -> 2.6 | H21: =[2]HAVERQ!M243 -> 3 | K21: 45444 | L21: =HAVERM!B27 -> 2.78 | M21: =HAVERM!C27 -> 2.713
A22: =A15+7 -> 46041 | B22: =HAVERD!B393 -> 78 | C22: =HAVERD!C393 -> 41 | F22: 45474 | G22: =[2]HAVERQ!L244 -> 2.7 | H22: =[2]HAVERQ!M244 -> 3.1 | K22: 45474 | L22: =HAVERM!B28 -> 2.545 | M22: =HAVERM!C28 -> 2.541
... A44: =A37+7 -> 46063 | B44: =HAVERD!B415 -> 95 | C44: =HAVERD!C415 -> 59 | F44: 46143 | G44: =[2]HAVERQ!L266 -> 4.7 | H44: =[2]HAVERQ!M266 -> 4 | K44: 46143 | L44: =HAVERM!B50 -> 3.738 | M44: =HAVERM!C50 -> 2.875
A45: =A38+7 -> 46064 | B45: =HAVERD!B416 -> 82 | C45: =HAVERD!C416 -> 46 | F45: 46174 | K45: 46174
A46: =A39+7 -> 46065 | B46: =HAVERD!B417 -> 119 | C46: =HAVERD!C417 -> 55
A47: =A40+7 -> 46066 | B47: =HAVERD!B418 -> 110 | C47: =HAVERD!C418 -> 64
A48: =A41+7 -> 46067 | B48: =HAVERD!B419 -> 99 | C48: =HAVERD!C419 -> 58
A49: =A42+7 -> 46068 | B49: =HAVERD!B420 -> 87 | C49: =HAVERD!C420 -> 50
A50: =A43+7 -> 46069 | B50: =HAVERD!B421 -> 95 | C50: =HAVERD!C421 -> 60
A51: =A44+7 -> 46070 | B51: =HAVERD!B422 -> 91 | C51: =HAVERD!C422 -> 43
A52: =A45+7 -> 46071 | B52: =HAVERD!B423 -> 113 | C52: =HAVERD!C423 -> 52
A53: =A46+7 -> 46072 | B53: =HAVERD!B424 -> 115 | C53: =HAVERD!C424 -> 62
A54: =A47+7 -> 46073 | B54: =HAVERD!B425 -> 90 | C54: =HAVERD!C425 -> 54
A55: =A48+7 -> 46074 | B55: =HAVERD!B426 -> 94 | C55: =HAVERD!C426 -> 54
A56: =A49+7 -> 46075 | B56: =HAVERD!B427 -> 129 | C56: =HAVERD!C427 -> 72
A57: =A50+7 -> 46076 | B57: =HAVERD!B428 -> 103 | C57: =HAVERD!C428 -> 62
... A161: =A154+7 -> 46180 | B161: =HAVERD!B532 -> 2 | C161: =HAVERD!C532 -> 1
A162: =A155+7 -> 46181
A163: =A156+7 -> 46182
A164: =A157+7 -> 46183
A165: =A158+7 -> 46184
...
