Workbook
Name _DLX1.INC: HAVERD!$A$1:$J$6
Name _DLX2.INC: HAVERQ!$1:$7

Sheet Data >>

Sheet HAVERD
A1: 20250501 !D | B1: R112LOS@INTDAILY | C1: M112MOT@INTDAILY | D1: M112MTH@INTDAILY | E1: M112MHF@INTDAILY | F1: M112MHV@INTDAILY
A2: .DESC | B2: UK:Lending Rate: Sterling Overnight Interbank Average [SONIA] (% pa) | C2: UK: Forward OIS: MPC Mtg Date # 1 vs MPC Mtg Date # 2: Mid Rate (% p.a.) | D2: UK: Forward OIS: MPC Mtg Date # 2 vs MPC Mtg Date # 3: Mid Rate (% p.a.) | E2: UK: Forward OIS: MPC Mtg Date # 3 vs MPC Mtg Date # 4: Mid Rate (% p.a.) | F2: UK: Forward OIS: MPC Mtg Date # 4 vs MPC Mtg Date # 5: Mid Rate (% p.a.)
A3: .T1 | B3: 02-Jan-1997 | C3: 16-May-2007 | D3: 16-May-2007 | E3: 16-May-2007 | F3: 16-May-2007
A4: .TN | B4: 05-Mar-2026 | C4: 06-Mar-2026 | D4: 06-Mar-2026 | E4: 06-Mar-2026 | F4: 06-Mar-2026
A5: .LSOURCE | B5: Bank of England | C5: Tullett Prebon Information/Haver Analytics | D5: Tullett Prebon Information/Haver Analytics | E5: Tullett Prebon Information/Haver Analytics | F5: Tullett Prebon Information/Haver Analytics
A6: .DTLM | B6: Mar-09-2026 09:30 | C6: Mar-06-2026 19:07 | D6: Mar-06-2026 19:07 | E6: Mar-06-2026 19:07 | F6: Mar-06-2026 19:07
A7: 20250501 | B7: 4.4586 | C7: 4.2 | D7: 4.062 | E7: 3.852 | F7: 3.715
A8: 20250502 | B8: 4.4594 | C8: 4.204 | D8: 4.075 | E8: 3.873 | F8: 3.735
A9: 20250505 | B9: #N/A | C9: 4.208 | D9: 4.078 | E9: 3.875 | F9: 3.74
A10: 20250506 | B10: 4.459 | C10: 4.2 | D10: 4.068 | E10: 3.866 | F10: 3.725
A11: 20250507 | B11: 4.4601 | C11: 4.204 | D11: 4.073 | E11: 3.872 | F11: 3.726
A12: 20250508 | B12: 4.21 | C12: 4.219 | D12: 4.172 | E12: 3.987 | F12: 3.876
A13: 20250509 | B13: 4.2103 | C13: 4.166 | D13: 3.976 | E13: 3.873 | F13: 3.712
A14: 20250512 | B14: 4.21 | C14: 4.19 | D14: 4.01 | E14: 3.934 | F14: 3.792
A15: 20250513 | B15: 4.2106 | C15: 4.195 | D15: 4.018 | E15: 3.946 | F15: 3.798
A16: 20250514 | B16: 4.2108 | C16: 4.199 | D16: 4.041 | E16: 3.984 | F16: 3.853
A17: 20250515 | B17: 4.2111 | C17: 4.199 | D17: 4.038 | E17: 3.971 | F17: 3.833
A18: 20250516 | B18: 4.2106 | C18: 4.202 | D18: 4.049 | E18: 3.98 | F18: 3.846
A19: 20250519 | B19: 4.2109 | C19: 4.199 | D19: 4.041 | E19: 3.981 | F19: 3.853
A20: 20250520 | B20: 4.2108 | C20: 4.203 | D20: 4.056 | E20: 3.996 | F20: 3.872
A21: 20250521 | B21: 4.2115 | C21: 4.213 | D21: 4.095 | E21: 4.035 | F21: 3.908
... A23: 20250523 | B23: 4.2108 | C23: 4.215 | D23: 4.088 | E23: 4.028 | F23: 3.884
A24: 20250526 | B24: #N/A | C24: 4.218 | D24: 4.093 | E24: 4.033 | F24: 3.884
A25: 20250527 | B25: 4.2107 | C25: 4.218 | D25: 4.102 | E25: 4.052 | F25: 3.912
A26: 20250528 | B26: 4.2104 | C26: 4.219 | D26: 4.104 | E26: 4.061 | F26: 3.924
A27: 20250529 | B27: 4.2107 | C27: 4.217 | D27: 4.101 | E27: 4.056 | F27: 3.907
A28: 20250530 | B28: 4.2111 | C28: 4.21 | D28: 4.098 | E28: 4.053 | F28: 3.909
A29: 20250602 | B29: 4.2112 | C29: 4.216 | D29: 4.1 | E29: 4.056 | F29: 3.916
A30: 20250603 | B30: 4.2112 | C30: 4.217 | D30: 4.074 | E30: 4.028 | F30: 3.889
A31: 20250604 | B31: 4.2111 | C31: 4.213 | D31: 4.065 | E31: 4.016 | F31: 3.869
A32: 20250605 | B32: 4.2119 | C32: 4.217 | D32: 4.063 | E32: 4.019 | F32: 3.877
A33: 20250606 | B33: 4.2118 | C33: 4.216 | D33: 4.062 | E33: 4.025 | F33: 3.891
A34: 20250609 | B34: 4.2128 | C34: 4.214 | D34: 4.054 | E34: 4.01 | F34: 3.867
A35: 20250610 | B35: 4.2126 | C35: 4.207 | D35: 4.017 | E35: 3.957 | F35: 3.802
A36: 20250611 | B36: 4.2129 | C36: 4.208 | D36: 4.018 | E36: 3.956 | F36: 3.801
... A88: 20250822 | B88: 3.9671 | C88: 3.973 | D88: 3.914 | E88: 3.866 | F88: 3.769
A89: 20250825 | B89: #N/A | C89: 3.975 | D89: 3.914 | E89: 3.863 | F89: 3.764
A90: 20250826 | B90: 3.9674 | C90: 3.975 | D90: 3.918 | E90: 3.87 | F90: 3.775
A91: 20250827 | B91: 3.9675 | C91: 3.977 | D91: 3.924 | E91: 3.879 | F91: 3.784
A92: 20250828 | B92: 3.9675 | C92: 3.974 | D92: 3.924 | E92: 3.872 | F92: 3.773
...

Sheet HAVERQ
A1: 20001 !Q | B1: UNQMPCPI@UK
A2: .DESC | B2: UK: BoE MPR Bank Staff Projections: CPI (Y/Y % Change)
A3: .T1 | B3: Q1-2004
A4: .TN | B4: Q1-2029
A5: .LSOURCE | B5: Bank of England
A6: .DTLM | B6: Feb-05-2026 12:04
A7: .FRQ | B7: Quarterly
A8: 20001 | B8: #N/A
A9: 20002 | B9: #N/A
A10: 20003 | B10: #N/A
A11: 20004 | B11: #N/A
A12: 20011 | B12: #N/A
A13: 20012 | B13: #N/A
A14: 20013 | B14: #N/A
A15: 20014 | B15: #N/A
A16: 20021 | B16: #N/A
A17: 20022 | B17: #N/A
A18: 20023 | B18: #N/A
A19: 20024 | B19: #N/A
... A23: 20034 | B23: #N/A
A24: 20041 | B24: 1.3
A25: 20042 | B25: 1.4
A26: 20043 | B26: 1.3
A27: 20044 | B27: 1.4
A28: 20051 | B28: 1.7
A29: 20052 | B29: 2
A30: 20053 | B30: 2.4
A31: 20054 | B31: 2.1
A32: 20061 | B32: 1.9
A33: 20062 | B33: 2.3
A34: 20063 | B34: 2.4
A35: 20064 | B35: 2.7
... A124: 20291 | B124: 2

Sheet Chart Data
A1: Implied probability of rate cut by meeting | F1: Change compared with today | J1: CPI inflation forecast (new vs pre-conflict baseline) | R1: Oil | T1: Gas
B2: March | C2: April | D2: 0.5 | F2: March | G2: April | K2: OE pre-conflict baseline | L2: OE March baseline | M2: 2% line | N2: BoE February forecast* | R2: Febuary 2026 MPR | S2: March 10 | T2: Febuary 2026 MPR | U2: March 10 | Y2: 12-months ahead | Z2: 5-10 years ahead | AA2: 12-month ahead avg | AB2: 5-10 years ahead avg
A3: 46006 | D3: 0.5 | J3: 45292 | K3: ='[1]CPI Forecast'!D601 -> 3.5377562 | L3: ='[2]CPI Forecast'!D601 -> 3.5377562 | M3: 2 | N3: =K3 -> 3.5377562 | Q3: 46023 | R3: 64.416 | S3: 87.8 | T3: 81.227111 | U3: 120.63 | X3: 42736 | Y3: 2.6 | Z3: 3 | AA3: 2.4608333 | AB3: 3.1545833
A4: 46007 | D4: 0.5 | J4: 45383 | K4: ='[1]CPI Forecast'!D602 -> 2.0988785 | L4: ='[2]CPI Forecast'!D602 -> 2.0988785 | M4: 2 | N4: =K4 -> 2.0988785 | Q4: 46113 | R4: 63.322667 | S4: 82.6 | T4: 68.946444 | U4: 114.47333 | X4: 42767 | Y4: 2.6 | Z4: 3.2 | AA4: 2.4608333 | AB4: 3.1545833
A5: 46008 | D5: 0.5 | J5: 45474 | K5: ='[1]CPI Forecast'!D603 -> 2.0428766 | L5: ='[2]CPI Forecast'!D603 -> 2.0428766 | M5: 2 | N5: =K5 -> 2.0428766 | Q5: 46204 | R5: 62.746 | S5: 76.91 | T5: 68.603333 | U5: 109.87 | X5: 42795 | Y5: 2.5 | Z5: 3 | AA5: 2.4608333 | AB5: 3.1545833
A6: 46009 | B6: =IF(F6<0,-F6/0.25,F6/0.25) -> 0.4336 | C6: =IF(G6<0,-G6/0.25,G6/0.25) -> 0.8936 | D6: 0.5 | F6: =HAVERD!E172-HAVERD!$B172 -> -0.1084 | G6: =HAVERD!F172-HAVERD!$B172 -> -0.2234 | J6: 45566 | K6: ='[1]CPI Forecast'!D604 -> 2.4685995 | L6: ='[2]CPI Forecast'!D604 -> 2.4685995 | M6: 2 | N6: =K6 -> 2.4685995 | Q6: 46296 | R6: 62.535667 | S6: 74.48 | T6: 73.668222 | U6: 111.99333 | X6: 42826 | Y6: 2.5 | Z6: 2.9 | AA6: 2.4608333 | AB6: 3.1545833
A7: 46010 | B7: =IF(F7<0,-F7/0.25,F7/0.25) -> 0.3824 | C7: =IF(G7<0,-G7/0.25,G7/0.25) -> 0.8144 | D7: 0.5 | F7: =HAVERD!D173-HAVERD!$B173 -> -0.0956 | G7: =HAVERD!E173-HAVERD!$B173 -> -0.2036 | J7: 45658 | K7: ='[1]CPI Forecast'!D605 -> 2.8036677 | L7: ='[2]CPI Forecast'!D605 -> 2.8036677 | M7: 2 | N7: =K7 -> 2.8036677 | Q7: 46388 | R7: 62.325333 | S7: 72.05 | T7: 70.086667 | U7: 101.41333 | X7: 42856 | Y7: 2.6 | Z7: 3 | AA7: 2.4608333 | AB7: 3.1545833
A8: 46013 | B8: =IF(F8<0,-F8/0.25,F8/0.25) -> 0.3884 | C8: =IF(G8<0,-G8/0.25,G8/0.25) -> 0.8244 | D8: 0.5 | F8: =HAVERD!D174-HAVERD!$B174 -> -0.0971 | G8: =HAVERD!E174-HAVERD!$B174 -> -0.2061 | J8: 45748 | K8: ='[1]CPI Forecast'!D606 -> 3.4872454 | L8: ='[2]CPI Forecast'!D606 -> 3.4872454 | M8: 2 | N8: =K8 -> 3.4872454 | Q8: 46478 | R8: 62.539333 | S8: 71.5525 | T8: 58.123778 | U8: 78.543333 | X8: 42887 | Y8: 2.6 | Z8: 3.1 | AA8: 2.4608333 | AB8: 3.1545833
A9: 46014 | B9: =IF(F9<0,-F9/0.25,F9/0.25) -> 0.3832 | C9: =IF(G9<0,-G9/0.25,G9/0.25) -> 0.8112 | D9: 0.5 | F9: =HAVERD!D175-HAVERD!$B175 -> -0.0958 | G9: =HAVERD!E175-HAVERD!$B175 -> -0.2028 | J9: 45839 | K9: ='[1]CPI Forecast'!D607 -> 3.8001303 | L9: ='[2]CPI Forecast'!D607 -> 3.8001303 | M9: 2 | N9: =K9 -> 3.8001303 | Q9: 46569 | R9: 62.753333 | S9: 71.055 | T9: 59.818222 | U9: 77.56 | X9: 42917 | Y9: 2.5 | Z9: 3.1 | AA9: 2.4608333 | AB9: 3.1545833
A10: 46015 | B10: =IF(F10<0,-F10/0.25,F10/0.25) -> 0.384 | C10: =IF(G10<0,-G10/0.25,G10/0.25) -> 0.828 | D10: 0.5 | F10: =HAVERD!D176-HAVERD!$B176 -> -0.096 | G10: =HAVERD!E176-HAVERD!$B176 -> -0.207 | J10: 45931 | K10: ='[1]CPI Forecast'!D608 -> 3.3933356 | L10: ='[2]CPI Forecast'!D608 -> 3.3933356 | M10: 2 | N10: =K10 -> 3.3933356 | Q10: 46661 | R10: 62.967333 | S10: 70.5575 | T10: 67.562222 | U10: 81.596667 | X10: 42948 | Y10: 2.6 | Z10: 3.2 | AA10: 2.4608333 | AB10: 3.1545833
A11: =A6+7 -> 46016 | B11: =IF(F11<0,-F11/0.25,F11/0.25) -> #N/A | C11: =IF(G11<0,-G11/0.25,G11/0.25) -> #N/A | D11: 0.5 | F11: =HAVERD!D177-HAVERD!$B177 -> #N/A | G11: =HAVERD!E177-HAVERD!$B177 -> #N/A | J11: 46023 | K11: ='[1]CPI Forecast'!D609 -> 2.8855186 | L11: ='[2]CPI Forecast'!D609 -> 2.894677 | M11: 2 | N11: =HAVERQ!B112 -> 3 | Q11: 46753 | R11: 63.181333 | S11: 70.06 | T11: 65.158889 | U11: 75.043333 | X11: 42979 | Y11: 2.5 | Z11: 3.1 | AA11: 2.4608333 | AB11: 3.1545833
A12: =A7+7 -> 46017 | B12: =IF(F12<0,-F12/0.25,F12/0.25) -> #N/A | C12: =IF(G12<0,-G12/0.25,G12/0.25) -> #N/A | D12: 0.5 | F12: =HAVERD!D178-HAVERD!$B178 -> #N/A | G12: =HAVERD!E178-HAVERD!$B178 -> #N/A | J12: 46113 | K12: ='[1]CPI Forecast'!D610 -> 2.0807736 | L12: ='[2]CPI Forecast'!D610 -> 2.4987706 | M12: 2 | N12: =HAVERQ!B113 -> 2.1 | T12: 54.168889 | U12: 57.193333 | X12: 43009 | Y12: 2.8 | Z12: 3.2 | AA12: 2.4608333 | AB12: 3.1545833
A13: =+A8+7 -> 46020 | B13: =IF(F13<0,-F13/0.25,F13/0.25) -> 0.4004 | C13: =IF(G13<0,-G13/0.25,G13/0.25) -> 0.8564 | D13: 0.5 | F13: =HAVERD!D179-HAVERD!$B179 -> -0.1001 | G13: =HAVERD!E179-HAVERD!$B179 -> -0.2141 | J13: 46204 | K13: ='[1]CPI Forecast'!D611 -> 2.1144006 | L13: ='[2]CPI Forecast'!D611 -> 2.8524327 | M13: 2 | N13: =HAVERQ!B114 -> 2 | T13: 56.538667 | U13: 57.72 | X13: 43040 | Y13: 2.6 | Z13: 3.2 | AA13: 2.4608333 | AB13: 3.1545833
A14: =+A9+7 -> 46021 | B14: =IF(F14<0,-F14/0.25,F14/0.25) -> 0.4136 | C14: =IF(G14<0,-G14/0.25,G14/0.25) -> 0.8656 | D14: 0.5 | F14: =HAVERD!D180-HAVERD!$B180 -> -0.1034 | G14: =HAVERD!E180-HAVERD!$B180 -> -0.2164 | J14: 46296 | K14: ='[1]CPI Forecast'!D612 -> 2.1117126 | L14: ='[2]CPI Forecast'!D612 -> 2.6221745 | M14: 2 | N14: =HAVERQ!B115 -> 2 | T14: 64.667111 | U14: 65.083333 | X14: 43070 | Y14: 2.7 | Z14: 3.3 | AA14: 2.4608333 | AB14: 3.1545833
A15: =+A10+7 -> 46022 | B15: =IF(F15<0,-F15/0.25,F15/0.25) -> 0.4188 | C15: =IF(G15<0,-G15/0.25,G15/0.25) -> 0.8748 | D15: 0.5 | F15: =HAVERD!D181-HAVERD!$B181 -> -0.1047 | G15: =HAVERD!E181-HAVERD!$B181 -> -0.2187 | J15: 46388 | K15: ='[1]CPI Forecast'!D613 -> 2.1963121 | L15: ='[2]CPI Forecast'!D613 -> 2.5834042 | M15: 2 | N15: =HAVERQ!B116 -> 1.7 | T15: 63.040667 | U15: 63.513333 | X15: 43101 | Y15: 2.5 | Z15: 3.1 | AA15: 2.4608333 | AB15: 3.1545833
A16: =+A11+7 -> 46023 | B16: =IF(F16<0,-F16/0.25,F16/0.25) -> #N/A | C16: =IF(G16<0,-G16/0.25,G16/0.25) -> #N/A | D16: 0.5 | F16: =HAVERD!D182-HAVERD!$B182 -> #N/A | G16: =HAVERD!E182-HAVERD!$B182 -> #N/A | J16: 46478 | K16: ='[1]CPI Forecast'!D614 -> 2.2973714 | L16: ='[2]CPI Forecast'!D614 -> 2.1828434 | M16: 2 | N16: =HAVERQ!B117 -> 2 | T16: 54.024222 | U16: 53.9 | X16: 43132 | Y16: 2.4 | Z16: 3.1 | AA16: 2.4608333 | AB16: 3.1545833
A17: =+A12+7 -> 46024 | B17: =IF(F17<0,-F17/0.25,F17/0.25) -> 0.4092 | C17: =IF(G17<0,-G17/0.25,G17/0.25) -> 0.8492 | D17: 0.5 | F17: =HAVERD!D183-HAVERD!$B183 -> -0.1023 | G17: =HAVERD!E183-HAVERD!$B183 -> -0.2123 | J17: 46569 | K17: ='[1]CPI Forecast'!D615 -> 2.2781117 | L17: ='[2]CPI Forecast'!D615 -> 1.8117809 | M17: 2 | N17: =HAVERQ!B118 -> 1.9 | T17: 55.600444 | U17: 55.17 | X17: 43160 | Y17: 2.4 | Z17: 3 | AA17: 2.4608333 | AB17: 3.1545833
A18: =+A13+7 -> 46027 | B18: =IF(F18<0,-F18/0.25,F18/0.25) -> 0.4244 | C18: =IF(G18<0,-G18/0.25,G18/0.25) -> 0.8724 | D18: 0.5 | F18: =HAVERD!D184-HAVERD!$B184 -> -0.1061 | G18: =HAVERD!E184-HAVERD!$B184 -> -0.2181 | J18: 46661 | K18: ='[1]CPI Forecast'!D616 -> 2.2931389 | L18: ='[2]CPI Forecast'!D616 -> 2.0345023 | M18: 2 | N18: =HAVERQ!B119 -> 1.8 | T18: 63.876 | U18: 64.573333 | X18: 43191 | Y18: 2.4 | Z18: 3.1 | AA18: 2.4608333 | AB18: 3.1545833
A19: =+A14+7 -> 46028 | B19: =IF(F19<0,-F19/0.25,F19/0.25) -> 0.41 | C19: =IF(G19<0,-G19/0.25,G19/0.25) -> 0.838 | D19: 0.5 | F19: =HAVERD!D185-HAVERD!$B185 -> -0.1025 | G19: =HAVERD!E185-HAVERD!$B185 -> -0.2095 | X19: 43221 | Y19: 2.5 | Z19: 3.2 | AA19: 2.4608333 | AB19: 3.1545833
A20: =+A15+7 -> 46029 | B20: =IF(F20<0,-F20/0.25,F20/0.25) -> 0.4312 | C20: =IF(G20<0,-G20/0.25,G20/0.25) -> 0.8672 | D20: 0.5 | F20: =HAVERD!D186-HAVERD!$B186 -> -0.1078 | G20: =HAVERD!E186-HAVERD!$B186 -> -0.2168 | X20: 43252 | Y20: 2.6 | Z20: 3.35 | AA20: 2.4608333 | AB20: 3.1545833
A21: =+A16+7 -> 46030 | B21: =IF(F21<0,-F21/0.25,F21/0.25) -> 0.4156 | C21: =IF(G21<0,-G21/0.25,G21/0.25) -> 0.8836 | D21: 0.5 | F21: =HAVERD!D187-HAVERD!$B187 -> -0.1039 | G21: =HAVERD!E187-HAVERD!$B187 -> -0.2209 | X21: 43282 | Y21: 2.5 | Z21: 3.3 | AA21: 2.4608333 | AB21: 3.1545833
A22: =+A17+7 -> 46031 | B22: =IF(F22<0,-F22/0.25,F22/0.25) -> 0.4264 | C22: =IF(G22<0,-G22/0.25,G22/0.25) -> 0.9104 | D22: 0.5 | F22: =HAVERD!D188-HAVERD!$B188 -> -0.1066 | G22: =HAVERD!E188-HAVERD!$B188 -> -0.2276 | X22: 43313 | Y22: 2.7 | Z22: 3.3 | AA22: 2.4608333 | AB22: 3.1545833
A23: =+A18+7 -> 46034 | B23: =IF(F23<0,-F23/0.25,F23/0.25) -> 0.3944 | C23: =IF(G23<0,-G23/0.25,G23/0.25) -> 0.8664 | D23: 0.5 | F23: =HAVERD!D189-HAVERD!$B189 -> -0.0986 | G23: =HAVERD!E189-HAVERD!$B189 -> -0.2166 | X23: 43344 | Y23: 2.9 | Z23: 3.4 | AA23: 2.4608333 | AB23: 3.1545833
A24: =+A19+7 -> 46035 | B24: =IF(F24<0,-F24/0.25,F24/0.25) -> 0.384 | C24: =IF(G24<0,-G24/0.25,G24/0.25) -> 0.856 | D24: 0.5 | F24: =HAVERD!D190-HAVERD!$B190 -> -0.096 | G24: =HAVERD!E190-HAVERD!$B190 -> -0.214 | X24: 43374 | Y24: 2.6 | Z24: 3.2 | AA24: 2.4608333 | AB24: 3.1545833
A25: =+A20+7 -> 46036 | B25: =IF(F25<0,-F25/0.25,F25/0.25) -> 0.3992 | C25: =IF(G25<0,-G25/0.25,G25/0.25) -> 0.9112 | D25: 0.5 | F25: =HAVERD!D191-HAVERD!$B191 -> -0.0998 | G25: =HAVERD!E191-HAVERD!$B191 -> -0.2278 | X25: 43405 | Y25: 2.7 | Z25: 3.1 | AA25: 2.4608333 | AB25: 3.1545833
A26: =+A21+7 -> 46037 | B26: =IF(F26<0,-F26/0.25,F26/0.25) -> 0.3196 | C26: =IF(G26<0,-G26/0.25,G26/0.25) -> 0.8156 | D26: 0.5 | F26: =HAVERD!D192-HAVERD!$B192 -> -0.0799 | G26: =HAVERD!E192-HAVERD!$B192 -> -0.2039 | X26: 43435 | Y26: 2.9 | Z26: 3.3 | AA26: 2.4608333 | AB26: 3.1545833
A27: =+A22+7 -> 46038 | B27: =IF(F27<0,-F27/0.25,F27/0.25) -> 0.2892 | C27: =IF(G27<0,-G27/0.25,G27/0.25) -> 0.7772 | D27: 0.5 | F27: =HAVERD!D193-HAVERD!$B193 -> -0.0723 | G27: =HAVERD!E193-HAVERD!$B193 -> -0.1943 | X27: 43466 | Y27: 2.6 | Z27: 3 | AA27: 2.4608333 | AB27: 3.1545833
A28: =+A23+7 -> 46041 | B28: =IF(F28<0,-F28/0.25,F28/0.25) -> 0.3216 | C28: =IF(G28<0,-G28/0.25,G28/0.25) -> 0.8056 | D28: 0.5 | F28: =HAVERD!D194-HAVERD!$B194 -> -0.0804 | G28: =HAVERD!E194-HAVERD!$B194 -> -0.2014 | X28: 43497 | Y28: 2.9 | Z28: 3.2 | AA28: 2.4608333 | AB28: 3.1545833
A29: =+A24+7 -> 46042 | B29: =IF(F29<0,-F29/0.25,F29/0.25) -> 0.2924 | C29: =IF(G29<0,-G29/0.25,G29/0.25) -> 0.8084 | D29: 0.5 | F29: =HAVERD!D195-HAVERD!$B195 -> -0.0731 | G29: =HAVERD!E195-HAVERD!$B195 -> -0.2021 | X29: 43525 | Y29: 2.7 | Z29: 3 | AA29: 2.4608333 | AB29: 3.1545833
A30: =+A25+7 -> 46043 | B30: =IF(F30<0,-F30/0.25,F30/0.25) -> 0.2904 | C30: =IF(G30<0,-G30/0.25,G30/0.25) -> 0.8464 | D30: 0.5 | F30: =HAVERD!D196-HAVERD!$B196 -> -0.0726 | G30: =HAVERD!E196-HAVERD!$B196 -> -0.2116 | X30: 43556 | Y30: 2.7 | Z30: 3.2 | AA30: 2.4608333 | AB30: 3.1545833
... A41: =+A36+7 -> 46058 | B41: =IF(F41<0,-F41/0.25,F41/0.25) -> 0.5952 | C41: =IF(G41<0,-G41/0.25,G41/0.25) -> 0.8952 | D41: 0.5 | F41: =HAVERD!D207-HAVERD!$B207 -> -0.1488 | G41: =HAVERD!E207-HAVERD!$B207 -> -0.2238 | X41: 43891 | Y41: 3.2 | Z41: 3.1 | AA41: 2.4608333 | AB41: 3.1545833
A42: =+A37+7 -> 46059 | B42: =IF(F42<0,-F42/0.25,F42/0.25) -> 0.6836 | C42: =IF(G42<0,-G42/0.25,G42/0.25) -> 0.9396 | D42: 0.5 | F42: =HAVERD!C208-HAVERD!$B208 -> -0.1709 | G42: =HAVERD!D208-HAVERD!$B208 -> -0.2349 | X42: 43922 | Y42: 3.2 | Z42: 2.9 | AA42: 2.4608333 | AB42: 3.1545833
A43: =+A38+7 -> 46062 | B43: =IF(F43<0,-F43/0.25,F43/0.25) -> 0.6764 | C43: =IF(G43<0,-G43/0.25,G43/0.25) -> 0.9124 | D43: 0.5 | F43: =HAVERD!C209-HAVERD!$B209 -> -0.1691 | G43: =HAVERD!D209-HAVERD!$B209 -> -0.2281 | X43: 43952 | Y43: 3.1 | Z43: 3 | AA43: 2.4608333 | AB43: 3.1545833
A44: =+A39+7 -> 46063 | B44: =IF(F44<0,-F44/0.25,F44/0.25) -> 0.676 | C44: =IF(G44<0,-G44/0.25,G44/0.25) -> 0.904 | D44: 0.5 | F44: =HAVERD!C210-HAVERD!$B210 -> -0.169 | G44: =HAVERD!D210-HAVERD!$B210 -> -0.226 | X44: 43983 | Y44: 3 | Z44: 3.2 | AA44: 2.4608333 | AB44: 3.1545833
A45: =+A40+7 -> 46064 | B45: =IF(F45<0,-F45/0.25,F45/0.25) -> 0.6816 | C45: =IF(G45<0,-G45/0.25,G45/0.25) -> 0.9136 | D45: 0.5 | F45: =HAVERD!C211-HAVERD!$B211 -> -0.1704 | G45: =HAVERD!D211-HAVERD!$B211 -> -0.2284 | X45: 44013 | Y45: 3.2 | Z45: 3.3 | AA45: 2.4608333 | AB45: 3.1545833
A46: =+A41+7 -> 46065 | B46: =IF(F46<0,-F46/0.25,F46/0.25) -> 0.7048 | C46: =IF(G46<0,-G46/0.25,G46/0.25) -> 0.9128 | D46: 0.5 | F46: =HAVERD!C212-HAVERD!$B212 -> -0.1762 | G46: =HAVERD!D212-HAVERD!$B212 -> -0.2282 | X46: 44044 | Y46: 3 | Z46: 3.2 | AA46: 2.4608333 | AB46: 3.1545833
A47: =+A42+7 -> 46066 | B47: =IF(F47<0,-F47/0.25,F47/0.25) -> 0.7028 | C47: =IF(G47<0,-G47/0.25,G47/0.25) -> 0.9548 | D47: 0.5 | F47: =HAVERD!C213-HAVERD!$B213 -> -0.1757 | G47: =HAVERD!D213-HAVERD!$B213 -> -0.2387 | X47: 44075 | Y47: 3.2 | Z47: 3.6 | AA47: 2.4608333 | AB47: 3.1545833
A48: =+A43+7 -> 46069 | B48: =IF(F48<0,-F48/0.25,F48/0.25) -> 0.7104 | C48: =IF(G48<0,-G48/0.25,G48/0.25) -> 0.9504 | D48: 0.5 | F48: =HAVERD!C214-HAVERD!$B214 -> -0.1776 | G48: =HAVERD!D214-HAVERD!$B214 -> -0.2376 | X48: 44105 | Y48: 3.2 | Z48: 3.5 | AA48: 2.4608333 | AB48: 3.1545833
A49: =+A44+7 -> 46070 | B49: =IF(F49<0,-F49/0.25,F49/0.25) -> 0.7664 | C49: =IF(G49<0,-G49/0.25,G49/0.25) -> 0.9384 | D49: 0.5 | F49: =HAVERD!C215-HAVERD!$B215 -> -0.1916 | G49: =HAVERD!D215-HAVERD!$B215 -> -0.2346 | X49: 44136 | Y49: 3.3 | Z49: 3.4 | AA49: 2.4608333 | AB49: 3.1545833
A50: =+A45+7 -> 46071 | B50: =IF(F50<0,-F50/0.25,F50/0.25) -> 0.7948 | C50: =IF(G50<0,-G50/0.25,G50/0.25) -> 0.9548 | D50: 0.5 | F50: =HAVERD!C216-HAVERD!$B216 -> -0.1987 | G50: =HAVERD!D216-HAVERD!$B216 -> -0.2387 | X50: 44166 | Y50: 3.8 | Z50: 3.4 | AA50: 2.4608333 | AB50: 3.1545833
...

Sheet Charts >>

Sheet Other charts >>
