Workbook
Name _DLX1.INC: HAVERA!$A$1:$D$4
Name Data: [1]sheet0!$C$2

Sheet Charts >>

Sheet Data >>

Sheet Chart data
A1: Share of household spending by income | M1: Actions taken by households | S1: Household deposits | X1: Distributional inflation
Y2: 0-10 | Z2: 11-20 | AA2: 21-30 | AB2: 31-40 | AC2: 41-50 | AD2: 51-60 | AE2: 61-70 | AF2: 71-80 | AG2: 81-90 | AH2: 91-100 | AI2: CPI
X3: 2010 | Y3: ='CPI by declile'!Q113 -> 2.9813552 | Z3: ='CPI by declile'!R113 -> 3.0382523 | AA3: ='CPI by declile'!S113 -> 3.0878782 | AB3: ='CPI by declile'!T113 -> 3.2147626 | AC3: ='CPI by declile'!U113 -> 3.3017874 | AD3: ='CPI by declile'!V113 -> 3.3501306 | AE3: ='CPI by declile'!W113 -> 3.3844234 | AF3: ='CPI by declile'!X113 -> 3.4118183 | ... AI3: ='CPI by declile'!AA113 -> 3.3015651
A4: Income deciles | B4: Food and non-alcoholic beverages | C4: Energy | D4: Motor fuel | H4: Food and non-alcoholic beverages | I4: Energy | J4: Motor fuel | N4: Buying the same or more | O4: Cutting back on some things | P4: Cutting back completely | T4: March 2022 survey | U4: March 2026 survey | X4: 2011 | Y4: ='CPI by declile'!Q114 -> 4.5767999 | Z4: ='CPI by declile'!R114 -> 4.6167534 | AA4: ='CPI by declile'!S114 -> 4.526999 | AB4: ='CPI by declile'!T114 -> 4.5833306 | AC4: ='CPI by declile'!U114 -> 4.5721223 | AD4: ='CPI by declile'!V114 -> 4.5216134 | AE4: ='CPI by declile'!W114 -> 4.5188635 | AF4: ='CPI by declile'!X114 -> 4.4954366 | ... AI4: ='CPI by declile'!AA114 -> 4.4632913
A5: 1 | B5: ='Apr26 MPR A.1'!B6 -> 14.6 | G5: 1 | H5: ='Apr26 MPR A.1'!B6 -> 14.6 | I5: ='Apr26 MPR A.1'!C6 -> 7.1 | J5: ='Apr26 MPR A.1'!D6 -> 2.4 | M5: 1 | N5: ='Apr26 MPR E.1'!B7 -> 26.99 | O5: ='Apr26 MPR E.1'!C7 -> 26.28 | P5: ='Apr26 MPR E.1'!D7 -> 46.73 | S5: Lowest quintile | T5: ='Apr26 MPR E.1'!G7 -> 43.548 | U5: ='Apr26 MPR E.1'!H7 -> 25.191 | X5: 2012 | Y5: ='CPI by declile'!Q115 -> 3.038899 | Z5: ='CPI by declile'!R115 -> 3.0740112 | AA5: ='CPI by declile'!S115 -> 2.9550293 | AB5: ='CPI by declile'!T115 -> 2.8965588 | AC5: ='CPI by declile'!U115 -> 2.8655041 | AD5: ='CPI by declile'!V115 -> 2.816043 | AE5: ='CPI by declile'!W115 -> 2.7913757 | AF5: ='CPI by declile'!X115 -> 2.7676168 | ... AI5: ='CPI by declile'!AA115 -> 2.8008242
B6: ='Apr26 MPR A.1'!B7 -> 15.4 | G6: 2 | H6: ='Apr26 MPR A.1'!B7 -> 15.4 | I6: ='Apr26 MPR A.1'!C7 -> 7.1 | J6: ='Apr26 MPR A.1'!D7 -> 2.7 | M6: 2 | N6: ='Apr26 MPR E.1'!B8 -> 36.19 | O6: ='Apr26 MPR E.1'!C8 -> 27.53 | P6: ='Apr26 MPR E.1'!D8 -> 36.29 | S6: Highest quintile | T6: ='Apr26 MPR E.1'!G8 -> 54.042 | U6: ='Apr26 MPR E.1'!H8 -> 17.142 | X6: 2013 | Y6: ='CPI by declile'!Q116 -> 2.9739702 | Z6: ='CPI by declile'!R116 -> 2.9389112 | AA6: ='CPI by declile'!S116 -> 2.7226476 | AB6: ='CPI by declile'!T116 -> 2.6749426 | AC6: ='CPI by declile'!U116 -> 2.619984 | AD6: ='CPI by declile'!V116 -> 2.5658926 | AE6: ='CPI by declile'!W116 -> 2.5404892 | AF6: ='CPI by declile'!X116 -> 2.5016419 | ... AI6: ='CPI by declile'!AA116 -> 2.5683227
B7: ='Apr26 MPR A.1'!B8 -> 15.2 | G7: 3 | H7: ='Apr26 MPR A.1'!B8 -> 15.2 | I7: ='Apr26 MPR A.1'!C8 -> 6.2 | J7: ='Apr26 MPR A.1'!D8 -> 2.8 | M7: 3 | N7: ='Apr26 MPR E.1'!B9 -> 38.8 | O7: ='Apr26 MPR E.1'!C9 -> 30.61 | P7: ='Apr26 MPR E.1'!D9 -> 30.59 | X7: 2014 | Y7: ='CPI by declile'!Q117 -> 1.6526726 | Z7: ='CPI by declile'!R117 -> 1.6443428 | AA7: ='CPI by declile'!S117 -> 1.5139332 | AB7: ='CPI by declile'!T117 -> 1.4743028 | AC7: ='CPI by declile'!U117 -> 1.4229924 | AD7: ='CPI by declile'!V117 -> 1.4377905 | AE7: ='CPI by declile'!W117 -> 1.425967 | AF7: ='CPI by declile'!X117 -> 1.4250676 | ... AI7: ='CPI by declile'!AA117 -> 1.4719567
B8: ='Apr26 MPR A.1'!B9 -> 13.8 | G8: 4 | H8: ='Apr26 MPR A.1'!B9 -> 13.8 | I8: ='Apr26 MPR A.1'!C9 -> 5.8 | J8: ='Apr26 MPR A.1'!D9 -> 2.9 | M8: 4 | N8: ='Apr26 MPR E.1'!B10 -> 43.78 | O8: ='Apr26 MPR E.1'!C10 -> 26.41 | P8: ='Apr26 MPR E.1'!D10 -> 29.8 | X8: 2015 | Y8: ='CPI by declile'!Q118 -> -0.11647601 | Z8: ='CPI by declile'!R118 -> -0.056553227 | AA8: ='CPI by declile'!S118 -> -0.11385871 | AB8: ='CPI by declile'!T118 -> -0.046916613 | AC8: ='CPI by declile'!U118 -> -0.027784789 | AD8: ='CPI by declile'!V118 -> 0.046917797 | AE8: ='CPI by declile'!W118 -> 0.015410863 | AF8: ='CPI by declile'!X118 -> -0.013084909 | ... AI8: ='CPI by declile'!AA118 -> 0.049990831
B9: ='Apr26 MPR A.1'!B10 -> 13.2 | G9: 5 | H9: ='Apr26 MPR A.1'!B10 -> 13.2 | I9: ='Apr26 MPR A.1'!C10 -> 5.2 | J9: ='Apr26 MPR A.1'!D10 -> 3.4 | M9: 5 | N9: ='Apr26 MPR E.1'!B11 -> 55.06 | O9: ='Apr26 MPR E.1'!C11 -> 24.83 | P9: ='Apr26 MPR E.1'!D11 -> 20.11 | X9: 2016 | Y9: ='CPI by declile'!Q119 -> 0.41385279 | Z9: ='CPI by declile'!R119 -> 0.43541139 | AA9: ='CPI by declile'!S119 -> 0.50533475 | AB9: ='CPI by declile'!T119 -> 0.56193473 | AC9: ='CPI by declile'!U119 -> 0.59785596 | AD9: ='CPI by declile'!V119 -> 0.6133612 | AE9: ='CPI by declile'!W119 -> 0.64888621 | AF9: ='CPI by declile'!X119 -> 0.65421761 | ... AI9: ='CPI by declile'!AA119 -> 0.64164674
B10: ='Apr26 MPR A.1'!B11 -> 12.4 | G10: 6 | H10: ='Apr26 MPR A.1'!B11 -> 12.4 | I10: ='Apr26 MPR A.1'!C11 -> 4.5 | J10: ='Apr26 MPR A.1'!D11 -> 2.9 | X10: 2017 | Y10: ='CPI by declile'!Q120 -> 2.6775345 | Z10: ='CPI by declile'!R120 -> 2.7010582 | AA10: ='CPI by declile'!S120 -> 2.7186288 | AB10: ='CPI by declile'!T120 -> 2.7228943 | AC10: ='CPI by declile'!U120 -> 2.7084349 | AD10: ='CPI by declile'!V120 -> 2.7026215 | AE10: ='CPI by declile'!W120 -> 2.706421 | AF10: ='CPI by declile'!X120 -> 2.7087024 | ... AI10: ='CPI by declile'!AA120 -> 2.6909091
B11: ='Apr26 MPR A.1'!B12 -> 11.3 | G11: 7 | H11: ='Apr26 MPR A.1'!B12 -> 11.3 | I11: ='Apr26 MPR A.1'!C12 -> 4.3 | J11: ='Apr26 MPR A.1'!D12 -> 3.3 | X11: 2018 | Y11: ='CPI by declile'!Q121 -> 2.6114711 | Z11: ='CPI by declile'!R121 -> 2.6002523 | AA11: ='CPI by declile'!S121 -> 2.568673 | AB11: ='CPI by declile'!T121 -> 2.5423537 | AC11: ='CPI by declile'!U121 -> 2.4970952 | AD11: ='CPI by declile'!V121 -> 2.5055084 | AE11: ='CPI by declile'!W121 -> 2.4830722 | AF11: ='CPI by declile'!X121 -> 2.4700969 | ... AI11: ='CPI by declile'!AA121 -> 2.4751738
B12: ='Apr26 MPR A.1'!B13 -> 10.9 | G12: 8 | H12: ='Apr26 MPR A.1'!B13 -> 10.9 | I12: ='Apr26 MPR A.1'!C13 -> 4.1 | J12: ='Apr26 MPR A.1'!D13 -> 3.1 | X12: 2019 | Y12: ='CPI by declile'!Q122 -> 1.8760809 | Z12: ='CPI by declile'!R122 -> 1.8623673 | AA12: ='CPI by declile'!S122 -> 1.8277129 | AB12: ='CPI by declile'!T122 -> 1.8067401 | AC12: ='CPI by declile'!U122 -> 1.7845732 | AD12: ='CPI by declile'!V122 -> 1.7726978 | AE12: ='CPI by declile'!W122 -> 1.7729592 | AF12: ='CPI by declile'!X122 -> 1.7491977 | ... AI12: ='CPI by declile'!AA122 -> 1.7780954
B13: ='Apr26 MPR A.1'!B14 -> 9.5 | G13: 9 | H13: ='Apr26 MPR A.1'!B14 -> 9.5 | I13: ='Apr26 MPR A.1'!C14 -> 3.4 | J13: ='Apr26 MPR A.1'!D14 -> 3.2 | X13: 2020 | Y13: ='CPI by declile'!Q123 -> 0.73536296 | Z13: ='CPI by declile'!R123 -> 0.71637156 | AA13: ='CPI by declile'!S123 -> 0.78219459 | AB13: ='CPI by declile'!T123 -> 0.76246951 | AC13: ='CPI by declile'!U123 -> 0.84178485 | AD13: ='CPI by declile'!V123 -> 0.83976225 | AE13: ='CPI by declile'!W123 -> 0.85248869 | AF13: ='CPI by declile'!X123 -> 0.91937172 | ... AI13: ='CPI by declile'!AA123 -> 0.8812616
A14: 10 | B14: ='Apr26 MPR A.1'!B15 -> 8.9 | G14: 10 | H14: ='Apr26 MPR A.1'!B15 -> 8.9 | I14: ='Apr26 MPR A.1'!C15 -> 3.3 | J14: ='Apr26 MPR A.1'!D15 -> 2.2 | X14: 2021 | Y14: ='CPI by declile'!Q124 -> 2.5349601 | Z14: ='CPI by declile'!R124 -> 2.5194748 | AA14: ='CPI by declile'!S124 -> 2.5676656 | AB14: ='CPI by declile'!T124 -> 2.5863433 | AC14: ='CPI by declile'!U124 -> 2.6125217 | AD14: ='CPI by declile'!V124 -> 2.6292926 | AE14: ='CPI by declile'!W124 -> 2.6069924 | AF14: ='CPI by declile'!X124 -> 2.6108352 | ... AI14: ='CPI by declile'!AA124 -> 2.5823448
X15: 2022 | Y15: ='CPI by declile'!Q125 -> 11.513326 | Z15: ='CPI by declile'!R125 -> 10.65336 | AA15: ='CPI by declile'!S125 -> 9.928738 | AB15: ='CPI by declile'!T125 -> 9.654986 | AC15: ='CPI by declile'!U125 -> 9.4473332 | AD15: ='CPI by declile'!V125 -> 8.9738745 | AE15: ='CPI by declile'!W125 -> 8.8500634 | AF15: ='CPI by declile'!X125 -> 8.9075284 | ... AI15: ='CPI by declile'!AA125 -> 9.0535621
A16: 1 | C16: ='Apr26 MPR A.1'!C6 -> 7.1 | X16: 2023 | Y16: ='CPI by declile'!Q126 -> 7.9134942 | Z16: ='CPI by declile'!R126 -> 7.9332343 | AA16: ='CPI by declile'!S126 -> 7.6490149 | AB16: ='CPI by declile'!T126 -> 7.4158543 | AC16: ='CPI by declile'!U126 -> 7.3449449 | AD16: ='CPI by declile'!V126 -> 7.2798219 | AE16: ='CPI by declile'!W126 -> 7.1971091 | AF16: ='CPI by declile'!X126 -> 7.1997001 | ... AI16: ='CPI by declile'!AA126 -> 7.3019268
C17: ='Apr26 MPR A.1'!C7 -> 7.1 | X17: 2024 | Y17: ='CPI by declile'!Q127 -> 1.6065477 | Z17: ='CPI by declile'!R127 -> 1.7955065 | AA17: ='CPI by declile'!S127 -> 2.1140166 | AB17: ='CPI by declile'!T127 -> 2.2416325 | AC17: ='CPI by declile'!U127 -> 2.3806101 | AD17: ='CPI by declile'!V127 -> 2.5627345 | AE17: ='CPI by declile'!W127 -> 2.6121776 | AF17: ='CPI by declile'!X127 -> 2.6984426 | ... AI17: ='CPI by declile'!AA127 -> 2.5406441
C18: ='Apr26 MPR A.1'!C8 -> 6.2 | X18: 2025 | Y18: ='CPI by declile'!Q128 -> 3.346226 | Z18: ='CPI by declile'!R128 -> 3.3729236 | AA18: ='CPI by declile'!S128 -> 3.3672608 | AB18: ='CPI by declile'!T128 -> 3.3246415 | AC18: ='CPI by declile'!U128 -> 3.340624 | AD18: ='CPI by declile'!V128 -> 3.3603711 | AE18: ='CPI by declile'!W128 -> 3.3519709 | AF18: ='CPI by declile'!X128 -> 3.3652103 | ... AI18: ='CPI by declile'!AA128 -> 3.3680392
C19: ='Apr26 MPR A.1'!C9 -> 5.8 | X19: 2026 | Y19: ='CPI by declile'!Q129 -> 3.9768501 | Z19: ='CPI by declile'!R129 -> 3.9689382 | AA19: ='CPI by declile'!S129 -> 3.9652023 | AB19: ='CPI by declile'!T129 -> 4.0031998 | AC19: ='CPI by declile'!U129 -> 3.9831629 | AD19: ='CPI by declile'!V129 -> 3.9655499 | AE19: ='CPI by declile'!W129 -> 3.9684312 | AF19: ='CPI by declile'!X129 -> 3.9615185 | ... AI19: ='CPI by declile'!AA129 -> 3.9541306
C20: ='Apr26 MPR A.1'!C10 -> 5.2
C21: ='Apr26 MPR A.1'!C11 -> 4.5
C22: ='Apr26 MPR A.1'!C12 -> 4.3
C23: ='Apr26 MPR A.1'!C13 -> 4.1
C24: ='Apr26 MPR A.1'!C14 -> 3.4
A25: 10 | C25: ='Apr26 MPR A.1'!C15 -> 3.3
A27: 1 | D27: ='Apr26 MPR A.1'!D6 -> 2.4
D28: ='Apr26 MPR A.1'!D7 -> 2.7
D29: ='Apr26 MPR A.1'!D8 -> 2.8
D30: ='Apr26 MPR A.1'!D9 -> 2.9
D31: ='Apr26 MPR A.1'!D10 -> 3.4
D32: ='Apr26 MPR A.1'!D11 -> 2.9
D33: ='Apr26 MPR A.1'!D12 -> 3.3
D34: ='Apr26 MPR A.1'!D13 -> 3.1
D35: ='Apr26 MPR A.1'!D14 -> 3.2
A36: 10 | D36: ='Apr26 MPR A.1'!D15 -> 2.2

Sheet Apr26 MPR A.1
A1: Section 2: Topical policy issues
A3: Chart A.1 - Share of household spending on categories particularly exposed to energy-driven price rises, by income decile
A5: Income decile | B5: Food and non-alcoholic beverages | C5: Electricity, gas and other fuels | D5: Motor fuels
A6: 1 (poorest) | B6: 14.6 | C6: 7.1 | D6: 2.4
A7: 2 | B7: 15.4 | C7: 7.1 | D7: 2.7
A8: 3 | B8: 15.2 | C8: 6.2 | D8: 2.8
A9: 4 | B9: 13.8 | C9: 5.8 | D9: 2.9
A10: 5 | B10: 13.2 | C10: 5.2 | D10: 3.4
A11: 6 | B11: 12.4 | C11: 4.5 | D11: 2.9
A12: 7 | B12: 11.3 | C12: 4.3 | D12: 3.3
A13: 8 | B13: 10.9 | C13: 4.1 | D13: 3.1
A14: 9 | B14: 9.5 | C14: 3.4 | D14: 3.2
A15: 10 (richest) | B15: 8.9 | C15: 3.3 | D15: 2.2

Sheet Apr26 MPR E.1
A1: Section 2: Topical policy issues
A3: Chart E.1 - Actions taken by households in response to higher costs and share of households with deposits worth less than two weeks of income
B5: Actions taken by households in response to higher costs, share of households (per cent) | G5: Share of households with deposits worth less than two weeks of income (per cent)
A6: Income quintile | B6: Buying the same or more | C6: Cutting back on some things | D6: Cutting back completely | F6: Date | G6: Low income | H6: High income
A7: 1 (lowest) | B7: 26.99 | C7: 26.28 | D7: 46.73 | F7: 2022 H1 | G7: 43.548 | H7: 25.191
A8: 2 | B8: 36.19 | C8: 27.53 | D8: 36.29 | F8: 2026 H1 | G8: 54.042 | H8: 17.142
A9: 3 | B9: 38.8 | C9: 30.61 | D9: 30.59
A10: 4 | B10: 43.78 | C10: 26.41 | D10: 29.8
A11: 5 (highest) | B11: 55.06 | C11: 24.83 | D11: 20.11

Sheet Distributional analysis >>

Sheet CPI by declile
A1: CPI data | O1: Weights - food | AC1: Weights - energy | AQ1: Weights - petrol & oil | BE1: Weights - other
B3: CPI | C3: Food | D3: Energy | E3: Petrol | F3: CPI other | G3: Check | P3: CPI food | Q3: EFS total | R3: 0-10 | S3: 11-20 | T3: 21-30 | U3: 31-40 | V3: 41-50 | W3: 51-60 | X3: 61-70 | Y3: 71-80 | Z3: 81-90 | AA3: 91-100 | AD3: CPI energy | AE3: EFS total | AF3: 0-10 | AG3: 11-20 | AH3: 21-30 | AI3: 31-40 | AJ3: 41-50 | AK3: 51-60 | AL3: 61-70 | AM3: 71-80 | AN3: 81-90 | AO3: 91-100 | AR3: CPI petrol | AS3: EFS total | AT3: 0-10 | AU3: 11-20 | AV3: 21-30 | AW3: 31-40 | AX3: 41-50 | AY3: 51-60 | AZ3: 61-70 | BA3: 71-80 | BB3: 81-90 | BC3: 91-100 | BF3: CPI oth | BG3: EFS total | BH3: 0-10 | BI3: 11-20 | BJ3: 21-30 | BK3: 31-40 | BL3: 41-50 | BM3: 51-60 | BN3: 61-70 | BO3: 71-80 | BP3: 81-90 | BQ3: 91-100
A4: 1987 | P4: =HAVERA!B5/1000 -> #N/A | Q4: =Q5 -> 0.10488419 | R4: =R5 -> 0.16946117 | S4: =S5 -> 0.16582996 | T4: =T5 -> 0.1484721 | U4: =U5 -> 0.1299966 | V4: =V5 -> 0.12155375 | W4: =W5 -> 0.10751169 | X4: =X5 -> 0.10524167 | ... AA4: =AA5 -> 0.071317947 | AD4: =HAVERA!C5/1000 -> #N/A | AE4: =AE5 -> 0.029417273 | AF4: =AF5 -> 0.059160641 | AG4: =AG5 -> 0.057823242 | AH4: =AH5 -> 0.046293902 | AI4: =AI5 -> 0.038459694 | AJ4: =AJ5 -> 0.034945783 | AK4: =AK5 -> 0.028826884 | AL4: =AL5 -> 0.027915083 | ... AO4: =AO5 -> 0.018580417 | AR4: =HAVERA!D5/1000 -> #N/A | AS4: =AS5 -> 0.037060748 | AT4: =AT5 -> 0.02434028 | AU4: =AU5 -> 0.02486177 | AV4: =AV5 -> 0.03334324 | AW4: =AW5 -> 0.038079986 | AX4: =AX5 -> 0.042426535 | AY4: =AY5 -> 0.038179695 | AZ4: =AZ5 -> 0.040970915 | ... BC4: =BC5 -> 0.03330738 | BF4: =1-P4-AD4-AR4 -> #N/A | BG4: =BG5 -> 0.82863779 | BH4: =BH5 -> 0.74703791 | BI4: =BI5 -> 0.75148502 | BJ4: =BJ5 -> 0.77189076 | BK4: =BK5 -> 0.79346372 | BL4: =BL5 -> 0.80107393 | BM4: =BM5 -> 0.82548174 | BN4: =BN5 -> 0.82587233 | ... BQ4: =BQ5 -> 0.87679426
A5: 1988 | P5: =HAVERA!B6/1000 -> 0.184 | Q5: =Q6 -> 0.10488419 | R5: =R6 -> 0.16946117 | S5: =S6 -> 0.16582996 | T5: =T6 -> 0.1484721 | U5: =U6 -> 0.1299966 | V5: =V6 -> 0.12155375 | W5: =W6 -> 0.10751169 | X5: =X6 -> 0.10524167 | ... AA5: =AA6 -> 0.071317947 | AD5: =HAVERA!C6/1000 -> 0.062 | AE5: =AE6 -> 0.029417273 | AF5: =AF6 -> 0.059160641 | AG5: =AG6 -> 0.057823242 | AH5: =AH6 -> 0.046293902 | AI5: =AI6 -> 0.038459694 | AJ5: =AJ6 -> 0.034945783 | AK5: =AK6 -> 0.028826884 | AL5: =AL6 -> 0.027915083 | ... AO5: =AO6 -> 0.018580417 | AR5: =HAVERA!D6/1000 -> 0.041 | AS5: =AS6 -> 0.037060748 | AT5: =AT6 -> 0.02434028 | AU5: =AU6 -> 0.02486177 | AV5: =AV6 -> 0.03334324 | AW5: =AW6 -> 0.038079986 | AX5: =AX6 -> 0.042426535 | AY5: =AY6 -> 0.038179695 | AZ5: =AZ6 -> 0.040970915 | ... BC5: =BC6 -> 0.03330738 | BF5: =1-P5-AD5-AR5 -> 0.713 | BG5: =BG6 -> 0.82863779 | BH5: =BH6 -> 0.74703791 | BI5: =BI6 -> 0.75148502 | BJ5: =BJ6 -> 0.77189076 | BK5: =BK6 -> 0.79346372 | BL5: =BL6 -> 0.80107393 | BM5: =BM6 -> 0.82548174 | BN5: =BN6 -> 0.82587233 | ... BQ5: =BQ6 -> 0.87679426
A6: 1989 | P6: =HAVERA!B7/1000 -> 0.177 | Q6: =Q7 -> 0.10488419 | R6: =R7 -> 0.16946117 | S6: =S7 -> 0.16582996 | T6: =T7 -> 0.1484721 | U6: =U7 -> 0.1299966 | V6: =V7 -> 0.12155375 | W6: =W7 -> 0.10751169 | X6: =X7 -> 0.10524167 | ... AA6: =AA7 -> 0.071317947 | AD6: =HAVERA!C7/1000 -> 0.062 | AE6: =AE7 -> 0.029417273 | AF6: =AF7 -> 0.059160641 | AG6: =AG7 -> 0.057823242 | AH6: =AH7 -> 0.046293902 | AI6: =AI7 -> 0.038459694 | AJ6: =AJ7 -> 0.034945783 | AK6: =AK7 -> 0.028826884 | AL6: =AL7 -> 0.027915083 | ... AO6: =AO7 -> 0.018580417 | AR6: =HAVERA!D7/1000 -> 0.039 | AS6: =AS7 -> 0.037060748 | AT6: =AT7 -> 0.02434028 | AU6: =AU7 -> 0.02486177 | AV6: =AV7 -> 0.03334324 | AW6: =AW7 -> 0.038079986 | AX6: =AX7 -> 0.042426535 | AY6: =AY7 -> 0.038179695 | AZ6: =AZ7 -> 0.040970915 | ... BC6: =BC7 -> 0.03330738 | BF6: =1-P6-AD6-AR6 -> 0.722 | BG6: =BG7 -> 0.82863779 | BH6: =BH7 -> 0.74703791 | BI6: =BI7 -> 0.75148502 | BJ6: =BJ7 -> 0.77189076 | BK6: =BK7 -> 0.79346372 | BL6: =BL7 -> 0.80107393 | BM6: =BM7 -> 0.82548174 | BN6: =BN7 -> 0.82587233 | ... BQ6: =BQ7 -> 0.87679426
A7: 1990 | P7: =HAVERA!B8/1000 -> 0.185 | Q7: =Q8 -> 0.10488419 | R7: =R8 -> 0.16946117 | S7: =S8 -> 0.16582996 | T7: =T8 -> 0.1484721 | U7: =U8 -> 0.1299966 | V7: =V8 -> 0.12155375 | W7: =W8 -> 0.10751169 | X7: =X8 -> 0.10524167 | ... AA7: =AA8 -> 0.071317947 | AD7: =HAVERA!C8/1000 -> 0.058 | AE7: =AE8 -> 0.029417273 | AF7: =AF8 -> 0.059160641 | AG7: =AG8 -> 0.057823242 | AH7: =AH8 -> 0.046293902 | AI7: =AI8 -> 0.038459694 | AJ7: =AJ8 -> 0.034945783 | AK7: =AK8 -> 0.028826884 | AL7: =AL8 -> 0.027915083 | ... AO7: =AO8 -> 0.018580417 | AR7: =HAVERA!D8/1000 -> 0.038 | AS7: =AS8 -> 0.037060748 | AT7: =AT8 -> 0.02434028 | AU7: =AU8 -> 0.02486177 | AV7: =AV8 -> 0.03334324 | AW7: =AW8 -> 0.038079986 | AX7: =AX8 -> 0.042426535 | AY7: =AY8 -> 0.038179695 | AZ7: =AZ8 -> 0.040970915 | ... BC7: =BC8 -> 0.03330738 | BF7: =1-P7-AD7-AR7 -> 0.719 | BG7: =BG8 -> 0.82863779 | BH7: =BH8 -> 0.74703791 | BI7: =BI8 -> 0.75148502 | BJ7: =BJ8 -> 0.77189076 | BK7: =BK8 -> 0.79346372 | BL7: =BL8 -> 0.80107393 | BM7: =BM8 -> 0.82548174 | BN7: =BN8 -> 0.82587233 | ... BQ7: =BQ8 -> 0.87679426
A8: 1991 | P8: =HAVERA!B9/1000 -> 0.177 | Q8: =Q9 -> 0.10488419 | R8: =R9 -> 0.16946117 | S8: =S9 -> 0.16582996 | T8: =T9 -> 0.1484721 | U8: =U9 -> 0.1299966 | V8: =V9 -> 0.12155375 | W8: =W9 -> 0.10751169 | X8: =X9 -> 0.10524167 | ... AA8: =AA9 -> 0.071317947 | AD8: =HAVERA!C9/1000 -> 0.054 | AE8: =AE9 -> 0.029417273 | AF8: =AF9 -> 0.059160641 | AG8: =AG9 -> 0.057823242 | AH8: =AH9 -> 0.046293902 | AI8: =AI9 -> 0.038459694 | AJ8: =AJ9 -> 0.034945783 | AK8: =AK9 -> 0.028826884 | AL8: =AL9 -> 0.027915083 | ... AO8: =AO9 -> 0.018580417 | AR8: =HAVERA!D9/1000 -> 0.039 | AS8: =AS9 -> 0.037060748 | AT8: =AT9 -> 0.02434028 | AU8: =AU9 -> 0.02486177 | AV8: =AV9 -> 0.03334324 | AW8: =AW9 -> 0.038079986 | AX8: =AX9 -> 0.042426535 | AY8: =AY9 -> 0.038179695 | AZ8: =AZ9 -> 0.040970915 | ... BC8: =BC9 -> 0.03330738 | BF8: =1-P8-AD8-AR8 -> 0.73 | BG8: =BG9 -> 0.82863779 | BH8: =BH9 -> 0.74703791 | BI8: =BI9 -> 0.75148502 | BJ8: =BJ9 -> 0.77189076 | BK8: =BK9 -> 0.79346372 | BL8: =BL9 -> 0.80107393 | BM8: =BM9 -> 0.82548174 | BN8: =BN9 -> 0.82587233 | ... BQ8: =BQ9 -> 0.87679426
A9: 1992 | P9: =HAVERA!B10/1000 -> 0.172 | Q9: =Q10 -> 0.10488419 | R9: =R10 -> 0.16946117 | S9: =S10 -> 0.16582996 | T9: =T10 -> 0.1484721 | U9: =U10 -> 0.1299966 | V9: =V10 -> 0.12155375 | W9: =W10 -> 0.10751169 | X9: =X10 -> 0.10524167 | ... AA9: =AA10 -> 0.071317947 | AD9: =HAVERA!C10/1000 -> 0.053 | AE9: =AE10 -> 0.029417273 | AF9: =AF10 -> 0.059160641 | AG9: =AG10 -> 0.057823242 | AH9: =AH10 -> 0.046293902 | AI9: =AI10 -> 0.038459694 | AJ9: =AJ10 -> 0.034945783 | AK9: =AK10 -> 0.028826884 | AL9: =AL10 -> 0.027915083 | ... AO9: =AO10 -> 0.018580417 | AR9: =HAVERA!D10/1000 -> 0.038 | AS9: =AS10 -> 0.037060748 | AT9: =AT10 -> 0.02434028 | AU9: =AU10 -> 0.02486177 | AV9: =AV10 -> 0.03334324 | AW9: =AW10 -> 0.038079986 | AX9: =AX10 -> 0.042426535 | AY9: =AY10 -> 0.038179695 | AZ9: =AZ10 -> 0.040970915 | ... BC9: =BC10 -> 0.03330738 | BF9: =1-P9-AD9-AR9 -> 0.737 | BG9: =BG10 -> 0.82863779 | BH9: =BH10 -> 0.74703791 | BI9: =BI10 -> 0.75148502 | BJ9: =BJ10 -> 0.77189076 | BK9: =BK10 -> 0.79346372 | BL9: =BL10 -> 0.80107393 | BM9: =BM10 -> 0.82548174 | BN9: =BN10 -> 0.82587233 | ... BQ9: =BQ10 -> 0.87679426
A10: 1993 | P10: =HAVERA!B11/1000 -> 0.159 | Q10: =Q11 -> 0.10488419 | R10: =R11 -> 0.16946117 | S10: =S11 -> 0.16582996 | T10: =T11 -> 0.1484721 | U10: =U11 -> 0.1299966 | V10: =V11 -> 0.12155375 | W10: =W11 -> 0.10751169 | X10: =X11 -> 0.10524167 | ... AA10: =AA11 -> 0.071317947 | AD10: =HAVERA!C11/1000 -> 0.052 | AE10: =AE11 -> 0.029417273 | AF10: =AF11 -> 0.059160641 | AG10: =AG11 -> 0.057823242 | AH10: =AH11 -> 0.046293902 | AI10: =AI11 -> 0.038459694 | AJ10: =AJ11 -> 0.034945783 | AK10: =AK11 -> 0.028826884 | AL10: =AL11 -> 0.027915083 | ... AO10: =AO11 -> 0.018580417 | AR10: =HAVERA!D11/1000 -> 0.039 | AS10: =AS11 -> 0.037060748 | AT10: =AT11 -> 0.02434028 | AU10: =AU11 -> 0.02486177 | AV10: =AV11 -> 0.03334324 | AW10: =AW11 -> 0.038079986 | AX10: =AX11 -> 0.042426535 | AY10: =AY11 -> 0.038179695 | AZ10: =AZ11 -> 0.040970915 | ... BC10: =BC11 -> 0.03330738 | BF10: =1-P10-AD10-AR10 -> 0.75 | BG10: =BG11 -> 0.82863779 | BH10: =BH11 -> 0.74703791 | BI10: =BI11 -> 0.75148502 | BJ10: =BJ11 -> 0.77189076 | BK10: =BK11 -> 0.79346372 | BL10: =BL11 -> 0.80107393 | BM10: =BM11 -> 0.82548174 | BN10: =BN11 -> 0.82587233 | ... BQ10: =BQ11 -> 0.87679426
A11: 1994 | P11: =HAVERA!B12/1000 -> 0.157 | Q11: =Q12 -> 0.10488419 | R11: =R12 -> 0.16946117 | S11: =S12 -> 0.16582996 | T11: =T12 -> 0.1484721 | U11: =U12 -> 0.1299966 | V11: =V12 -> 0.12155375 | W11: =W12 -> 0.10751169 | X11: =X12 -> 0.10524167 | ... AA11: =AA12 -> 0.071317947 | AD11: =HAVERA!C12/1000 -> 0.049 | AE11: =AE12 -> 0.029417273 | AF11: =AF12 -> 0.059160641 | AG11: =AG12 -> 0.057823242 | AH11: =AH12 -> 0.046293902 | AI11: =AI12 -> 0.038459694 | AJ11: =AJ12 -> 0.034945783 | AK11: =AK12 -> 0.028826884 | AL11: =AL12 -> 0.027915083 | ... AO11: =AO12 -> 0.018580417 | AR11: =HAVERA!D12/1000 -> 0.041 | AS11: =AS12 -> 0.037060748 | AT11: =AT12 -> 0.02434028 | AU11: =AU12 -> 0.02486177 | AV11: =AV12 -> 0.03334324 | AW11: =AW12 -> 0.038079986 | AX11: =AX12 -> 0.042426535 | AY11: =AY12 -> 0.038179695 | AZ11: =AZ12 -> 0.040970915 | ... BC11: =BC12 -> 0.03330738 | BF11: =1-P11-AD11-AR11 -> 0.753 | BG11: =BG12 -> 0.82863779 | BH11: =BH12 -> 0.74703791 | BI11: =BI12 -> 0.75148502 | BJ11: =BJ12 -> 0.77189076 | BK11: =BK12 -> 0.79346372 | BL11: =BL12 -> 0.80107393 | BM11: =BM12 -> 0.82548174 | BN11: =BN12 -> 0.82587233 | ... BQ11: =BQ12 -> 0.87679426
A12: 1995 | P12: =HAVERA!B13/1000 -> 0.158 | Q12: =Q13 -> 0.10488419 | R12: =R13 -> 0.16946117 | S12: =S13 -> 0.16582996 | T12: =T13 -> 0.1484721 | U12: =U13 -> 0.1299966 | V12: =V13 -> 0.12155375 | W12: =W13 -> 0.10751169 | X12: =X13 -> 0.10524167 | ... AA12: =AA13 -> 0.071317947 | AD12: =HAVERA!C13/1000 -> 0.049 | AE12: =AE13 -> 0.029417273 | AF12: =AF13 -> 0.059160641 | AG12: =AG13 -> 0.057823242 | AH12: =AH13 -> 0.046293902 | AI12: =AI13 -> 0.038459694 | AJ12: =AJ13 -> 0.034945783 | AK12: =AK13 -> 0.028826884 | AL12: =AL13 -> 0.027915083 | ... AO12: =AO13 -> 0.018580417 | AR12: =HAVERA!D13/1000 -> 0.041 | AS12: =AS13 -> 0.037060748 | AT12: =AT13 -> 0.02434028 | AU12: =AU13 -> 0.02486177 | AV12: =AV13 -> 0.03334324 | AW12: =AW13 -> 0.038079986 | AX12: =AX13 -> 0.042426535 | AY12: =AY13 -> 0.038179695 | AZ12: =AZ13 -> 0.040970915 | ... BC12: =BC13 -> 0.03330738 | BF12: =1-P12-AD12-AR12 -> 0.752 | BG12: =BG13 -> 0.82863779 | BH12: =BH13 -> 0.74703791 | BI12: =BI13 -> 0.75148502 | BJ12: =BJ13 -> 0.77189076 | BK12: =BK13 -> 0.79346372 | BL12: =BL13 -> 0.80107393 | BM12: =BM13 -> 0.82548174 | BN12: =BN13 -> 0.82587233 | ... BQ12: =BQ13 -> 0.87679426
A13: 1996 | B13: =DataA!N30 -> 68.81667 | C13: =DataA!O30 -> 58.90833 | D13: =DataA!P30 -> 40.2 | E13: =DataA!Q30 -> 50.46667 | F13: =$F$32*(1*B13/$B$32-P13*C13/$C$32-AD13*D13/$D$32-AR13*E13/$E$32)/(1-P13-AD13-AR13) -> 73.509342 | G13: =G14*(P13*C13/C14+AD13*D13/D14+AR13*E13/E14+BF13*F13/F14) -> 69.999737 | H13: =100*((G13/G12)-1) -> #DIV/0! | I13: =100*((B13/B12)-1) -> #DIV/0! | P13: =HAVERA!B14/1000 -> 0.156 | Q13: =Q14 -> 0.10488419 | R13: =R14 -> 0.16946117 | S13: =S14 -> 0.16582996 | T13: =T14 -> 0.1484721 | U13: =U14 -> 0.1299966 | V13: =V14 -> 0.12155375 | W13: =W14 -> 0.10751169 | X13: =X14 -> 0.10524167 | ... AA13: =AA14 -> 0.071317947 | AD13: =HAVERA!C14/1000 -> 0.045 | AE13: =AE14 -> 0.029417273 | AF13: =AF14 -> 0.059160641 | AG13: =AG14 -> 0.057823242 | AH13: =AH14 -> 0.046293902 | AI13: =AI14 -> 0.038459694 | AJ13: =AJ14 -> 0.034945783 | AK13: =AK14 -> 0.028826884 | AL13: =AL14 -> 0.027915083 | ... AO13: =AO14 -> 0.018580417 | AR13: =HAVERA!D14/1000 -> 0.04 | AS13: =AS14 -> 0.037060748 | AT13: =AT14 -> 0.02434028 | AU13: =AU14 -> 0.02486177 | AV13: =AV14 -> 0.03334324 | AW13: =AW14 -> 0.038079986 | AX13: =AX14 -> 0.042426535 | AY13: =AY14 -> 0.038179695 | AZ13: =AZ14 -> 0.040970915 | ... BC13: =BC14 -> 0.03330738 | BF13: =1-P13-AD13-AR13 -> 0.759 | BG13: =BG14 -> 0.82863779 | BH13: =BH14 -> 0.74703791 | BI13: =BI14 -> 0.75148502 | BJ13: =BJ14 -> 0.77189076 | BK13: =BK14 -> 0.79346372 | BL13: =BL14 -> 0.80107393 | BM13: =BM14 -> 0.82548174 | BN13: =BN14 -> 0.82587233 | ... BQ13: =BQ14 -> 0.87679426
A14: 1997 | B14: =DataA!N31 -> 70.06667 | C14: =DataA!O31 -> 59.60833 | D14: =DataA!P31 -> 39.01667 | E14: =DataA!Q31 -> 55.48333 | F14: =$F$32*(1*B14/$B$32-P14*C14/$C$32-AD14*D14/$D$32-AR14*E14/$E$32)/(1-P14-AD14-AR14) -> 74.767241 | G14: =G15*(P14*C14/C15+AD14*D14/D15+AR14*E14/E15+BF14*F14/F15) -> 71.199695 | H14: =100*((G14/G13)-1) -> 1.7142332 | I14: =100*((B14/B13)-1) -> 1.8164204 | P14: =HAVERA!B15/1000 -> 0.152 | Q14: =Q15 -> 0.10488419 | R14: =R15 -> 0.16946117 | S14: =S15 -> 0.16582996 | T14: =T15 -> 0.1484721 | U14: =U15 -> 0.1299966 | V14: =V15 -> 0.12155375 | W14: =W15 -> 0.10751169 | X14: =X15 -> 0.10524167 | ... AA14: =AA15 -> 0.071317947 | AD14: =HAVERA!C15/1000 -> 0.044 | AE14: =AE15 -> 0.029417273 | AF14: =AF15 -> 0.059160641 | AG14: =AG15 -> 0.057823242 | AH14: =AH15 -> 0.046293902 | AI14: =AI15 -> 0.038459694 | AJ14: =AJ15 -> 0.034945783 | AK14: =AK15 -> 0.028826884 | AL14: =AL15 -> 0.027915083 | ... AO14: =AO15 -> 0.018580417 | AR14: =HAVERA!D15/1000 -> 0.043 | AS14: =AS15 -> 0.037060748 | AT14: =AT15 -> 0.02434028 | AU14: =AU15 -> 0.02486177 | AV14: =AV15 -> 0.03334324 | AW14: =AW15 -> 0.038079986 | AX14: =AX15 -> 0.042426535 | AY14: =AY15 -> 0.038179695 | AZ14: =AZ15 -> 0.040970915 | ... BC14: =BC15 -> 0.03330738 | BF14: =1-P14-AD14-AR14 -> 0.761 | BG14: =BG15 -> 0.82863779 | BH14: =BH15 -> 0.74703791 | BI14: =BI15 -> 0.75148502 | BJ14: =BJ15 -> 0.77189076 | BK14: =BK15 -> 0.79346372 | BL14: =BL15 -> 0.80107393 | BM14: =BM15 -> 0.82548174 | BN14: =BN15 -> 0.82587233 | ... BQ14: =BQ15 -> 0.87679426
A15: 1998 | B15: =DataA!N32 -> 71.15833 | C15: =DataA!O32 -> 61.06666 | D15: =DataA!P32 -> 37.38334 | E15: =DataA!Q32 -> 58.25834 | F15: =$F$32*(1*B15/$B$32-P15*C15/$C$32-AD15*D15/$D$32-AR15*E15/$E$32)/(1-P15-AD15-AR15) -> 75.644456 | G15: =G16*(P15*C15/C16+AD15*D15/D16+AR15*E15/E16+BF15*F15/F16) -> 72.106848 | H15: =100*((G15/G14)-1) -> 1.2740967 | I15: =100*((B15/B14)-1) -> 1.5580304 | P15: =HAVERA!B16/1000 -> 0.144 | Q15: =Q16 -> 0.10488419 | R15: =R16 -> 0.16946117 | S15: =S16 -> 0.16582996 | T15: =T16 -> 0.1484721 | U15: =U16 -> 0.1299966 | V15: =V16 -> 0.12155375 | W15: =W16 -> 0.10751169 | X15: =X16 -> 0.10524167 | ... AA15: =AA16 -> 0.071317947 | AD15: =HAVERA!C16/1000 -> 0.043 | AE15: =AE16 -> 0.029417273 | AF15: =AF16 -> 0.059160641 | AG15: =AG16 -> 0.057823242 | AH15: =AH16 -> 0.046293902 | AI15: =AI16 -> 0.038459694 | AJ15: =AJ16 -> 0.034945783 | AK15: =AK16 -> 0.028826884 | AL15: =AL16 -> 0.027915083 | ... AO15: =AO16 -> 0.018580417 | AR15: =HAVERA!D16/1000 -> 0.043 | AS15: =AS16 -> 0.037060748 | AT15: =AT16 -> 0.02434028 | AU15: =AU16 -> 0.02486177 | AV15: =AV16 -> 0.03334324 | AW15: =AW16 -> 0.038079986 | AX15: =AX16 -> 0.042426535 | AY15: =AY16 -> 0.038179695 | AZ15: =AZ16 -> 0.040970915 | ... BC15: =BC16 -> 0.03330738 | BF15: =1-P15-AD15-AR15 -> 0.77 | BG15: =BG16 -> 0.82863779 | BH15: =BH16 -> 0.74703791 | BI15: =BI16 -> 0.75148502 | BJ15: =BJ16 -> 0.77189076 | BK15: =BK16 -> 0.79346372 | BL15: =BL16 -> 0.80107393 | BM15: =BM16 -> 0.82548174 | BN15: =BN16 -> 0.82587233 | ... BQ15: =BQ16 -> 0.87679426
A16: 1999 | B16: =DataA!N33 -> 72.11666 | C16: =DataA!O33 -> 62.375 | D16: =DataA!P33 -> 37.36666 | E16: =DataA!Q33 -> 63.16667 | F16: =$F$32*(1*B16/$B$32-P16*C16/$C$32-AD16*D16/$D$32-AR16*E16/$E$32)/(1-P16-AD16-AR16) -> 76.166192 | G16: =G17*(P16*C16/C17+AD16*D16/D17+AR16*E16/E17+BF16*F16/F17) -> 72.954361 | H16: =100*((G16/G15)-1) -> 1.1753565 | I16: =100*((B16/B15)-1) -> 1.3467573 | P16: =HAVERA!B17/1000 -> 0.141 | Q16: =Q17 -> 0.10488419 | R16: =R17 -> 0.16946117 | S16: =S17 -> 0.16582996 | T16: =T17 -> 0.1484721 | U16: =U17 -> 0.1299966 | V16: =V17 -> 0.12155375 | W16: =W17 -> 0.10751169 | X16: =X17 -> 0.10524167 | ... AA16: =AA17 -> 0.071317947 | AD16: =HAVERA!C17/1000 -> 0.04 | AE16: =AE17 -> 0.029417273 | AF16: =AF17 -> 0.059160641 | AG16: =AG17 -> 0.057823242 | AH16: =AH17 -> 0.046293902 | AI16: =AI17 -> 0.038459694 | AJ16: =AJ17 -> 0.034945783 | AK16: =AK17 -> 0.028826884 | AL16: =AL17 -> 0.027915083 | ... AO16: =AO17 -> 0.018580417 | AR16: =HAVERA!D17/1000 -> 0.043 | AS16: =AS17 -> 0.037060748 | AT16: =AT17 -> 0.02434028 | AU16: =AU17 -> 0.02486177 | AV16: =AV17 -> 0.03334324 | AW16: =AW17 -> 0.038079986 | AX16: =AX17 -> 0.042426535 | AY16: =AY17 -> 0.038179695 | AZ16: =AZ17 -> 0.040970915 | ... BC16: =BC17 -> 0.03330738 | BF16: =1-P16-AD16-AR16 -> 0.776 | BG16: =BG17 -> 0.82863779 | BH16: =BH17 -> 0.74703791 | BI16: =BI17 -> 0.75148502 | BJ16: =BJ17 -> 0.77189076 | BK16: =BK17 -> 0.79346372 | BL16: =BL17 -> 0.80107393 | BM16: =BM17 -> 0.82548174 | BN16: =BN17 -> 0.82587233 | ... BQ16: =BQ17 -> 0.87679426
A17: 2000 | B17: =DataA!N34 -> 72.69167 | C17: =DataA!O34 -> 63.075 | D17: =DataA!P34 -> 37.39167 | E17: =DataA!Q34 -> 71.475 | F17: =$F$32*(1*B17/$B$32-P17*C17/$C$32-AD17*D17/$D$32-AR17*E17/$E$32)/(1-P17-AD17-AR17) -> 75.623249 | G17: =G18*(P17*C17/C18+AD17*D17/D18+AR17*E17/E18+BF17*F17/F18) -> 73.028746 | H17: =100*((G17/G16)-1) -> 0.10196156 | I17: =100*((B17/B16)-1) -> 0.7973331 | P17: =HAVERA!B18/1000 -> 0.121 | Q17: =Q18 -> 0.10488419 | R17: =R18 -> 0.16946117 | S17: =S18 -> 0.16582996 | T17: =T18 -> 0.1484721 | U17: =U18 -> 0.1299966 | V17: =V18 -> 0.12155375 | W17: =W18 -> 0.10751169 | X17: =X18 -> 0.10524167 | ... AA17: =AA18 -> 0.071317947 | AD17: =HAVERA!C18/1000 -> 0.033 | AE17: =AE18 -> 0.029417273 | AF17: =AF18 -> 0.059160641 | AG17: =AG18 -> 0.057823242 | AH17: =AH18 -> 0.046293902 | AI17: =AI18 -> 0.038459694 | AJ17: =AJ18 -> 0.034945783 | AK17: =AK18 -> 0.028826884 | AL17: =AL18 -> 0.027915083 | ... AO17: =AO18 -> 0.018580417 | AR17: =HAVERA!D18/1000 -> 0.038 | AS17: =AS18 -> 0.037060748 | AT17: =AT18 -> 0.02434028 | AU17: =AU18 -> 0.02486177 | AV17: =AV18 -> 0.03334324 | AW17: =AW18 -> 0.038079986 | AX17: =AX18 -> 0.042426535 | AY17: =AY18 -> 0.038179695 | AZ17: =AZ18 -> 0.040970915 | ... BC17: =BC18 -> 0.03330738 | BF17: =1-P17-AD17-AR17 -> 0.808 | BG17: =BG18 -> 0.82863779 | BH17: =BH18 -> 0.74703791 | BI17: =BI18 -> 0.75148502 | BJ17: =BJ18 -> 0.77189076 | BK17: =BK18 -> 0.79346372 | BL17: =BL18 -> 0.80107393 | BM17: =BM18 -> 0.82548174 | BN17: =BN18 -> 0.82587233 | ... BQ17: =BQ18 -> 0.87679426
A18: 2001 | B18: =DataA!N35 -> 73.59167 | C18: =DataA!O35 -> 65.36667 | D18: =DataA!P35 -> 37.58333 | E18: =DataA!Q35 -> 67.80833 | F18: =$F$32*(1*B18/$B$32-P18*C18/$C$32-AD18*D18/$D$32-AR18*E18/$E$32)/(1-P18-AD18-AR18) -> 76.262117 | G18: =G19*(P18*C18/C19+AD18*D18/D19+AR18*E18/E19+BF18*F18/F19) -> 73.701226 | H18: =100*((G18/G17)-1) -> 0.92084212 | I18: =100*((B18/B17)-1) -> 1.2381061 | P18: =HAVERA!B19/1000 -> 0.114 | Q18: ='Family spending workbook 1'!Y8/100 -> 0.10488419 | R18: ='Family spending workbook 1'!O8/100 -> 0.16946117 | S18: ='Family spending workbook 1'!P8/100 -> 0.16582996 | T18: ='Family spending workbook 1'!Q8/100 -> 0.1484721 | U18: ='Family spending workbook 1'!R8/100 -> 0.1299966 | V18: ='Family spending workbook 1'!S8/100 -> 0.12155375 | W18: ='Family spending workbook 1'!T8/100 -> 0.10751169 | X18: ='Family spending workbook 1'!U8/100 -> 0.10524167 | Y18: ='Family spending workbook 1'!V8/100 -> 0.09551406 | ... AA18: ='Family spending workbook 1'!X8/100 -> 0.071317947 | AD18: =HAVERA!C19/1000 -> 0.029 | AE18: ='Family spending workbook 1'!Y39/100 -> 0.029417273 | AF18: ='Family spending workbook 1'!O39/100 -> 0.059160641 | AG18: ='Family spending workbook 1'!P39/100 -> 0.057823242 | AH18: ='Family spending workbook 1'!Q39/100 -> 0.046293902 | AI18: ='Family spending workbook 1'!R39/100 -> 0.038459694 | AJ18: ='Family spending workbook 1'!S39/100 -> 0.034945783 | AK18: ='Family spending workbook 1'!T39/100 -> 0.028826884 | AL18: ='Family spending workbook 1'!U39/100 -> 0.027915083 | AM18: ='Family spending workbook 1'!V39/100 -> 0.024749824 | ... AO18: ='Family spending workbook 1'!X39/100 -> 0.018580417 | AR18: =HAVERA!D19/1000 -> 0.037 | AS18: ='Family spending workbook 1'!Y70/100 -> 0.037060748 | AT18: ='Family spending workbook 1'!O70/100 -> 0.02434028 | AU18: ='Family spending workbook 1'!P70/100 -> 0.02486177 | AV18: ='Family spending workbook 1'!Q70/100 -> 0.03334324 | AW18: ='Family spending workbook 1'!R70/100 -> 0.038079986 | AX18: ='Family spending workbook 1'!S70/100 -> 0.042426535 | AY18: ='Family spending workbook 1'!T70/100 -> 0.038179695 | AZ18: ='Family spending workbook 1'!U70/100 -> 0.040970915 | BA18: ='Family spending workbook 1'!V70/100 -> 0.042121645 | ... BC18: ='Family spending workbook 1'!X70/100 -> 0.03330738 | BF18: =1-P18-AD18-AR18 -> 0.82 | BG18: =1-Q18-AE18-AS18 -> 0.82863779 | BH18: =1-R18-AF18-AT18 -> 0.74703791 | BI18: =1-S18-AG18-AU18 -> 0.75148502 | BJ18: =1-T18-AH18-AV18 -> 0.77189076 | BK18: =1-U18-AI18-AW18 -> 0.79346372 | BL18: =1-V18-AJ18-AX18 -> 0.80107393 | BM18: =1-W18-AK18-AY18 -> 0.82548174 | ... BQ18: =1-AA18-AO18-BC18 -> 0.87679426
A19: 2002 | B19: =DataA!N36 -> 74.5 | C19: =DataA!O36 -> 66.09167 | D19: =DataA!P36 -> 38.425 | E19: =DataA!Q36 -> 65.675 | F19: =$F$32*(1*B19/$B$32-P19*C19/$C$32-AD19*D19/$D$32-AR19*E19/$E$32)/(1-P19-AD19-AR19) -> 77.175481 | G19: =G20*(P19*C19/C20+AD19*D19/D20+AR19*E19/E20+BF19*F19/F20) -> 74.474908 | H19: =100*((G19/G18)-1) -> 1.0497552 | I19: =100*((B19/B18)-1) -> 1.2342837 | P19: =HAVERA!B20/1000 -> 0.115 | Q19: ='Family spending workbook 1'!Y9/100 -> 0.10520183 | R19: ='Family spending workbook 1'!O9/100 -> 0.15704853 | S19: ='Family spending workbook 1'!P9/100 -> 0.16338986 | T19: ='Family spending workbook 1'!Q9/100 -> 0.15702111 | U19: ='Family spending workbook 1'!R9/100 -> 0.12308773 | V19: ='Family spending workbook 1'!S9/100 -> 0.11976307 | W19: ='Family spending workbook 1'!T9/100 -> 0.10687917 | X19: ='Family spending workbook 1'!U9/100 -> 0.10740519 | Y19: ='Family spending workbook 1'!V9/100 -> 0.097301147 | ... AA19: ='Family spending workbook 1'!X9/100 -> 0.075718961 | AD19: =HAVERA!C20/1000 -> 0.028 | AE19: ='Family spending workbook 1'!Y40/100 -> 0.028784334 | AF19: ='Family spending workbook 1'!O40/100 -> 0.056798542 | AG19: ='Family spending workbook 1'!P40/100 -> 0.055393867 | AH19: ='Family spending workbook 1'!Q40/100 -> 0.045530941 | AI19: ='Family spending workbook 1'!R40/100 -> 0.036538901 | AJ19: ='Family spending workbook 1'!S40/100 -> 0.033104209 | AK19: ='Family spending workbook 1'!T40/100 -> 0.029968753 | AL19: ='Family spending workbook 1'!U40/100 -> 0.027078174 | AM19: ='Family spending workbook 1'!V40/100 -> 0.024760157 | ... AO19: ='Family spending workbook 1'!X40/100 -> 0.018750652 | AR19: =HAVERA!D20/1000 -> 0.028 | AS19: ='Family spending workbook 1'!Y71/100 -> 0.036521359 | AT19: ='Family spending workbook 1'!O71/100 -> 0.02195034 | AU19: ='Family spending workbook 1'!P71/100 -> 0.025403737 | AV19: ='Family spending workbook 1'!Q71/100 -> 0.029677211 | AW19: ='Family spending workbook 1'!R71/100 -> 0.036351205 | AX19: ='Family spending workbook 1'!S71/100 -> 0.036855088 | AY19: ='Family spending workbook 1'!T71/100 -> 0.038877889 | AZ19: ='Family spending workbook 1'!U71/100 -> 0.040017961 | BA19: ='Family spending workbook 1'!V71/100 -> 0.04180088 | ... BC19: ='Family spending workbook 1'!X71/100 -> 0.032584176 | BF19: =1-P19-AD19-AR19 -> 0.829 | BG19: =1-Q19-AE19-AS19 -> 0.82949248 | BH19: =1-R19-AF19-AT19 -> 0.76420259 | BI19: =1-S19-AG19-AU19 -> 0.75581254 | BJ19: =1-T19-AH19-AV19 -> 0.76777073 | BK19: =1-U19-AI19-AW19 -> 0.80402217 | BL19: =1-V19-AJ19-AX19 -> 0.81027764 | BM19: =1-W19-AK19-AY19 -> 0.82427419 | ... BQ19: =1-AA19-AO19-BC19 -> 0.87294621
A20: 2003 | B20: =DataA!N37 -> 75.525 | C20: =DataA!O37 -> 67.01667 | D20: =DataA!P37 -> 39.125 | E20: =DataA!Q37 -> 68.05 | F20: =$F$32*(1*B20/$B$32-P20*C20/$C$32-AD20*D20/$D$32-AR20*E20/$E$32)/(1-P20-AD20-AR20) -> 78.07417 | G20: =G21*(P20*C20/C21+AD20*D20/D21+AR20*E20/E21+BF20*F20/F21) -> 75.425866 | H20: =100*((G20/G19)-1) -> 1.276884 | I20: =100*((B20/B19)-1) -> 1.3758389 | P20: =HAVERA!B21/1000 -> 0.108 | Q20: ='Family spending workbook 1'!Y10/100 -> 0.10409083 | R20: ='Family spending workbook 1'!O10/100 -> 0.1532264 | S20: ='Family spending workbook 1'!P10/100 -> 0.16027044 | T20: ='Family spending workbook 1'!Q10/100 -> 0.15265657 | U20: ='Family spending workbook 1'!R10/100 -> 0.12240644 | V20: ='Family spending workbook 1'!S10/100 -> 0.11713357 | W20: ='Family spending workbook 1'!T10/100 -> 0.10866181 | X20: ='Family spending workbook 1'!U10/100 -> 0.10185856 | Y20: ='Family spending workbook 1'!V10/100 -> 0.091684736 | ... AA20: ='Family spending workbook 1'!X10/100 -> 0.074906704 | AD20: =HAVERA!C21/1000 -> 0.028 | AE20: ='Family spending workbook 1'!Y41/100 -> 0.028631137 | AF20: ='Family spending workbook 1'!O41/100 -> 0.056310083 | AG20: ='Family spending workbook 1'!P41/100 -> 0.050813824 | AH20: ='Family spending workbook 1'!Q41/100 -> 0.047442448 | AI20: ='Family spending workbook 1'!R41/100 -> 0.035665035 | AJ20: ='Family spending workbook 1'!S41/100 -> 0.032064158 | AK20: ='Family spending workbook 1'!T41/100 -> 0.029602689 | AL20: ='Family spending workbook 1'!U41/100 -> 0.026501233 | AM20: ='Family spending workbook 1'!V41/100 -> 0.023762872 | ... AO20: ='Family spending workbook 1'!X41/100 -> 0.019226402 | AR20: =HAVERA!D21/1000 -> 0.027 | AS20: ='Family spending workbook 1'!Y72/100 -> 0.035761298 | AT20: ='Family spending workbook 1'!O72/100 -> 0.024327927 | AU20: ='Family spending workbook 1'!P72/100 -> 0.024733822 | AV20: ='Family spending workbook 1'!Q72/100 -> 0.029539023 | AW20: ='Family spending workbook 1'!R72/100 -> 0.033440621 | AX20: ='Family spending workbook 1'!S72/100 -> 0.037471131 | AY20: ='Family spending workbook 1'!T72/100 -> 0.038535195 | AZ20: ='Family spending workbook 1'!U72/100 -> 0.038057991 | BA20: ='Family spending workbook 1'!V72/100 -> 0.038576037 | ... BC20: ='Family spending workbook 1'!X72/100 -> 0.034476651 | BF20: =1-P20-AD20-AR20 -> 0.837 | BG20: =1-Q20-AE20-AS20 -> 0.83151673 | BH20: =1-R20-AF20-AT20 -> 0.76613559 | BI20: =1-S20-AG20-AU20 -> 0.76418192 | BJ20: =1-T20-AH20-AV20 -> 0.77036196 | BK20: =1-U20-AI20-AW20 -> 0.8084879 | BL20: =1-V20-AJ20-AX20 -> 0.81333114 | BM20: =1-W20-AK20-AY20 -> 0.82320031 | ... BQ20: =1-AA20-AO20-BC20 -> 0.87139024
A21: 2004 | B21: =DataA!N38 -> 76.54167 | C21: =DataA!O38 -> 67.73334 | D21: =DataA!P38 -> 41.79166 | E21: =DataA!Q38 -> 71.85 | F21: =$F$32*(1*B21/$B$32-P21*C21/$C$32-AD21*D21/$D$32-AR21*E21/$E$32)/(1-P21-AD21-AR21) -> 78.860925 | G21: =G22*(P21*C21/C22+AD21*D21/D22+AR21*E21/E22+BF21*F21/F22) -> 76.396689 | H21: =100*((G21/G20)-1) -> 1.2871218 | I21: =100*((B21/B20)-1) -> 1.346137 | P21: =HAVERA!B22/1000 -> 0.106 | Q21: ='Family spending workbook 1'!Y11/100 -> 0.10297638 | R21: ='Family spending workbook 1'!O11/100 -> 0.1592675 | S21: ='Family spending workbook 1'!P11/100 -> 0.15891258 | T21: ='Family spending workbook 1'!Q11/100 -> 0.14269955 | U21: ='Family spending workbook 1'!R11/100 -> 0.11884906 | V21: ='Family spending workbook 1'!S11/100 -> 0.1165455 | W21: ='Family spending workbook 1'!T11/100 -> 0.10650418 | X21: ='Family spending workbook 1'!U11/100 -> 0.10268439 | Y21: ='Family spending workbook 1'!V11/100 -> 0.095494142 | ... AA21: ='Family spending workbook 1'!X11/100 -> 0.073741672 | AD21: =HAVERA!C22/1000 -> 0.026 | AE21: ='Family spending workbook 1'!Y42/100 -> 0.028887721 | AF21: ='Family spending workbook 1'!O42/100 -> 0.054691011 | AG21: ='Family spending workbook 1'!P42/100 -> 0.053264522 | AH21: ='Family spending workbook 1'!Q42/100 -> 0.042581598 | AI21: ='Family spending workbook 1'!R42/100 -> 0.035798322 | AJ21: ='Family spending workbook 1'!S42/100 -> 0.032498847 | AK21: ='Family spending workbook 1'!T42/100 -> 0.030185893 | AL21: ='Family spending workbook 1'!U42/100 -> 0.027068736 | AM21: ='Family spending workbook 1'!V42/100 -> 0.025582282 | ... AO21: ='Family spending workbook 1'!X42/100 -> 0.019621298 | AR21: =HAVERA!D22/1000 -> 0.026 | AS21: ='Family spending workbook 1'!Y73/100 -> 0.03725737 | AT21: ='Family spending workbook 1'!O73/100 -> 0.020871716 | AU21: ='Family spending workbook 1'!P73/100 -> 0.02630056 | AV21: ='Family spending workbook 1'!Q73/100 -> 0.032057508 | AW21: ='Family spending workbook 1'!R73/100 -> 0.034915541 | AX21: ='Family spending workbook 1'!S73/100 -> 0.036953302 | AY21: ='Family spending workbook 1'!T73/100 -> 0.039475378 | AZ21: ='Family spending workbook 1'!U73/100 -> 0.041325102 | BA21: ='Family spending workbook 1'!V73/100 -> 0.041574926 | ... BC21: ='Family spending workbook 1'!X73/100 -> 0.036026305 | BF21: =1-P21-AD21-AR21 -> 0.842 | BG21: =1-Q21-AE21-AS21 -> 0.83087853 | BH21: =1-R21-AF21-AT21 -> 0.76516977 | BI21: =1-S21-AG21-AU21 -> 0.76152234 | BJ21: =1-T21-AH21-AV21 -> 0.78266134 | BK21: =1-U21-AI21-AW21 -> 0.81043708 | BL21: =1-V21-AJ21-AX21 -> 0.81400235 | BM21: =1-W21-AK21-AY21 -> 0.82383455 | ... BQ21: =1-AA21-AO21-BC21 -> 0.87061072
A22: 2005 | B22: =DataA!N39 -> 78.1 | C22: =DataA!O39 -> 68.9 | D22: =DataA!P39 -> 47.28334 | E22: =DataA!Q39 -> 78.14166 | F22: =$F$32*(1*B22/$B$32-P22*C22/$C$32-AD22*D22/$D$32-AR22*E22/$E$32)/(1-P22-AD22-AR22) -> 80.281714 | G22: =B22 -> 78.1 | H22: =100*((G22/G21)-1) -> 2.2295613 | I22: =100*((B22/B21)-1) -> 2.0359237 | P22: =HAVERA!B23/1000 -> 0.106 | Q22: ='Family spending workbook 1'!Y12/100 -> 0.10219289 | R22: ='Family spending workbook 1'!O12/100 -> 0.1554441 | S22: ='Family spending workbook 1'!P12/100 -> 0.16474089 | T22: ='Family spending workbook 1'!Q12/100 -> 0.13221753 | U22: ='Family spending workbook 1'!R12/100 -> 0.12330339 | V22: ='Family spending workbook 1'!S12/100 -> 0.1176211 | W22: ='Family spending workbook 1'!T12/100 -> 0.1068728 | X22: ='Family spending workbook 1'!U12/100 -> 0.1047476 | Y22: ='Family spending workbook 1'!V12/100 -> 0.095866251 | ... AA22: ='Family spending workbook 1'!X12/100 -> 0.072158489 | AD22: =HAVERA!C23/1000 -> 0.028 | AE22: ='Family spending workbook 1'!Y43/100 -> 0.031301102 | AF22: ='Family spending workbook 1'!O43/100 -> 0.057790564 | AG22: ='Family spending workbook 1'!P43/100 -> 0.056381669 | AH22: ='Family spending workbook 1'!Q43/100 -> 0.046641105 | AI22: ='Family spending workbook 1'!R43/100 -> 0.041374441 | AJ22: ='Family spending workbook 1'!S43/100 -> 0.036869684 | AK22: ='Family spending workbook 1'!T43/100 -> 0.032708996 | AL22: ='Family spending workbook 1'!U43/100 -> 0.029665669 | AM22: ='Family spending workbook 1'!V43/100 -> 0.026571226 | ... AO22: ='Family spending workbook 1'!X43/100 -> 0.020565009 | AR22: =HAVERA!D23/1000 -> 0.027 | AS22: ='Family spending workbook 1'!Y74/100 -> 0.062920236 | AT22: ='Family spending workbook 1'!O74/100 -> 0.036202842 | AU22: ='Family spending workbook 1'!P74/100 -> 0.046296907 | AV22: ='Family spending workbook 1'!Q74/100 -> 0.04942166 | AW22: ='Family spending workbook 1'!R74/100 -> 0.053748211 | AX22: ='Family spending workbook 1'!S74/100 -> 0.067155425 | AY22: ='Family spending workbook 1'!T74/100 -> 0.068446557 | AZ22: ='Family spending workbook 1'!U74/100 -> 0.064355461 | BA22: ='Family spending workbook 1'!V74/100 -> 0.072610736 | ... BC22: ='Family spending workbook 1'!X74/100 -> 0.062595777 | BF22: =1-P22-AD22-AR22 -> 0.839 | BG22: =1-Q22-AE22-AS22 -> 0.80358578 | BH22: =1-R22-AF22-AT22 -> 0.7505625 | BI22: =1-S22-AG22-AU22 -> 0.73258053 | BJ22: =1-T22-AH22-AV22 -> 0.7717197 | BK22: =1-U22-AI22-AW22 -> 0.78157396 | BL22: =1-V22-AJ22-AX22 -> 0.77835379 | BM22: =1-W22-AK22-AY22 -> 0.79197165 | ... BQ22: =1-AA22-AO22-BC22 -> 0.84468072
A23: 2006 | B23: =DataA!N40 -> 79.93333 | C23: =DataA!O40 -> 70.66666 | D23: =DataA!P40 -> 58.96667 | E23: =DataA!Q40 -> 82.44167 | F23: =$F$32*(1*B23/$B$32-P23*C23/$C$32-AD23*D23/$D$32-AR23*E23/$E$32)/(1-P23-AD23-AR23) -> 81.764505 | G23: =G22*(P23*C23/C22+AD23*D23/D22+AR23*E23/E22+BF23*F23/F22) -> 80.270926 | H23: =100*((G23/G22)-1) -> 2.7796745 | I23: =100*((B23/B22)-1) -> 2.3474136 | P23: =HAVERA!B24/1000 -> 0.102 | Q23: ='Family spending workbook 1'!Y13/100 -> 0.10285063 | R23: ='Family spending workbook 1'!O13/100 -> 0.15729622 | S23: ='Family spending workbook 1'!P13/100 -> 0.15708845 | T23: ='Family spending workbook 1'!Q13/100 -> 0.13487698 | U23: ='Family spending workbook 1'!R13/100 -> 0.12053503 | V23: ='Family spending workbook 1'!S13/100 -> 0.11725278 | W23: ='Family spending workbook 1'!T13/100 -> 0.10812504 | X23: ='Family spending workbook 1'!U13/100 -> 0.10232598 | Y23: ='Family spending workbook 1'!V13/100 -> 0.097304216 | ... AA23: ='Family spending workbook 1'!X13/100 -> 0.074573905 | AD23: =HAVERA!C24/1000 -> 0.032 | AE23: ='Family spending workbook 1'!Y44/100 -> 0.034854812 | AF23: ='Family spending workbook 1'!O44/100 -> 0.065800519 | AG23: ='Family spending workbook 1'!P44/100 -> 0.062331171 | AH23: ='Family spending workbook 1'!Q44/100 -> 0.05140911 | AI23: ='Family spending workbook 1'!R44/100 -> 0.041946446 | AJ23: ='Family spending workbook 1'!S44/100 -> 0.040465447 | AK23: ='Family spending workbook 1'!T44/100 -> 0.036331291 | AL23: ='Family spending workbook 1'!U44/100 -> 0.032306615 | AM23: ='Family spending workbook 1'!V44/100 -> 0.030310467 | ... AO23: ='Family spending workbook 1'!X44/100 -> 0.02378899 | AR23: =HAVERA!D24/1000 -> 0.035 | AS23: ='Family spending workbook 1'!Y75/100 -> 0.062786832 | AT23: ='Family spending workbook 1'!O75/100 -> 0.041190967 | AU23: ='Family spending workbook 1'!P75/100 -> 0.045460325 | AV23: ='Family spending workbook 1'!Q75/100 -> 0.057382364 | AW23: ='Family spending workbook 1'!R75/100 -> 0.056518364 | AX23: ='Family spending workbook 1'!S75/100 -> 0.065682415 | AY23: ='Family spending workbook 1'!T75/100 -> 0.064615519 | AZ23: ='Family spending workbook 1'!U75/100 -> 0.066219308 | BA23: ='Family spending workbook 1'!V75/100 -> 0.068604752 | ... BC23: ='Family spending workbook 1'!X75/100 -> 0.063394792 | BF23: =1-P23-AD23-AR23 -> 0.831 | BG23: =1-Q23-AE23-AS23 -> 0.79950773 | BH23: =1-R23-AF23-AT23 -> 0.73571229 | BI23: =1-S23-AG23-AU23 -> 0.73512005 | BJ23: =1-T23-AH23-AV23 -> 0.75633155 | BK23: =1-U23-AI23-AW23 -> 0.78100016 | BL23: =1-V23-AJ23-AX23 -> 0.77659936 | BM23: =1-W23-AK23-AY23 -> 0.79092815 | ... BQ23: =1-AA23-AO23-BC23 -> 0.83824231
A24: 2007 | B24: =DataA!N41 -> 81.78333 | C24: =DataA!O41 -> 73.65833 | D24: =DataA!P41 -> 63.23333 | E24: =DataA!Q41 -> 84.83334 | F24: =$F$32*(1*B24/$B$32-P24*C24/$C$32-AD24*D24/$D$32-AR24*E24/$E$32)/(1-P24-AD24-AR24) -> 83.539699 | G24: =G23*(P24*C24/C23+AD24*D24/D23+AR24*E24/E23+BF24*F24/F23) -> 82.363854 | H24: =100*((G24/G23)-1) -> 2.6073303 | I24: =100*((B24/B23)-1) -> 2.3144288 | P24: =HAVERA!B25/1000 -> 0.103 | Q24: ='Family spending workbook 1'!Y14/100 -> 0.10480237 | R24: ='Family spending workbook 1'!O14/100 -> 0.14190576 | S24: ='Family spending workbook 1'!P14/100 -> 0.16534494 | T24: ='Family spending workbook 1'!Q14/100 -> 0.14086814 | U24: ='Family spending workbook 1'!R14/100 -> 0.12681719 | V24: ='Family spending workbook 1'!S14/100 -> 0.11953321 | W24: ='Family spending workbook 1'!T14/100 -> 0.10618105 | X24: ='Family spending workbook 1'!U14/100 -> 0.1089597 | Y24: ='Family spending workbook 1'!V14/100 -> 0.099061697 | ... AA24: ='Family spending workbook 1'!X14/100 -> 0.074074847 | AD24: =HAVERA!C25/1000 -> 0.039 | AE24: ='Family spending workbook 1'!Y45/100 -> 0.037356644 | AF24: ='Family spending workbook 1'!O45/100 -> 0.06362175 | AG24: ='Family spending workbook 1'!P45/100 -> 0.067427698 | AH24: ='Family spending workbook 1'!Q45/100 -> 0.053585002 | AI24: ='Family spending workbook 1'!R45/100 -> 0.046932899 | AJ24: ='Family spending workbook 1'!S45/100 -> 0.041630192 | AK24: ='Family spending workbook 1'!T45/100 -> 0.037691418 | AL24: ='Family spending workbook 1'!U45/100 -> 0.03704995 | AM24: ='Family spending workbook 1'!V45/100 -> 0.032595608 | ... AO24: ='Family spending workbook 1'!X45/100 -> 0.025559063 | AR24: =HAVERA!D25/1000 -> 0.036 | AS24: ='Family spending workbook 1'!Y76/100 -> 0.0398612 | AT24: ='Family spending workbook 1'!O76/100 -> 0.026784808 | AU24: ='Family spending workbook 1'!P76/100 -> 0.026966063 | AV24: ='Family spending workbook 1'!Q76/100 -> 0.033473822 | AW24: ='Family spending workbook 1'!R76/100 -> 0.039060926 | AX24: ='Family spending workbook 1'!S76/100 -> 0.042117341 | AY24: ='Family spending workbook 1'!T76/100 -> 0.04489631 | AZ24: ='Family spending workbook 1'!U76/100 -> 0.049051951 | BA24: ='Family spending workbook 1'!V76/100 -> 0.044105874 | ... BC24: ='Family spending workbook 1'!X76/100 -> 0.034214148 | BF24: =1-P24-AD24-AR24 -> 0.822 | BG24: =1-Q24-AE24-AS24 -> 0.81797979 | BH24: =1-R24-AF24-AT24 -> 0.76768768 | BI24: =1-S24-AG24-AU24 -> 0.7402613 | BJ24: =1-T24-AH24-AV24 -> 0.77207304 | BK24: =1-U24-AI24-AW24 -> 0.78718899 | BL24: =1-V24-AJ24-AX24 -> 0.79671925 | BM24: =1-W24-AK24-AY24 -> 0.81123123 | ... BQ24: =1-AA24-AO24-BC24 -> 0.86615194
A25: 2008 | B25: =DataA!N42 -> 84.725 | C25: =DataA!O42 -> 79.225 | D25: =DataA!P42 -> 74.93333 | E25: =DataA!Q42 -> 97.42498 | F25: =$F$32*(1*B25/$B$32-P25*C25/$C$32-AD25*D25/$D$32-AR25*E25/$E$32)/(1-P25-AD25-AR25) -> 85.278271 | G25: =G24*(P25*C25/C24+AD25*D25/D24+AR25*E25/E24+BF25*F25/F24) -> 85.442411 | H25: =100*((G25/G24)-1) -> 3.737753 | I25: =100*((B25/B24)-1) -> 3.5969066 | P25: =HAVERA!B26/1000 -> 0.109 | Q25: ='Family spending workbook 1'!Y15/100 -> 0.10764331 | R25: ='Family spending workbook 1'!O15/100 -> 0.17176318 | S25: ='Family spending workbook 1'!P15/100 -> 0.165 | T25: ='Family spending workbook 1'!Q15/100 -> 0.14741346 | U25: ='Family spending workbook 1'!R15/100 -> 0.13238413 | V25: ='Family spending workbook 1'!S15/100 -> 0.12748092 | W25: ='Family spending workbook 1'!T15/100 -> 0.11345819 | X25: ='Family spending workbook 1'!U15/100 -> 0.10285075 | Y25: ='Family spending workbook 1'!V15/100 -> 0.10132651 | ... AA25: ='Family spending workbook 1'!X15/100 -> 0.075988133 | AD25: =HAVERA!C26/1000 -> 0.035 | AE25: ='Family spending workbook 1'!Y46/100 -> 0.040127389 | AF25: ='Family spending workbook 1'!O46/100 -> 0.083929733 | AG25: ='Family spending workbook 1'!P46/100 -> 0.0735 | AH25: ='Family spending workbook 1'!Q46/100 -> 0.060676779 | AI25: ='Family spending workbook 1'!R46/100 -> 0.052105423 | AJ25: ='Family spending workbook 1'!S46/100 -> 0.044783715 | AK25: ='Family spending workbook 1'!T46/100 -> 0.040940767 | AL25: ='Family spending workbook 1'!U46/100 -> 0.037078442 | AM25: ='Family spending workbook 1'!V46/100 -> 0.03356241 | ... AO25: ='Family spending workbook 1'!X46/100 -> 0.027466743 | AR25: =HAVERA!D26/1000 -> 0.038 | AS25: ='Family spending workbook 1'!Y77/100 -> 0.044585987 | AT25: ='Family spending workbook 1'!O77/100 -> 0.026024723 | AU25: ='Family spending workbook 1'!P77/100 -> 0.0285 | AV25: ='Family spending workbook 1'!Q77/100 -> 0.036172695 | AW25: ='Family spending workbook 1'!R77/100 -> 0.042714329 | AX25: ='Family spending workbook 1'!S77/100 -> 0.047328244 | AY25: ='Family spending workbook 1'!T77/100 -> 0.046385017 | AZ25: ='Family spending workbook 1'!U77/100 -> 0.048071548 | BA25: ='Family spending workbook 1'!V77/100 -> 0.048106121 | ... BC25: ='Family spending workbook 1'!X77/100 -> 0.042970619 | BF25: =1-P25-AD25-AR25 -> 0.818 | BG25: =1-Q25-AE25-AS25 -> 0.80764331 | BH25: =1-R25-AF25-AT25 -> 0.71828237 | BI25: =1-S25-AG25-AU25 -> 0.733 | BJ25: =1-T25-AH25-AV25 -> 0.75573707 | BK25: =1-U25-AI25-AW25 -> 0.77279612 | BL25: =1-V25-AJ25-AX25 -> 0.78040712 | BM25: =1-W25-AK25-AY25 -> 0.79921603 | ... BQ25: =1-AA25-AO25-BC25 -> 0.8535745
A26: 2009 | B26: =DataA!N43 -> 86.575 | C26: =DataA!O43 -> 83.325 | D26: =DataA!P43 -> 80.14167 | E26: =DataA!Q43 -> 89.79167 | F26: =$F$32*(1*B26/$B$32-P26*C26/$C$32-AD26*D26/$D$32-AR26*E26/$E$32)/(1-P26-AD26-AR26) -> 87.276845 | G26: =G25*(P26*C26/C25+AD26*D26/D25+AR26*E26/E25+BF26*F26/F25) -> 87.615692 | H26: =100*((G26/G25)-1) -> 2.5435621 | I26: =100*((B26/B25)-1) -> 2.183535 | P26: =HAVERA!B27/1000 -> 0.118 | Q26: ='Family spending workbook 1'!Y16/100 -> 0.11472527 | R26: ='Family spending workbook 1'!O16/100 -> 0.15918869 | S26: ='Family spending workbook 1'!P16/100 -> 0.16050538 | T26: ='Family spending workbook 1'!Q16/100 -> 0.14926968 | U26: ='Family spending workbook 1'!R16/100 -> 0.13155529 | V26: ='Family spending workbook 1'!S16/100 -> 0.13120291 | W26: ='Family spending workbook 1'!T16/100 -> 0.12042367 | X26: ='Family spending workbook 1'!U16/100 -> 0.11488511 | Y26: ='Family spending workbook 1'!V16/100 -> 0.11149346 | ... AA26: ='Family spending workbook 1'!X16/100 -> 0.082048181 | AD26: =HAVERA!C27/1000 -> 0.046 | AE26: ='Family spending workbook 1'!Y47/100 -> 0.046813187 | AF26: ='Family spending workbook 1'!O47/100 -> 0.085433313 | AG26: ='Family spending workbook 1'!P47/100 -> 0.076275152 | AH26: ='Family spending workbook 1'!Q47/100 -> 0.063769149 | AI26: ='Family spending workbook 1'!R47/100 -> 0.058435721 | AJ26: ='Family spending workbook 1'!S47/100 -> 0.051182125 | AK26: ='Family spending workbook 1'!T47/100 -> 0.048583928 | AL26: ='Family spending workbook 1'!U47/100 -> 0.046753247 | AM26: ='Family spending workbook 1'!V47/100 -> 0.043358568 | ... AO26: ='Family spending workbook 1'!X47/100 -> 0.029936498 | AR26: =HAVERA!D27/1000 -> 0.034 | AS26: ='Family spending workbook 1'!Y78/100 -> 0.042197802 | AT26: ='Family spending workbook 1'!O78/100 -> 0.028887523 | AU26: ='Family spending workbook 1'!P78/100 -> 0.02620496 | AV26: ='Family spending workbook 1'!Q78/100 -> 0.03526897 | AW26: ='Family spending workbook 1'!R78/100 -> 0.040155829 | AX26: ='Family spending workbook 1'!S78/100 -> 0.041829047 | AY26: ='Family spending workbook 1'!T78/100 -> 0.046511628 | AZ26: ='Family spending workbook 1'!U78/100 -> 0.045754246 | BA26: ='Family spending workbook 1'!V78/100 -> 0.051445286 | ... BC26: ='Family spending workbook 1'!X78/100 -> 0.035883479 | BF26: =1-P26-AD26-AR26 -> 0.802 | BG26: =1-Q26-AE26-AS26 -> 0.79626374 | BH26: =1-R26-AF26-AT26 -> 0.72649047 | BI26: =1-S26-AG26-AU26 -> 0.73701451 | BJ26: =1-T26-AH26-AV26 -> 0.7516922 | BK26: =1-U26-AI26-AW26 -> 0.76985316 | BL26: =1-V26-AJ26-AX26 -> 0.77578592 | BM26: =1-W26-AK26-AY26 -> 0.78448077 | ... BQ26: =1-AA26-AO26-BC26 -> 0.85213184
A27: 2010 | B27: =DataA!N44 -> 89.43333 | C27: =DataA!O44 -> 86.625 | D27: =DataA!P44 -> 77.90834 | E27: =DataA!Q44 -> 104.8167 | F27: =$F$32*(1*B27/$B$32-P27*C27/$C$32-AD27*D27/$D$32-AR27*E27/$E$32)/(1-P27-AD27-AR27) -> 89.690583 | G27: =G26*(P27*C27/C26+AD27*D27/D26+AR27*E27/E26+BF27*F27/F26) -> 90.424967 | H27: =100*((G27/G26)-1) -> 3.2063603 | I27: =100*((B27/B26)-1) -> 3.3015651 | P27: =HAVERA!B28/1000 -> 0.108 | Q27: ='Family spending workbook 1'!Y17/100 -> 0.11233108 | R27: ='Family spending workbook 1'!O17/100 -> 0.14655172 | S27: ='Family spending workbook 1'!P17/100 -> 0.16061453 | T27: ='Family spending workbook 1'!Q17/100 -> 0.14668133 | U27: ='Family spending workbook 1'!R17/100 -> 0.13385598 | V27: ='Family spending workbook 1'!S17/100 -> 0.12675 | W27: ='Family spending workbook 1'!T17/100 -> 0.11857018 | X27: ='Family spending workbook 1'!U17/100 -> 0.11462451 | Y27: ='Family spending workbook 1'!V17/100 -> 0.10358835 | ... AA27: ='Family spending workbook 1'!X17/100 -> 0.081885125 | AD27: =HAVERA!C28/1000 -> 0.047 | AE27: ='Family spending workbook 1'!Y48/100 -> 0.045185811 | AF27: ='Family spending workbook 1'!O48/100 -> 0.072737069 | AG27: ='Family spending workbook 1'!P48/100 -> 0.079608939 | AH27: ='Family spending workbook 1'!Q48/100 -> 0.068573524 | AI27: ='Family spending workbook 1'!R48/100 -> 0.055168409 | AJ27: ='Family spending workbook 1'!S48/100 -> 0.05175 | AK27: ='Family spending workbook 1'!T48/100 -> 0.047515257 | AL27: ='Family spending workbook 1'!U48/100 -> 0.04197252 | AM27: ='Family spending workbook 1'!V48/100 -> 0.03943805 | ... AO27: ='Family spending workbook 1'!X48/100 -> 0.030927835 | AR27: =HAVERA!D28/1000 -> 0.041 | AS27: ='Family spending workbook 1'!Y79/100 -> 0.045608108 | AT27: ='Family spending workbook 1'!O79/100 -> 0.030711207 | AU27: ='Family spending workbook 1'!P79/100 -> 0.036312849 | AV27: ='Family spending workbook 1'!Q79/100 -> 0.036670334 | AW27: ='Family spending workbook 1'!R79/100 -> 0.041521487 | AX27: ='Family spending workbook 1'!S79/100 -> 0.047 | AY27: ='Family spending workbook 1'!T79/100 -> 0.049476896 | AZ27: ='Family spending workbook 1'!U79/100 -> 0.050065876 | BA27: ='Family spending workbook 1'!V79/100 -> 0.051963439 | ... BC27: ='Family spending workbook 1'!X79/100 -> 0.041531664 | BF27: =1-P27-AD27-AR27 -> 0.804 | BG27: =1-Q27-AE27-AS27 -> 0.796875 | BH27: =1-R27-AF27-AT27 -> 0.75 | BI27: =1-S27-AG27-AU27 -> 0.72346369 | BJ27: =1-T27-AH27-AV27 -> 0.74807481 | BK27: =1-U27-AI27-AW27 -> 0.76945412 | BL27: =1-V27-AJ27-AX27 -> 0.7745 | BM27: =1-W27-AK27-AY27 -> 0.78443766 | ... BQ27: =1-AA27-AO27-BC27 -> 0.84565538
A28: 2011 | B28: =DataA!N45 -> 93.425 | C28: =DataA!O45 -> 92.10001 | D28: =DataA!P45 -> 85.66666 | E28: =DataA!Q45 -> 120.1917 | F28: =$F$32*(1*B28/$B$32-P28*C28/$C$32-AD28*D28/$D$32-AR28*E28/$E$32)/(1-P28-AD28-AR28) -> 92.593543 | G28: =G27*(P28*C28/C27+AD28*D28/D27+AR28*E28/E27+BF28*F28/F27) -> 94.392667 | H28: =100*((G28/G27)-1) -> 4.3878374 | I28: =100*((B28/B27)-1) -> 4.4632913 | P28: =HAVERA!B29/1000 -> 0.118 | Q28: ='Family spending workbook 1'!Y18/100 -> 0.11331679 | R28: ='Family spending workbook 1'!O18/100 -> 0.1648786 | S28: ='Family spending workbook 1'!P18/100 -> 0.15503876 | T28: ='Family spending workbook 1'!Q18/100 -> 0.14006849 | U28: ='Family spending workbook 1'!R18/100 -> 0.13803767 | V28: ='Family spending workbook 1'!S18/100 -> 0.13193439 | W28: ='Family spending workbook 1'!T18/100 -> 0.11544133 | X28: ='Family spending workbook 1'!U18/100 -> 0.11259755 | Y28: ='Family spending workbook 1'!V18/100 -> 0.108867 | ... AA28: ='Family spending workbook 1'!X18/100 -> 0.083943774 | AD28: =HAVERA!C29/1000 -> 0.044 | AE28: ='Family spending workbook 1'!Y49/100 -> 0.045698925 | AF28: ='Family spending workbook 1'!O49/100 -> 0.078486731 | AG28: ='Family spending workbook 1'!P49/100 -> 0.075695394 | AH28: ='Family spending workbook 1'!Q49/100 -> 0.062328767 | AI28: ='Family spending workbook 1'!R49/100 -> 0.057070565 | AJ28: ='Family spending workbook 1'!S49/100 -> 0.053545586 | AK28: ='Family spending workbook 1'!T49/100 -> 0.047819676 | AL28: ='Family spending workbook 1'!U49/100 -> 0.044221479 | AM28: ='Family spending workbook 1'!V49/100 -> 0.040394089 | ... AO28: ='Family spending workbook 1'!X49/100 -> 0.031379925 | AR28: =HAVERA!D29/1000 -> 0.043 | AS28: ='Family spending workbook 1'!Y80/100 -> 0.051488834 | AT28: ='Family spending workbook 1'!O80/100 -> 0.028232637 | AU28: ='Family spending workbook 1'!P80/100 -> 0.036023712 | AV28: ='Family spending workbook 1'!Q80/100 -> 0.040068493 | AW28: ='Family spending workbook 1'!R80/100 -> 0.048636491 | AX28: ='Family spending workbook 1'!S80/100 -> 0.051374819 | AY28: ='Family spending workbook 1'!T80/100 -> 0.054771435 | AZ28: ='Family spending workbook 1'!U80/100 -> 0.057413601 | BA28: ='Family spending workbook 1'!V80/100 -> 0.05862069 | ... BC28: ='Family spending workbook 1'!X80/100 -> 0.049000198 | BF28: =1-P28-AD28-AR28 -> 0.795 | BG28: =1-Q28-AE28-AS28 -> 0.78949545 | BH28: =1-R28-AF28-AT28 -> 0.72840203 | BI28: =1-S28-AG28-AU28 -> 0.73324213 | BJ28: =1-T28-AH28-AV28 -> 0.75753425 | BK28: =1-U28-AI28-AW28 -> 0.75625527 | BL28: =1-V28-AJ28-AX28 -> 0.7631452 | BM28: =1-W28-AK28-AY28 -> 0.78196756 | ... BQ28: =1-AA28-AO28-BC28 -> 0.8356761
