Workbook
Name _DLX1.INC: HAVERQ!$D$1:$AD$6
Name Data: [1]sheet0!$C$2

Sheet CHARTS>>

Sheet DATA>>

Sheet Chart Data
A1: AE debt dynamics (2026-2030) | W1: Budget deficit in 2025 | AF1: Gross government debt in 2025 | AO1: Government net debt in 2025 | AX1: Budget deficit & debt | BG1: GG net debt | BK1: Term premium | BQ1: Inflation | CF1: Debt interest payments | CJ1: OBR forecasts - GNDBT% | DB1: OBR forecasts - PSNBX% | DT1: Output per worker long-term (5yr ma)
B2: =DataA!BK2 -> UK | C2: =DataA!BL2 -> US | D2: =DataA!BM2 -> Japan | E2: =DataA!BN2 -> Canada | F2: =DataA!BO2 -> Australia | G2: =DataA!BP2 -> Denmark | H2: =DataA!BQ2 -> Sweden | I2: =DataA!BR2 -> Switzerland | ... U2: =DataA!CD2 -> Portugal | X2: =RANK(X4,$X$4:$AD$4) -> 5 | Y2: =RANK(Y4,$X$4:$AD$4) -> 7 | Z2: =RANK(Z4,$X$4:$AD$4) -> 2 | AA2: =RANK(AA4,$X$4:$AD$4) -> 3 | AB2: =RANK(AB4,$X$4:$AD$4) -> 6 | AC2: =RANK(AC4,$X$4:$AD$4) -> 4 | AD2: =RANK(AD4,$X$4:$AD$4) -> 1 | AG2: =RANK(AG4,$AG$4:$AM$4) -> 6 | AH2: =RANK(AH4,$AG$4:$AM$4) -> 3 | AI2: =RANK(AI4,$AG$4:$AM$4) -> 1 | AJ2: =RANK(AJ4,$AG$4:$AM$4) -> 7 | AK2: =RANK(AK4,$AG$4:$AM$4) -> 4 | AL2: =RANK(AL4,$AG$4:$AM$4) -> 2 | AM2: =RANK(AM4,$AG$4:$AM$4) -> 5 | AP2: =RANK(AP4,$AP$4:$AV$4) -> 3 | AQ2: =RANK(AQ4,$AP$4:$AV$4) -> 2 | AR2: =RANK(AR4,$AP$4:$AV$4) -> 4 | AS2: =RANK(AS4,$AP$4:$AV$4) -> 6 | AT2: =RANK(AT4,$AP$4:$AV$4) -> 5 | AU2: =RANK(AU4,$AP$4:$AV$4) -> 1 | AV2: =RANK(AV4,$AP$4:$AV$4) -> 7 | AX2: 2026 | AY2: =X3&", "&$AX2 -> UK, 2026 | AZ2: =Y3&", "&$AX2 -> US, 2026 | BA2: =Z3&", "&$AX2 -> Japan, 2026 | BB2: =AA3&", "&$AX2 -> Germany, 2026 | BC2: =AB3&", "&$AX2 -> France, 2026 | BD2: =AC3&", "&$AX2 -> Italy, 2026 | BE2: =AD3&", "&$AX2 -> Canada, 2026 | BH2: GNDBT% | BI2: GNDBT% (from GEM) | BL2: UK | BM2: US | BN2: Germany | BO2: Japan | BR2: UK | BS2: G7 median | BT2: Bottom | BU2: Range of G7 exc. UK | BX2: UK | BY2: US | BZ2: Japan | CA2: Germany | CB2: France | CC2: Italy | CD2: Canada | CG2: % of government revenue | CH2: % of GDP | CK2: 2015 | CL2: 2016 | CM2: 2017 | CN2: 2018 | CO2: 2019 | CP2: 2020 | CQ2: 2021 | CR2: 2022 | CS2: 2023 | CT2: 2024 | CU2: 2025 | CV2: 2026 | CW2: 2027 | CX2: 2028 | CY2: 2029 | CZ2: 2030 | DC2: 2015 | DD2: 2016 | DE2: 2017 | DF2: 2018 | DG2: 2019 | DH2: 2020 | DI2: 2021 | DJ2: 2022 | DK2: 2023 | DL2: 2024 | DM2: 2025 | DN2: 2026 | DO2: 2027 | DP2: 2028 | DQ2: 2029 | DR2: 2030 | DU2: 5-year moving average | DV2: 10-year moving average | DW2: 1980-2007 average | DX2: 2008-2019 average | EA2: Pre-GFC trend calc | ED2: GFC-pandemic | EG2: Pandemic-now
A3: Expected effective interest rates on government debt (r) | B3: =AVERAGE(DataA!BK60:BK64) -> 4.3075818 | C3: =AVERAGE(DataA!BL60:BL64) -> 3.5375515 | D3: =AVERAGE(DataA!BM60:BM64) -> 1.0687388 | E3: =AVERAGE(DataA!BN60:BN64) -> 3.0697351 | F3: =AVERAGE(DataA!BO60:BO64) -> 2.7182818 | G3: =AVERAGE(DataA!BP60:BP64) -> 2.7025818 | H3: =AVERAGE(DataA!BQ60:BQ64) -> 1.4191454 | I3: =AVERAGE(DataA!BR60:BR64) -> 1.1865096 | ... U3: =AVERAGE(DataA!CD60:CD64) -> 2.2694908 | X3: UK | Y3: US | Z3: Japan | AA3: Germany | AB3: France | AC3: Italy | AD3: Canada | AG3: UK | AH3: US | AI3: Japan | AJ3: Germany | AK3: France | AL3: Italy | AM3: Canada | AP3: UK | AQ3: US | AR3: Japan | AS3: Germany | AT3: France | AU3: Italy | AV3: Canada | AY3: =X3 -> UK | AZ3: =Y3 -> US | BA3: =Z3 -> Japan | BB3: =AA3 -> Germany | BC3: =AB3 -> France | BD3: =AC3 -> Italy | BE3: =AD3 -> Canada | BG3: 1980 | BH3: =100*(SUMIF(HAVERQ!$B:$B,'Chart Data'!$BG3,HAVERQ!L:L)/SUMIF(HAVERQ!$A:$A,'Chart Data'!$BG3,HAVERQ!G:G)) -> 42.727615 | BI3: =100*('Data Q to A'!AK15/'Data Q to A'!AL15) -> 32.060879 | BK3: 43831 | BL3: =DataQ!AQ195 -> -1.400203 | BM3: =DataQ!AR195 -> -1.270818 | BN3: =DataQ!AS195 -> -1.554241 | BO3: =DataQ!AT195 -> -0.4589267 | BQ3: 2020 | BR3: =BX3 -> 1.6557638 | BS3: =MEDIAN(BX3:CD3) -> 1.5192134 | BT3: =MIN(BY3:CD3) -> 0.2790036 | BU3: =MAX(BY3:CD3)-BT3 -> 1.8647638 | BW3: 2020 | BX3: =100*((DataQ!AU195/DataQ!AU191)-1) -> 1.6557638 | BY3: =100*((DataQ!AV195/DataQ!AV191)-1) -> 2.1437674 | BZ3: =100*((DataQ!AW195/DataQ!AW191)-1) -> 0.66870612 | CA3: =100*((DataQ!AX195/DataQ!AX191)-1) -> 1.5192134 | CB3: =100*((DataQ!AY195/DataQ!AY191)-1) -> 1.1940649 | CC3: =100*((DataQ!AZ195/DataQ!AZ191)-1) -> 0.2790036 | CD3: =100*((DataQ!BA195/DataQ!BA191)-1) -> 1.8060865 | CF3: 1960 | CG3: =OBR_MAR26_C4.6!C30 -> 9.9517559 | CH3: =OBR_MAR26_C4.6!D30 -> 3.3290797 | CJ3: History | CK3: {=TRANSPOSE('OBR Agg (per cent of GDP)'!X72:X82)} -> 80.586366 | CL3: 82.708697 | CM3: 81.606768 | CN3: 79.644006 | CO3: 84.499793 | CP3: 95.381028 | CQ3: 94.313911 | CR3: 93.21417 | CS3: 94.1 | CT3: 93.2 | CU3: 93.8 | DB3: History | DC3: {=TRANSPOSE('OBR Agg (per cent of GDP)'!O72:O82)} -> 4.1512226 | DD3: 2.8199641 | DE3: 2.8034391 | DF3: 2.0233908 | DG3: 2.5789127 | DH3: 14.738132 | DI3: 5.0083361 | DJ3: 4.8346149 | DK3: 4.8376726 | DL3: 5.1732984 | DM3: 4.3221745 | DT3: 1960 | DZ3: 1980 | EA3: =AVERAGE(HAVERQ!J87:J90) -> 50.2 | EC3: 2007 | ED3: =AVERAGE(HAVERQ!J195:J198) -> 92.975 | EF3: 2019 | EG3: =AVERAGE(HAVERQ!J243:J246) -> 96.725
A4: Expected annual average nominal GDP growth (g) | B4: =100*((DataA!AP64/DataA!AP59)^(1/5)-1) -> 3.6166959 | C4: =100*((DataA!AQ64/DataA!AQ59)^(1/5)-1) -> 4.6423722 | D4: =100*((DataA!AR64/DataA!AR59)^(1/5)-1) -> 1.9108873 | E4: =100*((DataA!AS64/DataA!AS59)^(1/5)-1) -> 3.6692556 | F4: =100*((DataA!AT64/DataA!AT59)^(1/5)-1) -> 4.7650898 | G4: =100*((DataA!AU64/DataA!AU59)^(1/5)-1) -> 3.5404453 | H4: =100*((DataA!AV64/DataA!AV59)^(1/5)-1) -> 4.0334553 | I4: =100*((DataA!AW64/DataA!AW59)^(1/5)-1) -> 2.2351676 | ... U4: =100*((DataA!BI64/DataA!BI59)^(1/5)-1) -> 3.6953333 | W4: 2025 | X4: =100*('Data Q to A'!I60/'Data Q to A'!AD60) -> -4.9571948 | Y4: =100*('Data Q to A'!J60/'Data Q to A'!AE60) -> -7.4069828 | Z4: =100*('Data Q to A'!K60/'Data Q to A'!AF60) -> -1.842392 | AA4: =100*('Data Q to A'!L60/'Data Q to A'!AG60) -> -2.7607817 | AB4: =100*('Data Q to A'!M60/'Data Q to A'!AH60) -> -5.110621 | AC4: =100*('Data Q to A'!N60/'Data Q to A'!AI60) -> -3.0729095 | AD4: =100*('Data Q to A'!O60/'Data Q to A'!AJ60) -> -0.76203518 | AF4: 2025 | AG4: =100*(HAVERQ!K270/SUM(HAVERQ!$G$267:$G$270)) -> 102.3143 | AH4: =100*('Data Q to A'!Q60/'Data Q to A'!AE60) -> 137.36076 | AI4: =100*('Data Q to A'!R60/'Data Q to A'!AF60) -> 205.18095 | AJ4: =100*('Data Q to A'!S60/'Data Q to A'!AG60) -> 59.442747 | AK4: =100*('Data Q to A'!T60/'Data Q to A'!AH60) -> 124.09208 | AL4: =100*('Data Q to A'!U60/'Data Q to A'!AI60) -> 149.35996 | AM4: =100*('Data Q to A'!V60/'Data Q to A'!AJ60) -> 107.47438 | AO4: 2025 | AP4: =100*(HAVERQ!L270/SUM(HAVERQ!$G$267:$G$270)) -> 93.846256 | AQ4: =100*('Data Q to A'!X60/'Data Q to A'!AE60) -> 101.74622 | AR4: =100*('Data Q to A'!Y60/'Data Q to A'!AF60) -> 87.280865 | AS4: =100*('Data Q to A'!Z60/'Data Q to A'!AG60) -> 21.998883 | AT4: =100*('Data Q to A'!AA60/'Data Q to A'!AH60) -> 76.159851 | AU4: =100*('Data Q to A'!AB60/'Data Q to A'!AI60) -> 124.67013 | AV4: =100*('Data Q to A'!AC60/'Data Q to A'!AJ60) -> 8.3304342 | AX4: Budget deficit | AY4: =X4 -> -4.9571948 | AZ4: =Y4 -> -7.4069828 | BA4: =Z4 -> -1.842392 | BB4: =AA4 -> -2.7607817 | BC4: =AB4 -> -5.110621 | BD4: =AC4 -> -3.0729095 | BE4: =AD4 -> -0.76203518 | BG4: 1981 | BH4: =100*(SUMIF(HAVERQ!$B:$B,'Chart Data'!$BG4,HAVERQ!L:L)/SUMIF(HAVERQ!$A:$A,'Chart Data'!$BG4,HAVERQ!G:G)) -> 41.888487 | BI4: =100*('Data Q to A'!AK16/'Data Q to A'!AL16) -> 31.659426 | BK4: 43922 | BL4: =DataQ!AQ196 -> -0.4742025 | BM4: =DataQ!AR196 -> -1.328421 | BN4: =DataQ!AS196 -> -1.170631 | BO4: =DataQ!AT196 -> -0.3453717 | BR4: =BX4 -> 0.68024119 | BS4: =MEDIAN(BX4:CD4) -> 0.2935571 | BT4: =MIN(BY4:CD4) -> -0.15866324 | BU4: =MAX(BY4:CD4)-BT4 -> 0.99678261 | BX4: =100*((DataQ!AU196/DataQ!AU192)-1) -> 0.68024119 | BY4: =100*((DataQ!AV196/DataQ!AV192)-1) -> 0.40928934 | BZ4: =100*((DataQ!AW196/DataQ!AW192)-1) -> 0.13345898 | CA4: =100*((DataQ!AX196/DataQ!AX192)-1) -> 0.83811937 | CB4: =100*((DataQ!AY196/DataQ!AY192)-1) -> 0.2935571 | CC4: =100*((DataQ!AZ196/DataQ!AZ192)-1) -> -0.15866324 | CD4: =100*((DataQ!BA196/DataQ!BA192)-1) -> 0 | CF4: 1961 | CG4: =OBR_MAR26_C4.6!C31 -> 9.509018 | CH4: =OBR_MAR26_C4.6!D31 -> 3.3715849 | CJ4: Latest | CT4: =[2]TA.9!C26 -> 93.161363 | CU4: =[2]TA.9!D26 -> 94.309904 | CV4: =[2]TA.9!E26 -> 94.814987 | CW4: =[2]TA.9!F26 -> 95.738708 | CX4: =[2]TA.9!G26 -> 96.281069 | CY4: =[2]TA.9!H26 -> 96.065091 | CZ4: =[2]TA.9!I26 -> 95.050964 | DB4: Latest | DL4: =[2]TA.9!C17 -> 5.2058932 | DM4: =[2]TA.9!D17 -> 4.3453219 | DN4: =[2]TA.9!E17 -> 3.6491378 | DO4: =[2]TA.9!F17 -> 2.9437631 | DP4: =[2]TA.9!G17 -> 2.5367168 | DQ4: =[2]TA.9!H17 -> 1.8080768 | DR4: =[2]TA.9!I17 -> 1.625073 | DZ4: 2007 | EA4: =AVERAGE(HAVERQ!J195:J198) -> 92.975 | EC4: 2019 | ED4: =AVERAGE(HAVERQ!J243:J246) -> 96.725 | EF4: 2025 | EG4: =AVERAGE(HAVERQ!J265:J268) -> 99.25
AX5: Government debt | AY5: =AG4 -> 102.3143 | AZ5: =AH4 -> 137.36076 | BA5: =AI4 -> 205.18095 | BB5: =AJ4 -> 59.442747 | BC5: =AK4 -> 124.09208 | BD5: =AL4 -> 149.35996 | BE5: =AM4 -> 107.47438 | BG5: 1982 | BH5: =100*(SUMIF(HAVERQ!$B:$B,'Chart Data'!$BG5,HAVERQ!L:L)/SUMIF(HAVERQ!$A:$A,'Chart Data'!$BG5,HAVERQ!G:G)) -> 40.429295 | BI5: =100*('Data Q to A'!AK17/'Data Q to A'!AL17) -> 32.149926 | BK5: 44013 | BL5: =DataQ!AQ197 -> 0.2480247 | BM5: =DataQ!AR197 -> -1.259258 | BN5: =DataQ!AS197 -> -1.146578 | BO5: =DataQ!AT197 -> -0.205531 | BR5: =BX5 -> 0.61570178 | BS5: =MEDIAN(BX5:CD5) -> 0.31774619 | BT5: =MIN(BY5:CD5) -> -0.47543584 | BU5: =MAX(BY5:CD5)-BT5 -> 1.6986029 | BX5: =100*((DataQ!AU197/DataQ!AU193)-1) -> 0.61570178 | BY5: =100*((DataQ!AV197/DataQ!AV193)-1) -> 1.2231671 | BZ5: =100*((DataQ!AW197/DataQ!AW193)-1) -> 0.033341113 | CA5: =100*((DataQ!AX197/DataQ!AX193)-1) -> -0.033441474 | CB5: =100*((DataQ!AY197/DataQ!AY193)-1) -> 0.3469545 | CC5: =100*((DataQ!AZ197/DataQ!AZ193)-1) -> -0.47543584 | CD5: =100*((DataQ!BA197/DataQ!BA193)-1) -> 0.31774619 | CF5: 1962 | CG5: =OBR_MAR26_C4.6!C32 -> 8.9482247 | CH5: =OBR_MAR26_C4.6!D32 -> 3.1741182 | CJ5: 45931 | CT5: =[3]TA.9!C26 -> 93.621758 | CU5: =[3]TA.9!D26 -> 95.026166 | CV5: =[3]TA.9!E26 -> 95.296185 | CW5: =[3]TA.9!F26 -> 96.346622 | CX5: =[3]TA.9!G26 -> 96.987821 | CY5: =[3]TA.9!H26 -> 96.835817 | CZ5: =[3]TA.9!I26 -> 96.06548 | DB5: 45931 | DL5: =[3]TA.9!C17 -> 5.106433 | DM5: =[3]TA.9!D17 -> 4.5440104 | DN5: =[3]TA.9!E17 -> 3.5417875 | DO5: =[3]TA.9!F17 -> 3.0043702 | DP5: =[3]TA.9!G17 -> 2.5657879 | DQ5: =[3]TA.9!H17 -> 1.9368629 | DR5: =[3]TA.9!I17 -> 1.8510844 | DZ5: y/y | EA5: =100*((EA4/EA3)^(1/27)-1) -> 2.3089022 | EC5: y/y | ED5: =100*((ED4/ED3)^(1/12)-1) -> 0.33005399 | EF5: y/y | EG5: =100*((EG4/EG3)^(4/23)-1) -> 0.44918005
X6: 1 | Y6: 2 | Z6: 3 | AA6: 4 | AB6: 5 | AC6: 6 | AD6: 7 | AG6: 1 | AH6: 2 | AI6: 3 | AJ6: 4 | AK6: 5 | AL6: 6 | AM6: 7 | AP6: 1 | AQ6: 2 | AR6: 3 | AS6: 4 | AT6: 5 | AU6: 6 | AV6: 7 | BG6: 1983 | BH6: =100*(SUMIF(HAVERQ!$B:$B,'Chart Data'!$BG6,HAVERQ!L:L)/SUMIF(HAVERQ!$A:$A,'Chart Data'!$BG6,HAVERQ!G:G)) -> 40.028701 | BI6: =100*('Data Q to A'!AK18/'Data Q to A'!AL18) -> 26.707127 | BK6: 44105 | BL6: =DataQ!AQ198 -> 0.7901152 | BM6: =DataQ!AR198 -> -0.9656042 | BN6: =DataQ!AS198 -> -1.126168 | BO6: =DataQ!AT198 -> -0.06359368 | BR6: =BX6 -> 0.5841379 | BS6: =MEDIAN(BX6:CD6) -> 0.08475497 | BT6: =MIN(BY6:CD6) -> -0.9290342 | BU6: =MAX(BY6:CD6)-BT6 -> 2.1713177 | BX6: =100*((DataQ!AU198/DataQ!AU194)-1) -> 0.5841379 | BY6: =100*((DataQ!AV198/DataQ!AV194)-1) -> 1.2422835 | BZ6: =100*((DataQ!AW198/DataQ!AW194)-1) -> -0.9290342 | CA6: =100*((DataQ!AX198/DataQ!AX194)-1) -> -0.1 | CB6: =100*((DataQ!AY198/DataQ!AY194)-1) -> 0.08475497 | CC6: =100*((DataQ!AZ198/DataQ!AZ194)-1) -> -0.19896935 | CD6: =100*((DataQ!BA198/DataQ!BA194)-1) -> 0.7789924 | CF6: 1963 | CG6: =OBR_MAR26_C4.6!C33 -> 8.9001447 | CH6: =OBR_MAR26_C4.6!D33 -> 3.0818378 | CJ6: 45717 | CS6: =[4]TA.9!C27 -> 95.482908 | CT6: =[4]TA.9!D27 -> 95.860994 | CU6: =[4]TA.9!E27 -> 95.118117 | CV6: =[4]TA.9!F27 -> 95.765323 | CW6: =[4]TA.9!G27 -> 96.138698 | CX6: =[4]TA.9!H27 -> 96.261883 | CY6: =[4]TA.9!I27 -> 96.114047 | DB6: 45717 | DK6: =[4]TA.9!C18 -> 4.7735122 | DL6: =[4]TA.9!D18 -> 4.7741675 | DM6: =[4]TA.9!E18 -> 3.930973 | DN6: =[4]TA.9!F18 -> 3.1329234 | DO6: =[4]TA.9!G18 -> 2.4897772 | DP6: =[4]TA.9!H18 -> 2.3184554 | DQ6: =[4]TA.9!I18 -> 2.1374759 | DZ6: q/q | EA6: =100*((EA4/EA3)^(1/108)-1) -> 0.57229399 | EC6: q/q | ED6: =100*((ED4/ED3)^(1/48)-1) -> 0.082411566 | EF6: q/q | EG6: =100*((EG4/EG3)^(1/23)-1) -> 0.11210635
X7: =HLOOKUP(X$6,$X$2:$AD$4,2,FALSE) -> Canada | Y7: =HLOOKUP(Y$6,$X$2:$AD$4,2,FALSE) -> Japan | Z7: =HLOOKUP(Z$6,$X$2:$AD$4,2,FALSE) -> Germany | AA7: =HLOOKUP(AA$6,$X$2:$AD$4,2,FALSE) -> Italy | AB7: =HLOOKUP(AB$6,$X$2:$AD$4,2,FALSE) -> UK | AC7: =HLOOKUP(AC$6,$X$2:$AD$4,2,FALSE) -> France | AD7: =HLOOKUP(AD$6,$X$2:$AD$4,2,FALSE) -> US | AG7: =HLOOKUP(AG$6,$AF$2:$AM$4,2,FALSE) -> Japan | AH7: =HLOOKUP(AH$6,$AF$2:$AM$4,2,FALSE) -> Italy | AI7: =HLOOKUP(AI$6,$AF$2:$AM$4,2,FALSE) -> US | AJ7: =HLOOKUP(AJ$6,$AF$2:$AM$4,2,FALSE) -> France | AK7: =HLOOKUP(AK$6,$AF$2:$AM$4,2,FALSE) -> Canada | AL7: =HLOOKUP(AL$6,$AF$2:$AM$4,2,FALSE) -> UK | AM7: =HLOOKUP(AM$6,$AF$2:$AM$4,2,FALSE) -> Germany | AP7: =HLOOKUP(AP$6,$AO$2:$AV$4,2,FALSE) -> Italy | AQ7: =HLOOKUP(AQ$6,$AO$2:$AV$4,2,FALSE) -> US | AR7: =HLOOKUP(AR$6,$AO$2:$AV$4,2,FALSE) -> UK | AS7: =HLOOKUP(AS$6,$AO$2:$AV$4,2,FALSE) -> Japan | AT7: =HLOOKUP(AT$6,$AO$2:$AV$4,2,FALSE) -> France | AU7: =HLOOKUP(AU$6,$AO$2:$AV$4,2,FALSE) -> Germany | AV7: =HLOOKUP(AV$6,$AO$2:$AV$4,2,FALSE) -> Canada | AX7: 2030 | AY7: =X13&", "&$AX7 -> UK, 2030 | AZ7: =Y13&", "&$AX7 -> US, 2030 | BA7: =Z13&", "&$AX7 -> Japan, 2030 | BB7: =AA13&", "&$AX7 -> Germany, 2030 | BC7: =AB13&", "&$AX7 -> France, 2030 | BD7: =AC13&", "&$AX7 -> Italy, 2030 | BE7: =AD13&", "&$AX7 -> Canada, 2030 | BG7: 1984 | BH7: =100*(SUMIF(HAVERQ!$B:$B,'Chart Data'!$BG7,HAVERQ!L:L)/SUMIF(HAVERQ!$A:$A,'Chart Data'!$BG7,HAVERQ!G:G)) -> 40.50205 | BI7: =100*('Data Q to A'!AK19/'Data Q to A'!AL19) -> 25.47886 | BK7: 44197 | BL7: =DataQ!AQ199 -> 1.541162 | BM7: =DataQ!AR199 -> -0.4946406 | BN7: =DataQ!AS199 -> -0.8528938 | BO7: =DataQ!AT199 -> -0.0002151728 | BQ7: 2021 | BR7: =BX7 -> 0.64535936 | BS7: =MEDIAN(BX7:CD7) -> 0.74036936 | BT7: =MIN(BY7:CD7) -> -0.53141131 | BU7: =MAX(BY7:CD7)-BT7 -> 2.4341405 | BW7: 2021 | BX7: =100*((DataQ!AU199/DataQ!AU195)-1) -> 0.64535936 | BY7: =100*((DataQ!AV199/DataQ!AV195)-1) -> 1.9027292 | BZ7: =100*((DataQ!AW199/DataQ!AW195)-1) -> -0.53141131 | CA7: =100*((DataQ!AX199/DataQ!AX195)-1) -> 1.5298309 | CB7: =100*((DataQ!AY199/DataQ!AY195)-1) -> 0.74036936 | CC7: =100*((DataQ!AZ199/DataQ!AZ195)-1) -> 0.63592605 | CD7: =100*((DataQ!BA199/DataQ!BA195)-1) -> 1.5795379 | CF7: 1964 | CG7: =OBR_MAR26_C4.6!C34 -> 8.0443828 | CH7: =OBR_MAR26_C4.6!D34 -> 2.8281322 | CJ7: 45597 | CS7: =[5]TA.9!C27 -> 97.810368 | CT7: =[5]TA.9!D27 -> 98.395587 | CU7: =[5]TA.9!E27 -> 96.921744 | CV7: =[5]TA.9!F27 -> 96.966301 | CW7: =[5]TA.9!G27 -> 97.245969 | CX7: =[5]TA.9!H27 -> 97.339932 | CY7: =[5]TA.9!I27 -> 97.147985 | DB7: 9072 | DK7: =[5]TA.9!C18 -> 4.4802137 | DL7: =[5]TA.9!D18 -> 4.5295378 | DM7: =[5]TA.9!E18 -> 3.578844 | DN7: =[5]TA.9!F18 -> 2.8914094 | DO7: =[5]TA.9!G18 -> 2.2785057 | DP7: =[5]TA.9!H18 -> 2.1929134 | DQ7: =[5]TA.9!I18 -> 2.077655 | DT7: 1961
W8: =W4 -> 2025 | X8: =HLOOKUP(X$6,$X$2:$AD$4,3,FALSE) -> -0.76203518 | Y8: =HLOOKUP(Y$6,$X$2:$AD$4,3,FALSE) -> -1.842392 | Z8: =HLOOKUP(Z$6,$X$2:$AD$4,3,FALSE) -> -2.7607817 | AA8: =HLOOKUP(AA$6,$X$2:$AD$4,3,FALSE) -> -3.0729095 | AB8: =HLOOKUP(AB$6,$X$2:$AD$4,3,FALSE) -> -4.9571948 | AC8: =HLOOKUP(AC$6,$X$2:$AD$4,3,FALSE) -> -5.110621 | AD8: =HLOOKUP(AD$6,$X$2:$AD$4,3,FALSE) -> -7.4069828 | AF8: =AF4 -> 2025 | AG8: =HLOOKUP(AG$6,$AF$2:$AM$4,3,FALSE) -> 205.18095 | AH8: =HLOOKUP(AH$6,$AF$2:$AM$4,3,FALSE) -> 149.35996 | AI8: =HLOOKUP(AI$6,$AF$2:$AM$4,3,FALSE) -> 137.36076 | AJ8: =HLOOKUP(AJ$6,$AF$2:$AM$4,3,FALSE) -> 124.09208 | AK8: =HLOOKUP(AK$6,$AF$2:$AM$4,3,FALSE) -> 107.47438 | AL8: =HLOOKUP(AL$6,$AF$2:$AM$4,3,FALSE) -> 102.3143 | AM8: =HLOOKUP(AM$6,$AF$2:$AM$4,3,FALSE) -> 59.442747 | AO8: =AO4 -> 2025 | AP8: =HLOOKUP(AP$6,$AO$2:$AV$4,3,FALSE) -> 124.67013 | AQ8: =HLOOKUP(AQ$6,$AO$2:$AV$4,3,FALSE) -> 101.74622 | AR8: =HLOOKUP(AR$6,$AO$2:$AV$4,3,FALSE) -> 93.846256 | AS8: =HLOOKUP(AS$6,$AO$2:$AV$4,3,FALSE) -> 87.280865 | AT8: =HLOOKUP(AT$6,$AO$2:$AV$4,3,FALSE) -> 76.159851 | AU8: =HLOOKUP(AU$6,$AO$2:$AV$4,3,FALSE) -> 21.998883 | AV8: =HLOOKUP(AV$6,$AO$2:$AV$4,3,FALSE) -> 8.3304342 | AY8: =X13 -> UK | AZ8: =Y13 -> US | BA8: =Z13 -> Japan | BB8: =AA13 -> Germany | BC8: =AB13 -> France | BD8: =AC13 -> Italy | BE8: =AD13 -> Canada | BG8: 1985 | BH8: =100*(SUMIF(HAVERQ!$B:$B,'Chart Data'!$BG8,HAVERQ!L:L)/SUMIF(HAVERQ!$A:$A,'Chart Data'!$BG8,HAVERQ!G:G)) -> 38.740658 | BI8: =100*('Data Q to A'!AK20/'Data Q to A'!AL20) -> 25.767186 | BK8: 44287 | BL8: =DataQ!AQ200 -> 1.185967 | BM8: =DataQ!AR200 -> -0.3768889 | BN8: =DataQ!AS200 -> -1.156042 | BO8: =DataQ!AT200 -> 0.02403095 | BR8: =BX8 -> 2.0270276 | BS8: =MEDIAN(BX8:CD8) -> 2.0270276 | BT8: =MIN(BY8:CD8) -> -0.73287117 | BU8: =MAX(BY8:CD8)-BT8 -> 5.5158141 | BX8: =100*((DataQ!AU200/DataQ!AU196)-1) -> 2.0270276 | BY8: =100*((DataQ!AV200/DataQ!AV196)-1) -> 4.7829429 | BZ8: =100*((DataQ!AW200/DataQ!AW196)-1) -> -0.73287117 | CA8: =100*((DataQ!AX200/DataQ!AX196)-1) -> 2.1941482 | CB8: =100*((DataQ!AY200/DataQ!AY196)-1) -> 1.3826343 | CC8: =100*((DataQ!AZ200/DataQ!AZ196)-1) -> 1.231621 | CD8: =100*((DataQ!BA200/DataQ!BA196)-1) -> 3.2883689 | CF8: 1965 | CG8: =OBR_MAR26_C4.6!C35 -> 7.3234147 | CH8: =OBR_MAR26_C4.6!D35 -> 2.7059483 | CJ8: 45352 | CR8: =[6]TA.9!C27 -> 95.726818 | CS8: =[6]TA.9!D27 -> 97.589333 | CT8: =[6]TA.9!E27 -> 98.777579 | CU8: =[6]TA.9!F27 -> 96.357307 | CV8: =[6]TA.9!G27 -> 95.479822 | CW8: =[6]TA.9!H27 -> 95.061625 | CX8: =[6]TA.9!I27 -> 94.29872 | DB8: 45352 | DJ8: =[6]TA.9!C16 -> 5.040891 | DK8: =[6]TA.9!D16 -> 4.1766481 | DL8: =[6]TA.9!E16 -> 3.1313233 | DM8: =[6]TA.9!F16 -> 2.6949793 | DN8: =[6]TA.9!G16 -> 2.3003184 | DO8: =[6]TA.9!H16 -> 1.6339411 | DP8: =[6]TA.9!I16 -> 1.2294641
AX9: Budget deficit | AY9: =X14 -> -2.3446715 | AZ9: =Y14 -> -7.5133161 | BA9: =Z14 -> -2.8347063 | BB9: =AA14 -> -3.5461105 | BC9: =AB14 -> -4.5319327 | BD9: =AC14 -> -2.5705903 | BE9: =AD14 -> -2.2744649 | BG9: 1986 | BH9: =100*(SUMIF(HAVERQ!$B:$B,'Chart Data'!$BG9,HAVERQ!L:L)/SUMIF(HAVERQ!$A:$A,'Chart Data'!$BG9,HAVERQ!G:G)) -> 37.434227 | BI9: =100*('Data Q to A'!AK21/'Data Q to A'!AL21) -> 25.29025 | BK9: 44378 | BL9: =DataQ!AQ201 -> 0.5780302 | BM9: =DataQ!AR201 -> -0.8651952 | BN9: =DataQ!AS201 -> -1.259767 | BO9: =DataQ!AT201 -> -0.07522835 | BR9: =BX9 -> 2.7539788 | BS9: =MEDIAN(BX9:CD9) -> 2.7539788 | BT9: =MIN(BY9:CD9) -> -0.16666 | BU9: =MAX(BY9:CD9)-BT9 -> 5.4162205 | BX9: =100*((DataQ!AU201/DataQ!AU197)-1) -> 2.7539788 | BY9: =100*((DataQ!AV201/DataQ!AV197)-1) -> 5.2495605 | BZ9: =100*((DataQ!AW201/DataQ!AW197)-1) -> -0.16666 | CA9: =100*((DataQ!AX201/DataQ!AX197)-1) -> 3.8474775 | CB9: =100*((DataQ!AY201/DataQ!AY197)-1) -> 1.7210871 | CC9: =100*((DataQ!AZ201/DataQ!AZ197)-1) -> 2.1894985 | CD9: =100*((DataQ!BA201/DataQ!BA197)-1) -> 3.9961257 | CF9: 1966 | CG9: =OBR_MAR26_C4.6!C36 -> 7.4150429 | CH9: =OBR_MAR26_C4.6!D36 -> 2.7901506 | CJ9: 45231 | CR9: =[7]TA.9!C27 -> 95.789462 | CS9: =[7]TA.9!D27 -> 97.869671 | CT9: =[7]TA.9!E27 -> 98.626745 | CU9: =[7]TA.9!F27 -> 96.281813 | CV9: =[7]TA.9!G27 -> 95.509908 | CW9: =[7]TA.9!H27 -> 95.000759 | CX9: =[7]TA.9!I27 -> 94.105503 | DB9: 45231 | DJ9: =[7]TA.9!C16 -> 5.0256521 | DK9: =[7]TA.9!D16 -> 4.5446593 | DL9: =[7]TA.9!E16 -> 3.0226263 | DM9: =[7]TA.9!F16 -> 2.6614041 | DN9: =[7]TA.9!G16 -> 2.2839522 | DO9: =[7]TA.9!H16 -> 1.5795786 | DP9: =[7]TA.9!I16 -> 1.0877049
AX10: Government debt | AY10: =AG14 -> 100.18769 | AZ10: =AH14 -> 145.37042 | BA10: =AI14 -> 202.07445 | BB10: =AJ14 -> 64.967518 | BC10: =AK14 -> 128.1406 | BD10: =AL14 -> 149.40588 | BE10: =AM14 -> 103.37566 | BG10: 1987 | BH10: =100*(SUMIF(HAVERQ!$B:$B,'Chart Data'!$BG10,HAVERQ!L:L)/SUMIF(HAVERQ!$A:$A,'Chart Data'!$BG10,HAVERQ!G:G)) -> 33.857321 | BI10: =100*('Data Q to A'!AK22/'Data Q to A'!AL22) -> 21.118881 | BK10: 44470 | BL10: =DataQ!AQ202 -> 0.4362244 | BM10: =DataQ!AR202 -> -0.9455727 | BN10: =DataQ!AS202 -> -1.106633 | BO10: =DataQ!AT202 -> -0.1353906 | BR10: =BX10 -> 4.8899435 | BS10: =MEDIAN(BX10:CD10) -> 4.7047047 | BT10: =MIN(BY10:CD10) -> 0.50231415 | BU10: =MAX(BY10:CD10)-BT10 -> 6.2690999 | BX10: =100*((DataQ!AU202/DataQ!AU198)-1) -> 4.8899435 | BY10: =100*((DataQ!AV202/DataQ!AV198)-1) -> 6.771414 | BZ10: =100*((DataQ!AW202/DataQ!AW198)-1) -> 0.50231415 | CA10: =100*((DataQ!AX202/DataQ!AX198)-1) -> 4.7047047 | CB10: =100*((DataQ!AY202/DataQ!AY198)-1) -> 2.7176804 | CC10: =100*((DataQ!AZ202/DataQ!AZ198)-1) -> 3.5087679 | CD10: =100*((DataQ!BA202/DataQ!BA198)-1) -> 4.7342754 | CF10: 1967 | CG10: =OBR_MAR26_C4.6!C37 -> 7.3668372 | CH10: =OBR_MAR26_C4.6!D37 -> 2.8786453 | CJ10: 44986 | CQ10: =[8]TA.9!C27 -> 96.901805 | CR10: =[8]TA.9!D27 -> 100.61452 | CS10: =[8]TA.9!E27 -> 103.07297 | CT10: =[8]TA.9!F27 -> 102.41794 | CU10: =[8]TA.9!G27 -> 99.099826 | CV10: =[8]TA.9!H27 -> 97.602946 | CW10: =[8]TA.9!I27 -> 96.932318 | DB10: 44986 | DI10: =[8]TA.9!C16 -> 5.2345344 | DJ10: =[8]TA.9!D16 -> 6.0841634 | DK10: =[8]TA.9!E16 -> 5.1128597 | DL10: =[8]TA.9!F16 -> 3.1999641 | DM10: =[8]TA.9!G16 -> 2.7791586 | DN10: =[8]TA.9!H16 -> 2.2269114 | DO10: =[8]TA.9!I16 -> 1.6698882
W11: Budget deficit in 2030 | AF11: Gross government debt in 2030 | AO11: Government net debt in 2030 | BG11: 1988 | BH11: =100*(SUMIF(HAVERQ!$B:$B,'Chart Data'!$BG11,HAVERQ!L:L)/SUMIF(HAVERQ!$A:$A,'Chart Data'!$BG11,HAVERQ!G:G)) -> 28.259914 | BI11: =100*('Data Q to A'!AK23/'Data Q to A'!AL23) -> 16.615076 | BK11: 44562 | BL11: =DataQ!AQ203 -> -0.005793571 | BM11: =DataQ!AR203 -> -1.035532 | BN11: =DataQ!AS203 -> -0.9248759 | BO11: =DataQ!AT203 -> -0.1517915 | BQ11: 2022 | BR11: =BX11 -> 6.1984103 | BS11: =MEDIAN(BX11:CD11) -> 5.6477014 | BT11: =MIN(BY11:CD11) -> 0.86810679 | BU11: =MAX(BY11:CD11)-BT11 -> 7.1561654 | BW11: 2022 | BX11: =100*((DataQ!AU203/DataQ!AU199)-1) -> 6.1984103 | BY11: =100*((DataQ!AV203/DataQ!AV199)-1) -> 8.0242722 | BZ11: =100*((DataQ!AW203/DataQ!AW199)-1) -> 0.86810679 | CA11: =100*((DataQ!AX203/DataQ!AX199)-1) -> 4.7821144 | CB11: =100*((DataQ!AY203/DataQ!AY199)-1) -> 3.6593222 | CC11: =100*((DataQ!AZ203/DataQ!AZ199)-1) -> 5.6477014 | CD11: =100*((DataQ!BA203/DataQ!BA199)-1) -> 5.8612693 | CF11: 1968 | CG11: =OBR_MAR26_C4.6!C38 -> 6.8228266 | CH11: =OBR_MAR26_C4.6!D38 -> 2.7833002 | CJ11: 44866 | CQ11: =[9]TA.5!C27 -> 97.423344 | CR11: =[9]TA.5!D27 -> 101.86249 | CS11: =[9]TA.5!E27 -> 106.70332 | CT11: =[9]TA.5!F27 -> 105.78743 | CU11: =[9]TA.5!G27 -> 101.69865 | CV11: =[9]TA.5!H27 -> 99.985432 | CW11: =[9]TA.5!I27 -> 99.272594 | DB11: 44866 | DI11: =[9]TA.5!C17 -> 5.6891509 | DJ11: =[9]TA.5!D17 -> 7.0896394 | DK11: =[9]TA.5!E17 -> 5.5085268 | DL11: =[9]TA.5!F17 -> 3.2087565 | DM11: =[9]TA.5!G17 -> 2.8347858 | DN11: =[9]TA.5!H17 -> 2.8525034 | DO11: =[9]TA.5!I17 -> 2.3637925 | DT11: 1962
X12: =RANK(X14,$X$14:$AD$14) -> 2 | Y12: =RANK(Y14,$X$14:$AD$14) -> 7 | Z12: =RANK(Z14,$X$14:$AD$14) -> 4 | AA12: =RANK(AA14,$X$14:$AD$14) -> 5 | AB12: =RANK(AB14,$X$14:$AD$14) -> 6 | AC12: =RANK(AC14,$X$14:$AD$14) -> 3 | AD12: =RANK(AD14,$X$14:$AD$14) -> 1 | AG12: =RANK(AG14,$AG$14:$AM$14) -> 6 | AH12: =RANK(AH14,$AG$14:$AM$14) -> 3 | AI12: =RANK(AI14,$AG$14:$AM$14) -> 1 | AJ12: =RANK(AJ14,$AG$14:$AM$14) -> 7 | AK12: =RANK(AK14,$AG$14:$AM$14) -> 4 | AL12: =RANK(AL14,$AG$14:$AM$14) -> 2 | AM12: =RANK(AM14,$AG$14:$AM$14) -> 5 | AP12: =RANK(AP14,$AP$14:$AV$14) -> 3 | AQ12: =RANK(AQ14,$AP$14:$AV$14) -> 2 | AR12: =RANK(AR14,$AP$14:$AV$14) -> 4 | AS12: =RANK(AS14,$AP$14:$AV$14) -> 6 | AT12: =RANK(AT14,$AP$14:$AV$14) -> 5 | AU12: =RANK(AU14,$AP$14:$AV$14) -> 1 | AV12: =RANK(AV14,$AP$14:$AV$14) -> 7 | AX12: 2026 | AY12: =X19&", "&$AX12 -> UK, 2026 | AZ12: =Y19&", "&$AX12 -> US, 2026 | BA12: =Z19&", "&$AX12 -> Japan, 2026 | BB12: =AA19&", "&$AX12 -> Germany, 2026 | BC12: =AB19&", "&$AX12 -> France, 2026 | BD12: =AC19&", "&$AX12 -> Italy, 2026 | BE12: =AD19&", "&$AX12 -> Canada, 2026 | BG12: 1989 | BH12: =100*(SUMIF(HAVERQ!$B:$B,'Chart Data'!$BG12,HAVERQ!L:L)/SUMIF(HAVERQ!$A:$A,'Chart Data'!$BG12,HAVERQ!G:G)) -> 24.82894 | BI12: =100*('Data Q to A'!AK24/'Data Q to A'!AL24) -> 15.033128 | BK12: 44652 | BL12: =DataQ!AQ204 -> -1.116444 | BM12: =DataQ!AR204 -> -0.9544389 | BN12: =DataQ!AS204 -> -0.7541516 | BO12: =DataQ!AT204 -> -0.3281502 | BR12: =BX12 -> 9.1511767 | BS12: =MEDIAN(BX12:CD12) -> 6.9466369 | BT12: =MIN(BY12:CD12) -> 2.3825435 | BU12: =MAX(BY12:CD12)-BT12 -> 6.2024404 | BX12: =100*((DataQ!AU204/DataQ!AU200)-1) -> 9.1511767 | BY12: =100*((DataQ!AV204/DataQ!AV200)-1) -> 8.5849839 | BZ12: =100*((DataQ!AW204/DataQ!AW200)-1) -> 2.3825435 | CA12: =100*((DataQ!AX204/DataQ!AX200)-1) -> 6.6363023 | CB12: =100*((DataQ!AY204/DataQ!AY200)-1) -> 5.291745 | CC12: =100*((DataQ!AZ204/DataQ!AZ200)-1) -> 6.9466369 | CD12: =100*((DataQ!BA204/DataQ!BA200)-1) -> 7.5552388 | CF12: 1969 | CG12: =OBR_MAR26_C4.6!C39 -> 6.1751022 | CH12: =OBR_MAR26_C4.6!D39 -> 2.5837659 | CJ12: 44621 | CO12: ='[10]T3.38'!C16 -> 82.729735 | CP12: ='[10]T3.38'!D16 -> 93.977911 | CQ12: ='[10]T3.38'!E16 -> 95.551157 | CR12: ='[10]T3.38'!F16 -> 95.471541 | CS12: ='[10]T3.38'!G16 -> 94.08063 | CT12: ='[10]T3.38'!H16 -> 91.237255 | CU12: ='[10]T3.38'!I16 -> 85.813581 | CV12: ='[10]T3.38'!J16 -> 83.121441 | DB12: 44621 | DG12: ='[10]T3.38'!C21 -> 2.435919 | DH12: ='[10]T3.38'!D21 -> 15.029808 | DI12: ='[10]T3.38'!E21 -> 5.4064361 | DJ12: ='[10]T3.38'!F21 -> 3.9448448 | DK12: ='[10]T3.38'!G21 -> 1.9147022 | DL12: ='[10]T3.38'!H21 -> 1.3397308 | DM12: ='[10]T3.38'!I21 -> 1.2323035 | DN12: ='[10]T3.38'!J21 -> 1.0763712
X13: UK | Y13: US | Z13: Japan | AA13: Germany | AB13: France | AC13: Italy | AD13: Canada | AG13: UK | AH13: US | AI13: Japan | AJ13: Germany | AK13: France | AL13: Italy | AM13: Canada | AP13: UK | AQ13: US | AR13: Japan | AS13: Germany | AT13: France | AU13: Italy | AV13: Canada | AY13: =X18 -> 5 | AZ13: =Y18 -> 7 | BA13: =Z18 -> 2 | BB13: =AA18 -> 4 | BC13: =AB18 -> 6 | BD13: =AC18 -> 3 | BE13: =AD18 -> 1 | BG13: 1990 | BH13: =100*(SUMIF(HAVERQ!$B:$B,'Chart Data'!$BG13,HAVERQ!L:L)/SUMIF(HAVERQ!$A:$A,'Chart Data'!$BG13,HAVERQ!G:G)) -> 23.116243 | BI13: =100*('Data Q to A'!AK25/'Data Q to A'!AL25) -> 14.488901 | BK13: 44743 | BL13: =DataQ!AQ205 -> -2.262011 | BM13: =DataQ!AR205 -> -2.050474 | BN13: =DataQ!AS205 -> -1.08056 | BO13: =DataQ!AT205 -> -0.6069162 | BR13: =BX13 -> 10.005959 | BS13: =MEDIAN(BX13:CD13) -> 7.3775427 | BT13: =MIN(BY13:CD13) -> 2.8714456 | BU13: =MAX(BY13:CD13)-BT13 -> 5.504082 | BX13: =100*((DataQ!AU205/DataQ!AU201)-1) -> 10.005959 | BY13: =100*((DataQ!AV205/DataQ!AV201)-1) -> 8.2920958 | BZ13: =100*((DataQ!AW205/DataQ!AW201)-1) -> 2.8714456 | CA13: =100*((DataQ!AX205/DataQ!AX201)-1) -> 7.3775427 | CB13: =100*((DataQ!AY205/DataQ!AY201)-1) -> 5.850136 | CC13: =100*((DataQ!AZ205/DataQ!AZ201)-1) -> 8.3755275 | CD13: =100*((DataQ!BA205/DataQ!BA201)-1) -> 7.0993423 | CF13: 1970 | CG13: =OBR_MAR26_C4.6!C40 -> 5.8139032 | CH13: =OBR_MAR26_C4.6!D40 -> 2.3277161 | CJ13: 44470 | CO13: ='[11]T3.38'!C16 -> 84.150466 | CP13: ='[11]T3.38'!D16 -> 96.605899 | CQ13: ='[11]T3.38'!E16 -> 98.202523 | CR13: ='[11]T3.38'!F16 -> 97.898319 | CS13: ='[11]T3.38'!G16 -> 97.805409 | CT13: ='[11]T3.38'!H16 -> 94.671932 | CU13: ='[11]T3.38'!I16 -> 90.546261 | CV13: ='[11]T3.38'!J16 -> 87.956174 | DB13: 44470 | DG13: ='[11]T3.38'!C21 -> 2.5581097 | DH13: ='[11]T3.38'!D21 -> 15.244423 | DI13: ='[11]T3.38'!E21 -> 7.8965664 | DJ13: ='[11]T3.38'!F21 -> 3.3460556 | DK13: ='[11]T3.38'!G21 -> 2.3888791 | DL13: ='[11]T3.38'!H21 -> 1.7392579 | DM13: ='[11]T3.38'!I21 -> 1.6794935 | DN13: ='[11]T3.38'!J21 -> 1.5336108
W14: 2030 | X14: =100*('Data Q to A'!I65/'Data Q to A'!AD65) -> -2.3446715 | Y14: =100*('Data Q to A'!J65/'Data Q to A'!AE65) -> -7.5133161 | Z14: =100*('Data Q to A'!K65/'Data Q to A'!AF65) -> -2.8347063 | AA14: =100*('Data Q to A'!L65/'Data Q to A'!AG65) -> -3.5461105 | AB14: =100*('Data Q to A'!M65/'Data Q to A'!AH65) -> -4.5319327 | AC14: =100*('Data Q to A'!N65/'Data Q to A'!AI65) -> -2.5705903 | AD14: =100*('Data Q to A'!O65/'Data Q to A'!AJ65) -> -2.2744649 | AF14: 2030 | AG14: =100*('Data Q to A'!P65/'Data Q to A'!AD65) -> 100.18769 | AH14: =100*('Data Q to A'!Q65/'Data Q to A'!AE65) -> 145.37042 | AI14: =100*('Data Q to A'!R65/'Data Q to A'!AF65) -> 202.07445 | AJ14: =100*('Data Q to A'!S65/'Data Q to A'!AG65) -> 64.967518 | AK14: =100*('Data Q to A'!T65/'Data Q to A'!AH65) -> 128.1406 | AL14: =100*('Data Q to A'!U65/'Data Q to A'!AI65) -> 149.40588 | AM14: =100*('Data Q to A'!V65/'Data Q to A'!AJ65) -> 103.37566 | AO14: 2030 | AP14: =100*('Data Q to A'!W65/'Data Q to A'!AD65) -> 99.453613 | AQ14: =100*('Data Q to A'!X65/'Data Q to A'!AE65) -> 116.26922 | AR14: =100*('Data Q to A'!Y65/'Data Q to A'!AF65) -> 94.821064 | AS14: =100*('Data Q to A'!Z65/'Data Q to A'!AG65) -> 34.379022 | AT14: =100*('Data Q to A'!AA65/'Data Q to A'!AH65) -> 87.433644 | AU14: =100*('Data Q to A'!AB65/'Data Q to A'!AI65) -> 124.35997 | AV14: =100*('Data Q to A'!AC65/'Data Q to A'!AJ65) -> 20.926859 | AX14: Budget deficit | AY14: =X20 -> -4.0001734 | AZ14: =Y20 -> -8.5558702 | BA14: =Z20 -> -2.8506069 | BB14: =AA20 -> -3.2175664 | BC14: =AB20 -> -5.1308615 | BD14: =AC20 -> -2.8984413 | BE14: =AD20 -> -2.6887195 | BG14: 1991 | BH14: =100*(SUMIF(HAVERQ!$B:$B,'Chart Data'!$BG14,HAVERQ!L:L)/SUMIF(HAVERQ!$A:$A,'Chart Data'!$BG14,HAVERQ!G:G)) -> 24.039081 | BI14: =100*('Data Q to A'!AK26/'Data Q to A'!AL26) -> 18.162022 | BK14: 44835 | BL14: =DataQ!AQ206 -> -2.748286 | BM14: =DataQ!AR206 -> -2.42089 | BN14: =DataQ!AS206 -> -1.370171 | BO14: =DataQ!AT206 -> -0.8705126 | BR14: =BX14 -> 10.751748 | BS14: =MEDIAN(BX14:CD14) -> 7.0919783 | BT14: =MIN(BY14:CD14) -> 3.8654128 | BU14: =MAX(BY14:CD14)-BT14 -> 7.9219528 | BX14: =100*((DataQ!AU206/DataQ!AU202)-1) -> 10.751748 | BY14: =100*((DataQ!AV206/DataQ!AV202)-1) -> 7.0919783 | BZ14: =100*((DataQ!AW206/DataQ!AW202)-1) -> 3.8654128 | CA14: =100*((DataQ!AX206/DataQ!AX202)-1) -> 8.6042065 | CB14: =100*((DataQ!AY206/DataQ!AY202)-1) -> 6.0635666 | CC14: =100*((DataQ!AZ206/DataQ!AZ202)-1) -> 11.787366 | CD14: =100*((DataQ!BA206/DataQ!BA202)-1) -> 6.5959886 | CF14: 1971 | CG14: =OBR_MAR26_C4.6!C41 -> 6.2308313 | CH14: =OBR_MAR26_C4.6!D41 -> 2.3904259 | CJ14: 44256 | CO14: ='[12]T3.34'!C16 -> 84.385651 | CP14: ='[12]T3.34'!D16 -> 100.18536 | CQ14: ='[12]T3.34'!E16 -> 107.35822 | CR14: ='[12]T3.34'!F16 -> 108.99736 | CS14: ='[12]T3.34'!G16 -> 109.6843 | CT14: ='[12]T3.34'!H16 -> 106.17704 | CU14: ='[12]T3.34'!I16 -> 103.76446 | DB14: 44256 | DG14: ='[12]T3.34'!C21 -> 2.566323 | DH14: ='[12]T3.34'!D21 -> 16.913985 | DI14: ='[12]T3.34'!E21 -> 10.330701 | DJ14: ='[12]T3.34'!F21 -> 4.5020679 | DK14: ='[12]T3.34'!G21 -> 3.4702553 | DL14: ='[12]T3.34'!H21 -> 2.9172069 | DM14: ='[12]T3.34'!I21 -> 2.7783686
AX15: Government debt | AY15: =AG20 -> 102.90878 | AZ15: =AH20 -> 139.10168 | BA15: =AI20 -> 201.40608 | BB15: =AJ20 -> 60.85768 | BC15: =AK20 -> 126.12567 | BD15: =AL20 -> 151.13582 | BE15: =AM20 -> 106.07867 | BG15: 1992 | BH15: =100*(SUMIF(HAVERQ!$B:$B,'Chart Data'!$BG15,HAVERQ!L:L)/SUMIF(HAVERQ!$A:$A,'Chart Data'!$BG15,HAVERQ!G:G)) -> 28.391576 | BI15: =100*('Data Q to A'!AK27/'Data Q to A'!AL27) -> 26.942452 | BK15: 44927 | BL15: =DataQ!AQ207 -> -4.198305 | BM15: =DataQ!AR207 -> -3.155869 | BN15: =DataQ!AS207 -> -2.290555 | BO15: =DataQ!AT207 -> -0.8742595 | BQ15: 2023 | BR15: =BX15 -> 10.178266 | BS15: =MEDIAN(BX15:CD15) -> 5.9931317 | BT15: =MIN(BY15:CD15) -> 3.6412115 | BU15: =MAX(BY15:CD15)-BT15 -> 5.2559929 | BW15: 2023 | BX15: =100*((DataQ!AU207/DataQ!AU203)-1) -> 10.178266 | BY15: =100*((DataQ!AV207/DataQ!AV203)-1) -> 5.7298257 | BZ15: =100*((DataQ!AW207/DataQ!AW203)-1) -> 3.6412115 | CA15: =100*((DataQ!AX207/DataQ!AX203)-1) -> 8.221353 | CB15: =100*((DataQ!AY207/DataQ!AY203)-1) -> 5.9931317 | CC15: =100*((DataQ!AZ207/DataQ!AZ203)-1) -> 8.8972044 | CD15: =100*((DataQ!BA207/DataQ!BA203)-1) -> 5.1525424 | CF15: 1972 | CG15: =OBR_MAR26_C4.6!C42 -> 6.5073141 | CH15: =OBR_MAR26_C4.6!D42 -> 2.334262 | CJ15: 44136 | CO15: ='[13]T3.30'!C16 -> 85.454671 | CP15: ='[13]T3.30'!D16 -> 105.19319 | CQ15: ='[13]T3.30'!E16 -> 108.03806 | CR15: ='[13]T3.30'!F16 -> 108.57979 | CS15: ='[13]T3.30'!G16 -> 109.41773 | CT15: ='[13]T3.30'!H16 -> 104.97 | CU15: ='[13]T3.30'!I16 -> 104.74934 | DB15: 44136 | DG15: ='[13]T3.30'!C21 -> 2.5274085 | DH15: ='[13]T3.30'!D21 -> 19.016635 | DI15: ='[13]T3.30'!E21 -> 7.400033 | DJ15: ='[13]T3.30'!F21 -> 4.4492529 | DK15: ='[13]T3.30'!G21 -> 4.1130923 | DL15: ='[13]T3.30'!H21 -> 3.9269697 | DM15: ='[13]T3.30'!I21 -> 3.8616613 | DT15: 1963
BG16: 1993 | BH16: =100*(SUMIF(HAVERQ!$B:$B,'Chart Data'!$BG16,HAVERQ!L:L)/SUMIF(HAVERQ!$A:$A,'Chart Data'!$BG16,HAVERQ!G:G)) -> 33.091702 | BI16: =100*('Data Q to A'!AK28/'Data Q to A'!AL28) -> 31.477766 | BK16: 45017 | BL16: =DataQ!AQ208 -> -3.759159 | BM16: =DataQ!AR208 -> -3.433098 | BN16: =DataQ!AS208 -> -2.461839 | BO16: =DataQ!AT208 -> -1.02899 | BR16: =BX16 -> 8.439049 | BS16: =MEDIAN(BX16:CD16) -> 5.1773244 | BT16: =MIN(BY16:CD16) -> 3.3759095 | BU16: =MAX(BY16:CD16)-BT16 -> 3.9635321 | BX16: =100*((DataQ!AU208/DataQ!AU204)-1) -> 8.439049 | BY16: =100*((DataQ!AV208/DataQ!AV204)-1) -> 4.0439594 | BZ16: =100*((DataQ!AW208/DataQ!AW204)-1) -> 3.3759095 | CA16: =100*((DataQ!AX208/DataQ!AX204)-1) -> 6.5588144 | CB16: =100*((DataQ!AY208/DataQ!AY204)-1) -> 5.1773244 | CC16: =100*((DataQ!AZ208/DataQ!AZ204)-1) -> 7.3394417 | CD16: =100*((DataQ!BA208/DataQ!BA204)-1) -> 3.5785288 | CF16: 1973 | CG16: =OBR_MAR26_C4.6!C43 -> 6.7291653 | CH16: =OBR_MAR26_C4.6!D43 -> 2.4339033 | CJ16: 43891 | CN16: ='[14]T3.40'!C16 -> 80.646995 | CO16: ='[14]T3.40'!D16 -> 79.493871 | CP16: ='[14]T3.40'!E16 -> 77.435816 | CQ16: ='[14]T3.40'!F16 -> 74.993508 | CR16: ='[14]T3.40'!G16 -> 75.409295 | CS16: ='[14]T3.40'!H16 -> 75.55736 | CT16: ='[14]T3.40'!I16 -> 75.225038 | DB16: 43891 | DF16: ='[14]T3.40'!C21 -> 1.7721895 | DG16: ='[14]T3.40'!D21 -> 2.1289957 | DH16: ='[14]T3.40'!E21 -> 2.3773683 | DI16: ='[14]T3.40'!F21 -> 2.7843366 | DJ16: ='[14]T3.40'!G21 -> 2.481179 | DK16: ='[14]T3.40'!H21 -> 2.3514082 | DL16: ='[14]T3.40'!I21 -> 2.1823592
W17: Budget deficit in 2026 | AF17: Gross government debt in 2026 | AO17: Government net debt in 2026 | BG17: 1994 | BH17: =100*(SUMIF(HAVERQ!$B:$B,'Chart Data'!$BG17,HAVERQ!L:L)/SUMIF(HAVERQ!$A:$A,'Chart Data'!$BG17,HAVERQ!G:G)) -> 36.609602 | BI17: =100*('Data Q to A'!AK29/'Data Q to A'!AL29) -> 34.831446 | BK17: 45108 | BL17: =DataQ!AQ209 -> -3.51581 | BM17: =DataQ!AR209 -> -2.936102 | BN17: =DataQ!AS209 -> -2.727603 | BO17: =DataQ!AT209 -> -0.9281871 | BR17: =BX17 -> 6.7136185 | BS17: =MEDIAN(BX17:CD17) -> 4.6812076 | BT17: =MIN(BY17:CD17) -> 3.148296 | BU17: =MAX(BY17:CD17)-BT17 -> 2.432262 | BX17: =100*((DataQ!AU209/DataQ!AU205)-1) -> 6.7136185 | BY17: =100*((DataQ!AV209/DataQ!AV205)-1) -> 3.5660494 | BZ17: =100*((DataQ!AW209/DataQ!AW205)-1) -> 3.148296 | CA17: =100*((DataQ!AX209/DataQ!AX205)-1) -> 5.5805581 | CB17: =100*((DataQ!AY209/DataQ!AY205)-1) -> 4.6812076 | CC17: =100*((DataQ!AZ209/DataQ!AZ205)-1) -> 5.5715351 | CD17: =100*((DataQ!BA209/DataQ!BA205)-1) -> 3.7190541 | CF17: 1974 | CG17: =OBR_MAR26_C4.6!C44 -> 6.1927264 | CH17: =OBR_MAR26_C4.6!D44 -> 2.4156754 | CJ17: 43525 | CM17: ='[15]T4.37'!C16 -> 84.704401 | CN17: ='[15]T4.37'!D16 -> 83.31282 | CO17: ='[15]T4.37'!E16 -> 82.228042 | CP17: ='[15]T4.37'!F16 -> 78.981682 | CQ17: ='[15]T4.37'!G16 -> 74.925844 | CR17: ='[15]T4.37'!H16 -> 74.026199 | CS17: ='[15]T4.37'!I16 -> 72.980694 | DB17: 43525 | DE17: ='[15]T4.37'!C18 -> 2.0274272 | DF17: ='[15]T4.37'!D18 -> 1.0711559 | DG17: ='[15]T4.37'!E18 -> 1.3335606 | DH17: ='[15]T4.37'!F18 -> 0.93003908 | DI17: ='[15]T4.37'!G18 -> 0.74865478 | DJ17: ='[15]T4.37'!H18 -> 0.59081155 | DK17: ='[15]T4.37'!I18 -> 0.532105
X18: =RANK(X20,$X$20:$AD$20) -> 5 | Y18: =RANK(Y20,$X$20:$AD$20) -> 7 | Z18: =RANK(Z20,$X$20:$AD$20) -> 2 | AA18: =RANK(AA20,$X$20:$AD$20) -> 4 | AB18: =RANK(AB20,$X$20:$AD$20) -> 6 | AC18: =RANK(AC20,$X$20:$AD$20) -> 3 | AD18: =RANK(AD20,$X$20:$AD$20) -> 1 | AG18: =RANK(AG20,$AG$20:$AM$20) -> 6 | AH18: =RANK(AH20,$AG$20:$AM$20) -> 3 | AI18: =RANK(AI20,$AG$20:$AM$20) -> 1 | AJ18: =RANK(AJ20,$AG$20:$AM$20) -> 7 | AK18: =RANK(AK20,$AG$20:$AM$20) -> 4 | AL18: =RANK(AL20,$AG$20:$AM$20) -> 2 | AM18: =RANK(AM20,$AG$20:$AM$20) -> 5 | AP18: =RANK(AP20,$AP$20:$AV$20) -> 3 | AQ18: =RANK(AQ20,$AP$20:$AV$20) -> 2 | AR18: =RANK(AR20,$AP$20:$AV$20) -> 4 | AS18: =RANK(AS20,$AP$20:$AV$20) -> 6 | AT18: =RANK(AT20,$AP$20:$AV$20) -> 5 | AU18: =RANK(AU20,$AP$20:$AV$20) -> 1 | AV18: =RANK(AV20,$AP$20:$AV$20) -> 7 | BG18: 1995 | BH18: =100*(SUMIF(HAVERQ!$B:$B,'Chart Data'!$BG18,HAVERQ!L:L)/SUMIF(HAVERQ!$A:$A,'Chart Data'!$BG18,HAVERQ!G:G)) -> 38.837507 | BI18: =100*('Data Q to A'!AK30/'Data Q to A'!AL30) -> 36.45979 | BK18: 45200 | BL18: =DataQ!AQ210 -> -3.460574 | BM18: =DataQ!AR210 -> -2.457488 | BN18: =DataQ!AS210 -> -2.915811 | BO18: =DataQ!AT210 -> -0.7505955 | BR18: =BX18 -> 4.1568272 | BS18: =MEDIAN(BX18:CD18) -> 3.2334846 | BT18: =MIN(BY18:CD18) -> 0.9993143 | BU18: =MAX(BY18:CD18)-BT18 -> 2.7212708 | BX18: =100*((DataQ!AU210/DataQ!AU206)-1) -> 4.1568272 | BY18: =100*((DataQ!AV210/DataQ!AV206)-1) -> 3.2334846 | BZ18: =100*((DataQ!AW210/DataQ!AW206)-1) -> 2.9194418 | CA18: =100*((DataQ!AX210/DataQ!AX206)-1) -> 3.5211268 | CB18: =100*((DataQ!AY210/DataQ!AY206)-1) -> 3.7205851 | CC18: =100*((DataQ!AZ210/DataQ!AZ206)-1) -> 0.9993143 | CD18: =100*((DataQ!BA210/DataQ!BA206)-1) -> 3.1804407 | CF18: 1975 | CG18: =OBR_MAR26_C4.6!C45 -> 6.4126892 | CH18: =OBR_MAR26_C4.6!D45 -> 2.5727384 | CJ18: 43374 | CM18: ='[16]T4.45'!C16 -> 85.047161 | CN18: ='[16]T4.45'!D16 -> 83.675146 | CO18: ='[16]T4.45'!E16 -> 82.841229 | CP18: ='[16]T4.45'!F16 -> 79.670328 | CQ18: ='[16]T4.45'!G16 -> 75.687396 | CR18: ='[16]T4.45'!H16 -> 75.038262 | CS18: ='[16]T4.45'!I16 -> 74.050274 | DB18: 43374 | DE18: ='[16]T4.45'!C18 -> 1.9320546 | DF18: ='[16]T4.45'!D18 -> 1.1983087 | DG18: ='[16]T4.45'!E18 -> 1.4446749 | DH18: ='[16]T4.45'!F18 -> 1.1727942 | DI18: ='[16]T4.45'!G18 -> 1.0133467 | DJ18: ='[16]T4.45'!H18 -> 0.85562922 | DK18: ='[16]T4.45'!I18 -> 0.784627
X19: UK | Y19: US | Z19: Japan | AA19: Germany | AB19: France | AC19: Italy | AD19: Canada | AG19: UK | AH19: US | AI19: Japan | AJ19: Germany | AK19: France | AL19: Italy | AM19: Canada | AP19: UK | AQ19: US | AR19: Japan | AS19: Germany | AT19: France | AU19: Italy | AV19: Canada | BG19: 1996 | BH19: =100*(SUMIF(HAVERQ!$B:$B,'Chart Data'!$BG19,HAVERQ!L:L)/SUMIF(HAVERQ!$A:$A,'Chart Data'!$BG19,HAVERQ!G:G)) -> 40.021935 | BI19: =100*('Data Q to A'!AK31/'Data Q to A'!AL31) -> 37.120438 | BK19: 45292 | BL19: =DataQ!AQ211 -> -3.233632 | BM19: =DataQ!AR211 -> -2.455854 | BN19: =DataQ!AS211 -> -2.96869 | BO19: =DataQ!AT211 -> -0.8963838 | BQ19: 2024 | BR19: =BX19 -> 3.5491137 | BS19: =MEDIAN(BX19:CD19) -> 2.7905518 | BT19: =MIN(BY19:CD19) -> 0.92687951 | BU19: =MAX(BY19:CD19)-BT19 -> 2.317482 | BW19: 2024 | BX19: =100*((DataQ!AU211/DataQ!AU207)-1) -> 3.5491137 | BY19: =100*((DataQ!AV211/DataQ!AV207)-1) -> 3.2443615 | BZ19: =100*((DataQ!AW211/DataQ!AW207)-1) -> 2.5231228 | CA19: =100*((DataQ!AX211/DataQ!AX207)-1) -> 2.5418544 | CB19: =100*((DataQ!AY211/DataQ!AY207)-1) -> 2.7905518 | CC19: =100*((DataQ!AZ211/DataQ!AZ207)-1) -> 0.92687951 | CD19: =100*((DataQ!BA211/DataQ!BA207)-1) -> 2.8583495 | CF19: 1976 | CG19: =OBR_MAR26_C4.6!C46 -> 7.1401064 | CH19: =OBR_MAR26_C4.6!D46 -> 2.8710795 | CJ19: 43160 | CL19: ='[17]T4.40'!C16 -> 85.301455 | CM19: ='[17]T4.40'!D16 -> 85.567583 | CN19: ='[17]T4.40'!E16 -> 85.519318 | CO19: ='[17]T4.40'!F16 -> 85.107509 | CP19: ='[17]T4.40'!G16 -> 82.100865 | CQ19: ='[17]T4.40'!H16 -> 78.325555 | CR19: ='[17]T4.40'!I16 -> 77.941182 | DB19: 43160 | DD19: ='[17]T4.40'!C18 -> 2.3028187 | DE19: ='[17]T4.40'!D18 -> 2.198356 | DF19: ='[17]T4.40'!E18 -> 1.7511384 | DG19: ='[17]T4.40'!F18 -> 1.5574026 | DH19: ='[17]T4.40'!G18 -> 1.2820424 | DI19: ='[17]T4.40'!H18 -> 1.1242667 | DJ19: ='[17]T4.40'!I18 -> 0.89528229 | DT19: 1964
W20: 2026 | X20: =100*('Data Q to A'!I61/'Data Q to A'!AD61) -> -4.0001734 | Y20: =100*('Data Q to A'!J61/'Data Q to A'!AE61) -> -8.5558702 | Z20: =100*('Data Q to A'!K61/'Data Q to A'!AF61) -> -2.8506069 | AA20: =100*('Data Q to A'!L61/'Data Q to A'!AG61) -> -3.2175664 | AB20: =100*('Data Q to A'!M61/'Data Q to A'!AH61) -> -5.1308615 | AC20: =100*('Data Q to A'!N61/'Data Q to A'!AI61) -> -2.8984413 | AD20: =100*('Data Q to A'!O61/'Data Q to A'!AJ61) -> -2.6887195 | AF20: 2026 | AG20: =100*('Data Q to A'!P61/'Data Q to A'!AD61) -> 102.90878 | AH20: =100*('Data Q to A'!Q61/'Data Q to A'!AE61) -> 139.10168 | AI20: =100*('Data Q to A'!R61/'Data Q to A'!AF61) -> 201.40608 | AJ20: =100*('Data Q to A'!S61/'Data Q to A'!AG61) -> 60.85768 | AK20: =100*('Data Q to A'!T61/'Data Q to A'!AH61) -> 126.12567 | AL20: =100*('Data Q to A'!U61/'Data Q to A'!AI61) -> 151.13582 | AM20: =100*('Data Q to A'!V61/'Data Q to A'!AJ61) -> 106.07867 | AO20: 2026 | AP20: =100*('Data Q to A'!W61/'Data Q to A'!AD61) -> 97.203557 | AQ20: =100*('Data Q to A'!X61/'Data Q to A'!AE61) -> 105.08329 | AR20: =100*('Data Q to A'!Y61/'Data Q to A'!AF61) -> 87.313062 | AS20: =100*('Data Q to A'!Z61/'Data Q to A'!AG61) -> 24.549321 | AT20: =100*('Data Q to A'!AA61/'Data Q to A'!AH61) -> 79.389783 | AU20: =100*('Data Q to A'!AB61/'Data Q to A'!AI61) -> 125.03976 | AV20: =100*('Data Q to A'!AC61/'Data Q to A'!AJ61) -> 10.891426 | BG20: 1997 | BH20: =100*(SUMIF(HAVERQ!$C:$C,'Chart Data'!$BG20,HAVERQ!L:L)/SUMIF(HAVERQ!$A:$A,'Chart Data'!$BG20,HAVERQ!G:G)) -> 40.05669 | BI20: =100*('Data Q to A'!AK32/'Data Q to A'!AL32) -> 36.612845 | BK20: 45383 | BL20: =DataQ!AQ212 -> -2.550798 | BM20: =DataQ!AR212 -> -1.896409 | BN20: =DataQ!AS212 -> -2.469674 | BO20: =DataQ!AT212 -> -0.728087 | BR20: =BX20 -> 2.1108336 | BS20: =MEDIAN(BX20:CD20) -> 2.2330381 | BT20: =MIN(BY20:CD20) -> 0.85470769 | BU20: =MAX(BY20:CD20)-BT20 -> 2.3368129 | BX20: =100*((DataQ!AU212/DataQ!AU208)-1) -> 2.1108336 | BY20: =100*((DataQ!AV212/DataQ!AV208)-1) -> 3.1915206 | BZ20: =100*((DataQ!AW212/DataQ!AW208)-1) -> 2.7267288 | CA20: =100*((DataQ!AX212/DataQ!AX208)-1) -> 2.2330381 | CB20: =100*((DataQ!AY212/DataQ!AY208)-1) -> 2.2056875 | CC20: =100*((DataQ!AZ212/DataQ!AZ208)-1) -> 0.85470769 | CD20: =100*((DataQ!BA212/DataQ!BA208)-1) -> 2.7511196 | CF20: 1977 | CG20: =OBR_MAR26_C4.6!C47 -> 7.6961684 | CH20: =OBR_MAR26_C4.6!D47 -> 2.9544757 | CJ20: 43040 | CL20: ='[18]T4.43'!C16 -> 85.808696 | CM20: ='[18]T4.43'!D16 -> 86.455763 | CN20: ='[18]T4.43'!E16 -> 86.422084 | CO20: ='[18]T4.43'!F16 -> 86.10845 | CP20: ='[18]T4.43'!G16 -> 83.134737 | CQ20: ='[18]T4.43'!H16 -> 79.288509 | CR20: ='[18]T4.43'!I16 -> 79.054443 | DB20: 43040 | DD20: ='[18]T4.43'!C18 -> 2.3056284 | DE20: ='[18]T4.43'!D18 -> 2.4413815 | DF20: ='[18]T4.43'!E18 -> 1.8804656 | DG20: ='[18]T4.43'!F18 -> 1.6100221 | DH20: ='[18]T4.43'!G18 -> 1.4733212 | DI20: ='[18]T4.43'!H18 -> 1.308081 | DJ20: ='[18]T4.43'!I18 -> 1.0759828
BG21: 1998 | BH21: =100*(SUMIF(HAVERQ!$C:$C,'Chart Data'!$BG21,HAVERQ!L:L)/SUMIF(HAVERQ!$A:$A,'Chart Data'!$BG21,HAVERQ!G:G)) -> 38.146737 | BI21: =100*('Data Q to A'!AK33/'Data Q to A'!AL33) -> 35.516352 | BK21: 45474 | BL21: =DataQ!AQ213 -> -2.304361 | BM21: =DataQ!AR213 -> -1.963248 | BN21: =DataQ!AS213 -> -2.171902 | BO21: =DataQ!AT213 -> -0.7111451 | BR21: =BX21 -> 2.0547945 | BS21: =MEDIAN(BX21:CD21) -> 2.0248897 | BT21: =MIN(BY21:CD21) -> 1.0554954 | BU21: =MAX(BY21:CD21)-BT21 -> 1.7136055 | BX21: =100*((DataQ!AU213/DataQ!AU209)-1) -> 2.0547945 | BY21: =100*((DataQ!AV213/DataQ!AV209)-1) -> 2.6576119 | BZ21: =100*((DataQ!AW213/DataQ!AW209)-1) -> 2.7691009 | CA21: =100*((DataQ!AX213/DataQ!AX209)-1) -> 1.9323956 | CB21: =100*((DataQ!AY213/DataQ!AY209)-1) -> 1.7417055 | CC21: =100*((DataQ!AZ213/DataQ!AZ209)-1) -> 1.0554954 | CD21: =100*((DataQ!BA213/DataQ!BA209)-1) -> 2.0248897 | CF21: 1978 | CG21: =OBR_MAR26_C4.6!C48 -> 8.2497464 | CH21: =OBR_MAR26_C4.6!D48 -> 3.0445927 | CJ21: 42795 | CK21: ='[19]T4.41'!C16 -> 83.611666 | CL21: ='[19]T4.41'!D16 -> 86.571027 | CM21: ='[19]T4.41'!E16 -> 88.795212 | CN21: ='[19]T4.41'!F16 -> 88.496851 | CO21: ='[19]T4.41'!G16 -> 86.904105 | CP21: ='[19]T4.41'!H16 -> 82.976574 | CQ21: ='[19]T4.41'!I16 -> 79.795605 | DB21: 42795 | DC21: ='[19]T4.41'!C18 -> 3.7997915 | DD21: ='[19]T4.41'!D18 -> 2.6344292 | DE21: ='[19]T4.41'!E18 -> 2.8715301 | DF21: ='[19]T4.41'!F18 -> 1.9479472 | DG21: ='[19]T4.41'!G18 -> 0.98537529 | DH21: ='[19]T4.41'!H18 -> 0.91480607 | DI21: ='[19]T4.41'!I18 -> 0.71801817
BG22: 1999 | BH22: =100*(SUMIF(HAVERQ!$C:$C,'Chart Data'!$BG22,HAVERQ!L:L)/SUMIF(HAVERQ!$A:$A,'Chart Data'!$BG22,HAVERQ!G:G)) -> 36.94459 | BI22: =100*('Data Q to A'!AK34/'Data Q to A'!AL34) -> 32.730237 | BK22: 45566 | BL22: =DataQ!AQ214 -> -1.380183 | BM22: =DataQ!AR214 -> -1.07173 | BN22: =DataQ!AS214 -> -1.608057 | BO22: =DataQ!AT214 -> -0.5910925 | BR22: =BX22 -> 2.4753214 | BS22: =MEDIAN(BX22:CD22) -> 2.3242347 | BT22: =MIN(BY22:CD22) -> 1.1941351 | BU22: =MAX(BY22:CD22)-BT22 -> 1.7361027 | BX22: =100*((DataQ!AU214/DataQ!AU210)-1) -> 2.4753214 | BY22: =100*((DataQ!AV214/DataQ!AV210)-1) -> 2.7231785 | BZ22: =100*((DataQ!AW214/DataQ!AW210)-1) -> 2.9302378 | CA22: =100*((DataQ!AX214/DataQ!AX210)-1) -> 2.3242347 | CB22: =100*((DataQ!AY214/DataQ!AY210)-1) -> 1.270649 | CC22: =100*((DataQ!AZ214/DataQ!AZ210)-1) -> 1.1941351 | CD22: =100*((DataQ!BA214/DataQ!BA210)-1) -> 1.9081355 | CF22: 1979 | CG22: =OBR_MAR26_C4.6!C49 -> 8.7531871 | CH22: =OBR_MAR26_C4.6!D49 -> 3.262426 | CJ22: 42675 | CK22: ='[20]T4.40'!C16 -> 84.216421 | CL22: ='[20]T4.40'!D16 -> 87.302195 | CM22: ='[20]T4.40'!E16 -> 90.187612 | CN22: ='[20]T4.40'!F16 -> 89.6727 | CO22: ='[20]T4.40'!G16 -> 88.0211 | CP22: ='[20]T4.40'!H16 -> 84.847846 | CQ22: ='[20]T4.40'!I16 -> 81.563679 | DB22: 42675 | DC22: ='[20]T4.40'!C18 -> 4.0387713 | DD22: ='[20]T4.40'!D18 -> 3.4942744 | DE22: ='[20]T4.40'!E18 -> 2.946441 | DF22: ='[20]T4.40'!F18 -> 2.2327888 | DG22: ='[20]T4.40'!G18 -> 1.0126548 | DH22: ='[20]T4.40'!H18 -> 0.92048966 | DI22: ='[20]T4.40'!I18 -> 0.733998 | DU22: =100*((AVERAGE(HAVERQ!J7:J26)/AVERAGE(HAVERQ!J3:J22))-1) -> #N/A
BG23: 2000 | BH23: =100*(SUMIF(HAVERQ!$C:$C,'Chart Data'!$BG23,HAVERQ!L:L)/SUMIF(HAVERQ!$A:$A,'Chart Data'!$BG23,HAVERQ!G:G)) -> 31.639842 | BI23: =100*('Data Q to A'!AK35/'Data Q to A'!AL35) -> 28.560481 | BK23: 45658 | BL23: =DataQ!AQ215 -> -0.552002 | BM23: =DataQ!AR215 -> -0.6183422 | BN23: =DataQ!AS215 -> -0.7403606 | BO23: =DataQ!AT215 -> -0.3766288 | BQ23: 2025 | BR23: =BX23 -> 2.7973783 | BS23: =MEDIAN(BX23:CD23) -> 2.2775182 | BT23: =MIN(BY23:CD23) -> 1.0710117 | BU23: =MAX(BY23:CD23)-BT23 -> 2.6984276 | BW23: 2025 | BX23: =100*((DataQ!AU215/DataQ!AU211)-1) -> 2.7973783 | BY23: =100*((DataQ!AV215/DataQ!AV211)-1) -> 2.7239904 | BZ23: =100*((DataQ!AW215/DataQ!AW211)-1) -> 3.7694393 | CA23: =100*((DataQ!AX215/DataQ!AX211)-1) -> 2.2535499 | CB23: =100*((DataQ!AY215/DataQ!AY211)-1) -> 1.0710117 | CC23: =100*((DataQ!AZ215/DataQ!AZ211)-1) -> 1.6666633 | CD23: =100*((DataQ!BA215/DataQ!BA211)-1) -> 2.2775182 | CF23: 1980 | CG23: =OBR_MAR26_C4.6!C50 -> 8.8974986 | CH23: =OBR_MAR26_C4.6!D50 -> 3.424806 | DT23: 1965 | DU23: =100*((AVERAGE(HAVERQ!J8:J27)/AVERAGE(HAVERQ!J4:J23))-1) -> #N/A
BG24: 2001 | BH24: =100*(SUMIF(HAVERQ!$C:$C,'Chart Data'!$BG24,HAVERQ!L:L)/SUMIF(HAVERQ!$A:$A,'Chart Data'!$BG24,HAVERQ!G:G)) -> 30.427485 | BI24: =100*('Data Q to A'!AK36/'Data Q to A'!AL36) -> 28.25414 | BK24: 45748 | BL24: =DataQ!AQ216 -> -0.2413776 | BM24: =DataQ!AR216 -> -0.6384518 | BN24: =DataQ!AS216 -> -0.2694005 | BO24: =DataQ!AT216 -> -0.3859788 | BR24: =BX24 -> 3.4869498 | BS24: =MEDIAN(BX24:CD24) -> 2.1002526 | BT24: =MIN(BY24:CD24) -> 0.81892597 | BU24: =MAX(BY24:CD24)-BT24 -> 2.5761666 | BX24: =100*((DataQ!AU216/DataQ!AU212)-1) -> 3.4869498 | BY24: =100*((DataQ!AV216/DataQ!AV212)-1) -> 2.4610268 | BZ24: =100*((DataQ!AW216/DataQ!AW212)-1) -> 3.3950926 | CA24: =100*((DataQ!AX216/DataQ!AX212)-1) -> 2.1002526 | CB24: =100*((DataQ!AY216/DataQ!AY212)-1) -> 0.81892597 | CC24: =100*((DataQ!AZ216/DataQ!AZ212)-1) -> 1.6949084 | CD24: =100*((DataQ!BA216/DataQ!BA212)-1) -> 1.8057285 | CF24: 1981 | CG24: =OBR_MAR26_C4.6!C51 -> 9.2124473 | CH24: =OBR_MAR26_C4.6!D51 -> 3.7598037 | DU24: =100*((AVERAGE(HAVERQ!J9:J28)/AVERAGE(HAVERQ!J5:J24))-1) -> #N/A
BG25: 2002 | BH25: =100*(SUMIF(HAVERQ!$C:$C,'Chart Data'!$BG25,HAVERQ!L:L)/SUMIF(HAVERQ!$A:$A,'Chart Data'!$BG25,HAVERQ!G:G)) -> 31.233269 | BI25: =100*('Data Q to A'!AK37/'Data Q to A'!AL37) -> 30.139612 | BK25: 45839 | BL25: =DataQ!AQ217 -> 0.08038092 | BM25: =DataQ!AR217 -> -0.6522727 | BN25: =DataQ!AS217 -> 0.1669607 | BO25: =DataQ!AT217 -> -0.2569222 | BR25: =BX25 -> 3.803132 | BS25: =MEDIAN(BX25:CD25) -> 2.2302196 | BT25: =MIN(BY25:CD25) -> 1.0083417 | BU25: =MAX(BY25:CD25)-BT25 -> 1.893088 | BX25: =100*((DataQ!AU217/DataQ!AU213)-1) -> 3.803132 | BY25: =100*((DataQ!AV217/DataQ!AV213)-1) -> 2.9014297 | BZ25: =100*((DataQ!AW217/DataQ!AW213)-1) -> 2.8781069 | CA25: =100*((DataQ!AX217/DataQ!AX213)-1) -> 2.2302196 | CB25: =100*((DataQ!AY217/DataQ!AY213)-1) -> 1.0083417 | CC25: =100*((DataQ!AZ217/DataQ!AZ213)-1) -> 1.5835614 | CD25: =100*((DataQ!BA217/DataQ!BA213)-1) -> 1.9847017 | CF25: 1982 | CG25: =OBR_MAR26_C4.6!C52 -> 9.0962455 | CH25: =OBR_MAR26_C4.6!D52 -> 3.6860724 | DU25: =100*((AVERAGE(HAVERQ!J10:J29)/AVERAGE(HAVERQ!J6:J25))-1) -> #N/A
BG26: 2003 | BH26: =100*(SUMIF(HAVERQ!$C:$C,'Chart Data'!$BG26,HAVERQ!L:L)/SUMIF(HAVERQ!$A:$A,'Chart Data'!$BG26,HAVERQ!G:G)) -> 32.852304 | BI26: =100*('Data Q to A'!AK38/'Data Q to A'!AL38) -> 31.195293 | BK26: 45931 | BL26: =DataQ!AQ218 -> 0.013731 | BM26: =DataQ!AR218 -> -0.5917101 | BN26: =DataQ!AS218 -> 0.2965423 | BO26: =DataQ!AT218 -> -0.08502853 | BR26: =BX26 -> 3.3769049 | BS26: =MEDIAN(BX26:CD26) -> 2.2427778 | BT26: =MIN(BY26:CD26) -> 0.8779602 | BU26: =MAX(BY26:CD26)-BT26 -> 1.9519981 | BX26: =100*((DataQ!AU218/DataQ!AU214)-1) -> 3.3769049 | BY26: =100*((DataQ!AV218/DataQ!AV214)-1) -> 2.8299583 | BZ26: =100*((DataQ!AW218/DataQ!AW214)-1) -> 2.6650204 | CA26: =100*((DataQ!AX218/DataQ!AX214)-1) -> 2.1606654 | CB26: =100*((DataQ!AY218/DataQ!AY214)-1) -> 0.8779602 | CC26: =100*((DataQ!AZ218/DataQ!AZ214)-1) -> 1.1126095 | CD26: =100*((DataQ!BA218/DataQ!BA214)-1) -> 2.2427778 | CF26: 1983 | CG26: =OBR_MAR26_C4.6!C53 -> 9.3554799 | CH26: =OBR_MAR26_C4.6!D53 -> 3.6875007 | DU26: =100*((AVERAGE(HAVERQ!J11:J30)/AVERAGE(HAVERQ!J7:J26))-1) -> #N/A
BG27: 2004 | BH27: =100*(SUMIF(HAVERQ!$C:$C,'Chart Data'!$BG27,HAVERQ!L:L)/SUMIF(HAVERQ!$A:$A,'Chart Data'!$BG27,HAVERQ!G:G)) -> 35.780319 | BI27: =100*('Data Q to A'!AK39/'Data Q to A'!AL39) -> 33.809731 | BK27: 46023 | BL27: =DataQ!AQ219 -> 0.1694608 | BM27: =DataQ!AR219 -> -0.369029 | BN27: =DataQ!AS219 -> 0.458383 | BO27: =DataQ!AT219 -> 0.2529943 | BQ27: 2026 | BR27: =BX27 -> 3.1134829 | BS27: =MEDIAN(BX27:CD27) -> 2.1450455 | BT27: =MIN(BY27:CD27) -> 0.95908246 | BU27: =MAX(BY27:CD27)-BT27 -> 1.7449476 | BW27: 2026 | BX27: =100*((DataQ!AU219/DataQ!AU215)-1) -> 3.1134829 | BY27: =100*((DataQ!AV219/DataQ!AV215)-1) -> 2.70403 | BZ27: =100*((DataQ!AW219/DataQ!AW215)-1) -> 1.4110181 | CA27: =100*((DataQ!AX219/DataQ!AX215)-1) -> 2.2865289 | CB27: =100*((DataQ!AY219/DataQ!AY215)-1) -> 0.95908246 | CC27: =100*((DataQ!AZ219/DataQ!AZ215)-1) -> 1.4051222 | CD27: =100*((DataQ!BA219/DataQ!BA215)-1) -> 2.1450455 | CF27: 1984 | CG27: =OBR_MAR26_C4.6!C54 -> 9.7248373 | CH27: =OBR_MAR26_C4.6!D54 -> 3.8063912 | DT27: 1966 | DU27: =100*((AVERAGE(HAVERQ!J12:J31)/AVERAGE(HAVERQ!J8:J27))-1) -> #N/A
BG28: 2005 | BH28: =100*(SUMIF(HAVERQ!$C:$C,'Chart Data'!$BG28,HAVERQ!L:L)/SUMIF(HAVERQ!$A:$A,'Chart Data'!$BG28,HAVERQ!G:G)) -> 36.964145 | BI28: =100*('Data Q to A'!AK40/'Data Q to A'!AL40) -> 34.610253 | BK28: 46113 | BL28: =DataQ!AQ220 -> 0.6252518 | BM28: =DataQ!AR220 -> -0.1839261 | BN28: =DataQ!AS220 -> 0.4592803 | BO28: =DataQ!AT220 -> 0.3214837 | CF28: 1985 | CG28: =OBR_MAR26_C4.6!C55 -> 10.232056 | CH28: =OBR_MAR26_C4.6!D55 -> 3.910175 | DU28: =100*((AVERAGE(HAVERQ!J13:J32)/AVERAGE(HAVERQ!J9:J28))-1) -> #N/A
BG29: 2006 | BH29: =100*(SUMIF(HAVERQ!$C:$C,'Chart Data'!$BG29,HAVERQ!L:L)/SUMIF(HAVERQ!$A:$A,'Chart Data'!$BG29,HAVERQ!G:G)) -> 37.524424 | BI29: =100*('Data Q to A'!AK41/'Data Q to A'!AL41) -> 35.359782 | BK29: 46204 | BL29: =DataQ!AQ221 -> 0.7767475 | BM29: =DataQ!AR221 -> -0.3246279 | BN29: =DataQ!AS221 -> 0.2457361 | BO29: =DataQ!AT221 -> 0.4101481 | CF29: 1986 | CG29: =OBR_MAR26_C4.6!C56 -> 10.198507 | CH29: =OBR_MAR26_C4.6!D56 -> 3.8053068 | DU29: =100*((AVERAGE(HAVERQ!J14:J33)/AVERAGE(HAVERQ!J10:J29))-1) -> #N/A
BG30: 2007 | BH30: =100*(SUMIF(HAVERQ!$C:$C,'Chart Data'!$BG30,HAVERQ!L:L)/SUMIF(HAVERQ!$A:$A,'Chart Data'!$BG30,HAVERQ!G:G)) -> 37.905137 | BI30: =100*('Data Q to A'!AK42/'Data Q to A'!AL42) -> 35.728886 | BK30: 46296 | BL30: =DataQ!AQ222 -> 0.8152063 | BM30: =DataQ!AR222 -> -0.3651996 | BN30: =DataQ!AS222 -> 0.1769158 | BO30: =DataQ!AT222 -> 0.3521092 | CF30: 1987 | CG30: =OBR_MAR26_C4.6!C57 -> 10.061053 | CH30: =OBR_MAR26_C4.6!D57 -> 3.6278937 | DU30: =100*((AVERAGE(HAVERQ!J15:J34)/AVERAGE(HAVERQ!J11:J30))-1) -> #N/A
BG31: 2008 | BH31: =100*(SUMIF(HAVERQ!$C:$C,'Chart Data'!$BG31,HAVERQ!L:L)/SUMIF(HAVERQ!$A:$A,'Chart Data'!$BG31,HAVERQ!G:G)) -> 44.780264 | BI31: =100*('Data Q to A'!AK43/'Data Q to A'!AL43) -> 49.862549 | BK31: 46388 | BL31: =DataQ!AQ223 -> 0.7842233 | BM31: =DataQ!AR223 -> -0.3061402 | BN31: =DataQ!AS223 -> 0.2104012 | BO31: =DataQ!AT223 -> 0.2867934 | CF31: 1988 | CG31: =OBR_MAR26_C4.6!C58 -> 9.4655916 | CH31: =OBR_MAR26_C4.6!D58 -> 3.351217 | DT31: 1967 | DU31: =100*((AVERAGE(HAVERQ!J16:J35)/AVERAGE(HAVERQ!J12:J31))-1) -> #N/A
BG32: 2009 | BH32: =100*(SUMIF(HAVERQ!$C:$C,'Chart Data'!$BG32,HAVERQ!L:L)/SUMIF(HAVERQ!$A:$A,'Chart Data'!$BG32,HAVERQ!G:G)) -> 57.827376 | BI32: =100*('Data Q to A'!AK44/'Data Q to A'!AL44) -> 64.993532 | BK32: 46478 | BL32: =DataQ!AQ224 -> 0.8207624 | BM32: =DataQ!AR224 -> -0.206615 | BN32: =DataQ!AS224 -> 0.2725015 | BO32: =DataQ!AT224 -> 0.2386544 | CF32: 1989 | CG32: =OBR_MAR26_C4.6!C59 -> 9.1654459 | CH32: =OBR_MAR26_C4.6!D59 -> 3.1698509 | DU32: =100*((AVERAGE(HAVERQ!J17:J36)/AVERAGE(HAVERQ!J13:J32))-1) -> #N/A
BG33: 2010 | BH33: =100*(SUMIF(HAVERQ!$C:$C,'Chart Data'!$BG33,HAVERQ!L:L)/SUMIF(HAVERQ!$A:$A,'Chart Data'!$BG33,HAVERQ!G:G)) -> 68.457377 | BI33: =100*('Data Q to A'!AK45/'Data Q to A'!AL45) -> 71.031041 | BK33: 46569 | BL33: =DataQ!AQ225 -> 0.8354957 | BM33: =DataQ!AR225 -> -0.1461685 | BN33: =DataQ!AS225 -> 0.2912283 | BO33: =DataQ!AT225 -> 0.2211438 | CF33: 1990 | CG33: =OBR_MAR26_C4.6!C60 -> 8.5982169 | CH33: =OBR_MAR26_C4.6!D60 -> 2.9040419 | DU33: =100*((AVERAGE(HAVERQ!J18:J37)/AVERAGE(HAVERQ!J14:J33))-1) -> #N/A
BG34: 2011 | BH34: =100*(SUMIF(HAVERQ!$C:$C,'Chart Data'!$BG34,HAVERQ!L:L)/SUMIF(HAVERQ!$A:$A,'Chart Data'!$BG34,HAVERQ!G:G)) -> 72.883059 | BI34: =100*('Data Q to A'!AK46/'Data Q to A'!AL46) -> 74.500734 | BK34: 46661 | BL34: =DataQ!AQ226 -> 0.9301975 | BM34: =DataQ!AR226 -> -0.08266401 | BN34: =DataQ!AS226 -> 0.2674636 | BO34: =DataQ!AT226 -> 0.2099167 | CF34: 1991 | CG34: =OBR_MAR26_C4.6!C61 -> 7.4988932 | CH34: =OBR_MAR26_C4.6!D61 -> 2.5054983 | DU34: =100*((AVERAGE(HAVERQ!J19:J38)/AVERAGE(HAVERQ!J15:J34))-1) -> #N/A
BG35: 2012 | BH35: =100*(SUMIF(HAVERQ!$C:$C,'Chart Data'!$BG35,HAVERQ!L:L)/SUMIF(HAVERQ!$A:$A,'Chart Data'!$BG35,HAVERQ!G:G)) -> 75.67677 | BI35: =100*('Data Q to A'!AK47/'Data Q to A'!AL47) -> 77.978517 | BK35: 46753 | BL35: =DataQ!AQ227 -> 0.9513316 | BM35: =DataQ!AR227 -> -0.01909375 | BN35: =DataQ!AS227 -> 0.2579789 | BO35: =DataQ!AT227 -> 0.1942207 | CF35: 1992 | CG35: =OBR_MAR26_C4.6!C62 -> 7.9763233 | CH35: =OBR_MAR26_C4.6!D62 -> 2.5470652 | DT35: 1968 | DU35: =100*((AVERAGE(HAVERQ!J20:J39)/AVERAGE(HAVERQ!J16:J35))-1) -> #N/A
BG36: 2013 | BH36: =100*(SUMIF(HAVERQ!$C:$C,'Chart Data'!$BG36,HAVERQ!L:L)/SUMIF(HAVERQ!$A:$A,'Chart Data'!$BG36,HAVERQ!G:G)) -> 76.744424 | BI36: =100*('Data Q to A'!AK48/'Data Q to A'!AL48) -> 79.808516 | BK36: 46844 | BL36: =DataQ!AQ228 -> 0.9089571 | BM36: =DataQ!AR228 -> 0.1041012 | BN36: =DataQ!AS228 -> 0.2833322 | BO36: =DataQ!AT228 -> 0.2446561 | CF36: 1993 | CG36: =OBR_MAR26_C4.6!C63 -> 8.4102631 | CH36: =OBR_MAR26_C4.6!D63 -> 2.625316 | DU36: =100*((AVERAGE(HAVERQ!J21:J40)/AVERAGE(HAVERQ!J17:J36))-1) -> #N/A
BG37: 2014 | BH37: =100*(SUMIF(HAVERQ!$C:$C,'Chart Data'!$BG37,HAVERQ!L:L)/SUMIF(HAVERQ!$A:$A,'Chart Data'!$BG37,HAVERQ!G:G)) -> 78.372495 | BI37: =100*('Data Q to A'!AK49/'Data Q to A'!AL49) -> 81.374222 | BK37: 46935 | BL37: =DataQ!AQ229 -> 0.8601605 | BM37: =DataQ!AR229 -> 0.2399063 | BN37: =DataQ!AS229 -> 0.325026 | BO37: =DataQ!AT229 -> 0.3469173 | CF37: 1994 | CG37: =OBR_MAR26_C4.6!C64 -> 8.7682396 | CH37: =OBR_MAR26_C4.6!D64 -> 2.8138696 | DU37: =100*((AVERAGE(HAVERQ!J22:J41)/AVERAGE(HAVERQ!J18:J37))-1) -> #N/A
BG38: 2015 | BH38: =100*(SUMIF(HAVERQ!$C:$C,'Chart Data'!$BG38,HAVERQ!L:L)/SUMIF(HAVERQ!$A:$A,'Chart Data'!$BG38,HAVERQ!G:G)) -> 78.870092 | BI38: =100*('Data Q to A'!AK50/'Data Q to A'!AL50) -> 81.36435 | BK38: 47027 | BL38: =DataQ!AQ230 -> 0.8025382 | BM38: =DataQ!AR230 -> 0.3580289 | BN38: =DataQ!AS230 -> 0.3521523 | BO38: =DataQ!AT230 -> 0.4395704 | CF38: 1995 | CG38: =OBR_MAR26_C4.6!C65 -> 9.2409988 | CH38: =OBR_MAR26_C4.6!D65 -> 3.062618 | DU38: =100*((AVERAGE(HAVERQ!J23:J42)/AVERAGE(HAVERQ!J19:J38))-1) -> #N/A
BG39: 2016 | BH39: =100*(SUMIF(HAVERQ!$C:$C,'Chart Data'!$BG39,HAVERQ!L:L)/SUMIF(HAVERQ!$A:$A,'Chart Data'!$BG39,HAVERQ!G:G)) -> 78.310866 | BI39: =100*('Data Q to A'!AK51/'Data Q to A'!AL51) -> 83.47221 | BK39: 47119 | BL39: =DataQ!AQ231 -> 0.7665976 | BM39: =DataQ!AR231 -> 0.4511135 | BN39: =DataQ!AS231 -> 0.3748323 | BO39: =DataQ!AT231 -> 0.5587473 | CF39: 1996 | CG39: =OBR_MAR26_C4.6!C66 -> 9.3515614 | CH39: =OBR_MAR26_C4.6!D66 -> 3.0209788 | DT39: 1969 | DU39: =100*((AVERAGE(HAVERQ!J24:J43)/AVERAGE(HAVERQ!J20:J39))-1) -> #N/A
BG40: 2017 | BH40: =100*(SUMIF(HAVERQ!$C:$C,'Chart Data'!$BG40,HAVERQ!L:L)/SUMIF(HAVERQ!$A:$A,'Chart Data'!$BG40,HAVERQ!G:G)) -> 76.685587 | BI40: =100*('Data Q to A'!AK52/'Data Q to A'!AL52) -> 82.36411 | BK40: 47209 | BL40: =DataQ!AQ232 -> 0.7271161 | BM40: =DataQ!AR232 -> 0.4757442 | BN40: =DataQ!AS232 -> 0.3635231 | BO40: =DataQ!AT232 -> 0.6299802 | CF40: 1997 | CG40: =OBR_MAR26_C4.6!C67 -> 8.9393045 | CH40: =OBR_MAR26_C4.6!D67 -> 3.0729976 | DU40: =100*((AVERAGE(HAVERQ!J25:J44)/AVERAGE(HAVERQ!J21:J40))-1) -> #N/A
...

Sheet HAVERQ
D1: 19601 !Q | E1: NMFX@UK | F1: MU74@UK | G1: YBHAQ@UK | H1: JW2QQ@UK | I1: A4YMQ@UK | J1: LZVBQ@UK | K1: BKPXQ@UK | L1: MDK2@UK
D2: .DESC | E2: UK: Central Government: Current Expenditure: Interest (NSA, Mil.GBP) | F2: UK: BoE: Curr Exp: Int & Divs Paid to Priv Sector/Rest of World (NSA, Mil.GBP) | G2: UK: Gross Domestic Product [GDP] (SA, Mil.Pounds) | H2: UK: Public Sector ex Finl Intervention: Total Current Expenditure (NSA, Mil.GBP) | I2: UK: Output per Worker: Whole Economy (SA, 2023=100) | J2: U.K.: Output per Hour Worked: Whole Economy (SA, 2023=100) | K2: UK: General Government Consolidated Gross Debt - Nominal (EOP, NSA, Mil.GBP) | L2: UK: General Government Net Debt (EOP, NSA, Mil.GBP)
D3: .T1 | E3: Q2-1997 <- Apr-1997 | F3: Q1-1997 <- Mar-1997 | G3: Q1-1955 | H3: Q1-1946 | I3: Q3-1959 | J3: Q1-1971 | K3: Q1-1975 | L3: Q1-1975 <- Mar-1975
D4: .TN | E4: Q1-2026 <- Apr-2026 | F4: Q1-2026 <- Apr-2026 | G4: Q1-2026 | H4: Q1-2026 | I4: Q4-2025 | J4: Q4-2025 | K4: Q1-2026 | L4: Q1-2026 <- Apr-2026
D5: .LSOURCE | E5: Office for National Statistics | F5: Office for National Statistics | G5: Office for National Statistics | H5: Office for National Statistics | I5: Office for National Statistics | J5: Office for National Statistics | K5: Office for National Statistics | L5: Office for National Statistics
