Workbook
Name _DLX1.INC: HAVERD!$B$3:$AU$8
Name _DLX2.INC: 'HAVER BoE'!$B$2:$BP$7
Name _DLX3.INC: HAVERM!$B$1:$AF$6
Name Data: [1]sheet0!$C$2

Sheet CHARTS>>

Sheet DATA>>

Sheet Chart Data
A1: Vote share | E1: Term premium forecast | K1: RLG forecasts | S1: Impact of tighter FC on economy | X1: Quoted mortgage rates | AB1: Margins | AI1: Diff vs expiring deal
K2: Feb | M2: May | O2: Diff | X2: End-date: | Y2: =HAVERM!D4 -> Apr-2026 | Z2: =HAVERM!E4 -> Apr-2026 | AI2: 2 year fix, 75% LTV ** | AJ2: 5 year fix, 75% LTV **
B3: 2024 general election | C3: 2026 local elections | F3: UK | G3: US | H3: Japan | I3: Germany | K3: 2026 | L3: 2027 | M3: 2026 | N3: 2027 | O3: 2026 | P3: 2027 | T3: GDP | U3: C | V3: IPNR | Y3: 2 year fix, 75% LTV | Z3: 5 year fix, 75% LTV | AB3: 2 year fix, 75% LTV | AC3: 5 year fix, 75% LTV | AE3: 2 year swap | AF3: 5 year swap | AI3: 2 year fix, 75% LTV | AJ3: 5 year fix, 75% LTV
A4: Labour | B4: 33.7 | C4: 17 | E4: 2020 | F4: =Data!C194 -> -1.400203 | G4: =Data!D194 -> -1.270818 | H4: =Data!E194 -> -0.4589267 | I4: =Data!F194 -> -1.554241 | K4: 4.501 | L4: 4.318 | M4: 4.549 | N4: 4.792 | O4: =M4-K4 -> 0.048 | P4: =N4-L4 -> 0.474 | S4: 2026 | T4: =100*(('Data - Scen'!C218/'Data - Base'!C218)-1) -> 0 | U4: =100*(('Data - Scen'!D218/'Data - Base'!D218)-1) -> 0 | V4: =100*(('Data - Scen'!E218/'Data - Base'!E218)-1) -> 0 | X4: 41640 | Y4: =HAVERM!D175 -> 2.37 | Z4: =HAVERM!E175 -> 3.34 | AB4: =Y4-AE4 -> #N/A | AC4: =Z4-AF4 -> #N/A | AE4: =HAVERM!F175 -> #N/A | AF4: =HAVERM!G175 -> #N/A | AH4: 41640
A5: Conserv. | B5: 23.7 | C5: 17 | F5: =Data!C195 -> -0.4742025 | G5: =Data!D195 -> -1.328421 | H5: =Data!E195 -> -0.3453717 | I5: =Data!F195 -> -1.170631 | K5: 4.492 | L5: 4.196 | M5: 4.97 | N5: 4.682 | O5: =M5-K5 -> 0.478 | P5: =N5-L5 -> 0.486 | T5: =100*(('Data - Scen'!C219/'Data - Base'!C219)-1) -> 0.024372929 | U5: =100*(('Data - Scen'!D219/'Data - Base'!D219)-1) -> 0.026024031 | V5: =100*(('Data - Scen'!E219/'Data - Base'!E219)-1) -> 0.03558939 | X5: 41671 | Y5: =HAVERM!D176 -> 2.38 | Z5: =HAVERM!E176 -> 3.45 | AB5: =Y5-AE5 -> #N/A | AC5: =Z5-AF5 -> #N/A | AE5: =HAVERM!F176 -> #N/A | AF5: =HAVERM!G176 -> #N/A | AH5: 41671
A6: Reform | B6: 14.3 | C6: 26 | F6: =Data!C196 -> 0.2480247 | G6: =Data!D196 -> -1.259258 | H6: =Data!E196 -> -0.205531 | I6: =Data!F196 -> -1.146578 | K6: 4.467 | L6: 4.07 | M6: 4.961 | N6: 4.54 | O6: =M6-K6 -> 0.494 | P6: =N6-L6 -> 0.47 | T6: =100*(('Data - Scen'!C220/'Data - Base'!C220)-1) -> 0.058185233 | U6: =100*(('Data - Scen'!D220/'Data - Base'!D220)-1) -> 0.066199594 | V6: =100*(('Data - Scen'!E220/'Data - Base'!E220)-1) -> 0.10267494 | X6: 41699 | Y6: =HAVERM!D177 -> 2.37 | Z6: =HAVERM!E177 -> 3.48 | AB6: =Y6-AE6 -> #N/A | AC6: =Z6-AF6 -> #N/A | AE6: =HAVERM!F177 -> #N/A | AF6: =HAVERM!G177 -> #N/A | AH6: 41699
A7: Lib. Dem. | B7: 12.2 | C7: 16 | F7: =Data!C197 -> 0.7901152 | G7: =Data!D197 -> -0.9656042 | H7: =Data!E197 -> -0.06359368 | I7: =Data!F197 -> -1.126168 | K7: 4.412 | L7: 3.956 | M7: 4.88 | N7: 4.372 | O7: =M7-K7 -> 0.468 | P7: =N7-L7 -> 0.416 | Q7: =AVERAGE(O5:O7,P4:P7) -> 0.46942857 | T7: =100*(('Data - Scen'!C221/'Data - Base'!C221)-1) -> 0.10765458 | U7: =100*(('Data - Scen'!D221/'Data - Base'!D221)-1) -> 0.12617001 | V7: =100*(('Data - Scen'!E221/'Data - Base'!E221)-1) -> 0.2094553 | X7: 41730 | Y7: =HAVERM!D178 -> 2.54 | Z7: =HAVERM!E178 -> 3.69 | AB7: =Y7-AE7 -> #N/A | AC7: =Z7-AF7 -> #N/A | AE7: =HAVERM!F178 -> #N/A | AF7: =HAVERM!G178 -> #N/A | AH7: 41730
A8: Green | B8: 6.4 | C8: 18 | E8: 2021 | F8: =Data!C198 -> 1.541162 | G8: =Data!D198 -> -0.4946406 | H8: =Data!E198 -> -0.0002151728 | I8: =Data!F198 -> -0.8528938 | S8: 2027 | T8: =100*(('Data - Scen'!C222/'Data - Base'!C222)-1) -> 0.15659114 | U8: =100*(('Data - Scen'!D222/'Data - Base'!D222)-1) -> 0.19033725 | V8: =100*(('Data - Scen'!E222/'Data - Base'!E222)-1) -> 0.32678249 | X8: 41760 | Y8: =HAVERM!D179 -> 2.56 | Z8: =HAVERM!E179 -> 3.72 | AB8: =Y8-AE8 -> #N/A | AC8: =Z8-AF8 -> #N/A | AE8: =HAVERM!F179 -> #N/A | AF8: =HAVERM!G179 -> #N/A | AH8: 41760
A9: Other | B9: =100-SUM(B4:B8) -> 9.7 | C9: 6 | F9: =Data!C199 -> 1.185967 | G9: =Data!D199 -> -0.3768889 | H9: =Data!E199 -> 0.02403095 | I9: =Data!F199 -> -1.156042 | K9: RCB forecasts | T9: =100*(('Data - Scen'!C223/'Data - Base'!C223)-1) -> 0.18874361 | U9: =100*(('Data - Scen'!D223/'Data - Base'!D223)-1) -> 0.2458776 | V9: =100*(('Data - Scen'!E223/'Data - Base'!E223)-1) -> 0.42328042 | X9: 41791 | Y9: =HAVERM!D180 -> 2.6 | Z9: =HAVERM!E180 -> 3.69 | AB9: =Y9-AE9 -> #N/A | AC9: =Z9-AF9 -> #N/A | AE9: =HAVERM!F180 -> #N/A | AF9: =HAVERM!G180 -> #N/A | AH9: 41791
F10: =Data!C200 -> 0.5780302 | G10: =Data!D200 -> -0.8651952 | H10: =Data!E200 -> -0.07522835 | I10: =Data!F200 -> -1.259767 | K10: Feb | M10: May | O10: Diff | T10: =100*(('Data - Scen'!C224/'Data - Base'!C224)-1) -> 0.20621222 | U10: =100*(('Data - Scen'!D224/'Data - Base'!D224)-1) -> 0.29101465 | V10: =100*(('Data - Scen'!E224/'Data - Base'!E224)-1) -> 0.48333277 | X10: 41821 | Y10: =HAVERM!D181 -> 2.54 | Z10: =HAVERM!E181 -> 3.78 | AB10: =Y10-AE10 -> #N/A | AC10: =Z10-AF10 -> #N/A | AE10: =HAVERM!F181 -> #N/A | AF10: =HAVERM!G181 -> #N/A | AH10: 41821
F11: =Data!C201 -> 0.4362244 | G11: =Data!D201 -> -0.9455727 | H11: =Data!E201 -> -0.1353906 | I11: =Data!F201 -> -1.106633 | K11: 2026 | L11: 2027 | M11: 2026 | N11: 2027 | O11: 2026 | P11: 2027 | T11: =100*(('Data - Scen'!C225/'Data - Base'!C225)-1) -> 0.21144683 | U11: =100*(('Data - Scen'!D225/'Data - Base'!D225)-1) -> 0.32735412 | V11: =100*(('Data - Scen'!E225/'Data - Base'!E225)-1) -> 0.50517386 | X11: 41852 | Y11: =HAVERM!D182 -> 2.54 | Z11: =HAVERM!E182 -> 3.76 | AB11: =Y11-AE11 -> 1.5588 | AC11: =Z11-AF11 -> 2.15 | AE11: =HAVERM!F182 -> 0.9812 | AF11: =HAVERM!G182 -> 1.61 | AH11: 41852
E12: 2022 | F12: =Data!C202 -> -0.005793571 | G12: =Data!D202 -> -1.035532 | H12: =Data!E202 -> -0.1517915 | I12: =Data!F202 -> -0.9248759 | K12: 3.75 | L12: 3.25 | M12: 3.75 | N12: 3.75 | O12: =M12-K12 -> 0 | P12: =N12-L12 -> 0.5 | X12: 41883 | Y12: =HAVERM!D183 -> 2.46 | Z12: =HAVERM!E183 -> 3.61 | AB12: =Y12-AE12 -> 1.4812727 | AC12: =Z12-AF12 -> 1.9375955 | AE12: =HAVERM!F183 -> 0.97872727 | AF12: =HAVERM!G183 -> 1.6724045 | AH12: 41883
F13: =Data!C203 -> -1.116444 | G13: =Data!D203 -> -0.9544389 | H13: =Data!E203 -> -0.3281502 | I13: =Data!F203 -> -0.7541516 | K13: 3.581 | L13: 3.077 | M13: 3.75 | N13: 3.75 | O13: =M13-K13 -> 0.169 | P13: =N13-L13 -> 0.673 | X13: 41913 | Y13: =HAVERM!D184 -> 2.21 | Z13: =HAVERM!E184 -> 3.27 | AB13: =Y13-AE13 -> 1.3656522 | AC13: =Z13-AF13 -> 1.8341696 | AE13: =HAVERM!F184 -> 0.84434783 | AF13: =HAVERM!G184 -> 1.4358304 | AH13: 41913
F14: =Data!C204 -> -2.262011 | G14: =Data!D204 -> -2.050474 | H14: =Data!E204 -> -0.6069162 | I14: =Data!F204 -> -1.08056 | K14: 3.5 | L14: 3 | M14: 3.75 | N14: 3.75 | O14: =M14-K14 -> 0.25 | P14: =N14-L14 -> 0.75 | X14: 41944 | Y14: =HAVERM!D185 -> 2.17 | Z14: =HAVERM!E185 -> 3.21 | AB14: =Y14-AE14 -> 1.4026833 | AC14: =Z14-AF14 -> 1.8787167 | AE14: =HAVERM!F185 -> 0.76731667 | AF14: =HAVERM!G185 -> 1.3312833 | AH14: 41944
F15: =Data!C205 -> -2.748286 | G15: =Data!D205 -> -2.42089 | H15: =Data!E205 -> -0.8705126 | I15: =Data!F205 -> -1.370171 | K15: 3.345 | L15: 3 | M15: 3.75 | N15: 3.591 | O15: =M15-K15 -> 0.405 | P15: =N15-L15 -> 0.591 | Q15: =AVERAGE(O13:O15,P12:P15) -> 0.47685714 | X15: 41974 | Y15: =HAVERM!D186 -> 2.08 | Z15: =HAVERM!E186 -> 3.21 | AB15: =Y15-AE15 -> 1.3790636 | AC15: =Z15-AF15 -> 2.0094227 | AE15: =HAVERM!F186 -> 0.70093636 | AF15: =HAVERM!G186 -> 1.2005773 | AH15: 41974
E16: 2023 | F16: =Data!C206 -> -4.198305 | G16: =Data!D206 -> -3.155869 | H16: =Data!E206 -> -0.8742595 | I16: =Data!F206 -> -2.290555 | X16: 42005 | Y16: =HAVERM!D187 -> 2.01 | Z16: =HAVERM!E187 -> 3.09 | AB16: =Y16-AE16 -> 1.4174286 | AC16: =Z16-AF16 -> 2.1329952 | AE16: =HAVERM!F187 -> 0.59257143 | AF16: =HAVERM!G187 -> 0.95700476 | AH16: 42005
F17: =Data!C207 -> -3.759159 | G17: =Data!D207 -> -3.433098 | H17: =Data!E207 -> -1.02899 | I17: =Data!F207 -> -2.461839 | X17: 42036 | Y17: =HAVERM!D188 -> 1.96 | Z17: =HAVERM!E188 -> 3.05 | AB17: =Y17-AE17 -> 1.280755 | AC17: =Z17-AF17 -> 1.92882 | AE17: =HAVERM!F188 -> 0.679245 | AF17: =HAVERM!G188 -> 1.12118 | AH17: 42036
F18: =Data!C208 -> -3.51581 | G18: =Data!D208 -> -2.936102 | H18: =Data!E208 -> -0.9281871 | I18: =Data!F208 -> -2.727603 | X18: 42064 | Y18: =HAVERM!D189 -> 1.99 | Z18: =HAVERM!E189 -> 2.98 | AB18: =Y18-AE18 -> 1.3028524 | AC18: =Z18-AF18 -> 1.8285952 | AE18: =HAVERM!F189 -> 0.68714762 | AF18: =HAVERM!G189 -> 1.1514048 | AH18: 42064
F19: =Data!C209 -> -3.460574 | G19: =Data!D209 -> -2.457488 | H19: =Data!E209 -> -0.7505955 | I19: =Data!F209 -> -2.915811 | X19: 42095 | Y19: =HAVERM!D190 -> 1.95 | Z19: =HAVERM!E190 -> 2.92 | AB19: =Y19-AE19 -> 1.3036476 | AC19: =Z19-AF19 -> 1.8594333 | AE19: =HAVERM!F190 -> 0.64635238 | AF19: =HAVERM!G190 -> 1.0605667 | AH19: 42095
E20: 2024 | F20: =Data!C210 -> -3.233632 | G20: =Data!D210 -> -2.455854 | H20: =Data!E210 -> -0.8963838 | I20: =Data!F210 -> -2.96869 | X20: 42125 | Y20: =HAVERM!D191 -> 1.9 | Z20: =HAVERM!E191 -> 2.86 | AB20: =Y20-AE20 -> 1.1638524 | AC20: =Z20-AF20 -> 1.5970476 | AE20: =HAVERM!F191 -> 0.73614762 | AF20: =HAVERM!G191 -> 1.2629524 | AH20: 42125
F21: =Data!C211 -> -2.550798 | G21: =Data!D211 -> -1.896409 | H21: =Data!E211 -> -0.728087 | I21: =Data!F211 -> -2.469674 | X21: 42156 | Y21: =HAVERM!D192 -> 1.83 | Z21: =HAVERM!E192 -> 2.82 | AB21: =Y21-AE21 -> 1.0497955 | AC21: =Z21-AF21 -> 1.4679636 | AE21: =HAVERM!F192 -> 0.78020455 | AF21: =HAVERM!G192 -> 1.3520364 | AH21: 42156
F22: =Data!C212 -> -2.304361 | G22: =Data!D212 -> -1.963248 | H22: =Data!E212 -> -0.7111451 | I22: =Data!F212 -> -2.171902 | X22: 42186 | Y22: =HAVERM!D193 -> 1.87 | Z22: =HAVERM!E193 -> 2.83 | AB22: =Y22-AE22 -> 1.0242609 | AC22: =Z22-AF22 -> 1.422013 | AE22: =HAVERM!F193 -> 0.84573913 | AF22: =HAVERM!G193 -> 1.407987 | AH22: 42186
F23: =Data!C213 -> -1.380183 | G23: =Data!D213 -> -1.07173 | H23: =Data!E213 -> -0.5910925 | I23: =Data!F213 -> -1.608057 | X23: 42217 | Y23: =HAVERM!D194 -> 1.95 | Z23: =HAVERM!E194 -> 2.92 | AB23: =Y23-AE23 -> 1.1439048 | AC23: =Z23-AF23 -> 1.5978381 | AE23: =HAVERM!F194 -> 0.80609524 | AF23: =HAVERM!G194 -> 1.3221619 | AH23: 42217
E24: 2025 | F24: =Data!C214 -> -0.552002 | G24: =Data!D214 -> -0.6183422 | H24: =Data!E214 -> -0.3766288 | I24: =Data!F214 -> -0.7403606 | X24: 42248 | Y24: =HAVERM!D195 -> 1.91 | Z24: =HAVERM!E195 -> 2.84 | AB24: =Y24-AE24 -> 1.1834227 | AC24: =Z24-AF24 -> 1.6508136 | AE24: =HAVERM!F195 -> 0.72657727 | AF24: =HAVERM!G195 -> 1.1891864 | AH24: 42248
F25: =Data!C215 -> -0.2427194 | G25: =Data!D215 -> -0.6384518 | H25: =Data!E215 -> -0.3859788 | I25: =Data!F215 -> -0.2694005 | X25: 42278 | Y25: =HAVERM!D196 -> 1.87 | Z25: =HAVERM!E196 -> 2.78 | AB25: =Y25-AE25 -> 1.2124818 | AC25: =Z25-AF25 -> 1.6863545 | AE25: =HAVERM!F196 -> 0.65751818 | AF25: =HAVERM!G196 -> 1.0936455 | AH25: 42278
F26: =Data!C216 -> 0.07717013 | G26: =Data!D216 -> -0.6522727 | H26: =Data!E216 -> -0.2569222 | I26: =Data!F216 -> 0.1669607 | X26: 42309 | Y26: =HAVERM!D197 -> 1.92 | Z26: =HAVERM!E197 -> 2.77 | AB26: =Y26-AE26 -> 1.1974619 | AC26: =Z26-AF26 -> 1.5989381 | AE26: =HAVERM!F197 -> 0.7225381 | AF26: =HAVERM!G197 -> 1.1710619 | AH26: 42309
F27: =Data!C217 -> 0.007980824 | G27: =Data!D217 -> -0.5917101 | H27: =Data!E217 -> -0.08502853 | I27: =Data!F217 -> 0.2965423 | X27: 42339 | Y27: =HAVERM!D198 -> 1.9 | Z27: =HAVERM!E198 -> 2.75 | AB27: =Y27-AE27 -> 1.1574739 | AC27: =Z27-AF27 -> 1.5918435 | AE27: =HAVERM!F198 -> 0.74252609 | AF27: =HAVERM!G198 -> 1.1581565 | AH27: 42339
E28: 2026 | F28: =Data!C218 -> 0.1418591 | G28: =Data!D218 -> -0.369029 | H28: =Data!E218 -> 0.2529943 | I28: =Data!F218 -> 0.458383 | X28: 42370 | Y28: =HAVERM!D199 -> 1.93 | Z28: =HAVERM!E199 -> 2.68 | AB28: =Y28-AE28 -> 1.3224 | AC28: =Z28-AF28 -> 1.6969905 | AE28: =HAVERM!F199 -> 0.6076 | AF28: =HAVERM!G199 -> 0.98300952 | AH28: 42370 | AI28: =Y28-Y4 -> -0.44
F29: =Data!C219 -> 0.5102613 | G29: =Data!D219 -> -0.2961555 | H29: =Data!E219 -> 0.3214837 | I29: =Data!F219 -> 0.4592803 | X29: 42401 | Y29: =HAVERM!D200 -> 1.95 | Z29: =HAVERM!E200 -> 2.73 | AB29: =Y29-AE29 -> 1.5433238 | AC29: =Z29-AF29 -> 2.1155333 | AE29: =HAVERM!F200 -> 0.40667619 | AF29: =HAVERM!G200 -> 0.61446667 | AH29: 42401 | AI29: =Y29-Y5 -> -0.43
F30: =Data!C220 -> 0.4649615 | G30: =Data!D220 -> -0.3544827 | H30: =Data!E220 -> 0.4101481 | I30: =Data!F220 -> 0.2457602 | X30: 42430 | Y30: =HAVERM!D201 -> 1.9 | Z30: =HAVERM!E201 -> 2.7 | AB30: =Y30-AE30 -> 1.4501435 | AC30: =Z30-AF30 -> 2.0500696 | AE30: =HAVERM!F201 -> 0.44985652 | AF30: =HAVERM!G201 -> 0.64993043 | AH30: 42430 | AI30: =Y30-Y6 -> -0.47
F31: =Data!C221 -> 0.3446136 | G31: =Data!D221 -> -0.3542929 | H31: =Data!E221 -> 0.3521092 | I31: =Data!F221 -> 0.1769397 | X31: 42461 | Y31: =HAVERM!D202 -> 1.84 | Z31: =HAVERM!E202 -> 2.71 | AB31: =Y31-AE31 -> 1.3879619 | AC31: =Z31-AF31 -> 2.0608476 | AE31: =HAVERM!F202 -> 0.4520381 | AF31: =HAVERM!G202 -> 0.64915238 | AH31: 42461 | AI31: =Y31-Y7 -> -0.7
E32: 2027 | F32: =Data!C222 -> 0.2126694 | G32: =Data!D222 -> -0.2746601 | H32: =Data!E222 -> 0.2867934 | I32: =Data!F222 -> 0.2104251 | X32: 42491 | Y32: =HAVERM!D203 -> 1.91 | Z32: =HAVERM!E203 -> 2.64 | AB32: =Y32-AE32 -> 1.4411136 | AC32: =Z32-AF32 -> 1.9507182 | AE32: =HAVERM!F203 -> 0.46888636 | AF32: =HAVERM!G203 -> 0.68928182 | AH32: 42491 | AI32: =Y32-Y8 -> -0.65
F33: =Data!C223 -> 0.2192936 | G33: =Data!D223 -> -0.1621642 | H33: =Data!E223 -> 0.2386544 | I33: =Data!F223 -> 0.2725015 | X33: 42522 | Y33: =HAVERM!D204 -> 1.75 | Z33: =HAVERM!E204 -> 2.54 | AB33: =Y33-AE33 -> 1.3929045 | AC33: =Z33-AF33 -> 2.0278727 | AE33: =HAVERM!F204 -> 0.35709545 | AF33: =HAVERM!G204 -> 0.51212727 | AH33: 42522 | AI33: =Y33-Y9 -> -0.85
F34: =Data!C224 -> 0.24489 | G34: =Data!D224 -> -0.1229942 | H34: =Data!E224 -> 0.2211438 | I34: =Data!F224 -> 0.2912043 | X34: 42552 | Y34: =HAVERM!D205 -> 1.72 | Z34: =HAVERM!E205 -> 2.51 | AB34: =Y34-AE34 -> 1.5872619 | AC34: =Z34-AF34 -> 2.2893238 | AE34: =HAVERM!F205 -> 0.1327381 | AF34: =HAVERM!G205 -> 0.22067619 | AH34: 42552 | AI34: =Y34-Y10 -> -0.82
F35: =Data!C225 -> 0.3653541 | G35: =Data!D225 -> -0.07734013 | H35: =Data!E225 -> 0.2099167 | I35: =Data!F225 -> 0.2674395 | X35: 42583 | Y35: =HAVERM!D206 -> 1.69 | Z35: =HAVERM!E206 -> 2.39 | AB35: =Y35-AE35 -> 1.5824 | AC35: =Z35-AF35 -> 2.2147217 | AE35: =HAVERM!F206 -> 0.1076 | AF35: =HAVERM!G206 -> 0.17527826 | AH35: 42583 | AI35: =Y35-Y11 -> -0.85
E36: 2028 | F36: =Data!C226 -> 0.4382534 | G36: =Data!D226 -> -0.02301836 | H36: =Data!E226 -> 0.1942207 | I36: =Data!F226 -> 0.257955 | X36: 42614 | Y36: =HAVERM!D207 -> 1.59 | Z36: =HAVERM!E207 -> 2.34 | AB36: =Y36-AE36 -> 1.4666318 | AC36: =Z36-AF36 -> 2.1336091 | AE36: =HAVERM!F207 -> 0.12336818 | AF36: =HAVERM!G207 -> 0.20639091 | AH36: 42614 | AI36: =Y36-Y12 -> -0.87
F37: =Data!C227 -> 0.5065141 | G37: =Data!D227 -> 0.09917021 | H37: =Data!E227 -> 0.2446561 | I37: =Data!F227 -> 0.2833562 | X37: 42644 | Y37: =HAVERM!D208 -> 1.52 | Z37: =HAVERM!E208 -> 2.27 | AB37: =Y37-AE37 -> 1.3240381 | AC37: =Z37-AF37 -> 1.9146571 | AE37: =HAVERM!F208 -> 0.1959619 | AF37: =HAVERM!G208 -> 0.35534286 | AH37: 42644 | AI37: =Y37-Y13 -> -0.69
F38: =Data!C228 -> 0.5948478 | G38: =Data!D228 -> 0.2112072 | H38: =Data!E228 -> 0.3469173 | I38: =Data!F228 -> 0.325026 | X38: 42675 | Y38: =HAVERM!D209 -> 1.43 | Z38: =HAVERM!E209 -> 2.25 | AB38: =Y38-AE38 -> 1.1526455 | AC38: =Z38-AF38 -> 1.6863136 | AE38: =HAVERM!F209 -> 0.27735455 | AF38: =HAVERM!G209 -> 0.56368636 | AH38: 42675 | AI38: =Y38-Y14 -> -0.74
F39: =Data!C229 -> 0.6895179 | G39: =Data!D229 -> 0.3133483 | H39: =Data!E229 -> 0.4395704 | I39: =Data!F229 -> 0.3521523 | X39: 42705 | Y39: =HAVERM!D210 -> 1.45 | Z39: =HAVERM!E210 -> 2.26 | AB39: =Y39-AE39 -> 1.1509364 | AC39: =Z39-AF39 -> 1.6513864 | AE39: =HAVERM!F210 -> 0.29906364 | AF39: =HAVERM!G210 -> 0.60861364 | AH39: 42705 | AI39: =Y39-Y15 -> -0.63
E40: 2029 | F40: =Data!C230 -> 0.7829341 | G40: =Data!D230 -> 0.3990054 | H40: =Data!E230 -> 0.5587473 | I40: =Data!F230 -> 0.3748323 | X40: 42736 | Y40: =HAVERM!D211 -> 1.45 | Z40: =HAVERM!E211 -> 2.22 | AB40: =Y40-AE40 -> 1.1252182 | AC40: =Z40-AF40 -> 1.61045 | AE40: =HAVERM!F211 -> 0.32478182 | AF40: =HAVERM!G211 -> 0.60955 | AH40: 42736 | AI40: =Y40-Y16 -> -0.56
...

Sheet HAVERD
C1: UK | D1: US | E1: Germany | F1: Italy | G1: Japan | H1: New Zealand | I1: Sweden | J1: Canada | K1: France | L1: Spain | M1: Australia | O1: UK | P1: US | R1: UK | S1: UK | T1: US | U1: US | V1: Eurozone | W1: Eurozone | AS1: CALCULATIONS >> | AT1: UK | AU1: US | AV1: Eurozone | BA1: UK | BB1: US | BD1: =C1 -> UK | BE1: =D1 -> US | BF1: =E1 -> Germany | BG1: =F1 -> Italy | BH1: =G1 -> Japan | BI1: =H1 -> New Zealand | BJ1: =I1 -> Sweden | BK1: =J1 -> Canada | ... BN1: =M1 -> Australia | BQ1: RLG since 27/2 | CC1: =AT1 -> UK | CD1: =AU1 -> US | CE1: =AV1 -> Eurozone | CG1: Yield curve
C2: 10-year | D2: 10-year | E2: 10-year | O2: 2-year | P2: 2-year | R2: 1yr | S2: 2yr | T2: 1yr | U2: 2yr | V2: 1yr | W2: 2yr | Y2: 1Y | Z2: 2Y | AA2: 3Y | AB2: 4Y | AC2: 5Y | AD2: 6Y | AE2: 7Y | AF2: 8Y | AG2: 9Y | AH2: 10Y | AI2: 15Y | AJ2: 20Y | AK2: 30Y | AT2: 1y1y fwd | AU2: 1y1y fwd | AV2: 1y1y fwd | AX2: 10-year Gilt-US Treasury spread | AY2: Spread in policy rate expectations (1y1y OIS GBP-USD) | BA2: 2s10s | BB2: 2s10s | BD2: RLG since 27/2 | BE2: RLG since 27/2 | BF2: RLG since 27/2 | BG2: RLG since 27/2 | BH2: RLG since 27/2 | BI2: RLG since 27/2 | BJ2: RLG since 27/2 | BK2: RLG since 27/2 | BL2: RLG since 27/2 | BM2: RLG since 27/2 | BN2: RLG since 27/2 | BQ2: =RANK(BQ4,$BQ$4:$CA$4) -> 1 | BR2: =RANK(BR4,$BQ$4:$CA$4) -> 4 | BS2: =RANK(BS4,$BQ$4:$CA$4) -> 7 | BT2: =RANK(BT4,$BQ$4:$CA$4) -> 2 | BU2: =RANK(BU4,$BQ$4:$CA$4) -> 8 | BV2: =RANK(BV4,$BQ$4:$CA$4) -> 10 | BW2: =RANK(BW4,$BQ$4:$CA$4) -> 11 | BX2: =RANK(BX4,$BQ$4:$CA$4) -> 6 | ... CA2: =RANK(CA4,$BQ$4:$CA$4) -> 9 | CC2: 1yr1yr forward rate since 27/2 | CD2: 1yr1yr forward rate since 27/2 | CE2: 1yr1yr forward rate since 27/2 | CI2: 1Y | CJ2: 2Y | CK2: 3Y | CL2: 4Y | CM2: 5Y | CN2: 6Y | CO2: 7Y | CP2: 8Y | CQ2: 9Y | CR2: 10Y | CS2: 15Y | CT2: 20Y | CU2: 30Y
B3: 1240101 !D | C3: T112GA@INTDAILY | D3: R111GA@INTDAILY | E3: T134GA@INTDAILY | F3: T136GA@INTDAILY | G3: T158GA@INTDAILY | H3: T196GA@INTDAILY | I3: T144GA@INTDAILY | J3: T156GA@INTDAILY | K3: T132GA@INTDAILY | L3: T184GA@INTDAILY | M3: R193MA@INTDAILY | O3: T112G2@INTDAILY | P3: T111G2@INTDAILY | R3: M112I1Y@INTDAILY | S3: M112IHH@INTDAILY | T3: MUSAU1Y@INTDAILY | U3: MUSAU2Y@INTDAILY | V3: M02321M@INTDAILY | W3: M02341M@INTDAILY | Y3: T112G1@INTDAILY | Z3: T112G2@INTDAILY | AA3: T112G3@INTDAILY | AB3: T112G4@INTDAILY | AC3: T112G5@INTDAILY | AD3: T112G6@INTDAILY | AE3: T112G7@INTDAILY | AF3: T112G8@INTDAILY | AG3: T112G9@INTDAILY | AH3: T112GA@INTDAILY | AI3: T112GF@INTDAILY | AJ3: T112GK@INTDAILY | AK3: T112GT@INTDAILY | AL3: R11212F@INTDAILY | AM3: R11224F@INTDAILY | AN3: R11236F@INTDAILY | AO3: R11248F@INTDAILY | AP3: R11260F@INTDAILY | AQ3: R112I6A@INTDAILY | BQ3: =BD1 -> UK | BR3: =BE1 -> US | BS3: =BF1 -> Germany | BT3: =BG1 -> Italy | BU3: =BH1 -> Japan | BV3: =BI1 -> New Zealand | BW3: =BJ1 -> Sweden | BX3: =BK1 -> Canada | ... CA3: =BN1 -> Australia | CG3: 46080 | CH3: Pre-conflict | CI3: =INDEX($Y$9:$AK$723,MATCH($CG3,$A$9:$A$723,0),MATCH(CI$2,$Y$2:$AK$2,0)) -> 3.52 | CJ3: =INDEX($Y$9:$AK$723,MATCH($CG3,$A$9:$A$723,0),MATCH(CJ$2,$Y$2:$AK$2,0)) -> 3.69 | CK3: =INDEX($Y$9:$AK$723,MATCH($CG3,$A$9:$A$723,0),MATCH(CK$2,$Y$2:$AK$2,0)) -> 3.76 | CL3: =INDEX($Y$9:$AK$723,MATCH($CG3,$A$9:$A$723,0),MATCH(CL$2,$Y$2:$AK$2,0)) -> 3.68 | CM3: =INDEX($Y$9:$AK$723,MATCH($CG3,$A$9:$A$723,0),MATCH(CM$2,$Y$2:$AK$2,0)) -> 3.8 | CN3: =INDEX($Y$9:$AK$723,MATCH($CG3,$A$9:$A$723,0),MATCH(CN$2,$Y$2:$AK$2,0)) -> 3.85 | CO3: =INDEX($Y$9:$AK$723,MATCH($CG3,$A$9:$A$723,0),MATCH(CO$2,$Y$2:$AK$2,0)) -> 4.02 | CP3: =INDEX($Y$9:$AK$723,MATCH($CG3,$A$9:$A$723,0),MATCH(CP$2,$Y$2:$AK$2,0)) -> 4.17 | ... CU3: =INDEX($Y$9:$AK$723,MATCH($CG3,$A$9:$A$723,0),MATCH(CU$2,$Y$2:$AK$2,0)) -> 4.99
B4: .DESC | C4: UK: 10-Yr Government Bond Yield (%) | D4: U.S.: 10-Year Treasury Note Yield at Constant Maturity ( % p.a.) | E4: Germany: 10-Yr Government Bond Yield (%) | F4: Italy: 10-Yr Government Bond Yield (%) | G4: Japan: 10-Yr Government Bond Yield (%) | H4: New Zealand: 10-Yr Government Bond Yield (%) | I4: Sweden: 10-Yr Government Bond Yield (%) | J4: Canada: 10-Yr Government Bond Yield (%) | K4: France: 10-Yr Government Bond Yield (%) | L4: Spain: 10-Yr Government Bond Yield (%) | M4: Australia: 10 Year Treasury Bond Mid Yield (% p.a.) | O4: UK: 2-Yr Government Bond Yield (%) | P4: US: 2-Yr Treasury Note Yield (%) | R4: UK: 12 Month Overnight Index Swap[Ann,Act/365]v SONIA:Mid Rate[2PM ET](%p.a) | S4: UK: 24 Month Overnight Index Swap[Ann,Act/365]v SONIA:Mid Rate[2PM ET](%p.a) | T4: U.S: OIS [Act/360 Ann] vs SOFR: 1 Year Mid [NYK/LCH, 7AM ET] (% p.a) | U4: U.S: OIS [Act/360 Ann] vs SOFR: 2 Year Mid [NYK/LCH, 7AM ET] (% p.a) | V4: Euro Area: 1 Yr Int Rt Swp[Ann,Act/360]v 3 M EURIBOR[IMM Dt 1]:Mid Rt[2PM ET](%) | W4: Euro Area: 2 Yr Int Rt Swp[Ann,Act/360]v 3 M EURIBOR[IMM Dt 1]:Mid Rt[2PM ET](%) | Y4: UK: 1-Yr Government Bond Yield (%) | Z4: UK: 2-Yr Government Bond Yield (%) | AA4: UK: 3-Yr Government Bond Yield (%) | AB4: UK: 4-Yr Government Bond Yield (%) | AC4: UK: 5-Yr Government Bond Yield (%) | AD4: UK: 6-Yr Government Bond Yield (%) | AE4: UK: 7-Yr Government Bond Yield (%) | AF4: UK: 8-Yr Government Bond Yield (%) | AG4: UK: 9-Yr Government Bond Yield (%) | AH4: UK: 10-Yr Government Bond Yield (%) | AI4: UK: 15-Yr Government Bond Yield (%) | AJ4: UK: 20-Yr Government Bond Yield (%) | AK4: UK: 30-Yr Government Bond Yield (%) | AL4: UK: Overnight Index Swap: Forward Yields, 12-Month (% p.a.) | AM4: UK: Overnight Index Swap: Forward Yields, 24-Month (% p.a.) | AN4: UK: Overnight Index Swap: Forward Yields, 36-Month (% p.a.) | AO4: UK: Overnight Index Swap: Forward Yields, 48-Month (% p.a.) | AP4: UK: Overnight Index Swap: Forward Yields, 60-Month (% p.a.) | AQ4: UK: Overnight Index Swap: Forward Yields, 6-Year (% p.a.) | BP4: 46153 | BQ4: =INDEX($BD$9:$BN$723,MATCH($BP4,$A$9:$A$723,0),MATCH(BQ$3,$BD$1:$BN$1,0))+BQ5 -> 71.00001 | BR4: =INDEX($BD$9:$BN$723,MATCH($BP4,$A$9:$A$723,0),MATCH(BR$3,$BD$1:$BN$1,0))+BR5 -> 45.00002 | BS4: =INDEX($BD$9:$BN$723,MATCH($BP4,$A$9:$A$723,0),MATCH(BS$3,$BD$1:$BN$1,0))+BS5 -> 41.00003 | BT4: =INDEX($BD$9:$BN$723,MATCH($BP4,$A$9:$A$723,0),MATCH(BT$3,$BD$1:$BN$1,0))+BT5 -> 51.00004 | BU4: =INDEX($BD$9:$BN$723,MATCH($BP4,$A$9:$A$723,0),MATCH(BU$3,$BD$1:$BN$1,0))+BU5 -> 40.10005 | BV4: =INDEX($BD$9:$BN$723,MATCH($BP4,$A$9:$A$723,0),MATCH(BV$3,$BD$1:$BN$1,0))+BV5 -> 34.00006 | BW4: =INDEX($BD$9:$BN$723,MATCH($BP4,$A$9:$A$723,0),MATCH(BW$3,$BD$1:$BN$1,0))+BW5 -> 20.00007 | BX4: =INDEX($BD$9:$BN$723,MATCH($BP4,$A$9:$A$723,0),MATCH(BX$3,$BD$1:$BN$1,0))+BX5 -> 41.00008 | ... CA4: =INDEX($BD$9:$BN$723,MATCH($BP4,$A$9:$A$723,0),MATCH(CA$3,$BD$1:$BN$1,0))+CA5 -> 34.06011 | CG4: 46153 | CH4: Latest | CI4: =INDEX($Y$9:$AK$723,MATCH($CG4,$A$9:$A$723,0),MATCH(CI$2,$Y$2:$AK$2,0)) -> 4.39 | CJ4: =INDEX($Y$9:$AK$723,MATCH($CG4,$A$9:$A$723,0),MATCH(CJ$2,$Y$2:$AK$2,0)) -> 4.48 | CK4: =INDEX($Y$9:$AK$723,MATCH($CG4,$A$9:$A$723,0),MATCH(CK$2,$Y$2:$AK$2,0)) -> 4.51 | CL4: =INDEX($Y$9:$AK$723,MATCH($CG4,$A$9:$A$723,0),MATCH(CL$2,$Y$2:$AK$2,0)) -> 4.53 | CM4: =INDEX($Y$9:$AK$723,MATCH($CG4,$A$9:$A$723,0),MATCH(CM$2,$Y$2:$AK$2,0)) -> 4.59 | CN4: =INDEX($Y$9:$AK$723,MATCH($CG4,$A$9:$A$723,0),MATCH(CN$2,$Y$2:$AK$2,0)) -> 4.63 | CO4: =INDEX($Y$9:$AK$723,MATCH($CG4,$A$9:$A$723,0),MATCH(CO$2,$Y$2:$AK$2,0)) -> 4.75 | CP4: =INDEX($Y$9:$AK$723,MATCH($CG4,$A$9:$A$723,0),MATCH(CP$2,$Y$2:$AK$2,0)) -> 4.89 | ... CU4: =INDEX($Y$9:$AK$723,MATCH($CG4,$A$9:$A$723,0),MATCH(CU$2,$Y$2:$AK$2,0)) -> 5.69
B5: .T1 | C5: 26-Jan-1994 | D5: 02-Jan-1962 | E5: 10-Jan-1994 | F5: 02-Jan-1995 | G5: 13-Sep-1985 | H5: 14-Jul-1994 | I5: 02-Jan-1992 | J5: 03-Jan-1989 | K5: 02-Feb-1994 | L5: 18-Mar-1994 | M5: 01-Mar-2006 | O5: 26-Jan-1994 | P5: 29-Sep-1986 | R5: 26-Aug-2014 | S5: 26-Aug-2014 | T5: 01-Mar-2021 | U5: 01-Mar-2021 | V5: 25-Aug-2014 | W5: 25-Aug-2014 | Y5: 16-Jul-1999 | Z5: 26-Jan-1994 | AA5: 03-Jan-1995 | AB5: 06-Mar-1995 | AC5: 03-Jan-1995 | AD5: 06-Mar-1995 | AE5: 18-Jul-1995 | AF5: 06-Mar-1995 | AG5: 06-Mar-1995 | AH5: 26-Jan-1994 | AI5: 03-Jan-1995 | AJ5: 03-Jan-1995 | AK5: 03-Jan-1995 | AL5: 02-Jan-2009 | AM5: 02-Jan-2009 | AN5: 02-Jan-2009 | AO5: 02-Jan-2009 | AP5: 02-Jan-2009 | AQ5: 02-Jan-2018 | BQ5: 1e-05 | BR5: =+BQ5+0.00001 -> 2e-05 | BS5: =+BR5+0.00001 -> 3e-05 | BT5: =+BS5+0.00001 -> 4e-05 | BU5: =+BT5+0.00001 -> 5e-05 | BV5: =+BU5+0.00001 -> 6e-05 | BW5: =+BV5+0.00001 -> 7e-05 | BX5: =+BW5+0.00001 -> 8e-05 | BY5: =+BX5+0.00001 -> 9e-05 | ... CA5: =+BZ5+0.00001 -> 0.00011
B6: .TN | C6: 11-May-2026 | D6: 11-May-2026 | E6: 11-May-2026 | F6: 11-May-2026 | G6: 11-May-2026 | H6: 11-May-2026 | I6: 11-May-2026 | J6: 11-May-2026 | K6: 11-May-2026 | L6: 11-May-2026 | M6: 11-May-2026 | O6: 11-May-2026 | P6: 11-May-2026 | R6: 11-May-2026 | S6: 11-May-2026 | T6: 11-May-2026 | U6: 11-May-2026 | V6: 11-May-2026 | W6: 11-May-2026 | Y6: 11-May-2026 | Z6: 11-May-2026 | AA6: 11-May-2026 | AB6: 11-May-2026 | AC6: 11-May-2026 | AD6: 11-May-2026 | AE6: 11-May-2026 | AF6: 11-May-2026 | AG6: 11-May-2026 | AH6: 11-May-2026 | AI6: 11-May-2026 | AJ6: 11-May-2026 | AK6: 11-May-2026 | AL6: 11-May-2026 | AM6: 11-May-2026 | AN6: 11-May-2026 | AO6: 11-May-2026 | AP6: 11-May-2026 | AQ6: 11-May-2026 | BQ6: 1 | BR6: 2 | BS6: 3 | BT6: 4 | BU6: 5 | BV6: 6 | BW6: 7 | BX6: 8 | BY6: 9 | BZ6: 10 | CA6: 11 | CH6: Diff | CI6: =CI4-CI3 -> 0.87 | CJ6: =CJ4-CJ3 -> 0.79 | CK6: =CK4-CK3 -> 0.75 | CL6: =CL4-CL3 -> 0.85 | CM6: =CM4-CM3 -> 0.79 | CN6: =CN4-CN3 -> 0.78 | CO6: =CO4-CO3 -> 0.73 | CP6: =CP4-CP3 -> 0.72 | ... CU6: =CU4-CU3 -> 0.7
B7: .LSOURCE | C7: London Stock Exchange Group | D7: U.S. Treasury | E7: London Stock Exchange Group | F7: London Stock Exchange Group | G7: London Stock Exchange Group | H7: London Stock Exchange Group | I7: London Stock Exchange Group | J7: London Stock Exchange Group | K7: London Stock Exchange Group | L7: London Stock Exchange Group | M7: Tullett Prebon Information/Haver Analytics | O7: London Stock Exchange Group | P7: London Stock Exchange Group | R7: Tullett Prebon Information/Haver Analytics | S7: Tullett Prebon Information/Haver Analytics | T7: Tullett Prebon Information | U7: Tullett Prebon Information | V7: Tullett Prebon Information/Haver Analytics | W7: Tullett Prebon Information/Haver Analytics | Y7: London Stock Exchange Group | Z7: London Stock Exchange Group | AA7: London Stock Exchange Group | AB7: London Stock Exchange Group | AC7: London Stock Exchange Group | AD7: London Stock Exchange Group | AE7: London Stock Exchange Group | AF7: London Stock Exchange Group | AG7: London Stock Exchange Group | AH7: London Stock Exchange Group | AI7: London Stock Exchange Group | AJ7: London Stock Exchange Group | AK7: London Stock Exchange Group | AL7: Bank of England | AM7: Bank of England | AN7: Bank of England | AO7: Bank of England | AP7: Bank of England | AQ7: Bank of England | BQ7: =HLOOKUP(BQ$6,$BQ$2:$CA$4,2,FALSE) -> UK | BR7: =HLOOKUP(BR$6,$BQ$2:$CA$4,2,FALSE) -> Italy | BS7: =HLOOKUP(BS$6,$BQ$2:$CA$4,2,FALSE) -> France | BT7: =HLOOKUP(BT$6,$BQ$2:$CA$4,2,FALSE) -> US | BU7: =HLOOKUP(BU$6,$BQ$2:$CA$4,2,FALSE) -> Spain | BV7: =HLOOKUP(BV$6,$BQ$2:$CA$4,2,FALSE) -> Canada | BW7: =HLOOKUP(BW$6,$BQ$2:$CA$4,2,FALSE) -> Germany | BX7: =HLOOKUP(BX$6,$BQ$2:$CA$4,2,FALSE) -> Japan | ... CA7: =HLOOKUP(CA$6,$BQ$2:$CA$4,2,FALSE) -> Sweden
B8: .DTLM | C8: May-11-2026 20:55 | D8: May-11-2026 21:02 | E8: May-11-2026 20:55 | F8: May-11-2026 20:55 | G8: May-11-2026 19:01 | H8: May-11-2026 19:01 | I8: May-11-2026 20:55 | J8: May-12-2026 01:49 | K8: May-11-2026 20:55 | L8: May-11-2026 20:55 | M8: May-11-2026 12:04 | O8: May-11-2026 20:55 | P8: May-12-2026 01:49 | R8: May-11-2026 19:04 | S8: May-11-2026 19:04 | T8: May-11-2026 12:04 | U8: May-11-2026 12:04 | V8: May-11-2026 19:04 | W8: May-11-2026 19:04 | Y8: May-11-2026 20:55 | Z8: May-11-2026 20:55 | AA8: May-11-2026 20:55 | AB8: May-11-2026 20:55 | AC8: May-11-2026 20:55 | AD8: May-11-2026 20:55 | AE8: May-11-2026 20:55 | AF8: May-11-2026 20:55 | AG8: May-11-2026 20:55 | AH8: May-11-2026 20:55 | AI8: May-11-2026 20:55 | AJ8: May-11-2026 20:55 | AK8: May-11-2026 20:55 | AL8: May-12-2026 10:28 | AM8: May-12-2026 10:28 | AN8: May-12-2026 10:28 | AO8: May-12-2026 10:28 | AP8: May-12-2026 10:28 | AQ8: May-12-2026 10:28 | BQ8: =HLOOKUP(BQ$6,$BQ$2:$CA$4,3,FALSE) -> 71.00001 | BR8: =HLOOKUP(BR$6,$BQ$2:$CA$4,3,FALSE) -> 51.00004 | BS8: =HLOOKUP(BS$6,$BQ$2:$CA$4,3,FALSE) -> 46.00009 | BT8: =HLOOKUP(BT$6,$BQ$2:$CA$4,3,FALSE) -> 45.00002 | BU8: =HLOOKUP(BU$6,$BQ$2:$CA$4,3,FALSE) -> 41.0001 | BV8: =HLOOKUP(BV$6,$BQ$2:$CA$4,3,FALSE) -> 41.00008 | BW8: =HLOOKUP(BW$6,$BQ$2:$CA$4,3,FALSE) -> 41.00003 | BX8: =HLOOKUP(BX$6,$BQ$2:$CA$4,3,FALSE) -> 40.10005 | ... CA8: =HLOOKUP(CA$6,$BQ$2:$CA$4,3,FALSE) -> 20.00007
A9: 45292 | B9: 240101 | C9: #N/A | D9: #N/A | E9: 2.02 | F9: 3.7 | G9: 0.619 | H9: #N/A | I9: 2.03 | J9: #N/A | K9: 2.56 | L9: 2.99 | M9: 3.9545 | O9: #N/A | P9: #N/A | R9: 4.7307 | S9: 4.0314 | T9: 4.766 | U9: 4.08 | V9: 2.94 | W9: 2.442 | Y9: 4.73 | Z9: #N/A | AA9: 3.59 | AB9: 3.41 | AC9: 3.46 | AD9: 3.35 | AE9: 3.37 | AF9: 3.45 | AG9: 3.44 | AH9: #N/A | AI9: 3.92 | AJ9: 4.09 | AK9: #N/A | AL9: #N/A | AM9: #N/A | AN9: #N/A | AO9: #N/A | AP9: #N/A | AQ9: #N/A | AT9: =(2*S9)-R9 -> 3.3321 | AU9: =(2*U9)-T9 -> 3.394 | AV9: =(2*W9)-V9 -> 1.944 | AX9: =(C9-D9)*100 -> #N/A | AY9: =(AT9-AU9)*100 -> -6.19 | BA9: =C9-O9 -> #N/A | BB9: =D9-P9 -> #N/A
A10: 45293 | B10: 240102 | C10: 3.65 | D10: 3.95 | E10: 2.07 | F10: 3.72 | G10: 0.625 | H10: 4.41 | I10: 2.06 | J10: 3.18 | K10: 2.6 | L10: 3.03 | M10: 4.0058 | O10: 4.06 | P10: 4.33 | R10: 4.7456 | S10: 4.0735 | T10: 4.793 | U10: 4.128 | V10: 2.975 | W10: 2.486 | Y10: 4.79 | Z10: 4.06 | AA10: 3.69 | AB10: 3.5 | AC10: 3.55 | AD10: 3.46 | AE10: 3.47 | AF10: 3.56 | AG10: 3.55 | AH10: 3.65 | AI10: 4.04 | AJ10: 4.22 | AK10: 4.28 | AL10: 3.8133507 | AM10: 3.122496 | AN10: 2.9397965 | AO10: 2.9139373 | AP10: 2.976615 | AQ10: 3.0953136 | AT10: =(2*S10)-R10 -> 3.4014 | AU10: =(2*U10)-T10 -> 3.463 | AV10: =(2*W10)-V10 -> 1.997 | AX10: =(C10-D10)*100 -> -30 | AY10: =(AT10-AU10)*100 -> -6.16 | BA10: =C10-O10 -> -0.41 | BB10: =D10-P10 -> -0.38
A11: 45294 | B11: 240103 | C11: 3.61 | D11: 3.91 | E11: 2 | F11: 3.69 | G11: 0.625 | H11: 4.53 | I11: 2.06 | J11: 3.16 | K11: 2.55 | L11: 2.99 | M11: 4.0489 | O11: 4.07 | P11: 4.32 | R11: 4.7514 | S11: 4.0626 | T11: 4.822 | U11: 4.166 | V11: 2.94 | W11: 2.428 | Y11: 4.82 | Z11: 4.07 | AA11: 3.68 | AB11: 3.51 | AC11: 3.55 | AD11: 3.47 | AE11: 3.45 | AF11: 3.54 | AG11: 3.52 | AH11: 3.61 | AI11: 3.99 | AJ11: 4.19 | AK11: 4.26 | AL11: 3.8103909 | AM11: 3.0582151 | AN11: 2.9010166 | AO11: 2.8980372 | AP11: 2.9573435 | AQ11: 3.066086 | AT11: =(2*S11)-R11 -> 3.3738 | AU11: =(2*U11)-T11 -> 3.51 | AV11: =(2*W11)-V11 -> 1.916 | AX11: =(C11-D11)*100 -> -30 | AY11: =(AT11-AU11)*100 -> -13.62 | BA11: =C11-O11 -> -0.46 | BB11: =D11-P11 -> -0.41
A12: 45295 | B12: 240104 | C12: 3.74 | D12: 3.99 | E12: 2.13 | F12: 3.82 | G12: 0.622 | H12: 4.57 | I12: 2.12 | J12: 3.24 | K12: 2.68 | L12: 3.12 | M12: 4.048 | O12: 4.22 | P12: 4.38 | R12: 4.811 | S12: 4.1761 | T12: 4.839 | U12: 4.172 | V12: 3.062 | W12: 2.579 | Y12: 4.96 | Z12: 4.22 | AA12: 3.82 | AB12: 3.66 | AC12: 3.7 | AD12: 3.61 | AE12: 3.59 | AF12: 3.67 | AG12: 3.65 | AH12: 3.74 | AI12: 4.12 | AJ12: 4.3 | AK12: 4.38 | AL12: 3.9458216 | AM12: 3.2268182 | AN12: 3.0787962 | AO12: 3.071935 | AP12: 3.1227582 | AQ12: 3.2155848 | AT12: =(2*S12)-R12 -> 3.5412 | AU12: =(2*U12)-T12 -> 3.505 | AV12: =(2*W12)-V12 -> 2.096 | AX12: =(C12-D12)*100 -> -25 | AY12: =(AT12-AU12)*100 -> 3.62 | BA12: =C12-O12 -> -0.48 | BB12: =D12-P12 -> -0.39
A13: 45296 | B13: 240105 | C13: 3.81 | D13: 4.05 | E13: 2.18 | F13: 3.86 | G13: 0.605 | H13: 4.63 | I13: 2.21 | J13: 3.26 | K13: 2.72 | L13: 3.17 | M13: 4.1283 | O13: 4.24 | P13: 4.39 | R13: 4.8442 | S13: 4.2399 | T13: 4.883 | U13: 4.258 | V13: 3.099 | W13: 2.632 | Y13: 4.93 | Z13: 4.24 | AA13: 3.9 | AB13: 3.74 | AC13: 3.78 | AD13: 3.69 | AE13: 3.66 | AF13: 3.74 | AG13: 3.73 | AH13: 3.81 | AI13: 4.17 | AJ13: 4.35 | AK13: 4.42 | AL13: 4.0318583 | AM13: 3.3301963 | AN13: 3.1663868 | AO13: 3.1551932 | AP13: 3.1965007 | AQ13: 3.2772656 | AT13: =(2*S13)-R13 -> 3.6356 | AU13: =(2*U13)-T13 -> 3.633 | AV13: =(2*W13)-V13 -> 2.165 | AX13: =(C13-D13)*100 -> -24 | AY13: =(AT13-AU13)*100 -> 0.26 | BA13: =C13-O13 -> -0.43 | BB13: =D13-P13 -> -0.34
A14: =+A9+7 -> 45299 | B14: 240108 | C14: 3.77 | D14: 4.01 | E14: 2.14 | F14: 3.82 | G14: 0.603 | H14: 4.68 | I14: 2.21 | J14: 3.25 | K14: 2.67 | L14: 3.14 | M14: 4.1613 | O14: 4.19 | P14: 4.35 | R14: 4.8303 | S14: 4.2074 | T14: 4.86 | U14: 4.23 | V14: 3.082 | W14: 2.6 | Y14: 4.83 | Z14: 4.19 | AA14: 3.86 | AB14: 3.7 | AC14: 3.72 | AD14: 3.64 | AE14: 3.62 | AF14: 3.7 | AG14: 3.69 | AH14: 3.77 | AI14: 4.12 | AJ14: 4.31 | AK14: 4.38 | AL14: 3.9915985 | AM14: 3.3028128 | AN14: 3.1397409 | AO14: 3.1224812 | AP14: 3.1630678 | AQ14: 3.2511539 | AT14: =(2*S14)-R14 -> 3.5845 | AU14: =(2*U14)-T14 -> 3.6 | AV14: =(2*W14)-V14 -> 2.118 | AX14: =(C14-D14)*100 -> -24 | AY14: =(AT14-AU14)*100 -> -1.55 | BA14: =C14-O14 -> -0.42 | BB14: =D14-P14 -> -0.34
A15: =+A10+7 -> 45300 | B15: 240109 | C15: 3.79 | D15: 4.02 | E15: 2.19 | F15: 3.85 | G15: 0.588 | H15: 4.65 | I15: 2.27 | J15: 3.22 | K15: 2.72 | L15: 3.16 | M15: 4.1051 | O15: 4.21 | P15: 4.37 | R15: 4.8374 | S15: 4.2219 | T15: 4.854 | U15: 4.222 | V15: 3.136 | W15: 2.668 | Y15: 4.8 | Z15: 4.21 | AA15: 3.87 | AB15: 3.72 | AC15: 3.73 | AD15: 3.66 | AE15: 3.64 | AF15: 3.72 | AG15: 3.7 | AH15: 3.79 | AI15: 4.15 | AJ15: 4.32 | AK15: 4.4 | AL15: 4.0132622 | AM15: 3.3161053 | AN15: 3.1342282 | AO15: 3.1158539 | AP15: 3.1673712 | AQ15: 3.2636287 | AT15: =(2*S15)-R15 -> 3.6064 | AU15: =(2*U15)-T15 -> 3.59 | AV15: =(2*W15)-V15 -> 2.2 | AX15: =(C15-D15)*100 -> -23 | AY15: =(AT15-AU15)*100 -> 1.64 | BA15: =C15-O15 -> -0.42 | BB15: =D15-P15 -> -0.35
A16: =+A11+7 -> 45301 | B16: 240110 | C16: 3.82 | D16: 4.04 | E16: 2.23 | F16: 3.85 | G16: 0.584 | H16: 4.74 | I16: 2.25 | J16: 3.28 | K16: 2.76 | L16: 3.19 | M16: 4.121 | O16: 4.22 | P16: 4.37 | R16: 4.8524 | S16: 4.2558 | T16: 4.821 | U16: 4.187 | V16: 3.165 | W16: 2.702 | Y16: 4.86 | Z16: 4.22 | AA16: 3.88 | AB16: 3.74 | AC16: 3.75 | AD16: 3.68 | AE16: 3.67 | AF16: 3.76 | AG16: 3.74 | AH16: 3.82 | AI16: 4.18 | AJ16: 4.34 | AK16: 4.42 | AL16: 4.0516976 | AM16: 3.367845 | AN16: 3.1564854 | AO16: 3.1247781 | AP16: 3.1751377 | AQ16: 3.2731349 | AT16: =(2*S16)-R16 -> 3.6592 | AU16: =(2*U16)-T16 -> 3.553 | AV16: =(2*W16)-V16 -> 2.239 | AX16: =(C16-D16)*100 -> -22 | AY16: =(AT16-AU16)*100 -> 10.62 | BA16: =C16-O16 -> -0.4 | BB16: =D16-P16 -> -0.33
A17: =+A12+7 -> 45302 | B17: 240111 | C17: 3.85 | D17: 3.98 | E17: 2.19 | F17: 3.81 | G17: 0.594 | H17: 4.72 | I17: 2.23 | J17: 3.25 | K17: 2.73 | L17: 3.11 | M17: 4.1101 | O17: 4.25 | P17: 4.26 | R17: 4.8273 | S17: 4.2359 | T17: 4.804 | U17: 4.162 | V17: 3.138 | W17: 2.67 | Y17: 4.93 | Z17: 4.25 | AA17: 3.88 | AB17: 3.74 | AC17: 3.76 | AD17: 3.7 | AE17: 3.7 | AF17: 3.79 | AG17: 3.77 | AH17: 3.85 | AI17: 4.2 | AJ17: 4.36 | AK17: 4.44 | AL17: 4.0309256 | AM17: 3.3363711 | AN17: 3.180615 | AO17: 3.1794607 | AP17: 3.2379589 | AQ17: 3.3335096 | AT17: =(2*S17)-R17 -> 3.6445 | AU17: =(2*U17)-T17 -> 3.52 | AV17: =(2*W17)-V17 -> 2.202 | AX17: =(C17-D17)*100 -> -13 | AY17: =(AT17-AU17)*100 -> 12.45 | BA17: =C17-O17 -> -0.4 | BB17: =D17-P17 -> -0.28
A18: =+A13+7 -> 45303 | B18: 240112 | C18: 3.8 | D18: 3.96 | E18: 2.16 | F18: 3.75 | G18: 0.58 | H18: 4.64 | I18: 2.15 | J18: 3.22 | K18: 2.68 | L18: 3.1 | M18: 4.0743 | O18: 4.18 | P18: 4.14 | R18: 4.7549 | S18: 4.139 | T18: 4.737 | U18: 4.094 | V18: 3.04 | W18: 2.566 | Y18: 4.89 | Z18: 4.18 | AA18: 3.78 | AB18: 3.64 | AC18: 3.67 | AD18: 3.62 | AE18: 3.63 | AF18: 3.73 | AG18: 3.71 | AH18: 3.8 | AI18: 4.16 | AJ18: 4.34 | AK18: 4.43 | AL18: 3.906338 | AM18: 3.2413816 | AN18: 3.0985542 | AO18: 3.1066479 | AP18: 3.1735852 | AQ18: 3.2788019 | AT18: =(2*S18)-R18 -> 3.5231 | AU18: =(2*U18)-T18 -> 3.451 | AV18: =(2*W18)-V18 -> 2.092 | AX18: =(C18-D18)*100 -> -16 | AY18: =(AT18-AU18)*100 -> 7.21 | BA18: =C18-O18 -> -0.38 | BB18: =D18-P18 -> -0.18
A19: =+A14+7 -> 45306 | B19: 240115 | C19: 3.8 | D19: #N/A | E19: 2.2 | F19: 3.81 | G19: 0.558 | H19: 4.62 | I19: 2.16 | J19: 3.23 | K19: 2.73 | L19: 3.15 | M19: 4.078 | O19: 4.16 | P19: #N/A | R19: 4.7449 | S19: 4.1148 | T19: #N/A | U19: #N/A | V19: 3.103 | W19: 2.621 | Y19: 4.92 | Z19: 4.16 | AA19: 3.78 | AB19: 3.64 | AC19: 3.68 | AD19: 3.63 | AE19: 3.63 | AF19: 3.74 | AG19: 3.71 | AH19: 3.8 | AI19: 4.18 | AJ19: 4.36 | AK19: 4.46 | AL19: 3.882187 | AM19: 3.2212368 | AN19: 3.0832033 | AO19: 3.0955378 | AP19: 3.1690068 | AQ19: 3.2852854 | AT19: =(2*S19)-R19 -> 3.4847 | AU19: =(2*U19)-T19 -> #N/A | AV19: =(2*W19)-V19 -> 2.139 | AX19: =(C19-D19)*100 -> #N/A | AY19: =(AT19-AU19)*100 -> #N/A | BA19: =C19-O19 -> -0.36 | BB19: =D19-P19 -> #N/A
A20: =+A15+7 -> 45307 | B20: 240116 | C20: 3.83 | D20: 4.07 | E20: 2.25 | F20: 3.85 | G20: 0.591 | H20: 4.66 | I20: 2.2 | J20: 3.36 | K20: 2.78 | L20: 3.19 | M20: 4.1566 | O20: 4.19 | P20: 4.23 | R20: 4.7622 | S20: 4.1407 | T20: 4.683 | U20: 4.041 | V20: 3.124 | W20: 2.637 | Y20: 4.98 | Z20: 4.19 | AA20: 3.8 | AB20: 3.66 | AC20: 3.7 | AD20: 3.65 | AE20: 3.65 | AF20: 3.76 | AG20: 3.74 | AH20: 3.83 | AI20: 4.22 | AJ20: 4.41 | AK20: 4.51 | AL20: 3.8892679 | AM20: 3.2276975 | AN20: 3.1136786 | AO20: 3.1338846 | AP20: 3.2156826 | AQ20: 3.3398985 | AT20: =(2*S20)-R20 -> 3.5192 | AU20: =(2*U20)-T20 -> 3.399 | AV20: =(2*W20)-V20 -> 2.15 | AX20: =(C20-D20)*100 -> -24 | AY20: =(AT20-AU20)*100 -> 12.02 | BA20: =C20-O20 -> -0.36 | BB20: =D20-P20 -> -0.16
A21: =+A16+7 -> 45308 | B21: 240117 | C21: 3.98 | D21: 4.1 | E21: 2.28 | F21: 3.92 | G21: 0.609 | H21: 4.67 | I21: 2.25 | J21: 3.44 | K21: 2.82 | L21: 3.25 | M21: 4.2117 | O21: 4.38 | P21: 4.35 | R21: 4.9161 | S21: 4.3635 | T21: 4.758 | U21: 4.119 | V21: 3.221 | W21: 2.739 | Y21: 5.06 | Z21: 4.38 | AA21: 4 | AB21: 3.86 | AC21: 3.91 | AD21: 3.83 | AE21: 3.82 | AF21: 3.92 | AG21: 3.9 | AH21: 3.98 | AI21: 4.37 | AJ21: 4.54 | AK21: 4.64 | AL21: 4.1724997 | AM21: 3.5121132 | AN21: 3.3242844 | AO21: 3.3045953 | AP21: 3.3656448 | AQ21: 3.4747675 | AT21: =(2*S21)-R21 -> 3.8109 | AU21: =(2*U21)-T21 -> 3.48 | AV21: =(2*W21)-V21 -> 2.257 | AX21: =(C21-D21)*100 -> -12 | AY21: =(AT21-AU21)*100 -> 33.09 | BA21: =C21-O21 -> -0.4 | BB21: =D21-P21 -> -0.25
A22: =+A17+7 -> 45309 | B22: 240118 | C22: 3.94 | D22: 4.14 | E22: 2.32 | F22: 3.94 | G22: 0.643 | H22: 4.73 | I22: 2.26 | J22: 3.49 | K22: 2.85 | L22: 3.27 | M22: 4.2636 | O22: 4.31 | P22: 4.36 | R22: 4.8737 | S22: 4.2944 | T22: 4.783 | U22: 4.158 | V22: 3.197 | W22: 2.722 | Y22: 4.97 | Z22: 4.31 | AA22: 3.95 | AB22: 3.81 | AC22: 3.84 | AD22: 3.77 | AE22: 3.77 | AF22: 3.87 | AG22: 3.85 | AH22: 3.94 | AI22: 4.33 | AJ22: 4.51 | AK22: 4.61 | AL22: 4.1179306 | AM22: 3.4239054 | AN22: 3.2622235 | AO22: 3.2576652 | AP22: 3.3228304 | AQ22: 3.4345602 | AT22: =(2*S22)-R22 -> 3.7151 | AU22: =(2*U22)-T22 -> 3.533 | AV22: =(2*W22)-V22 -> 2.247 | AX22: =(C22-D22)*100 -> -20 | AY22: =(AT22-AU22)*100 -> 18.21 | BA22: =C22-O22 -> -0.37 | BB22: =D22-P22 -> -0.22
A23: =+A18+7 -> 45310 | B23: 240119 | C23: 3.92 | D23: 4.15 | E23: 2.3 | F23: 3.88 | G23: 0.664 | H23: 4.79 | I23: 2.3 | J23: 3.49 | K23: 2.83 | L23: 3.23 | M23: 4.2964 | O23: 4.29 | P23: 4.41 | R23: 4.8871 | S23: 4.3261 | T23: 4.803 | U23: 4.195 | V23: 3.265 | W23: 2.792 | Y23: 4.95 | Z23: 4.29 | AA23: 3.95 | AB23: 3.8 | AC23: 3.84 | AD23: 3.75 | AE23: 3.75 | AF23: 3.85 | AG23: 3.83 | AH23: 3.92 | AI23: 4.29 | AJ23: 4.46 | AK23: 4.56 | AL23: 4.1495841 | AM23: 3.4724444 | AN23: 3.2869698 | AO23: 3.2554136 | AP23: 3.2984134 | AQ23: 3.3935567 | AT23: =(2*S23)-R23 -> 3.7651 | AU23: =(2*U23)-T23 -> 3.587 | AV23: =(2*W23)-V23 -> 2.319 | AX23: =(C23-D23)*100 -> -23 | AY23: =(AT23-AU23)*100 -> 17.81 | BA23: =C23-O23 -> -0.37 | BB23: =D23-P23 -> -0.26
A24: =+A19+7 -> 45313 | B24: 240122 | C24: 3.91 | D24: 4.11 | E24: 2.26 | F24: 3.85 | G24: 0.653 | H24: 4.72 | I24: 2.29 | J24: 3.46 | K24: 2.79 | L24: 3.2 | M24: 4.23 | O24: 4.31 | P24: 4.38 | R24: 4.8696 | S24: 4.3097 | T24: 4.836 | U24: 4.221 | V24: 3.242 | W24: 2.751 | Y24: 4.95 | Z24: 4.31 | AA24: 3.97 | AB24: 3.82 | AC24: 3.85 | AD24: 3.77 | AE24: 3.75 | AF24: 3.84 | AG24: 3.82 | AH24: 3.91 | AI24: 4.27 | AJ24: 4.44 | AK24: 4.54 | AL24: 4.1228926 | AM24: 3.4913458 | AN24: 3.2940466 | AO24: 3.2473597 | AP24: 3.2848664 | AQ24: 3.3810345 | AT24: =(2*S24)-R24 -> 3.7498 | AU24: =(2*U24)-T24 -> 3.606 | AV24: =(2*W24)-V24 -> 2.26 | AX24: =(C24-D24)*100 -> -20 | AY24: =(AT24-AU24)*100 -> 14.38 | BA24: =C24-O24 -> -0.4 | BB24: =D24-P24 -> -0.27
A25: =+A20+7 -> 45314 | B25: 240123 | C25: 4 | D25: 4.14 | E25: 2.35 | F25: 3.93 | G25: 0.673 | H25: 4.7 | I25: 2.34 | J25: 3.47 | K25: 2.84 | L25: 3.27 | M25: 4.193 | O25: 4.38 | P25: 4.39 | R25: 4.9142 | S25: 4.3742 | T25: 4.849 | U25: 4.241 | V25: 3.259 | W25: 2.772 | Y25: 5.1 | Z25: 4.38 | AA25: 4.06 | AB25: 3.91 | AC25: 3.94 | AD25: 3.86 | AE25: 3.84 | AF25: 3.93 | AG25: 3.9 | AH25: 4 | AI25: 4.34 | AJ25: 4.51 | AK25: 4.59 | AL25: 4.2025817 | AM25: 3.5704832 | AN25: 3.3760902 | AO25: 3.3337293 | AP25: 3.3717084 | AQ25: 3.4630552 | AT25: =(2*S25)-R25 -> 3.8342 | AU25: =(2*U25)-T25 -> 3.633 | AV25: =(2*W25)-V25 -> 2.285 | AX25: =(C25-D25)*100 -> -14 | AY25: =(AT25-AU25)*100 -> 20.12 | BA25: =C25-O25 -> -0.38 | BB25: =D25-P25 -> -0.25
A26: =+A21+7 -> 45315 | B26: 240124 | C26: 4 | D26: 4.18 | E26: 2.35 | F26: 3.9 | G26: 0.719 | H26: 4.76 | I26: 2.35 | J26: 3.5 | K26: 2.85 | L26: 3.28 | M26: 4.2311 | O26: 4.38 | P26: 4.38 | R26: 4.9356 | S26: 4.3973 | T26: 4.814 | U26: 4.196 | V26: 3.251 | W26: 2.776 | Y26: 4.95 | Z26: 4.38 | AA26: 4.08 | AB26: 3.92 | AC26: 3.95 | AD26: 3.87 | AE26: 3.84 | AF26: 3.93 | AG26: 3.91 | AH26: 4 | AI26: 4.34 | AJ26: 4.51 | AK26: 4.59 | AL26: 4.2413794 | AM26: 3.5977218 | AN26: 3.3956214 | AO26: 3.3450975 | AP26: 3.3736588 | AQ26: 3.4577191 | AT26: =(2*S26)-R26 -> 3.859 | AU26: =(2*U26)-T26 -> 3.578 | AV26: =(2*W26)-V26 -> 2.301 | AX26: =(C26-D26)*100 -> -18 | AY26: =(AT26-AU26)*100 -> 28.1 | BA26: =C26-O26 -> -0.38 | BB26: =D26-P26 -> -0.2
A27: =+A22+7 -> 45316 | B27: 240125 | C27: 3.99 | D27: 4.14 | E27: 2.29 | F27: 3.83 | G27: 0.745 | H27: 4.76 | I27: 2.33 | J27: 3.48 | K27: 2.78 | L27: 3.18 | M27: 4.239 | O27: 4.37 | P27: 4.31 | R27: 4.9043 | S27: 4.359 | T27: 4.828 | U27: 4.228 | V27: 3.153 | W27: 2.664 | Y27: 4.93 | Z27: 4.37 | AA27: 4.04 | AB27: 3.89 | AC27: 3.92 | AD27: 3.85 | AE27: 3.83 | AF27: 3.92 | AG27: 3.9 | AH27: 3.99 | AI27: 4.34 | AJ27: 4.51 | AK27: 4.6 | AL27: 4.1762114 | AM27: 3.5261338 | AN27: 3.372546 | AO27: 3.3486961 | AP27: 3.3895437 | AQ27: 3.4778425 | AT27: =(2*S27)-R27 -> 3.8137 | AU27: =(2*U27)-T27 -> 3.628 | AV27: =(2*W27)-V27 -> 2.175 | AX27: =(C27-D27)*100 -> -15 | AY27: =(AT27-AU27)*100 -> 18.57 | BA27: =C27-O27 -> -0.38 | BB27: =D27-P27 -> -0.17
A28: =+A23+7 -> 45317 | B28: 240126 | C28: 3.97 | D28: 4.15 | E28: 2.3 | F28: 3.83 | G28: 0.716 | H28: 4.72 | I28: 2.36 | J28: 3.52 | K28: 2.79 | L28: 3.21 | M28: 4.239 | O28: 4.34 | P28: 4.37 | R28: 4.8807 | S28: 4.3207 | T28: 4.782 | U28: 4.168 | V28: 3.167 | W28: 2.689 | Y28: 4.89 | Z28: 4.34 | AA28: 4.01 | AB28: 3.85 | AC28: 3.89 | AD28: 3.82 | AE28: 3.81 | AF28: 3.91 | AG28: 3.88 | AH28: 3.97 | AI28: 4.33 | AJ28: 4.5 | AK28: 4.59 | AL28: 4.1361011 | AM28: 3.4827399 | AN28: 3.3349198 | AO28: 3.3284474 | AP28: 3.3763003 | AQ28: 3.4670205 | AT28: =(2*S28)-R28 -> 3.7607 | AU28: =(2*U28)-T28 -> 3.554 | AV28: =(2*W28)-V28 -> 2.211 | AX28: =(C28-D28)*100 -> -18 | AY28: =(AT28-AU28)*100 -> 20.67 | BA28: =C28-O28 -> -0.37 | BB28: =D28-P28 -> -0.22
A29: =+A24+7 -> 45320 | B29: 240129 | C29: 3.88 | D29: 4.08 | E29: 2.23 | F29: 3.74 | G29: 0.712 | H29: 4.75 | I29: 2.35 | J29: 3.45 | K29: 2.72 | L29: 3.12 | M29: 4.2193 | O29: 4.27 | P29: 4.32 | R29: 4.8403 | S29: #N/A | T29: 4.788 | U29: 4.181 | V29: 3.123 | W29: 2.632 | Y29: 4.87 | Z29: 4.27 | AA29: 3.94 | AB29: 3.78 | AC29: 3.81 | AD29: 3.74 | AE29: 3.73 | AF29: 3.82 | AG29: 3.8 | AH29: 3.88 | AI29: 4.25 | AJ29: 4.43 | AK29: 4.51 | AL29: 4.0609841 | AM29: 3.4125505 | AN29: 3.2642552 | AO29: 3.2506235 | AP29: 3.2913976 | AQ29: 3.3833081 | AT29: =(2*S29)-R29 -> #N/A | AU29: =(2*U29)-T29 -> 3.574 | AV29: =(2*W29)-V29 -> 2.141 | AX29: =(C29-D29)*100 -> -20 | AY29: =(AT29-AU29)*100 -> #N/A | BA29: =C29-O29 -> -0.39 | BB29: =D29-P29 -> -0.24
A30: =+A25+7 -> 45321 | B30: 240130 | C30: 3.9 | D30: 4.06 | E30: 2.27 | F30: 3.81 | G30: 0.702 | H30: 4.71 | I30: 2.34 | J30: 3.41 | K30: 2.76 | L30: 3.16 | M30: 4.1426 | O30: 4.33 | P30: 4.36 | R30: 4.8761 | S30: 4.318 | T30: 4.79 | U30: 4.173 | V30: 3.167 | W30: 2.68 | Y30: 4.93 | Z30: 4.33 | AA30: 4 | AB30: 3.84 | AC30: 3.86 | AD30: 3.77 | AE30: 3.76 | AF30: 3.85 | AG30: 3.82 | AH30: 3.9 | AI30: 4.27 | AJ30: 4.45 | AK30: 4.53 | AL30: 4.1444715 | AM30: 3.4983825 | AN30: 3.2994999 | AO30: 3.2551629 | AP30: 3.2980624 | AQ30: 3.3986548 | AT30: =(2*S30)-R30 -> 3.7599 | AU30: =(2*U30)-T30 -> 3.556 | AV30: =(2*W30)-V30 -> 2.193 | AX30: =(C30-D30)*100 -> -16 | AY30: =(AT30-AU30)*100 -> 20.39 | BA30: =C30-O30 -> -0.43 | BB30: =D30-P30 -> -0.3
A31: =+A26+7 -> 45322 | B31: 240131 | C31: 3.79 | D31: 3.99 | E31: 2.17 | F31: 3.72 | G31: 0.724 | H31: 4.63 | I31: 2.19 | J31: 3.32 | K31: 2.67 | L31: 3.12 | M31: 4.0135 | O31: 4.22 | P31: 4.23 | R31: 4.7962 | S31: 4.213 | T31: 4.805 | U31: 4.188 | V31: 3.108 | W31: 2.604 | Y31: 4.81 | Z31: 4.22 | AA31: 3.87 | AB31: 3.71 | AC31: 3.74 | AD31: 3.65 | AE31: 3.63 | AF31: 3.73 | AG31: 3.7 | AH31: 3.79 | AI31: 4.16 | AJ31: 4.35 | AK31: 4.45 | AL31: 4.0272195 | AM31: 3.3484123 | AN31: 3.1736842 | AO31: 3.1499939 | AP31: 3.1941967 | AQ31: 3.2908242 | AT31: =(2*S31)-R31 -> 3.6298 | AU31: =(2*U31)-T31 -> 3.571 | AV31: =(2*W31)-V31 -> 2.1 | AX31: =(C31-D31)*100 -> -20 | AY31: =(AT31-AU31)*100 -> 5.88 | BA31: =C31-O31 -> -0.43 | BB31: =D31-P31 -> -0.24
A32: =+A27+7 -> 45323 | B32: 240201 | C32: 3.76 | D32: 3.87 | E32: 2.16 | F32: 3.72 | G32: 0.686 | H32: 4.61 | I32: 2.16 | J32: 3.27 | K32: 2.66 | L32: 3.1 | M32: 4.0154 | O32: 4.24 | P32: 4.19 | R32: 4.8297 | S32: 4.2253 | T32: 4.73 | U32: 4.079 | V32: 3.156 | W32: 2.643 | Y32: 4.81 | Z32: 4.24 | AA32: 3.85 | AB32: 3.69 | AC32: 3.71 | AD32: 3.62 | AE32: 3.6 | AF32: 3.7 | AG32: 3.67 | AH32: 3.76 | AI32: 4.14 | AJ32: 4.33 | AK32: 4.43 | AL32: 4.0357457 | AM32: 3.290833 | AN32: 3.1267148 | AO32: 3.1156765 | AP32: 3.1671779 | AQ32: 3.2647526 | AT32: =(2*S32)-R32 -> 3.6209 | AU32: =(2*U32)-T32 -> 3.428 | AV32: =(2*W32)-V32 -> 2.13 | AX32: =(C32-D32)*100 -> -11 | AY32: =(AT32-AU32)*100 -> 19.29 | BA32: =C32-O32 -> -0.48 | BB32: =D32-P32 -> -0.32
A33: =+A28+7 -> 45324 | B33: 240202 | C33: 3.92 | D33: 4.03 | E33: 2.23 | F33: 3.82 | G33: 0.651 | H33: 4.6 | I33: 2.25 | J33: 3.38 | K33: 2.74 | L33: 3.16 | M33: 3.9823 | O33: 4.43 | P33: 4.37 | R33: 4.9085 | S33: 4.3523 | T33: 4.734 | U33: 4.084 | V33: 3.253 | W33: 2.745 | Y33: 4.96 | Z33: 4.43 | AA33: 4.05 | AB33: 3.89 | AC33: 3.91 | AD33: 3.81 | AE33: 3.78 | AF33: 3.86 | AG33: 3.83 | AH33: 3.92 | AI33: 4.28 | AJ33: 4.46 | AK33: 4.55 | AL33: 4.2314125 | AM33: 3.5046886 | AN33: 3.3004236 | AO33: 3.2740175 | AP33: 3.3153328 | AQ33: 3.4043849 | AT33: =(2*S33)-R33 -> 3.7961 | AU33: =(2*U33)-T33 -> 3.434 | AV33: =(2*W33)-V33 -> 2.237 | AX33: =(C33-D33)*100 -> -11 | AY33: =(AT33-AU33)*100 -> 36.21 | BA33: =C33-O33 -> -0.51 | BB33: =D33-P33 -> -0.34
A34: =+A29+7 -> 45327 | B34: 240205 | C34: 4 | D34: 4.17 | E34: 2.32 | F34: 3.87 | G34: 0.714 | H34: 4.71 | I34: 2.27 | J34: 3.51 | K34: 2.82 | L34: 3.23 | M34: 4.0996 | O34: 4.49 | P34: 4.47 | R34: 4.9633 | S34: 4.451 | T34: 4.911 | U34: 4.302 | V34: 3.281 | W34: 2.791 | Y34: 4.92 | Z34: 4.49 | AA34: 4.12 | AB34: 3.96 | AC34: 3.98 | AD34: 3.89 | AE34: 3.86 | AF34: 3.94 | AG34: 3.91 | AH34: 4 | AI34: 4.35 | AJ34: 4.52 | AK34: 4.61 | AL34: 4.2995466 | AM34: 3.6350742 | AN34: 3.4230267 | AO34: 3.3576259 | AP34: 3.3761608 | AQ34: 3.4611283 | AT34: =(2*S34)-R34 -> 3.9387 | AU34: =(2*U34)-T34 -> 3.693 | AV34: =(2*W34)-V34 -> 2.301 | AX34: =(C34-D34)*100 -> -17 | AY34: =(AT34-AU34)*100 -> 24.57 | BA34: =C34-O34 -> -0.49 | BB34: =D34-P34 -> -0.3
A35: =+A30+7 -> 45328 | B35: 240206 | C35: 3.94 | D35: 4.09 | E35: 2.28 | F35: 3.84 | G35: 0.726 | H35: 4.7 | I35: 2.28 | J35: 3.43 | K35: 2.79 | L35: 3.19 | M35: 4.1337 | O35: 4.43 | P35: 4.41 | R35: 4.9409 | S35: 4.419 | T35: 4.908 | U35: 4.322 | V35: 3.256 | W35: 2.764 | Y35: 4.76 | Z35: 4.43 | AA35: 4.08 | AB35: 3.92 | AC35: 3.94 | AD35: 3.84 | AE35: 3.81 | AF35: 3.89 | AG35: 3.85 | AH35: 3.94 | AI35: 4.29 | AJ35: 4.45 | AK35: 4.54 | AL35: 4.2673702 | AM35: 3.5957926 | AN35: 3.3766193 | AO35: 3.3052161 | AP35: 3.3236646 | AQ35: 3.4014301 | AT35: =(2*S35)-R35 -> 3.8971 | AU35: =(2*U35)-T35 -> 3.736 | AV35: =(2*W35)-V35 -> 2.272 | AX35: =(C35-D35)*100 -> -15 | AY35: =(AT35-AU35)*100 -> 16.11 | BA35: =C35-O35 -> -0.49 | BB35: =D35-P35 -> -0.32
A36: =+A31+7 -> 45329 | B36: 240207 | C36: 4 | D36: 4.09 | E36: 2.32 | F36: 3.89 | G36: 0.715 | H36: 4.79 | I36: 2.31 | J36: 3.48 | K36: 2.83 | L36: 3.24 | M36: 4.092 | O36: 4.48 | P36: 4.42 | R36: 4.9504 | S36: 4.4349 | T36: 4.868 | U36: 4.276 | V36: 3.301 | W36: 2.817 | Y36: 4.8 | Z36: 4.48 | AA36: 4.13 | AB36: 3.97 | AC36: 3.98 | AD36: 3.89 | AE36: 3.86 | AF36: 3.94 | AG36: 3.91 | AH36: 4 | AI36: 4.33 | AJ36: 4.49 | AK36: 4.58 | AL36: 4.2922424 | AM36: 3.6234413 | AN36: 3.3971393 | AO36: 3.3400918 | AP36: 3.3722969 | AQ36: 3.459763 | AT36: =(2*S36)-R36 -> 3.9194 | AU36: =(2*U36)-T36 -> 3.684 | AV36: =(2*W36)-V36 -> 2.333 | AX36: =(C36-D36)*100 -> -9 | AY36: =(AT36-AU36)*100 -> 23.54 | BA36: =C36-O36 -> -0.48 | BB36: =D36-P36 -> -0.33
A37: =+A32+7 -> 45330 | B37: 240208 | C37: 4.06 | D37: 4.15 | E37: 2.36 | F37: 3.94 | G37: 0.704 | H37: 4.79 | I37: 2.38 | J37: 3.55 | K37: 2.87 | L37: 3.31 | M37: 4.104 | O37: 4.55 | P37: 4.46 | R37: 4.9731 | S37: 4.4835 | T37: 4.869 | U37: 4.287 | V37: 3.338 | W37: 2.864 | Y37: 4.87 | Z37: 4.55 | AA37: 4.19 | AB37: 4.04 | AC37: 4.06 | AD37: 3.97 | AE37: 3.93 | AF37: 4.01 | AG37: 3.97 | AH37: 4.06 | AI37: 4.38 | AJ37: 4.54 | AK37: 4.62 | AL37: 4.3165857 | AM37: 3.7049529 | AN37: 3.492197 | AO37: 3.4251139 | AP37: 3.4407334 | AQ37: 3.5096235 | AT37: =(2*S37)-R37 -> 3.9939 | AU37: =(2*U37)-T37 -> 3.705 | AV37: =(2*W37)-V37 -> 2.39 | AX37: =(C37-D37)*100 -> -9 | AY37: =(AT37-AU37)*100 -> 28.89 | BA37: =C37-O37 -> -0.49 | BB37: =D37-P37 -> -0.31
A38: =+A33+7 -> 45331 | B38: 240209 | C38: 4.06 | D38: 4.17 | E38: 2.38 | F38: 3.96 | G38: 0.725 | H38: 4.88 | I38: 2.43 | J38: 3.55 | K38: 2.89 | L38: 3.36 | M38: 4.1276 | O38: 4.57 | P38: 4.49 | R38: 4.9961 | S38: 4.5318 | T38: 4.905 | U38: 4.334 | V38: 3.368 | W38: 2.897 | Y38: 4.88 | Z38: 4.57 | AA38: 4.22 | AB38: 4.06 | AC38: 4.08 | AD38: 3.99 | AE38: 3.94 | AF38: 4.02 | AG38: 3.98 | AH38: 4.06 | AI38: 4.38 | AJ38: 4.52 | AK38: 4.59 | AL38: 4.4001298 | AM38: 3.7510339 | AN38: 3.5239403 | AO38: 3.4549601 | AP38: 3.4555105 | AQ38: 3.5079092 | AT38: =(2*S38)-R38 -> 4.0675 | AU38: =(2*U38)-T38 -> 3.763 | AV38: =(2*W38)-V38 -> 2.426 | AX38: =(C38-D38)*100 -> -11 | AY38: =(AT38-AU38)*100 -> 30.45 | BA38: =C38-O38 -> -0.51 | BB38: =D38-P38 -> -0.32
A39: =+A34+7 -> 45334 | B39: 240212 | C39: 4.06 | D39: 4.17 | E39: 2.36 | F39: 3.9 | G39: 0.721 | H39: 4.91 | I39: 2.42 | J39: 3.58 | K39: 2.86 | L39: 3.32 | M39: 4.1613 | O39: 4.55 | P39: 4.47 | R39: 4.9594 | S39: 4.4775 | T39: 4.9 | U39: 4.323 | V39: 3.335 | W39: 2.862 | Y39: 4.83 | Z39: 4.55 | AA39: 4.2 | AB39: 4.05 | AC39: 4.06 | AD39: 3.97 | AE39: 3.93 | AF39: 4.01 | AG39: 3.98 | AH39: 4.06 | AI39: 4.37 | AJ39: 4.52 | AK39: 4.59 | AL39: 4.3545467 | AM39: 3.7385228 | AN39: 3.5187691 | AO39: 3.4426787 | AP39: 3.4487837 | AQ39: 3.5164127 | AT39: =(2*S39)-R39 -> 3.9956 | AU39: =(2*U39)-T39 -> 3.746 | AV39: =(2*W39)-V39 -> 2.389 | AX39: =(C39-D39)*100 -> -11 | AY39: =(AT39-AU39)*100 -> 24.96 | BA39: =C39-O39 -> -0.49 | BB39: =D39-P39 -> -0.3
A40: =+A35+7 -> 45335 | B40: 240213 | C40: 4.16 | D40: 4.31 | E40: 2.4 | F40: 3.96 | G40: 0.725 | H40: 4.9 | I40: 2.44 | J40: 3.65 | K40: 2.9 | L40: 3.37 | M40: 4.1747 | O40: 4.68 | P40: 4.66 | R40: 5.0727 | S40: 4.6386 | T40: 4.902 | U40: 4.331 | V40: 3.422 | W40: 2.954 | Y40: 4.95 | Z40: 4.68 | AA40: 4.34 | AB40: 4.19 | AC40: 4.2 | AD40: 4.1 | AE40: 4.04 | AF40: 4.11 | AG40: 4.08 | AH40: 4.16 | AI40: 4.47 | AJ40: 4.6 | AK40: 4.67 | AL40: 4.5397856 | AM40: 3.912166 | AN40: 3.6341962 | AO40: 3.5295794 | AP40: 3.5237192 | AQ40: 3.5806898 | AT40: =(2*S40)-R40 -> 4.2045 | AU40: =(2*U40)-T40 -> 3.76 | AV40: =(2*W40)-V40 -> 2.486 | AX40: =(C40-D40)*100 -> -15 | AY40: =(AT40-AU40)*100 -> 44.45 | BA40: =C40-O40 -> -0.52 | BB40: =D40-P40 -> -0.35
...

Sheet BoE market pricing
A1: Interest rates - OE forecast & market expectations - monthly
D2: 45292 | E2: 45323 | F2: 45352 | G2: 45383 | H2: 45413 | I2: 45444 | J2: 45474 | K2: 45505 | L2: 45536 | M2: 45566 | N2: 45597 | O2: 45627 | P2: 45658 | Q2: 45689 | R2: 45717 | S2: 45748 | T2: 45778 | U2: 45809 | V2: 45839 | W2: 45870 | X2: 45901 | Y2: 45931 | Z2: 45962 | AA2: 45992 | AB2: 46023 | AC2: 46054 | AD2: 46082 | AE2: 46113 | AF2: 46143 | AG2: 46174 | AH2: 46204 | AI2: 46235 | AJ2: 46266 | AK2: 46296 | AL2: 46327 | AM2: 46357 | AN2: 46388 | AO2: 46419 | AP2: 46447 | AQ2: 46478 | AR2: 46508 | AS2: 46539 | AT2: 46569 | AU2: 46600 | AV2: 46631 | AW2: 46661 | AX2: 46692 | AY2: 46722
D3: =EOMONTH(D2,0) -> 45322 | E3: =EOMONTH(E2,0) -> 45351 | F3: =EOMONTH(F2,0) -> 45382 | G3: =EOMONTH(G2,0) -> 45412 | H3: =EOMONTH(H2,0) -> 45443 | I3: =EOMONTH(I2,0) -> 45473 | J3: =EOMONTH(J2,0) -> 45504 | K3: =EOMONTH(K2,0) -> 45535 | ... AY3: =EOMONTH(AY2,0) -> 46752
A4: =C4 -> Bank Rate | B4: =C4 -> Bank Rate | C4: Bank Rate | D4: =VLOOKUP(D2,HAVERM!$A:$C,3,FALSE) -> 5.25 | E4: =VLOOKUP(E2,HAVERM!$A:$C,3,FALSE) -> 5.25 | F4: =VLOOKUP(F2,HAVERM!$A:$C,3,FALSE) -> 5.25 | G4: =VLOOKUP(G2,HAVERM!$A:$C,3,FALSE) -> 5.25 | H4: =VLOOKUP(H2,HAVERM!$A:$C,3,FALSE) -> 5.25 | I4: =VLOOKUP(I2,HAVERM!$A:$C,3,FALSE) -> 5.25 | J4: =VLOOKUP(J2,HAVERM!$A:$C,3,FALSE) -> 5.25 | K4: =VLOOKUP(K2,HAVERM!$A:$C,3,FALSE) -> 5 | ... AY4: =VLOOKUP(AY2,HAVERM!$A:$C,3,FALSE) -> #N/A
A5: Market expectations - Pre-conflict | B5: =C5 -> 46080 | C5: =C14 -> 46080 | D5: =HLOOKUP(D$3,$D$13:$AN$14,2,FALSE) -> #N/A | E5: =HLOOKUP(E$3,$D$13:$AN$14,2,FALSE) -> #N/A | F5: =HLOOKUP(F$3,$D$13:$AN$14,2,FALSE) -> #N/A | G5: =HLOOKUP(G$3,$D$13:$AN$14,2,FALSE) -> #N/A | H5: =HLOOKUP(H$3,$D$13:$AN$14,2,FALSE) -> #N/A | I5: =HLOOKUP(I$3,$D$13:$AN$14,2,FALSE) -> #N/A | J5: =HLOOKUP(J$3,$D$13:$AN$14,2,FALSE) -> #N/A | K5: =HLOOKUP(K$3,$D$13:$AN$14,2,FALSE) -> #N/A | ... AY5: =HLOOKUP(AY$3,$D$13:$AN$14,2,FALSE) -> 3.3130203
A6: Market expectations - Current | B6: =C6 -> 46153 | C6: =C22 -> 46153 | D6: =HLOOKUP(D$3,$D$21:$AN$22,2,FALSE) -> #N/A | E6: =HLOOKUP(E$3,$D$21:$AN$22,2,FALSE) -> #N/A | F6: =HLOOKUP(F$3,$D$21:$AN$22,2,FALSE) -> #N/A | G6: =HLOOKUP(G$3,$D$21:$AN$22,2,FALSE) -> #N/A | H6: =HLOOKUP(H$3,$D$21:$AN$22,2,FALSE) -> #N/A | I6: =HLOOKUP(I$3,$D$21:$AN$22,2,FALSE) -> #N/A | J6: =HLOOKUP(J$3,$D$21:$AN$22,2,FALSE) -> #N/A | K6: =HLOOKUP(K$3,$D$21:$AN$22,2,FALSE) -> #N/A | ... AY6: =HLOOKUP(AY$3,$D$21:$AN$22,2,FALSE) -> 4.442842
A7: =C7 -> OE forecast | C7: OE forecast | D7: =IF(D3>$E$1,HLOOKUP(D$3,$AK$34:$EN$35,2,FALSE),NA()) -> #N/A | E7: =IF(E3>$E$1,HLOOKUP(E$3,$AK$34:$EN$35,2,FALSE),NA()) -> #N/A | F7: =IF(F3>$E$1,HLOOKUP(F$3,$AK$34:$EN$35,2,FALSE),NA()) -> #N/A | G7: =IF(G3>$E$1,HLOOKUP(G$3,$AK$34:$EN$35,2,FALSE),NA()) -> #N/A | H7: =IF(H3>$E$1,HLOOKUP(H$3,$AK$34:$EN$35,2,FALSE),NA()) -> #N/A | I7: =IF(I3>$E$1,HLOOKUP(I$3,$AK$34:$EN$35,2,FALSE),NA()) -> #N/A | J7: =IF(J3>$E$1,HLOOKUP(J$3,$AK$34:$EN$35,2,FALSE),NA()) -> #N/A | K7: =IF(K3>$E$1,HLOOKUP(K$3,$AK$34:$EN$35,2,FALSE),NA()) -> #N/A | ... AD7: =IF(AD3>$E$1,HLOOKUP(AD$3,$AK$34:$EN$35,2,FALSE),NA()) -> #N/A | AE7: =AE4 -> 3.75 | AF7: =AE7 -> 3.75 | AG7: =AF7 -> 3.75 | AH7: =AG7 -> 3.75 | AI7: =AH7 -> 3.75 | AJ7: =AI7 -> 3.75 | AK7: =AJ7 -> 3.75 | AL7: =AK7 -> 3.75 | AM7: =AL7 -> 3.75 | ... AW7: =AV7 -> 3.75 | AX7: =AW7-0.25 -> 3.5 | AY7: =AX7 -> 3.5
C9: Column # | D9: 4 | E9: =+D9+1 -> 5 | F9: =+E9+1 -> 6 | G9: =+F9+1 -> 7 | H9: =+G9+1 -> 8 | I9: =+H9+1 -> 9 | J9: =+I9+1 -> 10 | K9: =+J9+1 -> 11 | L9: =+K9+1 -> 12 | ... BL9: =+BK9+1 -> 64
C10: Months | D10: ='HAVER BoE'!D1 -> Overnight | E10: ='HAVER BoE'!E1 -> 1 | F10: ='HAVER BoE'!F1 -> 2 | G10: ='HAVER BoE'!G1 -> 3 | H10: ='HAVER BoE'!H1 -> 4 | I10: ='HAVER BoE'!I1 -> 5 | J10: ='HAVER BoE'!J1 -> 6 | K10: ='HAVER BoE'!K1 -> 7 | ... BL10: ='HAVER BoE'!BL1 -> 60
C11: Days | E11: 30.416667 | F11: =+E11+30.4166667 -> 60.833333 | G11: =+F11+30.4166667 -> 91.25 | H11: =+G11+30.4166667 -> 121.66667 | I11: =+H11+30.4166667 -> 152.08333 | J11: =+I11+30.4166667 -> 182.5 | K11: =+J11+30.4166667 -> 212.91667 | L11: =+K11+30.4166667 -> 243.33333 | M11: =+L11+30.4166667 -> 273.75 | ... BL11: =+BK11+30.4166667 -> 1825
D12: =C14 -> 46080 | E12: =$D12+E11 -> 46110.417 | F12: =$D12+F11 -> 46140.833 | G12: =$D12+G11 -> 46171.25 | H12: =$D12+H11 -> 46201.667 | I12: =$D12+I11 -> 46232.083 | J12: =$D12+J11 -> 46262.5 | K12: =$D12+K11 -> 46292.917 | L12: =$D12+L11 -> 46323.333 | ... BL12: =$D12+BL11 -> 47905
D13: =EOMONTH(D12,0) -> 46081 | E13: =EOMONTH(E12,0) -> 46112 | F13: =EOMONTH(F12,0) -> 46142 | G13: =EOMONTH(G12,0) -> 46173 | H13: =EOMONTH(H12,0) -> 46203 | I13: =EOMONTH(I12,0) -> 46234 | J13: =EOMONTH(J12,0) -> 46265 | K13: =EOMONTH(K12,0) -> 46295 | ... BL13: =EOMONTH(BL12,0) -> 47907
C14: 46080 | D14: =VLOOKUP($C14,'HAVER BoE'!$A:$BL,D9,FALSE) -> 3.7267 | E14: =VLOOKUP($C14,'HAVER BoE'!$A:$BL,E9,FALSE) -> 3.5178962 | F14: =VLOOKUP($C14,'HAVER BoE'!$A:$BL,F9,FALSE) -> 3.4951976 | G14: =VLOOKUP($C14,'HAVER BoE'!$A:$BL,G9,FALSE) -> 3.4552224 | H14: =VLOOKUP($C14,'HAVER BoE'!$A:$BL,H9,FALSE) -> 3.4041663 | I14: =VLOOKUP($C14,'HAVER BoE'!$A:$BL,I9,FALSE) -> 3.3509989 | J14: =VLOOKUP($C14,'HAVER BoE'!$A:$BL,J9,FALSE) -> 3.3038578 | K14: =VLOOKUP($C14,'HAVER BoE'!$A:$BL,K9,FALSE) -> 3.265964 | ... BL14: =VLOOKUP($C14,'HAVER BoE'!$A:$BL,BL9,FALSE) -> 3.865903
C15: Diff vs overnight | E15: =E14-$D$14 -> -0.2088038 | F15: =F14-$D$14 -> -0.2315024 | G15: =G14-$D$14 -> -0.2714776 | H15: =H14-$D$14 -> -0.3225337 | I15: =I14-$D$14 -> -0.3757011 | J15: =J14-$D$14 -> -0.4228422 | K15: =K14-$D$14 -> -0.460736 | L15: =L14-$D$14 -> -0.4875258 | ... BL15: =BL14-$D$14 -> 0.139203
C17: Column # | D17: 4 | E17: =+D17+1 -> 5 | F17: =+E17+1 -> 6 | G17: =+F17+1 -> 7 | H17: =+G17+1 -> 8 | I17: =+H17+1 -> 9 | J17: =+I17+1 -> 10 | K17: =+J17+1 -> 11 | L17: =+K17+1 -> 12 | ... BL17: =+BK17+1 -> 64
C18: Months | D18: ='HAVER BoE'!D9 -> 5.1863 | E18: ='HAVER BoE'!E9 -> 5.1869458 | F18: ='HAVER BoE'!F9 -> 5.1737152 | G18: ='HAVER BoE'!G9 -> 5.1274641 | H18: ='HAVER BoE'!H9 -> 5.0330693 | I18: ='HAVER BoE'!I9 -> 4.8948084 | J18: ='HAVER BoE'!J9 -> 4.7267552 | K18: ='HAVER BoE'!K9 -> 4.5455904 | ... BL18: ='HAVER BoE'!BL9 -> 2.976615
C19: Days | E19: 30.416667 | F19: =+E19+30.4166667 -> 60.833333 | G19: =+F19+30.4166667 -> 91.25 | H19: =+G19+30.4166667 -> 121.66667 | I19: =+H19+30.4166667 -> 152.08333 | J19: =+I19+30.4166667 -> 182.5 | K19: =+J19+30.4166667 -> 212.91667 | L19: =+K19+30.4166667 -> 243.33333 | M19: =+L19+30.4166667 -> 273.75 | ... BL19: =+BK19+30.4166667 -> 1825
D20: =C22 -> 46153 | E20: =$D20+E19 -> 46183.417 | F20: =$D20+F19 -> 46213.833 | G20: =$D20+G19 -> 46244.25 | H20: =$D20+H19 -> 46274.667 | I20: =$D20+I19 -> 46305.083 | J20: =$D20+J19 -> 46335.5 | K20: =$D20+K19 -> 46365.917 | L20: =$D20+L19 -> 46396.333 | ... BL20: =$D20+BL19 -> 47978
