Workbook
Name _DLX1.INC: HAVERQ!$4:$10

Sheet Data >>
A3: Chains of reasoning:
A4: 1 | B4: Headline GDP appears to be stronger in Q1 since the pandemic
A5: 2 | B5: NSA data suggests that this is due to a shift in actual output more towards Q1, rather than being a function of the ONS' adjustments. But it does suggest the ONS isn't squeezing this underlying seasonality change out of the system.
A6: 3 | B6: This regime shift in output comes from XYZ (e.g. need to take a look at the expenditure components)
A7: 4 | B7: Implications - creates difficulty for policymakers. Users should take care to not overemphasise individual monthly/quarterly GDP outturns, and instead look at a broader sweep of indicators
B10: Question is whether we've now seen a long enough time series (a few years after pandemic distortions) to judge whether the shift in seasonality towards Q1 is a sustained shift (the implication being that the ONS should be adjusting for a sustained shift)
A13: ONS data link:
A14: https://www.ons.gov.uk/economy/grossdomesticproductgdp/datasets/uksecondestimateofgdpdatatables
A16: Investment has been running very hot in Q1 and very soft in Q3 and Q4 since the pandemic/energy crisis
A18: Look at what's driving those investment gains in Q1. Looks to be business investment - ICT investment, other buildings investment, and intellectual property investment
A20: Do the same but on the output side of GDP, particularly for IoS. Not sure this is possible
A26: Conclusions
A28: 1. | B28: The headline GDP data has been showing signs of residual seasonality for some time now
A30: 2. | B30: The ONS is now making downwards adjustments to the Q1 NSA data when forming its seasonally adjusted GDP series. However, these downward adjustments need to be bigger.
A32: 3. | B32: We can also see that the non-seasonally adjusted data in Q1 is now much stronger than is used to be (i.e. there has been a regime shift in underlying activity towards Q1). This suggests the ONS should be squeezing this shift in underlying activity towards Q1 out of the system
A34: 4. | B34: Where is this coming from? Our analysis suggests the change in pattern of activity towards Q1 is coming from investments, specifically business investment. Within this, there are some signs it results from ICT, building, and IP investment. No signs this is coming from deflators
A36: 5. | B36: The ONS' downward adjustments to Q1 are now increasingly geared towards lowering investment - so they have correctly identified the source of the issues, but they clearly need to go further in brining Q1 investment lower
A38: 6. | B38: The key question for the ONS is whether we've now seen a long enough period to judge whether the shift in output towards Q1 is a sustained shift. If so, further downward adjustments to Q1 would be warranted.
A40: 7. | B40: Last year's note suggests the ONS is watching this closely, given the scrutiny from us and other economists. The takeaway is that, for the timing being at least, we're likely to continue seeing stronger Q1's and weaker H2's, which clients and policymakers need to be aware of. Broader sweep of indicators is better

Sheet ONS A2 AGG
A1: Worksheet A2: National accounts aggregates [note 1, 5]
A2: This worksheet contains five tables with one blank row between them. Some cells refer to notes which can be found on the notes worksheet.
A3: Some cells in this table are empty because data was not collected for these variables at these time points.
A4: Reference year 2023 = 100
A5: Figures are in £ million
A7: Table 1: Annual
A8: Time period and dataset code row | B8: Gross national income at market prices: Current prices | C8: Net income from abroad: Current prices [note 2] | D8: Gross domestic product at market prices: Current prices | E8: less Basic price adjustment: Current prices [note 3] | F8: Gross value added at basic prices: Current prices | G8: Gross domestic product at market prices: Chained volume measure | H8: less Basic price adjustment: Chained volume measure [note 3] | I8: Gross value added at basic prices: Chained volume measure | J8: Gross domestic product at market prices: Chained volume measure: Non-seasonally adjusted | K8: Gross value added excluding oil & gas: Chained volume measure [note 4]
A9: Dataset identifier | B9: ABMZ | C9: CAES | D9: YBHA | E9: NTAP | F9: ABML | G9: ABMI | H9: NTAO | I9: ABMM | J9: BKVT | K9: KLS2
A10: 1948 | B10: 11632 | D10: 11429 | E10: 1049 | F10: 10380 | G10: 455134 | H10: 53600 | I10: 403688 | J10: 455134
A11: 1949 | B11: 12358 | D11: 12172 | E11: 1045 | F11: 11127 | G11: 470210 | H11: 53600 | I11: 418450 | J11: 470210
A12: 1950 | B12: 13099 | D12: 12742 | E12: 1160 | F12: 11582 | G12: 485925 | H12: 56267 | I12: 431768 | J12: 485925
A13: 1951 | B13: 14606 | D13: 14305 | E13: 1345 | F13: 12960 | G13: 503980 | H13: 59808 | I13: 446669 | J13: 503980
A14: 1952 | B14: 15745 | D14: 15536 | E14: 1386 | F14: 14150 | G14: 511536 | H14: 58207 | I14: 455294 | J14: 511536
A15: 1953 | B15: 16862 | D15: 16682 | E15: 1476 | F15: 15206 | G15: 539917 | H15: 60475 | I15: 481238 | J15: 539917
A16: 1954 | B16: 17796 | D16: 17598 | E16: 1493 | F16: 16105 | G16: 563461 | H16: 61909 | I16: 503188 | J16: 563461
A17: 1955 | B17: 19291 | D17: 19170 | E17: 1678 | F17: 17492 | G17: 586122 | H17: 65724 | I17: 522421 | J17: 586122
A18: 1956 | B18: 21019 | D18: 20846 | E18: 1789 | F18: 19057 | G18: 596062 | H18: 64980 | I18: 532656 | J18: 596062
A19: 1957 | B19: 22298 | D19: 22107 | E19: 1799 | F19: 20308 | G19: 607813 | H19: 64653 | I19: 544373 | J19: 607813
A20: 1958 | B20: 23450 | D20: 23223 | E20: 1858 | F20: 21365 | G20: 615967 | H20: 67312 | I20: 550345 | J20: 615967
A21: 1959 | B21: 24587 | D21: 24392 | E21: 1969 | F21: 22423 | G21: 642287 | H21: 72638 | I21: 572136 | J21: 642287
... A58: 1996 | B58: 912967 | D58: 913609 | E58: 83316 | F58: 830293 | G58: 1665005 | H58: 161059 | I58: 1503264 | J58: 1665005
A59: 1997 | B59: 957920 | C59: -619 | D59: 958539 | E59: 91510 | F59: 867029 | G59: 1746257 | H59: 180523 | I59: 1565755 | J59: 1746257 | K59: 1499012
A60: 1998 | B60: 1013611 | C60: 10807 | D60: 1002804 | E60: 98710 | F60: 904094 | G60: 1802946 | H60: 185366 | I60: 1617515 | J60: 1802946 | K60: 1548754
A61: 1999 | B61: 1043174 | C61: -3556 | D61: 1046727 | E61: 107063 | F61: 939664 | G61: 1856033 | H61: 189603 | I61: 1666306 | J61: 1856033 | K61: 1595763
A62: 2000 | B62: 1107797 | C62: 3038 | D62: 1104759 | E62: 113237 | F62: 991522 | G62: 1940007 | H62: 197096 | I62: 1742783 | J62: 1940007 | K62: 1671783
A63: 2001 | B63: 1156730 | C63: 6191 | D63: 1150542 | E63: 115018 | F63: 1035524 | G63: 1986393 | H63: 201320 | I63: 1784946 | J63: 1986393 | K63: 1715551
A64: 2002 | B64: 1208435 | C64: 13788 | D64: 1194646 | E64: 119282 | F64: 1075364 | G64: 2020341 | H64: 208136 | I64: 1812127 | J64: 2020341 | K64: 1743698
A65: 2003 | B65: 1276902 | C65: 14396 | D65: 1262502 | E65: 125442 | F65: 1137060 | G65: 2085366 | H65: 215723 | I65: 1869594 | J65: 2085366 | K65: 1801377
A66: 2004 | B66: 1338028 | C66: 10885 | D66: 1327143 | E66: 133224 | F66: 1193919 | G66: 2133872 | H66: 225408 | I66: 1908618 | J66: 2133872 | K66: 1841379
A67: 2005 | B67: 1417765 | C67: 14515 | D67: 1403249 | E67: 138843 | F67: 1264406 | G67: 2193421 | H67: 226520 | I67: 1966774 | J67: 2193421 | K67: 1901664
A68: 2006 | B68: 1472303 | C68: -5780 | D68: 1478080 | E68: 146111 | F68: 1331969 | G68: 2241453 | H68: 228207 | I68: 2012964 | J68: 2241453 | K68: 1952689
A69: 2007 | B69: 1537626 | C69: -14105 | D69: 1551729 | E69: 154479 | F69: 1397250 | G69: 2307148 | H69: 234884 | I69: 2071973 | J69: 2307148 | K69: 2013717
A70: 2008 | B70: 1581186 | C70: -21031 | D70: 1602217 | E70: 151577 | F70: 1450640 | G70: 2306008 | H70: 229852 | I70: 2075743 | J70: 2306008 | K70: 2020533
... A87: 2025 | B87: 3021037 | C87: -18824 | D87: 3039861 | E87: 297086 | F87: 2742775 | G87: 2820520 | H87: 258843 | I87: 2561677 | J87: 2820520 | K87: 2538746
A89: Table 2: Quarterly
A90: Time period and dataset code row | B90: Gross national income at market prices: Current prices | C90: Net income from abroad: Current prices [note 2] | D90: Gross domestic product at market prices: Current prices | E90: less Basic price adjustment: Current prices [note 3] | F90: Gross value added at basic prices: Current prices | G90: Gross domestic product at market prices: Chained volume measure | H90: less Basic price adjustment: Chained volume measure [note 3] | I90: Gross value added at basic prices: Chained volume measure | J90: Gross domestic product at market prices: Chained volume measure: Non-seasonally adjusted | K90: Gross value added excluding oil & gas: Chained volume measure [note 4]
A91: Dataset identifier | B91: ABMZ | C91: CAES | D91: YBHA | E91: NTAP | F91: ABML | G91: ABMI | H91: NTAO | I91: ABMM | J91: BKVT | K91: KLS2
A92: 1955 Q1 | B92: 4694 | D92: 4666 | E92: 394 | F92: 4272 | G92: 145457 | H92: 15759 | I92: 130040 | J92: 142178
A93: 1955 Q2 | B93: 4725 | D93: 4688 | E93: 417 | F93: 4271 | G93: 145551 | H93: 16295 | I93: 129812 | J93: 144515
A94: 1955 Q3 | B94: 4911 | D94: 4862 | E94: 440 | F94: 4422 | G94: 147995 | H94: 17110 | I94: 131515 | J94: 149341
...

Sheet HAVERQ
B1: Seasonally adjusted >> | L1: Non seasonally adjusted >> | U1: Investment detail >> | AK1: Nominal GDP and components
AK2: SA >> | AT2: NSA >>
B3: GDP | C3: Consumer spending | D3: NPISH | E3: Government consumption | F3: Investment | G3: Inventories | H3: Acquisitions | I3: Exports | J3: Imports | K3: Statistical discrepancy | L3: GDP | M3: Consumer spending | N3: NPISH | O3: Government consumption | P3: Investment | Q3: Inventories | R3: Acquisitions | S3: Exports | T3: Imports | U3: IPNR SA | V3: GI SA | W3: IPNR NSA | X3: GI NSA | Y3: Transport SA | Z3: ICT SA | AA3: Dwellings SA | AB3: Other buildings SA | AC3: IP SA | AD3: Transport NSA | AE3: ICT NSA | AF3: Dwellings NSA | AG3: Other buildings NSA | AH3: IP NSA | AK3: GDP | AL3: Consumer spending | AM3: NPISH | AN3: Government consumption | AO3: Investment | AP3: Inventories | AQ3: Acquisitions | AR3: Exports | AS3: Imports | AT3: GDP | AU3: Consumer spending | AV3: NPISH | AW3: Government consumption | AX3: Investment | AY3: Inventories | AZ3: Acquisitions | BA3: Exports | BB3: Imports
A4: 19901 !Q | B4: ABMIQ@UK | C4: ABJRQ@UK | D4: HAYOQ@UK | E4: NMRYQ@UK | F4: NPQTQ@UK | G4: CAFUQ@UK | H4: NPJRQ@UK | I4: IKBKQ@UK | J4: IKBLQ@UK | K4: GIXSQ@UK | L4: BKVTQ@UK | M4: ABPFQ@UK | N4: ABNUQ@UK | O4: NMRUQ@UK | P4: NPQRQ@UK | Q4: ABMQQ@UK | R4: NPJPQ@UK | S4: KTMZQ@UK | T4: KTNBQ@UK | U4: NPELQ@UK | V4: DLWFQ@UK | W4: NPENQ@UK | X4: EQDNQ@UK | Y4: DLWLQ@UK | Z4: DLWOQ@UK | AA4: DFEGQ@UK | AB4: DLWTQ@UK | AC4: EQDOQ@UK | AD4: DLWJQ@UK | AE4: DLWMQ@UK | AF4: DFDVQ@UK | AG4: DLWQQ@UK | AH4: EQDTQ@UK | AK4: YBHAQ@UK | AL4: ABJQQ@UK | AM4: HAYEQ@UK | AN4: NMRPQ@UK | AO4: NPQSQ@UK | AP4: CAEXQ@UK | AQ4: NPJQQ@UK | AR4: IKBHQ@UK | AS4: IKBIQ@UK | AT4: BKTLQ@UK | AU4: ABPBQ@UK | AV4: ABNVQ@UK | AW4: NMRKQ@UK | AX4: NPQXQ@UK | AY4: ABMPQ@UK | AZ4: NPJOQ@UK | BA4: KTMWQ@UK | BB4: KTMXQ@UK
A5: .DESC | B5: UK: Real Gross Domestic Product (SA, Mil.Chn.2023.GBP) | C5: UK: Household Final Consumption Expenditure (SA, Mil.Chn.2023.GBP) | D5: UK: Nonprofit Inst Final Consumption Expenditure (SA, Mil.Chn.2023.GBP) | E5: UK: General Govt Final Consumption Expenditure (SA, Mil.Chn.2023.GBP) | F5: UK: Gross Fixed Capital Formation (SA, Mil.Chn.2023.GBP) | G5: UK: Change in Inventories/Stocks: All Industries (SA, Mil.Chn.2023.GBP) | H5: UK: Acquisitions less Disposals of Valuables (SA, Mil.Chn.2023.GBP) | I5: UK: Exports of Goods & Services (SA, Mil.Chn.2023.Pounds) | J5: UK: Imports of Goods & Services (SA, Mil.Chn.2023.Pounds) | K5: UK: Statistical Discrepancy (SA, Mil.Chn.2023.GBP) | L5: U.K.: Gross Domestic Product (NSA, Mil.Chn.2023.GBP) | M5: UK: HH Final Consumption Expenditure: National Concept (NSA, Mil.Chn.2023.GBP) | N5: U.K.: Nonprofit Inst Final Consumption Expenditure (NSA, Mil.Chn.2023.GBP) | O5: UK: General Government Final Consumption Expenditure (NSA, Mil.Chn.2023.GBP) | P5: UK: Gross Fixed Capital Formation (NSA, Mil.Chn.2023.GBP) | Q5: U.K.: Changes in Inventories (NSA, Mil.Chn.2023.GBP) | R5: UK: Acquisitions less Disposals of Valuables (NSA, Mil.Chn.2023.GBP) | S5: UK: Exports: Goods & Services (NSA, Mil.Chn.2023.Pounds) | T5: UK: Imports: Goods & Services (NSA, Mil.Chn.2023.Pounds) | U5: UK: Gross Fixed Capital Formation: Business Investment (SA, Mil.Chn.2023.GBP) | V5: UK: Gross Fixed Capital Formation: General Government (SA, Mil.Chn.2023.GBP) | W5: UK: GFCF: Total Business Investment (NSA, Mil.Chn.2023.GBP) | X5: UK: GFCF: General Government (NSA, Mil.Chn.2023.GBP) | Y5: UK: Gross Fixed Capital Formation: Transport Equipment (SA, Mil.Chn.2023.GBP) | Z5: UK: GDP: GFCF: Plant & Machinery (SA, Mil.Chained.2023.Pounds) | AA5: UK: Gross Fixed Capital Formation: Dwellings (SA, Mil.Chn.2023.GBP) | AB5: UK: GFCF: Other Buildings & Structures (SA, Mil.Chn.2023.GBP) | AC5: UK: GDP: GFCF: All Intangible Fixed Assets (SA, Mil.Chained.2023.Pounds) | AD5: U.K.: GDP: GFCF: Vehicles, Ships & Aircraft (NSA, Mil.Chained.2023.Pounds) | AE5: U.K.: GDP: GFCF: Plant & Machinery (NSA, Mil.Chained.2023.Pounds) | AF5: UK: GFCF: Asset: Dwellings (NSA, Mil.Chn.2023.GBP) | AG5: UK: GFCF: Asset: Other New Buildings & Structures (NSA, Mil.Chn.2023.GBP) | AH5: U.K.: GDP: GFCF: All Intangible Fixed Assets (NSA, Mil.Chained.2023.Pounds) | AK5: UK: Gross Domestic Product [GDP] (SA, Mil.Pounds) | AL5: UK: GDP: Household Final Consumption Expenditure (SA, Mil.Pounds) | AM5: UK: GDP: Nonprofit Institutions Final Consumption Expenditure (SA,Mil.Pounds) | AN5: UK: GDP: General Government Final Consumption Expenditure (SA, Mil.Pounds) | AO5: UK: GDP: Gross Fixed Capital Formation (SA, Mil.Pounds) | AP5: UK: GDP: Changes in Inventories and Stocks (SA, Mil.Pounds) | AQ5: UK: GDP: Acquisitions Less Disposals of Valuables (SA, Mil.Pounds) | AR5: UK: GDP: Exports of Goods and Services (SA, Mil.Pounds) | AS5: UK: GDP: Imports of Goods and Services (SA, Mil.Pounds) | AT5: UK: Gross Domestic Product [GDP] (NSA, Mil.Pounds) | AU5: UK: GDP: Household Final Consumption Expenditure (NSA, Mil.Pounds) | AV5: UK: GDP: Nonprofit Institutions Final Consumption Expenditure (NSA, Mil.Pounds) | AW5: UK: GDP: General Government Final Consumption Expenditure (NSA, Mil.Pounds) | AX5: UK: GDP: Gross Fixed Capital Formation (NSA, Mil.Pounds) | AY5: UK: GDP: Changes in Inventories and Stocks (NSA, Mil.Pounds) | AZ5: UK: GDP: Acquisitions Less Disposals of Valuables (NSA, Mil.Pounds) | BA5: UK: GDP: Exports of Goods and Services (NSA, Mil.Pounds) | BB5: UK: GDP: Imports of Goods and Services (NSA, Mil.Pounds)
A6: .T1 | B6: Q1-1955 | C6: Q1-1955 | D6: Q1-1955 | E6: Q1-1955 | F6: Q1-1955 | G6: Q1-1955 | H6: Q1-1955 | I6: Q1-1955 | J6: Q1-1955 | K6: Q1-1955 | L6: Q1-1955 | M6: Q1-1955 | N6: Q1-1955 | O6: Q1-1955 | P6: Q1-1955 | Q6: Q1-1955 | R6: Q1-1955 | S6: Q1-1955 | T6: Q1-1955 | U6: Q1-1997 | V6: Q1-1997 | W6: Q1-1997 | X6: Q1-1997 | Y6: Q1-1997 | Z6: Q1-1997 | AA6: Q1-1997 | AB6: Q1-1997 | AC6: Q1-1997 | AD6: Q1-1997 | AE6: Q1-1997 | AF6: Q1-1997 | AG6: Q1-1997 | AH6: Q1-1997 | AK6: Q1-1955 | AL6: Q1-1955 | AM6: Q1-1955 | AN6: Q1-1955 | AO6: Q1-1955 | AP6: Q1-1955 | AQ6: Q1-1986 | AR6: Q1-1955 | AS6: Q1-1955 | AT6: Q1-1955 | AU6: Q1-1955 | AV6: Q1-1955 | AW6: Q1-1955 | AX6: Q1-1955 | AY6: Q1-1955 | AZ6: Q1-1986 | BA6: Q1-1955 | BB6: Q1-1955
A7: .TN | B7: Q4-2025 | C7: Q4-2025 | D7: Q4-2025 | E7: Q4-2025 | F7: Q4-2025 | G7: Q4-2025 | H7: Q4-2025 | I7: Q4-2025 | J7: Q4-2025 | K7: Q4-2025 | L7: Q4-2025 | M7: Q4-2025 | N7: Q4-2025 | O7: Q4-2025 | P7: Q4-2025 | Q7: Q4-2025 | R7: Q4-2025 | S7: Q4-2025 | T7: Q4-2025 | U7: Q4-2025 | V7: Q4-2025 | W7: Q4-2025 | X7: Q4-2025 | Y7: Q4-2025 | Z7: Q4-2025 | AA7: Q4-2025 | AB7: Q4-2025 | AC7: Q4-2025 | AD7: Q4-2025 | AE7: Q4-2025 | AF7: Q4-2025 | AG7: Q4-2025 | AH7: Q4-2025 | AK7: Q4-2025 | AL7: Q4-2025 | AM7: Q4-2025 | AN7: Q4-2025 | AO7: Q4-2025 | AP7: Q4-2025 | AQ7: Q4-2025 | AR7: Q4-2025 | AS7: Q4-2025 | AT7: Q4-2025 | AU7: Q4-2025 | AV7: Q4-2025 | AW7: Q4-2025 | AX7: Q4-2025 | AY7: Q4-2025 | AZ7: Q4-2025 | BA7: Q4-2025 | BB7: Q4-2025
A8: .LSOURCE | B8: Office for National Statistics | C8: Office for National Statistics | D8: Office for National Statistics | E8: Office for National Statistics | F8: Office for National Statistics | G8: Office for National Statistics | H8: Office for National Statistics | I8: Office for National Statistics | J8: Office for National Statistics | K8: Office for National Statistics | L8: Office for National Statistics | M8: Office for National Statistics | N8: Office for National Statistics | O8: Office for National Statistics | P8: Office for National Statistics | Q8: Office for National Statistics | R8: Office for National Statistics | S8: Office for National Statistics | T8: Office for National Statistics | U8: Office for National Statistics | V8: Office for National Statistics | W8: Office for National Statistics | X8: Office for National Statistics | Y8: Office for National Statistics | Z8: Office for National Statistics | AA8: Office for National Statistics | AB8: Office for National Statistics | AC8: Office for National Statistics | AD8: Office for National Statistics | AE8: Office for National Statistics | AF8: Office for National Statistics | AG8: Office for National Statistics | AH8: Office for National Statistics | AK8: Office for National Statistics | AL8: Office for National Statistics | AM8: Office for National Statistics | AN8: Office for National Statistics | AO8: Office for National Statistics | AP8: Office for National Statistics | AQ8: Office for National Statistics | AR8: Office for National Statistics | AS8: Office for National Statistics | AT8: Office for National Statistics | AU8: Office for National Statistics | AV8: Office for National Statistics | AW8: Office for National Statistics | AX8: Office for National Statistics | AY8: Office for National Statistics | AZ8: Office for National Statistics | BA8: Office for National Statistics | BB8: Office for National Statistics
A9: .DTLM | B9: Mar-31-2026 07:04 | C9: Mar-31-2026 07:04 | D9: Mar-31-2026 07:04 | E9: Mar-31-2026 07:04 | F9: Mar-31-2026 07:04 | G9: Mar-31-2026 07:04 | H9: Mar-31-2026 07:04 | I9: Apr-16-2026 07:03 | J9: Apr-16-2026 07:03 | K9: Mar-31-2026 07:04 | L9: Mar-31-2026 07:46 | M9: Mar-31-2026 07:46 | N9: Mar-31-2026 07:46 | O9: Mar-31-2026 07:46 | P9: Mar-31-2026 07:46 | Q9: Mar-31-2026 07:46 | R9: Mar-31-2026 07:46 | S9: Mar-31-2026 07:46 | T9: Mar-31-2026 07:46 | U9: Mar-31-2026 10:14 | V9: Mar-31-2026 07:04 | W9: Mar-31-2026 10:14 | X9: Mar-31-2026 07:46 | Y9: Mar-31-2026 10:14 | Z9: Mar-31-2026 10:14 | AA9: Mar-31-2026 10:14 | AB9: Mar-31-2026 10:14 | AC9: Mar-31-2026 10:14 | AD9: Mar-31-2026 07:46 | AE9: Mar-31-2026 07:46 | AF9: Mar-31-2026 07:46 | AG9: Mar-31-2026 07:46 | AH9: Mar-31-2026 07:46 | AK9: Mar-31-2026 07:04 | AL9: Mar-31-2026 07:04 | AM9: Mar-31-2026 07:04 | AN9: Mar-31-2026 07:04 | AO9: Mar-31-2026 07:04 | AP9: Mar-31-2026 07:04 | AQ9: Mar-31-2026 07:04 | AR9: Mar-31-2026 07:02 | AS9: Mar-31-2026 07:02 | AT9: Mar-31-2026 07:04 | AU9: Mar-31-2026 07:46 | AV9: Mar-31-2026 07:46 | AW9: Mar-31-2026 07:46 | AX9: Mar-31-2026 07:46 | AY9: Mar-31-2026 07:46 | AZ9: Mar-31-2026 07:46 | BA9: Mar-31-2026 07:46 | BB9: Mar-31-2026 07:46
A10: .FRQ | B10: Quarterly | C10: Quarterly | D10: Quarterly | E10: Quarterly | F10: Quarterly | G10: Quarterly | H10: Quarterly | I10: Quarterly | J10: Quarterly | K10: Quarterly | L10: Quarterly | M10: Quarterly | N10: Quarterly | O10: Quarterly | P10: Quarterly | Q10: Quarterly | R10: Quarterly | S10: Quarterly | T10: Quarterly | U10: Quarterly | V10: Quarterly | W10: Quarterly | X10: Quarterly | Y10: Quarterly | Z10: Quarterly | AA10: Quarterly | AB10: Quarterly | AC10: Quarterly | AD10: Quarterly | AE10: Quarterly | AF10: Quarterly | AG10: Quarterly | AH10: Quarterly | AK10: Quarterly | AL10: Quarterly | AM10: Quarterly | AN10: Quarterly | AO10: Quarterly | AP10: Quarterly | AQ10: Quarterly | AR10: Quarterly | AS10: Quarterly | AT10: Quarterly | AU10: Quarterly | AV10: Quarterly | AW10: Quarterly | AX10: Quarterly | AY10: Quarterly | AZ10: Quarterly | BA10: Quarterly | BB10: Quarterly
A11: 19901 | B11: 379458 | C11: 215861 | D11: 6862 | E11: 77235 | F11: 73856 | G11: 348 | H11: -336 | I11: 69304 | J11: 68197 | K11: 1 | L11: 364170 | M11: 201610 | N11: 6759 | O11: 78352 | P11: 73861 | Q11: 179 | R11: -303 | S11: 66749 | T11: 66340 | U11: #N/A | V11: #N/A | W11: #N/A | X11: #N/A | Y11: #N/A | Z11: #N/A | AA11: #N/A | AB11: #N/A | AC11: #N/A | AD11: #N/A | AE11: #N/A | AF11: #N/A | AG11: #N/A | AH11: #N/A | AK11: 163591 | AL11: 98144 | AM11: 2139 | AN11: 26492 | AO11: 39711 | AP11: 413 | AQ11: 146 | AR11: 35672 | AS11: 39126 | AT11: 161953 | AU11: 94443 | AV11: 2123 | AW11: 26821 | AX11: 41923 | AY11: 148 | AZ11: 138 | BA11: 34459 | BB11: 38102
A12: 19902 | B12: 381997 | C12: 216571 | D12: 6568 | E12: 77520 | F12: 72815 | G12: 1826 | H12: 1143 | I12: 69149 | J12: 68012 | K12: 1 | L12: 372155 | M12: 208672 | N12: 6684 | O12: 76427 | P12: 72814 | Q12: 1288 | R12: 1047 | S12: 69030 | T12: 69254 | U12: #N/A | V12: #N/A | W12: #N/A | X12: #N/A | Y12: #N/A | Z12: #N/A | AA12: #N/A | AB12: #N/A | AC12: #N/A | AD12: #N/A | AE12: #N/A | AF12: #N/A | AG12: #N/A | AH12: #N/A | AK12: 167263 | AL12: 100606 | AM12: 2042 | AN12: 27463 | AO12: 39742 | AP12: 467 | AQ12: 128 | AR12: 36108 | AS12: 39293 | AT12: 162310 | AU12: 98783 | AV12: 2068 | AW12: 27283 | AX12: 37043 | AY12: 732 | AZ12: 136 | BA12: 35966 | BB12: 39701
A13: 19903 | B13: 377831 | C13: 215211 | D13: 6734 | E13: 78145 | F13: 72153 | G13: -1895 | H13: -3101 | I13: 69065 | J13: 66865 | K13: 0 | L13: 386781 | M13: 222850 | N13: 6746 | O13: 77933 | P13: 72151 | Q13: 249 | R13: -2987 | S13: 68723 | T13: 68804 | U13: #N/A | V13: #N/A | W13: #N/A | X13: #N/A | Y13: #N/A | Z13: #N/A | AA13: #N/A | AB13: #N/A | AC13: #N/A | AD13: #N/A | AE13: #N/A | AF13: #N/A | AG13: #N/A | AH13: #N/A | AK13: 170618 | AL13: 102143 | AM13: 2093 | AN13: 28389 | AO13: 39970 | AP13: -382 | AQ13: 141 | AR13: 35662 | AS13: 37398 | AT13: 170916 | AU13: 103826 | AV13: 2107 | AW13: 28183 | AX13: 39644 | AY13: -41 | AZ13: 141 | BA13: 35580 | BB13: 38524
A14: 19904 | B14: 375916 | C14: 215007 | D14: 6832 | E14: 78838 | F14: 71349 | G14: -6060 | H14: 1053 | I14: 69632 | J14: 65714 | K14: 0 | L14: 392096 | M14: 229518 | N14: 6807 | O14: 79026 | P14: 71347 | Q14: -7497 | R14: 1002 | S14: 72648 | T14: 64390 | U14: #N/A | V14: #N/A | W14: #N/A | X14: #N/A | Y14: #N/A | Z14: #N/A | AA14: #N/A | AB14: #N/A | AC14: #N/A | AD14: #N/A | AE14: #N/A | AF14: #N/A | AG14: #N/A | AH14: #N/A | AK14: 171505 | AL14: 103680 | AM14: 2122 | AN14: 28924 | AO14: 40066 | AP14: -2298 | AQ14: 143 | AR14: 36072 | AS14: 37204 | AT14: 177798 | AU14: 107521 | AV14: 2098 | AW14: 28981 | AX14: 40879 | AY14: -2639 | AZ14: 143 | BA14: 37509 | BB14: 36694
A15: 19911 | B15: 374060 | C15: 214735 | D15: 6531 | E15: 79041 | F15: 68137 | G15: -1893 | H15: -2024 | I15: 66995 | J15: 63535 | K15: 0 | L15: 357751 | M15: 200541 | N15: 6475 | O15: 79913 | P15: 68143 | Q15: -4244 | R15: -1987 | S15: 64001 | T15: 61158 | U15: #N/A | V15: #N/A | W15: #N/A | X15: #N/A | Y15: #N/A | Z15: #N/A | AA15: #N/A | AB15: #N/A | AC15: #N/A | AD15: #N/A | AE15: #N/A | AF15: #N/A | AG15: #N/A | AH15: #N/A | AK15: 173745 | AL15: 105632 | AM15: 1868 | AN15: 29365 | AO15: 38516 | AP15: -852 | AQ15: 123 | AR15: 34859 | AS15: 35766 | AT15: 170440 | AU15: 101439 | AV15: 1869 | AW15: 29510 | AX15: 40396 | AY15: -1457 | AZ15: 150 | BA15: 33002 | BB15: 34469
A16: 19912 | B16: 373608 | C16: 213315 | D16: 6485 | E16: 81070 | F16: 67111 | G16: -4769 | H16: 4205 | I16: 69215 | J16: 63812 | K16: 0 | L16: 363951 | M16: 205225 | N16: 6520 | O16: 80148 | P16: 67112 | Q16: -1711 | R16: 4101 | S16: 69165 | T16: 65393 | U16: #N/A | V16: #N/A | W16: #N/A | X16: #N/A | Y16: #N/A | Z16: #N/A | AA16: #N/A | AB16: #N/A | AC16: #N/A | AD16: #N/A | AE16: #N/A | AF16: #N/A | AG16: #N/A | AH16: #N/A | AK16: 176366 | AL16: 107349 | AM16: 1946 | AN16: 30346 | AO16: 38045 | AP16: -1569 | AQ16: 184 | AR16: 36588 | AS16: 36523 | AT16: 172098 | AU16: 105384 | AV16: 1948 | AW16: 30634 | AX16: 35322 | AY16: -808 | AZ16: 157 | BA16: 36763 | BB16: 37302
A17: 19913 | B17: 372878 | C17: 213544 | D17: 6558 | E17: 80462 | F17: 65897 | G17: -3885 | H17: -2001 | I17: 70286 | J17: 64199 | K17: 1 | L17: 381218 | M17: 221618 | N17: 6596 | O17: 80288 | P17: 65896 | Q17: -297 | R17: -1894 | S17: 70172 | T17: 66165 | U17: #N/A | V17: #N/A | W17: #N/A | X17: #N/A | Y17: #N/A | Z17: #N/A | AA17: #N/A | AB17: #N/A | AC17: #N/A | AD17: #N/A | AE17: #N/A | AF17: #N/A | AG17: #N/A | AH17: #N/A | AK17: 177818 | AL17: 108833 | AM17: 1924 | AN17: 31240 | AO17: 37007 | AP17: -1401 | AQ17: 163 | AR17: 37516 | AS17: 37464 | AT17: 179802 | AU17: 110810 | AV17: 1951 | AW17: 31110 | AX17: 36897 | AY17: -339 | AZ17: 163 | BA17: 37724 | BB17: 38514
A18: 19914 | B18: 373357 | C18: 213576 | D18: 6678 | E18: 80327 | F18: 66146 | G18: -2274 | H18: -1022 | I18: 70075 | J18: 65130 | K18: 1 | L18: 390983 | M18: 227786 | N18: 6661 | O18: 80551 | P18: 66140 | Q18: -6569 | R18: -1062 | S18: 73233 | T18: 63960 | U18: #N/A | V18: #N/A | W18: #N/A | X18: #N/A | Y18: #N/A | Z18: #N/A | AA18: #N/A | AB18: #N/A | AC18: #N/A | AD18: #N/A | AE18: #N/A | AF18: #N/A | AG18: #N/A | AH18: #N/A | AK18: 180143 | AL18: 110093 | AM18: 2044 | AN18: 31673 | AO18: 37414 | AP18: -1105 | AQ18: 169 | AR18: 37339 | AS18: 37484 | AT18: 185732 | AU18: 114274 | AV18: 2014 | AW18: 31370 | AX18: 38367 | AY18: -2323 | AZ18: 169 | BA18: 38813 | BB18: 36952
A19: 19921 | B19: 373317 | C19: 213040 | D19: 6583 | E19: 80646 | F19: 66335 | G19: -1362 | H19: -837 | I19: 70839 | J19: 66269 | K19: 1 | L19: 362126 | M19: 203115 | N19: 6486 | O19: 81269 | P19: 66348 | Q19: -2575 | R19: -841 | S19: 68493 | T19: 64588 | U19: #N/A | V19: #N/A | W19: #N/A | X19: #N/A | Y19: #N/A | Z19: #N/A | AA19: #N/A | AB19: #N/A | AC19: #N/A | AD19: #N/A | AE19: #N/A | AF19: #N/A | AG19: #N/A | AH19: #N/A | AK19: 182024 | AL19: 111080 | AM19: 1933 | AN19: 32247 | AO19: 37102 | AP19: -698 | AQ19: 178 | AR19: 37905 | AS19: 37723 | AT19: 178952 | AU19: 107064 | AV19: 1913 | AW19: 32245 | AX19: 38855 | AY19: -872 | AZ19: 172 | BA19: 36389 | BB19: 36814
A20: 19922 | B20: 372751 | C20: 215855 | D20: 6339 | E20: 80966 | F20: 65950 | G20: -3117 | H20: 223 | I20: 72581 | J20: 69297 | K20: 0 | L20: 366762 | M20: 210292 | N20: 6407 | O20: 80314 | P20: 65948 | Q20: 31 | R20: 225 | S20: 71971 | T20: 70236 | U20: #N/A | V20: #N/A | W20: #N/A | X20: #N/A | Y20: #N/A | Z20: #N/A | AA20: #N/A | AB20: #N/A | AC20: #N/A | AD20: #N/A | AE20: #N/A | AF20: #N/A | AG20: #N/A | AH20: #N/A | AK20: 182472 | AL20: 113093 | AM20: 1856 | AN20: 32598 | AO20: 36307 | AP20: -971 | AQ20: 167 | AR20: 38579 | AS20: 39157 | AT20: 177930 | AU20: 110941 | AV20: 1870 | AW20: 32632 | AX20: 33634 | AY20: -106 | AZ20: 173 | BA20: 38486 | BB20: 39700
A21: 19923 | B21: 374537 | C21: 217123 | D21: 6366 | E21: 80958 | F21: 66215 | G21: -1381 | H21: -319 | I21: 71131 | J21: 68557 | K21: 0 | L21: 380547 | M21: 224008 | N21: 6431 | O21: 80783 | P21: 66209 | Q21: 939 | R21: -320 | S21: 71413 | T21: 70670 | U21: #N/A | V21: #N/A | W21: #N/A | X21: #N/A | Y21: #N/A | Z21: #N/A | AA21: #N/A | AB21: #N/A | AC21: #N/A | AD21: #N/A | AE21: #N/A | AF21: #N/A | AG21: #N/A | AH21: #N/A | AK21: 183139 | AL21: 114392 | AM21: 1791 | AN21: 33110 | AO21: 35600 | AP21: -260 | AQ21: 165 | AR21: 37103 | AS21: 38762 | AT21: 184996 | AU21: 116536 | AV21: 1836 | AW21: 32979 | AX21: 35724 | AY21: 278 | AZ21: 165 | BA21: 37431 | BB21: 39953
A22: 19924 | B22: 377418 | C22: 217528 | D22: 6454 | E22: 81332 | F22: 64649 | G22: 327 | H22: 1245 | I22: 73975 | J22: 69367 | K22: 1 | L22: 388588 | M22: 226131 | N22: 6418 | O22: 81536 | P22: 64644 | Q22: -3928 | R22: 1248 | S22: 76649 | T22: 67996 | U22: #N/A | V22: #N/A | W22: #N/A | X22: #N/A | Y22: #N/A | Z22: #N/A | AA22: #N/A | AB22: #N/A | AC22: #N/A | AD22: #N/A | AE22: #N/A | AF22: #N/A | AG22: #N/A | AH22: #N/A | AK22: 185586 | AL22: 115536 | AM22: 1897 | AN22: 33428 | AO22: 35624 | AP22: -8 | AQ22: 156 | AR22: 40518 | AS22: 41565 | AT22: 191343 | AU22: 119560 | AV22: 1858 | AW22: 33527 | AX22: 36420 | AY22: -1237 | AZ22: 156 | BA22: 41799 | BB22: 40740
... A38: 19964 | B38: 422639 | C38: 246780 | D38: 8445 | E38: 83484 | F38: 68837 | G38: 1941 | H38: -220 | I38: 98508 | J38: 88403 | K38: 1 | L38: 437703 | M38: 256947 | N38: 8425 | O38: 83983 | P38: 68376 | Q38: 3579 | R38: -220 | S38: 100908 | T38: 88182 | U38: #N/A | V38: #N/A | W38: #N/A | X38: #N/A | Y38: #N/A | Z38: #N/A | AA38: #N/A | AB38: #N/A | AC38: #N/A | AD38: #N/A | AE38: #N/A | AF38: #N/A | AG38: #N/A | AH38: #N/A | AK38: 233368 | AL38: 146261 | AM38: 3349 | AN38: 37882 | AO38: 42260 | AP38: 1439 | AQ38: 208 | AR38: 61441 | AS38: 59472 | AT38: 242422 | AU38: 150871 | AV38: 3341 | AW38: 38082 | AX38: 43354 | AY38: 2876 | AZ38: 192 | BA38: 62477 | BB38: 58771
A39: 19971 | B39: 429418 | C39: 249328 | D39: 10272 | E39: 82772 | F39: 66734 | G39: -2841 | H39: 602 | I39: 105733 | J39: 90862 | K39: 0 | L39: 423715 | M39: 242507 | N39: 10272 | O39: 82517 | P39: 69063 | Q39: -3676 | R39: 563 | S39: 102511 | T39: 87296 | U39: 37825 | V39: 6170 | W39: 37189 | X39: 9179 | Y39: 3547 | Z39: 9079 | AA39: 20290 | AB39: 24335 | AC39: 12217 | AD39: 3890 | AE39: 9669 | AF39: 20570 | AG39: 25442 | AH39: 12184 | AK39: 233344 | AL39: 148217 | AM39: 3731 | AN39: 38420 | AO39: 40184 | AP39: 366 | AQ39: 286 | AR39: 61079 | AS39: 58939 | AT39: 232219 | AU39: 144345 | AV39: 3731 | AW39: 37943 | AX39: 42365 | AY39: 1014 | AZ39: 245 | BA39: 59332 | BB39: 56756
A40: 19972 | B40: 434199 | C40: 253090 | D40: 10160 | E40: 81353 | F40: 67734 | G40: -972 | H40: 642 | I40: 107210 | J40: 95127 | K40: 0 | L40: 432165 | M40: 250043 | N40: 10160 | O40: 82169 | P40: 65642 | Q40: 2139 | R40: 745 | S40: 107155 | T40: 95773 | U40: 38040 | V40: 6934 | W40: 37998 | X40: 5250 | Y40: 3730 | Z40: 9397 | AA40: 19619 | AB40: 25029 | AC40: 12530 | AD40: 3987 | AE40: 8583 | AF40: 19392 | AG40: 23798 | AH40: 12486 | AK40: 237250 | AL40: 151927 | AM40: 3792 | AN40: 37377 | AO40: 40498 | AP40: 3084 | AQ40: 347 | AR40: 60994 | AS40: 60769 | AT40: 235358 | AU40: 150478 | AV40: 3792 | AW40: 37834 | AX40: 39334 | AY40: 3829 | AZ40: 390 | BA40: 61062 | BB40: 61361
A41: 19973 | B41: 438100 | C41: 256735 | D41: 10263 | E41: 82427 | F41: 71812 | G41: 3796 | H41: 613 | I41: 106575 | J41: 94199 | K41: 0 | L41: 440937 | M41: 259576 | N41: 10263 | O41: 81848 | P41: 70444 | Q41: 3192 | R41: 512 | S41: 107459 | T41: 97448 | U41: 40957 | V41: 7403 | W41: 40158 | X41: 6711 | Y41: 3954 | Z41: 10301 | AA41: 20015 | AB41: 26487 | AC41: 12904 | AD41: 3884 | AE41: 9719 | AF41: 20212 | AG41: 26061 | AH41: 12885 | AK41: 245353 | AL41: 154724 | AM41: 3870 | AN41: 37964 | AO41: 43161 | AP41: 3917 | AQ41: 272 | AR41: 61133 | AS41: 59688 | AT41: 244272 | AU41: 156277 | AV41: 3870 | AW41: 37939 | AX41: 41932 | AY41: 3670 | AZ41: 256 | BA41: 61888 | BB41: 61560
A42: 19974 | B42: 444540 | C42: 258701 | D42: 10337 | E42: 84058 | F42: 73702 | G42: 3235 | H42: 590 | I42: 110005 | J42: 96661 | K42: 0 | L42: 449440 | M42: 265728 | N42: 10337 | O42: 84076 | P42: 74833 | Q42: 1563 | R42: 627 | S42: 112398 | T42: 96332 | U42: 41619 | V42: 7631 | W42: 43095 | X42: 6998 | Y42: 3838 | Z42: 10462 | AA42: 21434 | AB42: 27305 | AC42: 13228 | AD42: 3307 | AE42: 11268 | AF42: 21184 | AG42: 27856 | AH42: 13325 | AK42: 242592 | AL42: 155080 | AM42: 3920 | AN42: 39014 | AO42: 44347 | AP42: -1375 | AQ42: 303 | AR42: 62362 | AS42: 61059 | AT42: 246690 | AU42: 158848 | AV42: 3920 | AW42: 39059 | AX42: 44559 | AY42: -2521 | AZ42: 317 | BA42: 63286 | BB42: 60778
A43: 19981 | B43: 447712 | C43: 260797 | D43: 10445 | E43: 84775 | F43: 74393 | G43: 3707 | H43: 844 | I43: 110615 | J43: 98715 | K43: 0 | L43: 443596 | M43: 254184 | N43: 10445 | O43: 84655 | P43: 78694 | Q43: 1790 | R43: 789 | S43: 108241 | T43: 96135 | U43: 42028 | V43: 8473 | W43: 42952 | X43: 11854 | Y43: 4489 | Z43: 10318 | AA43: 20045 | AB43: 27821 | AC43: 13651 | AD43: 4794 | AE43: 10889 | AF43: 20331 | AG43: 30829 | AH43: 13756 | AK43: 247175 | AL43: 157183 | AM43: 3949 | AN43: 39473 | AO43: 44749 | AP43: 1658 | AQ43: 461 | AR43: 61446 | AS43: 61744 | AT43: 244068 | AU43: 152694 | AV43: 3949 | AW43: 39005 | AX43: 46813 | AY43: 1080 | AZ43: 420 | BA43: 59996 | BB43: 59889
A44: 19982 | B44: 450292 | C44: 263411 | D44: 10482 | E44: 85124 | F44: 74474 | G44: 2303 | H44: 718 | I44: 110558 | J44: 101342 | K44: 0 | L44: 442790 | M44: 260527 | N44: 10482 | O44: 85695 | P44: 70490 | Q44: 2944 | R44: 815 | S44: 110010 | T44: 101708 | U44: 42503 | V44: 7895 | W44: 40997 | X44: 5767 | Y44: 3991 | Z44: 10328 | AA44: 20520 | AB44: 27940 | AC44: 13986 | AD44: 4333 | AE44: 9514 | AF44: 20297 | AG44: 24549 | AH44: 13933 | AK44: 249234 | AL44: 159647 | AM44: 3951 | AN44: 39359 | AO44: 44776 | AP44: 2495 | AQ44: 391 | AR44: 61016 | AS44: 62401 | AT44: 246263 | AU44: 158388 | AV44: 3951 | AW44: 39814 | AX44: 43089 | AY44: 2528 | AZ44: 433 | BA44: 60874 | BB44: 62814
A45: 19983 | B45: 451005 | C45: 267649 | D45: 10328 | E45: 85950 | F45: 73749 | G45: 2199 | H45: 967 | I45: 110034 | J45: 101742 | K45: 0 | L45: 450046 | M45: 270292 | N45: 10328 | O45: 85429 | P45: 72124 | Q45: 626 | R45: 881 | S45: 110606 | T45: 104415 | U45: 41933 | V45: 7804 | W45: 41014 | X45: 7026 | Y45: 3911 | Z45: 10188 | AA45: 20052 | AB45: 27676 | AC45: 14039 | AD45: 3844 | AE45: 9605 | AF45: 20250 | AG45: 27103 | AH45: 13946 | AK45: 251492 | AL45: 163345 | AM45: 3985 | AN45: 40204 | AO45: 44339 | AP45: 1047 | AQ45: 502 | AR45: 60327 | AS45: 62257 | AT45: 251429 | AU45: 165192 | AV45: 3985 | AW45: 40187 | AX45: 43684 | AY45: 966 | AZ45: 485 | BA45: 61009 | BB45: 64079
A46: 19984 | B46: 453937 | C46: 267397 | D46: 10214 | E46: 85893 | F46: 75273 | G46: -3081 | H46: 829 | I46: 109183 | J46: 101486 | K46: 0 | L46: 466514 | M46: 274251 | N46: 10214 | O46: 85963 | P46: 76581 | Q46: -232 | R46: 873 | S46: 111533 | T46: 101027 | U46: 42520 | V46: 8151 | W46: 44021 | X46: 7675 | Y46: 4386 | Z46: 10518 | AA46: 20264 | AB46: 27687 | AC46: 14037 | AD46: 3806 | AE46: 11344 | AF46: 20004 | AG46: 28643 | AH46: 14079 | AK46: 254903 | AL46: 163595 | AM46: 4015 | AN46: 40579 | AO46: 46163 | AP46: 1475 | AQ46: 458 | AR46: 61107 | AS46: 62489 | AT46: 261044 | AU46: 167496 | AV46: 4015 | AW46: 40609 | AX46: 46441 | AY46: 2101 | AZ46: 474 | BA46: 62017 | BB46: 62109
A47: 19991 | B47: 457044 | C47: 270159 | D47: 10146 | E47: 85762 | F47: 75322 | G47: 1452 | H47: 803 | I47: 109716 | J47: 104893 | K47: 0 | L47: 456503 | M47: 263344 | N47: 10146 | O47: 85541 | P47: 77359 | Q47: 2349 | R47: 741 | S47: 107024 | T47: 102160 | U47: 43428 | V47: 7429 | W47: 42777 | X47: 10242 | Y47: 4471 | Z47: 10547 | AA47: 20149 | AB47: 27724 | AC47: 13937 | AD47: 4695 | AE47: 11128 | AF47: 20446 | AG47: 28455 | AH47: 14015 | AK47: 257115 | AL47: 165881 | AM47: 4035 | AN47: 41798 | AO47: 46564 | AP47: 2462 | AQ47: 457 | AR47: 60130 | AS47: 64212 | AT47: 255362 | AU47: 161207 | AV47: 4035 | AW47: 41339 | AX47: 48442 | AY47: 3503 | AZ47: 416 | BA47: 58708 | BB47: 62288
A48: 19992 | B48: 458710 | C48: 275407 | D48: 10538 | E48: 88720 | F48: 75306 | G48: 312 | H48: 516 | I48: 110243 | J48: 106418 | K48: 0 | L48: 449667 | M48: 272027 | N48: 10538 | O48: 89218 | P48: 71534 | Q48: -862 | R48: 600 | S48: 109814 | T48: 106508 | U48: 43043 | V48: 7559 | W48: 41082 | X48: 6048 | Y48: 3987 | Z48: 10570 | AA48: 21262 | AB48: 27772 | AC48: 13892 | AD48: 4417 | AE48: 9753 | AF48: 21049 | AG48: 24629 | AH48: 13850 | AK48: 258836 | AL48: 168797 | AM48: 4127 | AN48: 42423 | AO48: 46044 | AP48: -115 | AQ48: 276 | AR48: 61928 | AS48: 64644 | AT48: 255719 | AU48: 167296 | AV48: 4127 | AW48: 42899 | AX48: 44391 | AY48: -285 | AZ48: 317 | BA48: 61899 | BB48: 64925
A49: 19993 | B49: 466387 | C49: 278331 | D49: 10548 | E49: 89707 | F49: 76109 | G49: -251 | H49: 665 | I49: 116888 | J49: 109856 | K49: 0 | L49: 468640 | M49: 281591 | N49: 10548 | O49: 89307 | P49: 75581 | Q49: 2008 | R49: 595 | S49: 117414 | T49: 112640 | U49: 42939 | V49: 7620 | W49: 43192 | X49: 6693 | Y49: 4283 | Z49: 11283 | AA49: 21615 | AB49: 26676 | AC49: 14084 | AD49: 4183 | AE49: 10658 | AF49: 21796 | AG49: 27278 | AH49: 14001 | AK49: 262328 | AL49: 169584 | AM49: 4205 | AN49: 43319 | AO49: 47459 | AP49: 26 | AQ49: 356 | AR49: 64440 | AS49: 67061 | AT49: 263487 | AU49: 171727 | AV49: 4205 | AW49: 43313 | AX49: 46461 | AY49: 1390 | AZ49: 334 | BA49: 64996 | BB49: 68939
A50: 19994 | B50: 473892 | C50: 280651 | D50: 10704 | E50: 89800 | F50: 75564 | G50: 5435 | H50: 1052 | I50: 118826 | J50: 112125 | K50: 0 | L50: 481223 | M50: 287586 | N50: 10704 | O50: 89923 | P50: 77827 | Q50: 3453 | R50: 1100 | S50: 121421 | T50: 111984 | U50: 42381 | V50: 7508 | W50: 44739 | X50: 7132 | Y50: 4479 | Z50: 10425 | AA50: 21806 | AB50: 27091 | AC50: 14274 | AD50: 3927 | AE50: 11286 | AF50: 21542 | AG50: 28901 | AH50: 14322 | AK50: 268448 | AL50: 171557 | AM50: 4327 | AN50: 43587 | AO50: 47388 | AP50: 2487 | AQ50: 646 | AR50: 66920 | AS50: 68464 | AT50: 272159 | AU50: 175589 | AV50: 4327 | AW50: 43576 | AX50: 48161 | AY50: 252 | AZ50: 668 | BA50: 67815 | BB50: 68229
... A154: 20254 | B154: 706067 | C154: 416308 | D154: 14870 | E154: 149250 | F154: 138849 | G154: -992 | H154: 5891 | I154: 227206 | J154: 244706 | K154: -609 | L154: 716608 | M154: 425640 | N154: 14870 | O154: 149877 | P154: 140714 | Q154: -6017 | R154: 5911 | S154: 234329 | T154: 248107 | U154: 76573 | V154: 25855 | W154: 79298 | X154: 24206 | Y154: 4867 | Z154: 20288 | AA154: 27560 | AB154: 47128 | AC154: 39005 | AD154: 6063 | AE154: 20794 | AF154: 27785 | AG154: 47464 | AH154: 38607 | AK154: 769261 | AL154: 448516 | AM154: 15339 | AN154: 164036 | AO154: 145928 | AP154: -2015 | AQ154: 10281 | AR154: 233723 | AS154: 245884 | AT154: 774633 | AU154: 457895 | AV154: 15339 | AW154: 163797 | AX154: 147694 | AY154: -6495 | AZ154: 10239 | BA154: 241689 | BB154: 249595

Sheet Real calculations >>

Sheet GDP calculations
D1: Levels >> | H1: Quarterly ratios of levels >> | P1: Seven-quarter rolling window >> | W1: 2x4 MA >>
A4: Date | B4: Year | C4: Quarter | D4: GDP SA | E4: GDP NSA | F4: Ratio | H4: Year | I4: Q1 | J4: Q2 | K4: Q3 | L4: Q4 | M4: One line | P4: Q1 | Q4: Q2 | R4: Q3 | S4: Q4 | T4: One line | W4: Q1 | X4: Q2 | Y4: Q3 | Z4: Q4 | AA4: One line
A5: 1990 Q1 | B5: =LEFT(A5,4) -> 1990 | C5: =RIGHT(A5,2) -> Q1 | D5: ='ONS A2 AGG'!G232 -> 379458 | E5: ='ONS A2 AGG'!J232 -> 364170 | F5: =D5/E5 -> 1.0419804 | H5: 1990 | I5: =INDEX($F5:$F$148,MATCH(I$4,$C5:$C$148,0)) -> 1.0419804 | J5: =INDEX($F5:$F$148,MATCH(J$4,$C5:$C$148,0)) -> 1.026446 | K5: =INDEX($F5:$F$148,MATCH(K$4,$C5:$C$148,0)) -> 0.97686029 | L5: =INDEX($F5:$F$148,MATCH(L$4,$C5:$C$148,0)) -> 0.9587346 | M5: 1 | S5: =E8/AVERAGE(E5:E11) -> 1.0483362 | T5: 1 | AA5: 1
A6: 1990 Q2 | B6: =LEFT(A6,4) -> 1990 | C6: =RIGHT(A6,2) -> Q2 | D6: ='ONS A2 AGG'!G233 -> 381997 | E6: ='ONS A2 AGG'!J233 -> 372155 | F6: =D6/E6 -> 1.026446 | H6: 1991 | I6: =F9 -> 1.0455876 | J6: =F10 -> 1.0265338 | K6: =F11 -> 0.97812275 | L6: =F12 -> 0.95491876 | M6: 1 | P6: =E9/AVERAGE(E6:E12) -> 0.9468123 | Q6: =E10/AVERAGE(E7:E13) -> 0.96688724 | R6: =E11/AVERAGE(E8:E14) -> 1.0205129 | S6: =E12/AVERAGE(E9:E15) -> 1.0512968 | T6: 1 | AA6: 1
A7: 1990 Q3 | B7: =LEFT(A7,4) -> 1990 | C7: =RIGHT(A7,2) -> Q3 | D7: ='ONS A2 AGG'!G234 -> 377831 | E7: ='ONS A2 AGG'!J234 -> 386781 | F7: =D7/E7 -> 0.97686029 | H7: 1992 | I7: =INDEX($F13:$F$148,MATCH(I$4,$C13:$C$148,0)) -> 1.0309036 | J7: =INDEX($F13:$F$148,MATCH(J$4,$C13:$C$148,0)) -> 1.0163294 | K7: =INDEX($F13:$F$148,MATCH(K$4,$C13:$C$148,0)) -> 0.98420694 | L7: =INDEX($F13:$F$148,MATCH(L$4,$C13:$C$148,0)) -> 0.9712549 | M7: 1 | P7: =E13/AVERAGE(E10:E16) -> 0.96230585 | Q7: =E14/AVERAGE(E11:E17) -> 0.97310199 | R7: =E15/AVERAGE(E12:E18) -> 1.0128339 | S7: =E16/AVERAGE(E13:E19) -> 1.0340987 | T7: 1 | AA7: 1
A8: 1990 Q4 | B8: =LEFT(A8,4) -> 1990 | C8: =RIGHT(A8,2) -> Q4 | D8: ='ONS A2 AGG'!G235 -> 375916 | E8: ='ONS A2 AGG'!J235 -> 392096 | F8: =D8/E8 -> 0.9587346 | H8: 1993 | I8: =INDEX($F17:$F$148,MATCH(I$4,$C17:$C$148,0)) -> 1.0306867 | J8: =INDEX($F17:$F$148,MATCH(J$4,$C17:$C$148,0)) -> 1.0215848 | K8: =INDEX($F17:$F$148,MATCH(K$4,$C17:$C$148,0)) -> 0.98260803 | L8: =INDEX($F17:$F$148,MATCH(L$4,$C17:$C$148,0)) -> 0.96862514 | M8: 1 | P8: =E17/AVERAGE(E14:E20) -> 0.96572162 | Q8: =E18/AVERAGE(E15:E21) -> 0.97331595 | R8: =E19/AVERAGE(E16:E22) -> 1.01868 | S8: =E20/AVERAGE(E17:E23) -> 1.0342096 | T8: 1 | AA8: 1
A9: 1991 Q1 | B9: =LEFT(A9,4) -> 1991 | C9: =RIGHT(A9,2) -> Q1 | D9: ='ONS A2 AGG'!G236 -> 374060 | E9: ='ONS A2 AGG'!J236 -> 357751 | F9: =D9/E9 -> 1.0455876 | H9: 1994 | I9: =INDEX($F21:$F$148,MATCH(I$4,$C21:$C$148,0)) -> 1.0254483 | J9: =INDEX($F21:$F$148,MATCH(J$4,$C21:$C$148,0)) -> 1.0193807 | K9: =INDEX($F21:$F$148,MATCH(K$4,$C21:$C$148,0)) -> 0.98473116 | L9: =INDEX($F21:$F$148,MATCH(L$4,$C21:$C$148,0)) -> 0.97319264 | M9: 1 | P9: =E21/AVERAGE(E18:E24) -> 0.97117956 | Q9: =E22/AVERAGE(E19:E25) -> 0.97883421 | R9: =E23/AVERAGE(E20:E26) -> 1.0229956 | S9: =E24/AVERAGE(E21:E27) -> 1.0344043 | T9: 1 | AA9: 1
A10: 1991 Q2 | B10: =LEFT(A10,4) -> 1991 | C10: =RIGHT(A10,2) -> Q2 | D10: ='ONS A2 AGG'!G237 -> 373608 | E10: ='ONS A2 AGG'!J237 -> 363951 | F10: =D10/E10 -> 1.0265338 | H10: 1995 | I10: =INDEX($F25:$F$148,MATCH(I$4,$C25:$C$148,0)) -> 1.0246205 | J10: =INDEX($F25:$F$148,MATCH(J$4,$C25:$C$148,0)) -> 1.0269614 | K10: =INDEX($F25:$F$148,MATCH(K$4,$C25:$C$148,0)) -> 0.98614829 | L10: =INDEX($F25:$F$148,MATCH(L$4,$C25:$C$148,0)) -> 0.96570835 | M10: 1 | P10: =E25/AVERAGE(E22:E28) -> 0.97286844 | Q10: =E26/AVERAGE(E23:E29) -> 0.96823229 | R10: =E27/AVERAGE(E24:E30) -> 1.0204124 | S10: =E28/AVERAGE(E25:E31) -> 1.040613 | T10: 1 | AA10: 1
A11: 1991 Q3 | B11: =LEFT(A11,4) -> 1991 | C11: =RIGHT(A11,2) -> Q3 | D11: ='ONS A2 AGG'!G238 -> 372878 | E11: ='ONS A2 AGG'!J238 -> 381218 | F11: =D11/E11 -> 0.97812275 | H11: 1996 | I11: =INDEX($F29:$F$148,MATCH(I$4,$C29:$C$148,0)) -> 1.0293808 | J11: =INDEX($F29:$F$148,MATCH(J$4,$C29:$C$148,0)) -> 1.0266062 | K11: =INDEX($F29:$F$148,MATCH(K$4,$C29:$C$148,0)) -> 0.98254588 | L11: =INDEX($F29:$F$148,MATCH(L$4,$C29:$C$148,0)) -> 0.96558397 | M11: 1 | P11: =E29/AVERAGE(E26:E32) -> 0.96786511 | Q11: =E30/AVERAGE(E27:E33) -> 0.96322093 | R11: =E31/AVERAGE(E28:E34) -> 1.0089807 | S11: =E32/AVERAGE(E29:E35) -> 1.0344717 | T11: 1 | AA11: 1
A12: 1991 Q4 | B12: =LEFT(A12,4) -> 1991 | C12: =RIGHT(A12,2) -> Q4 | D12: ='ONS A2 AGG'!G239 -> 373357 | E12: ='ONS A2 AGG'!J239 -> 390983 | F12: =D12/E12 -> 0.95491876 | H12: 1997 | I12: =INDEX($F33:$F$148,MATCH(I$4,$C33:$C$148,0)) -> 1.0134595 | J12: =INDEX($F33:$F$148,MATCH(J$4,$C33:$C$148,0)) -> 1.0047065 | K12: =INDEX($F33:$F$148,MATCH(K$4,$C33:$C$148,0)) -> 0.99356597 | L12: =INDEX($F33:$F$148,MATCH(L$4,$C33:$C$148,0)) -> 0.98909754 | M12: 1 | P12: =E33/AVERAGE(E30:E36) -> 0.98505646 | Q12: =E34/AVERAGE(E31:E37) -> 0.99120965 | R12: =E35/AVERAGE(E32:E38) -> 1.0052805 | S12: =E36/AVERAGE(E33:E39) -> 1.0205635 | T12: 1 | AA12: 1
A13: 1992 Q1 | B13: =LEFT(A13,4) -> 1992 | C13: =RIGHT(A13,2) -> Q1 | D13: ='ONS A2 AGG'!G240 -> 373317 | E13: ='ONS A2 AGG'!J240 -> 362126 | F13: =D13/E13 -> 1.0309036 | H13: 1998 | I13: =INDEX($F37:$F$148,MATCH(I$4,$C37:$C$148,0)) -> 1.0092787 | J13: =INDEX($F37:$F$148,MATCH(J$4,$C37:$C$148,0)) -> 1.0169426 | K13: =INDEX($F37:$F$148,MATCH(K$4,$C37:$C$148,0)) -> 1.0021309 | L13: =INDEX($F37:$F$148,MATCH(L$4,$C37:$C$148,0)) -> 0.97304047 | M13: 1 | P13: =E37/AVERAGE(E34:E40) -> 0.9934999 | Q13: =E38/AVERAGE(E35:E41) -> 0.98403213 | R13: =E39/AVERAGE(E36:E42) -> 0.99739311 | S13: =E40/AVERAGE(E37:E43) -> 1.0276428 | T13: 1 | AA13: 1
A14: 1992 Q2 | B14: =LEFT(A14,4) -> 1992 | C14: =RIGHT(A14,2) -> Q2 | D14: ='ONS A2 AGG'!G241 -> 372751 | E14: ='ONS A2 AGG'!J241 -> 366762 | F14: =D14/E14 -> 1.0163294 | H14: 1999 | I14: =INDEX($F41:$F$148,MATCH(I$4,$C41:$C$148,0)) -> 1.0011851 | J14: =INDEX($F41:$F$148,MATCH(J$4,$C41:$C$148,0)) -> 1.0201104 | K14: =INDEX($F41:$F$148,MATCH(K$4,$C41:$C$148,0)) -> 0.99519247 | L14: =INDEX($F41:$F$148,MATCH(L$4,$C41:$C$148,0)) -> 0.9847659 | M14: 1 | P14: =E41/AVERAGE(E38:E44) -> 0.99382282 | Q14: =E42/AVERAGE(E39:E45) -> 0.96969567 | R14: =E43/AVERAGE(E40:E46) -> 1.0020166 | S14: =E44/AVERAGE(E41:E47) -> 1.0218236 | T14: 1 | AA14: 1
A15: 1992 Q3 | B15: =LEFT(A15,4) -> 1992 | C15: =RIGHT(A15,2) -> Q3 | D15: ='ONS A2 AGG'!G242 -> 374537 | E15: ='ONS A2 AGG'!J242 -> 380547 | F15: =D15/E15 -> 0.98420694 | H15: 2000 | I15: =INDEX($F45:$F$148,MATCH(I$4,$C45:$C$148,0)) -> 1.0142931 | J15: =INDEX($F45:$F$148,MATCH(J$4,$C45:$C$148,0)) -> 1.0121075 | K15: =INDEX($F45:$F$148,MATCH(K$4,$C45:$C$148,0)) -> 0.99461219 | L15: =INDEX($F45:$F$148,MATCH(L$4,$C45:$C$148,0)) -> 0.98014309 | M15: 1 | P15: =E45/AVERAGE(E42:E48) -> 0.99238757 | Q15: =E46/AVERAGE(E43:E49) -> 0.98894547 | R15: =E47/AVERAGE(E44:E50) -> 1.0075484 | S15: =E48/AVERAGE(E45:E51) -> 1.0223211 | T15: 1 | AA15: 1
A16: 1992 Q4 | B16: =LEFT(A16,4) -> 1992 | C16: =RIGHT(A16,2) -> Q4 | D16: ='ONS A2 AGG'!G243 -> 377418 | E16: ='ONS A2 AGG'!J243 -> 388588 | F16: =D16/E16 -> 0.9712549 | H16: 2001 | I16: =INDEX($F49:$F$148,MATCH(I$4,$C49:$C$148,0)) -> 1.0017251 | J16: =INDEX($F49:$F$148,MATCH(J$4,$C49:$C$148,0)) -> 1.021527 | K16: =INDEX($F49:$F$148,MATCH(K$4,$C49:$C$148,0)) -> 0.99242039 | L16: =INDEX($F49:$F$148,MATCH(L$4,$C49:$C$148,0)) -> 0.98521812 | M16: 1 | P16: =E49/AVERAGE(E46:E52) -> 0.99887632 | Q16: =E50/AVERAGE(E47:E53) -> 0.9773746 | R16: =E51/AVERAGE(E48:E54) -> 1.0097084 | S16: =E52/AVERAGE(E49:E55) -> 1.0157177 | T16: 1 | AA16: 1
A17: 1993 Q1 | B17: =LEFT(A17,4) -> 1993 | C17: =RIGHT(A17,2) -> Q1 | D17: ='ONS A2 AGG'!G244 -> 379370 | E17: ='ONS A2 AGG'!J244 -> 368075 | F17: =D17/E17 -> 1.0306867 | H17: 2002 | I17: =INDEX($F53:$F$148,MATCH(I$4,$C53:$C$148,0)) -> 1.0022816 | J17: =INDEX($F53:$F$148,MATCH(J$4,$C53:$C$148,0)) -> 1.0212721 | K17: =INDEX($F53:$F$148,MATCH(K$4,$C53:$C$148,0)) -> 0.98615566 | L17: =INDEX($F53:$F$148,MATCH(L$4,$C53:$C$148,0)) -> 0.99121625 | M17: 1 | P17: =E53/AVERAGE(E50:E56) -> 0.99532414 | Q17: =E54/AVERAGE(E51:E57) -> 0.97366257 | R17: =E55/AVERAGE(E52:E58) -> 1.0125698 | S17: =E56/AVERAGE(E53:E59) -> 1.0082405 | T17: 1 | AA17: 1
A18: 1993 Q2 | B18: =LEFT(A18,4) -> 1993 | C18: =RIGHT(A18,2) -> Q2 | D18: ='ONS A2 AGG'!G245 -> 381045 | E18: ='ONS A2 AGG'!J245 -> 372994 | F18: =D18/E18 -> 1.0215848 | H18: 2003 | I18: =INDEX($F57:$F$148,MATCH(I$4,$C57:$C$148,0)) -> 0.99789174 | J18: =INDEX($F57:$F$148,MATCH(J$4,$C57:$C$148,0)) -> 1.0220343 | K18: =INDEX($F57:$F$148,MATCH(K$4,$C57:$C$148,0)) -> 0.99429838 | L18: =INDEX($F57:$F$148,MATCH(L$4,$C57:$C$148,0)) -> 0.98675228 | M18: 1 | P18: =E57/AVERAGE(E54:E60) -> 0.99993511 | Q18: =E58/AVERAGE(E55:E61) -> 0.97631931 | R18: =E59/AVERAGE(E56:E62) -> 1.0122325 | S18: =E60/AVERAGE(E57:E63) -> 1.0196112 | T18: 1 | AA18: 1
A19: 1993 Q3 | B19: =LEFT(A19,4) -> 1993 | C19: =RIGHT(A19,2) -> Q3 | D19: ='ONS A2 AGG'!G246 -> 384524 | E19: ='ONS A2 AGG'!J246 -> 391330 | F19: =D19/E19 -> 0.98260803 | H19: 2004 | I19: =INDEX($F61:$F$148,MATCH(I$4,$C61:$C$148,0)) -> 1.0068332 | J19: =INDEX($F61:$F$148,MATCH(J$4,$C61:$C$148,0)) -> 1.0242709 | K19: =INDEX($F61:$F$148,MATCH(K$4,$C61:$C$148,0)) -> 0.9822317 | L19: =INDEX($F61:$F$148,MATCH(L$4,$C61:$C$148,0)) -> 0.9879507 | M19: 1 | P19: =E61/AVERAGE(E58:E64) -> 0.99478203 | Q19: =E62/AVERAGE(E59:E65) -> 0.97390386 | R19: =E63/AVERAGE(E60:E66) -> 1.0176956 | S19: =E64/AVERAGE(E61:E67) -> 1.0109809 | T19: 1 | AA19: 1
A20: 1993 Q4 | B20: =LEFT(A20,4) -> 1993 | C20: =RIGHT(A20,2) -> Q4 | D20: ='ONS A2 AGG'!G247 -> 387143 | E20: ='ONS A2 AGG'!J247 -> 399683 | F20: =D20/E20 -> 0.96862514 | H20: 2005 | I20: =INDEX($F65:$F$148,MATCH(I$4,$C65:$C$148,0)) -> 1.0010047 | J20: =INDEX($F65:$F$148,MATCH(J$4,$C65:$C$148,0)) -> 1.0238773 | K20: =INDEX($F65:$F$148,MATCH(K$4,$C65:$C$148,0)) -> 0.99099459 | L20: =INDEX($F65:$F$148,MATCH(L$4,$C65:$C$148,0)) -> 0.98536593 | M20: 1 | P20: =E65/AVERAGE(E62:E68) -> 0.99539608 | Q20: =E66/AVERAGE(E63:E69) -> 0.97165628 | R20: =E67/AVERAGE(E64:E70) -> 1.0122573 | S20: =E68/AVERAGE(E65:E71) -> 1.0230282 | T20: 1 | AA20: 1
A21: 1994 Q1 | B21: =LEFT(A21,4) -> 1994 | C21: =RIGHT(A21,2) -> Q1 | D21: ='ONS A2 AGG'!G248 -> 391026 | E21: ='ONS A2 AGG'!J248 -> 381322 | F21: =D21/E21 -> 1.0254483 | H21: 2006 | I21: =INDEX($F69:$F$148,MATCH(I$4,$C69:$C$148,0)) -> 1.0014924 | J21: =INDEX($F69:$F$148,MATCH(J$4,$C69:$C$148,0)) -> 1.0225351 | K21: =INDEX($F69:$F$148,MATCH(K$4,$C69:$C$148,0)) -> 0.99288815 | L21: =INDEX($F69:$F$148,MATCH(L$4,$C69:$C$148,0)) -> 0.98399327 | M21: 1 | P21: =E69/AVERAGE(E66:E72) -> 1.0020504 | Q21: =E70/AVERAGE(E67:E73) -> 0.97603992 | R21: =E71/AVERAGE(E68:E74) -> 1.0058946 | S21: =E72/AVERAGE(E69:E75) -> 1.0125731 | T21: 1 | AA21: 1
A22: 1994 Q2 | B22: =LEFT(A22,4) -> 1994 | C22: =RIGHT(A22,2) -> Q2 | D22: ='ONS A2 AGG'!G249 -> 394588 | E22: ='ONS A2 AGG'!J249 -> 387086 | F22: =D22/E22 -> 1.0193807 | H22: 2007 | I22: =INDEX($F73:$F$148,MATCH(I$4,$C73:$C$148,0)) -> 1.007342 | J22: =INDEX($F73:$F$148,MATCH(J$4,$C73:$C$148,0)) -> 1.0272762 | K22: =INDEX($F73:$F$148,MATCH(K$4,$C73:$C$148,0)) -> 0.98580326 | L22: =INDEX($F73:$F$148,MATCH(L$4,$C73:$C$148,0)) -> 0.98145409 | M22: 1 | P22: =E73/AVERAGE(E70:E76) -> 0.99042223 | Q22: =E74/AVERAGE(E71:E77) -> 0.97171386 | R22: =E75/AVERAGE(E72:E78) -> 1.0200176 | S22: =E76/AVERAGE(E73:E79) -> 1.0311307 | T22: 1 | AA22: 1
A23: 1994 Q3 | B23: =LEFT(A23,4) -> 1994 | C23: =RIGHT(A23,2) -> Q3 | D23: ='ONS A2 AGG'!G250 -> 398566 | E23: ='ONS A2 AGG'!J250 -> 404746 | F23: =D23/E23 -> 0.98473116 | H23: 2008 | I23: =INDEX($F77:$F$148,MATCH(I$4,$C77:$C$148,0)) -> 1.0065538 | J23: =INDEX($F77:$F$148,MATCH(J$4,$C77:$C$148,0)) -> 1.0182984 | K23: =INDEX($F77:$F$148,MATCH(K$4,$C77:$C$148,0)) -> 0.98974322 | L23: =INDEX($F77:$F$148,MATCH(L$4,$C77:$C$148,0)) -> 0.98534132 | M23: 1 | P23: =E77/AVERAGE(E74:E80) -> 1.0078136 | Q23: =E78/AVERAGE(E75:E81) -> 0.99385435 | R23: =E79/AVERAGE(E76:E82) -> 1.0189182 | S23: =E80/AVERAGE(E77:E83) -> 1.0118849 | T23: 1 | AA23: 1
A24: 1994 Q4 | B24: =LEFT(A24,4) -> 1994 | C24: =RIGHT(A24,2) -> Q4 | D24: ='ONS A2 AGG'!G251 -> 400279 | E24: ='ONS A2 AGG'!J251 -> 411305 | F24: =D24/E24 -> 0.97319264 | H24: 2009 | I24: =INDEX($F81:$F$148,MATCH(I$4,$C81:$C$148,0)) -> 1.0068962 | J24: =INDEX($F81:$F$148,MATCH(J$4,$C81:$C$148,0)) -> 1.0244589 | K24: =INDEX($F81:$F$148,MATCH(K$4,$C81:$C$148,0)) -> 0.98856621 | L24: =INDEX($F81:$F$148,MATCH(L$4,$C81:$C$148,0)) -> 0.98128103 | M24: 1 | P24: =E81/AVERAGE(E78:E84) -> 0.97538003 | Q24: =E82/AVERAGE(E79:E85) -> 0.96100537 | R24: =E83/AVERAGE(E80:E86) -> 1.0050401 | S24: =E84/AVERAGE(E81:E87) -> 1.0155806 | T24: 1 | AA24: 1
A25: 1995 Q1 | B25: =LEFT(A25,4) -> 1995 | C25: =RIGHT(A25,2) -> Q1 | D25: ='ONS A2 AGG'!G252 -> 402390 | E25: ='ONS A2 AGG'!J252 -> 392721 | F25: =D25/E25 -> 1.0246205 | H25: 2010 | I25: =INDEX($F85:$F$148,MATCH(I$4,$C85:$C$148,0)) -> 1.0069672 | J25: =INDEX($F85:$F$148,MATCH(J$4,$C85:$C$148,0)) -> 1.0239363 | K25: =INDEX($F85:$F$148,MATCH(K$4,$C85:$C$148,0)) -> 0.9901191 | L25: =INDEX($F85:$F$148,MATCH(L$4,$C85:$C$148,0)) -> 0.98034274 | M25: 1 | P25: =E85/AVERAGE(E82:E88) -> 0.99015883 | Q25: =E86/AVERAGE(E83:E89) -> 0.97848949 | R25: =E87/AVERAGE(E84:E90) -> 1.0179234 | S25: =E88/AVERAGE(E85:E91) -> 1.0260243 | T25: 1 | W25: =$E85/(($E83/8)+($E84/4)+($E85/4)+($E86/4)+($E87/8)) -> 0.99181266 | X25: =$E86/(($E84/8)+($E85/4)+($E86/4)+($E87/4)+($E88/8)) -> 0.97973939 | Y25: =$E87/(($E85/8)+($E86/4)+($E87/4)+($E88/4)+($E89/8)) -> 1.0136286 | Z25: =$E88/(($E86/8)+($E87/4)+($E88/4)+($E89/4)+($E90/8)) -> 1.0207454 | AA25: 1
A26: 1995 Q2 | B26: =LEFT(A26,4) -> 1995 | C26: =RIGHT(A26,2) -> Q2 | D26: ='ONS A2 AGG'!G253 -> 403259 | E26: ='ONS A2 AGG'!J253 -> 392672 | F26: =D26/E26 -> 1.0269614 | H26: 2011 | I26: =INDEX($F89:$F$148,MATCH(I$4,$C89:$C$148,0)) -> 1.0100763 | J26: =INDEX($F89:$F$148,MATCH(J$4,$C89:$C$148,0)) -> 1.0197176 | K26: =INDEX($F89:$F$148,MATCH(K$4,$C89:$C$148,0)) -> 0.99275009 | L26: =INDEX($F89:$F$148,MATCH(L$4,$C89:$C$148,0)) -> 0.97852622 | M26: 1 | P26: =E89/AVERAGE(E86:E92) -> 0.99032146 | Q26: =E90/AVERAGE(E87:E93) -> 0.9757884 | R26: =E91/AVERAGE(E88:E94) -> 1.0062612 | S26: =E92/AVERAGE(E89:E95) -> 1.0209506 | T26: 1 | W26: =$E89/(($E87/8)+($E88/4)+($E89/4)+($E90/4)+($E91/8)) -> 0.99081884 | X26: =$E90/(($E88/8)+($E89/4)+($E90/4)+($E91/4)+($E92/8)) -> 0.98018899 | Y26: =$E91/(($E89/8)+($E90/4)+($E91/4)+($E92/4)+($E93/8)) -> 1.0062755 | Z26: =$E92/(($E90/8)+($E91/4)+($E92/4)+($E93/4)+($E94/8)) -> 1.0186234 | AA26: 1
A27: 1995 Q3 | B27: =LEFT(A27,4) -> 1995 | C27: =RIGHT(A27,2) -> Q3 | D27: ='ONS A2 AGG'!G254 -> 407795 | E27: ='ONS A2 AGG'!J254 -> 413523 | F27: =D27/E27 -> 0.98614829 | H27: 2012 | I27: =INDEX($F93:$F$148,MATCH(I$4,$C93:$C$148,0)) -> 1.0089845 | J27: =INDEX($F93:$F$148,MATCH(J$4,$C93:$C$148,0)) -> 1.018873 | K27: =INDEX($F93:$F$148,MATCH(K$4,$C93:$C$148,0)) -> 0.99777373 | L27: =INDEX($F93:$F$148,MATCH(L$4,$C93:$C$148,0)) -> 0.97565153 | M27: 1 | P27: =E93/AVERAGE(E90:E96) -> 0.99164392 | Q27: =E94/AVERAGE(E91:E97) -> 0.97718472 | R27: =E95/AVERAGE(E92:E98) -> 1.0072646 | S27: =E96/AVERAGE(E93:E99) -> 1.0263475 | T27: 1 | W27: =$E93/(($E91/8)+($E92/4)+($E93/4)+($E94/4)+($E95/8)) -> 0.99382477 | X27: =$E94/(($E92/8)+($E93/4)+($E94/4)+($E95/4)+($E96/8)) -> 0.9792193 | Y27: =$E95/(($E93/8)+($E94/4)+($E95/4)+($E96/4)+($E97/8)) -> 1.0065275 | Z27: =$E96/(($E94/8)+($E95/4)+($E96/4)+($E97/4)+($E98/8)) -> 1.0238726 | AA27: 1
A28: 1995 Q4 | B28: =LEFT(A28,4) -> 1995 | C28: =RIGHT(A28,2) -> Q4 | D28: ='ONS A2 AGG'!G255 -> 409132 | E28: ='ONS A2 AGG'!J255 -> 423660 | F28: =D28/E28 -> 0.96570835 | H28: 2013 | I28: =INDEX($F97:$F$148,MATCH(I$4,$C97:$C$148,0)) -> 1.0111484 | J28: =INDEX($F97:$F$148,MATCH(J$4,$C97:$C$148,0)) -> 1.0142085 | K28: =INDEX($F97:$F$148,MATCH(K$4,$C97:$C$148,0)) -> 0.99768932 | L28: =INDEX($F97:$F$148,MATCH(L$4,$C97:$C$148,0)) -> 0.97817767 | M28: 1 | P28: =E97/AVERAGE(E94:E100) -> 0.98397374 | Q28: =E98/AVERAGE(E95:E101) -> 0.9802025 | R28: =E99/AVERAGE(E96:E102) -> 0.9999571 | S28: =E100/AVERAGE(E97:E103) -> 1.0233971 | T28: 1 | W28: =$E97/(($E95/8)+($E96/4)+($E97/4)+($E98/4)+($E99/8)) -> 0.98586029 | X28: =$E98/(($E96/8)+($E97/4)+($E98/4)+($E99/4)+($E100/8)) -> 0.9848487 | Y28: =$E99/(($E97/8)+($E98/4)+($E99/4)+($E100/4)+($E101/8)) -> 1.001935 | Z28: =$E100/(($E98/8)+($E99/4)+($E100/4)+($E101/4)+($E102/8)) -> 1.0196837 | AA28: 1
A29: 1996 Q1 | B29: =LEFT(A29,4) -> 1996 | C29: =RIGHT(A29,2) -> Q1 | D29: ='ONS A2 AGG'!G256 -> 412022 | E29: ='ONS A2 AGG'!J256 -> 400262 | F29: =D29/E29 -> 1.0293808 | H29: 2014 | I29: =INDEX($F101:$F$148,MATCH(I$4,$C101:$C$148,0)) -> 1.0062565 | J29: =INDEX($F101:$F$148,MATCH(J$4,$C101:$C$148,0)) -> 1.0085093 | K29: =INDEX($F101:$F$148,MATCH(K$4,$C101:$C$148,0)) -> 1.0025393 | L29: =INDEX($F101:$F$148,MATCH(L$4,$C101:$C$148,0)) -> 0.98338026 | M29: 1 | P29: =E101/AVERAGE(E98:E104) -> 0.99126823 | Q29: =E102/AVERAGE(E99:E105) -> 0.99115062 | R29: =E103/AVERAGE(E100:E106) -> 1.0002383 | S29: =E104/AVERAGE(E101:E107) -> 1.0231271 | T29: 1 | W29: =$E101/(($E99/8)+($E100/4)+($E101/4)+($E102/4)+($E103/8)) -> 0.99122979 | X29: =$E102/(($E100/8)+($E101/4)+($E102/4)+($E103/4)+($E104/8)) -> 0.99156084 | Y29: =$E103/(($E101/8)+($E102/4)+($E103/4)+($E104/4)+($E105/8)) -> 0.99950967 | Z29: =$E104/(($E102/8)+($E103/4)+($E104/4)+($E105/4)+($E106/8)) -> 1.020256 | AA29: 1
A30: 1996 Q2 | B30: =LEFT(A30,4) -> 1996 | C30: =RIGHT(A30,2) -> Q2 | D30: ='ONS A2 AGG'!G257 -> 413325 | E30: ='ONS A2 AGG'!J257 -> 402613 | F30: =D30/E30 -> 1.0266062 | H30: 2015 | I30: =INDEX($F105:$F$148,MATCH(I$4,$C105:$C$148,0)) -> 1.0118686 | J30: =INDEX($F105:$F$148,MATCH(J$4,$C105:$C$148,0)) -> 1.009249 | K30: =INDEX($F105:$F$148,MATCH(K$4,$C105:$C$148,0)) -> 0.9988949 | L30: =INDEX($F105:$F$148,MATCH(L$4,$C105:$C$148,0)) -> 0.98083798 | M30: 1 | P30: =E105/AVERAGE(E102:E108) -> 0.98778657 | Q30: =E106/AVERAGE(E103:E109) -> 0.9900348 | R30: =E107/AVERAGE(E104:E110) -> 0.99981424 | S30: =E108/AVERAGE(E105:E111) -> 1.022447 | T30: 1 | W30: =$E105/(($E103/8)+($E104/4)+($E105/4)+($E106/4)+($E107/8)) -> 0.98920929 | X30: =$E106/(($E104/8)+($E105/4)+($E106/4)+($E107/4)+($E108/8)) -> 0.99107819 | Y30: =$E107/(($E105/8)+($E106/4)+($E107/4)+($E108/4)+($E109/8)) -> 1.00018 | Z30: =$E108/(($E106/8)+($E107/4)+($E108/4)+($E109/4)+($E110/8)) -> 1.0192236 | AA30: 1
A31: 1996 Q3 | B31: =LEFT(A31,4) -> 1996 | C31: =RIGHT(A31,2) -> Q3 | D31: ='ONS A2 AGG'!G258 -> 417019 | E31: ='ONS A2 AGG'!J258 -> 424427 | F31: =D31/E31 -> 0.98254588 | H31: 2016 | I31: =INDEX($F109:$F$148,MATCH(I$4,$C109:$C$148,0)) -> 1.01115 | J31: =INDEX($F109:$F$148,MATCH(J$4,$C109:$C$148,0)) -> 1.0083283 | K31: =INDEX($F109:$F$148,MATCH(K$4,$C109:$C$148,0)) -> 1.0047323 | L31: =INDEX($F109:$F$148,MATCH(L$4,$C109:$C$148,0)) -> 0.97686292 | M31: 1 | P31: =E109/AVERAGE(E106:E112) -> 0.98643252 | Q31: =E110/AVERAGE(E107:E113) -> 0.99090039 | R31: =E111/AVERAGE(E108:E114) -> 0.99401357 | S31: =E112/AVERAGE(E109:E115) -> 1.0247734 | T31: 1 | W31: =$E109/(($E107/8)+($E108/4)+($E109/4)+($E110/4)+($E111/8)) -> 0.98871691 | X31: =$E110/(($E108/8)+($E109/4)+($E110/4)+($E111/4)+($E112/8)) -> 0.99323735 | Y31: =$E111/(($E109/8)+($E110/4)+($E111/4)+($E112/4)+($E113/8)) -> 0.99446585 | Z31: =$E112/(($E110/8)+($E111/4)+($E112/4)+($E113/4)+($E114/8)) -> 1.0225982 | AA31: 1
A32: 1996 Q4 | B32: =LEFT(A32,4) -> 1996 | C32: =RIGHT(A32,2) -> Q4 | D32: ='ONS A2 AGG'!G259 -> 422639 | E32: ='ONS A2 AGG'!J259 -> 437703 | F32: =D32/E32 -> 0.96558397 | H32: 2017 | I32: =INDEX($F113:$F$148,MATCH(I$4,$C113:$C$148,0)) -> 1.011936 | J32: =INDEX($F113:$F$148,MATCH(J$4,$C113:$C$148,0)) -> 1.0118512 | K32: =INDEX($F113:$F$148,MATCH(K$4,$C113:$C$148,0)) -> 1.0018753 | L32: =INDEX($F113:$F$148,MATCH(L$4,$C113:$C$148,0)) -> 0.97567149 | M32: 1 | P32: =E113/AVERAGE(E110:E116) -> 0.98641081 | Q32: =E114/AVERAGE(E111:E117) -> 0.98925182 | R32: =E115/AVERAGE(E112:E118) -> 1.0010389 | S32: =E116/AVERAGE(E113:E119) -> 1.0338793 | T32: 1 | W32: =$E113/(($E111/8)+($E112/4)+($E113/4)+($E114/4)+($E115/8)) -> 0.9892996 | X32: =$E114/(($E112/8)+($E113/4)+($E114/4)+($E115/4)+($E116/8)) -> 0.98939042 | Y32: =$E115/(($E113/8)+($E114/4)+($E115/4)+($E116/4)+($E117/8)) -> 0.99876594 | Z32: =$E116/(($E114/8)+($E115/4)+($E116/4)+($E117/4)+($E118/8)) -> 1.0280911 | AA32: 1
A33: 1997 Q1 | B33: =LEFT(A33,4) -> 1997 | C33: =RIGHT(A33,2) -> Q1 | D33: ='ONS A2 AGG'!G260 -> 429418 | E33: ='ONS A2 AGG'!J260 -> 423715 | F33: =D33/E33 -> 1.0134595 | H33: 2018 | I33: =INDEX($F117:$F$148,MATCH(I$4,$C117:$C$148,0)) -> 1.0115 | J33: =INDEX($F117:$F$148,MATCH(J$4,$C117:$C$148,0)) -> 1.0120291 | K33: =INDEX($F117:$F$148,MATCH(K$4,$C117:$C$148,0)) -> 1.0031067 | L33: =INDEX($F117:$F$148,MATCH(L$4,$C117:$C$148,0)) -> 0.97444962 | M33: 1 | P33: =E117/AVERAGE(E114:E120) -> 0.98837662 | Q33: =E118/AVERAGE(E115:E121) -> 0.98661435 | R33: =E119/AVERAGE(E116:E122) -> 0.99600605 | S33: =E120/AVERAGE(E117:E123) -> 1.0283803 | T33: 1 | W33: =$E117/(($E115/8)+($E116/4)+($E117/4)+($E118/4)+($E119/8)) -> 0.98885254 | X33: =$E118/(($E116/8)+($E117/4)+($E118/4)+($E119/4)+($E120/8)) -> 0.98786173 | Y33: =$E119/(($E117/8)+($E118/4)+($E119/4)+($E120/4)+($E121/8)) -> 0.99757572 | Z33: =$E120/(($E118/8)+($E119/4)+($E120/4)+($E121/4)+($E122/8)) -> 1.024854 | AA33: 1
